{{structure info}}
[[File:Amethyst Geode JE4 BE1.png|thumb|A Geode, crystal ball]]

== Materials ==
{| class="wikitable"
!Block        
!Amount      
|-
|{{BlockLink|Smooth Basalt}}
|60+
|-
|{{BlockLink|Calcite}}
|30+
|-
|{{BlockLink|Block of Amethyst}}
|20+
|-
|{{BlockLink|Budding Amethyst}}
|5+
|}

Small Amethyst Buds to Amethyst Clusters are always random depending on Budding Amethyst to grow them.

There are 3 sizes: Small, Medium and Large.

{{Layered blueprint|default=Layer 15|name=Amethyst Geode
|C=Calcite|B=Smooth Basalt|A=Block of Amethyst|M=Budding Amethyst

|----Layer 1|
 
 
 
     BBB
    BBBBB
    BBBBB
    BBBBB
    BBBBB
      BB
      
      
      
|----Layer 2|
 
 
     BBB
    BBBBB
   BBBCBBB
   BBCCCBB
   BBCCCBB
   BBBCCBB
    BBBBBB
     BBBB
|----Layer 3|
 
     BBBB
    BBBCBB
   BBCCCBB
  BBCCACCBB
  BBCAMACBBB
  BBCCAACCBB
  BBCCCCCCBB
   BBCCCCBB
    BBCCBB
     BBBB
|----Layer 4|
    BBBBBB
   BBBBBBBB
  BBBCCCBBBB
 BBBCAAACBBB
 BBCAA ACBBBB
 BBCA   ACBBB
 BBBCA  ACBBB
 BBBCAMAACBBB
 BBBCAAMACBBB
  BBBCAACBBB
   BBBCCBBB
    BBBBBB
|----Layer 5|
   BBBBBBBB
  BBBCCCBBBB
 BBBCAMACBBBB
BBBCA   ACBBBB
BBCA    MCBBBB
BBCA     ACBBB
BBBCA    ACBBB
 BBCA    ACBBB
 BBCA    ACBBB
  BBCA  ACBBB
   BBCAACBBB
    BBCCBBB
     BBBB
|----Layer 6|
   BBBBBBBB
  BBCCCCCBBB
 BBCAAMAACBBB
BBCA     ACBBB
BCA      MCBBB
BCA       ACBB
BBCA      ACBB
 BCA      ACBB
 BCA      ACBB
  BCA    ACBBB
   BCAAAACBBB
    BCCCCBB
     BBBBB

|----Layer 7|
   BBBBBBBB
  BBCCCCCBBB
 BBCAAAAACBBB
BBCA     ACBBB
BCA      ACBBB
BCA       ACBB
BBCA      ACBB
 BCA      ACBB
 BCA      ACBB
  BCA    ACBBB
   BCAMMACBBB
    BCCCCBB
     BBBBB

|----Layer 8|
   BBBBBBBB
  BBCCCCCBBB
 BBCAAAAACBBB
BBCM     ACBBB
BCA      ACBBB
BCA       ACBB
BBCA      MCBB
 BCA      ACBB
 BCA      ACBB
  BCA    ACBBB
   BCAAAACBBB
    BCCCCBB
     BBBBB

|----Layer 9|
   BBBBBBBB
  BBCCCCCBBB
 BBCAAAAACBBB
BBCA     ACBBB
BCA      MCBBB
BCA       ACBB
BBCA      ACBB
 BCA      ACBB
 BCA      ACBB
  BCA    ACBBB
   BCAAAACBBB
    BCCCCBB
     BBBBB
|----Layer 10|
   BBBBBBBB
  BBBBBBBBBB
 BBBCCCCCCBBB
BBBCAAMAAACBBB
BBCAA   AAACBB
BBCA     AACBB
BBCA     AACBB
 BBCA    ACBBB
 BBCA    ACBBB
  BBCAAAACBBB
   BBCCCCBB
     BBBBB
|----Layer 11|
 
   BBBBBBBB
  BBBBBBBBBB
 BBBCCCCCCBBB
 BBCCAAACCCBB
 BBCA   MCCBB
 BBCA   ACCBB
  BBCA  ACBBB
  BBCAAAACBB
   BBCCCCBB
     BBBBB
|----Layer 12|
 
 
    BBBBBB
   BBBBBBBB
  BBBCCCBBBB
  BBCAAMCBBB
  BBCM ACBBB
   BBCAACBBB
    BBCCBBB
     BBBBB
|----Layer 13|
 
 
 
    BBBBBB
   BBBBBBBB
   BBCCCBBB
   BBCACBBB
    BBCCBB
     BBBB
|----Layer 14|
 
 
 
 
     BBBB
    BBBBBB
    BBCBBB
     BBBB
|----Layer 15|
 
 
 
 
 
      BB
      B
}}