<noinclude>{{structure info}}</noinclude>
[[File:Ancient City camp 1.png|thumb|Camp 1 (Deep Dark)]]

{{layered blueprint|name=Ancient City Camp 1|default=Layer 1
|D=Cobbled Deepslate
|S=Cobbled Deepslate Stairs
|C=Cyan Wool
|B=Blue Wool
|L=Light Blue Wool
|E=Deepslate Bricks
|----Layer 1|
DDD DD DDDD
D    D  DD
D
D  SSSSSSSSSSS
   SDDDDDDDDDS
   SDDDDDDDDDS
D  SDDDDDDDDDS
D  SDDDDDDDDDS
D  SDDDDDDDDDS  D
D  SDDDDDDDDDS  D
   SDDDDDDDDDS  E
   SDDDDDDDDDS
   SSSSSSSSSSS
   
                E
      D        DD
     DDDDDDD D DD
|----Layer 2|
 D   D
D
 
D
         BBB
       BBBBB
       BBBBB
D       BBBB
D    CCCCLLL
     CCCLLLL
      CCCLLL    E
       CCCLL
       
       
                D
                
          DD    D
|----Layer 3|
 D
 
 
 
          BB
        BBBB
         BBB
         LLL
       CC LL
      CCCLLL
        CLLL
|----Layer 4|
 
 
 
 
          BB
          B
          
          
          
          L
         L
|----Layer 5|
 
 
 
 
          BB
          B
}}