{{Wip}}
[[File:Ancient_City_top_left_corner.png|thumb|Top left corner]]

{{layered blueprint|name=Bottom Wall 1|default=Layer 1
|J=Chiseled Deepslate
|F=Dark Oak Fence
|P=Dark Oak Planks
|S=Deepslate
|K=Deepslate Brick Stairs
|D=Deepslate Bricks
|C=Cracked Deepslate Bricks
|H=Deepslate Tile Slab
|I=Deepslate Tile Stairs
|Y=Deepslate Tile Wall
|T=Deepslate Tiles
|N=Cracked Deepslate Tiles
|W=Gray Wool
|R=Polished Deepslate
|A=Polished Deepslate Stairs
|L=Redstone Lamp
|E=Sculk Sensor

|----Layer 1|
DDDDDDDDDDDDS
DDDDDDDCCDDDS
DDDDDDDDDDDDS
DDDDDCDDDDDDS
DDDDDDDDDDDDS
DDCCCDDDDDDDS
DDDDCCDDDDDDS
DDDDDDCDDDDCS
DDDDDDDDDDCDS
DDDDCDDDDDCDS
DDDCCDDDDDDDS
DDDDDDDDDDDDS
							
|----Layer 2|
WWSK     KDWS
SSSW     KDWD
 KWW      WWD
         KDWD
         K WD
          WWS
         KWDS
         KWDS
 K  KK KKKDWS
WDDWDDWDDDDWS
WWWWWWWWWWWWD
SSDDDDSSSSSDD

|----Layer 3|
W D       JWT
DDCW      JWC
  W       WWJ
          J J
          JWD
          WWT
          JWT
          JWT
          J T
WJJWJJWJJJJWT
WWWWWWWWWWW D
TTDJJDTTTTTDJ

|----Layer 4|
WDDI      IWI
CDDW      IWD
JIWW      WWJ
          IWJ
          IWD
          WWI
          IWI
          IWI
          IWI
WIIWII IIIIWI
WWWWWWWWWWWWD
IICJJDIIIIIDJ

|----Layer 5|
DDDI      IWWI
DDDW      I WD
IIWW      WWWC
          IWWD
          IWWD
           WWI
          IWWI
          IWWI
          IWWI
WIIWII IIIIWWI
 WWWWWWW WWWWD
WWWWWWWWWWWWWD
IID DDIIIIIDDD

|----Layer 6|
WW I      J  J
   W      J  Y
IIW       I  J
              
              
              
              
             Y
		  I  J
IJJIJJIJJIJ  J
             Y
             J
JJY     YJJYJJ

|----Layer 7|
 W I         I
WW        I  I
          I   
I  W         I
          I  I
		      
              
              
              
		     I
 II II III   I
              
			 I
II       II II

|----Layer 8|
             I
          I  I
          I   
             I
          I  I
              
              
              
		      
          H  I
 II II IIHH  I

			 I
II       II IH
}}