<noinclude>{{structure info}}</noinclude>
[[File:Ancient City sauna 1.png|thumb|Sauna 1 (Deep Dark)]]

{{layered blueprint|name=Ancient City Sauna 1|default=Layer 1
|D=Deepslate Bricks
|T=Deepslate Tiles
|C=Cracked Deepslate Bricks
|E=Deepslate
|H=Chiseled Deepslate
|W=Water
|R=Cracked Deepslate Tiles
|A=White Candle
|S=Deepslate Tile Stairs
|B=Chest
|I=Deepslate Tile Slab
|L=Deepslate Brick Slab
|----Layer 1|
DDDDDDDDDDDDDDDDDDDDDDDC     
 DDDDDDDDDDDDDDDDDDDCDC      
 DDDDDDDDDDDDDDDDDDDDDCCCD DD
  DDDDDTTTTTTTTTTTTTTTCCCDDDD
  DDDDDTTTTTTTTTTTTTTTDCCDDDD
   DDDDTTTTTTTTTTTTTTTDCCCDDD
     DDTTTTTTTTTTTTTTTDDDDDDD
     DDTTTTTTTTTTTTTTTDDDDDDD
     DDTTTTTTTTTTTTTTTDDDDDDD
     CDTTTTTTTTTTTTTTEDDDDDDD
    CCDDDDDDDDDDDDDDDDDDDDDDD
   CEEEDDDDDDDDDDDDDCDDDDDDDD
  CCDEEEEDDDDDCDDDDCDCDDDDDDD
D DCDDDDDDCCDCCCDDDDDDCCCCDDD
DDDDCDCDDDDDDDCCDCCDDDDDDDDDD
DDDCDDDDDDDDDDCDDDDDDDDDCDDDD
DDCDDDEEEEEEEEDEETTTTTDDCDCDD
DDDDCDEEEEEEEECEEEETTTDDDCCCD
DDDCDDEEEEEEEECEEEEETTDDCC   
DDDDDDEEEEEEEEDEDTTTTTDDC    
DDDCDDEEEEEEEECEDTTTTTDDC    
DDDCCDEEEEEEEECCDDDDDDDCCCCC 
DDDDCDCDDDCCDDCCCCDDCCDCC    
DDDCCDCCDCDTTTTTTTTTTTDDC    
DDCDCDDDDDDTSWWWWWWWWTDDCC   
DDCCDDTTTTDTSWWWWWWWWTDDCC   
DDDC ETTTTDTSWWWWWWWWTDDCCCCD
DDD CDTTTTDTSWWWWWWWWTDDCCCDD
    DDTTTTDTSWWWWWWWWTDD   DD
     DDDDDDTTTTTTTTTTTDD  DDD
      CDDDDDDDDDDDDDDDDDDDDDD
       DEDCDDDDDDDDDDDDDDDDDD
        ECDDDDDDDDDDDDDDDDDDD
        DDDDDDDDDDEDDDDDDDDDD
        DDDDDDDDDDDDDDDDDDDDD
         DDDDDDDDDDDCCCCDDDDD
         DDDDDDDDDDDDC CDDDDD
|----Layer 2|
 DDDDDDDDDDDCCC CDDDDDD      
                             
  RR   RR           RR   R   
  TT   TT           TT   TT  
         TTTT   TTTTS       D
         TTTT   TTTTS       D
         TTTTAAATTTTS       D
        STTTTTTTTTTTS       D
        STTTTSISTTT     DDD D
           TT   TT        D D
                       D BD D
                       DDDD D
                            D
                            D
D                           D
RR               DDDDDD    RR
TT    DDCCDD D        C    TT
D     D      I        D     D
DD          AD       BD      
DD          BD  D     D      
      D      D  DA    D      
      DDDDDDDD  DDDIDDD      
                             
                       D     
      DDDD             D     
      DDA              D     
DD                     D    D
DD                     D    D
      DDA              D    D
      DDDD             D   RR
                       D   TT
            DA         D    D
            DDDDA   DDDD    D
            DDDDD   DDDD    D
                            D
                            D
           DDDDDDDDDD    CCDD
|----Layer 3|
  DDDDDDDDDCCCC  CDDC D      
                             
  HH   HH           HH   HH  
  H    HH           HH   HH  
         STTT   TTTS        D
         STTT   TTTS        D
          TTT   TTTS        D
          TTTAAATTT         D
         STTSSHSST       DD D
           AA   AA        D D
                       D  D D
                       DDDD D
                            D
                            D
D                           D
HH               CCDDCC    HH
HH    DD  ADDC        C    HH
D     D               D     D
DD           D        D      
DD           D  D     D      
      D      D  D     D      
      CDDDDDDD  DDD DDD      
                             
                       D     
      DDDD             D     
       A               D     
DD                     D    D
DD                     D   DD
                            D
      ADDD             A   HH
                       D   HH
            D          D    D
            D         AD     
           CDDDDD   DDDD     
                             
                            D
               D DDD       CD
|----Layer 4|
    DDDDDDDDDDDD CC          
                             
  TR    R           TR   TR  
                    T    TR  
          STTTTTTTS         D
          STTTTTTTS         D
          STTTTTTTS         D
           TTTTTTT          D
            TTTTTT       DD D
                          D D
                          D  
                        DDD  
                            D
                            D
D                           D
TR                 CCDC    TR
T     DC    CC        C    TR
D     C      D        C     D
DD           D        C      
DD                           
      CC              D      
      D DD L     DDDDDD      
                             
                       D     
      DDCD             D     
         D             D     
DD       D                 DD
DD       D                 DD
         D                  D
        DD                 TR
                       A   TR
            D          D    D
            D          D     
             DDDD   DDDD     
                             
                             
            DDDDDDDD        D
|----Layer 5|
    DDDDDDD DD CDDDC         
                             
   S    S           S    SS  
   S                     SS  
            AAAAA            
            SSSSS           D
            SWWWS           D
            SSSSS           D
             AAAA           D
                             
                             
                             
                             
                             
                            D
SS                         SS
                            S
                             
DD                           
DD                           
                             
                             
                             
                             
                             
                             
DD                         DD
DD                         DD
                            D
                           SS
                           SS
                            D
            C          D     
            DCDCDDDDD  D     
                             
                             
            DDDDD DDD       C
|----Layer 6|
       DD   D                
                             
  SS   SS           S    SS  
  SS    S           S    SS  
                             
                             
                             
                             
                             
                             
                             
                             
                             
                             
                            D
                           SS
                           SS
                            D
DD                           
DD                           
DD                           
DD                           
                             
                             
DD                         DD
DD                         DD
DD                         DD
DD                         DD
                            D
                           SS
                           SS
                            D
                            D
                             
                             
                             
          DDDDDDD  DDD       
|----Layer 7|
                             
                             
   H   HH           H    HH  
   H                H    HH  
                             
                             
                             
                             
                             
                             
                             
                             
                             
                             
                            D
                           HH
                           HH
                            D
                            D
DD                           
DD                           
DD                           
DD                           
DD                          D
DD                          D
DD                          D
 D                         DD
                            D
                            D
                           HH
                           HH
                            D
                            D
                             
                             
                             
          DDDDDD   DDD       
|----Layer 8|
                             
                             
   TS STT           T S S T  
   TS S                 S T  
                             
                             
                             
                             
                             
                             
                             
                             
                             
                            D
                            D
                           TT
                           TT
                            D
D                           D
D                           D
D                            
DD                           
DD                           
DD                           
DD                           
D                           D
                             
                            D
                            D
                           TT
                           TT
                            D
                            D
                            D
                             
                             
          DDDDDD             
|----Layer 9|
                             
                             
  TTTTTT            TTTT     
  TTTTT                      
                             
                             
                             
                             
                             
                             
                             
                             
                             
                            D
                            D
                           TT
                           TT
                            D
                            D
                            D
                            D
                            D
D                            
D                            
D                            
                             
                             
                             
                            D
                           TT
                           TT
                            D
                             
                             
                             
                             
          DDD                
          
}}