{{Wip}}
[[File:Ancient_City_right.png|thumb|Right wall]]

{{layered blueprint|name=Bottom Wall 1|default=Layer 1
|J=Chiseled Deepslate
|F=Dark Oak Fence
|P=Dark Oak Planks
|S=Deepslate
|K=Deepslate Brick Stairs
|D=Deepslate Bricks
|C=Cracked Deepslate Bricks
|H=Deepslate Tile Slab
|I=Deepslate Tile Stairs
|Y=Deepslate Tile Wall
|T=Deepslate Tiles
|N=Cracked Deepslate Tiles
|W=Gray Wool
|R=Polished Deepslate
|A=Polished Deepslate Stairs
|L=Redstone Lamp
|E=Sculk Sensor

|----Layer 1|
 SDDDDDDDDDDDD
 SDDDDDSSDDDDS
 SDDDDSSSDDDDS
 SDDDDSSDDDDDS
 SDDDDDSDDDDDS
ASDDDDDDDDDDDS
DDDDDDSDDDDDDS
DDDDDDSSSDDDDS
DDDDDDDSSDDDDS
DSDDDDDDSDDDDS
DSDDDDDDDDDDDS
ASDDDDDDDDDDDS
 SDDDDDDDDDDDS
 SDDDDDSSDDDDS
 SDDDDDDDDDDDS
 SDDDDDDDDDDDS
 SDDDSDDDDDDDS
 SDDDDDDDDDDDS
 SDDDDDDDDDDDS

|----Layer 2|
 SWDK     KSWS
 SWDK     WSWS
 DWW      WSWS
 DWK      WSWS
 DW       WSWS
 DWK      KSWS
ASSK       DWS
WA        KSWS
WA        WSWS
WA        WSWS
ASWDK     KSWS
 DWDK      DWS
 DWW      KSWS
 DWDK     WSWS
 DWDK     WSWS
 SWW      WSWS
 SWDK     WSWS
 SWDK     KSWS

|----Layer 3|
 TWJ       DWS
 TWJ      WDWS
 DWW      WDWS
 JW       WDWS
 JW       WDWS
 DW        DWS
 TI        DWS
           DWS
          WDWS
          WDWS
 TWJ       DWS
 DWJ       DWS
 JWW       DWS
 JWJ      WDWS
 DWJ      WDWS
 TWW      WDWS
 TWJ      WDWS
 TWJ       DWS
 

|----Layer 4|
 IWI      IDWD
 IWI      WDWD
 DWW      WDWD
 JWI      WDWD
 JWJ      WDWD
 DWJ      IDWD
 I        JDWD
          IDWD
          WDWD
          WDWD
 IWI      IDWD
 DWI      JDWD
 JWW      IDWD
 JWI      WDWD
 DWI      WDWD
 IWW      WDWD
 IWI      WDWD
 IWI      IDWD
 

|----Layer 5|
IWWI      IDWD
IWWI      WDWD
DWWW      WDWD
DW W      WDWD
DI        WDWD
D         IDWD
I         IDWD
   I      IDWD
          WDWD
   I      WDWD
IWWI      IDWD
DWWI      IDWD
DWWW      IDWD
DWWI      WDWD
DWWI      WDWD
IWWW      WDWD
IWWI      WDWD
IWWI      IDWD

|----Layer 6|
J  J      I W 
J  J      W W 
Y  I      W W 
J         W W 
J         W W 
Y         I W 
J         I W 
JWWJ      I W 
YWWJ      W W 
JWWI      W W 
J  J      I W 
Y  J      I W 
J  I      I W 
J  J      W W 
Y  J      W W 
J  I      W W 
J  J      W W 
Y  J      I W 

|----Layer 7|
I  I      
I  I        W 
          W   
I           W 
I         W   
            W 
I         I   
I  I        W 
   I      W   
I         W W 
I  I          
   I      I W 
I             
I  I      W W 
   I          
I         W W 
I  I          
   I      I W 
   
|----Layer 8|
I             
I             
              
              
              
              
I             
I             
              
              
   I          
   I          
I             
I             
              
              
   I          
   I          

}}