<noinclude>{{structure info}}</noinclude>
[[File:Ancient City camp 2.png|thumb|Camp 2 (Deep Dark)]]
{{layered blueprint|name=Ancient City Camp 2|default=Layer 1
|D=Cobbled Deepslate
|S=Cobbled Deepslate Stairs
|C=Cyan Wool
|B=Blue Wool
|L=Light Blue Wool
|O=Dark Oak Log
|M=Campfire
|E=Deepslate Bricks
|----Layer 1|
DDD DD DDDD
D    D  DD
D
D  SSSSSSSSSSS
   SDDDDDDDDDS
   SDDDDDDDDDS
D  SDDDDDDDDDS
D  SDDDDDDDDDS
D  SDDDDDDDDDS  D
D  SDDDDDDDDDS  D
   SDDDDDDDDDS  E
   SDDDDDDDDDS
   SSSSSSSSSSS
   
                E
      D        DD
     DDDDDDD D DD
|----Layer 2|
 D   D
D

D
    OLBO BBBO
    L       B
    L SSS O B
D     SSS
D         M C
     L OO   C
    OLLLCCCCO   E
 
 
 
                D
                
          DD    D
|----Layer 3|
 D
 
 
 
    OLB   BBO
            B
  
  
            
     L      C
    OLLLLCCCO
|----Layer 4|
 
 
 
 
    L      BB
            B
            
            
            
            
    OL      C
|----Layer 5|
 
 
 
 
 
 
 
 
 
 
     L      C
}}