{{Wip}}
[[File:Ancient_City_bottom_left_corner.png|thumb|Bottom left corner]]

{{layered blueprint|name=Bottom Wall 1|default=Layer 1
|J=Chiseled Deepslate
|F=Dark Oak Fence
|P=Dark Oak Planks
|S=Deepslate
|K=Deepslate Brick Stairs
|D=Deepslate Bricks
|C=Cracked Deepslate Bricks
|H=Deepslate Tile Slab
|I=Deepslate Tile Stairs
|Y=Deepslate Tile Wall
|T=Deepslate Tiles
|N=Cracked Deepslate Tiles
|W=Gray Wool
|R=Polished Deepslate
|A=Polished Deepslate Stairs
|L=Redstone Lamp
|E=Sculk Sensor

|----Layer 1|
             
SSSSSSSSSSSSS
DDDDDDDSSDDDS
DDDDDDDDDDDDS
DDDDDSDDDDDDS
DDDDDDDDDDDDS
DDSSSDDDDDDDS
DDDDSSDDDDDDS
DDDDDDSDDDDSS
DDDDDDDDDDSDS
DDDDSDDDDDSDS
DDDSSDDDDDDDS
DDDDDDDDDDDDS


|----Layer 2|
              
SSDDDDSSSSSDD 
WWWWWWWWWWWWD 
WDDWDDWDDWWWS 
 KK KK KKKWWS 
         KDWS 
         KDWS 
          WWS 
         KDWD 
         KDWD 
 KWW      WWD 
 SSSW    KDWD 
 WWSK    KDWS 
 SWS      WWS 

|----Layer 3|
             
TTDJJDTTTTTDJ 
WWWWWWWWWWWWD 
WJJWJJWJJWWWT 
          WWT 
          JWT
          JWT
          WWT
          JWD
          JWJ
  WW      WWJ 
DDDW      JWD 
WWD       JWT 
DWD       WWT 

|----Layer 4|
             
IIDJJDIIIIIDJ 
WWWWWWWWWWWWD 
WIIWIIWIIWWWI 
          WWI 
          IWI 
          IWI 
          WWI 
          IWD 
          IWJ 
JIWW      WWJ 
DDDW      IWD 
WWDI      IWI 
DWDJ      WWI 

|----Layer 5|
IIDDDDIIIIIDD 
             D
             D
WIIWIIWIIWWWWI
          WWWI
          IWWI
          IWWI
          WWWI
          IWWD
          IWWD
IIWW      WWWD
DDDW      IWWD
DDDI      IWWI
DDDI      WWWI

|----Layer 6|
JJYJJYJJYJJYJJ
             J
             Y
IJJIJJIJJII  J
          I  J
          J  Y
          J  J
          I  J
          J  Y
          J  J
IIWW      I  J
   W      J  Y
WW I      J  J
 W I      I  J

|----Layer 7|
II II II II II
             I
              
 II II II     
              
              
          I  I
             I
          I   
          I  I
I  W         I
          I   
 W        I  I
    I        I

|----Layer 8|
II    II    IH
             I
              
    II        
              
              
             I
             I
          I   
          I   
              
             I
             I

}}