<noinclude>{{structure info}}[[uk:Стародавнє місто/Структура/Плани/Вхідний шлях 2]]</noinclude>
[[File:Ancient City entrance path 2.png|thumb|Entrance Path 2 (Deep Dark)]]

{{layered blueprint|name=Ancient City Entrance Path 2|default=Layer 1
|D=Deepslate Tiles
|E=Deepslate
|P=Polished Deepslate
|C=Chiseled Deepslate
|B=Polished Basalt
|S=Smooth Basalt
|R=Deepslate Bricks
|T=Deepslate Tile Stairs
|L=Deepslate Brick Slab
|O=Dark Oak Planks
|A=Ladder
|N=Candle
|I=Deepslate Tile Slab
|W=Polished Deepslate Wall
|U=Soul Lantern
|K=Deepslate Brick Stairs
|----Layer −1|
   DDDDDDDDDDDDDDDDDDDDDDDDDDDDDDDD
  DDDDDDDDDDDDDDDDDDDDDDDDDDDDDDDDD
DDDDDDDDDDDDDDDDDDDDDDDDDDDDDDDDDDD
DDDDDD DDDDDDDDDDDDDDDDDDDDDDDDDDDD
DDDDDDDDDDDDDDDDDDDDDDDDDDDDDDDDDDD
DDDDDDDDDDDDDDDDDDDDDDDDDDDDDDDDDDD
DDDDDDD DDDDDDDDDDDDDDDDDDDDDDDDDDD
DDDDDDDDDDDDDDDDDDDDDDDDDDDDDDDDDDD
DDDDDDDDDDDDDDDDDDDDDDDDDDDDDDDDDDD
                                   
                                   
                                   
                                   
                                   
                                   
 PDDDDDDDAADDDDDDDDAADDDDDDDD  DDDD
PDDDDDDDDBBDDDDDDDDBBDDDDDDDDDDDDDD
PDDDDDDDDDDDDDDDDDDDDDDDDDDDDDDDDDD
PDDDDDDDDDDDDDDDDDDDDDDDDDDDDDDDDDD
PDDDDDDDDDDDDDDDDDDDDDDDDDDDDDDDDDP
PDDDDDDDDDDDDDDDDDDDDDDDDDDDDDDDDDD
PDDDDDDDDDDDDDDDDDDDDDDDDDDDDDDDDDD
PDDDDDDDDDDDDDDDDDDDDDDDDDDDDDDDDDD
 PDDDDDDDDDDDDDDDDDDDDDDDDDDDDDDDDD
                                   
                                   
              B          EE        
              BEB        E       B 
                                 E 
                                 EE
DDDDDDDDDDDDDDDDDDDDDDDDDDDDDDDDDDD
DDDDDDDDDDDDDDDDDDDDDDDDDDDDDDDDDDD
 DDDDDDDDDDDDDDDDDDDDDDDDDDDDDDDDDD
DDDDDDDDDDDDDDDDDDDDDDDDDDDDDDDDDDD
DDDDDDDDDDDDDDDDDDDDDDDDDDDDDDDDDDD
DDDDDDDDDDDDDDDDDDDDDDDDDDDDDDDDDDD
DDDDDDDDDDDDDDDDDDDDDDDDDDDDDDDDDDD
  DDDDDDDDDDDDDDDDDDDDDDDDDDDDDDDDD
   DDDDDDDDDDDDDDDDDDDDDDDDDDDDDDDD
|----Layer 0|
    DDDDDDDDDDDDDDDDDDDDDDDDDDDDDDD
     DD DDDDDDDDDDDDDDDDDDDDDDDDDDD
     D   DDDDDDDDDDDDDDDDDDDDDDDDDD
  DDD   DDDDDDDDDDDDDDDDDDDDDDDDDDD
DDDD    DDDDDDDDDDDDDDDDDDDDDDDDDDD
 DDD   DDDDDDDDDDDDDDDDDDDDDDDDDDDD
DDDD    DDDDDDDDDDDDDDDDDDDDDDDDDDD
  DDDD DD  DDDDDDDDD DDDDDDDDDDDDDD
 DDDD      DDDDDDD   DDDDDDD   DDDD
                                   
                                   
                                   
                                   
                                   
                                   
  PPDDDDDAADDDDDDDDAADDDDDDDD  DDDD
  DDDDDDDBBDDDDDDDDBBDDDDDDDDDDDDDD
 DDDDDDDDDDDDDDDDDDDDDDDDDDDDDDDDDD
 DDDDDDDDDDDDDDDDDDDDDDDDDDDDDDDDDD
 DDDDDDDDDDDDDDDDDDDDDDDDDDDDDDDDDD
 DDDDDDDDDDDDDDDDDDDDDDDDDDDDDDDDDD
 DDDDDDDDDDDDDDDDDDDDDDDDDDDDDDDDDD
  DDDDDDDDDDDDDDDDDDDDDDDDDDDDDDDDD
  PPDDDDDDDDDDDDDDDDDDDDDDDDDDDDDDD
                                   
                                   
                                   
                                   
                                   
                                   
DDDDDDDDDDDDDDDDDDDDDDDDDDDDDDDDDDD
DDDDDDDDDDDDDDDDDDDDDDDDDDDDDDDDDDD
 DDDDDDDDDDDDDDDDDDDDDDDDDDDDDDDDDD
    DD  DDDDDDDDDDDDDDDDDDDDDDDDDDD
D  DDDD DDDDDDDDDDDDDDDDDDDDDDDDDDD
D   D    DDDDDDDDDDDDDDDDDDDDDDDDDD
DDDDD  DDDDDDDDDDDDDDDDDDDDDDDDDDDD
  DDD  DDDDDDDDDDDDDDDDDDDDDDDDDDDD
      DDDDDDDDDDDDDDDDDDDDDDDDDDDDD
|----Layer 1|
         BBBEEEEEEBBBBEEEEEEBBBBEEE
         BEEEEEEEEEEEEEEEEEEEEEEEEE
         BEEEEEEEEEEEEEEEEEEEEEEEEE
         BEEEEEEEEEEEEEEEEEEEEEEEEE
         BEEEEEEEEEEEEEEEEEEEEEEEEE
         BEEEEEEEEEEEEEEEEEEEEEEEEE
          EEEEEEEEEEEEEEEEEEEEEEEEE
            EEEOEEE   EEEEEEE   EEE
           BBBOOOB    BBEEB     BOO
               OO      BEEB      OO
               OO      BEEB      O 
              OEO      BEEB        
              OEB      BEEB        
              EEB      BEEB       O
             BEEB      BEEB      OO
    PPDDDAADDDEEDDDAADDDEEDDD  DDOO
    DDDDDBBDDDEEDDDBBDDDEEDDDDDDDDE
   DDDDDDDDDDDDDDDDDDDDDDDDDDDDI   
  DDDDDDDDDDDDDDDDDDDDDDDDDDDDDI   
  DDDDDDDDDDDDDDDDDDDDDDDDDDDDDI   
  DDDDD DDDDDDDDDDDDDDDDDDDDDDDI   
   DDDDDDDDDDDDDDDDDDDDDDDDDDDD    
   DDDDDDDDDDDEEDDDDDDDDEEDDDDDDDDE
    PPDDDDDDDDEEDDDDDDDDEEDDDDDDDDE
             BEEB      BEEB      BE
             BEEB      BEEB       E
                B       EEB        
                        EE         
             BE         E B      BE
             BE        BEEB      BE
         BBBBBEEBBBBBBBBEEBBBBBBBBE
         BEEEEEEEEEEEEEEEEEEEEEEEEE
         BEEEEEEEEEEEEEEEEEEEEEEEEE
         BEEEEEEEEEEEEEEEEEEEEEEEEE
         BEEEEEEEEEEEEEEEEEEEEEEEEE
         BEEEEEEEEEEEEEEEEEEEEEEEEE
         BEEEEEEEEEEEEEEEEEEEEEEEEE
         BEEEEEEEEEEEEEEEEEEEEEEEEE
         BBBEEEEEEBBBBEEEEEEBBBBEEE
|----Layer 2|
           TDDDDDT    TDDDDDT  TDDD
            TEEEET    TEEEET    TEE
            TEEEET    TEEEET    TEE
            TEEEET    TEEEET     EE
            T EEET    TEEEET     EE
              TTTT    TTTTTT     TT
              W U                  
                                   
                                   
                                   
                                   
                                   
                                   
                                   
                                   
      DDD   DD  DDD  DDD  DDD  DDD 
      DDD N  D  DDD  DDD  DDD  DDD 
   TTTSPST    TTSPSTTSPSTTSPS      
   T  DD   DDDDDDDDDDDDDDDI        
   TD  DDDD  DDDDDDDDDDDDDI        
   TD   DDDDDDDDDDDDDDDDDDDD       
   TTTS  TTSPSTTSPSTTSPSTTSPS      
      DDD  DDD  DDD  DDD  DDD  DDD 
      DDD  DDD  DDDDDDDD  DDD  DDD 
                                   
                                   
                                   
                                   
                                   
                                   
                                   
                                   
           D E EEEE            EEE 
              TEETP       TT   ETE 
          DDTPEEETE      EET  EETE 
            TEEEEEE    EEEET   ETEE
           DTEEEEET   TEEEET   ETEE
            TEEEET    TEEEET  E TEE
           TDD DDT    TDDDDDT  TDDD
|----Layer 3|
            KRRRR      RRRRK    KRR
             EEEE      EEEE      EE
             EEEE      EEEE      EE
             EEEE      EEEE      EE
             E EE      EEEE       E
                                   
                                   
                                   
                                   
                                   
                                   
                                   
                                   
                                   
                                   
      DDD       DDD  DDD  DDD  DDD 
      SPS       SPS  SPS  SPS  SPS 
                      D            
                        D          
               D       DI          
               DI   DI             
                 PP  D             
      SPS  SPS  SPS  SPS  SPS  SPS 
      DDD  DDD  DDDDDDDD  DDD  DDD 
                                   
                                   
                                   
                                   
                                   
                                   
                                   
                                   
                                   
               E                   
              EEE        EE        
              EEEE       EE      E 
             EEEEE     EEEE      EE
             EEEE      EEEE      EE
            KRRRR      RRRRK    KRR
|----Layer 4|
                                   
             TTTT      TTTT      TT
             TPPT      TPPT      TP
             TPPT      TPPT      TP
               TT      TTTT       T
                                   
                                   
                                   
                                   
                                   
                                   
                                   
                                   
                                   
                                   
      P P  P P  P P  P P  P P  P   
      N N       N N    N   NN  NN  
                                   
                                   
                                   
                                   
                                   
      NN    NN   PP   N   NNN  N N 
      P P  P P    PDDP P  P P  P P 
                                   
                                   
                                   
                                   
                                   
                                   
                                   
                                   
                                   
                                   
               TT        TT        
              PPT        PT      TP
             TPPT       PPT      TP
             TTTT      TTTT      TT
                                   
|----Layer 5|
                                   
             PPPP      PPPP      PP
             PPPP      PPPP      PP
             PPPP      PPPP      PP
               PP      PPPP      PP
                                   
                                   
                                   
                                   
                                   
                                   
                                   
                                   
                                   
                                   
       CR  RCR  RCR  RCR  RCR  RC  
                                   
                                   
                                   
                                   
                                   
                                   
                                   
      RC   RCR      DRCR  RCR  RCR 
                                   
                                   
                                   
                                   
                                   
                                   
                                   
                                   
                                   
                                   
               PP        PP        
              PPP        PP      PP
             PPPP       PPP      PP
             PPPP      PPPP      PP
                                   
|----Layer 6|
                                   
              DDC      CDDC      CD
             DPPD      DPPD      DP
              PPD      DPPD      DP
              DDC      CDDC      CD
                                   
                       U  U      U 
                                   
                                   
                                   
                                   
                                   
                                   
                                   
                                   
       DD  DDD  DDD  DDD  DDD  DD  
       DD  DDD  DDD       DDD  DD  
       TT  TTT  TTT       TTT  TTT 
                                   
                                   
                                   
      TT    TT       TTT    T   T  
      DD   DDD       DDD    D   DD 
      D      D       DDD  DDD  DDD 
                                   
                                   
                                   
                                   
                                   
                                   
                                   
                                   
             U  U         U        
                                   
             CDDC        DC        
             DPPD        PD      DP
             DPPD       PPD      DP
             CDDC      CDDC      CD
                                   
|----Layer 7|
                                   
              PPP      PPPP      PP
              PPP      PPPP      PP
             PPPP      PPPP      PP
             PPPP      PPPP      PP
                W      W  W      W 
                W      W  W      W 
                                   
                                   
                                   
                                   
                                   
                                   
                                   
                                   
                                   
       LL  LLL  LLL       LLL  LL  
       DD  DDD  DDD       DDD  DDD 
      DDD  D DDDDDD   DD  DDDDDDDD 
      D DDDD D    DDDDDDDDDDD    D 
      DDDD DDD  DDD  DDD   DD   DD 
      DD    DD       DDD        D  
      LL    LL       LLL        LL 
                                   
                                   
                                   
                                   
                                   
                                   
                                   
                                   
                                   
             W  W         W        
             W  W         W        
             PPPP       PPP       P
             PPPP        PP       P
             PPPP      PPPP      PP
             PPPP      PPPP      PP
                                   
|----Layer 8|
                                   
                D      DCCD      DC
               PC      CPPC      CP
               PC      CPPC       P
               CD      DCCD      DC
                                   
                                   
                                   
                                   
                                   
                                   
                                   
                                   
                                   
                                   
                                   
                                   
                                   
                                   
                                   
                                   
                                   
                                   
                                   
                                   
                                   
                                   
                                   
                                   
                                   
                                   
                                   
                                   
                                   
             D CD      DCCD        
             CPPC      CPPC      CP
             CPPC      CPPC      CP
             DCCD      DCCD       C
                                  E
|----Layer 9|
                                   
             PPPP      PPPP      PP
             PPPP      PPPP      PP
             PPPP      PPPP      PP
              PPP       PPP      PP
                                   
                                   
                                   
                                   
                                   
                                   
                                   
                                   
                                   
                                   
                                   
                                   
                                   
                                   
                                   
                                   
                                   
                                   
                                   
                                   
                                   
                                   
                                   
                                   
                                   
                                   
                                   
                                   
                                   
                       PPPP      PP
              P        PPPP      PP
             PP        PPPP      PP
             PPP       PPPP       P
                                   
|----Layer 10|
                                   
             TTTT      TTTT      TT
             TPPT      TPPT      TP
             TPPT      TPPT      TP
             TTTT      TTTT      TT
                                   
                                   
                                   
                                   
                                   
                                   
                                   
                                   
                                   
                                   
                                   
                                   
                                   
                                   
                                   
                                   
                                   
                                   
                                   
                                   
                                   
                                   
                                   
                                   
                                   
                                   
                                   
                                   
                                   
                       TTTT       T
              P T      TPPT       P
              PP       TPPT      TP
             TT        TTTT      TT
                                   
|----Layer 11|
                                   
             EEEE      EEEE      EE
             EEEE      EEEE      EE
             EEEE       EEE      EE
             EEE       EEEE      EE
                                   
                                   
                                   
                                   
                                   
                                   
                                   
                                   
                                   
                                   
                                   
                                   
                                   
                                   
                                   
                                   
                                   
                                   
                                   
                                   
                                   
                                   
                                   
                                   
                                   
                                   
                                   
                                   
                                   
                       EEEE        
                       EEEE        
                       EEEE      EE
             EE        EEEE       E
                                   
|----Layer 12|
            TT  TT      TTTT    TTT
            TE  ET    TEEEET    TEE
            TEEEET    TEEEET    TEE
            TEEEE     TEEEET    TEE
            TEEE         EET     EE
            TTT                  TT
                                   
                                   
                                   
                                   
                                   
                                   
                                   
                                   
                                   
                                   
                                   
                                   
                                   
                                   
                                   
                                   
                                   
                                   
                                   
                                   
                                   
                                   
                                   
                                   
                                   
                                   
                                   
                      TTTT         
                      TEEEE        
                      TEEEE        
                      TEEEET       
                      TEEEET       
                      TTTTTT       
|----Layer 13|
            E   EE       EEE    EEE
            EE  EE      EEEE    EEE
            EE EEE     EEEEE    EEE
            EEEEE     EEE E     EEE
            EEEE        E        EE
            EEE                  EE
                                   
                                   
                                   
                                   
                                   
                                   
                                   
                                   
                                   
                                   
                                   
                                   
                                   
                                   
                                   
                                   
                                   
                                   
                                   
                                   
                                   
                                   
                                   
                                   
                                   
                                   
                                   
                      EEEE         
                      EEEE         
                      EEEEE        
                      EEEEEE       
                      EEEEEE       
                      EEEEEE       
}}