<noinclude>{{structure info}}</noinclude>
[[File:Ancient City tall ruin 4.png|thumb|Tall Ruin 4 (Deep Dark)]]

{{layered blueprint|name=Ancient City Tall Ruin 4|default=Layer 1
|D=Deepslate Bricks
|T=Deepslate Tiles
|G=Gray Carpet
|S=Deepslate Tile Stairs
|W=Deepslate Tile Wall
|C=Chest
|----Layer 1|
                 
     TTSS        
     TTTTTTT     
    STTTTTTTTTS  
    STTTTTTTTTS  
     TTTTTTTTT   
    STTTTTTTTTS  
    STTTTT TTTS  
     TTTTT TTT   
     TTTTTTTTT   
    STTTTTTTTTS  
    STTTTTTTTTS  
     TTTTTTTTT   
    STTTTTTTTTS  
    STTTTTTTTTS  
     TTSSTSSTT   
                 
|----Layer 2|
                 
                 
      D  D  D    
                 
                 
      D  D       
       DD        
       D         
      DDD        
      DSSD  D    
                 
                 
      D  D  D    
                 
                 
      D  D  D    
                 
|----Layer 3|
                 
                 
      D  D  D    
                 
                 
      D          
       D         
       D         
      DSS        
      D          
                 
                 
      D  D  D    
                 
                 
      D  D  D    
                 
|----Layer 4|
                 
                 
      D  D  D    
                 
                 
      DD         
       D         
       S         
      D          
      D          
                 
                 
      D  D  D    
                 
                 
      D  D  D    
                 
|----Layer 5|
                 
                 
      D  D  D    
                 
       DD        
      DDD        
       S         
                 
      D          
      D          
                 
                 
      D  D  D    
                 
                 
      D  D  D    
                 
|----Layer 6|
                 
                 
      D  D  D    
       DD        
       DD        
       S         
                 
                 
      D          
      D          
                 
                 
      D  D  D    
                 
                 
      D  D  D    
                 
|----Layer 7|
                 
    DDDDDDDDDDD  
    DDDDDDDDDDD  
    DDD  DD DDD  
         D  DDD  
               DD
              DDD
              DDD
    DD        DDD
    DD       DDDD
    DDD      DDDD
    DDD      DDDD
    DDDDDD   DDDD
    DDDDDDDDDDD  
    DDDDDDDDDDD  
    DDDDDDDDDDD  
    DDDDDDDDDDD  
|----Layer 8|
                 
                 
              D  
                 
                 
             WDWW
                W
                W
    D         D W
    D           W
     GW         W
     GW         W
    DGWWW     DWW
     GGGC  GGG   
     GGGG GGGG   
    DGGG  GGGGD  
                 
|----Layer 9|
                 
                 
              D  
                 
                 
             WD  
                 
                 
    D         D  
    D            
                 
                 
    D WWW     D  
                 
                 
    D         D  
                 
|----Layer 10|
                 
                 
                 
                 
                 
              D  
                 
                 
              D  
    D            
                 
                 
       WW        
                 
                 
    D         D  
                 
|----Layer 11|
                 
                 
                 
                 
                 
              D  
                 
                 
              D  
              D  
                 
                 
    D         D  
                 
                 
    D         D  
                 
|----Layer 12|
                 
                 
                 
                 
                 
                 
                 
                 
                 
              TT 
              TT 
   TT         TT 
   TTTTTTTTTTTTT 
   TT         TT 
   TT         TT 
   TTTTTTTTTTTTT 
   TT         TT 
|----Layer 13|
                 
                 
                 
                 
                 
                 
                 
                 
                 
         T       
        TTTTTTS  
    ST  TTTTTTS  
    STTTTTTTTTS  
    STTTTTTTTTS  
    STTTTTTTTTS  
    STTTTTTTTTS  
    STTTTTTTTTS  
}}