<noinclude>{{structure info}}</noinclude>
[[File:Ancient City small ruin 2.png|thumb|Small Ruin 2 (Deep Dark)]]

{{layered blueprint|name=Ancient City Small Ruin 2|default=Layer 1
|C=Cobbled Deepslate
|----Layer 1|
    C  C
C      C
C      C
C C    C
|----Layer 2|
    C   
       C
C      C
       C
|----Layer 3|
        
        
       C
       C
}}