<noinclude>{{structure info}}</noinclude>
[[File:Ancient City medium ruin 2.png|thumb|Medium Ruin 2 (Deep Dark)]]

{{layered blueprint|name=Ancient City Medium Ruin 2 |default=Layer 1
|C=Cobbled Deepslate
|----Layer 1|
     CCC C CC C 
                
               C
                
C               
C              C
                
                
C               
C               
CCC    CC C     
|----Layer 2|
      CC C  C   
                
               C
                
C               
                
                
                
                
C               
C               
|----Layer 3|
         C      
                
                
                
                
                
                
                
                
C               
             
}}