<noinclude>{{structure info}}[[uk:Стародавнє місто/Структура/Плани/Вхідний шлях 4]]</noinclude>
[[File:Ancient City entrance path 4.png|thumb|Entrance Path 4 (Deep Dark)]]

{{layered blueprint|name=Ancient City Entrance Path 4 |default=Layer 1
|D=Deepslate Tiles
|E=Deepslate
|P=Polished Deepslate
|O=Dark Oak Planks
|B=Deepslate Bricks
|A=Polished Basalt
|T=Deepslate Tile Stairs
|S=Smooth Basalt
|C=Chiseled Deepslate
|R=Deepslate Brick Slab
|L=Dark Oak Log
|F=Ladder
|K=Dark Oak Fence
|W=Cobbled Deepslate Wall
|N=Candle
|I=Light Blue Carpet
|G=Deepslate Tile Slab
|H=Deepslate Brick Stairs
|J=Cobbled Deepslate
|U=Soul Lantern
|M=Polished Deepslate Wall
|Q=Torch
|----Layer −1|
     DDDDDDDDDDDDDDDDDDDDDDDDDDDDDD
   DDDDDDDDDDDDDDDDDDDDDDDDDDDDDDDD
    DDDDDDDDDDDDDDDDDDDDDDDDDDDDDDD
   DDD DDDDDDDDDDDDDDDDDDDDDDDDDDDD
  DDDDDDDDDDDDDDDDDDDDDDDDDDDDDDDDD
     DDDDDDDDDDDDDDDDDDDDDDDDDDDDDD
     DD DDDDDDDDDDDDDDDDDDDDDDDDDDD
    DDDDDDDDDDDDDDDDDDDDDDDDDDDDDDD
    DDDDDDDDDDDDDDDDDDDDDDDDDDDDDDD
                                   
                                   
                                   
                                   
                                   
                                   
 PDDDDDDDFFDDDDDDDDFFDDDDDDDD  DDD 
PDDDDDDDDAADDDDDDDDAADDDDDDDDDDDDDD
PDDDDDDDDDDDDDDDDDDDDDDDDDDDDDDDDDD
PDDDDDDDDDDDDDDDDDDDDDDDDDDDDDDDDDD
PDDDDDDDDDDDDDDDDDDDDDDDDDDDDDDDDDP
PDDDDDDDDDDDDDDDDDDDDDDDDDDDDDDDDDD
PDDDDDDDDDDDDDDDDDDDDDDDDDDDDDDDDDD
PDDDDDDDDD DDDDDDDDDDDDDDDDDDDDDDDD
 PDDDDDDDDDDDDDDDDDDDDDDDDDDDDDDDDD
                                   
                                   
                                   
                                 A 
                                 E 
                                 EE
DDDDDDDDDDDDDDDDDDDDDDDDDDDDDDDDDDD
DDDDDDDDDDDDDDDDDDDDDDDDDDDDDDDDDDD
 DDDDDDDDDDDDDDDDDDDDDDDDDDDDDDDDDD
DDDDDDDDDDDDDDDDDDDDDDDDDDDDDDDDDDD
DDDDDDDDDDDDDDDDDDDDDDDDDDDDDDDDDDD
DDDDDDDDDDDDDDDDDDDDDDDDDDDDDDDDDDD
DDDDDDDDDDDDDDDDDDDDDDDDDDDDDDDDDDD
  DDDDDDDDDDDDDDDDDDDDDDDDDDDDDDDDD
   DDDDDDDDDDDDDDDDDDDDDDDDDDDDDDDD
|----Layer 0|
    DDDDDDDDDDDDDDDDDDDDDDDDDDDDDDD
     DD DDDDDDDDDDDDDDDDDDDDDDDDDDD
     D   DDDDEE  DDDDDDDDDDDDDDDDDD
   DD   DDDDDDDT DDDDDDDDDDDDDDDDDD
        DDDDTDDE DDDDDDDDDDDDDDDDDD
       DDDDDDDDP DDDDDDDDDDDDDDDDDD
        DDDDDDDDDDDDD DDDDDDDDDDDDD
       DD  DDDDDDDDD DDDDDDDDD  DDD
           DDDDDDD   DDDDDDD   DD  
                                   
                                   
                                   
                                   
                                   
                                   
  PPDDDDDFFDDDDDDDDFFDDDDDDDD  DD  
  DDDDDDDAADDDDDDDDAADDDDDDDDDDDD  
 DDDDDDDDDDDDDDDDDDDDDDDDDDDDDDDDDD
 DDDDDDDDDDDDDDDDDDDDDDDDDDDDD DDDD
 DDDDDDDDDDDDDDDDDDDDDDDDDDDDDDDDDD
 DDDDDDDDDDDDDDDDDDDDDDDDDDDDDDDDDD
 DDDDDDDDDDDDDDDDDDDDDDDDDDDDDDDDDD
  DDDDDDDD  DDDDDDDDDDDDDDDDDDDDDDD
  PPDDD D    DDDDDDDDDDDDDDDDDDDDDD
                                   
                                   
                                   
                                   
                                   
                                   
DDDDDDDDDDDDDDDDDDDDDDDDDDDDDDDDDDD
DDDDDDDDDDDDDDDDDDDDDDDDDDDDDDDDDDD
 DDDDDDDDDDDDDDDDDDDDDDDDDDDDDDDDDD
    DD  DDDDDDDDDDDDDDDDDDDDDDDDDDD
D  DDDD DDDDDDDDDDDDDDDDDDDDDDDDDDD
D   D    DDDDDDDDDDDDDDDDDDDDDDDDDD
DDDDD  DDDDDDDDDDDDDDDDDDDDDDDDDDDD
  DDD  DDDDDDDDDDDDDDDDDDDDDDDDDDDD
      DDDDDDDDDDDDDDDDDDDDDDDDDDDDD
|----Layer 1|
         AAAEEEEEEAAAAEEEEEEAAAAEEE
         AEE    TEEEEEEEEEEEEEEEEEE
         AE AEP  EEEEEEEEEEEEEEEEEE
         AE TED   EEEEEEEEEEEEEEEEE
         AP  EEE EEEEEEEEEEEEEEEEEE
         APP T P EEEEEEEEEEEEEEEEEE
          P   E  E E  EEEEEEE EEEEE
              EOO      O EEEE   EEE
           A  O O      OOEA        
                       OO          
               O       OOO         
              OEO      OOO         
              OEA      OOO         
              EEA      OOO         
             AEEA      OOOA        
    PPDDDFFDDDEEDDDFFDDOOO DD  DD  
    DDDDDAADDDEEDDDAADDOOODDDDDDD  
   DDDDDDDDDDDDDDDDDDDDODDDD       
  DDDDDDDDDDDDDDDDDDDDDD DD        
  DDDDDDDDDDDDDDDDDDDDDDDDD    G   
  DDDDD DDDDDDDDDDDDDDDDDDDDDDDG   
   DDDDDDD DDDDDDDDDDDDDDDDDDDD    
   DDDDD    DDEEDDDDDDDDEEDDDDDDDDE
      D D    DEEDDDDDDDDEEDDDDDDDDE
               EA       EEA      AE
              O                   E
             OO                    
             OO                    
             OEO          A      AE
             AEO       AEEA      AE
         AAAAAEEAAAAAAAAEEAAAAAAAAE
         AEEEEEEEEEEEEEEEEEEEEEEEEE
         AEEEEEEEEEEEEEEEEEEEEEEEEE
         AEEEEEEEEEEEEEEEEEEEEEEEEE
         AEEEEEEEEEEEEEEEEEEEEEEEEE
         AEEEEEEEEEEEEEEEEEEEEEEEEE
         AEEEEEEEEEEEEEEEEEEEEEEEEE
         AEEEEEEEEEEEEEEEEEEEEEEEEE
         AAAEEEEEEAAAAEEEEEEAAAAEEE
|----Layer 2|
          LEDDL  T    TDDDDDT  TDDD
           EE T  T    TEEEET    TEE
          EEAF        TEEEET   ETEE
          EEEED       TEEEET     EE
          LDDELE      TEEEET E E EE
                      TTTTTT E E TT
                               E   
                                   
                                   
                       O           
                       K K         
                                   
                                   
                                   
                       K K         
      DDD   DD  DDD  DD   DDD  DDD 
      DDD N  D  DDD  D     DD  DDD 
   TTTSPST    TT PST               
   T  DD   DDDDD                   
   TD  DDDD  DDD      DDDDG        
   TD   DD DDDDD     DDDDDDD       
   TTTS  T  PSTTSPSTTSPSTTSPS      
       DD    D  DDD  D    DDD  DDD 
      D      D  DDDDDD    DDD  DDD 
                                   
                                   
              I                    
             II                    
             I                     
                                   
                                   
                                   
           D E EEEE  BBE       EEE 
              TEETP BBBE  TT   ETE 
          DDTPEEETE  BTBE     EETE 
            TEEEEEE  BBBBE     ETEE
           DTEEEEET   TB EE    ETEE
            TEEEET    T B     E TEE
           TDD DDT    T        TDDD
|----Layer 3|
          L   L        BBBBH    HBB
           EE          EEEE      EE
          EEAF         EEEE      EE
          EEEE         EEEE      EE
          LBBPLE       EEEE  E    E
                             E     
                                   
                                   
                                   
                                   
                         K         
                                   
                                   
                                   
                       K K         
      DDD       DDD  D    DDD  DDD 
      SPS       SPS  S      S  SPS 
                                   
                                   
                       D           
                                   
                                   
      SPS    S  SP   S    SPS  SPS 
      D      D  DDDDDD    DDD  DDD 
                                   
                                   
                                   
                                   
                                   
                                   
                                   
                                   
                      E            
               E     BB            
              EEE    T  E          
              EEEE               E 
             EEEEE     B E       EE
             EEEE       B        EE
            HBBBB               HBB
|----Layer 4|
              L                    
            P          TTTT      TT
           PAF         TPPT      TP
          TTTT         TPPT      TP
          L   LP       TTTT       T
                                   
                                   
                                   
                                   
                                   
                         O         
                                   
                                   
                                   
                       OOO         
      P P  P P  P P  P    P P  P   
      N N       N N         N  NN  
                                   
                                   
                                   
                                   
                                   
      NN     N   PP       NNN  N N 
      P P    P    PDDP P    P  P P 
                                   
                                   
                                   
                                   
                                   
                                   
                                   
                                   
                                   
                                   
               TT                  
              PPT                TP
             TPPT                TP
             TTTT                TT
                                   
|----Layer 5|
            P L                    
            P          PPPP      PP
           PAF         PPPP      PP
          PPPP         PPPP      PP
          L   L        PPPP      PP
                                   
                                   
                                   
                                   
                                   
                                   
                                   
                                   
                                   
                                   
       CB  BCB  BCB  BCB  BCB  BC  
                                   
                                   
                                   
                                   
                                   
                                   
                                   
      BC   BCB      DBCB    B  BCB 
                                   
                                   
                                   
                                   
                                   
                                   
                                   
                                   
                                   
                                   
               P                   
              PPP                  
             PPPP                  
             PPPP                PP
                                   
|----Layer 6|
            B L                    
            B  P       CDDC      CD
          BBAF B       DPPD      DP
            B  P       DPPD       P
          L B L        CDDC       D
                                   
                       U  U        
                                   
                                   
                                   
                                   
                                   
                                   
                                   
                                   
        D  DDD  DDD  DDD  DDD  DD  
        D  DDD  DDD         D  DD  
        T  TTT  TTT            TTT 
                                   
                                   
                                   
      TT    TT       TTT        T  
      DD   DDD       DDD        DD 
      D      D       DDD       DDD 
                                   
                                   
                                   
                                   
                                   
                                   
                                   
                                   
                                   
                                   
                                   
             DPPD                  
             DPP                   
             CDDC                CD
                                   
|----Layer 7|
              L                    
            OOOL       PPPP        
           OAFOL       PPPP        
          OOOOO        PPPP        
          JOOOJ        PPPP        
                       M  M        
                       M  M        
                                   
                                   
                                   
                                   
                                   
                                   
                                   
                                   
                                   
        R  RRR  RRR       R R  RR  
        D  DDD  DDD            DDD 
        D  D DDDDDD   DD     DDDDD 
          DD D    DDDDDDDD       D 
           DDD  DDD  DDD        DD 
      DD    DD       DDD        D  
      RR    RR       RRR        RR 
                                   
                                   
                                   
                                   
                                   
                                   
                                   
                                   
                                   
                                   
                                   
              PPP                  
             PP                    
             PP                    
             PPP                 PP
                                   
|----Layer 8|
              W                    
              KK       DCC         
                       CPP         
          K   K        CPPC        
          WK KW        DCCD        
                                   
                                   
                                   
                                   
                                   
                                   
                                   
                                   
                                   
                                   
                                   
                                   
                                   
                                   
                                   
                                   
                                   
                                   
                                   
                                   
                                   
                                   
                                   
                                   
                                   
                                   
                                   
                                   
                                   
                D                  
               P                   
             C                     
             DC                   C
                                  E
|----Layer 9|
              W                    
                       PP          
                       PPP         
                       PPP         
          W   W         PPP        
                                   
                                   
                                   
                                   
                                   
                                   
                                   
                                   
                                   
                                   
                                   
                                   
                                   
                                   
                                   
                                   
                                   
                                   
                                   
                                   
                                   
                                   
                                   
                                   
                                   
                                   
                                   
                                   
                                   
                                   
                                   
             P                     
             PP                   P
                                   
|----Layer 10|
              W                    
                       TT          
                       TPP         
                       TPPT        
          W   W        TTTT        
                                   
                                   
                                   
                                   
                                   
                                   
                                   
                                   
                                   
                                   
                                   
                                   
                                   
                                   
                                   
                                   
                                   
                                   
                                   
                                   
                                   
                                   
                                   
                                   
                                   
                                   
                                   
                                   
                                   
                                   
                                   
                                   
             TT                    
                                   
|----Layer 11|
              O                    
              O        EE          
                       EEE         
              O         EEE        
          OO OO        EEEE        
                                   
                                   
                                   
                                   
                                   
                                   
                                   
                                   
                                   
                                   
                                   
                                   
                                   
                                   
                                   
                                   
                                   
                                   
                                   
                                   
                                   
                                   
                                   
                                   
                                   
                                   
                                   
                                   
                                   
                                   
                                   
                                   
             EE                    
                                   
|----Layer 12|
                                   
             OO       TEE          
                      TEE          
             O        TEEE         
          QOOO           EE        
                                   
                                   
                                   
                                   
                                   
                                   
                                   
                                   
                                   
                                   
                                   
                                   
                                   
                                   
                                   
                                   
                                   
                                   
                                   
                                   
                                   
                                   
                                   
                                   
                                   
                                   
                                   
                                   
                                   
                                   
                                   
                                   
                                   
                                   
|----Layer 13|
                                   
            O                      
           OOO         EE          
           OOO        EEE          
                        E          
                                   
                                   
                                   
                                   
                                   
                                   
                                   
                                   
                                   
                                   
                                   
                                   
                                   
                                   
                                   
                                   
                                   
                                   
                                   
                                   
                                   
                                   
                                   
                                   
                                   
                                   
                                   
                                   
                                   
                                   
                                   
                                   
                                   
                                   
}}