<noinclude>{{structure info}}</noinclude>
[[File:Ancient City tall ruin 2.png|thumb|Tall Ruin 2 (Deep Dark)]]

{{layered blueprint|name=Ancient City Tall Ruin 2|default=Layer 1
|D=Deepslate Tiles
|B=Deepslate Bricks
|G=Gray Carpet
|T=Deepslate Tile Stairs
|W=Deepslate Tile Wall
|S=Soul Lantern
|C=Chest
|----Layer 1|
                 
     DDTTDTTDD   
     DDDDDDDDD   
    TDDDDDDDDDT  
    TDDDDDDDDDT  
     DDDDDDDDD   
    TDDDDDDDDDT  
    TDDDDDDDDDT  
     DDDDDDDDD   
     DDDDDDDDD   
    TDDDDDDDDDT  
    TDDDDDDDDDT  
     DDDDDDDDD   
    TDDDDDDDDDT  
    TDDDDDDDDDT  
     DDTTDTTDD   
                 
|----Layer 2|
                 
                 
      B  B  B    
                 
                 
      BC B  B    
       BB        
       BB        
      BBBB  B    
      BTTB  B    
                 
                 
      B  B  B    
                 
                 
      B  B  B    
                 
|----Layer 3|
                 
                 
      B  B  B    
                 
                 
      B  B  B    
       BB        
       BB        
      BTTB  B    
      B  B  B    
                 
                 
      B  B  B    
                 
                 
      B  B  B    
                 
|----Layer 4|
                 
                 
      B  B  B    
                 
                 
      BBBB  B    
       BB        
       TT        
      B  B  B    
      B  B  B    
                 
                 
      B  B  B    
                 
                 
      B  B  B    
                 
|----Layer 5|
                 
                 
      B  B  B    
                 
       BB        
      BBBB  B    
       TT        
                 
      B  B  B    
      B  B  B    
                 
                 
      B  B  B    
                 
                 
      B  B  B    
                 
|----Layer 6|
                 
                 
      B  B  B    
       BB        
       BB        
      BTTB  B    
                 
                 
      B  B  B    
      B  B  B    
                 
                 
      B  B  B    
                 
                 
      B  B  B    
                 
|----Layer 7|
                 
    BBBBBBBBBBB  
    BBBBBBBBBBB  
    BBBBBBBBBBB  
    BBBTTBBBBBB  
    BBB  BBBBBBBB
    BBB  BBBBBBBB
    BBB  BBBBBBBB
    BBB  BBBBBBBB
    BBB  BBBBBBBB
    BBB  BBBBBBBB
    BBB  BBBBBBBB
    BBBBBBBBBBBBB
    BBBBBBBBBBB  
    BBBBBBBBBBB  
    BBBBBBBBBBB  
    BBBBBBBBBBB  
|----Layer 8|
                 
                 
    BGGGGGGGGGB  
     GGGGGGGGG   
     GW  WGGGG   
    BGW  WGWWWBWW
     GW  WG     W
     GW  WG     W
    BGW  WGWWWB W
    BGW  WG  CB W
     GW  WG     W
     GW  WG     W
    BGWWWWGWWWBWW
     GGGGGGGGG   
     GGGGGGGGG   
    BGGGGGGGGGB  
                 
|----Layer 9|
                 
                 
    B         B  
                 
      S  S       
    B      WWWB  
                 
                 
    B      WWWB  
    B         B  
                 
                 
    B WWWW WWWB  
                 
                 
    B         B  
                 
|----Layer 10|
                 
                 
    B         B  
                 
                 
    B      WWWB  
                 
                 
    B      WWWB  
    B         B  
                 
                 
    B WWWW WWWB  
                 
                 
    B         B  
                 
|----Layer 11|
                 
                 
    B         B  
                 
                 
    B      S  B  
                 
                 
    B      S  B  
    B         B  
                 
                 
    B S  S S  B  
                 
                 
    B         B  
                 
|----Layer 12|
                 
   DD         DD 
   DDDDDDDDDDDDD 
   DD         DD 
   DD         DD 
   DDDDDDDDDDDDD 
   DD         DD 
   DD         DD 
   DD         DD 
   DD         DD 
   DD         DD 
   DD         DD 
   DDDDDDDDDDDDD 
   DD         DD 
   DD         DD 
   DDDDDDDDDDDDD 
   DD         DD 
|----Layer 13|
                 
    TDDDDDDDDDT  
    TDDDDDDDDDT  
    TDDDDDDDDDT  
    TDDDDDDDDDT  
    TDDDDDDDDDT  
    TDDDDDDDDDT  
    TDDDDDDDDDT  
    TDDDDDDDDDT  
    TDDDDDDDDDT  
    TDDDDDDDDDT  
    TDDDDDDDDDT  
    TDDDDDDDDDT  
    TDDDDDDDDDT  
    TDDDDDDDDDT  
    TDDDDDDDDDT  
    TDDDDDDDDDT  
}}