<noinclude>{{structure info}}[[uk:Стародавнє місто/Структура/Плани/Вхідний шлях 3]]</noinclude>
[[File:Ancient City entrance path 3.png|thumb|Entrance Path 3 (Deep Dark)]]

{{layered blueprint|name=Ancient City Entrance Path 3|default=Layer 1
|D=Deepslate Tiles
|E=Deepslate
|P=Polished Deepslate
|O=Dark Oak Planks
|B=Deepslate Bricks
|A=Polished Basalt
|C=Chiseled Deepslate
|T=Deepslate Tile Stairs
|S=Smooth Basalt
|L=Dark Oak Log
|R=Deepslate Brick Slab
|F=Ladder
|W=Cobbled Deepslate Wall
|K=Dark Oak Fence
|N=Candle
|G=Cobbled Deepslate
|I=Deepslate Tile Slab
|U=Soul Lantern
|H=Polished Deepslate Wall
|J=Torch
|M=Deepslate Brick Stairs
|----Layer −1|
     DDDDDDDDDDDDDDDDDDDDDDDDDDDDDD
   DDDDDDDDDDDDDDDDDDDDDDDDDDDDDDDD
    DDDDDDDDDDDDDDDDDDDDDDDDDDDDDDD
   DDD DDDDDDDDDDDDDDDDDDDDDDDDDDDD
  DDDDDDDDDDDDDDDDDDDDDDDDDDDDDDDDD
     DDDDDDDDDDDDDDDDDDDDDDDDDDDDDD
     DD DDDDDDDDDDDDDDDDDDDDDDDDDDD
    DDDDDDDDDDDDDDDDDDDDDDDDDDDDDDD
    DDDDDDDDDDDDDDDDDDDDDDDDDDDDDDD
                                   
                                   
                                   
                                   
                                   
                                   
 PDDDDDDDFFDDDDDDDDFFDDDDDDDD  DDD 
PDDDDDDDDAADDDDDDDDAADDDDDDDDDDDDDD
PDDDDDDDDDDDDDDDDDDDDDDDDDDDDDDDDDD
PDDDDDDDDDDDDDDDDDDDDDDDDDDDDDDDDDD
PDDDDDDDDDDDDDDDDDDDDDDDDDDDDDDDDDP
PDDDDDDDDDDDDDDDDDDDDDDDDDDDDDDDDDD
PDDDDDDDDDDDDDDDDDDDDDDDDDDDDDDDDDD
PDDDDDDDDD DDDDDDDDDDDDDDDDDDDDDDDD
 PDDDDDDDDDDDDDDDDDDDDDDDDDDDDDDDDD
                                   
                                   
                                   
                                 A 
                                 E 
                                 EE
DDDDDDDDDDDDDDDDDDDDDDDDDDDDDDDDDDD
DDDDDDDDDDDDDDDDDDDDDDDDDDDDDDDDDDD
 DDDDDDDDDDDDDDDDDDDDDDDDDDDDDDDDDD
DDDDDDDDDDDDDDDDDDDDDDDDDDDDDDDDDDD
DDDDDDDDDDDDDDDDDDDDDDDDDDDDDDDDDDD
DDDDDDDDDDDDDDDDDDDDDDDDDDDDDDDDDDD
DDDDDDDDDDDDDDDDDDDDDDDDDDDDDDDDDDD
  DDDDDDDDDDDDDDDDDDDDDDDDDDDDDDDDD
   DDDDDDDDDDDDDDDDDDDDDDDDDDDDDDDD
|----Layer 0|
    DDDDDDDDDDDDDDDDDDDDDDDDDDDDDDD
     DD DDDDDDDDDDDDDDDDDDDDDDDDDDD
     D   DDDDEE  DDDDDDDDDDDDDDDDDD
   DD   DDDDDDDT DDDDDDDDDDDDDDDDDD
        DDDDTDDE DDDDDDDDDDDDDDDDDD
       DDDDDDDDP DDDDDDDDDDDDDDDDDD
        DDDDDDDDDDDDD DDDDDDDDDDDDD
       DD  DDDDDDDDD DDDDDDDDD  DDD
           DDDDDDD   DDDDDDD   DD  
                                   
                                   
                                   
                                   
                                   
                                   
  PPDDDDDFFDDDDDDDDFFDDDDDDDD  DD  
  DDDDDDDAADDDDDDDDAADDDDDDDDDDDD  
 DDDDDDDDDDDDDDDDDDDDDDDDDDDDDDDDDD
 DDDDDDDDDDDDDDDDDDDDDDDDDDDDD DDDD
 DDDDDDDDDDDDDDDDDDDDDDDDDDDDDDDDDD
 DDDDDDDDDDDDDDDDDDDDDDDDDDDDDDDDDD
 DDDDDDDDDDDDDDDDDDDDDDDDDDDDDDDDDD
  DDDDDDDD  DDDDDDDDDDDDDDDDDDDDDDD
  PPDDD D    DDDDDDDDDDDDDDDDDDDDDD
                                   
                                   
                                   
                                   
                                   
                                   
DDDDDDDDDDDDDDDDDDDDDDDDDDDDDDDDDDD
DDDDDDDDDDDDDDDDDDDDDDDDDDDDDDDDDDD
 DDDDDDDDDDDDDDDDDDDDDDDDDDDDDDDDDD
    DD  DDDDDDDDDDDDDDDDDDDDDDDDDDD
D  DDDD DDDDDDDDDDDDDDDDDDDDDDDDDDD
D   D    DDDDDDDDDDDDDDDDDDDDDDDDDD
DDDDD  DDDDDDDDDDDDDDDDDDDDDDDDDDDD
  DDD  DDDDDDDDDDDDDDDDDDDDDDDDDDDD
      DDDDDDDDDDDDDDDDDDDDDDDDDDDDD
|----Layer 1|
         AAAEEEEEEAAAAEEEEEEAAAAEEE
         AEE    TEEEEEEEEEEEEEEEEEE
         AE  EP  EEEEEEEEEEEEEEEEEE
         AE TED   EEEEEEEEEEEEEEEEE
         AP  EEE EEEEEEEEEEEEEEEEEE
         APP T P EEEEEEEEEEEEEEEEEE
          P   E  E E  EEEEEEE EEEEE
              EOO      O EEEE   EEE
           A  O O      OOEA        
                       OO          
               O       OOO         
              OEO      OOO         
              OEA      OOO         
              EEA      OOO         
             AEEA      OOOA        
    PPDDDFFDDDEEDDDFFDDOOO DD  DD  
    DDDDDAADDDEEDDDAADDOOODDDDDDD  
   DDDDDDDDDDDDDDDDDDDDODDDD       
  DDDDDDDDDDDDDDDDDDDDDDDDD        
  DDDDDDDDDDDDDDDDDDDDDDDDD    I   
  DDDDD DDDDDDDDDDDDDDDDDDDDDDDI   
   DDDDDDD DDDDDDDDDDDDDDDDDDDD    
   DDDDD    DDEEDDDDDDDDEEDDDDDDDDE
      D D    DEEDDDDDDDDEEDDDDDDDDE
               EA       EEA      AE
                                  E
                                   
                                   
              E           A      AE
             AE        AEEA      AE
         AAAAAEEAAAAAAAAEEAAAAAAAAE
         AEEEEEEEEEEEEEEEEEEEEEEEEE
         AEEEEEEEEEEEEEEEEEEEEEEEEE
         AEEEEEEEEEEEEEEEEEEEEEEEEE
         AEEEEEEEEEEEEEEEEEEEEEEEEE
         AEEEEEEEEEEEEEEEEEEEEEEEEE
         AEEEEEEEEEEEEEEEEEEEEEEEEE
         AEEEEEEEEEEEEEEEEEEEEEEEEE
         AAAEEEEEEAAAAEEEEEEAAAAEEE
|----Layer 2|
           TDD   T    TDDDDDT  TDDD
                 T    TEEEET    TEE
             E        TEEEET   ETEE
             ED       TEEEET     EE
             EEE      TEEEET E E EE
                      TTTTTT E E TT
                               E   
                                   
                                   
                       O           
                       K K         
                                   
                                   
                                   
                       K K         
      DDD   DD  DDD  DD   DDD  DDD 
      DDD N  D  DDD  D     DD  DDD 
   TTTSPST    TTSPSTTS             
   T  DD   DDDDDDDDDDDDD           
   TD  DDDD  DDDDDDD  DDDDI        
   TD   DD DDDDDDDDDDDDDDDDD       
   TTTS  T  PSTTSPSTTSPSTTSPS      
       DD    D  DDD  D    DDD  DDD 
      D      D  DDDDDD    DDD  DDD 
                                   
                                   
                                   
                                   
                                   
                                   
                                   
                                   
           D E EEEE  BBE       EEE 
              TEETP BBBB  TT   ETE 
          DDTPEEETE  BTLE  L  EETE 
            TEEEEEE  B EEE T   ETEE
           DTEEEEET   TEEAF    ETEE
            TEEEET    TEEEE   E TEE
           TDD DDT    TLDD L   TDDD
|----Layer 3|
                       BBBBM    MBB
                       EEEE      EE
                       EEEE      EE
             E         EEEE      EE
             PEE       EEEE  E    E
                             E     
                                   
                                   
                                   
                                   
                         K         
                                   
                                   
                                   
                       K K         
      DDD       DDD  D    DDD  DDD 
      SPS       SPS  S      S  SPS 
                                   
                                   
               D       D           
               DI                  
                 PP                
      SPS    S  SPS  S    SPS  SPS 
      D      D  DDDDDD    DDD  DDD 
                                   
                                   
                                   
                                   
                                   
                                   
                                   
                                   
                      E            
               E     BB            
              EEE    T L   L       
              EEEE      EE       E 
             EEEEE     EEAF      EE
             EEEE      EEEE      EE
            MBBBB      LBB L    MBB
|----Layer 4|
                                   
                       TTTT      TT
                       TPPT      TP
                       TPPT      TP
               P       TTTT       T
                                   
                                   
                                   
                                   
                                   
                         O         
                                   
                                   
                                   
                       OOO         
      P P  P P  P P  P    P P  P   
      N N       N N         N  NN  
                                   
                                   
                                   
                                   
                                   
      NN     N   PP       NNN  N N 
      P P    P    PDDP P    P  P P 
                                   
                                   
                                   
                                   
                                   
                                   
                                   
                                   
                                   
                                   
               TT      L   L       
              PPT        P       TP
             TPPT       PAF      TP
             TTTT      TTTT      TT
                       L   L       
|----Layer 5|
                                   
                       PPPP      PP
                       PPPP      PP
                       PPPP      PP
                       PPPP      PP
                                   
                                   
                                   
                                   
                                   
                                   
                                   
                                   
                                   
                                   
       CB  BCB  BCB  BCB  BCB  BC  
                                   
                                   
                                   
                                   
                                   
                                   
                                   
      BC   BCB      DBCB    B  BCB 
                                   
                                   
                                   
                                   
                                   
                                   
                                   
                                   
                                   
                                   
               PP      L P L       
              PPP        P         
             PPPP       PAF        
             PPPP      PPPP      PP
                       L   L       
|----Layer 6|
                                   
                       CDDC      CD
                       DPPD      DP
                       DPPD       P
                       CDDC       D
                                   
                       U  U        
                                   
                                   
                                   
                                   
                                   
                                   
                                   
                                   
        D  DDD  DDD  DDD  DDD  DD  
        D  DDD  DDD         D  DD  
        T  TTT  TTT            TTT 
                                   
                                   
                                   
      TT    TT       TTT        T  
      DD   DDD       DDD        DD 
      D      D       DDD       DDD 
                                   
                                   
                                   
                                   
                                   
                                   
                                   
                                   
             U  U                  
                        PBP        
             CDDC      L B L       
             DPPD        B  P      
             DPPD      BBAF B      
             CDDC     P  B  P    CD
                       L B LP      
|----Layer 7|
                                   
                       PPPP        
                       PPPP        
                       PPPP        
                       PPPP        
                       H  H        
                       H  H        
                                   
                                   
                                   
                                   
                                   
                                   
                                   
                                   
                                   
        R  RRR  RRR       R R  RR  
        D  DDD  DDD            DDD 
        D  D DDDDDD   DD     DDDDD 
          DD D    DDDDDDDD       D 
           DDD  DDD  DDD        DD 
      DD    DD       DDD        D  
      RR    RR       RRR        RR 
                                   
                                   
                                   
                                   
                                   
                                   
                                   
                                   
                                   
             H  H                  
             H  H       LLL        
             PPPP      G  OG       
             PPPP      OOOOOL      
             PPPP       OAFOL      
             PPPP      OOOOOL    PP
                       GOOOG       
|----Layer 8|
                                   
                       DCCD        
                       CPPC        
                       CPPC        
                       DCCD        
                                   
                                   
                                   
                                   
                                   
                                   
                                   
                                   
                                   
                                   
                                   
                                   
                                   
                                   
                                   
                                   
                                   
                                   
                                   
                                   
                                   
                                   
                                   
                                   
                                   
                                   
                                   
                                   
                        K K        
             D CD      WK KW       
             CPPC     KK   KK      
             CPPC                  
             DCCD     KK   KK     C
                       WK KW      E
|----Layer 9|
                                   
                       PPPP        
                       PPPP        
                       PPPP        
                        PPP        
                                   
                                   
                                   
                                   
                                   
                                   
                                   
                                   
                                   
                                   
                                   
                                   
                                   
                                   
                                   
                                   
                                   
                                   
                                   
                                   
                                   
                                   
                                   
                                   
                                   
                                   
                                   
                                   
                                   
                       W   W       
              P                    
             PP                    
             PPP                  P
                       W   W       
|----Layer 10|
                                   
                       TTTT        
                       TPPT        
                       TPPT        
                       TTTT        
                                   
                                   
                                   
                                   
                                   
                                   
                                   
                                   
                                   
                                   
                                   
                                   
                                   
                                   
                                   
                                   
                                   
                                   
                                   
                                   
                                   
                                   
                                   
                                   
                                   
                                   
                                   
                                   
                                   
                       W   W       
              P T                  
              PP                   
             TT                    
                       W   W       
|----Layer 11|
                                   
                       EEEE        
                       EEEE        
                        EEE        
                       EEEE        
                                   
                                   
                                   
                                   
                                   
                                   
                                   
                                   
                                   
                                   
                                   
                                   
                                   
                                   
                                   
                                   
                                   
                                   
                                   
                                   
                                   
                                   
                                   
                                   
                                   
                                   
                                   
                                   
                                   
                       OO OO       
                       O   O       
                                   
             EE        O   O       
                       OO OO       
|----Layer 12|
                        TTTT       
                      TEEEET       
                      TEEEET       
                      TEEEET       
                         EET       
                                   
                                   
                                   
                                   
                                   
                                   
                                   
                                   
                                   
                                   
                                   
                                   
                                   
                                   
                                   
                                   
                                   
                                   
                                   
                                   
                                   
                                   
                                   
                                   
                                   
                                   
                                   
                                   
                                   
                       JOOOJ       
                       OO OO       
                       O   O       
                       OO OO       
                       JOOOJ       
|----Layer 13|
                         EEE       
                        EEEE       
                       EEEEE       
                      EEE E        
                        E          
                                   
                                   
                                   
                                   
                                   
                                   
                                   
                                   
                                   
                                   
                                   
                                   
                                   
                                   
                                   
                                   
                                   
                                   
                                   
                                   
                                   
                                   
                                   
                                   
                                   
                                   
                                   
                                   
                                   
                                   
                        OOO        
                        OOO        
                        OOO        
                                   
}}