<noinclude>{{structure info}}</noinclude>
[[File:Ancient City chamber 3.png|thumb|Chamber 3 (Deep Dark)]]

{{layered blueprint|name=Ancient City Chamber 3|default=Layer 1
|C=Cobbled Deepslate
|D=Deepslate Bricks
|T=Deepslate Tiles
|H=Chiseled Deepslate
|E=Chest
|P=Deepslate
|----Layer 1|
 DDDDDDDDD
DDC CCCCCC
 DC     DD
  DDTTTTDD
  DDTTTTDD
    TTTTD 
  DDTTTTDD
 DC PTTTDD
 DC    CCC
DDCCCCCCCC
 DDDDDDDDD
|----Layer 2|
 CCCCCCCDD
TCCC C CCC
 TCDDDDDDD
  DD    DD
        DD
       EDD
        DD
  DD    DD
 DCDDDDDDD
TTC C C CC
 TCCCCCCCC
|----Layer 3|
 C        
CCC     CC
 TC      C
         T
         T
         T
         T
         T
 TC      T
TCC      C
 T        
|----Layer 4|
 C        
CHC       
 CC       
         C
         T
         T
         T
         C
 CC      T
TCC      C
 C        
|----Layer 5|
          
HC        
          
          
         C
         C
         C
         T
         C
H        C
          
|----Layer 6|
          
D         
          
          
          
         C
         C
         C
         C
D         
          
}}