<noinclude>{{structure info}}[[uk:Стародавнє місто/Структура/Плани/Вхідний шлях 5]]</noinclude>
[[File:Ancient City entrance path 5.png|thumb|Entrance Path 5 (Deep Dark)]]

{{layered blueprint|name=Ancient City Entrance Path 5|default=Layer 1
|D=Deepslate Tiles
|E=Deepslate
|P=Polished Deepslate
|B=Deepslate Bricks
|O=Polished Basalt
|S=Smooth Basalt
|T=Deepslate Tile Stairs
|A=Dark Oak Planks
|C=Chiseled Deepslate
|R=Deepslate Brick Slab
|L=Ladder
|N=Candle
|K=Dark Oak Log
|I=Light Blue Carpet
|F=Deepslate Tile Slab
|G=Deepslate Brick Stairs
|----Layer −1|
     DDDDDDD    DDDDDDDDDDDDDDDDDDD
   DDDDDDDDD     DDDDDDDDDDDDDDDDDD
    DDDDDDDD     DDDDDDDDDDDDDDDDDD
   DDD DDDDDD     DDDDDDDDDDDDDDDDD
  DDDDDDDDDDDDDDDDDDDDDDDDDDDDDDDDD
     DDDDDDDDDDDDDDDDDDDDDDDDDDDDDD
     DD DDDDDDDDDDDDDDDDDDDDDDDDDDD
    DDDDDDDDDDDDDDDDDDDDDDDDDDDDDDD
    DDDDDDDDDDDDDDDDDDDDDDDDDDDDDDD
                                   
                                   
                                   
                                   
                                   
                                   
 PDDDDDDDLLDDDDDDDDLLDDDDDDDD  DDD 
PDDDDDDDDOODDDDDDDDOODDDDDDDDDDDDDD
PDDDDDDDDDDDDDDDDDDDDDDDDDDDDDDDDDD
PDDDDDDDDDDDDDDDDDDDDDDDDDDDDDDDDDD
PDDDDDDDDDDDDDDDDDDDDDDDDDDDDDDDDDP
PDDDDDDDDDDDDDDDDDDDDDDDDDDDDDDDDDD
PDDDDDDDDDDDDDDDDDDDDDDDDDDDDDDDDDD
PDDDDDDDDD DDDDDDDDDDDDDDDDDDDDDDDD
 PDDDDDDDDDDDDDDDDDDDDDDDDDDDDDDDDD
                                   
                                   
                                   
                                 O 
                                 E 
                                 EE
DDDDDDDDDDDDDDDDDDDDDDDDDDDDDDDDDDD
DDDDDDDDDDDDDDDDDDDDDDDDDDDDDDDDDDD
 DDDDDDDDDDDDDDDDDDDDDDDDDDDDDDDDDD
DDDDDDDDDDDDDDDDDDDDDDDDDDDDDDDDDDD
DDDD   DD   DDDDDDDDDDDDDDDDDDDDDDD
DDDD   DD   DDDDDDDDDDDDDDDDDDDDDDD
DDDD   DD   DDDDDDDDDDDDDDDDDDDDDDD
  DDDDDDDDDDDDDDDDDDDDDDDDDDDDDDDDD
   DDDDDDDDDDDDDDDDDDDDDDDDDDDDDDDD
|----Layer 0|
    DDDDDDD      DDDDDDDDDDDDDDDDDD
     DD DDD      DDDDDDDDDDDDDDDDDD
     D   D        DDDDDDDDDDDDDDDDD
   DD   DDD       DDDDDDDDDDD DDDDD
        DDDDTDDE  DDDDDDDDDDDDDDDDD
       DDDDDDDDP DDDDDDDDDDDDD DDDD
        DDDDDDDDDDDDD DDDDDDDDDDDDD
       DD  DDDDDDDDD DDDDDDDDD  DDD
           DDDDDDD   DDDDDDD   DD  
                                   
                                   
                                   
                                   
                                   
                                   
  PPDDDDDLLDDDDDDDDLLDD   DDD  DD  
  DDDDDDDOODDDDDDDDOODDDDDDDDDDDD  
 DDDDDDDDDDDDDDDDDDDDDDDDDDDDDDDDDD
 DDDDDDDDDDDDDDDDDDDDDDDDDDDDD DDDD
 DDDDDDDDDDDDDDDDDDDDDDDDDDDDDDDDDD
 DDDDDDDDDDDDDDDDDDDDDDDDDDDDDDDDDD
 DDDDDDDDDDDDDDDDDDDDDDDDDDDDDDDDDD
  DDDDDDDD  DDDDDDDDDDDDDDDDDDDDDDD
  PPDDD D    DDDDDDDDDDDDDDDDDDDDDD
                                   
                                   
                                   
                                   
                                   
                                   
DDDDDDDDDDDDDDDDDDDDDDDDDDDDDDDDDDD
DDDDDDDDDDDDDDDDDDDDDDDDDDDDDDDDDDD
 DDDDDDDDDD   DDDDDDDDDDDDDDDDDDDDD
    DD  D     DDDDDDDDDDDDDDDDDDDDD
D  D          DDDDDDDDDDDDDDDDDDDDD
D             DDDDDDDDDDDDDDDDDDDDD
DDDD          DDDDDDDDDDDDDDDDDDDDD
  DD    D     DDDDDDDDDDDDDDDDDDDDD
        DDDDDDDDDDDDDDDDDDDDDDDDDDD
|----Layer 1|
         OO      EOOOOEEEEEEO OOEEE
         OE      EEEEEEEEEEEE     E
         O        EEEEEEEEEEE     E
         O        EEEEEEEEEE      E
         OP  EE   EEEEEEEEEE    EEE
         OPP T P EEEEEEEEEEEE    EE
          P   E  E E  EEEEEEE E EEE
              EAA      A EEEE   EEE
           O  A A      AAEO        
                       AA          
                                   
                                   
                                   
                                   
             OEEO                  
    PPDDDLLDDDEEDDDLL      DD  DD  
    DDDDDOODDDEEDDDOO      DDDDDD  
    DDDDDDDDDDDDDDDDDDD    D       
      DDDDDDDDDDDDDDDD             
       DDDDDDDDD   DDDDD DD    F   
     D  DDDDDDDD   DDDDDDDDDDDDF   
   DDDDDDD DDDDD   DDDDDDDDDDDD    
   DDDDD    DDEEDDDDDDDDEEDDDDDDDDE
      D D    DEEDDDDDDDDEEDDDDDDDDE
               EO       EEO      OE
              A                   E
             AA                    
             AA                    
             AEA          O      OE
             OEA       OEEO      OE
         OOOOOEEOOOOOOOOEEOOOOOOOOE
         OE EEEEEEEEEEEEEEEEEEEEEEE
         OE   EEEEEEEEEEEEEEEEEEEEE
               EEEEEEEEEEEEEEEEEEEE
               EEEEEEEEEEEEEEEEEEEE
                 EEEEEEEEEEEEEEEEEE
                 EEEEEEEEEEEEEEEEEE
                 EEEEEEEEEEEEEEEEEE
          O EEEEEEOOOOEEEEEEOOOOEEE
|----Layer 2|
          K           TDDDDD    DDD
                      TEEEE       E
          E           TEEEET      E
          E           TEEE        E
          KD          TEEE        E
                      TTTT       TT
                                   
                                   
                                   
                       A           
                                   
                                   
                                   
                                   
                                   
      DDD                   D  DDD 
      DDD N  D  DDD         D  DDD 
       PST    T                    
           DDDD                    
          D  DD                    
        D  DDDD      DDDDDDD       
    TTS  T  PST     T PSTTSPS      
       DD    D  DDD  D    DDD  DDD 
      D      D  DDDDDD    DDD  DDD 
                                   
                                   
              I                    
             II                    
                                   
                                   
                                   
                                   
               EEEE  BBE       EEE 
                 TP BBBE  TT   ETE 
                 TE  BTBE     EETE 
                 EE  BBBBE     ETEE
                 ET   TB EE    ETEE
                 T    T B     E TEE
               DDT    T        TDDD
|----Layer 3|
                       BBBB     GBB
                       EEEE       E
          E            EEE        E
          E            EEE        E
          K            EEE        E
                                   
                                   
                                   
                                   
                                   
                                   
                                   
                                   
                                   
                                   
      DDD                      DDD 
      S S        PS            SPS 
                                   
                                   
                                   
                                   
                                   
      SPS    S   P   S    SPS  SPS 
      D      D  DDDDDD    DDD  DDD 
                                   
                                   
                                   
                                   
                                   
                                   
                                   
                                   
                      E            
                     BB            
                     T  E          
                 E               E 
                 E     B E       EE
                        B        EE
               BB               GBB
|----Layer 4|
                                   
                       TTTT       T
                       TPP        P
                       TPP        P
                       TTT        T
                                   
                                   
                                   
                                   
                                   
                                   
                                   
                                   
                                   
                                   
      P P         P            P   
      N N                      NN  
                                   
                                   
                                   
                                   
                                   
      NN                  NN   N N 
      P P    P    PDDP P    P  P P 
                                   
                                   
                                   
                                   
                                   
                                   
                                   
                                   
                                   
                                   
                                   
                                 TP
                T                TP
               TT                TT
                                   
|----Layer 5|
                                   
                                 PP
                                  P
                                 PP
                       PPP        P
                                   
                                   
                                   
                                   
                                   
                                   
                                   
                                   
                                   
                                   
       CB       B B            BC  
                                   
                                   
                                   
                                   
                                   
                                   
                                   
      BC   BCB      DBCB    B  BCB 
                                   
                                   
                                   
                                   
                                   
                                   
                                   
                                   
                                   
                                   
                                   
                P                  
               PP                  
              PPP                PP
                                   
|----Layer 6|
                                   
                                 CD
                                 DP
                                  P
                                  D
                                   
                                   
                                   
                                   
                                   
                                   
                                   
                                   
                                   
                                   
        D       DDD            DD  
        D       DDD            DD  
        T       TTT            TTT 
                                   
                                   
                                   
      TT    TT       TTT        T  
      DD   DDD       DDD        DD 
      D      D       DDD       DDD 
                                   
                                   
                                   
                                   
                                   
                                   
                                   
                                   
                                   
                                   
                                   
             D PD                  
             DPP                   
             CDDC                CD
                                   
|----Layer 7|
                                   
                                   
                                   
                                   
                                   
                                   
                                   
                                   
                                   
                                   
                                   
                                   
                                   
                                   
                                   
                                   
                RRR            RR  
                DDD            DDD 
        D  D DDDDDD   DD     DDDDD 
          DD D    DDDDDDDD       D 
           DDD  DDD  DDD        DD 
      DD    DD       DDD        D  
      RR     R       RRR        RR 
                                   
                                   
                                   
                                   
                                   
                                   
                                   
                                   
                                   
                                   
                                   
              PPP                  
             PP                    
             PP                    
             PPP                 PP
                                   
|----Layer 8|
                                   
                                   
                                   
                                   
                                   
                                   
                                   
                                   
                                   
                                   
                                   
                                   
                                   
                                   
                                   
                                   
                                   
                                   
                                   
                                   
                                   
                                   
                                   
                                   
                                   
                                   
                                   
                                   
                                   
                                   
                                   
                                   
                                   
                                   
                D                  
               P                   
             C                     
             DC                   C
                                  E
|----Layer 9|
                                   
                                   
                                   
                                   
                                   
                                   
                                   
                                   
                                   
                                   
                                   
                                   
                                   
                                   
                                   
                                   
                                   
                                   
                                   
                                   
                                   
                                   
                                   
                                   
                                   
                                   
                                   
                                   
                                   
                                   
                                   
                                   
                                   
                                   
                                   
                                   
             P                     
             PP                   P
                                   
|----Layer 10|
                                   
                                   
                                   
                                   
                                   
                                   
                                   
                                   
                                   
                                   
                                   
                                   
                                   
                                   
                                   
                                   
                                   
                                   
                                   
                                   
                                   
                                   
                                   
                                   
                                   
                                   
                                   
                                   
                                   
                                   
                                   
                                   
                                   
                                   
                                   
                                   
                                   
             TT                    
                                   
|----Layer 11|
                                   
                                   
                                   
                                   
                                   
                                   
                                   
                                   
                                   
                                   
                                   
                                   
                                   
                                   
                                   
                                   
                                   
                                   
                                   
                                   
                                   
                                   
                                   
                                   
                                   
                                   
                                   
                                   
                                   
                                   
                                   
                                   
                                   
                                   
                                   
                                   
                                   
             EE                    
                                   
}}