<noinclude>{{structure info}}</noinclude>
[[File:Ancient City tall ruin 1.png|thumb|Tall Ruin 1 (Deep Dark)]]

{{layered blueprint|name=Ancient City Tall Ruin 1|default=Layer 1
|D=Deepslate Tiles
|B=Deepslate Bricks
|T=Deepslate Tile Slab
|P=Polished Basalt
|W=Polished Deepslate Wall
|L=Ladder
|C=Chiseled Deepslate
|S=Deepslate Tile Stairs
|O=Soul Lantern
|E=Deepslate Tile Wall
|H=Chest
|----Layer 1|
                 
                 
                 
     SSSSSSS     
    SSDBBBBSS    
   SSPBBBBBPSS   
   SDBBDDDBBDS   
   SBBDDDDDBBS   
   SBBDDDDDBBS   
   SBBDDDDDBBS   
   SDBBDDDBBDS   
   SSPBBBBBPSS   
    SSDBBBDSS    
     SSSSSSS     
                 
                 
                 
|----Layer 2–7|
                 
                 
                 
                 
                 
     PL   LP     
     LD   DL     
                 
                 
                 
     LD   BL     
     PL   LP     
                 
                 
                 
                 
                 
|----Layer 8|
                 
                 
                 
      BBBBB      
     BBBBBBB     
    BPLBBBLPB    
   BBLBBBBBLBB   
   BBBBBBBBBBB   
   BBBBBBBBBBB   
   BBBBBBBBBBB   
   BBLBBBBBLBB   
    BPLBBBLPB    
     BBBBBBB     
      BBBBB      
                 
                 
                 
|----Layer 9|
                 
                 
                 
      W   W      
                 
     PL   LP     
   W L     L W   
        L        
       LPL       
        L        
   W L     L W   
     PL   LP     
                 
      W   W      
                 
                 
                 
|----Layer 10|
                 
                 
                 
      W   W      
                 
     C     C     
   W         W   
        L        
       LPL       
        L        
   W         W   
     C     C     
                 
      W   W      
                 
                 
                 
|----Layer 11–13|
                 
                 
                 
      W   W      
                 
                 
   W         W   
        L        
       LPL       
        L        
   W         W   
                 
                 
      W   W      
                 
                 
                 
|----Layer 14|
                 
                 
                 
      D   D      
     TDTTTDT     
    TDDTTTDDT    
   DDDDDDDDDDD   
    TTDTLTDTT    
    TTDLPLDTT    
    TTDTLTDTT    
   DDDDDDDDDDD   
    TDDTTTDDT    
     TDTTTDT     
      D   D      
                 
                 
                 
|----Layer 15|
                 
                 
      D   D      
     TDTT DT     
    T       T    
   T         T   
  DD         DD  
   T    L    T   
   T   LPL   T   
   T    L    T   
  DD         DD  
   T         T   
    T       T    
     TDTTTDT     
      D   D      
                 
                 
|----Layer 16|
                 
      D   D      
     TD   DT     
    T       T    
   T         T   
  T           T  
 DD           DD 
  T           T  
  T     C     T  
  T           T  
 DD           DD 
  T           T  
   T         T   
    T       T    
     TDTTTDT     
      D   D      
                 
|----Layer 17|
                 
      D   D      
      D   D      
                 
                 
                 
 DD   O   O   DD 
                 
        H        
                 
 DD   O   O   DD 
                 
                 
                 
      D   D      
      D   D      
                 
|----Layer 18|
                 
                 
      D   D      
      D   D      
                 
                 
  DD  E   E  DD  
                 
                 
                 
  DD  E   E  DD  
                 
                 
      D   D      
      D   D      
                 
                 
|----Layer 19|
                 
                 
                 
      D   D      
      D   D      
      D   D      
   DDDDDDDDDDD   
      D   D      
      D   D      
      D   D      
   DDDDDDDDDDD   
      D   D      
      D   D      
      D   D      
                 
                 
                 
}}