<noinclude>{{structure info}}</noinclude>
[[File:Ancient City small statue.png|thumb|Small Statue (Deep Dark)]]

{{layered blueprint|name=Ancient City Small Statue |default=Layer 1
|P=Polished Deepslate
|D=Deepslate
|C=Cobbled Deepslate
|B=Deepslate Brick Slab
|W=White Candle
|T=Deepslate Tiles
|S=Deepslate Tile Slab
|O=Polished Deepslate Wall
|E=Deepslate Brick Stairs
|----Layer 1|
PPP    PPP
PDDDDDDDDP
 DCCCCCDD 
 PCCCCCDP 
 PCCCCCDP 
 DCCCCCDD 
PDDDDDDDDP
PPP    PPP
|----Layer 2|
PP      PP
         P
  PPPPP   
  DCDDD   
  DCDDD   
  PPPPP   
         P
PP      PP
|----Layer 3|
P        P
          
   TW     
   SW     
   SW     
   TW     
          
P        P
|----Layer 4|
          
   O      
   E      
          
          
   E      
   O      
          
|----Layer 5|
          
          
   B      
   B      
   B      
   B      
          
          
}}