<noinclude>{{structure info}}[[uk:Стародавнє місто/Структура/Плани/Вхідний шлях 1]]</noinclude>
[[File:Ancient City entrance path 1.png|thumb|Entrance Path 1 (Deep Dark)]]

{{layered blueprint|name=Ancient City Entrance Path 1|default=Layer 1
|D=Deepslate
|T=Deepslate Tiles
|P=Polished Deepslate
|C=Chiseled Deepslate
|B=Polished Basalt
|S=Smooth Basalt
|E=Deepslate Bricks
|I=Deepslate Tile Stairs
|R=Deepslate Brick Slab
|A=Candle
|L=Soul Lantern
|W=Polished Deepslate Wall
|K=Deepslate Brick Stairs
|O=Polished Deepslate Slab
|F=Cobbled Deepslate Slab
|----Layer 1|
         BBBDDDDDDBBBBDDDDDDBBBBDDD
         BDDDDDDDDDDDDDDDDDDDDDDDDD
         BDDDDDDDDDDDDDDDDDDDDDDDDD
         BDDDDDDDDDDDDDDDDDDDDDDDDD
         BDDDDDDDDDDDDDDDDDDDDDDDDD
         BDDDDDDDDDDDDDDDDDDDDDDDDD
         BDDDDDDDDDDDDDDDDDDDDDDDDD
         BDDDDDDDDDDDDDDDDDDDDDDDDD
         BBBBBDDBBBBBBBBDDBBBBBBBBD
             BDDB      BDDB      BD
             BDDB      BDDB      BD
             BDDB      BDDB      BD
             BDDB      BDDB      BD
             BDDB      BDDB      BD
             BDDB      BDDB      BD
  PPPPTTTTTTTTDDTTTTTTTTDDTTTTTTTTD
 PTTTTTTTTTTTTDDTTTTTTTTDDTTTTTTTTD
PTTTTTTTTTTTTTTTTTTTTTTTTTTTTTTTTTT
PTTTTTTTTTTTTTTTTTTTTTTTTTTTTTTTTTT
PTTTTTTTTTTTTTTTTTTTTTTTTTTTTTTTTTP
PTTTTTTTTTTTTTTTTTTTTTTTTTTTTTTTTTT
PTTTTTTTTTTTTTTTTTTTTTTTTTTTTTTTTTT
 PTTTTTTTTTTTTDDTTTTTTTTDDTTTTTTTTD
  PPPPTTTTTTTTDDTTTTTTTTDDTTTTTTTTD
             BDDB      BDDB      BD
             BDDB      BDDB      BD
             BDDB      BDDB      BD
             BDDB      BDDB      BD
             BDDB      BDDB      BD
             BDDB      BDDB      BD
         BBBBBDDBBBBBBBBDDBBBBBBBBD
         BDDDDDDDDDDDDDDDDDDDDDDDDD
         BDDDDDDDDDDDDDDDDDDDDDDDDD
         BDDDDDDDDDDDDDDDDDDDDDDDDD
         BDDDDDDDDDDDDDDDDDDDDDDDDD
         BDDDDDDDDDDDDDDDDDDDDDDDDD
         BDDDDDDDDDDDDDDDDDDDDDDDDD
         BDDDDDDDDDDDDDDDDDDDDDDDDD
         BBBDDDDDDBBBBDDDDDDBBBBDDD
|----Layer 2|
           ITTTTTI    ITTTTTI  ITTT
            IDDDDI    IDDDDI    IDD
            IDDDDI    IDDDDI    IDD
            IDDDDI    IDDDDI     DD
            IDDDDI    IDDDDI     DD
            IIIIII    IIIIII     II
                                   
                                   
                                   
                                   
                                   
                                   
                                   
                                   
                                   
      TTT  TTT  TTT  TTT  TTT  TTT 
      TTT  TTT  TTT  TTT  TTT  TTT 
   IIISPSIISPSIISPSIISPSIISPSIISPSI
   ITTTTTTTTTTTTTTTTTTTTTTTTTTTTTTT
   ITTTTTTTTTTTTTTTTTTTTTTTTTTTTTTT
   ITTTTTTTTTTTTTTTTTTTTTTTTTTTTTTT
   IIISPSIISPSIISPSIISPSIISPSIISPSI
      TTT  TTT  TTT  TTT  TTT  TTT 
      TTT  TTT  TTT  TTT  TTT  TTT 
                                   
                                   
                                   
                                   
                                   
                                   
                                   
                                   
                                   
              IIII        II    I  
            IDDDDI       DDI    ID 
            IDDDDI     DDDDI    IDD
            IDDDDI    IDDDDI    IDD
            IDDDDI    IDDDDI    IDD
           ITTTTTI    ITTTTTI  ITTT
|----Layer 3|
            KEEEE      EEEEK    KEE
             DDDD      DDDD      DD
             DDDD      DDDD      DD
             DDDD      DDDD      DD
             DDDD      DDDD       D
                                   
                                   
                                   
                                   
                                   
                                   
                                   
                                   
                                   
                                   
      TTT  TTT  TTT  TTT  TTT  TTT 
      SPS  SPS  SPS  SPS  SPS  SPS 
                                   
                TT  O  FF          
          I             F          
              I        O           
                      O            
      SPS  SPS  SPS  SPS  SPS  SPS 
      TTT  TTT  TTT  TTT  TTT  TTT 
                                   
                                   
                                   
                                   
                                   
                                   
                                   
                                   
                                   
                                   
              DDD        DD        
              DDD        DD      D 
             DDDD      DDDD      DD
             DDDD      DDDD      DD
            KEEEE      EEEEK    KEE
|----Layer 4|
                                   
             IIII      IIII      II
             IPPI      IPPI      IP
             IPPI      IPPI      IP
             IIII      IIII       I
                                   
                                   
                                   
                                   
                                   
                                   
                                   
                                   
                                   
                                   
      P P  P P  P P  P P  P P  P   
      A A  AAA  A A    A   AA  AA  
                                   
                                   
                                   
                                   
                                   
      AA    AA   AA   A   AAA  A A 
      P P  P P  P P  P P  P P  P P 
                                   
                                   
                                   
                                   
                                   
                                   
                                   
                                   
                                   
                                   
               II        II        
              PPI        PI      IP
             IPPI       PPI      IP
             IIII      IIII      II
                                   
|----Layer 5|
                                   
             PPPP      PPPP      PP
             PPPP      PPPP      PP
             PPPP      PPPP      PP
             PPPP      PPPP      PP
                                   
                                   
                                   
                                   
                                   
                                   
                                   
                                   
                                   
                                   
       CE  ECE  ECE  ECE  ECE  EC  
                                   
                                   
                                   
                                   
                                   
                                   
                                   
      EC   ECE  ECE  ECE  ECE  ECE 
                                   
                                   
                                   
                                   
                                   
                                   
                                   
                                   
                                   
                                   
               PP        PP        
              PPP        PP      PP
             PPPP       PPP      PP
             PPPP      PPPP      PP
                                   
|----Layer 6|
                                   
              TTC      CTTC      CT
             TPPT      TPPT      TP
             TPPT      TPPT      TP
             CTTC      CTTC      CT
                                   
                L      L  L      L 
                                   
                                   
                                   
                                   
                                   
                                   
                                   
                                   
       TT  TTT  TTT  TTT  TTT  TT  
       TT  TTT  TTT       TTT  TT  
       II  III  III       III  III 
                                   
                                   
                                   
      II    II  III  III    I   I  
      TT   TTT  TTT  TTT    T   TT 
      T      T  TTT  TTT  TTT  TTT 
                                   
                                   
                                   
                                   
                                   
                                   
                                   
                                   
             L  L         L        
                                   
             CTTC        TC        
             TPPT        PT      TP
             TPPT       PPT      TP
             CTTC      CTTC      CT
                                   
|----Layer 7|
                                   
              PPP      PPPP      PP
              PPP      PPPP      PP
             PPPP      PPPP      PP
             PPPP      PPPP      PP
                W      W  W      W 
                W      W  W      W 
                                   
                                   
                                   
                                   
                                   
                                   
                                   
                                   
                                   
       RR  RRR  RRR       RRR  RR  
       TT  TTT TTTT       TTT  TTT 
      TTT TT T   TT   TTTTTTTTTTTT 
      T TTTT T    T  TTTTTTTT T  T 
      TT   TTTTTTTTTTTTT   TTTTTTT 
      TT    TT  TTT  TTT        T  
      RR    RR  RRR  RRR        RR 
                                   
                                   
                                   
                                   
                                   
                                   
                                   
                                   
                                   
             W  W         W        
             W  W         W        
             PPPP       PPP       P
             PPPP        PP       P
             PPPP      PPPP      PP
             PPPP      PPPP      PP
                                   
|----Layer 8|
                                   
                T      TCCT      TC
               PC      CPPC      CP
               PC      CPPC       P
               CT      TCCT      TC
                                   
                                   
                                   
                                   
                                   
                                   
                                   
                                   
                                   
                                   
                                   
                                   
                                   
                                   
                                   
                                   
                                   
                                   
                                   
                                   
                                   
                                   
                                   
                                   
                                   
                                   
                                   
                                   
                                   
             TCCT      TCCT        
             CPPC      CPPC      CP
             CPPC      CPPC      CP
             TCCT      TCCT      TC
                                   
|----Layer 9|
                                   
                P      PPPP      PP
               PP      PPPP       P
               PP      PPPP        
               PP       PPP      PP
                                   
                                   
                                   
                                   
                                   
                                   
                                   
                                   
                                   
                                   
                                   
                                   
                                   
                                   
                                   
                                   
                                   
                                   
                                   
                                   
                                   
                                   
                                   
                                   
                                   
                                   
                                   
                                   
                                   
             PPPP      PPPP      PP
             PPPP      PPPP      PP
             PPPP      PPPP      PP
             PPPP      PPPP      PP
                                   
|----Layer 10|
                                   
               TC      CTTC      CT
               PT      TPPT      TP
               PT       PPT       P
               TC       TTC      CT
                                   
                                   
                                   
                                   
                                   
                                   
                                   
                                   
                                   
                                   
                                   
                                   
                                   
                                   
                                   
                                   
                                   
                                   
                                   
                                   
                                   
                                   
                                   
                                   
                                   
                                   
                                   
                                   
                                   
             CTT       CTTC      CT
             TPPT      TPPT      TP
             TPPT      TPPT      TP
             CTTC      CTTC      CT
                                   
|----Layer 11|
                                   
             PPPP      PPPP      PP
             PPPP      PPPP      PP
             PPPP      PPPP      PP
              PPP       PPP      PP
                                   
                                   
                                   
                                   
                                   
                                   
                                   
                                   
                                   
                                   
                                   
                                   
                                   
                                   
                                   
                                   
                                   
                                   
                                   
                                   
                                   
                                   
                                   
                                   
                                   
                                   
                                   
                                   
                                   
             PP        PPPP      PP
             PP        PPPP      PP
             PP        PPPP      PP
             PPP       PPPP      PP
                                   
|----Layer 12|
                                   
             IIII      IIII      II
             IPPI      IPPI      IP
             IPPI      IPPI      IP
             IIII      IIII      II
                                   
                                   
                                   
                                   
                                   
                                   
                                   
                                   
                                   
                                   
                                   
                                   
                                   
                                   
                                   
                                   
                                   
                                   
                                   
                                   
                                   
                                   
                                   
                                   
                                   
                                   
                                   
                                   
                                   
             II        IIII       I
             IP I      IPPI       P
             IPP       IPPI      IP
             II        IIII      II
                                   
|----Layer 13|
                                   
             DDDD      DDDD      DD
             DDDD      DDDD      DD
             DDDD      DDDD      DD
             DDDD      DDDD      DD
                                   
                                   
                                   
                                   
                                   
                                   
                                   
                                   
                                   
                                   
                                   
                                   
                                   
                                   
                                   
                                   
                                   
                                   
                                   
                                   
                                   
                                   
                                   
                                   
                                   
                                   
                                   
                                   
                                   
             DD        DDDD       D
             DDD       DDDD       D
             DDD       DDDD      DD
             DD        DDDD      DD
                                   
|----Layer 14|
            II  II      IIII    III
            ID  DI    IDDDDI    IDD
            IDDDDI    IDDDDI    IDD
            IDDDDI    IDDDDI    IDD
            IDDDDI    IDDDDI     DD
            IIIIII    IIII       II
                                   
                                   
                                   
                                   
                                   
                                   
                                   
                                   
                                   
                                   
                                   
                                   
                                   
                                   
                                   
                                   
                                   
                                   
                                   
                                   
                                   
                                   
                                   
                                   
                                   
                                   
                                   
            IIII      IIII        I
            IDDD      IDDDD       D
            IDD       IDDDD     IDD
            IDDD      IDDDDI    IDD
            IDD       IDDDDI    IDD
            III       IIIIII    III
|----Layer 15|
            D   DD       DDD    DDD
            DD  DD      DDDD    DDD
            DD DDD     DDDDD    DDD
            DDDDDD    DDDDDD    DDD
            DDDDDD    DDDDDD     DD
            DDDDDD    DDDDD      DD
                                   
                                   
                                   
                                   
                                   
                                   
                                   
                                   
                                   
                                   
                                   
                                   
                                   
                                   
                                   
                                   
                                   
                                   
                                   
                                   
                                   
                                   
                                   
                                   
                                   
                                   
                                   
            DDDD      DDDD        D
            DDDD      DDDD       DD
            DDD       DDDDD     DDD
            DDD       DDDDDD    DDD
            DD        DDDDDD    DDD
            DD        DDDDDD    DDD
}}