<noinclude>{{structure info}}</noinclude>
[[File:Ancient_City_barracks.png|thumb|Barracks (Deep Dark)]]

{{layered blueprint|name=Ancient City Barracks|default=Layer 1
|D=Deepslate
|T=Deepslate Tiles
|P=Polished Deepslate
|C=Cobbled Deepslate
|B=Deepslate Brick Stairs
|H=Chiseled Deepslate
|W=White Candle
|S=Cobbled Deepslate Stairs
|E=Deepslate Bricks
|R=Deepslate Brick Slab
|I=Deepslate Tile Stairs
|L=Deepslate Tile Slab
|O=Soul Sand
|F=Soul Fire
|A=Chest
|G=Polished Deepslate Wall
|K=Skeleton Skull
|----Layer 1|
 DDDDDDDCCDDDDDDDDBD 
 DDDDDDDDDDDDDDDDDDD 
 DDDDDDDDDDDDDDDDDDD 
 DDDDDDDDDDDDDDDDDDD 
 DDDDDDDDDDDDDDDDDDD 
 DDDDDDDDDDDDDDDDDDD 
 DDDDDDDDDDDDDDDDDDD 
 DDDDDDDDDDDDDDDDDDD 
 DDDDDDDDDDDDDDDDDDD 
 DDDDDDDDDDDDDDDDDDD 
   SDDDDDDDDDDDDDDDD 
   SDDDDDDDDDDDDDDDD 
 DDDDDDDDDDDDDDDDDDD 
 DDDDDDDDDDDDDDDDDDD 
 DDDDDDDDDDDDDDDDDDD 
 DDDDDDDDDDDDDDDDDDD 
 DDDDDDDDDDDDDDDDDDD 
|----Layer 2|
 DDDDDDC  CDDDDDDD D 
 DDDDDDDDCDDDDDDDDBD 
 DDDDDDDDDDDDDDDDDDD 
 DDDDDDDDDDDDDDDDDDD 
 DDDDDDDDDDDDDDDDDDD 
 DDDDDDDDDDDDDDDDDDD 
 DDDDDDDDDDDDDDDDDDD 
 DDDDDDDDDDDDDDDDDDD 
 DDDDDDDDDDDDDDDDDDD 
 PDDDDDDDDDDDDDDDDDD 
    SDDDDDDDDDDDDDDD 
    SDDDDDDDDDDDDDDD 
 PDDDDDDDDDDDDDDDDDD 
 DDDDDDDDDDDDDDDDDDD 
 DDDDDDDDDDDDDDDDDDD 
 DDDDDDDDDDDDDDDDDDD 
 DDDDDDDDDDDDDDDDDDD 
|----Layer 3|
 DPDPDP    PDPDPDP D 
 PDDDDDD  DDDDDDDD P 
 DDDDDDDCDDDDDDDDDBD 
 PDDDDDDDDDDDDDDDDDP 
 DDDDDDDDDDDDDDDDDDD 
 PDDDDDDDDDDDDDDDDDP 
 PDDDDDDDDDDDDDDDDDD 
 DDDDDDDDDDDDDDDDDDP 
 PDDDDDDDDDDDDDDDDDD 
 PDDDDDDDDDDDDDDDDDP 
     SDDDDDDDDDDDDDD 
     SDDDDDDDDDDDDDP 
 PDDDDDDDDDDDDDDDDDD 
 PDDDDDDDDDDDDDDDDDP 
 DDDDDDDDDDDDDDDDDDD 
 PDDDDDDDDDDDDDDDDDP 
 DPDPDPDPDPDPDPDPDPD 
|----Layer 4|
 PPPPPC    PPPPPPP D 
 PDDDDD    CDDDDDD D 
 PDDDDDC  CDCDDDB  D 
 PDDDCDCD DDCDDDB  D 
 PDDDDDDDCDCDDDDDD D 
 PDDDDDDDDDDDDDDB  D 
 PDDDDDDDDDDDDDDB  D 
 PDDDDDDDDDDDDDDDD D 
 PDDDDDDDDDDDDDDB  D 
 PDDDDDDDCCCDDDDDD D 
 PS   SDDCDCDDDDB  D 
 PS   SDDDCDCDDDB  D 
 PDDDDDDDDDDDCDDDD D 
 PDDDDDDDDDDDDDDB  D 
 PDDDDDDDDDDDDDDB  D 
 PDDDDDDDDDDDDDDDD D 
 PPPPPPPPPPPPPPPPPDD 
|----Layer 5|
 TTTTTC     TTTTTTTTT
 T   C        ITTT TT
 T                 HT
 TT                HT
 TT            BTT HT
                   TT
 P     TLLT        TT
 P             BTT HT
                   HT
 P             BTT HT
 P                 TT
                   TT
 TT            BTT HT
 TT   WW  W        HT
 T   WRBBBRW       HT
 T  A BEEEB A ITTT TT
 TTTTDDDDDDDTTTTTTTTT
|----Layer 6|
 DDDDC      DDDDTTTTT
 D             ITT TT
                   WT
 TT                WT
 TT             WT WT
                   TT
      GB  BG       TT
                WT WT
                   WT
                WT WT
                   TT
                   TT
 TT             WT KT
 TT                WT
                   WT
 D     WHW     ITT TT
 DD  BDTHTDB DDDDTTTT
|----Layer 7|
 DDDD        DDDDTTTT
                ITTTT
                 BTTT
 T               BTTT
 T               TTTT
                 BTET
       RRRR      BTOT
                 TTTT
                 RTTT
                 TTTT
                 BTOT
                 BTTT
 T               TTTT
 T               BTTT
                 BTTT
                ITTTT
 D    BDDDB   DDDTTTT
|----Layer 8|
               DD    
                     
                     
 T                   
 T                   
                    B
                   FT
                  WBT
                   ET
                   BT
                   FT
                    B
 T                   
 T                   
                     
                     
       BCB     DD    
|----Layer 9|
                     
                     
                     
PPP                  
PPP                  
                     
                    B
                   WT
                   HT
                   WT
                    B
                     
PPP                  
PPP                  
                     
                     
                     
|----Layer 10|
                     
                     
                     
                     
                     
                     
                     
                    B
                    E
                    B
                     
                     
                     
                     
                     
                     
                     
}}