<noinclude>{{structure info}}</noinclude>
[[File:Ancient City large ruin 1.png|thumb|Large Ruin 1 (Deep Dark)]]

{{layered blueprint|name=Ancient City Large Ruin 1|default=Layer 1
|C=Cobbled Deepslate
|D=Deepslate Bricks
|----Layer 1|
CCC CC C         
C                
C                
C                
                 
                 
C                
C                
C               C
C               C
                D
                 
                 
                 
                D
                C
        CCCC C CC
|----Layer 2|
 C   C           
C                
                 
C                
                 
                 
                 
C                
C                
                 
                D
                 
                 
                 
                C
                 
          C  C  C
|----Layer 3|
 C               
                 
                 
                 
                 
                 
                 
                 
                 
                 
                 
                 
                 
                 
                 
                 
                C             
}}