{{Wip}}
[[File:Ancient_City_top.png|thumb|Top wall]]

{{layered blueprint|name=Bottom Wall 1|default=Layer 1
|J=Chiseled Deepslate
|F=Dark Oak Fence
|P=Dark Oak Planks
|S=Deepslate
|K=Deepslate Brick Stairs
|D=Deepslate Bricks
|C=Cracked Deepslate Bricks
|H=Deepslate Tile Slab
|I=Deepslate Tile Stairs
|Y=Deepslate Tile Wall
|T=Deepslate Tiles
|N=Cracked Deepslate Tiles
|W=Gray Wool
|R=Polished Deepslate
|A=Polished Deepslate Stairs
|L=Redstone Lamp
|E=Sculk Sensor
|----Layer 1|
                ADDDDDA                  
SSSSSSSSSSSSSSSSSSDDDSSSSSSSSSSSSSSSSSSSS
DDDDDDDDDDDDDDDDDDDDDDDDDDDDDDDDDDDDDDDDD
DDDDDDDDDDDDDDDDDDDDDSSDDDDDDDDDDDDDDDDDD
DDDDDDDDSDDDDDDDDDDDDDDDDDDDDDDDDDDDDDDDD
DDDDDDDDDSSDDDDDDDDDDDDDDDDDSSSSDDDDDDDDD
DDDDDDDDDDDDDDDDDDDDDDDDDDDDDDSDDDDDDDDDD
DDDDDDDDDDDDDDDDDDDDDDDDDDDDDDSSSDDDDDDDD
DDDDDDDDDDDDDSSDDDDDDDDDDDDDDDDDDDDDDDDDD
DDDDDDDDDDDDSDSDDDDDDDDDDDDDDDDDDDDDDDDDD
DDDDDDDDDDDDDDDDDDDDDDDDDDDDDDDDDDDDDDDDD
SSSSSSSSSSSSSSSSSSSSSSSSSSSSSSSSSSSSSSSSS
SSSSSSSSSSSSSSSSSSSSSSSSSSSSSSSSSSSSSSSSS
SSSSSSSSSSSSSSSSSSSSSSSSSSSSSSSSSSSSSSSSS
SSSSSSSSSSSSSSSSSSSSSSSSSSSSSSSSSSSSSSSSS
			
|----Layer 2|
                 AWWWA                   
SSSDDDDSSSSDDDDSSSWWWDDDDSSSDDDDSSSDDDDSS
WWWWWWWWWWWWWWWWWW   WWWWWWWWWWWWWWWWWWWW
DDWDDWDDWDDWDDWDDW   WDWDDWDDWDDWDDWDDWDD
II II II II II II    II II II II II II II
                                         
                                         
                                         
                                         
                                         
I IWWI IWWI IWWI IWWI IWWI IWWI IWWI IWWI
SSSSSSSSSSSSSSSSSSSSSSSSSSSSSSSSSSSSSSSSS
WWWWWWWWWWWWWWWWWWWWWWWWWWWWWWWWWWWWWWWWW
SSSSSSSSSSSSSSSSSSSSSSSSSSSSSSSSSSSSSSSSS

|----Layer 3|
                                         
TTTDJJDTTTTDJJDTTT   JJDTTTTDJDTTTTDJJDTT
WWWWWWWWWWWWWWWWWW   WWWWWWWWWWWWWWWWWWWW
JJWJJWJJWJJWJJWJJW   WJWJJWJJWJJWJJWJJWJJ
                                         
                                         
                                         
                                         
                                         
                                         
   WW   WW   WW   WW   WW   WW   WW   WW 
DDDDDDDDDDDDDDDDDDDDDDDDDDDDDDDDDDDDDDDDD
WWWWWWWWWWWWWWWWWWWWWWWWWWWWWWWWWWWWWWWWW
SSSSSSSSSSSSSSSSSSSSSSSSSSSSSSSSSSSSSSSSS

|----Layer 4|
                                         
IIIDJJDIIIIDJJDIII   JDIIIIDJJDIIIIDJJDII
WWWWWWWWWWWWWWWWWW   WWWWWWWWWWWWWWWWWWWW
IIWIIWIIWIIWIIWIIW   WIWIIWIIWIIWIIWIIWII
                                         
                                         
                                         
                                         
                                         
                                         
IJIWWIJIWWIJIWWIJIWWIJIWWIJIWWIJIWWIJIWWI
DDDDDDDDDDDDDDDDDDDDDDDDDDDDDDDDDDDDDDDDD
WWWWWWWWWWWWWWWWWWWWWWWWWWWWWWWWWWWWWWWWW
DDDDDDDDDDDDDDDDDDDDDDDDDDDDDDDDDDDDDDDDD

|----Layer 5|
IIIDDDDIIIIDDDDIII   DDIIIIDDDDIIIIDDDDII
WWWWWWWWWWWWWWWWWW   WWWWWWWWWWWWWWWWWWWW
WWWWWWWWWWWWWWWWWW   WWWWWWWWWWWWWWWWWWWW
IIWIIWIIWIIWIIWIIWI IWIWIIWIIWIIWIIWIIWII
                                         
                                         
                                         
                                         
                                         
                                         
IIIWWIIIWWIIIWWIIIWWIIIWWIIIWWIIIWWIIIWWI
 DDDDDDDDDDDDDDDDDDDDDDDDDDDDDDDDDDDDDDDD
WWWWWWWWWWWWWWWWWWWWWWWWWWWWWWWWWWWWWWWWW
DDDDDDDDDDDDDDDDDDDDDDDDDDDDDDDDDDDDDDDDD

|----Layer 6|
JJJYJJYJJJJYJJYJJJJYJJYJJJJYJJYJJJJYJJYJJ
                   WWW                   
                                         
JJI  IJJI  IJJI  IJJI  IJJI  IJJI  IJJI  
                                         
                                         
                                         
                                         
                                         
                                         
IIIWWIIIWWIIIWWIIIWWIIIWWIIIWWIIIWWIIIWWI
                                         
 WWWWW WWWWWWWWWWWWWWWWWWWWWWWWWWWWWWWWWWA
                                          

|----Layer 7|
III II IIII II IIII II IIII II IIII II II
                                         
                                         
II    II    II    II    II    II    II   
                                         
                                         
                                         
                                         
                                         
                                         
 I  W I    I  W I W  I  W I W  I  W I W  
                                         
W W W W W W   W W W W W W W W W W W   W W


|----Layer 8|
III II IIII II IIII II IIII II IIII II II
                                         
                                         
II    II    II    II    II    II    II   
                                         
                                         
                                         
                                         
                                         
                                         
                                         
                                         
                                         
										 
}}