<noinclude>{{structure info}}</noinclude>
[[File:Ancient City chamber 1.png|thumb|Chamber 1 (Deep Dark)]]

{{layered blueprint|name=Ancient City Chamber 1|default=Layer 1
|C=Cobbled Deepslate
|D=Deepslate Bricks
|T=Deepslate Tiles
|H=Chiseled Deepslate
|E=Chest
|P=Deepslate
|----Layer 1|
 DDD               
 DDDDDDDDDDDDD DDDD
   DCCCCCCCCCCCDDCC
   DCCCDDDDDDDCCCCC
   DCCCDDDDDCCCCCCC
C DDC CDDDDDCCCDDCC
   TT CDDDDDPCCDDDC
   TT CDDDDDDDDD C 
   TT CDDDDDDDDDDDC
    T CCDDCDDDCCDCC
C  DC CCCCDD DDD CC
   DCCCCCCDD     CC
   DCCCCCCCCCCCCCCC
 DDDDDDDDDDDDDDDDDD
 DDD               
|----Layer 2|
 DDD               
 DDDCCCCCCCCCC CCC 
   CCCCCCCCCCCC  CC
   CCCC           C
   CCCC           C
C DDHC           CC
   TTT            C
   TTT          CCC
   TT             C
    TT           CC
C   HC      D   DCC
   DCCC     DCCCCCC
   TCCCCCCCCCCCCCCC
 DDDCCDDCCC CCCCCCC
 DDD               
|----Layer 3|
  DD               
  DDCCCCCCCCCCCCCCC
    CCCCCCCCCCCCCCC
   CCCC          CC
   CCCC          CC
H  DHD           CC
    TT            C
    TT          CCC
                  C
    TT           CC
H    T      DTTTDCC
   CCCC     DTTTDCC
   CCCCCCCCCCCCCCCC
  DDCCCCCCCCCC  CCC
  DD               
|----Layer 4|
 DDD               
 DDD PCCCCCCCCCCCCC
    CCCCCCCCCCC CCC
   CCCC          CC
    CCC          CC
D  HHD           CC
    TT            C
    TT          HCC
                  C
    TT           CC
D    T           CC
   CCCC       E  CC
     CCCCCCCCCCCCCC
 D D CCCCCCCCCCCCC 
 DDD               
|----Layer 5|
 DDD               
 DDD       CCC CCC 
            CCCCCCC
     CC          CC
    CCC          CC
    TT           CC
     T           C 
                DC 
                   
                   
     T           C 
                 C 
          HTDCC CC 
 D D               
 DDD               
|----Layer 6|
                   
  H             CC 
            CCC CCC
                 CC
     CC            
    TT             
                   
                   
                   
                   
    DD             
                   
           CCCC    
 DDD               
 D D               
|----Layer 7|
                   
  D                
                   
                   
                   
    TT             
     T             
                   
                   
     T             
    DD             
                   
                   
 DDD               
 DDD               
|----Layer 8|
                   
                   
                   
                   
                   
    TT             
                   
                   
                   
                   
    DD             
                   
                   
 DDD               
  DD               
|----Layer 9|
                   
                   
                   
                   
                   
    TT             
     T             
                   
                   
     T             
    DD             
                   
                   
                   
                   
|----Layer 10|
                   
                   
                   
                   
                   
     T             
    TT             
    TT             
    TT             
    TT             
                   
                   
                   
                   
                   
}}