<noinclude>{{structure info}}[[uk:Стародавнє місто/Структура/Плани/Центр міста 1]]</noinclude>
[[File:Ancient City city center 1 2.png|thumb|City Center 1 (Deep Dark)]]

{{layered blueprint|name=Ancient City City Center 1|default=Layer 1
|D=Deepslate Bricks
|T=Deepslate Tiles
|E=Deepslate
|C=Cobbled Deepslate
|G=Gray Carpet
|W=Gray Wool
|P=Glass Pane
|S=Soul Sand
|F=Soul Fire
|R=Reinforced Deepslate
|B=Grass Block
|L=Deepslate Brick Slab
|I=Deepslate Tile Stairs
|A=Candle
|M=Redstone Lamp
|O=Redstone Dust
|H=Chiseled Deepslate
|K=Cracked Deepslate Bricks
|J=Deepslate Brick Wall
|U=Soul Lantern
|N=Dirt
|Q=Cracked Deepslate Tiles
|V=Redstone Repeater
|X=Redstone Comparator
|Y=Block of Redstone
|Z=Sticky Piston
|a=Piston Head
|b=Polished Deepslate Wall
|c=Glass
|d=Target
|e=Redstone Wall Torch
|f=Lever
|g=Sculk Sensor
|h=Lectern
|----Layer 1|
EEEEEEEEEEEEEEEEEE
EEEEEEEEEEEEEEEEEE
EEEEEEEEEEEEEEEEEE
EEEEEEEEEEEEEEEEEE
EEEEEEEEEEEEEEEEEE
EEEEEEEEEEEEEEEEEE
EEEEEEEEEEEEEEEEEE
EEEEEEEEEEEEEEEEEE
EEEEEEEEEEEEEEEEEE
EEEEEEEEEEEEEEEEEE
EEEEEEEEEEEEEEEEEE
EEEEEEEEEEEEEEEEEE
EEEEEEEEEEEEEEEEEE
EEEEEEEEEEEEEEEEEE
EEEEEEEEEEEEEEEEEE
EEEEEEEEEEEEEEEEEE
EEEEEEEEEEEEEEEEEE
EEEEEEEEEEEEEEEEEE
EEEEEEEEEEEEEEEEEE
EEEEEEEEEEEEEEEEEE
EEEEEEEEEEEEEEEEEE
EEEEEEEEEEEEEEEEEE
EEEEEEEEEEEEEEEEEE
EEEEEEEEEEEEEEEEEE
EEEEEEEEEEEEEEEEEE
EEEEEEEEEEEEEEEEEE
EEEEEEEEEEEEEEEEEE
EEEEEEEEEEEEEEEEEE
EEEEEEEEEEEEEEEEEE
EEEEEEEEEEEEEEEEEE
EEEEEEEEEEEEEEEEEE
EEEEEEEEEEEEEEEEEE
EEEEEEEEEEEEEEEEEE
EEEEEEEEEEEEEEEEEE
EEEEEEEEEEEEEEEEEE
EEEEEEEEEEEEEEEEEE
EEEEEEEEEEEEEEEEEE
EEEEEEEEEEEEEEEEEE
EEEEEEEEEEEEEEEEEE
EEEEEEEEEEEEEEEEEE
EEEEEEEEEEEEEEEEEE
|----Layer 2|
DEEEEEEEEEEEEEEEED
EEEEEEEEEEEEEEEEEE
EEEEEEEEEEEEEEEEEE
EEEEEEEEEEEEEEEEEE
EEEEEEEEEEEEEEEEEE
EEEEEEEEEEEEEEEEEE
EEEEEEEEEEEEEEEEEE
EEEEEEEEEEEEEEEEEE
EEEEEEEEEEEEEEEEEE
EEEEEEEEEEEEEEEEEE
EEEEEEEEEEEEEEEEEE
EEEEEEEEEEEEEEEEEE
EEEEEEEEEEEEEEEEEE
EEEEEEEEEEEEEEEEEE
EEEEEEEEEEEEEEEEEE
EEEEEEEEEEEEEEEEEE
EEEEEEEEEEEEEEEEEE
EEEEEEEEEEEEEEEEEE
EEEEEEEEEEEEEEEEEE
EEEEEEEEEEEEEEEEEE
EEEEEEEEEEEEEEEEEE
EEEEEEEEEEEEEEEEEE
EEEEEEEEEEEEEEEEEE
EEEEEEEEEEEEEEEEEE
EEEEEEEEEEEEEEEEEE
EEEEEEEEEEEEEEEEEE
EEEEEEEEEEEEEEEEEE
EEEEEEEEEEEEEEEEEE
EEEEEEEEEEEEEEEEEE
EEEEEEEEEEEEEEEEEE
EEEEEEEEEEEEEEEEEE
EEEEEEEEEEEEEEEEEE
EEEEEEEEEEEEEEEEEE
EEEEEEEEEEEEEEEEEE
EEEEEEEEEEEEEEEEEE
EEEEEEEEEEEEEEEEEE
EEEEEEEEEEEEEEEEEE
EEEEEEEEEEEEEEEEEE
EEEEEEEEEEEEEEEEEE
EEEEEEEEEEEEEEEEEE
EEEEEEEEEEEEEEEEEE
|----Layer 3|
DDDDDDDDDDDDDDDDDD
DTWWWWWWWWTTTTTTTD
DTWWWWWWWWTTTTTTTD
DTWWWWWWWWTTTTTTTD
DTWWWWWWWWTTTTTTTD
DTWWWWWWWWTTTTTTTD
DTWWWWWWWWTTTTTTTD
DTWWWWWWWWTTTTTTTD
DTWWWWWWWWTTTTTTTD
DTWWWWWWWWTTTTTTTD
DTWWWWWWWWTTTTTTTD
DTWWWWWWWWTTTTTTTD
DTWWWWWWWWTTTTTTTD
DTWWWWWWWWTTTTTTTD
DTWWWWWWWWTTTTTTTD
DTWWWWWWWWTTTTTTTD
DTWWWWWWWWTTTTTTTD
DDWWWWWWWWTTTTTTTD
DTTTTTTTTTTTTTTTTD
ITTTTTTTTTTTTTTTTD
DTTTTTTTTTTTTTTTTD
ITTTTTTTTTTTTTTTTD
DTTTTTTTTTTTTTTTTD
DTWWTTTTTTTBNBBBBD
DTTTTTTTTTTBBBNBBD
DTTTTTTTTTTBBBBBBD
DTTTTTTTTTTBBBBBBD
DTTTTTTTTTTBBBNBBD
DTTTTTTTTTTBBBBBBD
DTGTGTGTTTTBBBNBBD
DTGTGTGTTTTBBBBBBD
DTGTGTGTTTTTTTTTTD
DTGTGTGTTTTTTTTTTD
DTGGGGGTTTTTTTTTTD
DTIIIIITTTTTTTTTTD
DTTTTTTTTTTTTTTTTD
DTTTTTTTTTTTTTTTTD
DTIIIIITTTTTTTTTTD
DTGGGGGTTTTTTTTTTD
DTGGGGGTTTTTTTTTTD
DDDDDDDDDDDDDDDDDD
|----Layer 4|
DDDDDDDDDDDDDDDDDD
DT        TGGT b D
DT        TGGT   D
DT        TGGT   D
DT    MMM TGGT b D
IT  MMM M TGGT   D
IT  M   M TGGT   D
DT  M   MITGGTIIID
DT  M  OOTIGGITTTD
IT  M  XXTIGGITTTD
IT  MM XXITGGITTTD
IT     XX TGGITTTD
DT  OOeMO TGGTIIID
DT  O  V  TGGT   D
IT  V  X  TGGT h D
ITTTWTWWW TGGT X D
ITWWWTWgW TGGT M D
DZVOGTWWW TGGT   D
DaGGGTTTTTTGGTTTTD
 DGGGGGGGGGGGGGGGD
IDGGGGGGGGGGGGGGGD
 DGGGGGGGGGGGGGGGD
DaGGGTTTGGTTTTTTTD
DZVWGTTTGGT M    D
ITWWTTGGGGT O M  D
ITTTTTTTGGT O O  D
ITTTTTGGGGT c O  D
DTTGGGGGGGT V W  D
DTTTTTTTGGT O V  D
IT     TGG  OOY  D
IT     TGGT      D
DT     TGGTTTT TTD
DT J J TGGGGGGGGGD
IT     TGGGGGGGGGD
IT     TGGTTTGGTTD
DTGGGGGGGGTGGGGGGD
DTGGGGGGGGTGGTGTGD
IT     TGGTGGTGTGD
IT     TGGTGGTGTGD
DT     TGGTTTTGTGD
DDDDDDDDDDDDDDDDDD
|----Layer 5|
DDDDDDDDDDDDDDDDDD
DT        T  P b D
DT        P  P   D
DT        P  P   D
DT    OOO P  P d D
IT  OOO O P  P   D
IT  O   O P  P   D
DT  O   O T  Q   D
DT  O         GGGD
 T  O         GGGD
 T  OO    T   GGGD
 T        P   GGGD
DT     f  P  Q   D
DT        P  P   D
 T        P  P   D
 TPPOTWPW P      D
 TVOOTW W P  P   D
DZ  WTWPW P  P   D
Da   TPPPPT  TP TD
 D               D
ID               D
 D               D
Da   TTT  TP PPPTD
DZ OWT J  P      D
 TVO T    P      D
 TTTTT J  P      D
 T   J    P      D
DT        P      D
DTTTT  T  P      D
 T T   P         D
 T T      P      D
DT T   P  TPPT TPD
DT T J P         D
IT     P         D
IT     T  TPP  PPD
DT        P      D
DT        P  J J D
IT     T  P      D
IT     P  P      D
DT     P  P      D
DDDDDDDDDDDDDDDDDD
|----Layer 6|
DDDDDDDDDDDDDDDDDD
DDDDD     T  P M D
DDDDD     P  P   D
DDDDD     P  P Y D
DDDDD     P  P Z D
DDDDD     P  P   D
DDDDD     P  P   D
DDDDD     TU Q   D
DDDDD            D
IDDDD            D
IDDDD     T      D
IDDDD     P      D
DDDDD     P  Q   D
DT        P  P   D
IT        P  P   D
ITPPPTWWW P  P   D
IT   TW W P  P   D
DT  OTWWW P  P   D
DT  WTPPPPTU T PTD
IT  W            D
HH  W            D
IT  W     U      D
DT  WTTT UTPP PPTD
DT  OTTT  P      D
IT   T    P      D
ITTTTTTT  P      D
ITTTTT    P      D
DTT       P      D
DDDDD  T         D
IDDDD  P         D
IDDDD  P  P      D
DDDDD  P  TPPT TPD
DDDDDJ P         D
DDDDD  P  U      D
DDDDD  T UTPP  PPD
DDDDD     P      D
DDDDD     P  T T D
DDDDD  T  P  T T D
DDDDD  P  P  T T D
DDDDD  P  P TT T D
DDDDDDDDDDDDDDDDDD
|----Layer 7|
    DDDDDDDDDDDDDD
    D     T  P   D
    D     P  P   D
    D     P  P   D
    D     P  P   D
LLLLD     P  P   D
DDDDD     P  P   D
DDDDD     Tb T   D
DDDDD        T   D
DDDDD        T   D
DDDDDIIIIIT  T   D
DDDDDTTTTTP  T   D
DDDDDTTTTTP  T   D
DTTTTTTTTTP  T   D
DTTTTTTTTTP  T   D
DTTTTTWWW P  T   D
DT   TWDW P  T   D
DT   TWWWTP  T   D
DT  OTTDTTTb TTTTD
DT  O            D
DT  O            D
DT  O     b      D
DT  OTTT bTTTTTTTD
DT   T    T      D
DT   T    T      D
DTTTTT    T      D
DT        T      D
DT        T      D
DDDDDTTT  T      D
DDDDDTTT  T      D
DDDDDTTT  T      D
DDDDDTTT  TTTTTTTD
DDDDDTTT         D
DDDDDTTT  b      D
DDDDDTTT bTTTTTTTD
LLLLDTTT  T      D
    DTTT  T      D
    DTTT  T      D
    DTTT  T      D
    DTTT  T      D
    DDDDDDDDDDDDDD
|----Layer 8|
    DDDDDDDDDDDDDD
    DDDDDDDDDDDDDD
    DDDDDDDD DDDDD
    DDDDDDDDDDDDDD
    DDDDDDDDDDDDDD
    DDDDDDDDDDDDDD
    DDDDDDDDDDDDDD
    DDDDDDDDDDDDDD
LLLLDDDDDDDDDDDDDD
DDDDDDDDDDDDDDDDDD
DDDDDDDDDDDDDDDDDD
DDDDDDDDDDDDDDDDDD
DDDDDDDDDDDDDDDDDD
DDDDDDDDDDDDDDDDDD
DDDDDDDDDDDDDDDDDD
DDDDDDWWWDDDDDDDDD
DDDDDDWDWDDDDDDDDD
 DDDDDWWWDDDDDDDDD
 DDDDDDDDDDDDDDDDD
 DDDDDDDDDDDDDDDDD
 DDDDDDDDDDDDDDDDD
 DDDDDDDDDDDDDDDDD
 DDDDDDDDDDDDDDDDD
 DDDDDDDDDDDDDDDDD
DDDDDDDDDDDDDDDDDD
DDDDDDDDDDDDDDDDDD
DDDDDDDDDDDDDDDDDD
DDDDDDDDDDDDDDDDDD
DDDDDDDDDDDDDDDDDD
DDDDDDDDDDDDDDDDDD
DDDDDDDDDDDDDDDDDD
DDDDDDDDDDDDDDDDDD
LLLLDDDDDDDDDDDDDD
    DDDDDDDDDDDDDD
    DDDDDDDDDDDDDD
    DDDDDDDDDDDDDD
    DDDDDDDDDDDDDD
    DDDDDDDDDDDDDD
    DDDDDDDDDDDDDD
    DDDDDDDDDDDDDD
    DDDDDDDDDDDDDD
|----Layer 9|
    DDDDDDDDDDDDDD
    DDDDDDDDDDDDDD
    DDDDDDDDDDDDDD
    DDDDDDDDDDDDDD
    DDDDDDDDDDDDDD
    DDDDDDDDDDDDDD
    DDDDDDDDDDDDDD
    DDDDDDDDDDDDDD
    DDDDDDDDDDDDDD
    DDDDDDDDDDDDDD
    DDDDDDDDDDDDDD
LLLLDDDDDDDDDDDDDD
KDDDDDDDDDDDDDDDDD
KKDDDDDDDDDDDDDDDD
DDDDDDDD DDDDDDDDD
DDDDDDWWWDDDDDDDDD
DDDDDDWHWDDDDDDDDD
   DDDWWWDDDDDDDDD
   DDDDDDDDDDDDDDD
     DDDDDDDDDDDDD
     DDDDDDDDDDDDD
     DDDDDDDDDDDDD
   DDDDDDDDDDDDDDD
   DDDDDDDDDDDDDDD
DDDDDDDDDDDDDDDDDD
DKDDDDDDDDDDDDDDDD
KDDDDDDDDDDDDDDDDD
KDDDDDDDDDDDDDDDDD
DDDDDDDDDDDDDDDDDD
LLLLDDDDDDDDDDDDDD
    DDDDDDDDDDDDDD
    DDDDDDDDDDDDDD
    DDDDDDDDDDDDDD
    DDDDDDDDDDDDDD
    DDDDDDDDDDDDDD
    DDDDDDDDDDDDDD
    DDDDDDDDDDDDDD
    DDDDDDDDDDDDDD
    DDDDDDDDDDDDDD
    DDDDDDDDDDDDDD
    DDDDDDDDDDDDDD
|----Layer 10|
                  
                  
                  
          TTTTTTTT
         TTTTTTTTT
         TTTTTTTTT
         TTTTTTTTT
         TTTTTTTTT
        ATTTTTTTTT
       AATTTTTTTTT
      AAATTTTTTTTT
      ALDTTTSSSTTT
    LLLDDTTTSSSTTT
   LDDDDDTTTSSSTTT
   TDDDDDTTTSSSTTT
  ATCDDDDDDDSSSTTT
  AAADDHDDDDSSSDDD
   AADDDDDDDSSSDDD
    A DDDDDDSSSDDD
      DDDDDDSSSDDD
      DDDDDDSSSDDD
      DDDDDDSSSDDD
      DDDDDDSSSDDD
    ADDDDDDDSSSDDD
   AADDDDDDDSSSDDD
  ATCDDDDDDDSSSDDD
  ATCCCCCDDDSSSDDD
    AAAAADDDSSSDDD
      A ATTTSSSTTT
      AAATTTSSSTTT
      AAATTTTTTTTT
       AATTTTTTTTT
        ATTTTDTTTT
         TTDDDDDDD
         TTTTTDDDD
         TTTTTTTTD
         TTTTTTTTT
         TTTTTTTTT
         TTTTTTTTT
                 E
                 E
|----Layer 11|
                  
                  
                  
                  
          TTTTTT  
          T     T 
          T     T 
          T     T 
          T     T 
          T     T 
                  
        A   FFF   
       AA   FFF   
     A AA   FFF   
    HDDDD   FFF   
    HCCDC   FFF   
            FFF   
            FFF   
            FFF   
            FFF   
            FFF   
            FFF   
            FFF   
            FFF   
            FFF   
    HDDCC   FFF   
    HDDCD   FFF   
            FFF   
            FFF   
            FFF   
                  
          TTTTTTT 
          T     T 
          T     T 
          T     T 
          T     T 
          T     T 
          TTTTTTT 
                  
                  
                  
|----Layer 12|
                  
                  
                  
                  
                  
            DDDD  
           CDDDD  
           CDDDD  
           CDDDD  
           CDDDD  
           CDDDD  
           CCCCC  
           CCCCC  
           CCCCC  
    AA     CCCCC  
    AA     CCCCC  
           CCCCC  
           CCCCC  
           DDDDD  
           DDDDD  
            DDDD  
            DDDD  
           DDDD   
           DDDDD  
           DDDDD  
    AAA    DDDDD  
    AA     DDDDD  
           DDDDD  
           DDDDD  
           DDDDD  
            DDDD  
            DDDD  
            DDDD  
           DDDDT  
           DDDDD  
           DDDDD  
            DDDD  
                  
                  
                  
                  
|----Layer 13|
                  
                  
                  
                  
                  
           CDDDD  
           CDDDD  
           CDDDD  
           CDDDD  
           DDDDD  
           DDDDD  
           DDDDD  
           DDDDD  
           CDDDD  
           CCCDD  
           CCCCC  
           CCCCC  
           CCCCC  
           DDDDD  
           DDDDD  
           DDDDD  
           DDDDD  
           DDDDD  
           DDDDD  
           DDDDD  
           DDDDD  
           DDDDD  
           DDDDD  
           DDDDD  
           DDDDD  
           DDDDD  
            DDDD  
            DTTT  
           DTTTT  
           DDDTT  
           DDDDD  
           DDDDD  
                  
                  
                  
                  
|----Layer 14|
                  
                  
                  
                  
                  
            DDDD  
           CDDDD  
           DDDDD  
           DDCCC  
           CCCCD  
           DDDDD  
           DDDDD  
           DDDDD  
           DDDDD  
           DDDDD  
            DDDD  
            DDDD  
           DDDDD  
           DDDDD  
           DDDDD  
           DDDDD  
           DDDDD  
           DDDDD  
           DDDDD  
           DDDDD  
           DDDDD  
           DDDDD  
           DDDDD  
           DDDDD  
           DDDDD  
           DDDDD  
            TTTD  
           TTTTT  
           TTTTT  
           TTTTT  
           DDDDD  
           DDDDD  
                  
                  
                  
                  
|----Layer 15|
                  
                  
                  
                  
                  
                  
           DDDDD  
           DDDDC  
           DCCCC  
           CCCCC  
           CCCCD  
           DDDDD  
           DDDDD  
           DDDDD  
           DDDDD  
           DDDDD  
           DDDDD  
           DDDDD  
           DDDDD  
           DDDDD  
           DDDDD  
           DDDDD  
           DDDDD  
           DDDDD  
           DDDDD  
           DDDDD  
           DDDDD  
           DDDDD  
           DDDDD  
           DDDDD  
           DDDDD  
           DDDD   
           TTDDD  
           TTTTT  
            TTTT  
            DDDD  
              DD  
                  
                  
                  
                  
|----Layer 16|
                  
                  
                  
                  
                  
             DDD  
           DDDDD  
           DDCCC  
            CCC   
           CCCC   
           TCCCT  
           TCCTT  
           TTTTT  
           TTTTT  
           TTTTT  
           TTTTT  
           TTTTT  
           TTTTT  
           TTTTT  
           TTTTT  
           TTTTT  
           TTTTT  
           TTTTT  
           TTTTT  
           TTTTT  
           TTTTT  
           TTTTT  
           TTTTT  
           TTTTT  
           TTTTT  
           TTTTT  
           TTTTT  
            TTTD  
           TDDDD  
           DDDDD  
           DDDDD  
           DDDDD  
                  
                  
                  
                  
|----Layer 17|
                  
                  
                  
                  
                  
           DDD    
           DDDDD  
           DDDCC  
            CCC   
           TCCCT  
           TCCCT  
            CTC   
           TCCCT  
           TCCTT  
            TTT   
             TT   
           TTTTT  
           TTTTT  
            TTT   
            TTT   
           TTTTT  
           TTTTT  
            TTT   
            TTT   
           TTTTT  
           TTTTT  
            TTT   
            TTT   
           TTTTT  
           TTTTT  
            TTT   
           TTTTT  
           TTTTT  
           DDDDD  
           DDDDD  
           DDDDD  
            DDDD  
                  
                  
                  
                  
|----Layer 18|
                  
                  
                  
                  
                  
           DDDDD  
           DDDDD  
           DDDDD  
           DTTTD  
           TTTTT  
           T R T  
             R    
             R    
             R    
             R    
             R    
             R    
             R    
             R    
             R    
             R    
             R    
             R    
             R    
             R    
             R    
             R    
             R    
             R    
             R    
             R    
           T R T  
           TTTTT  
           DDDDD  
           DDDDD  
           DDDDD  
            DDDD  
                  
                  
                  
                  
|----Layer 19|
                  
                  
                  
                  
                  
           CCDDD  
           DDDDD  
           DDDDD  
           DTTTD  
           TTTTT  
             R    
                  
                  
                  
                  
                  
                  
                  
                  
                  
                  
                  
                  
                  
                  
                  
                  
                  
                  
                  
                  
             R    
           TTTTT  
           DDDDD  
           DDDDD  
           DDDDD  
           DDDDD  
                  
                  
                  
                  
|----Layer 20|
                  
                  
                  
                  
                  
           CCCCC  
           CCCDD  
           DDDDD  
           TTTTT  
           TTTTT  
             R    
                  
                  
                  
                  
                  
                  
                  
                  
                  
                  
                  
                  
                  
                  
                  
                  
                  
                  
                  
                  
             R    
           TTTTT  
           TDDDT  
           DDDDD  
           DDDDD  
           CCCDD  
                  
                  
                  
                  
|----Layer 21|
                  
             CC   
            CCC   
             CC   
            CCC   
           CCCCC  
           CCCDD  
           DDDDD  
           TTTTT  
            TTT   
             R    
                  
                  
                  
                  
                  
                  
                  
                  
                  
                  
                  
                  
                  
                  
                  
                  
                  
                  
                  
                  
             R    
            TTT   
           TDDDT  
           DDDDD  
           CCDDD  
           CCCCC  
            CCC   
            CCC   
            CCC   
                  
|----Layer 22|
                  
            CCC   
            CCC   
            CCC   
            CCC   
           CCCCC  
            CCDD  
           DDDDD  
           TTTTT  
            TTT   
             R    
                  
                  
                  
                  
                  
                  
                  
                  
                  
                  
                  
                  
                  
                  
                  
                  
                  
                  
                  
                  
             R    
            TTT   
           TDDDT  
           DDDDD  
           CCDDD  
           CCCCC  
            CCC   
            CCC   
            CCC   
            CCC   
|----Layer 23|
                  
             CC   
            CCC   
                  
                  
           CCCCC  
           CCDDD  
           DDDDD  
           TTTTT  
           TTTTT  
             R    
                  
                  
                  
                  
                  
                  
                  
                  
                  
                  
                  
                  
                  
                  
                  
                  
                  
                  
                  
                  
             R    
           TTTTT  
           TDDDT  
           DDDDD  
           CCDDD  
            CCCC  
                  
                  
            CCC   
            CCC   
|----Layer 24|
                  
            CCC   
             CC   
                  
                  
           CCCCC  
           CCCDD  
           DDDDD  
           DTTTD  
           TTTTT  
             R    
                  
                  
                  
                  
                  
                  
                  
                  
                  
                  
                  
                  
                  
                  
                  
                  
                  
                  
                  
                  
             R    
           TTTTT  
           DDDDD  
           DDDDD  
           CDDDD  
           CCCCC  
                  
                  
            CCC   
            CCC   
|----Layer 25|
                  
            CCC   
            CCC   
            CCC   
            CCC   
           CCCCC  
           CCCCD  
           DDDDD  
           DTTTD  
           DTTTT  
           T R T  
             R    
             R    
             R    
             R    
             R    
             R    
             R    
             R    
             R    
             R    
             R    
             R    
             R    
             R    
             R    
             R    
             R    
             R    
             R    
             R    
           T R T  
           DTTTD  
           DDDDD  
           DDDDD  
           DDDDD  
           CCCCD  
            CCC   
            CCC   
            CCC   
            CCC   
|----Layer 26|
                  
             CC   
            CCC   
            CCC   
             CC   
            CCCC  
           CCCCD  
           DDDDD  
           DTTTD  
           DDTTD  
           DTTTT  
           TTTTT  
           TTTTT  
           TTTTT  
            TTT   
            TTT   
           TTTTT  
           TTTTT  
            TTT   
            TTT   
           TTTTT  
           TTTTT  
            TTT   
            TTTT  
           TTTTT  
           TTTTT  
            TTT   
            TTT   
           TTTTT  
           TTTTT  
           TTTTT  
           DTTT   
           DTTT   
           DDDDD  
           DDDDD  
           DDDDD  
           CCCDD  
            CCC   
            CCC   
            CCC   
             CC   
|----Layer 27|
                  
                  
                  
                  
                  
           CCCCC  
           CCCDD  
           DDDDD  
           D TTD  
           DTTTD  
           DTTTD  
           DTTTD  
           DTTTD  
           DTTTD  
           DTTTD  
           DTTTD  
           DTTTD  
           DTTTD  
           DTTTD  
           DTTTD  
           DTTTD  
           DTTTD  
           DTTTD  
           DTTTD  
           DTTTD  
           DTTTD  
           DTTTD  
           DTTTD  
           DTTTD  
           DTTTD  
           DTTTD  
           DTTT   
           DTTT   
            DDDD  
           DDDDD  
           DDDDD  
           DDDDD  
                  
                  
                  
                  
|----Layer 28|
                  
                  
                  
                  
                  
           CCCCC  
           CDDDD  
           DDDDD  
           DDDDD  
           DDDDD  
           DDDDD  
           DDDDD  
           DDDDD  
           DDDDD  
           DDDDD  
           DDDDD  
           DDDDD  
           DDDDD  
           DDDDD  
           DDDDD  
           DDDDD  
           DDDDT  
           TTTTT  
           TTTTT  
           TTTTT  
           DDDDD  
           DDDDD  
           DDDDD  
           DDDDD  
           DDDDD  
           DDDDD  
           DDDDD  
            DDDD  
            DDDD  
           TTTTT  
           DDDDD  
           DDDDD  
                  
                  
                  
                  
|----Layer 29|
                  
                  
                  
                  
                  
           CCCCC  
           DDDDD  
            DDDD  
           DDDDD  
           DDDDD  
           DDDDD  
           DDDDD  
           DDDDD  
           DDDDD  
           DDDDD  
           DDDDD  
           DDDDD  
           DDDDD  
           DDDDD  
           DDDDD  
           DDDDD  
           DDDDD  
           DDDDD  
           DDDDT  
           TTTDD  
           DDDDD  
           DDDDD  
           DDDDD  
           DDDDD  
           TTTTD  
           DDDDD  
           DDDDD  
            DDDD  
            TTTT  
           TTTTT  
             TTT  
              DT  
                  
                  
                  
                  
|----Layer 30|
                  
                  
                  
                  
                  
            DDDD  
           DDDDD  
           DDDDD  
            DDDD  
           DDDDD  
           DDDDD  
           DDDDD  
           DDDDD  
           DDDDD  
           DDDDD  
           DDDDD  
           DDDDD  
           DDDDD  
           DDDDD  
           DDDDD  
           DDDDD  
           DDDDD  
           DDDDD  
           DDDDD  
           DDDDD  
           TTTTT  
           TTTTT  
           TTTTT  
           TTTTT  
           TTTTT  
           TTTTT  
           TTTTT  
           TTTTT  
           TTTTT  
           TTTTT  
                  
                  
                  
                  
                  
                  
|----Layer 31|
                  
                  
                  
                  
                  
             DDD  
           DDDDD  
           DDDDD  
           DDDDD  
           DDDDD  
           DDDDD  
           DDDDD  
           DDDDD  
           DDDD   
                  
             D    
               D  
           DDDDD  
             DD   
              D   
           DDDDD  
           DDDDD  
           DDDDD  
           DDDTT  
           TTTTT  
           TTTTT  
           TTTTT  
            TTTT  
            TTTT  
           TTTTT  
           TTTTT  
           TT TT  
           TTTTT  
           TTTTT  
            TTT   
                  
                  
                  
                  
                  
                  
}}