{{Wip}}
[[File:Ancient_City_top_right_corner.png|thumb|Top right corner]]

{{layered blueprint|name=Bottom Wall 1|default=Layer 1
|J=Chiseled Deepslate
|F=Dark Oak Fence
|P=Dark Oak Planks
|S=Deepslate
|K=Deepslate Brick Stairs
|D=Deepslate Bricks
|C=Cracked Deepslate Bricks
|H=Deepslate Tile Slab
|I=Deepslate Tile Stairs
|Y=Deepslate Tile Wall
|T=Deepslate Tiles
|N=Cracked Deepslate Tiles
|W=Gray Wool
|R=Polished Deepslate
|A=Polished Deepslate Stairs
|L=Redstone Lamp
|E=Sculk Sensor

|----Layer 1|
SDDDDDDDDDDDDD
SDDCCDDDDDDDDD
SDDDDDDCCDDDDC
SDDDDDDDDDDDDD
SDDDDDDDDDDDDD
SDDCCCCDDDDDDD
SDDDDDDDDDDDDD
SDDDDDDDCCDDDD
SDDDDDCDDDDDDD
SDDDDDDDCDDDDD
SCDDDDCDCDDDDD
SDDDDDDDDCDDDD
SSSSSSSSSSSSSS

|----Layer 2|
 SWW       SWS
 SWDK      SWW
 DWDK     WSSS
 CWW      WWK 
 DWDK         
 DWCK         
 SWW          
 SWCK         
 SWDK         
  WDKKK KK KK 
 S DDCDWDCWDCW
 DWWW  WW WWWW
 DDDDCD CCDDSS
									
|----Layer 3|
 TWW       DWS
 NWJ       DWW
 DWJ      WDDD
 JWW      WW  
 JWJ          
 DWJ          
 T W          
 TWJ          
 TWJ          
 TWJ          
 TWJJJJWJJWJJW
 DWWWWWWWWWWWW
 JDJJJJTDJJDTT

|----Layer 4|
 IWW      J WD
 IWI      ICW 
 DWI      WDDD
 JWW      WWIJ
 JWI          
 DWI          
 IWW          
 IWI          
 IWI          
 IWI          
 IWIIIIWIIWIIW
 DWWWWW WWWWWW
 JWIIIIIDJJCII

|----Layer 5|
IWWW      IDDD
IWWI      ICDD
DWWI      WCDC
DWWW      WWII
DWWI          
DWWI          
IWWW          
IWWI          
IWWI          
IWWI          
IWWIIIIWII IIW
DWWW WWWWWWWWW
CWWWWWWWWWWWWW
DCCIIIII DDDII

|----Layer 6|
J  I      I W 
J  J      I WW
Y  J         W   
J  Y      WWII
J  J          
Y  J          
J  I          
J  J          
Y  J          
J  I          
J  JIJJIJJIJJI
Y             
J             
JJYJJYJJYJJYJJ

|----Layer 7|
I         I W 
I           WW
              
          W  I
   I          
   I          
I             
I             
              
   I          
    I   II    
              
I             
II    II    II

|----Layer 8|
              
              
			  
              
              
              
I             
I             
              
              
        II    
              
I             
 I    II    II

}}