<noinclude>{{structure info}}</noinclude>
[[File:Ancient City ice box 1.png|thumb|Ice Box 1 (Deep Dark)]]

{{layered blueprint|name=Ancient City Ice Box 1 |default=Layer 1
|C=Cobbled Deepslate
|D=Deepslate Bricks
|T=Deepslate Tiles
|P=Packed Ice
|B=Cracked Deepslate Bricks
|S=Snow
|I=Blue Ice
|H=Chiseled Deepslate
|E=Ice
|O=Polished Deepslate Stairs
|G=Gray Carpet
|A=Polished Basalt
|L=Ladder
|R=Stone Pressure Plate
|N=Note Block
|K=Deepslate Brick Stairs
|U=Soul Lantern
|V=Lever
|F=Polished Deepslate Slab
|J=Iron Trapdoor
|M=Chest
|Q=Deepslate
|----Layer 1|
 DDD               
 DDDDDDDDDDDDD DDDD
   DCCCCCCCCCCCDDCC
   DCCCDDDDDDDCCCCC
   DCCCDDCCDCCCCCCC
C DDC CDDDCCCCCDDCC
TTTTT CDDDCCQCCDDDC
OTTTT CDDDCDDDDD C 
OTTTT CDDDDDDDDDDDC
TTTTT CCDDCDDDCCDCC
C  DC CCCCDDDDDDDCC
   DCCCCCCDDDDDDDCC
   DCCCCCCCCCCCCCCC
 DDDDDDDDDDDDDDDDDD
 DDD               
|----Layer 2|
 DDD               
 DDDCCCCCCCCCC CCC 
   CCCCCCCCCCCCPPCC
   CCCCPPPP PPEPPPC
   CCCCPPSSLPPPPP C
C DDHCP  S ASPPPPCC
TTTT TPP  S  SSPEPC
 OTTTTPPSS  MCCSCCC
 OTTT PPSS S SSSSSC
 TTTTTP S  SSSSEICC
C   HCP SSSSSEEIIC 
   DCCCPPP SEIIIICC
   TCCCCCCCCCCCCCC 
 DDDCCD  CC CCCCCCC
 DDD               
|----Layer 3|
  DD               
  DDCCCCCCCCCCCCCCC
    CCCCCCCCCCCCCCC
   CCCCPP      EPCC
   CCCCP   L    ECC
H  DHD     A     CC
    TT            C
   OTTPP     S  CCC
   OTTPP         CC
    TT           C 
H    T          EC 
   CCCC        IIC 
   CCCCCCCCCCCCCCCC
  DDCCC   CCCC  CCC
  DD               
|----Layer 4|
 DDD               
 DDD QCCCCCCCCCCCCC
    CCCCCCCCCCC CCC
   CCCCP   V    PCC
    CCC    L     CC
D  HHD     A     CC
     T            C
     TPP   UHCCCHC 
    OTPP         C 
     T           C 
D    T          PC 
   CCCC CCC    PIC 
    DCCCC CCCCCCCCC
 D D CC    CCCCCCC 
 DDD               
|----Layer 5|
 DDD               
 DDD       CCC CCC 
     DDDDCCDCCCCCCC
     CCTTTTTTTTTTCC
    CCCTTTTJTTTTTCC
    TTTTTTTATTTTTCC
     TTTTTTTTTTTTC 
     OTNTTTTTTTTDC 
     FTNTTTTTTTTT  
     DTTTTTTTTTTT  
     TTTTTTTTTTTPC 
   K DTTTTTTTTPPPC 
    DDDDD    DDDCC 
 D D               
   D               
|----Layer 6|
                   
  H             CC 
     DBDDCDBBCCBCCC
     D    TTTPIBBCC
     CC   T T PIB  
    TT     R       
     D             
      R  GGGG      
      R  GGGG      
     D             
    TD             
     DD        PP  
     DDDD   CCCD   
   D               
                   
|----Layer 7|
                   
  D                
      DBDCB        
               PB  
     D          B  
    UD             
     D             
                   
                   
     D             
    UD             
     DD         P  
     DDDD   DDDD   
                   
                   
|----Layer 8|
                   
                   
       DD          
                B  
                B  
     D             
     D             
     D             
     D             
     D             
     D             
     D             
     D  D    D D   
                   
                   
|----Layer 9|
                   
                   
        D          
                B  
                B  
                   
     KB            
     DB            
                   
                   
                   
     D             
               D   
                   
                   
|----Layer 10|
                   
                   
                   
                B  
               BB  
                B  
                   
                   
                   
                   
                   
                   
                   
                   
                   
}}