<noinclude>{{structure info}}</noinclude>
[[File:Ancient City camp 3.png|thumb|Camp 3 (Deep Dark)]]

{{layered blueprint|name=Ancient City Camp 3|default=Layer 1
|D=Cobbled Deepslate
|S=Cobbled Deepslate Stairs
|C=Cyan Wool
|B=Blue Wool
|L=Light Blue Wool
|A=Blue Carpet
|M=Campfire
|E=Deepslate Bricks
|----Layer 1|
DDD DD DDDD
D    D  DD
D
D       S SSSS
   SDDDDDDDDDS
   SDDDDDDDDDS
D   DDDDDDDDDS
D    DDDDD DDS
D  S DD  DDDDS  D
D   DD DDDDDDS  D
    DDDDDDDD S  E
     DDDDDD  S
      SSSSS
                E
      DD
      DDD
     DDD
     |----Layer 2|
 D   D
D    
     
D    
    L     BB
    L AA BBB 
    L SSS   B
D    ASSS   
D         MB  
         BB  
      LL B      E
             

                D
      D
      DD
     
          |----Layer 3|
 D   
     
     
     
    L     B 
            B 
        B   
            
            
           
                
             

                
      
      
     
}}