<noinclude>{{structure info}}</noinclude>
[[File:Ancient City chamber 2.png|thumb|Chamber 2 (Deep Dark)]]

{{layered blueprint|name=Ancient City Chamber 2|default=Layer 1
|C=Cobbled Deepslate
|D=Deepslate Bricks
|T=Deepslate Tiles
|H=Chiseled Deepslate
|E=Chest
|P=Deepslate
|----Layer 1|
    DCDDDD  
   DCCCCCCCC
C  DCCCCCCDD
    DDCCCCDD
    DDCCCCDD
    DDCCCCDD
    DDCCCCD 
   DCCCCCCDD
C  DCCCCCCCC
   DCCCCCCCC
    DCDDDDDD
|----Layer 2|
    CCCCCC  
   CCCCCCCCC
H  CCDDDDDDD
    DDTTTTDD
    DDTTTTDD
    DDTTPTDD
    DDTTTTDD
    HDTTTTDD
H  DCDDDDDDD
   TCCCCCCCC
    CCC CCCC
|----Layer 3|
     CCCCC  
    CCCCCCCC
D  CC  D   C
           T
           T
          ET
           T
           T
D  CC  D   T
   CCCCCCCCC
     CCCCC  
|----Layer 4|
            
    CCCCCC  
    C  D    
           C
           T
           T
           T
           C
   CC  D   T
     CCCCCCC
     CCCCC  
|----Layer 5|
            
            
       H    
            
           C
           C
           C
           T
       H   C
        TDCC
        TD  
|----Layer 6|
            
            
            
            
            
           C
           C
           C
           C
        C   
            
}}