<noinclude>{{structure info}}</noinclude>
[[File:Ancient City medium ruin 1.png|thumb|Medium Ruin 1 (Deep Dark)]]

{{layered blueprint|name=Ancient City Medium Ruin 1|default=Layer 1
|C=Cobbled Deepslate
|----Layer 1|
CC CC  C
C       
C      C
        
C       
        
        
       C
        
        
       C
       C
       C
|----Layer 2|
        
C       
C      C
        
C       
        
        
        
        
        
        
       C
        
|----Layer 3|
        
        
C       
        
        
        
        
        
        
        
        
        
             
}}