{{Wip}}
[[File:Ancient City bottom 1 2.png|thumb|Front Central Wall(Intact)]]

{{layered blueprint|name=Bottom Wall 1|default=Layer 1
|J=Chiseled Deepslate
|F=Dark Oak Fence
|P=Dark Oak Planks
|S=Deepslate
|K=Deepslate Brick Stairs
|D=Deepslate Bricks
|C=Cracked Deepslate Bricks
|H=Deepslate Tile Slab
|I=Deepslate Tile Stairs
|Y=Deepslate Tile Wall
|T=Deepslate Tiles
|N=Cracked Deepslate Tiles
|W=Gray Wool
|R=Polished Deepslate
|A=Polished Deepslate Stairs
|L=Redstone Lamp
|E=Sculk Sensor
|----Layer 1|
DSSSSSSSSSSSSSSSSSSSSSSSSSSSSSSSSSSSSSSSS
DDDDDDDDDDDDDDDDDDDDDDDDDDDDDDDDDDDDDDDDD
DDDDDDDDDDDDDDDDDDDDDDDDDDDDDDDDDDDDDDDDD
DDDDDDDDDDDDDDDDDDDDDDDDDDDDDDDDDDDDDDDDD
DDDDDDDDDDDDDDDDDDDDDDDDDDDDDDDDDDDDDDDDD
DDSSDDSDDDDDSSDDDSSDDSSDDDSSSSSDDDDSSDDDD
DSDDDSDDSSDSSSSSDDSDSSSSSDSSSSSSDDSSSSDDD
SSDSDDDSSSDSSSSSSDDDSSSSDDDSDSSDDDDDDSSDD
DDDDDDDDDDDDSSSDDDDDSSSDDDSSDDDDSSDDDDDDD
DDDDDDDDDDDDDDDDDDDDDDDDDDDDDDDDDDDDDDDDD
DDDDDDDDDDDDDDDDDDDDDDDDDDDDDDDDDDDDDDDDD
DDDDDDDDDDDDDDDDDDDDDDDDDDDDDDDDDDDDDDDDD
SSSSSSSSSSSSSSSSSSDDDDDSSSSSSSSSSSSSSSSSS
                  DDDDD                  
|----Layer 2|
 SSSSSSSSSSSSSSSSS     SSSSSSSSSSSSSSSSSS
WWWWWWWWWWWWWWWWWW     WWWWWWWWWWWWWWWWWW
SSSSSSSSSSSSSSSSSS     SSSSSSSSSSSSSSSSSS
KWWWWK KWWWWK KD         DK KWWWWK KWWWWK





KK KK KK KK     KK     KK    IKK KK KK KK
DDWDDWDDWDDAK KWDDWK KWDDWK KSDDWDDWDDWDD
WWWWWWWWWWWSWWWWWWWWWWWWWWWWWSWWWW WWWWWW
SSSDDDDSSSSSDDDDSSDDDDDSSDDDDSSSSSDDDCSSS
|----Layer 3|
 SSSSSSSSSSSSSSSSS     SSSSSSSSSSSSSSSSSS
WWWWWWWWWWWWWWWWWW     WWWWWWWWWWWWWWWWWW
DDDDDDDDDDDDDDDDDD     DDDDDDDDDDDDDDDDDD
 WWWW   WWWW   D         D   WWWW   WWWW






JJWJJWJJWJJ    WJJW   WJJW   IJJW   JJWJJ
WWWWWWWWWWWIWWWWWWWWWWWWWWWWWDWWWW WWWWWW
TTTDJJDTTTTTDJJDTTDDDDDTNDJJDNTTNTCJJDNNN
|----Layer 4|
 DDDDDDDDDDDDDDDDD     DDDDDDDDDDDDDDDDDD
WWWWWWWWWWWWWWWWWW     WWWWWWWWWWWWWWWWWW
DDDDDDDDDDDDDDDDDD     DDDDDDDDDDDDDDDDDD
IWWWWIJIWWWWIJID         DIJIWWWWIJIWWWWI






IIWIIWIIWII IJIWIIWIJIWIIWIJI II    IIWII
WWWWWWWWWWW WWWWWWWWWWWWWWWWW WWWTWWWWWWW
TTTDJJDTTTTTDJJDTTDDDDDNNDJJDNTTT DJJDTTT
                  KKKKK
|----Layer 5|
 DDDDDDDDDDDDDCDDDCDDCCDDDDCDDDDDDDDDDDDD
WWWWWWWWWWWWWWWWWWWWWWWWWWWWWWWWWWWWWWWWW
DDDDDDDDDDDDDDDDDDDDDDDDDDDDDDDDDDDDDDDDD
IWWWWIIIWWWIH HI  IPDPI  IH HIWWWIIIWWWWI
                   PPP                   
                   PPP
                   PPP
                   PPP
                   PPP
II II II II III II PDP II III  I    II II
TTWTTWTTWTT TRNWTTWDDDWTTWTRT TT    TTWTT
WWWWWWWWWWW WWWWWWWWWWWWWWWWW  WW   WWWWW
WWWWWWWWWI   IWWWWWWWWWWWWWI   IWW WWWWWW
IIIDDDDIIIIIDDDDIIDDDDDIIDDDDNIIIIDCDCIII
|----Layer 6|
         AAA   AAA     AAA   AAA         
WWWWWWWWWWWW W WWW WWW WWW W WWWWWWWWWWWW
         AAA   AAA     AAA   AAA
IWWWWIIIWWW        F F        WWWIIIWWWWI


                   F F                   
                   
                   
JJ JJ JJ JJ     JJ F F JJ JJJ  J    JJ JJ
JJIJJIJJIJJ    IJJI   IJJI          JJIJJ


YJJYJJYJJYJJYJJYJJ     JJYJJYJJYJJYJJYJJY
|----Layer 7|
                                        
 W W W W WS  W  S   W   S  W  SW W W W W
 
 W W  I  W         F F         W  I  W W
                   
                   
                   F F
                   
                   
         II     II F F II III          II
   II    II     II     II           II II


    II    II    II     II    II    II
|----Layer 8|
                                         
          R     R       R     R          
                                         
                   PPP                   
                                         
                                         
                   PPP                   
                                         
                                         
                   PPP                   
   II    II     II     II            I II 
                         
                         
    II    II                 II    II    
|----Layer 9-10|
                                         
          R     R       R     R          
                                         
                                         
                                         
                                         
                                         
                                         
                                         
                                         
                                         
                                         
                                         
                                         
|----Layer 11|
                                         
          L     L       L     L          
                                         
                                         
                                         
                                         
                                         
                                         
                                         
                                         
                                         
                                         
                                         
                                         
|----Layer 12|
         AJA   AJA     AJA   AJA         
         JEJ   JEJ     JEJ   JEJ         
         AJA   AJA     AJA   AJA         
                                         
                                         
                                         
                                         
                                         
                                         
                                         
                                         
                                         
                                         
                                         
|----Layer 13|
         RJR   RJR     RJR   RJR         
         J J   J J     J J   J J         
         RJR   RJR     RJR   RJR
}}