<noinclude>{{structure info}}</noinclude>
[[File:Ancient City medium pillar 1.png|thumb|Medium Pillar 1 (Deep Dark)]]

{{layered blueprint|name=Ancient City Medium Pillar 1|default=Layer 1
|D=Deepslate
|C=Chiseled Deepslate
|P=Polished Deepslate
|T=Deepslate Tiles
|S=Deepslate Tile Stairs
|E=Deepslate Tile Slab
|K=Skeleton Skull
|----Layer 1|
       
       
 TCCT  
 CDDC  
 CDDC  
 TCCT  
       
       
|----Layer 2|
       
       
 SSSE  
 SDD   
 SDDK  
 SSSE  
       
       
|----Layer 3|
       
       
       
  DD   
  DD   
       
       
       
|----Layer 4|
       
       
       
  PP   
  PP   
       
       
       
|----Layer 5|
       
       
       
  CC   
  CC   
       
       
       
|----Layer 6|
       
       
       
  TT   
  TT   
       
       
       
|----Layer 7|
       
       
       
  PP   
  PP   
       
       
       
|----Layer 8|
       
       
       
  DD   
  DD   
       
       
       
|----Layer 9|
       
       
 SSSS  
 SDDS  
 SDDS  
 SSSS  
       
       
|----Layer 10|
   D   
  DDD  
 PDDP  
DDDDDDD
DDDDDDD
DDDDDD 
DDDD   
       
|----Layer 11|
       
       
  DD   
 DDDDDD
 DDDDD 
DDDDDD 
DDD    
DDD    
}}