<noinclude>{{structure info}}[[uk:Стародавнє місто/Структура/Плани/З'єднувач входу]]</noinclude>
[[File:Ancient City entrance connector.png|thumb|Entrance Connector (Deep Dark)]]
{{layered blueprint|name=Ancient City Entrance Connector|default=Layer 1
|D=Deepslate
|T=Deepslate Tiles
|P=Polished Deepslate
|B=Deepslate Bricks
|O=Polished Basalt
|C=Chiseled Deepslate
|S=Smooth Basalt
|E=Deepslate Tile Stairs
|R=Deepslate Brick Slab
|A=Candle
|L=Soul Lantern
|W=Polished Deepslate Wall
|I=Deepslate Brick Stairs
|----Layer 1|
DDDOOOODDDDDDOOOODDDDDDOOO    
DDDDDDDDDDDDDDDDDDDDDDDDDO    
DDDDDDDDDDDDDDDDDDDDDDDDDO    
DDDDDDDDDDDDDDDDDDDDDDDDDO    
DDDDDDDDDDDDDDDDDDDDDDDDDO    
DDDDDDDDDDDDDDDDDDDDDDDDDO    
DDDDDDDDDDDDDDDDDDDDDDDDDO    
DDDDDDDDDDDDDDDDDDDDDDDDDO    
DOOOOOOOODDOOOOOOOODDOOOOO    
DO      ODDO      ODDO        
DO      ODDO      ODDO        
DO      ODDO      ODDO        
DO      ODDO      ODDO        
DO      ODDO      ODDO        
DO      ODDO      ODDO        
DTTTTTTTTDDTTTTTTTTDDTTT      
DTTTTTTTTDDTTTTTTTTDDTTT      
TTTTTTTTTTTTTTTTTTTTTTTTTTTTTT
TTTTTTTTTTTTTTTTTTTTTTTTTTTTTT
TTTTTTTTTTTTTTTTTTTTTTTTTTTTTT
TTTTTTTTTTTTTTTTTTTTTTTTTTTTTT
TTTTTTTTTTTTTTTTTTTTTTTTTTTTTT
DTTTTTTTTDDTTTTTTTTDDTTT      
DTTTTTTTTDDTTTTTTTTDDTTT      
DO      ODDO      ODDO        
DO      ODDO      ODDO        
DO      ODDO      ODDO        
DO      ODDO      ODDO        
DO      ODDO      ODDO        
DO      ODDO      ODDO        
DOOOOOOOODDOOOOOOOODDOOOOO    
DDDDDDDDDDDDDDDDDDDDDDDDDO    
DDDDDDDDDDDDDDDDDDDDDDDDDO    
DDDDDDDDDDDDDDDDDDDDDDDDDO    
DDDDDDDDDDDDDDDDDDDDDDDDDO    
DDDDDDDDDDDDDDDDDDDDDDDDDO    
DDDDDDDDDDDDDDDDDDDDDDDDDO    
DDDDDDDDDDDDDDDDDDDDDDDDDO    
DDDOOOODDDDDDOOOODDDDDDOOO    
|----Layer 2|
TTE    ETTTTTE  ETTTTTE       
DDE    EDDDDE    EDDDDE       
DDE     DDDDE    EDDDD        
DD      DDDDE    EDDDDE       
DD       DDDE    EDDDD        
EE       EEEE    EEEE         
                              
                              
                              
                              
                              
                              
                              
                              
                              
 TTT  TTT  TTT  TTT  TTT      
 TTT  TTT  TTT  TTT  TTT      
ESPSEESPSEESPSEESPSEESPSPBB   
TTTTTTTTTTTTTTTTTTTTTTTTTBB   
TTTTTTTTTTTTTTTTTTTTTTTTTBB   
TTTTTTTTTTTTTTTTTTTTTTTTTBB   
ESPSEESPSEESPSEESPSEESPSPBB   
 TTT  TTT  TTT  TTT  TTT      
 TTT  TTT  TTT  TTT  TTT      
                              
                              
                              
                              
                              
                              
                              
                              
                              
EEE    EEEE      EEEEEE       
DDE    EDDD      EDDDDE       
DDE    EDDDD     EDDDDE       
DDE    EDDDDE    EDDDDE       
DDE    EDDDDE    EDDDDE       
TTE    ETTTTTE  ETTTTTE       
|----Layer 3|
BB      BBBBI    IBBBB        
DD      DDDD      DDDD        
DD      DDDD      DDDD        
DD       DDD      DDDD        
D        DDD      DDD         
                              
                              
                              
                              
                              
                              
                              
                              
                              
                              
 TTT  TTT  TTT  TTT  TTT      
 SPS  SPS  SPS  SPS  SPS      
                        PBB   
                        BBB   
                        BBB   
                        BBB   
                        PBB   
 SPS  SPS  SPS  SPS  SPS      
 TTT  TTT  TTT  TTT  TTT      
                              
                              
                              
                              
                              
                              
                              
                              
                              
                              
DD      D          DDD        
DD      D D        DDD        
DD      DDDD      DDDD        
DD      DDDD      DDDD        
BB      BBBBI    IBBBB        
|----Layer 4|
                              
EE      EEEE      EEEE        
PE      EPPE      EPPE        
PE      EPPE      EPPE        
E         EE      EEEE        
                              
                              
                              
                              
                              
                              
                              
                              
                              
                              
 P P  P P  P P  P P  P P      
 A A  AAA       AAA           
                        EBBI  
                         BBI  
                         BBI  
                         BBI  
                        EBBI  
 AAA  AA     A  AAA  AAA      
 P P  P P  P P  P P  P P      
                              
                              
                              
                              
                              
                              
                              
                              
                              
                              
EE      E E         EE        
PE      EPPE       PPE        
PE      EPPE      EPPE        
EE      EEEE      EEEE        
                              
|----Layer 5|
                              
PP      PPPP      PPPP        
PP      PPPP      PPPP        
PP      PPPP      PPPP        
P        PPP      PPPP        
                              
                              
                              
                              
                              
                              
                              
                              
                              
                              
 BCB   CB  BC   BCB  BC       
                              
                         EBBBB
                          BBBB
                          BBBB
                          BBBB
                         EBBBB
                              
 BCB  BCB  BCB  BCB  BCB      
                              
                              
                              
                              
                              
                              
                              
                              
                              
                              
PP      PPPP        PP        
PP      PPPP        PP        
PP      PPPP      PPPP        
PP      PPPP      PPP         
                              
|----Layer 6|
                              
TC      CTTC      CTTC        
PT      TPPT      TPPT        
PT      TPPT      TPPT        
TC      C TC      CTT         
                              
           L      L           
                              
                              
                              
                              
                              
                              
                              
                              
 TTT   TT  TTT  TTT  T        
 TTT        TT  TTT  T        
 EEE        EE  EEE       EBBB
                              
                              
                              
 EEE  E     EE  EEE   EE  EBBB
 TTT  TTT   TT  TTT  TTT      
 TTT   TT   TT  TTT  TTT      
                              
                              
                              
                              
                              
                              
                              
                              
 L      L  L         L        
                              
TC      CTTC       TTC        
PT      TPPT      TPPT        
PT      TPPT      TPPT        
TC      CTT       CTT         
                              
|----Layer 7|
                              
PP      PPPP      PPPP        
PP      PPPP      PPPP        
PP      P PP      PPP         
P       PPPP      PPP         
           W      W           
           W      W           
                              
                              
                              
                              
                              
                              
                              
                              
                              
 RRR        RR  RRR  RR       
 TTT        TT  TTT  TT       
 TTT        TT  TTT  TTT      
  TT         T   TT   TT      
   T             TT    T      
 TTT  T          TT  TTT      
 RRR  RRR        RR  RRR      
                              
                              
                              
                              
                              
                              
                              
                              
                              
 W      W  W         W        
 W      W  W         W        
PP      P PP      PPPP        
PP      PPPP      PPPP        
PP      PPPP      PP          
PP      PP        PP          
                              
|----Layer 8|
                              
CT      TCCT      TCCT        
PC      CPPC      CPPC        
P       C PC      CPP         
          CT      TCC         
                              
                              
                              
                              
                              
                              
                              
                              
                              
                              
                              
                              
                              
                              
                              
                              
                              
                              
                              
                              
                              
                              
                              
                              
                              
                              
                              
                              
                              
CT      T         TCCT        
PC      CP C      CPPC        
PC      CPPC      CP          
CT      TC        TCC         
                              
|----Layer 9|
                              
PP      PPPP      PPPP        
PP      PPPP      PPPP        
P         PP      PPP         
P         PP      PP          
                              
                              
                              
                              
                              
                              
                              
                              
                              
                              
                              
                              
                              
                              
                              
                              
                              
                              
                              
                              
                              
                              
                              
                              
                              
                              
                              
                              
                              
PP      P  P       PPP        
PP      P  P        PP        
PP      PP        PPPP        
PP      PP        PP          
                              
|----Layer 10|
                              
TC      CTTC      CTTC        
PT      TPPT      TPPT        
PT      TPPT      TPPT        
T         TC      CTT         
                              
                              
                              
                              
                              
                              
                              
                              
                              
                              
                              
                              
                              
                              
                              
                              
                              
                              
                              
                              
                              
                              
                              
                              
                              
                              
                              
                              
                              
TC      CTTC       TTC        
PT      TPPT      TPPT        
PT      TP        TPPT        
TC      CTT       CTT         
                              
|----Layer 11|
                              
PP      PPPP      PPPP        
PP      PPPP      PPPP        
PP      PPPP      PPPP        
P       PPPP      PPPP        
                              
                              
                              
                              
                              
                              
                              
                              
                              
                              
                              
                              
                              
                              
                              
                              
                              
                              
                              
                              
                              
                              
                              
                              
                              
                              
                              
                              
                              
PP      PPPP        PP        
PP      PPPP       PPP        
PP      PPPP      PPPP        
PP      PPPP      PPPP        
                              
|----Layer 12|
                              
EE      EEEE      EEEE        
PE      EPPE      EPPE        
PE      EPPE      EPPE        
E       EEEE      EEEE        
                              
                              
                              
                              
                              
                              
                              
                              
                              
                              
                              
                              
                              
                              
                              
                              
                              
                              
                              
                              
                              
                              
                              
                              
                              
                              
                              
                              
                              
EE      EEEE       EEE        
PE      EPPE      EPPE        
PE      EPPE      EPPE        
EE      EEEE      EEEE        
                              
|----Layer 13|
                              
DD      DDDD      DDDD        
DD      DDDD      DDDD        
DD      DDDD      DDDD        
D        DDD      DDDD        
                              
                              
                              
                              
                              
                              
                              
                              
                              
                              
                              
                              
                              
                              
                              
                              
                              
                              
                              
                              
                              
                              
                              
                              
                              
                              
                              
                              
                              
DD      DDDD        DD        
DD      DDDD       DDD        
DD      DDDD      DDDD        
DD      DDDD      DDDD        
                              
|----Layer 14|
EEE    EEEEEE    EEEEE        
DDE    EDDDDE    EDDDD        
DDE    EDDDDE    EDDDD        
DDE     DDDDE    EDDDDE       
DD       DDDE    EDDDDE       
EE        EEE    EEEEEE       
                              
                              
                              
                              
                              
                              
                              
                              
                              
                              
                              
                              
                              
                              
                              
                              
                              
                              
                              
                              
                              
                              
                              
                              
                              
                              
                              
EEE    EEEEEE        EE       
DDE    EDDDDE      DDDE       
DDE    EDDDDE     DDDDE       
DDE    EDDDDE    EDDDDE       
DDE     DDDDE    EDDDDE       
EEE     EEEEE    EEEEEE       
|----Layer 15|
DDD    DDDDDD    DDDD         
DDD    DDDDDD    DDD          
DDD    DDDDDD    DDDDD        
DDD     DDDDD    DDDDDD       
DDD      DDDD    DDDDDD       
DD       DDDD    DDDDDD       
                              
                              
                              
                              
                              
                              
                              
                              
                              
                              
                              
                              
                              
                              
                              
                              
                              
                              
                              
                              
                              
                              
                              
                              
                              
                              
                              
DDD    DDDDDD       DDD       
DDD    DDDDDD      DDDD       
DDD    DDDDDD    DDDDDD       
DDD     DDDDD    DDDDDD       
DDD      DDDD    DDDDDD       
DDD      DDDD    DDDDDD       
}}