<noinclude>{{structure info}}</noinclude>
[[File:Ancient City tall ruin 3.png|thumb|Tall Ruin 3 (Deep Dark)]]

{{layered blueprint|name=Ancient City Tall Ruin 3|default=Layer 1
|D=Deepslate Tiles
|B=Deepslate Bricks
|T=Deepslate Tile Slab
|P=Polished Deepslate Wall
|S=Deepslate Tile Stairs
|W=Deepslate Tile Wall
|L=Ladder
|C=Chest
|----Layer 1|
                 
                 
                 
     SSSSSSS     
    SSDBBBBSS    
   SSBBBBBBBSS   
   SDBBDDDBBDS   
   SBB D  DBB    
   SB      BB    
   S       BB    
   SD     BBD    
   SSB  B  BS    
    SSDBBBDSS    
     SSSS S      
                 
                 
                 
|----Layer 2–3|
                 
                 
                 
                 
                 
     B     B     
          D      
                 
                 
                 
                 
                 
                 
                 
                 
                 
                 
|----Layer 4|
                 
                 
                 
                 
                 
           B     
                 
                 
                 
                 
                 
                 
                 
                 
                 
                 
                 
|----Layer 5–6|
                 
                 
                 
                 
                 
     B     B     
          D      
                 
                 
                 
                 
                 
                 
                 
                 
                 
                 
|----Layer 7|
                 
                 
                 
                 
                 
     B     B     
          D      
                 
                 
                 
          D      
           B     
                 
                 
                 
                 
                 
|----Layer 8|
                 
                 
                 
      BBBBB      
     BBBBBBB     
    BB BBB BB    
      B  BBLBB   
         BBBBB   
         BBBBB   
           BBB   
          B BB   
           BB    
           B     
                 
                 
                 
                 
|----Layer 9–12|
                 
                 
                 
      P   P      
                 
                 
             P   
                 
                 
                 
             P   
                 
                 
                 
                 
                 
                 
|----Layer 13|
                 
                 
                 
      P   P      
                 
                 
             P   
                 
                 
                 
             P   
                 
                 
          P      
                 
                 
                 
|----Layer 14|
                 
                 
                 
      D   D      
        TTDT     
         TDDT    
         DDDDD   
         TDTT    
          D      
         T       
         DD      
         TD      
         TDT     
          D      
                 
                 
                 
|----Layer 15|
                 
                 
      D   D      
          DT     
            T    
   T         T   
  D           D  
          C      
                 
                 
              D  
                 
                 
                 
          D      
                 
                 
|----Layer 16|
                 
      D   D      
     TD   DT     
            T    
   T         T   
  T           T  
 DD           DD 
              T  
              T  
              T  
              DD 
                 
                 
            T    
        TTDT     
                 
                 
|----Layer 17|
                 
      D   D      
      D   D      
                 
                 
                 
 DD           DD 
                 
                 
                 
               D 
                 
                 
                 
          D      
          D      
                 
|----Layer 18|
                 
                 
      D   D      
      D   D      
                 
                 
  DD  W   W  DD  
                 
                 
                 
              D  
                 
                 
          D      
          D      
                 
                 
|----Layer 19|
                 
                 
                 
      D   D      
      D   D      
      D   D      
   DDDDDDDDDDD   
      D   D      
      D   D      
      D   D      
      DDDDDDDD   
      D   D      
      D   D      
      D   D      
                 
                 
                 
}}