{{Wip}}
[[File:Ancient_City_left.png|thumb|Left wall]]

{{layered blueprint|name=Bottom Wall 1|default=Layer 1
|J=Chiseled Deepslate
|F=Dark Oak Fence
|P=Dark Oak Planks
|S=Deepslate
|K=Deepslate Brick Stairs
|D=Deepslate Bricks
|C=Cracked Deepslate Bricks
|H=Deepslate Tile Slab
|I=Deepslate Tile Stairs
|Y=Deepslate Tile Wall
|T=Deepslate Tiles
|N=Cracked Deepslate Tiles
|W=Gray Wool
|R=Polished Deepslate
|A=Polished Deepslate Stairs
|L=Redstone Lamp
|E=Sculk Sensor

|----Layer 1|
SDDDDDDDDDDDS
SDDDDDDDDDDDS
SDDDDDDDDDDDS
SDDDDDDDDDDDS
SDDDDDDDDDDDS
SDDDDDDDDDDDS
SDDDDDDDDDDDSA
SDDDDDDDDDDDSD
SDDDDDDDDDDDDD
SDDDDDDDDDDDDD
SDDDDDDDDDDDDD
SDDDDDDDDDDDDD
SDDDDDDDDDDDSA
SDDDDDDDDDDDS
SDDDDDDDDDDDS
SDDDDDDDDDDDS
SDDDDDDDDDDDS
SDDDDDDDDDDDS
DDDDDDDDDDDDS

|----Layer 2|
SWSI     IDWS
SWSW     IDWS
SWSW      WWD
SWSW      IWD
SWSW       W 
SWSI      IWD
SWS       ASS
SWSI     IDWSA
SWSW        AW
SWSW        AW
SWSI        AW
SWS      IDWSA
SWSI      WWD
SWSW     IDWD
SWSW     IDWD
SWSW      WWS
SWSW     IDWS
SWSI     IDWS
SWS       WWS

|----Layer 3|
SWD       JWT
SWDW      JWT
SWDW      WWD
SWDW       WJ
SWDW       WJ
SWD        WD
SWD        IT
SWD       JWT
SWDW         
SWDW         
SWD          
SWD       JWD
SWD       WWJ
SWDW      JWJ
SWDW      JWD
SWDW      WWT
SWDW      JWT
SWD       JWT
SWD       WWT

|----Layer 4|
DWDI      IWI 
DWDW      IWI
DWDW      WWD
DWDW      IWJ
DWDW      JWJ
DWDI      IWD
DWDJ        I
DWDI      IWI
DWDW         
DWDW         
DWDI         
DWDJ      IWD
DWDI      WWJ
DWDW      IWJ
DWDW      IWD
DWDW      WWI
DWDW      IWI
DWDI      IWI
DWDJ      WWI

|----Layer 5|
DWDI      IWWI
DWDW      IWWI
DWDW      WWWD
DWDW      WWWD
DWDW      WWID
DWDI      WW D
DWDI         I
DWDI      IWWI
DWDW      I   
DWDW          
DWDI      I   
DWDI      IWW 
DWDI      WWWD
DWDW      IWWD
DWDW      IWWD
DWDW      WWWI
DWDW      IWWI
DWDI      IWWI
DWDI      WWWI

|----Layer 6|
 W I      J  J
 W W      J  J
 W W      I  Y
 W W         J
 W W         J
 W I         Y
 W I         J
 W I      J  J
 W W      JWWY
 W W      IWWJ
 W I      JWWJ
 W I      J  Y
 W I      I  J
 W W      J  J
 W W      J  Y
 W W      I  J
 W W      J  J
 W I      J  Y
 W I      I  J

|----Layer 7|
 W        I  I
          I  I
 W W          
             I
 W W         I
              
 W I         I
          I  I
 W W      I   
   W         I
 W        I  I
   I      I   
 W           I
   W      I  I
 W        I   
   W         I
 W        I  I
          I   
              

|----Layer 8|
          I   
          I   
              
             I
             I
              
              
          I   
          I   
             I
             I
             
             
          I   
          I   
             I
             I
             
             

}}