<noinclude>{{structure info}}[[uk:Стародавнє місто/Структура/Плани/Центр міста 2]]</noinclude>
[[File:Ancient City city center 2 2.png|thumb|City Center 2 (Deep Dark)]]

{{layered blueprint|name=Ancient City City Center 2|default=Layer 1
|D=Deepslate Bricks
|T=Deepslate Tiles
|E=Deepslate
|C=Cobbled Deepslate
|G=Gray Carpet
|W=Gray Wool
|P=Glass Pane
|S=Soul Sand
|F=Soul Fire
|R=Reinforced Deepslate
|B=Grass Block
|L=Deepslate Brick Slab
|I=Deepslate Tile Stairs
|A=Candle
|M=Redstone Lamp
|O=Redstone Dust
|H=Deepslate Tile Slab
|K=Deepslate Brick Stairs
|J=Chiseled Deepslate
|N=Cracked Deepslate Bricks
|Q=Deepslate Brick Wall
|U=Soul Lantern
|V=Dirt
|X=Glass
|Y=Cracked Deepslate Tiles
|Z=Redstone Repeater
|b=Redstone Comparator
|c=Block of Redstone
|d=Sticky Piston
|e=Piston Head
|f=Polished Deepslate Slab
|g=Polished Deepslate Wall
|h=Target
|i=Redstone Wall Torch
|j=Lever
|k=Sculk Sensor
|l=Furnace
|m=Lectern
|n=Chest
|----Layer 1|
EEEEEEEEEEEEEEEEEE
EEEEEEEEEEEEEEEEEE
EEEEEEEEEEEEEEEEEE
EEEEEEEEEEEEEEEEEE
EEEEEEEEEEEEEEEEEE
EEEEEEEEEEEEEEEEEE
EEEEEEEEEEEEEEEEEE
EEEEEEEEEEEEEEEEEE
EEEEEEEEEEEEEEEEEE
EEEEEEEEEEEEEEEEEE
EEEEEEEEEEEEEEEEEE
EEEEEEEEEEEEEEEEEE
EEEEEEEEEEEEEEEEEE
EEEEEEEEEEEEEEEEEE
EEEEEEEEEEEEEEEEEE
EEEEEEEEEEEEEEEEEE
EEEEEEEEEEEEEEEEEE
EEEEEEEEEEEEEEEEEE
EEEEEEEEEEEEEEEEEE
EEEEEEEEEEEEEEEEEE
EEEEEEEEEEEEEEEEEE
EEEEEEEEEEEEEEEEEE
EEEEEEEEEEEEEEEEEE
EEEEEEEEEEEEEEEEEE
EEEEEEEEEEEEEEEEEE
EEEEEEEEEEEEEEEEEE
EEEEEEEEEEEEEEEEEE
EEEEEEEEEEEEEEEEEE
EEEEEEEEEEEEEEEEEE
EEEEEEEEEEEEEEEEEE
EEEEEEEEEEEEEEEEEE
EEEEEEEEEEEEEEEEEE
EEEEEEEEEEEEEEEEEE
EEEEEEEEEEEEEEEEEE
EEEEEEEEEEEEEEEEEE
EEEEEEEEEEEEEEEEEE
EEEEEEEEEEEEEEEEEE
EEEEEEEEEEEEEEEEEE
EEEEEEEEEEEEEEEEEE
EEEEEEEEEEEEEEEEEE
EEEEEEEEEEEEEEEEEE
|----Layer 2|
DEEEEEEEEEEEEEEEED
EEEEEEEEEEEEEEEEEE
EEEEEEEEEEEEEEEEEE
EEEEEEEEEEEEEEEEEE
EEEEEEEEEEEEEEEEEE
EEEEEEEEEEEEEEEEEE
EEEEEEEEEEEEEEEEEE
EEEEEEEEEEEEEEEEEE
EEEEEEEEEEEEEEEEEE
EEEEEEEEEEEEEEEEEE
EEEEEEEEEEEEEEEEEE
EEEEEEEEEEEEEEEEEE
EEEEEEEEEEEEEEEEEE
EEEEEEEEEEEEEEEEEE
EEEEEEEEEEEEEEEEEE
EEEEEEEEEEEEEEEEEE
EEEEEEEEEEEEEEEEEE
EEEEEEEEEEEEEEEEEE
EEEEEEEEEEEEEEEEEE
EEEEEEEEEEEEEEEEEE
EEEEEEEEEEEEEEEEEE
EEEEEEEEEEEEEEEEEE
EEEEEEEEEEEEEEEEEE
EEEEEEEEEEEEEEEEEE
EEEEEEEEEEEEEEEEEE
EEEEEEEEEEEEEEEEEE
EEEEEEEEEEEEEEEEEE
EEEEEEEEEEEEEEEEEE
EEEEEEEEEEEEEEEEEE
EEEEEEEEEEEEEEEEEE
EEEEEEEEEEEEEEEEEE
EEEEEEEEEEEEEEEEEE
EEEEEEEEEEEEEEEEEE
EEEEEEEEEEEEEEEEEE
EEEEEEEEEEEEEEEEEE
EEEEEEEEEEEEEEEEEE
EEEEEEEEEEEEEEEEEE
EEEEEEEEEEEEEEEEEE
EEEEEEEEEEEEEEEEEE
EEEEEEEEEEEEEEEEEE
EEEEEEEEEEEEEEEEEE
|----Layer 3|
DDDDDDDDDDDDDDDDDD
DTWWWWWWWWTTTTTTTD
DTWWWWWWWWTTTTTTTD
DTWWWWWWWWTTTTTTTD
DTWWWWWWWWTTTTTTTD
DTWWWWWWWWTTTTTTTD
DTWWWWWWWWTTTTTTTD
DTWWWWWWWWTTTTTTTD
DTWWWWWWWWTTTTTTTD
DTWWWWWWWWTTTTTTTD
DTWWWWWWWWTTTTTTTD
DTWWWWWWWWTTTTTTTD
DTWWWWWWWWTTTTTTTD
DTWWWWWWWWTTTTTTTD
DTWWWWWWWWTTTTTTTD
DTWWWWWWWWTTTTTTTD
DTWWWWWWWWTTTTTTTD
DDWWWWWWWWTTTTTTTD
DTTTTTTTTTTTTTTTTD
ITTTTTTTTTTTTTTTTD
DTTTTTTTTTTTTTTTTD
ITTTTTTTTTTTTTTTTD
DTTTTTTTTTTTTTTTTD
DTWWTTTTTTTBVBBBBD
DTTTTTTTTTTBBBVBBD
DTTTTTTTTTTBBBBBBD
DTTTTTTTTTTBBBBBBD
DTTTTTTTTTTBBBVBBD
DTTTTTTTTTTBBBBBBD
DTGTGTGTTTTBBBVBBD
DTGTGTGTTTTBBBBBBD
DTGTGTGTTTTTTTTTTD
DTGTGTGTTTTTTTTTTD
DTGGGGGTTTTTTTTTTD
DTIIIIITTTTTTTTTTD
DTTTTTTTTTTTTTTTTD
DTTTTTTTTTTTTTTTTD
DTIIIIITTTTTTTTTTD
DTGGGGGTTTTTTTTTTD
DTGGGGGTTTTTTTTTTD
DDDDDDDDDDDDDDDDDD
|----Layer 4|
DDDDDDDDDDDDDDDDDD
DT        TGGT g D
DT        TGGT   D
DT    MMM TGGT   D
DT    M M TGGT g D
IT    M M TGGT   D
IT    M M TGGT   D
DT  MMM M TGGTIIID
DT      MMfGGITTTD
IT   ObbbOfGGITTTD
IT   WbbbOTGGITTTD
IT   i   iTGGITTTD
DT  OO WZWTGGTIIID
DT  O  WiOTGGT   D
IT  Z  bblTGGT m D
ITTTWT W  TGGT b D
ITWWWTXkX TGGT M D
DdZOGT X  TGGT   D
DeGGGTTTTTTGGTTTTD
 DGGGGGGGGGGGGGGGD
IDGGGGGGGGGGGGGGGD
 DGGGGGGGGGGGGGGGD
DeGGGTTTGGTTTTTTTD
DdZWGTTTGGT M    D
ITWWTTGGGGT O M  D
ITTTTTTTGGT O O  D
ITTTTTGGGGT X O  D
DTTGGGGGGGT Z W  D
DTTTTTTTGGT O Z  D
IT     TGG  OOc  D
IT     TGGT      D
DT     TGGTTTT TTD
DT Q Q TGGGGGGGGGD
IT     TGGGGGGGGGD
IT     TGGTTTGGTTD
DTGGGGGGGGTGGGGGGD
DTGGGGGGGGTGGTGTGD
IT     TGGTGGTGTGD
IT     TGGTGGTGTGD
DT     TGGTTTTGTGD
DDDDDDDDDDDDDDDDDD
|----Layer 5|
DDDDDDDDDDDDDDDDDD
DT        T  P g D
DT        P  P   D
DT    OOO P  P   D
DT    O O P  P h D
IT    O O P  P   D
IT    O O P  P   D
DT  OOO O T  Y   D
DT      OO    GGGD
 T        j   GGGD
 T       iT   GGGD
 T        P   GGGD
DT     O OP  Y   D
DT     O  P  P   D
 T        P  P   D
 TPPOT    P      D
 TZOOT    P  P   D
Dd  WT    P  P   D
De   TPPPPT  TP TD
 D               D
ID               D
 D               D
De   TTT  TP PPPTD
Dd OWT Q  P      D
 TZO T    P      D
 TTTTT Q  P      D
 T   Q    P      D
DT        P      D
DTTTT  T  P      D
 T T   P         D
 T T      P      D
DT T   P  TPPT TPD
DT T Q P         D
IT     P         D
IT     T  TPP  PPD
DT        P      D
DT        P  Q Q D
IT     T  P      D
IT     P  P      D
DT     P  P      D
DDDDDDDDDDDDDDDDDD
|----Layer 6|
DDDDDDDDDDDDDDDDDD
DDDDD     T  P M D
DDDDD     P  P   D
DDDDD     P  P c D
DDDDD     P  P d D
DDDDD     P  P   D
DDDDD     P  P   D
DDDDD     TU Y   D
DDDDD            D
IDDDD            D
IDDDD     T      D
IDDDD     P      D
DDDDD     P  Y   D
DT        P  P   D
IT        P  P   D
ITPPPT    P  P   D
IT   T    P  P   D
DT  OT    P  P   D
DT  WTPPPPTU T PTD
IT  W            D
JJ  W            D
IT  W     U      D
DT  WTTT UTPP PPTD
DT  OTTT  P      D
IT   T    P      D
ITTTTTTT  P      D
ITTTTT    P      D
DTT       P      D
DDDDD  T         D
IDDDD  P         D
IDDDD  P  P      D
DDDDD  P  TPPT TPD
DDDDDQ P         D
DDDDD  P  U      D
DDDDD  T UTPP  PPD
DDDDD     P      D
DDDDD     P  T T D
DDDDD  T  P  T T D
DDDDD  P  P  T T D
DDDDD  P  P TT T D
DDDDDDDDDDDDDDDDDD
|----Layer 7|
    DDDDDDDDDDDDDD
    D     T  P   D
    D     P  P   D
    D     P  P   D
    D     P  P   D
LLLLD     P  P   D
DDDDD     P  P   D
DDDDD     Tg T   D
DDDDD        T   D
DDDDD        T   D
DDDDDIIIIIT  T   D
DDDDDTTTTTP  T   D
DDDDDTTTTTP  T   D
DTTTTTTTTTP  T   D
DTTTTTTTTTP  T   D
DTTTTT    P  T   D
DT   T    P  T   D
DT   T   TP  T   D
DT  OTTTTTTg TTTTD
D   O            D
D   O            D
D   O     g      D
DT  OTTT gTTTTTTTD
DT   T    T      D
DT   T    T      D
DTTTTT    T      D
DT        T      D
DT        T      D
DDDDDTTT  T      D
DDDDDTTT  T      D
DDDDDTTT  T      D
DDDDDTTT  TTTTTTTD
DDDDDTTT         D
DDDDDTTT  g      D
DDDDDTTT gTTTTTTTD
LLLLDTTT  T      D
    DTTT  T      D
    DTTT  T      D
    DTTT  T      D
    DTTT  T      D
    DDDDDDDDDDDDDD
|----Layer 8|
    DDDDDDDDDDDDDD
    DDDDDDDDDDDDDD
    DDDDDDDD DDDDD
    DDDDDDDDDDDDDD
    DDDDDDDDDDDDDD
    DDDDDDDDDDDDDD
    DDDDDDDDDDDDDD
    DDDDDDDDDDDDDD
LLLLDDDDDDDDDDDDDD
DDDDDDDDDDDDDDDDDD
DDDDDDDDDDDDDDDDDD
DDDDDDDDDDDDDDDDDD
DDDDDDDDDDDDDDDDDD
DDDDDDDDDDDDDDDDDD
DDDDDDDDDDDDDDDDDD
DDDDDDDDDDDDDDDDDD
DDDDDDDDDDDDDDDDDD
 DDDDDDDDDDDDDDDDD
 KKKKIIIDDDDDDDDDD
 LLLIHHHHTTTTTTTTD
 LLLHHHHHTTTTTTTTD
 LLLLKIHHTTTTTTTTD
 KKKKKLKDDDDDDDDDD
 DDDDDDDDDDDDDDDDD
DDDDDDDDDDDDDDDDDD
DDDDDDDDDDDDDDDDDD
DDDDDDDDDDDDDDDDDD
DDDDDDDDDDDDDDDDDD
DDDDDDDDDDDDDDDDDD
DDDDDDDDDDDDDDDDDD
DDDDDDDDDDDDDDDDDD
DDDDDDDDDDDDDDDDDD
LLLLDDDDDDDDDDDDDD
    DDDDDDDDDDDDDD
    DDDDDDDDDDDDDD
    DDDDDDDDDDDDDD
    DDDDDDDDDDDDDD
    DDDDDDDDDDDDDD
    DDDDDDDDDDDDDD
    DDDDDDDDDDDDDD
    DDDDDDDDDDDDDD
|----Layer 9|
    DDDDDDDDDDDDDD
    DDDDDDDDDDDDDD
    DDDDDDDDDDDDDD
    DDDDDDDDDDDDDD
    DDDDDDDDDDDDDD
    DDDDDDDDDDDDDD
    DDDDDDDDDDDDDD
    DDDDDDDDDDDDDD
    DDDDDDDDDDDDDD
    DDDDDDDDDDDDDD
    DDDDDDDDDDDDDD
LLLLDDDDDDDDDDDDDD
NDDDDDDDDDDDDDDDDD
NNDDDDDDDDDDDDDDDD
DDDDDDDDDDDDDDDDDD
DDDDDDDDDDDDDDDDDD
DDDDDDDDDDDDDDDDDD
   DDDKKDDDDDDDDDD
        IDDDDDDDDD
         IDDDDDDDD
         nDDDDDDDD
         IDDDDDDDD
        IDDDDDDDDD
   DDDDDDDDDDDDDDD
DDDDDDDDDDDDDDDDDD
DNDDDDDDDDDDDDDDDD
NDDDDDDDDDDDDDDDDD
NDDDDDDDDDDDDDDDDD
DDDDDDDDDDDDDDDDDD
LLLLDDDDDDDDDDDDDD
    DDDDDDDDDDDDDD
    DDDDDDDDDDDDDD
    DDDDDDDDDDDDDD
    DDDDDDDDDDDDDD
    DDDDDDDDDDDDDD
    DDDDDDDDDDDDDD
    DDDDDDDDDDDDDD
    DDDDDDDDDDDDDD
    DDDDDDDDDDDDDD
    DDDDDDDDDDDDDD
    DDDDDDDDDDDDDD
|----Layer 10|
                  
                  
                  
          TTTTTTTT
         TTTTTTTTT
         TTTTTTTTT
         TTTTTTTTT
         TTTTTTTTT
        ATTTTTTTTT
       AATTTTTTTTT
      AAATTTTTTTTT
      ALDTTTSSSTTT
    LLLDDTTTSSSTTT
   LDDDDDTTTSSSTTT
   TDDDDDTTTSSSTTT
  ATCDDDDDDDSSSTTT
  AAADDDDDDDSSSDDD
   AAKKKKKDDSSSDDD
         KKDSSSDDD
          KDSSSDDD
          KDSSSDDD
          KDSSSDDD
         KKDSSSDDD
    AKKKKKDDSSSDDD
   AADDDDDDDSSSDDD
  ATCDDDDDDDSSSDDD
  ATCCCCCDDDSSSDDD
    AAAAADDDSSSDDD
      A ATTTSSSTTT
      AAATTTSSSTTT
      AAATTTTTTTTT
       AATTTTTTTTT
        ATTTTDTTTT
         TTDDDDDDD
         TTTTTDDDD
         TTTTTTTTD
         TTTTTTTTT
         TTTTTTTTT
         TTTTTTTTT
                 E
                 E
|----Layer 11|
                  
                  
                  
                  
          TTTTTT  
          T     T 
          T     T 
          T     T 
          T     T 
          T     T 
                  
        A   FFF   
       AA   FFF   
     A AA   FFF   
    JDDDD   FFF   
    JCCDC   FFF   
       A    FFF   
            FFF   
            FFF   
            FFF   
            FFF   
            FFF   
            FFF   
            FFF   
     AA     FFF   
    JDDDD   FFF   
    JDDDD   FFF   
            FFF   
            FFF   
            FFF   
                  
          TTTTTTT 
          T     T 
          T     T 
          T     T 
          T     T 
          T     T 
          TTTTTTT 
                  
                  
                  
|----Layer 12|
                  
                  
                  
                  
                  
            DDDD  
           CDDDD  
           CDDDD  
           CDDDD  
           CDDDD  
           CDDDD  
           CCCCC  
           CCCCC  
           CCCCC  
    AA     CCCCC  
    AA     CCCCC  
           CCCCC  
           CCCCC  
           DDDDD  
           DDDDD  
            DDDD  
            DDDD  
           DDDD   
           DDDDD  
           DDDDD  
    AAA    DDDDD  
    AA     DDDDD  
           DDDDD  
           DDDDD  
           DDDDD  
            DDDD  
            DDDD  
            DDDD  
           DDDDT  
           DDDDD  
           DDDDD  
            DDDD  
                  
                  
                  
                  
|----Layer 13|
                  
                  
                  
                  
                  
           CDDDD  
           CDDDD  
           CDDDD  
           CDDDD  
           DDDDD  
           DDDDD  
           DDDDD  
           DDDDD  
           CDDDD  
           CCCDD  
           CCCCC  
           CCCCC  
           CCCCC  
           DDDDD  
           DDDDD  
           DDDDD  
           DDDDD  
           DDDDD  
           DDDDD  
           DDDDD  
           DDDDD  
           DDDDD  
           DDDDD  
           DDDDD  
           DDDDD  
           DDDDD  
            DDDD  
            DTTT  
           DTTTT  
           DDDTT  
           DDDDD  
           DDDDD  
                  
                  
                  
                  
|----Layer 14|
                  
                  
                  
                  
                  
            DDDD  
           CDDDD  
           DDDDD  
           DDCCC  
           CCCCD  
           DDDDD  
           DDDDD  
           DDDDD  
           DDDDD  
           DDDDD  
            DDDD  
            DDDD  
           DDDDD  
           DDDDD  
           DDDDD  
           DDDDD  
           DDDDD  
           DDDDD  
           DDDDD  
           DDDDD  
           DDDDD  
           DDDDD  
           DDDDD  
           DDDDD  
           DDDDD  
           DDDDD  
            TTTD  
           TTTTT  
           TTTTT  
           TTTTT  
           DDDDD  
           DDDDD  
                  
                  
                  
                  
|----Layer 15|
                  
                  
                  
                  
                  
                  
           DDDDD  
           DDDDC  
           DCCCC  
           CCCCC  
           CCCCD  
           DDDDD  
           DDDDD  
           DDDDD  
           DDDDD  
           DDDDD  
           DDDDD  
           DDDDD  
           DDDDD  
           DDDDD  
           DDDDD  
           DDDDD  
           DDDDD  
           DDDDD  
           DDDDD  
           DDDDD  
           DDDDD  
           DDDDD  
           DDDDD  
           DDDDD  
           DDDDD  
           DDDD   
           TTDDD  
           TTTTT  
            TTTT  
            DDDD  
              DD  
                  
                  
                  
                  
|----Layer 16|
                  
                  
                  
                  
                  
             DDD  
           DDDDD  
           DDCCC  
            CCC   
           CCCC   
           TCCCT  
           TCCTT  
           TTTTT  
           TTTTT  
           TTTTT  
           TTTTT  
           TTTTT  
           TTTTT  
           TTTTT  
           TTTTT  
           TTTTT  
           TTTTT  
           TTTTT  
           TTTTT  
           TTTTT  
           TTTTT  
           TTTTT  
           TTTTT  
           TTTTT  
           TTTTT  
           TTTTT  
           TTTTT  
            TTTD  
           TDDDD  
           DDDDD  
           DDDDD  
           DDDDD  
                  
                  
                  
                  
|----Layer 17|
                  
                  
                  
                  
                  
           DDD    
           DDDDD  
           DDDCC  
            CCC   
           TCCCT  
           TCCCT  
            CTC   
           TCCCT  
           TCCTT  
            TTT   
             TT   
           TTTTT  
           TTTTT  
            TTT   
            TTT   
           TTTTT  
           TTTTT  
            TTT   
            TTT   
           TTTTT  
           TTTTT  
            TTT   
            TTT   
           TTTTT  
           TTTTT  
            TTT   
           TTTTT  
           TTTTT  
           DDDDD  
           DDDDD  
           DDDDD  
            DDDD  
                  
                  
                  
                  
|----Layer 18|
                  
                  
                  
                  
                  
           DDDDD  
           DDDDD  
           DDDDD  
           DTTTD  
           TTTTT  
           T R T  
             R    
             R    
             R    
             R    
             R    
             R    
             R    
             R    
             R    
             R    
             R    
             R    
             R    
             R    
             R    
             R    
             R    
             R    
             R    
             R    
           T R T  
           TTTTT  
           DDDDD  
           DDDDD  
           DDDDD  
            DDDD  
                  
                  
                  
                  
|----Layer 19|
                  
                  
                  
                  
                  
           CCDDD  
           DDDDD  
           DDDDD  
           DTTTD  
           TTTTT  
             R    
                  
                  
                  
                  
                  
                  
                  
                  
                  
                  
                  
                  
                  
                  
                  
                  
                  
                  
                  
                  
             R    
           TTTTT  
           DDDDD  
           DDDDD  
           DDDDD  
           DDDDD  
                  
                  
                  
                  
|----Layer 20|
                  
                  
                  
                  
                  
           CCCCC  
           CCCDD  
           DDDDD  
           TTTTT  
           TTTTT  
             R    
                  
                  
                  
                  
                  
                  
                  
                  
                  
                  
                  
                  
                  
                  
                  
                  
                  
                  
                  
                  
             R    
           TTTTT  
           TDDDT  
           DDDDD  
           DDDDD  
           CCCDD  
                  
                  
                  
                  
|----Layer 21|
                  
             CC   
            CCC   
             CC   
            CCC   
           CCCCC  
           CCCDD  
           DDDDD  
           TTTTT  
            TTT   
             R    
                  
                  
                  
                  
                  
                  
                  
                  
                  
                  
                  
                  
                  
                  
                  
                  
                  
                  
                  
                  
             R    
            TTT   
           TDDDT  
           DDDDD  
           CCDDD  
           CCCCC  
            CCC   
            CCC   
            CCC   
                  
|----Layer 22|
                  
            CCC   
            CCC   
            CCC   
            CCC   
           CCCCC  
            CCDD  
           DDDDD  
           TTTTT  
            TTT   
             R    
                  
                  
                  
                  
                  
                  
                  
                  
                  
                  
                  
                  
                  
                  
                  
                  
                  
                  
                  
                  
             R    
            TTT   
           TDDDT  
           DDDDD  
           CCDDD  
           CCCCC  
            CCC   
            CCC   
            CCC   
            CCC   
|----Layer 23|
                  
             CC   
            CCC   
                  
                  
           CCCCC  
           CCDDD  
           DDDDD  
           TTTTT  
           TTTTT  
             R    
                  
                  
                  
                  
                  
                  
                  
                  
                  
                  
                  
                  
                  
                  
                  
                  
                  
                  
                  
                  
             R    
           TTTTT  
           TDDDT  
           DDDDD  
           CCDDD  
            CCCC  
                  
                  
            CCC   
            CCC   
|----Layer 24|
                  
            CCC   
             CC   
                  
                  
           CCCCC  
           CCCDD  
           DDDDD  
           DTTTD  
           TTTTT  
             R    
                  
                  
                  
                  
                  
                  
                  
                  
                  
                  
                  
                  
                  
                  
                  
                  
                  
                  
                  
                  
             R    
           TTTTT  
           DDDDD  
           DDDDD  
           CDDDD  
           CCCCC  
                  
                  
            CCC   
            CCC   
|----Layer 25|
                  
            CCC   
            CCC   
            CCC   
            CCC   
           CCCCC  
           CCCCD  
           DDDDD  
           DTTTD  
           DTTTT  
           T R T  
             R    
             R    
             R    
             R    
             R    
             R    
             R    
             R    
             R    
             R    
             R    
             R    
             R    
             R    
             R    
             R    
             R    
             R    
             R    
             R    
           T R T  
           DTTTD  
           DDDDD  
           DDDDD  
           DDDDD  
           CCCCD  
            CCC   
            CCC   
            CCC   
            CCC   
|----Layer 26|
                  
             CC   
            CCC   
            CCC   
             CC   
            CCCC  
           CCCCD  
           DDDDD  
           DTTTD  
           DDTTD  
           DTTTT  
           TTTTT  
           TTTTT  
           TTTTT  
            TTT   
            TTT   
           TTTTT  
           TTTTT  
            TTT   
            TTT   
           TTTTT  
           TTTTT  
            TTT   
            TTTT  
           TTTTT  
           TTTTT  
            TTT   
            TTT   
           TTTTT  
           TTTTT  
           TTTTT  
           DTTT   
           DTTT   
           DDDDD  
           DDDDD  
           DDDDD  
           CCCDD  
            CCC   
            CCC   
            CCC   
             CC   
|----Layer 27|
                  
                  
                  
                  
                  
           CCCCC  
           CCCDD  
           DDDDD  
           D TTD  
           DTTTD  
           DTTTD  
           DTTTD  
           DTTTD  
           DTTTD  
           DTTTD  
           DTTTD  
           DTTTD  
           DTTTD  
           DTTTD  
           DTTTD  
           DTTTD  
           DTTTD  
           DTTTD  
           DTTTD  
           DTTTD  
           DTTTD  
           DTTTD  
           DTTTD  
           DTTTD  
           DTTTD  
           DTTTD  
           DTTT   
           DTTT   
            DDDD  
           DDDDD  
           DDDDD  
           DDDDD  
                  
                  
                  
                  
|----Layer 28|
                  
                  
                  
                  
                  
           CCCCC  
           CDDDD  
           DDDDD  
           DDDDD  
           DDDDD  
           DDDDD  
           DDDDD  
           DDDDD  
           DDDDD  
           DDDDD  
           DDDDD  
           DDDDD  
           DDDDD  
           DDDDD  
           DDDDD  
           DDDDD  
           DDDDT  
           TTTTT  
           TTTTT  
           TTTTT  
           DDDDD  
           DDDDD  
           DDDDD  
           DDDDD  
           DDDDD  
           DDDDD  
           DDDDD  
            DDDD  
            DDDD  
           TTTTT  
           DDDDD  
           DDDDD  
                  
                  
                  
                  
|----Layer 29|
                  
                  
                  
                  
                  
           CCCCC  
           DDDDD  
            DDDD  
           DDDDD  
           DDDDD  
           DDDDD  
           DDDDD  
           DDDDD  
           DDDDD  
           DDDDD  
           DDDDD  
           DDDDD  
           DDDDD  
           DDDDD  
           DDDDD  
           DDDDD  
           DDDDD  
           DDDDD  
           DDDDT  
           TTTDD  
           DDDDD  
           DDDDD  
           DDDDD  
           DDDDD  
           TTTTD  
           DDDDD  
           DDDDD  
            DDDD  
            TTTT  
           TTTTT  
             TTT  
              DT  
                  
                  
                  
                  
|----Layer 30|
                  
                  
                  
                  
                  
            DDDD  
           DDDDD  
           DDDDD  
            DDDD  
           DDDDD  
           DDDDD  
           DDDDD  
           DDDDD  
           DDDDD  
           DDDDD  
           DDDDD  
           DDDDD  
           DDDDD  
           DDDDD  
           DDDDD  
           DDDDD  
           DDDDD  
           DDDDD  
           DDDDD  
           DDDDD  
           TTTTT  
           TTTTT  
           TTTTT  
           TTTTT  
           TTTTT  
           TTTTT  
           TTTTT  
           TTTTT  
           TTTTT  
           TTTTT  
                  
                  
                  
                  
                  
                  
|----Layer 31|
                  
                  
                  
                  
                  
             DDD  
           DDDDD  
           DDDDD  
           D  DD  
            DD D  
            KD D  
           D DDD  
           DDDDD  
           DDDD   
                  
             D    
               D  
           DDDDD  
             DD   
              D   
           DDDDD  
           DDDDD  
           DDDDD  
           DDDTT  
           TTTTT  
           TTTTT  
           TTTTT  
            TTTT  
            TTTT  
           TTTTT  
           TTTTT  
           TT TT  
           TTTTT  
           TTTTT  
            TTT   
                  
                  
                  
                  
                  
                  
}}