<noinclude>{{structure info}}</noinclude>
[[File:Ancient City small ruin 1.png|thumb|Small Ruin 1 (Deep Dark)]]

{{layered blueprint|name=Small Ruin 1|default=Layer 1
|C=Cobbled Deepslate
|----Layer 1|
C CCC C
       
       
       
       
C     C
C      
CC   CC
|----Layer 2|
       
       
       
       
       
       
C      
CC     
|----Layer 3|
       
       
       
       
       
       
       
C       
}}