<noinclude>{{structure info}}</noinclude>
[[File:Ancient City large pillar 1.png|thumb|Large Pillar 1 (Deep Dark)]]

{{layered blueprint|name=Ancient City Large Pillar 1 |default=Layer 1
|D=Deepslate
|P=Polished Deepslate
|T=Deepslate Tiles
|C=Chiseled Deepslate
|S=Deepslate Tile Stairs
|----Layer 1|
DDDDDD
DDDDDD
DDDDDD 
DDDDDD
DDDDDD
DDDDDD
|----Layer 2|
SSSSSS
SDDDDS
SDDDDS
SDDDDS
SDDDDS
SSSSSS
|----Layer 3|
      
 DDDD 
 DDDD 
 DDDD 
 DDDD 
      
|----Layer 4|
      
 SSSS 
 SPPS 
 SPPS 
 SSSS 
      
|----Layer 5|
      
 PPPP 
 PPPP 
 PPPP 
 PPPP 
      
|----Layer 6|
      
 CTTC 
 TPPT 
 TPPT 
 CTTC 
      
|----Layer 7|
      
 PPPP 
 PPPP 
 PPPP 
 PPPP 
      
|----Layer 8|
      
 TCCT 
 CPPC 
 CPPC 
 TCCT 
      
|----Layer 9|
      
 PPPP 
 PPPP 
 PPPP 
 PPPP 
      
|----Layer 10|
      
 CTTC 
 TPPT 
 TPPT 
 CTTC 
      
|----Layer 11|
      
 PPPP 
 PPPP 
 PPPP 
 PPPP 
      
|----Layer 12|
      
 SSSS 
 SPPS 
 SPPS 
 SSSS 
      
|----Layer 13|
      
 DDDD 
 DDDD 
 DDDD 
 DDDD 
      
|----Layer 14|
SSSSSS
SDDDDS
SDDDDS
SDDDDS
SDDDDS
SSSSSS
|----Layer 15|
DDDDDD
DDDDDD
DDDDDD
DDDDDD
DDDDDD
DDDDDD
}}