<noinclude>{{structure info}}</noinclude>
[[File:Bastion Remnant rampart 0.png|thumb|Rampart 0]]
====Materials====
{| class="wikitable sortable mw-collapsible"
|-
!Name !!Layer 1 !!Layer 2 !!Layer 3 !!Layer 4 !!Layer 5 !!Layer 6 !!Layer 7 !!Layer 8 !!Layer 9 !!Layer 10 !!Layer 11 !!Layer 12 !!Layer 13 !!Layer 14 !!Layer 15 !!Layer 16 !!Layer 17 !!Layer 18 !!Layer 19 !!Layer 20 !!Layer 21 !!Layer 22 !!Total
|-
| {{BlockSprite|Polished-Blackstone-Bricks|link=Polished Blackstone Bricks|text=Polished Blackstone Bricks}} || ? || ... 2954
|-
| {{BlockSprite|Blackstone|link=Blackstone|text=Blackstone}} || ? || ... 491
|-
| {{BlockSprite|Basalt|link=Basalt|text=Basalt}} || ? || ... 235
|-
| {{BlockSprite|Cracked-Polished-Blackstone-Bricks|link=Cracked Polished Blackstone Bricks|text=Cracked Polished Blackstone Bricks}} || ? || ... 89
|-
| {{BlockSprite|Polished-Blackstone-Brick-Stairs|link=Polished Blackstone Brick Stairs|text=Polished Blackstone Brick Stairs}} || ? || ... 15
|-
| {{BlockSprite|Blackstone-Stairs|link=Blackstone Stairs|text=Blackstone Stairs}} || ? || 1
|-
| {{BlockSprite|Chest|link=Chest|text=Chest}} || ? || ... 1
|-
| {{BlockSprite|Gilded-Blackstone|link=Gilded Blackstone|text=Gilded Blackstone}} || ? || ... 1
|}

==== Blueprint ====
{{layered blueprint
|name=Bridge rampart 0
|default=Layer 1
|P=Polished Blackstone Bricks
|B=Blackstone
|A=Basalt
|C=Cracked Polished Blackstone Bricks
|S=Polished Blackstone Brick Stairs
|R=Blackstone Stairs
|L=Chest
|G=Gilded Blackstone
|----Layer 1|
PPBBBBBBBBBBB  B
PPBBBBBBBBBBB  B
PPBBBBBBBBBBBBBB
PPBBBBBBBBBBBBBB
PPBBBBBBBBBBBBBB
PPBBBBBBBBBBBBBB
BBBBBBBBBBBBBBBB
BBBBBBBBBBBBBBBB
BBBBBBBBBBBBBBBB
BBBBBBBBBBBBBBBB
BBBBBBBBBBBBBBBB
BBBBBBBBBBBBBBBB
BBBBBBBBBBBBBBBB
BBBBBBBBBBBBBBBB
BBBBBBBBBBBBBBBB
BBBBBBBBBBBBBBBB
|----Layer 2|
PPPPPBBBBBBB    
PPPPPBBBBBBB    
PPPPPBBBBBBB    
PPPPPBBBBBBB    
PPPBPBBBBBBBBBBB
PPPBBBBBBBBBBBBB
BBBBBBBBBBBBBBBB
BBBBBBBBBBBBBBBB
BBBBBBBBBBBBBBBB
BBBBBBBBBBBBBBBB
BBBBBBBBBBBBBBBB
BBBBBBBBBBBBBBBB
BBBBBBBBBBBBBBBB
BBBBBBBBBBBBBBBB
BBBBBBBBBBBBBBBB
BBBBBB BBBBBBBBB
|----Layer 3|
CPPPPPPPPPP     
CPPPPPPPPPP     
}}