<noinclude>{{structure info}}</noinclude>
[[File:Bastion Remnant bridge.png|thumb|Bridge]]
====Materials====
{| class="wikitable sortable mw-collapsible"
|-
!Name !!Layer 1 !!Layer 2 !!Layer 3 !!Layer 4 !!Layer 5 !!Layer 6 !!Layer 7 !!Layer 8 !!Layer 9 !!Layer 10 !!Layer 11 !!Layer 12 !!Layer 13 !!Layer 14 !!Layer 15 !!Layer 16 !!Layer 17 !!Layer 18 !!Layer 19 !!Total
|-
| {{BlockSprite|polished-blackstone-bricks|link=Polished Blackstone Bricks|text=Polished Blackstone Bricks}} || 67 || 42 || 42 || 174 || 96 || 29 || 24 || 25 || 28 || 233 || 201 || 175 || 163 || 74 || 6 || 4 || 1 || - || - || 1384
|-
| {{BlockSprite|blackstone|link=Blackstone|text=Blackstone}} || 4 || 20 || 21 || 21 || 79 || 2 || 2 || 1 || 1 || - || 20 || 38 || 38 || 67 || 1 || 1 || - || - || - || 316
|-
| {{BlockSprite|basalt|link=Basalt|text=Basalt}} || - || - || - || - || 1 || 1 || - || - || 1 || - || 45 || 45 || 46 || 16 || - || - || - || - || - || 155
|-
| {{BlockSprite|polished-basalt|link=Basalt|text=Polished Basalt}} || - || - || - || - || - || - || - || - || - || - || - || - || - || 2 || 16 || 10 || 13 || 4 || - || 45
|-
| {{BlockSprite|block-of-gold|link=Block of Gold|text=Block of Gold}} || - || - || - || - || - || - || - || - || - || - || - || - || - || - || - || - || - || 9 || 7 || 16
|-
| {{BlockSprite|polished-blackstone-brick-stairs|link=Stairs|text=Polished Blackstone Brick Stairs}} || - || - || - || - || - || - || - || - || - || - || - || - || - || - || - || - || 8 || - || - || 8
|-
| {{BlockSprite|iron-chain|link=Iron Chain|text=Iron Chain}} || - || - || - || - || - || - || - || - || 5 || - || - || - || - || - || - || - || - || - || - ||5
|-
| {{BlockSprite|lantern|link=Lantern|text=Lantern}} || - || - || - || - || - || - || - || 5 || - || - || - || - || - || - || - || - || - || - || - || 5
|-
| {{BlockSprite|chiseled-polished-blackstone|link=Chiseled Polished Blackstone|text=Chiseled Polished Blackstone}} || - || - || - || - || - || - || - || - || - || - || - || - || - || - || - || 4 ||  - || - || - || 4
|-
| {{BlockSprite|block-of-quartz|link=Block of Quartz|text=Block of Quartz}} || - || - || - || - || - || - || - || - || - || - || - || - || - || 4 || - || - || - || - || - || 4
|-
| {{BlockSprite|smooth quartz|link=Smooth Quartz Block|text=Smooth Quartz Block}} || - || - || - || - || - || - || - || - || - || - || - || - || - || 2 || - || - || - || - || - || 2
|-
| {{BlockSprite|smooth-quartz-slab|link=Slab|text=Smooth Quartz Slab}} || - || - || - || - || - || - || - || - || - || - || - || - || - || - || - || - || - || 2 || - || 2
|}

==== Blueprint ====
{{layered blueprint
|name=Bridge bridge
|default=Layer 1
|B=Polished Blackstone Bricks
|S=Blackstone
|A=Basalt
|O=Polished Basalt
|G=Block of Gold
|T=Polished Blackstone Brick Stairs
|C=Iron Chain
|L=Lantern
|P=Chiseled Polished Blackstone
|Q=Block of Quartz
|Z=Smooth Quartz Block
|U=Smooth Quartz Slab
|----Layer 1|
                
                
                
                
   BBBBBBBBBBBBB
   BSS BBBBBBBB 
       BBSSBBBB 
                
                
                
                
                
                
                
                
                
                
                
                
                
                
                
 BBBBBBBBBBBBB  
 BBBBBBBBBBBBB  
 BBBBBBBBBBBBB  
                
                
                
                
                
                
|----Layer 2|
                
                
                
                
  BBBBBBBBBBBBB 
    SSSBBBBBBBB 
       SSSSBBBB 
                
                
                
                
                
                
                
                
                
                
                
                
                
                
                
 BBSBSBSSBB B   
 BBSBBBSSB      
 BBBB SSS SSS   
                
                
                
                
                
                
|----Layer 3|
                
                
                
                
 BBBBBBBBBBBBBBB
 B BBSSBBBBBBBBB
   SS SSSSSBBBB 
                
          S     
                
                
                
                
                
                
                
                
                
                
                
                
       S        
 BBS SSSS  B    
 BBBSS SSS      
 BBBBB          
                
                
                
                
                
                
|----Layer 4|
      BBBBBB    
     BBB BBBB   
     BBB BBBB   
     BBBBBBBB   
 BBB BBBBBBBB BB
 BBB BBBBBBBB BB
  SB BBBBBBBB BB
     BBBBSSBB   
       B SBB    
         SB     
        SSB     
        SS      
      BSSS      
     BBSSB      
     BBSSB      
      BSSBB     
       SBBBB    
       BBBBBB   
       BBBBBB   
       B   BB   
       BB  BB   
       BB BB    
 BBS  SBBBB     
 BBB  BBBBB     
 BBB BBBBBBB    
     BBB        
     BBB        
     BBBBBBBB   
     BBBBBBBB   
     BBBBBBBB   
      BBBBBBB   
|----Layer 5|
       BBBSS    
        BBSB    
         BBBS   
      BSSBSBB   
 BBB B SSSBSB BB
  BB BSBSSSSB BB
  BB SSSSSBB  BB
     SBSBBSB    
        SBB     
        BSB     
        SBB     
        SBB     
      SSSB      
     SBSSS      
     SSSBB      
      B BBB     
       SBSS     
       SSBSB    
       SBBSB    
       SS  SB   
       SS   B   
       BS  SB   
 BBB   BSSSS    
 BBB  SBSSS     
 BAB SBSSSS     
     BSS   S    
     BSS        
     SSSSBSBB   
     SSSBBBB    
      BBBBBBB   
       BB BBB   
|----Layer 6|
                
                
                
                
 BBB    BB    BB
 BBB    BB    BB
 BBB          B 
                
                
                
                
                
                
                
                
                
                
                
                
                
                
                
 BBB    SB      
 BBB    BB      
 ASB     B      
                
                
                
                
                
                
|----Layer 7|
                
                
                
                
 BBB    B     BB
 BB     B     BB
 BB           BB
                
                
                
                
                
                
                
                
                
                
                
                
                
                
                
 BBB    B       
 BBB    BS      
 SB             
                
                
                
                
                
                
|----Layer 8|
                
    L        L  
                
                
 BBB    B     BB
 BB     B     BB
 B      B     BB
                
                
                
    L           
                
                
                
                
                
                
                
    L        L  
                
                
                
 BBB    BB      
 B B    B       
 BSB            
                
                
                
                
                
                
|----Layer 9|
                
    C        C  
                
                
 BBB    B     BB
 BB     BB    BB
        BB    BB
                
                
                
    C           
                
                
                
                
                
                
                
    C        C  
                
                
                
 BBB    BB      
 BBB    BB      
 A S    BB      
                
                
                
                
                
                
|----Layer 10|
      BBBBBBB   
    BBBBBBBBBB  
     BBBBBBBBB  
     BBBBBBBBB  
 BBBBBBBBBBB BBB
 BB BBBBBBBB BBB
    B BBBBBB BBB
       BBBBB    
       BBBBB    
      BBBBBB    
    BBBBBBBB    
    BBBBBBBB    
    BBBBBBBBB   
    BBB   BBBB  
    BBB   BBBB  
    BB    BBBB  
    BB     BBB  
    BB     BBB  
    BB     BBB  
    BBB  BBBBB  
    BBBB BBBBB  
    BBBBBBBBBB  
 BBBBB  BBBBBB  
 BBBB   BBBBBB  
 B BB   BBBBBB  
    B BBBBBBBB  
    BBBBBBBBBB  
    BBBBBBBB B  
                
                
                
|----Layer 11|
     BBBBBSSS   
    BBBBBBSS B  
    BBBBBBBBBB  
    BBBBBBBBBB  
 BBBBBBBBBBBBBBB
 BBBBBBBBBBB BBB
    BBBBBBBBBBBS
    B BBBBBBBB  
    B BBBBAA    
    BBBBBBAAAA  
    BBBBBBAAA   
    ABBBBBAAAA  
    ABBSS AAAS  
    BBB   AAAS   
    BBS    AAS  
    ABS   AAAS  
    BBBB   AAS  
    BBBB BAAASB 
    BBBBBBAAAA  
    ABBBBBAAAA  
    BBBBBBAAAA  
    BBBBBBBBBB  
 BBBBS BBBBBBB  
 BBBB   BBBBB   
 BBBS   BBBBBB  
    S  BBBBBBB  
    BBSBBBBBBB  
    BBBBBBBB    
                
                
                
|----Layer 12|
     BBBBS      
    BBBBBB   B  
    BBBBBBBBBB  
    SSBBBBBBBB  
 BBBSSSBBBBBBBBB
 BBBSSSBBBBBBBBB
    BSBBBBBBBBBS
    BBBBBBBBBB  
    BBBBBBAAAS  
    BBBBBBAAAA  
    ABBBBBAAA   
    ABSBBBAAAA  
     BSSSSAAA   
    ASSS   AA   
    BSS    AA   
    AS     AS   
    ABBB   AS  
    BBBB   AAS 
    ABBBBBAAAA  
    ABBBBBAAAA  
    BBBBBBAAAA  
    BBBBBBBBB   
 BBBBS BBBBBBB  
 BBBS  SBBBBBB  
 BBB   SBBBBBB  
    S  BBBBBBB  
    BS BBBBBBB  
    BBSSSSSSB   
                
                
                
|----Layer 13|
    BBSBBS      
    BBBBBS   S  
    BSSSBBBB B  
BBBB  SSBBBBBBBB
BBBB   SBBBBBBBB
BBBB   SBBBBBBBB
 BBBS SBBBBBBBBB
    SSBBBBSBBBSS
    BBBBBBAAAA  
    BBSSBBAAAA  
    ABSSSBAAA   
      SSSBAAA   
        SSAAA   
           AA   
    A      AA   
    A      A    
    AB     AA   
    ABB    AA   
    ABBBB AAAA  
    ABBBBBAAAA  
    ABBBBBAAAA  
BBBBBBBBBBBBBB  
BBBBB  BBSBBBB  
BBBBS   BBBBBB  
 BBB   SBBBBBB  
  SB   SBBBBBBB 
    B  BBBBB B  
    BBSSSSSS    
    B           
                
                
|----Layer 14|
    B  SSS      
    B   SS      
        BBSS    
BBBB    BBS   BB
BBBB    SB   BQQ
BBBB    SB OBBQQ
BBBB    SB  BBZZ
   B    B  SBBSS
    B   S  BBA  
    AS  S  SA   
     S    SSA   
     A   BSB    
         BSA    
          AS    
           S    
                
     A     S    
    SB     S    
    ABSS   A    
    ASSSB   AA  
    ABSS  SSAA  
BBBBBSSS  S SB  
BBBBS S   BSBB  
BBBB    SBSSS   
  BBS   SBS SB  
   SS   SBSBBO  
       SSBSSB   
      SSSSSS    
     B          
                
                
|----Layer 15|
                
                
                
                
 OOO          OO
 OOO          OO
 OOO          OO
                
                
                
                
                
                
                
                
                
                
                
                
                
                
            O   
 BBB            
 BBB            
   S            
                
                
                
                
                
                
|----Layer 16|
                
                
                
                
 OO            O
 OO            O
 OO           OO
                
                
                
                
                
                
                
                
                
                
                
                
                
                
                
 BPB            
 PBP            
 BPS            
                
                
                
                
                
                
|----Layer 17|
                
                
                
                
 OOO          OO
 OO            O
 OOO          OO
                
                
                
                
                
                
                
                
                
                
                
                
                
                
                
 TTT            
 TBT            
 TTT            
                
                
                
                
                
                
|----Layer 18|
                
                
                
                
              OO
               O
               O
                
                
                
                
                
                
                
                
                
                
                
                
                
                
                
 GGGU           
 GGG            
 GGGU           
                
                
                
                
                
                
|----Layer 19|
                
                
                
                
                
                
                
                
                
                
                
                
                
                
                
                
                
                
                
                
                
                
  GG            
  GGG           
  GG            
                
                
                
                
                
                
}}