<noinclude>{{structure info}}</noinclude>
[[File:Bastion Remnant plate 0.png|thumb|Plate 0]]
====Materials====
{| class="wikitable sortable mw-collapsible"
|-
!Name !!Layer 1 !!Layer 2 !!Layer 3 !!Layer 4 !!Layer 5 !!Layer 6 !!Layer 7 !!Layer 8 !!Layer 9 !!Layer 10 !!Layer 11 !!Layer 12 !!Layer 13 !!Layer 14 !!Layer 15 !!Layer 16 !!Layer 17 !!Layer 18 !!Layer 19 !!Total
|-
| {{BlockSprite|Polished-Blackstone-Bricks|link=Polished Blackstone Bricks|text=Polished Blackstone Bricks}} || 6 || 6 || 7 || 8 || 8 || 7 || 24 || 32 || 32 || 27 || 24 || 22 || 17 || 17 || 14 || 7 || 2 || - || - || 260
|-
| {{BlockSprite|Basalt|link=Basalt|text=Basalt}} || - || - || - || - || - || - || - || - || - || - || 1 || 2 || 4 || 4 || 7 || 21 || 23 || 15 || 5 || 82
|-
| {{BlockSprite|Blackstone|link=Blackstone|text=Blackstone}} || - || - || - || - || - || - || - || - || - || - || - || 5 || 8 || 8 || 7 || 4 || 6 || - || - || 38
|-
| {{BlockSprite|Cracked-Polished-Blackstone-Bricks|link=Cracked Polished Blackstone Bricks|text=Cracked Polished Blackstone Bricks}} || 1 || 2 || 1 || - || - || - || - || - || - || 4 || 6 || 3 || 3 || 3 || 3 || - || - || - || - || 26
|}

==== Blueprint ====
{{layered blueprint
|name=Bridge rampart 1
|default=Layer 1
|P=Polished Blackstone Bricks
|A=Basalt
|B=Blackstone
|C=Cracked Polished Blackstone Bricks
|----Layer 1|
P   C  PP  PP  P
                
|----Layer 2|
P  CC  PP  PP  P
                
|----Layer 3|
P  CC  PP  PP  P
                
|----Layer 4|
P  PP  PP  PP  P
                
|----Layer 5|
P  PP  PP  PP  P
                
|----Layer 6|
P  PP   P  PP  P
                
|----Layer 7|
P  PP  PP  PP  P
PPPPPPPPPPPPPPPP
|----Layer 8|
PPPPPPPPPPPPPPPP
PPPPPPPPPPPPPPPP
|----Layer 9|
PPPPPPPPPPPPPPPP
PPPPPPPPPPPPPPPP
|----Layer 10|
P PPPPPPCCPPPPPP
PPPPPPPPCCPPPPPP
|----Layer 11|
PPPPPPCPC PPPPPP
PPAPPPCCCCPPPPPP
|----Layer 12|
PPPPPPBCBCPPPPPP
PCAPPPBABBPPPPPP
|----Layer 13|
CPPPPPBBBBPPPPPP
CAACPPBAABPPPBBP
|----Layer 14|
CPPPPPBBBBPPPPPP
CAACPPBAABPPPBBP
|----Layer 15|
CPPPPP BBBPPPPPP
AAACCABAAAPPBBBP
|----Layer 16|
BPAAAAAAAAPPPPAA
AAAPAAAAAABBBPAA
|----Layer 17|
AAAAPAAAAAPBBBAA
AAAAAAAAAABBB AA
|----Layer 18|
AA    AAAA    AA
AA    AAA     AA
|----Layer 19|
      AAA     A 
      A         
}}