<noinclude>{{structure info}}</noinclude>
[[File:Bastion Remnant back bridge bottom.png|thumb|Back Bridge Bottom]]
====Materials====
{| class="wikitable sortable mw-collapsible"
|-
!Name !!Layer 1 !!Layer 2 !!Layer 3 !!Total
|-
| {{BlockSprite|Polished-Blackstone-Bricks|link=Polished Blackstone Bricks|text=Polished Blackstone Bricks}} || 48 || 26 || 1 || 75
|-
| {{BlockSprite|Blackstone|link=Blackstone|text=Blackstone}} || 3 || 10 || 3 || 16
|}

==== Blueprint ====
{{layered blueprint
|name=Bridge back bridge bottom
|default=Layer 1
|P=Polished Blackstone Bricks
|B=Blackstone
|----Layer1|
         PP        
     PPBBPPP       
     PPPBPPP       
     PPPPPPP       
     PPPPPPP       
     PPPPPPP       
     PPPPPPP       
     PPPPPPP       
|----Layer 2|
       P           
       PPB         
     B PPPB        
     PBP P         
     PPPPBB        
      PPPBBB       
      PPPPBP       
       PPPPP       
|----Layer 3|
                   
                   
                   
                   
       B           
        B          
        B          
        P          
}}