<noinclude>{{structure info}}</noinclude>
[[File:Bastion Remnant back bridge top.png|thumb|Back Bridge Top]]
====Materials====
{| class="wikitable sortable mw-collapsible"
|-
!Name !!Layer 1 !!Layer 2 !!Layer 3 !!Layer 4 !!Total
|-
| {{BlockSprite|Polished-Blackstone-Bricks|link=Polished Blackstone Bricks|text=Polished Blackstone Bricks}} || 25 || 19 || 4 || - || 48
|-
| {{BlockSprite|Blackstone|link=Blackstone|text=Blackstone}} || 8 || 10 || 18 || 4 || 40
|}

==== Blueprint ====
{{layered blueprint
|name=Bridge back bridge top
|default=Layer 1
|P=Polished Blackstone Bricks
|B=Blackstone
|----Layer 1|
                   
                   
                   
                   
         B  B      
     BB  B  B      
   PPPBB P PP      
   PPPPPPP PP      
   PPPPPPPPPP      
|----Layer 2|
                   
                   
           B       
           B       
      B    B       
    P BB  PBB      
   PPPPBP PBP      
   PPPPPPPPPP      
|----Layer 3|
                   
                   
                   
            B      
            B      
     B    PPB      
    BB BB BBB      
   B BBBBPBBP      
|----Layer 4|
                   
                   
                   
                   
                   
                   
     B  B          
      B B          
}}