<noinclude>{{structure info}}</noinclude>
[[File:Bastion Remnant leg 1.png|thumb|Leg 1]]
====Materials====
{| class="wikitable sortable mw-collapsible"
|-
!Name !!Layer 1 !!Layer 2 !!Layer 3 !!Layer 4 !!Layer 5 !!Layer 6 !!Layer 7 !!Layer 8 !!Layer 9 !!Layer 10 !!Layer 11 !!Layer 12 !!Layer 13 !!Layer 14 !!Layer 15 !!Layer 16 !!Layer 17 !!Layer 18 !!Layer 19 !!Layer 20 !!Layer 21 !!Layer 22 !!Total
|-
| {{BlockSprite|Polished-Blackstone-Bricks|link=Polished Blackstone Bricks|text=Polished Blackstone Bricks}} || 9 || 9 || 9 || 8 || 6 || 6 || 6 || 4 || 3 || 4 || 3 || 4 || 4 || 3 || 4 || 4 || 4 || 4 || 7 || 7 || 5 || 7 || 120
|-
| {{BlockSprite|Blackstone|link=Blackstone|text=Blackstone}} || - ||  - || - || 1 || 2 || 2 || 2 || 1 || 2 || 2 || 3 || 1 || 1 || 4 || 4 || 4 || 3 || 2 || 1 || 1 || 2 || - || 38
|}

==== Blueprint ====
{{layered blueprint
|name=Bridge leg 1
|default=Layer 1
|P=Polished Blackstone Bricks
|B=Blackstone
|----Layer 1|
PPP
PPP
PPP
|----Layer 2|
PPP
PPP
PPP
|----Layer 3|
PPP
PPP
PPP
|----Layer 4|
BPP
PPP
PPP
|----Layer 5|
 PP
BPP
BPP
|----Layer 6|
BBP
 PP
PPP
|----Layer 7|
BPP
BPP
PP 
|----Layer 8|
 PP
 PP
B  
|----Layer 9|
BPP
B  
P  
|----Layer 10|
BBP
PP 
P  
|----Layer 11|
BBP
BPP
   
|----Layer 12|
 PB
 PP
 P 
|----Layer 13|
 P 
 PP
BP 
|----Layer 14|
BPB
 PB
BP 
|----Layer 15|
PPB
BPB
 BP
|----Layer 16|
PPB
BPB
 BP
|----Layer 17|
PPB
BBP
  P
|----Layer 18|
PPB
 PB
  P
|----Layer 19|
PPP
PPP
 BP
|----Layer 20|
PPP
PPP
B P
|----Layer 21|
PPP
BPP
  B
|----Layer 22|
PPP
PPP
P  
}}