<noinclude>{{structure info}}</noinclude>
[[File:Bastion Remnant leg 0.png|thumb|Leg 0]]
====Materials====
{| class="wikitable sortable mw-collapsible"
|-
!Name !!Layer 1 !!Layer 2 !!Layer 3 !!Layer 4 !!Layer 5 !!Layer 6 !!Layer 7 !!Layer 8 !!Layer 9 !!Layer 10 !!Layer 11 !!Layer 12 !!Layer 13 !!Layer 14 !!Layer 15 !!Layer 16 !!Layer 17 !!Layer 18 !!Layer 19 !!Layer 20 !!Layer 21 !!Layer 22 !!Total
|-
| {{BlockSprite|Polished-Blackstone-Bricks|link=Polished Blackstone Bricks|text=Polished Blackstone Bricks}} || 9 || 9 || 9 || 9 || 9 || 9 || 9 || 9 || 7 || 5 || 3 || 2 || 1 || 1 || 1 || 1 || - || 1 || 1 || 4 || 8 || 8 || 115
|-
| {{BlockSprite|Blackstone|link=Blackstone|text=Blackstone}} || - || - || - || - || - || - || - || - || 1 || 2 || 6 || 4 || 7 || 6 || 5 || 4 || 2 || 1 || 2 || - || - || - || 40
|}

==== Blueprint ====
{{layered blueprint
|name=Bridge leg 0
|default=Layer 1
|P=Polished Blackstone Bricks
|B=Blackstone
|----Layer 1|
PPP
PPP
PPP
|----Layer 2|
PPP
PPP
PPP
|----Layer 3|
PPP
PPP
PPP
|----Layer 4|
PPP
PPP
PPP
|----Layer 5|
PPP
PPP
PPP
|----Layer 6|
PPP
PPP
PPP
|----Layer 7|
PPP
PPP
PPP
|----Layer 8|
PPP
PPP
PPP
|----Layer 9|
P B
PPP
PPP
|----Layer 10|
BP 
PPB
PP 
|----Layer 11|
BBB
BBB
PPP
|----Layer 12|
   
BBB
BPP
|----Layer 13|
BB 
BBB
BBP
|----Layer 14|
BB 
BBB
PB 
|----Layer 15|
B  
BB 
PBB
|----Layer 16|
   
BB 
PBB
|----Layer 17|
   
 B 
 B 
|----Layer 18|
   
   
PB 
|----Layer 19|
   
 P 
BB 
|----Layer 20|
 PP
 P 
 P 
|----Layer 21|
 PP
PPP
PPP
|----Layer 22|
PPP
PPP
P P
}}