{{structure info}}
== Materials ==

{|class=wikitable data-description="Blocks composing a desert pyramid before 14w03a"
! Block
! Amount
|-
| {{BlockLink|Sandstone}}
| 3078
|-
| {{BlockLink|Cut Sandstone}}
| 189
|-
| {{BlockLink|Orange Wool}}
| 59
|-
| {{BlockLink|Chiseled Sandstone}}
| 34
|-
| {{BlockLink|Sandstone Stairs}}
| 14
|-
| {{BlockLink|TNT}}
| 9
|-
| {{BlockLink|Chest}}
| 4
|-
| {{BlockLink|Sandstone Slab}}
| 2
|-
| {{BlockLink|Blue Wool}}
| 1
|-
| {{BlockLink|Stone Pressure Plate}}
| 1
|}
[[File:Desert pyramid JE1 BE1.png|600px|right]]
== Blueprint ==

{| class="wikitable"
|-
! Layer !! Block !! Coords !! Facing
|-
| -10
| {{BlockSprite|Chest|link=Chest|text=Chest}}
| 
| Pressure Plate
|-
| 11
| {{BlockSprite|Sandstone Stairs|link=Sandstone Stairs|text=Sandstone Stairs}}
| 
| Middle Sandstone
|-
|}

<table><tr><td style="width:550px;">
{{layered blueprint|name=Desert Temple|default=Layer 3
|S=Cut Sandstone|T=TNT|c=Chest|P=Stone Pressure Plate|C=Chiseled Sandstone|O=Sandstone|H=Orange Wool|B=Blue Wool|$=Sandstone Slab|A=Sandstone Stairs
|----Layer -13|
                     
                  
                
            
              
               
                 
                  
        SSSSS        
        SSSSS        
        SSSSS        
        SSSSS        
        SSSSS        
                     
                    
                   
                   
                    
                   
                    
                    
|----Layer -12|
                     
                     
                     
                     
                      
                      
                      
                      
        SSSSS        
        STTTS        
        STTTS        
        STTTS        
        SSSSS        
                     
                    
                     
                  
                   
                   
                  
     
|----Layer -11|
                     
                     
                     
                     
                     
                     
                     
                     
        SSSSS        
        SSSSS        
        SSSSS        
        SSSSS        
        SSSSS        
                     
                     
                     
                     
                     
                     
                     
                     
|----Layer -10|
                     
                     
                     
                     
                     
                     
                     
          S          
        SScSS        
        S   S        
       Sc P cS       
        S   S        
        SScSS        
          S          
                     
                     
                     
                     
                     
                     
  
|----Layer -9|
                     
                     
                     
                     
                     
                     
                    
          C          
        CC CC        
        C   C        
       C     C       
        C   C        
        CC CC        
          C          
                     
                     
                     
                      
                      
                      
                     
|----Layer -8|
                     
                     
                     
                     
                     
                     
                     
                     
        SSSSS        
        S   S        
        S   S        
        S   S        
        SSSSS       
                     
                     
                     
                     
                     
                     
                     
                      
|----Layer -7 to -4|
                     
                     
                     
                     
                     
                     
                     
                     
        OOOOO        
        O   O        
        O   O        
        O   O        
        OOOOO       
                     
                     
                     
                     
                     
                     
                     
                      
|----Layer -3 to 0 (Ground Layer)|
OOOOOOOOOOOOOOOOOOOOO
OOOOOOOOOOOOOOOOOOOOO
OOOOOOOOOOOOOOOOOOOOO
OOOOOOOOOOOOOOOOOOOOO
OOOOOOOOOOOOOOOOOOOOO
OOOOOOOOOOOOOOOOOOOOO
OOOOOOOOOOOOOOOOOOOOO
OOOOOOOOOOOOOOOOOOOOO
OOOOOOOOOOOOOOOOOOOOO
OOOOOOOOO   OOOOOOOOO
OOOOOOOOO   OOOOOOOOO
OOOOOOOOO   OOOOOOOOO
OOOOOOOOOOOOOOOOOOOOO
OOOOOOOOOOOOOOOOOOOOO
OOOOOOOOOOOOOOOOOOOOO
OOOOOOOOOOOOOOOOOOOOO
OOOOOOOOOOOOOOOOOOOOO
OOOOOOOOOOOOOOOOOOOOO
OOOOOOOOOOOOOOOOOOOOO
OOOOOOOOOOOOOOOOOOOOO
OOOOOOOOOOOOOOOOOOOOO
|----Layer 1|
OOOOOOOOOOOOOOOOOOOOO
OOOOOOOOOOOOOOOOOOOOO
OOOOOOOOOOOOOOOOOOOOO
OOOOOOOOOOOOOOOOOOOOO
OOOOOOOOOOOOOOOOOOOOO
OOOOOOOOOOOOOOOOOOOOO
OOOOOOOOOOOOOOOOOOOOO
OOOOOOOOOOHOOOOOOOOOO
OOOOOOOOOOHOOOOOOOOOO
OOOOOOOOOHOHOOOOOOOOO
OOOOOOOHHOBOHHOOOOOOO
OOOOOOOOOHOHOOOOOOOOO
OOOOOOOOOOHOOOOOOOOOO
OOOOOOOOOOHOOOOOOOOOO
OOOOOOOOOOOOOOOOOOOOO
OOOOOOOOOOOOOOOOOOOOO
OOOOOOOOOOOOOOOOOOOOO
OOOOOOOOOOOOOOOOOOOOO
OOOOOOOOOOOOOOOOOOOOO
OOOOOOOOOOOOOOOOOOOOO
OOOOOOOOOOOOOOOOOOOOO
|----Layer 2|
                     
 OOOOOOOOOOOOOOOOOOO 
 O                 O 
 O  S           S  O 
 O                 O 
 O  S           S  O 
 O                 O 
 O  S           S  O 
 O      S   S      O 
 OOOS           S OO 
 OOO              OO 
 OOOS           S OO 
 OOO    S   S     OO 
 OOOS           S OO 
 OOO              OO 
 OOOS           S OO 
OOOOO   O   O   OOOOO
OOO OOOOO   OOOOO OOO
OOA               AOO
O   OOOOOS SOOOOO   O
OOOOO   O   O   OOOOO
|----Layer 3|
                     
                     
  OOOOOOOOOOOOOOOOO  
  O C           C O  
  O               O  
  O C           C O  
  O               O  
  O C           C O  
  O     S   S     O  
 OOOC           C OO 
 OOO              OO 
 OOOC           C OO 
 OOO    S   S     OO 
 OOOC           C OO 
 OOO              OO 
 OOOC           C OO 
OOOOO   O   O   OOOOO
SOO OOOOO   OOOOO OOS
H$                 $H
S   OOOOOS SOOOOO   S
OSHSO   O   O   OSHSO
|----Layer 4|
                     
                     
                     
   OOOOOOOOOOOOOOO   
   OO           OO   
   OO           OO   
   OO           OO   
   OO           OO   
   OO   S   S   OO   
 OOOO           OOOO 
 OOOO           OOOO 
 OOOO           OOOO 
 OOOO   S   S   OOOO 
 OOOO           OOOO 
 OOOO           OOOO 
 OOOO           OOOO 
OOAOO   O   O   OOAOO
S   OOOOO   OOOOO   S
H   OOOOO   OOOOO   H
S   OOOOOSSSOOOOO   S
OSHSO   O   O   OSHSO
|----Layer 5|
                     
                     
                     
                     
    OOOOOOOOOOOOO    
    OOOOOOOOOOOOO    
    OOOOOOOOOOOOO    
    OOOOOOOOOOOOO    
    OOOOOOOOOOOOO    
 OOOOOOOO   OOOOOOOO 
 OOOOOOOO   OOOOOOOO 
 OOOOOOOO   OOOOOOOO 
 OOOOOOOOOOOOOOOOOOO 
 OOOOOOOOOOOOOOOOOOO 
 OOOOOOOOOOOOOOOOOOO 
 OAOOOOOOOOOOOOOOOAO 
OO OOOOOOOOOOOOOOO OO
H   O   OOOOO   O   H
C   O   OOOOO   O   C
H   O   OOOOO   O   H
OHCHO   SSSSS   OHCHO
|----Layer 6|
                     
                     
                     
                     
                     
     OOOOOOOOOOO     
     O         O     
     O         O     
     O         O     
     S         S     
                     
     S         S     
     O         O     
     O         O     
     O         O     
     OOOOOOOOOOO     
OO OO           OO OO
S   O           O   S
H   O           O   H
S   O           O   S
OSHSO   SHCHS   OSHSO
|----Layer 7|
                     
                     
                     
                     
                     
                     
      OOOOOOOOO      
      O       O      
      O       O      
     SO       OS     
                     
     SO       OS     
      O       O      
      O       O      
      OOOOOOOOO      
                     
OO OO           OO OO
H   O           O   H
C   O           O   C
H   O           O   H
OHCHO    SSS    OHCHO
|----Layer 8|
                     
                     
                     
                     
                     
                     
                     
       OOOOOOO       
       O     O       
     SOO     OOS     
     SOO     OOS     
     SOO     OOS     
       O     O       
       OOOOOOO       
                     
                     
OOOOO           OOOOO
H   O           O   H
H   O           O   H
H   O           O   H
OHHHO           OHHHO
|----Layer 9|
                     
                     
                     
                     
                     
                     
                     
                     
        OOOOO        
        O   O        
        O   O        
        O   O        
        OOOOO        
                     
                     
                     
OOOOO           OOOOO
S   O           O   S
S   O           O   S
S   O           O   S
OSSSO           OSSSO
|----Layer 10|
                     
                     
                     
                     
                     
                     
                     
                     
                     
         OOO         
         O O         
         OOO         
                     
                     
                     
                     
OOOOO           OOOOO
OOOOO           OOOOO
OOOOO           OOOOO
OOOOO           OOOOO
OOOOO           OOOOO
|----Layer 11|
                     
                     
                     
                     
                     
                     
                     
                     
                     
                     
                     
                     
                     
                     
                     
                     
  A               A  
 OOO             OOO 
AOOOA           AOOOA
 OOO             OOO 
  A               A  
}}
</td><td style="vertical-align:top;">
</td></tr></table>