{{structure info}}
[[File:Desert pyramid JE3 BE3.png|thumb|A Desert Temple, also known as a Desert Pyramid.]]

== Materials ==
{| class="wikitable"
|-
! Block !! Amount
|-
| {{BlockLink|Blue Terracotta}} || 2
|-
| {{BlockLink|Chest}} || 4
|-
| {{BlockLink|Chiseled Sandstone}} || 62
|-
| {{BlockLink|Cut Sandstone}} || 238
|-
| {{BlockLink|Orange Terracotta}} || 66
|-
| {{BlockLink|Sand}} || 101-103<ref group=note name=cellar_room_generation>83 blocks buried in the cellar room are generated as sand initially. 5 to 7 of these are replaced with suspicious sand in random positions.</ref><ref group=note name=collapsed_roof_generation />
|-
| {{BlockLink|Sandstone}} || 2885+<ref group=note name=collapsed_roof_generation>Of the 25 blocks which make up the cellar room's collapsed roof, 33% is sandstone, while the rest is sand. One of these blocks is replaced with suspicious sand. On average, the cellar roof consists of 8 sandstone, 16 sand, and 1 suspicious sand, which this tally reflects.</ref><ref group=note>Additional layers of sandstone may generate from the base of the pyramid to the ground.</ref>
|-
| {{BlockLink|Sandstone Slab}} || 2
|-
| {{BlockLink|Sandstone Stairs}} || 17
|-
| {{BlockLink|Stone Pressure Plate}} || 1
|-
| {{BlockLink|Suspicious Sand}} ||  6-8<ref group=note name=cellar_room_generation /><ref group=note name=collapsed_roof_generation />
|-
| {{BlockLink|TNT}} || 9
|}
; Notes
{{Notelist}}

== Blueprint ==
{| class="wikitable"
|-
! Layer !! Block !! Facing
|-
| -11
| {{BlockSprite|Chest|link=Chest|text=Chest}}
| Pressure Plate
|-
| 10
| {{BlockSprite|Sandstone Stairs|link=Sandstone Stairs|text=Sandstone Stairs}}
| Middle Sandstone
|-
|}

'''NOTE''': Red, green, and blue wool do not actually generate. In this blueprint, they represent:
* Red wool: Blocks buried in cellar room, which consists of sand and suspicious sand. Consult [[#Materials]] for generation rules.
* Green wool: One sand block and one sandstone block. They are mutually exclusive (i.e. if sand generates in one position, then sandstone will generate in the other).
* Blue wool: Blocks which make up the collapsed roof of the cellar room. Consult [[#Materials]] for generation rules.

<table><tr><td style="width:500px;">
{{layered blueprint|name=Desert Pyramid|A=Cut Sandstone|B=TNT|C=Chest|D=Stone Pressure Plate|E=Chiseled Sandstone|F=Sandstone|G=Orange Terracotta|H=Blue Terracotta|I=Sand|J=Sandstone Stairs|K=Red Wool|L=Green Wool|M=Blue Wool|N=Sandstone Slab|default=Layer 0
|----Layer -14|
                     
                     
                     
                     
                     
                     
                     
                     
        AAAAA        
        AAAAA        
        AAAAA        
        AAAAA        
        AAAAA        
                     
                     
                     
                     
                     
                     
                     
                     
|----Layer -13|
                     
                     
                     
                     
                     
                     
                     
                     
        AAAAA        
        ABBBA        
        ABBBA        
        ABBBA        
        AAAAA        
                     
                     
                     
                     
                     
                     
                     
                     
|----Layer -12|
                     
                     
                     
                     
                     
                     
                     
                     
        AAAAA        
        AAAAA        
        AAAAA        
        AAAAA        
        AAAAA        
                     
                     
                     
                     
                     
                     
                     
                     
|----Layer -11|
                     
                     
                     
                     
                     
                     
                     
          A          
        AACAA        
        A   A        
       AC D CA       
        A   A        
        AACAA        
          A          
                     
                     
                     
                     
                     
                     
                     
|----Layer -10|
                     
                     
                     
                     
                     
                     
                     
          E          
        EE EE        
        E   E        
       E     E       
        E   E        
        EE EE        
          E          
                     
                     
                     
                     
                     
                     
                     
|----Layer -9|
                     
                     
                     
                     
                     
                     
                     
                     
        AAAAA        
        A   A        
        A   A        
        A   A        
        AAAAA        
                     
                     
                     
                     
                     
                     
                     
                     
|----Layer -8 to -5|
                     
                     
                     
                     
                     
                     
                     
                     
        FFFFF        
        F   F        
        F   F        
        F   F        
        FFFFF        
                     
                     
                     
                     
                     
                     
                     
                     
|----Layer -4|
FFFFFFFFFFFFFFFFFFFFF
FFFFFFFFFFFFFFFFFFFFF
FFFFFFFFFFFFFFFFFFFFF
FFFFFFFFFFFFFFFFFFFFF
FFFFGFFFFFFFFFFFFFFFF
FFFFGFFFFFFFFFFFFFFFF
FFFGFGFFFFFFFFFFFFFFF
FGGFHFGGFFFFFFFFFFFFF
FFFGFGFFFFFFFFFFFFFFF
FFFFGFFFF   FFFFFFFFF
FFFFGFFFF   FFFFFFFFF
FFFFFFFFF   FFFFFFFFF
FFFFFFFFFFFFFFFFFFFFF
FFFFFFFFFFFFFFFFFFFFF
FFFFFFFFFFFFFFFFFFFFF
FFFFFFFFFFFFFFFFFFFFF
FFFFFFFFFFFFFFFFFFFFF
FFFFFFFFFFFFFFFFFFFFF
FFFFFFFFFFFFFFFFFFFFF
FFFFFFFFFFFFFFFFFFFFF
FFFFFFFFFFFFFFFFFFFFF
|----Layer -3|
FFFFFFFFFFFFFFFFFFFFF
FFFFFFFFFFFFFFFFFFFFF
FFFFFFFFFFFFFFFFFFFFF
FFFFIJFFFFFFFFFFFFFFF
FAAAKAAAFFFFFFFFFFFFF
FAKKKKKAFFFFFFFFFFFFF
FAKKKKKAFFFFFFFFFFFFF
AKKKKKKKAFFFFFFFFFFFF
FAKKKKKAFFFFFFFFFFFFF
FAKKKKKAF   FFFFFFFFF
FAAAKAAAF   FFFFFFFFF
FFFFAFFFF   FFFFFFFFF
FFFFFFFFFFFFFFFFFFFFF
FFFFFFFFFFFFFFFFFFFFF
FFFFFFFFFFFFFFFFFFFFF
FFFFFFFFFFFFFFFFFFFFF
FFFFFFFFFFFFFFFFFFFFF
FFFFFFFFFFFFFFFFFFFFF
FFFFFFFFFFFFFFFFFFFFF
FFFFFFFFFFFFFFFFFFFFF
FFFFFFFFFFFFFFFFFFFFF
|----Layer -2|
FFFFFFFFFFFFFFFFFFFFF
FFFFFFFFFFFFFFFFFFFFF
FFFFFFFFFFFFFFFFFFFFF
FFFFFIJFFFFFFFFFFFFFF
FEEEKEEEFFFFFFFFFFFFF
FEKKKKKEFFFFFFFFFFFFF
FEKKKKKEFFFFFFFFFFFFF
EKKKKKKKEFFFFFFFFFFFF
FEKKKKKEFFFFFFFFFFFFF
FEKKKKKEF   FFFFFFFFF
FEEEKEEEF   FFFFFFFFF
FFFFEFFFF   FFFFFFFFF
FFFFFFFFFFFFFFFFFFFFF
FFFFFFFFFFFFFFFFFFFFF
FFFFFFFFFFFFFFFFFFFFF
FFFFFFFFFFFFFFFFFFFFF
FFFFFFFFFFFFFFFFFFFFF
FFFFFFFFFFFFFFFFFFFFF
FFFFFFFFFFFFFFFFFFFFF
FFFFFFFFFFFFFFFFFFFFF
FFFFFFFFFFFFFFFFFFFFF
|----Layer -1|
FFFFFFFFFFFFFFFFFFFFF
FFFFFFFFFFFFFFFFFFFFF
FFFFFFFFFFFFFFFFFFFFF
FFFFLLIJFFFFFFFFFFFFF
FAAAAAAAFFFFFFFFFFFFF
FAKKKKKAFFFFFFFFFFFFF
FAKKKKKAFFFFFFFFFFFFF
FAKKKKKAFFFFFFFFFFFFF
FAKKKKKAFFFFFFFFFFFFF
FAKKKKKAF   FFFFFFFFF
FAAAAAAAF   FFFFFFFFF
FFFFFFFFF   FFFFFFFFF
FFFFFFFFFFFFFFFFFFFFF
FFFFFFFFFFFFFFFFFFFFF
FFFFFFFFFFFFFFFFFFFFF
FFFFFFFFFFFFFFFFFFFFF
FFFFFFFFFFFFFFFFFFFFF
FFFFFFFFFFFFFFFFFFFFF
FFFFFFFFFFFFFFFFFFFFF
FFFFFFFFFFFFFFFFFFFFF
FFFFFFFFFFFFFFFFFFFFF
|----Layer 0|
FFFFFFFFFFFFFFFFFFFFF
FFFFFFFFFFFFFFFFFFFFF
FFFFFFFFFFFFFFFFFFFFF
FFFFIIIIIFFFFFFFFFFFF
FFFFFFFFFFFFFFFFFFFFF
FFMMMMMFFFFFFFFFFFFFF
FFMMMMMFFFFFFFFFFFFFF
FFMMMMMFFFGFFFFFFFFFF
FFMMMMMFFFGFFFFFFFFFF
FFMMMMMFFGFGFFFFFFFFF
FFFFFFFGGFHFGGFFFFFFF
FFFFFFFFFGFGFFFFFFFFF
FFFFFFFFFFGFFFFFFFFFF
FFFFFFFFFFGFFFFFFFFFF
FFFFFFFFFFFFFFFFFFFFF
FFFFFFFFFFFFFFFFFFFFF
FFFFFFFFFFFFFFFFFFFFF
FFFFFFFFFFFFFFFFFFFFF
FFFFFFFFFFFFFFFFFFFFF
FFFFFFFFFFFFFFFFFFFFF
FFFFFFFFFFFFFFFFFFFFF
|----Layer 1|
                     
 FFFFFFFFFFFFFFFFFFF 
 F                 F 
 F  A           A  F 
 F                 F 
 F  A           A  F 
 F                 F 
 F  A           A  F 
 F      A   A      F 
 FFFA           A FF 
 FFF              FF 
 FFFA           A FF 
 FFF    A   A     FF 
 FFFA           A FF 
 FFF              FF 
 FFFA           A FF 
FFFFF   F   F   FFFFF
FFF FFFFF   FFFFF FFF
FFJ               JFF
F   FFFFFA AFFFFF   F
FFFFF   F   F   FFFFF
|----Layer 2|
                     
                     
  FFFFFFFFFFFFFFFFF  
  F E           E F  
  F               F  
  F E           E F  
  F               F  
  F E           E F  
  F     A   A     F  
 FFFE           E FF 
 FFF              FF 
 FFFE           E FF 
 FFF    A   A     FF 
 FFFE           E FF 
 FFF              FF 
 FFFE           E FF 
FFFFF   F   F   FFFFF
AFF FFFFF   FFFFF FFA
GN                 NG
A   FFFFFA AFFFFF   A
FAGAF   F   F   FAGAF
|----Layer 3|
                     
                     
                     
   FFFFFFFFFFFFFFF   
   FF           FF   
   FF           FF   
   FF           FF   
   FF           FF   
   FF   A   A   FF   
 FFFF           FFFF 
 FFFF           FFFF 
 FFFF           FFFF 
 FFFF   A   A   FFFF 
 FFFF           FFFF 
 FFFF           FFFF 
 FFFF           FFFF 
FFJFF   F   F   FFJFF
A   FFFFF   FFFFF   A
G   FFFFF   FFFFF   G
A   FFFFFAAAFFFFF   A
FAGAF   F   F   FAGAF
|----Layer 4|
                     
                     
                     
                     
    FFFFFFFFFFFFF    
    FFFFFFFFFFFFF    
    FFFFFFFFFFFFF    
    FFFFFFFFFFFFF    
    FFFFFFFFFFFFF    
 FFFFFFFF   FFFFFFFF 
 FFFFFFFF   FFFFFFFF 
 FFFFFFFF   FFFFFFFF 
 FFFFFFFFFFFFFFFFFFF 
 FFFFFFFFFFFFFFFFFFF 
 FFFFFFFFFFFFFFFFFFF 
 FJFFFFFFFFFFFFFFFJF 
FF FFFFFFFFFFFFFFF FF
G   F   FFFFF   F   G
E   F   FFFFF   F   E
G   F   FFFFF   F   G
FGEGF   AAAAA   FGEGF
|----Layer 5|
                     
                     
                     
                     
                     
     FFFFFFFFFFF     
     F         F     
     F         F     
     F         F     
     A         A     
                     
     A         A     
     F         F     
     F         F     
     F         F     
     FFFFFFFFFFF     
FF FF           FF FF
A   F           F   A
G   F           F   G
A   F           F   A
FAGAF   AGEGA   FAGAF
|----Layer 6|
                     
                     
                     
                     
                     
                     
      FFFFFFFFF      
      F       F      
      F       F      
     AF       FA     
                     
     AF       FA     
      F       F      
      F       F      
      FFFFFFFFF      
                     
FF FF           FF FF
G   F           F   G
E   F           F   E
G   F           F   G
FGEGF    AAA    FGEGF
|----Layer 7|
                     
                     
                     
                     
                     
                     
                     
       FFFFFFF       
       F     F       
     AFF     FFA     
     AFF     FFA     
     AFF     FFA     
       F     F       
       FFFFFFF       
                     
                     
FFFFF           FFFFF
G   F           F   G
G   F           F   G
G   F           F   G
FGGGF           FGGGF
|----Layer 8|
                     
                     
                     
                     
                     
                     
                     
                     
        FFFFF        
        F   F        
        F   F        
        F   F        
        FFFFF        
                     
                     
                     
FFFFF           FFFFF
A   F           F   A
A   F           F   A
A   F           F   A
FAAAF           FAAAF
|----Layer 9|
                     
                     
                     
                     
                     
                     
                     
                     
                     
         FFF         
         F F         
         FFF         
                     
                     
                     
                     
FFFFF           FFFFF
FFFFF           FFFFF
FFFFF           FFFFF
FFFFF           FFFFF
FFFFF           FFFFF
|----Layer 10|
                     
                     
                     
                     
                     
                     
                     
                     
                     
                     
                     
                     
                     
                     
                     
                     
  J               J  
 FFF             FFF 
JFFFJ           JFFFJ
 FFF             FFF 
  J               J  
}}
</td></tr></table>
<noinclude>
</noinclude>

[[Category:Structure Blueprints]]

[[fr:Pyramide/Plan]]
[[ja:砂漠の寺院/構造]]
[[zh:沙漠神殿/结构]]