<noinclude>{{structure info}}</noinclude>
Small rooms have banners hanging on the outside, and a shulker hanging from the ceiling. Must be placed on top of [[End City/Structure/Small Tower|small tower]].

==== Materials ====
{| class="wikitable"
|-
! Name !! Total !! Stack
|-
| {{BlockLink|Purpur Block}}
| 66
| 1 + 2 blocks
|-
| {{BlockLink|Purpur Pillar}}
| 12
|
|-
| {{BlockLink|Purpur Slab}}
| 2
|
|-
| {{BlockLink|Purpur Stairs}}
| 56
|
|-
| {{BlockLink|Magenta Banner}}
| 8
| 
|-
| {{BlockLink|End Rod}}
| 4
| 
|-
| {{BlockLink|End Stone Bricks}}
| 26
| 
|-
| {{BlockLink|Magenta Stained Glass}}
| 6
|
|-
|}

==== Blueprint ====
* The banners are purple with a black chevron and a black inverted chevron.
* Each stairs at the middle, corner, and next to corner is upside-down.

{{layered blueprint|name=small room|default=Layer 2|
P=Purpur Block|S=Purpur Stairs-rot180|s=Purpur Stairs|L=Purpur Slab|B=Magenta Wall Banner|D=End Rod|E=End Stone Bricks|U=Purpur Pillar+top|G=Magenta Stained Glass|H=EntitySprite:Shulker-rot180
|----Layer 0|
  B   B  
 SSsSsSS 
BSPPPPPSB
 sPLLPPs 
 SP   PS 
 sP   Ps 
BSPPPPPSB
 SSsSsSS 
  B   B  
|----Layer 1|
         
 D     D 
  UEEEU  
  E      
  E      
  E   E  
  UEEEU  
 D     D 
         
|----Layer 2|
         
         
  UEGEU  
  E      
  G      
  E   E  
  UEGEU  
         
         
|----Layer 3|
         
         
  UEGEU  
  E   E  
  G H E  
  E   E  
  UEGEU  
         
         
|----Layer 4|
SSssSssSS
SPPPPPPPS
sPPPPPPPs
sPPPPPPPs
SPPPPPPPS
sPPPPPPPs
sPPPPPPPs
SPPPPPPPS
SSssSssSS
}}<noinclude>
[[ja:エンドシティ/構造/小さな部屋]]
[[zh:末地城/结构/小房间]]
</noinclude>