<noinclude>{{structure info}}</noinclude>
'''Loot rooms''' consist of two [[chests]] with valuable [[End City#Loot|loot]]; some rooms may have an [[ender chest]] as well as a normal chest.

==== Materials ====
{| class="wikitable"
|-
! Name !! Total !! Stack
|-
| {{BlockLink|Chest}}
| 2
|
|-
| {{BlockLink|Purpur Slab}}
| 9
|
|-
| {{BlockLink|Purpur Stairs}}
| 123
| 1 + 63 Blocks
|}

==== Blueprint ====
* If the block is Green Wool the stair next to it is flipped upside-down and if it's Red Wool, then it's not.
* DON'T add any wool to the structure.

{{layered blueprint|name=Loot Room|default=Layer 0|
P=Purpur Block|S=Purpur Stairs|L=Purpur Slab|Y=Green Wool|N=Red Wool|C=Chest|U=Purpur Pillar+top|G=Purple Stained Glass|E=End Stone Bricks|D=End Rod

|----Layer 0|
   YYNNYYNNNYYNNYY
   SSSSSSSSSSSSSSS
  YSPPPPPPPPPPPPPSY
  NSPPPPPPPPPPPPPSN
  NSPPPPPL PPPPPPSN
  YSPPP    PPPPPPSY
  YSPPP    PPPPPPSY
  NSPP     PPPPPPSN
  NSPP         PPSN
  NSPPPPPP     PPSN
  YSPPPPPP    PPPSY
  YSPPPPPP    PPPSY
  NSPPPPPP LPPPPPSN
  NSPPPPPPPPPPPPPSN
  YSPPPPPPPPPPPPPSY
   SSSSSSSSSSSSSSS
   YYNNYYNNNYYNNYY
|----Layer 1|
        
   D             D
    UEEEEEEEEEEEU
    E    LPL    E
    E           E
    E           E
    E           E
    E      U    E
    E           E
    E    U      E
    E           E
    EC          E
    E           E
    E  C        E
    UEEEEEEEEEEEU
   D             D
|----Layer 2|
       
             
    UEGEEGEEEEEEU
    E      LPL  E
    G           E
    E           E
    E           E
    G      U    G
    E           E
    G    U      G
    E           E
    E           E
    G           G
    E           E
    UEGEEGEGEEGEU
|----Layer 3|
          
             
    UEGEEGEEEEEEU
    E        LPLE
    G           E
    E           E
    E           E
    G      U    G
    E           E
    G    U      G
    E           E
    E           E
    G           G
    E           E
    UEGEEGEGEEGEU
|----Layer 4|
  YYNNYYNNYNNYYNNYY
  SSSSSSSSSSSSSSSSS
 YSPPPPPPPPPPPPPPPSY
 NSPPPPPPPPPPPPPPPSN
 NSPPPPPPP     LPPSN
 YSPPPPPPPPPPPPPPPSY
 YSPPPPPPPPPPPPPPPSY
 NSPPPPPPPPPPPPPPPSN
 NSPPPPPPPPPPPPPPPSN
 YSPPPPPPPPPPPPPPPSY
 NSPPPPPPPPPPPPPPPSN
 NSPPPPPPPPPPPPPPPSN
 YSPPPPPPPPPPPPPPPSY
 YSPPPPPPPPPPPPPPPSY
 NSPPPPPPPPPPPPPPPSN
 NSPPPPPPPPPPPPPPPSN
 YSPPPPPPPPPPPPPPPSY
  SSSSSSSSSSSSSSSSS
  YYNNYYNNYNNYYNNYY
|----Layer 5|
        
        
       
         SSSSS
         S    
         SSSSS
}}<noinclude>
[[ja:エンドシティ/構造/宝の部屋]]
[[zh:末地城/结构/箱子房间]]
</noinclude>