<noinclude>{{structure info}}</noinclude>
==== Materials ====
{| class="wikitable"
|-
! Name !! Total !! Stack
|-
| {{BlockLink|Purpur Block}}
| 490
| 7 + 42 blocks
|-
| {{BlockLink|Purpur Stairs}}
| 170
| 2 + 42 blocks
|-
| {{BlockLink|Purpur Slab}}
| 15
|
|-
| {{BlockLink|Purpur Pillar}}
| 45
|
|-
| {{BlockLink|End Stone Bricks}}
| 228
| 3 + 36 blocks
|-
| {{BlockLink|Magenta Stained Glass}}
| 54
|
|-
| {{BlockLink|Ladder}}
| 3
|
|-
| {{BlockLink|End Rod}}
| 12
|
|-
|}

==== Blueprint ====
{| class="wikitable"
|-
! Layer !! Block !! Coords !! Facing/Placement
|-
| 1
| {{BlockLink|Purpur Stairs}}
| 
| South
|-
| 2
| {{BlockLink|Purpur Slab}}
| 6x 9y
| Bottom
|-
| 2
| {{BlockLink|Purpur Slab}}
| 6x 11y
| Top
|-
| 3
| {{BlockLink|Purpur Slab}}
| 6x 11y
| Bottom
|-
| 3
| {{BlockLink|Purpur Slab}}
| 8x 11y
| Top
|-
| 4
| {{BlockLink|Purpur Slab}}
| 8x 11y
| Bottom
|-
| 4
| {{BlockLink|Purpur Slab}}
| 10x 11y
| Top
|-
| 5
| {{BlockLink|Purpur Slab}}
| 
| Bottom
|-
| 5
| {{BlockLink|Purpur Stairs}}
| 
| Against Purpur Block
|-
| 6
| {{BlockLink|Purpur Slab}}
| 12x 5y
| Bottom
|-
| 6
| {{BlockLink|Purpur Slab}}
| 10x 5y
| Top
|-
| 7
| {{BlockLink|Purpur Slab}}
| 10x 5y
| Bottom
|-
| 7
| {{BlockLink|Purpur Slab}}
| 8x 5y
| Top
|-
| 8
| {{BlockLink|Purpur Slab}}
| 8x 5y
| Bottom
|-
| 8
| {{BlockLink|Purpur Slab}}
| 6x 5y
| Bottom
|-
| 9
| {{BlockLink|Purpur Stairs}}
| 
| Against Purpur Block
|-
| 10
| {{BlockLink|Purpur Stairs}}
| From 8x 7y to 8x 13y
| East
|-
| 10
| {{BlockLink|Purpur Stairs}}
| From 9x 7y to 9x 13y
| West
|-
| 10-12
| {{BlockLink|Ladder}}
| 
| North
|-
| 13
| {{BlockLink|Purpur Stairs}}
| 
| Against Purpur Block
|-
| 13
| {{BlockLink|Purpur Slab}}
| 
| Bottom
|-
|}
* If the block is green [[wool]], the stair next to it is flipped upside-down. If it is red wool, then it is not.
* Do ''not'' add any wool to the structure.
* For reference, the black wool block is at coordinates 0x 0y

{{layered blueprint|name=Base Room|default=Layer 1
|P=Purpur Block|S=Purpur Stairs|U=Purpur Pillar+top|E=End Stone Bricks|L=Purpur Slab|G=Magenta Stained Glass|Y=Green Wool|N=Red Wool|D=End Rod|A=Ladder|O=EntitySprite:Shulker|B=Black Wool
|----Layer 1|
B



      SPPPPS
     PPPPPPPP
     PPPPPPPP
     PPPPPPPP
     PPPPPPPP
     PPPPPPPP
     PPPPPPPP
     PPPPPPPP
     PPPPPPPP
|----Layer 2|
B




     UEE  EEU
     E      E
     E      E
     E      E
     EL     E
     EP     E
     EL     E
     UEEEEEEU
|----Layer 3|
B



       O  O
     UEE  EEU
     E      E
     G      G
     E      E
     E      E
     G      G
     ELPL   E
     UEEEEEEU
|----Layer 4|
B




     UEE  EEU
     E      E
     G      G
     E      E
     E      E
     G      G
     E  LPL E
     UEEEEEEU
|----Layer 5|
B

    YNYYNNYYNY
  YSSSSSSSSSSSSY
  YSPPPPPPPPPPSY
  NSPPPPPPPPPPSN
  YSPPPPPPPPPPSY
  YSPPPPPPPPPPSY
  NSPP PPPPPPPSN
  NSPP PPPPPPPSN
  YSPP PPPPPPPSY
  YSPP    LPPPSY
  NSPPPPPPPPPPSN
  YSPPPPPPPPPPSY
  YSSSSSSSSSSSSY
    YNYYNNYYNY
|----Layer 6|
B


   D          D
    UEEEEEEEEU
    E     LPLE
    E        E
    E        E
    E        E
    E        E
    E        E
    E        E
    E        E
    UEEEEEEEEU
   D          D
|----Layer 7|
B



    UEEEEEEGEU
    E   LPL  E
    G        G
    E        E
    E        E
    E        E
    E        E
    G        G
    E        E
    UEGEEEEGEU
|----Layer 8|
B



    UEEEEEEGEU
    E LPL    E
    G        G
    E        E
    E        E
    E        E
    E        E
    G        G
    E        E
    UEGEEEEGEU
|----Layer 9|
B
   YNNYYNNYYNNY
 YSSSSSSSSSSSSSSY
 YSPPPPPPPPPPPPSY
 NSPPPPPPPPPPPPSN
 NSPPPL      PPSN
 YSPPPPPPPPPPPPSY
 YSPPPPPPPPPPPPSY
 NSPPPPPPPPPPPPSN
 NSPPPPPPPPPPPPSN
 YSPPPPPPPPPPPPSY
 YSPPPPPPPPPPPPSY
 NSPPPPPPPPPPPPSN
 NSPPPPPPPPPPPPSN
 YSPPPPPPPPPPPPSY
 YSSSSSSSSSSSSSSY
   YNNYYNNYYNNY
|----Layer 10|
B

  D            D
   UEEEEEEEEEEU
   E          E
   E          E
   E          E
   E    SS    E
   E    SSU   E
   E    UUA   E
   E    SS    E
   E    SS    E
   E    SS    E
   E    SS    E
   UEEEEEEEEEEU
  D            D
|----Layer 11-12|
B


   UEGEGEEGEGEU
   E          E
   G          G
   E          E
   G          G
   E      U   E
   E    UUA   E
   G          G
   E          E
   G          G
   E          E
   UEGEGEEGEGEU
|----Layer 13|
B YNNYYNYYNYYNNY
YSSSSSSSSSSSSSSSSY
YSPPPPPPPPPPPPPPSY
NSPPPPPPPPPPPPPPSN
NSPPPPPPPPPPPPPPSN
YSPPPPPPPPPPPPPPSY
YSPPPPPPPPPPPPPPSY
NSPPPPPPPPPPPPPPSN
YSPPPPPPPPPPPPPPSY
YSPPPPPPP   PPPPSY
NSPPPPPPP  LPPPPSN
YSPPPPPPP   PPPPSY
YSPPPPPPPPPPPPPPSY
NSPPPPPPPPPPPPPPSN
NSPPPPPPPPPPPPPPSN
YSPPPPPPPPPPPPPPSY
YSSSSSSSSSSSSSSSSY
  YNNYYNYYNYYNNY
|----Layer 14|
B

  D            D












  D            D
}}<noinclude>
[[ja:エンドシティ/構造/基礎]]
[[zh:末地城/结构/基本房间]]
</noinclude>