<noinclude>{{structure info}}</noinclude>
This shows the documents for the Empty Room, which acts as the entrance to most End Cities.

==== Materials ====
{| class="wikitable"
|-
! Name !! Total !! Stack
|-
| {{BlockLink|End rod}}
| 4 
|
|-
| {{BlockLink|End Stone Bricks}}
| 54
|
|-
| {{BlockLink|Magenta Stained Glass}}
| 12
|
|-
| {{BlockLink|Purpur Block}}
| 168
| 2 + 40 blocks
|-
| {{BlockLink|Purpur Pillar}}
| 12
|
|-
| {{BlockLink|Purpur Stairs}}
| 46
|
|}

==== Blueprint ====
{| class="wikitable"
|-
! Layer !! Block !! Coords !! Half
|-
| 4
| {{BlockLink|Purpur Stairs}}
| 1x 3y 6y 7y and 10y
| Bottom
|-
| 4
| {{BlockLink|Purpur Stairs}}
| 3x 6x 7x and 10x 1y
| Bottom
|-
| 4
| {{BlockLink|Purpur Stairs}}
| 12x 3y 6y 7y and 10y
| Bottom
|-
| 4
| {{BlockLink|Purpur Stairs}}
| 3x 6x 7x and 10x 12y
| Bottom
|-
| 4
| {{BlockLink|Purpur Stairs}}
| else
| Top
|}
{{layered blueprint|name=Empty Room|default=Layer 3
|P=Purpur Block|U=Purpur Pillar+top|S=Purpur Stairs|E=End Stone Bricks|D=End Rod|G=Magenta Stained Glass|K=EntitySprite:Shulker-rot270
|----Layer 0|
            
            
  PPPPPPPP  
 SPPPPPPPP  
 PPPPPPPPP  
 PPPPPPPPP  
 PPPPPPPPP  
 PPPPPPPPP  
 SPPPPPPPP  
  PPPPPPPP  
            
            
|----Layer 1|
            
            
  UEEEEEEU  
  E      E  
  E      E  
         E  
         E  
  E      E  
  E      E  
  UEEEEEEU  
            
            
|----Layer 2|
            
            
  UEGEEGEU  
  E      E  
 KE      G  
         E  
         E  
 KE      G  
  E      E  
  UEGEEGEU  
            
            
|----Layer 3|
            
            
  UEGEEGEU  
  E      E  
  E      G  
         E  
         E  
  E      G  
  E      E  
  UEGEEGEU  
            
            
|----Layer 4|
SSSSSSSSSSSS
SPPPPPPPPPPS
SPPPPPPPPPPS
SPPPPPPPPPPS
SPPPPPPPPPPS
SPPPPPPPPPPS
SPPPPPPPPPPS
SPPPPPPPPPPS
SPPPPPPPPPPS
SPPPPPPPPPPS
SPPPPPPPPPPS
SSSSSSSSSSSS
|----Layer 5|
            
 D        D 
            
            
            
            
            
            
            
            
 D        D 
            
}}<noinclude>
[[ja:エンドシティ/構造/空き部屋]]
[[zh:末地城/结构/空房间]]
</noinclude>