<noinclude>{{structure info}}</noinclude>
__NOTOC__
==== Bridge ====
;Materials
{| class="wikitable"
|-
! Name !! Total !! Stack
|-
| {{BlockLink|Purpur Block}}
| 20
|
|-
| {{BlockLink|Purpur Pillar}}
| 4
|
|-
| {{BlockLink|Purpur Stairs}}
| 10
|
|}
;Blueprint
{{layered blueprint|name=Bridge|default=Layer 1
|B=Purpur Block|P=Purpur Pillar|S=Purpur Stairs
|----Layer -1|
  P  
  P  
  P  
 SPS 
|----Layer 0|
BBBBB
BBBBB
BBBBB
SBBBS
|----Layer 1|
S   S
S   S
S   S
B   B
}}
==== Gentle Stairs ====
;Materials
{| class="wikitable"
|-
! Name !! Total !! Stack
|-
| {{BlockLink|Purpur Block}}
| 42
|
|-
| {{BlockLink|Purpur Pillar}}
| 2
|
|-
| {{BlockLink|Purpur Stairs}}
| 22
|
|-
| {{BlockLink|Purpur Slab}}
| 12
|
|}
;Blueprint
{{layered blueprint|name=Gentle Stairs|default=Layer 3
|B=Purpur Block|H=Purpur Slab|P=Purpur Pillar|S=Purpur Stairs
|----Layer -1|
  P  
     
     
     
     
     
     
     
|----Layer 0|
SBBBS
     
     
     
     
     
     
     
|----Layer 1|
BHHHB
BBBBB
SBBBS
     
     
     
     
     
|----Layer 2|
S   S
S   S
BHHHB
BBBBB
SBBBS
     
     
     
|----Layer 3|
     
     
S   S
S   S
BHHHB
BBBBB
SBBBS
  P  
|----Layer 4|
     
     
     
     
S   S
S   S
BHHHB
BBBBB
|----Layer 5|
     
     
     
     
     
     
S   S
B   B
}}
==== Steep Stairs ====
;Materials
{| class="wikitable"
|-
! Name !! Total !! Stack
|-
| {{BlockLink|Purpur Block}}
| 15
|
|-
| {{BlockLink|Purpur Pillar}}
| 2
|
|-
| {{BlockLink|Purpur Stairs}}
| 24
|
|}
;Blueprint
{{layered blueprint|name=Steep Stairs|default=Layer 5
|B=Purpur Block|P=Purpur Pillar|S=Purpur Stairs
|----Layer -1|
  P  
     
     
     
|----Layer 0|
 BBB
     
     
     
|----Layer 1|
BSSSB
 SBS 
     
     
|----Layer 2|
S   S
BSSSB
 SBS 
     
|----Layer 3|
     
S   S
BSSSB
 SBS 
|----Layer 4|
     
     
S   S
BSSSB
|----Layer 5|
     
     
     
B   B
}}
==== Dock ====
Dock appears when the bridge is over, substituting the last part of bridge.
;Materials
{| class="wikitable"
|-
! Name !! Total !! Stack
|-
| {{BlockLink|Purpur Block}}
| 21
|
|-
| {{BlockLink|Purpur Pillar}}
| 1
|
|-
| {{BlockLink|Purpur Slab}}
| 4
|
|-
| {{BlockLink|Purpur Stairs}}
| 3
|
|-
| {{BlockLink|End Rod}}
| 2
|
|}
;Blueprint
{{layered blueprint|name=Dock|default=Layer 2
|B=Purpur Block|P=Purpur Pillar|S=Purpur Stairs|H=Purpur Slab|E=End Rod
|----Layer -1|
  P  
 BBB 
|----Layer 0|
BSSSB
BBBBB
|----Layer 1|
B   B
B   B
|----Layer 2|
E   E
B   B
|----Layer 3|
     
BH HB
|----Layer 4|
     
HBBBH
}}<noinclude>
[[ja:エンドシティ/構造/橋]]
[[zh:末地城/结构/桥]]
</noinclude>