<noinclude>{{structure info}}</noinclude>
{{wip|section=y}}

'''Large rooms''' hold complex staircases that often lead up to another tower or a loot room.
==== Two-story ====
;Materials
{| class="wikitable"
|-
! Name !! Total !! Stack
|-
|{{BlockLink|Purpur Block}}
|275
|4 + 19 blocks
|- 
|{{BlockLink|Purpur Pillar}}
|27
|
|- 
|{{BlockLink|Purpur Stairs}}
|103
|1 + 39 blocks
|-
|{{BlockLink|Purpur Slab}}
|8
|
|-
|{{BlockLink|End Rod}}
|8
|
|-
|{{BlockLink|End Stone Bricks}}
|136
|2 + 8 blocks
|-
|{{BlockLink|Magenta Stained Glass}}
|26
|
|-
|{{BlockLink|Ladder}}
|3
|
|-
|}

==== Blueprint ====
{{layered blueprint|name=Two-storey|default=Layer 1
|P=Purpur Block|S=Purpur Stairs|U=Purpur Pillar+top|E=End Stone Bricks|L=Purpur Slab|G=Magenta Stained Glass|D=End Rod|A=Ladder
|----Layer 1|
                     
              
      SPPPPS
     PPPPPPPP
     PPPPPPPP
     PPPPPPPP
     PPPPPPPP
     PPPPPPPP
     PPPPPPPP
     PPPPPPPP
     PPPPPPPP
|----Layer 2|
                      
               
         
     UEE  EEU
     E      E
     E  L   E
     E  SP  E
     E  PP  E
     E      E
     E      E
     UEEEEEEU
|----Layer 3|
                 
               
                            
     UEE  EEU
     E      E
     G      G
     E   P  E
     E LSP  E
     G      G
     E      E
     UEGEEGEU
|----Layer 4|
                 
               
                         
     UEE  EEU
     E      E
     G      G
     E   PL E
     E   S  E
     G   L  G
     E      E
     UEGEEGEU
|----Layer 5|
                   
   SSSS     SSS   
   SPPPPPPPPPPS         
   SPPPPPPPPPPS
   SPP      PPS
   SPP      PPS
   SPPLLLS  PPS
   SPP      PPS
   SPP      PPS
   SPP      PPS
   SPPPPPPPPPPS
   SPPPPPPPPPPS
   SSSSSSSSSSSS
|----Layer 6|
                   
   D          D
    UEEEEEEEEU
    E        E
    ES   U   E
    ES   A   E
    E        E
    E        E
    E        E
    E        E
    E        E
    UEEEEEEEEU
   D          D               
|----Layer 7|
                  
                   
    UEEEEEEEEU
    E        E
    ES   U   G
    ES   A   E
    E        E
    E        E
    E        E
    G        G
    E        E
    UEGEEEEGEU
|----Layer 8|
              
                  
    UEEEEEEEEU
    E        E
    ES   U   G
    ES   A   E
    E        E
    E        E
    E        E
    G        G
    E        E
    UEGEEEEGEU
|----Layer 9|
  SSSSSSSSSSSSSS 
  SPPPPPPPPPPPPS
  SPPPPPPPPPPPPS
  SPPPPPPPPPPPPS
  SPPPPPPPPPPPPS
  SPPPPP   PPPPS
  SPPPPP  LPPPPS
  SPPPPP   PPPPS
  SPPPPPPPPPPPPS
  SPPPPPPPPPPPPS
  SPPPPPPPPPPPPS
  SPPPPPPPPPPPPS
  SPPPPPPPPPPPPS
  SSSSSSSSSSSSSS
|----Layer 10|
              
   D          D


 
                   
                  
                 
                  
                 
                   
          
   D          D       
           


         
  















}}
==== Three-story ====
;Materials
{| class="wikitable"
|-
! Name !! Total !! Stack
|-
|
|
|
|-
|}

==== Blueprint ====
All slabs are lower except Layer 5 and Layer 8 where they are higher
{{layered blueprint|name=Three-storey|default=Layer 1
|P=Purpur Block|S=Purpur Stairs|U=Purpur Pillar+top|E=End Stone Bricks|L=Purpur Slab|G=Magenta Stained Glass|D=End Rod|A=Ladder|C=Chest|e=Ender Chest
|----Layer 1|
         
                            
              
      SPPPPS
     PPPPPPPP
     PPPPPPPP
     PPPPPPPP
     PPPPPPPP
     PPPPPPPP
     PPPPPPPP
     PPPPPPPP
     PPPPPPPP
|----Layer 2|
       
                               
               
         
     UEE  EEU
     E      E
     E  L   E
     E  SP  E
     E  PP  E
     E      E
     E      E
     UEEEEEEU
|----Layer 3|
                 
                 
               
                            
     UEE  EEU
     E      E
     G      G
     E   P  E
     E LSP  E
     G      G
     E      E
     UEGEEGEU
|----Layer 4|
               
             
               
                         
     UEE  EEU
     E      E
     G      G
     E   PL E
     E   S  E
     G   L  G
     E      E
     UEGEEGEU
|----Layer 5|
                    
                   
   SSSS     SSS   
   SPPPPPPPPPPS         
   SPPPPPPPPPPS
   SPP   PPPPPS
   SPP      PPS
   SPPLLLS  PPS
   SPP      PPS
   SPP      PPS
   SPP      PPS
   SPPPPPPPPPPS
   SPPPPPPPPPPS
   SSSSSSSSSSSS
|----Layer 6|
                 
                  
   D          D
    UEEEEEEEEU
    E PPPP   E
    ES   PPS E
    ES       E
    E        E
    E        E
    E        E
    E        E
    E        E
    UEEEEEEEEU
   D          D
 |----Layer 7|
                 
                 
                  
    UEEEEEEGEU 
    E PPPP   E
    ES   PS  G
    ES       E
    E        E
    E        E
    E        E
    G        G
    E        E
    UEGEEEEGEU
 |----Layer 8|
                
                
                 
    UEEEEEEGEU
    E PS     E
    ESL      G
    ESL      E
    E        E
    E        E
    E        E
    G        G
    E        E
    UEGEEEEGEU
|----Layer 9|
                
  SSSSSSSSSSSSSS
  SPPPPPPPPPPPPS
  SPPPPPPPPPPPPS
  SPPPS      PPS
  SPP        PPS
  SPP  PPPP  PPS
  SPP        PPS
  SPP        PPS
  SPP        PPS
  SPP   DD   PPS
  SPP   PP   PPS
  SPPPPPPPPPPPPS
  SPPPPPPPPPPPPS
  SSSSSSSSSSSSSS
|----Layer 10|
               
  D            D
   UEEEEEEEEEEU
   E          E
   EP        PE
   E          E
   EP         E
   E      U   E
   EP     A   E
   E          E
   E          E
   E          E
   E    eC    E
   UEEEEEEEEEEU
  D            D
|----Layer 11|
                
                  
   UEGEGEEGEGEU
   E          E
   EP        PE
   E          E
   EPPP       E
   E      U   E 
   EP     A   E
   G          G
   E          E
   G          G
   E          E
   UEGEGEEGEGEU
|----Layer 12|
               
               
   UEGEGEEGEGEU
   E          E
   EP        PE
   E          E
   EP         E
   E      U   E 
   EP     A   E
   G          G
   E          E
   G          G
   E          E
   UEGEGEEGEGEU
|----Layer 13|
 SSSSSSSSSSSSSSSS
 SPPPPPPPPPPPPPPS
 SPPPPPPPPPPPPPPS
 SPPPPPPPPPPPPPPS
 SPPPPPPPPPPPPPPS
 SPPPPPPPPPPPPPPS
 SPPPPPPPPPPPPPPS
 SPPPPPPPPPPPPPPS
 SPPPPPPP   PPPPS
 SPPPPPPP  LPPPPS
 SPPPPPPP   PPPPS
 SPPPPPPPPPPPPPPS
 SPPPPPPPPPPPPPPS
 SPPPPPPPPPPPPPPS
 SPPPPPPPPPPPPPPS
 SSSSSSSSSSSSSSSS
|----Layer 14|
                  
  D            D












  D            D







}}<noinclude>
[[ja:エンドシティ/構造/大きな部屋]]
[[zh:末地城/结构/大房间]]
</noinclude>