<noinclude>{{structure info}}</noinclude>
The End City Ship can be found near the End City Tower which contains an elytra and few loot chests.

In Java the path to load the structure from a structure block is minecraft:end_city/ship.

== Dimensions ==

The end ship is 24 blocks high, 29 blocks long and 13 blocks wide.

== Materials ==
{| class="wikitable"
|-
! Name
! Total
! Stack
|-
| {{BlockLink|Brewing Stand}}
| 1
|
|-
| {{BlockLink|Chest}}
| 2
|
|-
| {{BlockLink|Dragon Head}}
| 1
|
|-
| {{ItemLink|Elytra}}
| 1
|
|-
| {{BlockLink|End Rod}}
| 6
|
|-
| {{BlockLink|End Stone Bricks}}
| 36
|
|-
| {{EntityLink|Item Frame|id=Empty Item Frame}}
| 1
|
|-
| {{BlockLink|Ladder}}
| 14
|
|-
| {{BlockLink|Magenta Stained Glass}}
| 7
|
|-
| {{BlockLink|Obsidian}}
| 26
|
|-
| {{ItemLink|Potion of Healing}}
| 2
|
|-
| {{BlockLink|Purpur Block}}
| 557
| 8 + 45 blocks
|-
| {{BlockLink|Purpur Pillar}}
| 97
| 1 + 33 blocks
|-
| {{BlockLink|Purpur Slab}}
| 7
| 
|-
| {{BlockLink|Purpur Stairs}}
| 154
| 2 + 47 blocks
|-
| {{EntityLink|Shulker}}
| 3
|
|}

== Block orientation and instructions ==
{| class="wikitable collapsible collapsed"
|-
! Layer(s) !! Block orientation and instructions
|-
| 1 || ''13 pillars, oriented front/back.''
|-
| 2 || ''The pillars are oriented front/back.''<br>
''The stairs outside the ship are upside-down, facing the ship.''
|-
| 3 || ''The pillars are oriented front/back.''<br>
''The stairs outside the ship are upside-down, facing the ship.''
|-
| 4 || ''The pillar in the middle is oriented up/down, and the pillars at the front are oriented front/back.''<br>
''The stairs outside the ship are upside-down, facing the ship.''<br>
''The stairs inside the ship are facing the back.''
|-
| 5 || ''The pillar in the middle is oriented up/down.''<br>
''The chests are each oriented with their hinges against the front of the ship.''<br>
''The stairs outside the ship are upside-down, facing the ship.''<br>
''The stairs inside the ship are facing the back.''
|-
| 6 || ''The pillar in the middle is oriented up/down.  The pillars at the bow of the ship point toward/away from the direction of the ship.''<br>
''The item frame contains an elytra, and is attached to the block at the front of the ship.''<br>
''The stairs outside the ship are all facing the ship; all are upside-down except the 3rd and 6th from the back (along the sides) and the 3rd and the 6th from the left (along the bottom).  The four on the corners of the deck area are "outside-corner" stairs.''<br>
''The stairs inside the ship are facing the back.''
|-
| 7 || ''All pillars point up/down, except those at the bow of the ship, which point toward/away from the direction of the ship.''<br>
''The stairs are oriented to ascend up into the purpur block area.''<br>
''The end rods in the back point up/down, and the one in front points backward.''
|-
| 8 || ''Pillars below the central glass all point up/down; pillars above the central glass are all pointing toward/away from the glass''<br>
''The stairs are oriented to ascend up into the purpur block area.''<br>
''The brewing stand contains two potions of healing.''
|-
| 9 || ''Dragon head is pointing away from the ship, and the stair is facing the dragon head.''<br>
''Pillars within the ship body by the stair are oriented toward the stair, and the stair is facing the pillars.''<br>
''Central pillar is oriented up/down, ladder is against the pillar.''<br>
''The stairs interior to the ship on the right-hand side are right-side-up, but facing downward (toward the end stone bricks).''<br>
''All other stairs are right-side-up, and facing the interior of the ship.''<br>
''The four stairs in the 9th and 11th rows from the top are "inside-corner" stairs.''
|-
| 10 || ''Pillars by the stair are oriented toward the stair, stair is facing the pillars.''<br>
''End rods are pointing up.''<br>
''Central pillar is oriented up/down, ladder is against the pillar.''<br>
''Stairs along the outside of the deck are all facing inward.  Stairs on the four corners are all "outside corner" stairs.''<br>
''On the bottom row of stairs, the 3rd & 4th, 7th, 10th & 11th stairs (counting from the left) are right-side-up, and along the sides, the 3rd & 4th, 7th & 8th (counting from the bottom) are right-side-up.  The two stairs off-center toward the top-right of the deck are right-side up.''<br>
''The rest of the stairs are upside-down.''
|-
| 11 || ''Pillars by the stair are oriented toward the stair, stair is facing the pillars.''<br>
''Central pillar is oriented up/down, ladder is against the pillar.''<br>
''Pillar on the deck is oriented up/down.  Stairs along the outside of the deck are all facing inward.  Stairs along the inside of the "bottom" are facing outward.''<br>
''The 2 stairs on the ends of the 4 stairs on the top are "inside corner" stairs.  The 2 stairs on the ends of the 5 stairs on the bottom are "outside corner" stairs.''
|-
| 12 || ''Pillars by the stair are oriented toward the stair, stair is facing the pillars.''<br>
''Central pillar is oriented up/down, ladder is against the pillar''
|-
| 13 || ''Slab is upside-down, pillars by the stair are oriented toward the stair, stair is facing the pillars.''<br>
''Central pillar is oriented up/down, ladder is against the pillar''
|-
| 14–22 || ''Pillar is oriented up/down, ladder is against the pillar''
|-
| 23 || ''Pillar is oriented up/down''
|-
|}

== Blueprints ==
<table><tr><td style="width:400px;">
{{layered blueprint|name=End Ship|default=Layer 11
|P=Purpur Pillar|s=Purpur Stairs|B=Purpur Block|S=Purpur Slab|o=Obsidian|z=Red Wool|c=Chest|i=EntitySprite:Item Frame|E=End Stone Bricks|e=End Rod|b=Brewing Stand|g=Magenta Stained Glass|d=Dragon Head|L=Ladder|h=EntitySprite:Shulker
|----Layer 1|
             
             
             
             
             
             
             
             
             
             
             
      P      
      P      
      P      
      P      
      P      
      P      
      P      
      P      
      P      
      P      
      P      
      P      
      P      
             
             
             
             
             
|----Layer 2|
             
             
             
             
             
             
             
             
      P      
      P      
      P      
      P      
     BBB     
    sBBBs    
     BBB     
     BBB     
     BBB     
    sBBBs    
     BBB     
     BBB     
     BBB     
    sBBBs    
     BBB     
     BPB     
     BPB     
             
             
             
             
|----Layer 3|
             
             
             
             
             
             
      P      
      P      
     BPB     
     BPB     
    BBPBB    
    BBPBB    
    BoPoB    
   sBoPoBs   
    BoPoB    
    BoPoB    
    BoPoB    
   sBoPoBs   
    BoPoB    
    BoPoB    
    BoPoB    
   sBoPoBs   
    BoPoB    
    BoPoB    
    BoPoB    
   sBBPBBs   
             
             
             
|----Layer 4|
             
             
             
             
             
      P      
      P      
     BBB     
    BBBBB    
    B   B    
   B     B   
   B     B   
   B     B   
  sB     Bs  
   B  P  B   
   B    sB   
   B    BB   
  sB    BBs  
   B    BB   
   B    BB   
   B    BB   
  sB    BBs  
   B    BB   
   B    BB   
   B    BB   
  sBBBBBBBs  
             
             
             
|----Layer 5|
             
             
             
             
             
      B      
     BBB     
    Bc cB    
    B h B    
   B     B   
   B     B   
  B       B  
  B       B  
  B       B  
  B   P   B  
  B       B  
  B       B  
  B       B  
  B       B  
  B     ssB  
  B     BBB  
  B     BBB  
  B     BBB  
  B     BBB  
  B     BBB  
  BBBBBBBBB  
  s   s   s  
             
             
|----Layer 6|
             
             
             
             
      P      
      P      
     BBB     
    B i B    
    B   B    
   B     B   
   B     B   
  B       B  
  B       B  
 sB       Bs 
  B   P   B  
  B       B  
 sB       Bs 
  B       B  
  B       B  
  B       B  
 sBBBBBBssBs 
 sBBBBBBBBBs 
 sBBBBBBBBBs 
 sBBBBBBBBBs 
 sBBBBBBBBBs 
 sBBBBBBBBBs 
 sBBBBBBBBBs 
 sssssssssss 
             
|----Layer 7|
             
             
             
      P      
      P      
      B      
     BeB     
    B   B    
    B   B    
   B     B   
   B     B   
  B       B  
  B       B  
             
  B   P   B  
  B       B  
             
  B       B  
  B       B  
  BBBBBB  B  
  BBssBB  B  
  PB  BB  P  
  E       E  
  E       E  
  E       E  
  E   P   E  
  PEEEPEEEP  
 e      h  e 
             
|----Layer 8|
             
      P      
      P      
      P      
      P      
     BBB     
    BBBBB    
    BBBBB    
   BBBBBBB   
   BBBBBBB   
  BBBBBBBBB  
  BBBBBBBBB  
  BBBBPBBBB  
  BBBBgBBBB  
  BBBBPBBBB  
  BBBBBBBBB  
  BBBBBBBBB  
  BBBBBBBBB  
  BBBBBBBBB  
  BBssBB  B  
  BB  BB  B  
  PB  BB  P  
  E       E  
  g       g  
  g       g  
  E   b   E  
  PEgEPEgEP  
     
             
|----Layer 9|
      d      
      s      
             
             
      B      
     B B     
    B   B    
    s   s    
   Bs   sB   
   s     s   
  Bs  P  sB  
  s   P   s  
  s   s   s  
  B       B  
  s   P   s  
  s   L   s  
  B       B  
  s       s  
  s       s  
  B     ssB  
  B     BBB  
  PB  BBBBP  
  E       E  
  E       E  
  E       E  
  E       E  
  PEEEPEEEP  
             
             
|----Layer 10|
             
             
             
             
      e      
             
             
             
      P      
      P      
  e   s   e  
             
             
             
      P      
      L      
             
             
             
ssss       ss
sBBB  BBssBBs
sBBBBBBBBBBBs
sBBBBBBBBBBBs
sBBBBBBBBBBBs
sBBBBBBBBBBBs
sBBBBBBBBBBBs
sBBBBBBBBBBBs
sBBBBBBBBBBBs
sssssssssssss
|----Layer 11|
             
             
             
             
             
             
      P       
      P      
      s      
            
             
             
             
             
      P      
      L      
             
             
             
             
 BsB  BB  BB 
 s ssss    s 
 s  P      s 
 s         s 
 s         s 
 s         s 
 s  sssss  s 
 BssBsssBssB 
             
|----Layer 12|
             
             
             
             
      P       
      P      
      s      
            
             
             
             
             
             
             
      P      
      L      
             
             
             
             
             
             
             
             
            
             
             
    h         
             
|----Layer 13|
             
      S      
      P      
      P      
      s      
             
             
             
             
             
             
             
             
             
      P      
      L      
             
             
             
             
             
             
             
             
             
             
             
             
             
|----Layers 14–20|
             
             
             
             
             
             
             
             
             
             
             
             
             
             
      P      
      L      
             
             
             
             
             
             
             
             
             
             
             
             
             
|----Layer 21|
             
             
             
             
             
             
             
             
             
             
             
             
             
     S S     
     SPS     
     SLS     
             
             
             
             
             
             
             
             
             
             
             
             
             
|----Layer 22|
             
             
             
             
             
             
             
             
             
             
             
             
    sssss    
    s   s    
    s P s    
    s L s    
    sssss    
             
             
             
             
             
             
             
             
             
             
             
             
|----Layer 23|
             
             
             
             
             
             
             
             
             
             
             
             
             
             
      P      
             
             
             
             
             
             
             
             
             
             
             
             
             
             
|----Layer 24|
             
             
             
             
             
             
             
             
             
             
             
             
             
			 
      B      
             
             
             
             
             
             
             
             
             
             
             
             
             
			 
}}
</td><td style="vertical-align:top;">

[[File:End_Ship.png|500px]]
</td></tr></table>

[[Category:Structure Blueprints]]

[[fr:Cité de l'End/Structure/Navire de l'End]]
[[ja:エンドシティ/構造/エンドシップ]]
[[zh:末地船/结构]]