<noinclude>{{structure info}}</noinclude>
A Large Tower is three times the diameter of the smaller towers and consist of a treacherous double spiral staircase made of purpur slabs and end rods, as well as housing two shulkers.

==== Materials ====
{| class="wikitable"
|-
! Name !! Total !! Stack
|-
| {{BlockLink|End Rod}}
| 12
|
|-
| {{BlockLink|Purpur Block}}
| 136
| 2 + 8 Blocks
|-
| {{BlockLink|Purpur Pillar}}
| 256
| 4
|-
| {{BlockLink|Purpur Slab}}
| 11
| 
|-
| {{BlockLink|Purpur Stairs}}
| 12
|
|}

==== Blueprint ====
All of these stairs are upside-down

{{layered blueprint|name=large room|default=Layer 0|
P=Purpur Block|S=Purpur Stairs|L=Purpur Slab|D=End Rod|E=End Rod-rot90|d=End Rod-rot180|e=End Rod-rot270|U=Purpur Pillar+top|u=Purpur Pillar|p=Purpur Pillar+horizontal|H=EntitySprite:Shulker|K=EntitySprite:Shulker-rot90|h=EntitySprite:Shulker-rot180|k=EntitySprite:Shulker-rot270
|----Layer 0|
         
      PPP
    PPPPPPP  
   PPPPPPPPP
   PPPPPPPPP
  PPPP   PPPP
  PPPP   PPPP
  PPPP L PPPP
   PPPPPPPPP
   PPPPPPPPP
    PPPPPPP  
      PPP

|----Layer 1|
          
      UUU
    UU   UU  
   U       U
   U       U
  UL        U
  U         U
  U        LU
   U       U
   U       U
    UU   UU  
      UUU

|----Layer 2|
       S
      UuU
    UU   UU  
   U       U
   UE      U
  U         U
 Sp         pS
  U         U
   U      eU
   U       U
    UU   UU  
      UuU
       S

|----Layer 3|
        
      UUU
    UU   UU  
   U d     U
   U       U
  U         U
  U         U
  U         U
   U       U
   U     D U
    UU   UU  
      UUU
|----Layer 4|
         
      PPP
    PPL  PP  
   P       P
   P       P
  P         P
  P         P
  P         P
   P       P
   P       P
    PP  LPP  
      PPP
|----Layer 5|
         
      UUU
    UU  LUU  
   U       U
   U       U
  U         U
  U         U
  U         U
   U       U
   U       U
    UUL  UU  
      UUU
|----Layer 6|
       S
      UuU
    UU   UU  
   U     d U
   U       U
  U         U
 SpK       kpS
  U         U
   U       U
   U D     U
    UU   UU  
      UuU
       S
|----Layer 7|
         
      UUU
    UU   UU  
   U       U
   U      eU
  U         U
  U         U
  U         U
   UE      U
   U       U
    UU   UU  
      UUU
|----Layer 8|
        
      PPP
    PP   PP  
   P       P
   P       P
  P        LP
  P         P
  PL        P
   P       P
   P       P
    PP   PP  
      PPP
|----Layer 9|
         
      UUU
    UU   UU  
   U       U
   U       U
  UL        U
  U         U
  U        LU
   U       U
   U       U
    UU   UU  
      UUU
|----Layer 10|
       S
      UuU
    UU h UU  
   U       U
   UE      U
  U         U
 Sp         pS
  U         U
   U      eU
   U       U
    UU H UU  
      UuU
       S
|----Layer 11|
       U
      UUU
    UU   UU  
   U d     U
   U       U
  U         U
 UU         UU
  U         U
   U       U
   U     D U
    UU   UU  
      UUU
       U
}}<noinclude>
[[ja:エンドシティ/構造/大きな塔]]
[[zh:末地城/结构/大塔楼]]
</noinclude>