<noinclude>{{structure info}}</noinclude>
'''Towers''' are hollow, consisting only of a single [[Purpur Slab]] staircase. Can be placed everywhere on the roof of rooms.
__NOTOC__
==== Materials ====
{| class="wikitable"
|-
! Name !! Total !! Stack
|-
| {{BlockLink|Purpur Block}}
| 40
| 
|-
| {{BlockLink|Purpur Pillar}}
| 52
| 
|-
| {{BlockLink|Purpur Slab}}
| 8
|
|-
| {{BlockLink|Purpur Stairs}}
| 4
|
|-
| {{BlockLink|Ladder}}
| 3
|
|-
|}

==== Blueprint ====
Each of these stairs are upside-down.

===== Base =====
{{layered blueprint|name=Small Tower Base|default=Layer 0|
P=Purpur Block|U=Purpur Pillar+top|u=Purpur Pillar+horizontal|p=Purpur Pillar|L=Purpur Slab|S=Purpur Stairs|l=Ladder
|----Layer -3~-1|
       
       
       
       
   l   
   U   
       
|----Layer 0|
PPPPPPP
PPPPPPP
PP   PP
PPL  PP
PP   PP
PPPPPPP
PPPPPPP
|----Layer 1|
       
  UUU  
 U L U 
 U   U 
 U   U 
  UUU  
       
|----Layer 2|
   S   
  UpU  
 U   U 
Su  LuS
 U   U 
  UpU  
   S   
|----Layer 3|
       
  UUU  
 U   U 
 U   U 
 U L U 
  UUU  
       
}}
===== Extension =====
{{layered blueprint|name=Small Tower Extention|default=Layer 0|
P=Purpur Block|U=Purpur Pillar+top|u=Purpur Pillar+horizontal|p=Purpur Pillar|L=Purpur Slab|S=Purpur Stairs
|----Layer 0|
       
  PPP  
 P   P 
 PL  P 
 P   P 
  PPP  
       
|----Layer 1|
       
  UUU  
 U L U 
 U   U 
 U   U 
  UUU  
       
|----Layer 2|
   S   
  UpU  
 U   U 
Su  LuS
 U   U 
  UpU  
   S   
|----Layer 3|
       
  UUU  
 U   U 
 U   U 
 U L U 
  UUU  
       
}}<noinclude>
[[ja:エンドシティ/構造/小さな塔]]
[[zh:末地城/结构/小塔楼]]
</noinclude>