{{structure info}}
==Materials==
{| class="wikitable" data-description="Materials"
|-
! Name !! Total
|-
| {{BlockLink|Bedrock}} || 41
|-
| {{BlockLink|Dragon Egg}} || 1
|-
| {{BlockLink|id=End Portal|End Portal (block)}} || 20
|-
| {{BlockLink|End Stone}} || 16
|-
| {{BlockLink|Torch}} || 4
|-
|}

==Blueprint==
<table><tr><td style="width:200px;">
{{layered blueprint|name=Exit Portal|default=Layer 4
|O=Bedrock|e=End Stone|P=End Portal?End Portal (block)|T=Torch|t=Torch-rot90|H=Torch-rot180|h=Torch-rot270|D=Dragon Egg
|----Layer 1|
  eee
 eOOOe
eOOOOOe
eOOOOOe
eOOOOOe
 eOOOe
  eee
|----Layer 2|
  OOO
 OPPPO
OPPPPPO
OPPOPPO
OPPPPPO
 OPPPO
  OOO
|----Layer 3|
 
 
 
   O
 
 
 
|----Layer 4|
 
 
   T
  hOt
   H
 
 
|----Layer 5|
 
 
     
   O
    
 
 
|----Layer 6|
 
 
    
   D
    
 
 
}}
</td><td style="vertical-align:top;">
[[File:EnderDragonPortal.png|200px|right]]
</td></tr></table>

<noinclude>
[[es:Portal de salida/Estructura]]
[[fr:Portail de sortie/Structure]]
[[ja:出口ポータル/構造]]
[[pt:Portal de saída/Estrutura]]
[[zh:返回传送门/结构]]
</noinclude>