{{structure info}}
==Skull 1==
<table><tr><td style="width:300px;">
{| class="wikitable"
|-
! Name !! Total !! Stack
|-
| {{BlockLink|Bone Block}}
| 86
| 1 + 22 blocks
|-
|}

This skull is 6×5×7 blocks.
{{layered blueprint|name=Skull 1|default=Layer 5
|v=Bone Block
|h=Bone Block-rot90
|t=Bone Block+top
|----Layer 1|
      
 hhhh 
 hhhh 
 hhhh 
 h  h 
 h  h 
      
|----Layer 2|
 t  t 
t    t
v    v
v    v
v    v
t    t
 thht 
|----Layer 3|
 tttt 
t    t
v    v
v    v
v    v
t    t
 thht 
|----Layer 4|
  hh  
t    t
v    v
v    v
v    v
t    t
 thht 
|----Layer 5|
      
 hhhh 
 hhhh 
 hhhh 
 hhhh 
 hhhh 
      
}}
</td><td style="vertical-align:top;">
[[File:Fossil Skull 1.png|150px|right]]
</td></tr></table>

==Skull 2==
<table><tr><td style="width:300px;">
{| class="wikitable"
|-
! Name !! Total !! Stack
|-
| {{BlockLink|Bone Block}}
| 75
| 1 + 11 blocks
|-
|}

This skull is 7×5×5 blocks.
{{layered blueprint|name=Skull 2|default=Layer 5
|v=Bone Block
|h=Bone Block-rot90
|t=Bone Block+top
|----Layer 1|
       
 hhhhh 
 hhhhh 
 hhhhh 
       
|----Layer 2|
 t   t 
t     t
v     v
t     t
 thhht 
|----Layer 3|
 thhht 
t     t
v     v
t     t
 thhht 
|----Layer 4|
 t t t 
t     t
v     v
t     t
 thhht 
|----Layer 5|
  h h  
 hhhhh 
 hhhhh 
 hhhhh 
       
}}
</td><td style="vertical-align:top;">
[[File:Fossil Skull 2.png|150px|right]]
</td></tr></table>

==Skull 3==
<table><tr><td style="width:300px;">
{| class="wikitable"
|-
! Name !! Total
|-
| {{BlockLink|Bone Block}}
| 58
|-
|}

This skull is 5×4×5 blocks.
{{layered blueprint|name=Skull 3|default=Layer 4
|v=Bone Block
|h=Bone Block-rot90
|t=Bone Block+top
|----Layer 1|
t   t
 hhh 
 hhh 
 hhh 
 hhh 
|----Layer 2|
thhht
v   v
v   v
v   v
thhht
|----Layer 3|
t t t
v   v
v   v
v   v
thhht
|----Layer 4|
hhhhh
 hhh 
 hhh 
 hhh 
     
}}
</td><td style="vertical-align:top;">
[[File:Fossil Skull 3.png|150px|right]]
</td></tr></table>

==Skull 4==
<table><tr><td style="width:300px;">
{| class="wikitable"
|-
! Name !! Total
|-
| {{BlockLink|Bone Block}}
| 32
|-
|}

This skull is 4×4×4 blocks.
{{layered blueprint|name=Skull 4|default=Layer 4
|v=Bone Block
|h=Bone Block-rot90
|t=Bone Block+top
|----Layer 1|
t  t
 hh 
 hh 
    
|----Layer 2|
thht
t  t
t  t
 tt 
|----Layer 3|
t  t
t  t
t  t
 tt 
|----Layer 4|
hhhh
 hh 
 hh 
    
}}
</td><td style="vertical-align:top;">
[[File:Fossil Skull 4.png|150px|right]]
</td></tr></table>

==Spine 1==
<table><tr><td style="width:300px;">
{| class="wikitable"
|-
! Name !! Total
|-
| {{BlockLink|Bone Block}}
| 37
|-
|}

This spine segment is 3×3×13 blocks.
{{layered blueprint|name=Spine 1|default=Layer 3
|v=Bone Block
|h=Bone Block-rot90
|t=Bone Block+top
|----Layer 1–2|
   
t t
   
t t
   
t t
   
t t
   
t t
   
t t
   
|----Layer 3|
 v 
 v 
 v 
 v 
 v 
 v 
 v 
 v 
 v 
 v 
 v 
 v 
 v 
}}
</td><td style="vertical-align:top;">
[[File:Fossil Spine 1.png|150px|right]]
</td></tr></table>

==Spine 2==
<table><tr><td style="width:300px;">
{| class="wikitable"
|-
! Name !! Total
|-
| {{BlockLink|Bone Block}}
| 61
|-
|}

This spine segment is 5×4×13 blocks.
{{layered blueprint|name=Spine 2|default=Layer 4
|v=Bone Block
|h=Bone Block-rot90
|t=Bone Block+top
|----Layer 1|
     
 h h 
     
 h h 
     
 h h 
     
 h h 
     
 h h 
     
 h h 
     
|----Layer 2–3|
     
t   t
     
t   t
     
t   t
     
t   t
     
t   t
     
t   t
     
|----Layer 4|
  v  
 hvh 
  v  
 hvh 
  v  
 hvh 
  v  
 hvh 
  v  
 hvh 
  v  
 hvh 
  v  
}}
</td><td style="vertical-align:top;">
[[File:Fossil Spine 2.png|150px|right]]
</td></tr></table>

==Spine 3==
<table><tr><td style="width:300px;">
{| class="wikitable"
|-
! Name !! Total !! Stack
|-
| {{BlockLink|Bone Block}}
| 97
| 1 + 33 blocks
|-
|}

This spine segment is 7×4×13 blocks.
{{layered blueprint|name=Spine 3|default=Layer 4
|v=Bone Block
|h=Bone Block-rot90
|t=Bone Block+top
|----Layer 1|
       
th   ht
       
th   ht
       
th   ht
       
th   ht
       
th   ht
       
th   ht
       
|----Layer 2–3|
       
t     t
       
t     t
       
t     t
       
t     t
       
t     t
       
t     t
       
|----Layer 4|
   v   
hhhvhhh
   v   
hhhvhhh
   v   
hhhvhhh
   v   
hhhvhhh
   v   
hhhvhhh
   v   
hhhvhhh
   v   
}}
</td><td style="vertical-align:top;">
[[File:Fossil Spine 3.png|150px|right]]
</td></tr></table>

==Spine 4==
<table><tr><td style="width:300px;">
{| class="wikitable"
|-
! Name !! Total !! Stack
|-
| {{BlockLink|Bone Block}}
| 121
| 1 + 57 blocks
|-
|}

This spine segment is 9×5×13 blocks.
{{layered blueprint|name=Spine 4|default=Layer 5
|v=Bone Block
|h=Bone Block-rot90
|t=Bone Block+top
|----Layer 1|
         
 hh   hh 
         
 hh   hh 
         
 hh   hh 
         
 hh   hh 
         
 hh   hh 
         
 hh   hh 
         
|----Layer 2–4|
         
t       t
         
t       t
         
t       t
         
t       t
         
t       t
         
t       t
         
|----Layer 5|
    v    
hhhhvhhhh
    v    
hhhhvhhhh
    v    
hhhhvhhhh
    v    
hhhhvhhhh
    v    
hhhhvhhhh
    v    
hhhhvhhhh
    v    
}}
</td><td style="vertical-align:top;">
[[File:Fossil Spine 4.png|150px|right]]
</td></tr></table>

[[fr:Fossile/Plan]]
[[ja:化石/構造]]
[[pt:Fóssil/Estrutura]]
[[zh:化石/结构]]