{{structure info}}
== Red Mushrooms ==
<table><tr><td style="width:200px;">
{{layered blueprint|name=Red Mushroom|default=Layer 4
|S=Mushroom Stem|R=Red Mushroom Block
|----Layer 0|
 
 
  S
|----Layer 1-3|
 RRR
R   R
R S R
R   R
 RRR
|----Layer 4|
 
 RRR
 RRR
 RRR
}}
</td><td style="vertical-align:top;">
[[File:Huge_Red_Mushroom.png|200px|right]]
</td></tr></table>

== Brown Mushrooms ==
<table><tr><td style="width:200px;">
{{layered blueprint|name=Brown Mushroom|default=Layer 1
|S=Mushroom Stem|B=Brown Mushroom Block
|----Layer 0|
 
 
 
   S
|----Layer 1|
 BBBBB
BBBBBBB
BBBBBBB
BBBBBBB
BBBBBBB
BBBBBBB
 BBBBB
}}
</td><td style="vertical-align:top;">
[[File:Huge_Brown_Mushroom.png|200px|right]]
</td></tr></table>

[[uk:Величезний гриб/Структура]]
[[zh:巨型蘑菇/结构]]