{{Structure info}}
[[File:Jungle pyramid JE2 BE2.png|thumb|A Jungle Temple, also known as a Jungle Pyramid.]]
<br />
==Materials==
{| class="wikitable"
|-
! Name !! Total !! Stack
|-
| {{BlockLink|Chest}}
| 2
|
|-
| {{BlockLink|Chiseled Stone Bricks}}
| 3
|
|-
| {{BlockLink|Cobblestone}} or {{BlockLink|Mossy Cobblestone}}
| 1159
| 18 + 7 blocks
|-
| {{BlockLink|Cobblestone Stairs}}
| 22
|
|-
| {{BlockLink|Dispenser}}
| 2
|
|-
| {{BlockLink|Lever}}
| 3
|
|-
| {{ItemLink|Redstone Dust}}
| 15
|
|-
| {{BlockLink|Redstone Repeater}}
| 1
|
|-
| {{BlockLink|Sticky Piston}}
| 3
|
|-
| {{ItemLink|String}}
| 5
|
|-
| {{BlockLink|Tripwire Hook}}
| 4
|
|-
| {{BlockLink|Vines}}
| 3
|
|-
|}

==Blueprint==
{| class="wikitable"
|-
! Layer !! Block !! Coords !! Facing
|-
| -2
| {{BlockLink|Chest}}
| 5x 10y
| East
|-
| -2
| {{BlockLink|Chest}}
| 12x 9y
| North
|-
| -2
| {{BlockLink|Cobblestone Stairs}}
|
| East
|-
| -1
| {{BlockLink|Dispenser}}
| All Dispensers
| Towards Vines
|-
| -1
| {{BlockLink|Sticky Piston}}
| 7x 11y
| North
|-
| -1
| {{BlockLink|Sticky Piston}}
| 7x 10y
| Up
|-
| -1
| {{BlockLink|Redstone Repeater}}
| 
| East
|-
| -1
| {{BlockLink|Cobblestone Stairs}}
|
| East
|-
| 0
| {{BlockLink|Sticky Piston}}
| 
| North
|-
| 0
| {{BlockLink|Cobblestone Stairs}}
|
| East
|-
| 1
| {{BlockLink|Cobblestone Stairs}}
| 9x 6y and 7y
| East
|-
| 1
| {{BlockLink|Cobblestone Stairs}}
| 15x 5y 6y 7y and 8y
| West
|-
| 2~4
| {{BlockLink|Cobblestone Stairs}}
|
| West
|-
| 10
| {{BlockLink|Cobblestone Stairs}}
| 7x 6y and 7y
| East
|-
| 10
| {{BlockLink|Cobblestone Stairs}}
| 9x 6y and 7y
| West
|-
|}
<table><tr><td style="width:100px;">
{{layered blueprint|name=Jungle pyramid|default=Layer -1
|C=Cobblestone
|T=Redstone Dust
|H=Tripwire Hook
|E=Chest-rot270
|S=Cobblestone Stairs
|A=tripwire
|U=Redstone Dust+up
|Y=Redstone Dust+upright
|M=Redstone Dust+upleft
|d=Redstone Dust+dot
|I=Tripwire+up
|V=Vines
|L=Lever-rot270
|B=Chiseled Stone Bricks
|P=Sticky Piston
|D=Dispenser
|R=Redstone Repeater+On-rot90
|e=Trapped Chest-rot180
|p=piston+side up
|@=Tripwire Hook-rot180
|----Layer -3|
CCCCCCCCCCCCCCC
CCCCCCCCCCCCCCC
CCCCCCCCCCCCCCC
CCCCCCCCCCCCCCC
CCCCCCCCCCCCCCC
CCCCCCCCCCCCCCC
CCCCCCCCCCCCCCC
CCCCCCCCCCCCCCC
CCCCCCCCCCCCCCC
CCCCCCCCCCCCCCC
CCCCCCCCCCCCCCC
CCCCCCCCCCCCCCC
|----Layer -2|
CCCCCCCCCCCCCCC
CC C C@C C C CC
C     I       C
C     I      CC
C  CCCHCCC   UC
C    SCTTTTTTMC
C    SCCCC   CC
C  CCCCCCHAAAHC
C  CCCCCUC e CC
C  CE  CYTC C C
C  CCCCCCCCCCCC
CCCCCCCCCCCCCCC
|----Layer -1|
CCCCCCCCCCCCCCC
CC C C C C C CC
C            CC
C           VDC
C  CCCCCC    CC
C     SCCC   CC
C     SCC     C
C  CCCCCCC   CC
C LBTT CC  V CC
C LB  PCC TD CC
C LBRCpCCCCCCCC
CCCCCCCCCCCCCCC
|----Layer 0 (Ground)|
CCCCCCCCCCCCCCC
C C C C C C C C
C C C C C C C C
C C C C C C C C
C  CCCCCC     C
C  C   SCC    C
C  C   SC    CC
C  CCCCCCC    C
C  C   CC  V  C
C  C   CCCCCCCC
C  C dpCCCCCCCC
CCCCCCCCCCCCCCC
|----Layer 1|
CCCCCCCCCCCCCCC
CCCCCCCCCCCCCCC
CCCCCCCCCCCCCCC
CCCCCCCCCCCCCCC
CCCCCCCCCCCCCCS
CCCCC   SCCCCCS
CCCCC   SCCCCCS
CCCCCCCCCCCCCCS
CCCCCCCCCCCCCCC
CCCCCCCCCCCCCCC
CCCCCCCCCCCCCCC
CCCCCCCCCCCCCCC
|----Layer 2|
 
 
  CCCCCCCCCCC
  C         C
  C CCS     C
  C C          
  C C          
  C CCS     C
  C         C
  CCCCCCCCCCC
 
 
|----Layer 3|
 
                
  CCCCCCCCCCC  
  C         C  
  C CS      C  
    C          
    C          
  C CS      C  
  C         C  
  CCCCCCCCCCC  
                
     
|----Layer 4|
               
 CCCCCCCCCCCCC 
 CCCCCCCCCCCCC 
 CCCCCCCCCCCCC 
 CCCS    CCCCC 
 CCCC    CCCCC 
 CCCC    CCCCC 
 CCCS    CCCCC 
 CCCCCCCCCCCCC 
 CCCCCCCCCCCCC 
 CCCCCCCCCCCCC 
               
|----Layer 5|
  C C C C C C  
 CCCCCCCCCCCCC 
CC           CC
 C           C 
CC       C   CC
 C       C   C 
 C       C   C 
CC       C   CC
 C           C 
CC           CC
 CCCCCCCCCCCCC 
  C C C C C C  
|----Layer 6|
  C C C C C C  
 CCCC CCC CCCC 
CC           CC
 C           C 
CC           CC
               
               
CC           CC
 C           C 
CC           CC
 CCCC CCC CCCC 
  C C C C C C
|----Layer 7|
     C   C     
 CCCCCCCCCCCCC 
 CCCCCCCCCCCCC 
 CCCCCCCCCCCCC 
 CCCC     CCCC 
 CCCC     CCCCC
 CCCC     CCCCC
 CCCC     CCCC 
 CCCCCCCCCCCCC 
 CCCCCCCCCCCCC 
 CCCCCCCCCCCCC 
     C   C     
|----Layer 8|
                
                
  C         C  
   CCCCCCCCC   
   CCCCCCCCC   
   CCC   CCC   
   CCC   CCC   
   CCCCCCCCC   
   CCCCCCCCC   
  C         C  
                
        
|----Layer 9|
                
                
  C         C  
               
    CCCCCCC    
    CCCCCCC    
    CCCCCCC    
    CCCCCCC    
               
  C         C  
               
     
|----Layer 10|
                
                
  C         C  
               
    C     C    
      SCS      
      SCS      
    C     C    
               
  C         C  
                
 
}}
</td><td style="vertical-align:top;"></td></tr></table>

[[Category:Structure Blueprints]]

[[fr:Temple de la jungle/Structure]]
[[zh:丛林神庙/结构]]