{{Structure info}}

== Materials ==
<!-- WHY ARE ALL THE MATERIALS HAVING PLUS?! Because it depends on how big the mineshaft you will build. -->
{| class="wikitable"
! Name !! Total !! Stack
|-
| {{BlockSprite|oak planks}} Matching [[planks]]
| 6+
| rowspan=9 | < 1
|-
| {{BlockSprite|fences|link=Fence}} Matching [[fence]]
| 8+
|-
| {{BlockSprite|rail|link=Rail|text=Rail}}
| 4+
|-
| {{BlockSprite|torch|link=Torch|text=Torch}}
| 1+
|-
| {{BlockSprite|cobweb|link=Cobweb|text=Cobweb}}
| 39+
|-
| {{BlockSprite|monster spawner|link=Monster Spawner|text=Monster Spawner}}
| 1+
|-
| {{EntitySprite|minecart-with-chest|link=Minecart with Chest|text=Minecart with Chest}}
| 1+
|-
| {{BlockLink|Oak Log}}
| 
|-
| {{BlockLink|Iron Chain}}
|
|}

== Blueprint ==
<!-- WHY SMALL?! It depends on how big you will build the mineshaft. --><!-- I believe there are a few rooms missing that generate with the mineshaft. I'm not sure there exact layout, but there still part of the mineshaft. -->
''The [[minecart with chest]] can be placed anywhere on top of [[rail]].''
''The [[monster spawner]] should contain [[cave spider]].''
''Stone is replaced with whatever the floor material is.''
''The Starting Room can have up to 4 exits and may only spawn once''
=== Rail area ===
<table><tr><td style="width:150px;">
{{layered blueprint|name=Rail Area|default=Layer 1
|R=Rail|F=Oak Fence|P=Oak Planks
|----Layer 1|
FRF
 R
 R
 R
 R
FRF
|----Layer 2|
F F



 
F F
|----Layer 3|
PPP
 

  
  
PPP
}}
</td><td style="vertical-align:top;">
[[File:SBP_Rail_Area.png|200px|right]]
</td></tr></table>

=== Monster spawner area ===
<table><tr><td style="width:150px;">
{{layered blueprint|name=Monster Spawner Area|default=Layer 1
|F=Oak Fence|W=Cobweb|S=Monster Spawner|P=Oak Planks
|----Layer 1|
FWF
WWW
WWW
WWW
WSW
FWF
|----Layer 2|
FWF
WWW
WWW
WWW
WWW
FWF
|----Layer 3|
PPP
WWW
WWW
WWW
WWW
PPP
}}
</td><td style="vertical-align:top;">
[[File:SBP_Spawner_Area.png|200px|right]]
</td></tr></table>

=== Intersection area ===
<table><tr><td style="width:175px;">
{{layered blueprint|name=Intersection Area|default=Ground layer
|S=Stone|W=Oak Planks
|----Ground layer|
SSS
SSS
SSS
|----Layers 1-3|
W W
 
W W
}}
</td><td style="vertical-align:top;">
[[File:SBP_Intersection_Area.png|150px|right]]
</td></tr></table>

=== Staircase ===
<table><tr><td style="width:200px;">
{{layered blueprint|name=Staircase|default=Ground layer
|s=Stone
|----Ground layer|
sss
sss
   
   
   
   
   
|----Layer 1|
   
   
sss
   
   
   
   
|----Layer 2|
   
   
   
sss
   
   
   
|----Layer 3|
   
   
   
   
sss
   
   
|----Layer 4|
sss
   
   
   
   
sss
sss
|----Layer 5|
   
sss
   
   
   
   
   
|----Layer 6|
   
   
sss
   
   
   
   
|----Layer 7|
   
   
   
sss

   
   
|----Layer 8|
   
   
   
   
sss
sss
sss
}}
</td></tr></table>

===Short Tunnel===
<table><tr><td style="width:200px;">
{{layered blueprint|name=Short Tunnel|default=Ground layer
|s=Stone
|----Ground layer|
sss
sss
|----Layer 1-3|
   
   
|----Layer 4|
sss
sss
}}
</td></tr></table>

===Starting Room===
<table><tr><td style="width:200px;">
{{layered blueprint|name=Start|default=Ground layer
|s=Stone
|----Ground layer|
ssssssss
ssssssss
ssssssss
ssssssss
ssssssss
ssssssss
ssssssss
ssssssss
ssssssss
ssssssss
ssssssss
|----Layer 1-5|
        
        
        
        
        
        
        
        
        
        
        
|----Layer 6|
ssssssss
ssssssss
ssssssss
ssssssss
ssssssss
ssssssss
ssssssss
ssssssss
ssssssss
ssssssss
ssssssss
}}
</td></tr></table>
[[Category:Structure Blueprints]]

[[fr:Puits de mine abandonné/Structure]]
[[ja:廃坑/構造]]
[[zh:废弃矿井/结构]]