<noinclude>{{structure info}}</noinclude>
These are used to connect bridges and corridors. On Layer 4, the three fences above the path show the bridge side.
====Materials====
{| class="wikitable"
|-
! Name!!Total!!Stack
|-
|{{BlockLink|Nether Bricks}}
|1,447
|22 + 39 blocks
|-
|{{BlockLink|Nether Brick Fence}}
|91
|1 + 27 blocks
|-
|{{BlockLink|Lava}}
|1
|
|-
|}

==== Blueprint====
{{layered blueprint|name=Cauldron Room|default=Layer 2
|N=Nether Bricks|F=Nether Brick Fence|L=Lava
|----Layer -5 to ground|
    NNNNN    
    NNNNN    
    NNNNN    
             
NNN       NNN
NNN       NNN
NNN       NNN
NNN       NNN
NNN       NNN
             
    NNNNN    
    NNNNN    
    NNNNN    
|----Layer -4|
    NNNNN    
    NNNNN    
    NNNNN    
    NNNNN    
NNNN     NNNN
NNNN     NNNN
NNNN  N  NNNN
NNNN     NNNN
NNNN     NNNN
    NNNNN    
    NNNNN    
    NNNNN    
    NNNNN    
|----Layer -3|
    NNNNN    
    NNNNN    
    NNNNN    
    NNNNN    
NNNN     NNNN
NNNN     NNNN
NNNN     NNNN
NNNN     NNNN
NNNN     NNNN
    NNNNN    
    NNNNN    
    NNNNN    
    NNNNN    
|----Layer -2|
    NNNNN    
    NNNNN    
    NNNNN    
    NNNNN    
NNNNNNNNNNNNN
NNNNNNNNNNNNN
NNNNNN NNNNNN
NNNNNNNNNNNNN
NNNNNNNNNNNNN
    NNNNN    
    NNNNN    
    NNNNN    
    NNNNN    
|----Layer -1 & 0|
NNNNNNNNNNNNN
NNNNNNNNNNNNN
NNNNNNNNNNNNN
NNNNNNNNNNNNN
NNNNNNNNNNNNN
NNNNNNNNNNNNN
NNNNNN NNNNNN
NNNNNNNNNNNNN
NNNNNNNNNNNNN
NNNNNNNNNNNNN
NNNNNNNNNNNNN
NNNNNNNNNNNNN
NNNNNNNNNNNNN
|----Layer 1|
NNNNN   NNNNN
NNNNN   NNNNN
NN         NN
NN         NN
NN         NN
NN   NNN   NN
NN   NLN   NN
NN   NNN   NN
NN         NN
NN         NN
NN         NN
NNNNN   NNNNN
NNNNN   NNNNN
|----Layer 2|
NNNNN   NNNNN
NNNNN   NNNNN
NN         NN
NN         NN
NN         NN
NN         NN
NN         NN
NN         NN
NN         NN
NN         NN
NN         NN
NNNNN   NNNNN
NNNNN   NNNNN
|----Layer 3|
NNNNN   NNNNN
NNNNN   NNNNN
NN         NN
NF         FN
NN         NN
NF         FN
NN         NN
NF         FN
NN         NN
NF         FN
NN         NN
NNNNN   NNNNN
NNNNN   NNNNN
|----Layer 4|
NNNNNFFFNNNNN
NNNNN   NNNNN
NN         NN
NF         FN
NN         NN
NF         FN
NN         NN
NF         FN
NN         NN
NF         FN
NN         NN
NNNNN   NNNNN
NNNNN   NNNNN
|----Layer 5|
NNNNNNNNNNNNN
NNNNNNNNNNNNN
NN         NN
NN         NN
NN         NN
NN         NN
NN         NN
NN         NN
NN         NN
NN         NN
NN         NN
NNNNNNNNNNNNN
NNNNNNNNNNNNN
|----Layer 6|
NFNFNFNFNFNFN
FNNNNNNNNNNNF
NN         NN
FN         NF
NN         NN
FN         NF
NN         NN
FN         NF
NN         NN
FN         NF
NN         NN
FNNNNNNNNNNNF
NFNFNFNFNFNFN
|----Layer 7|
NFNFNFNFNFNFN
FNNNNNNNNNNNF
NNNNNNNNNNNNN
FNNNNNNNNNNNF
NNNNNNNNNNNNN
FNNNNNNNNNNNF
NNNNNNNNNNNNN
FNNNNNNNNNNNF
NNNNNNNNNNNNN
FNNNNNNNNNNNF
NNNNNNNNNNNNN
FNNNNNNNNNNNF
NFNFNFNFNFNFN
|----Layer 8|
NNNNNNNNNNNNN
NNNNNNNNNNNNN
NNNNNNNNNNNNN
NNNNNNNNNNNNN
NNNNNNNNNNNNN
NNNNNNNNNNNNN
NNNNNNNNNNNNN
NNNNNNNNNNNNN
NNNNNNNNNNNNN
NNNNNNNNNNNNN
NNNNNNNNNNNNN
NNNNNNNNNNNNN
NNNNNNNNNNNNN
|----Layer 9|
FNFNFNFNFNFNF
N           N
F           F
N           N
F           F
N           N
F           F
N           N
F           F
N           N
F           F
N           N
FNFNFNFNFNFNF
}}<noinclude>
[[fr:Forteresse du Nether/Structure/Salle du puits de lave]]
[[zh:下界要塞/结构/熔岩井房间]]
</noinclude>