<noinclude>{{structure info}}</noinclude>
The staircase goes to the right and the exit is to the left at the top. These connect to bridges on the top and bottom. These can be mirrored to turn the other direction.
====Materials====
{| class="wikitable"
|-
! Name!!Total!!Stack
|-
|{{BlockLink|Nether Bricks}}
|222
|3 + 30
|-
|{{BlockLink|Nether Brick Fence}}
|18
|
|-
|}

==== Blueprint====
{{layered blueprint|name=Bridge Staircases|default=Layer 4
|N=Nether Bricks|F=Nether Brick Fence
|----Layer 0 to ground|
NNNNNNN
NNNNNNN
NNNNNNN
NNNNNNN
NNNNNNN
NNNNNNN
NNNNNNN
|----Layer 1|
NNNNNNN
NNNNNNN
N     N
N     N
N     N
N     N
NN   NN
|----Layer 2|
NNNNNNN
N NNNNN
F     F
N     F
F     F
N     N
NN   NN
|----Layer 3|
NNNNNNN
N  NNNN
F     F
N     F
F     F
N     N
NN   NN
|----Layer 4|
NNNNNNN
N   NNN
F     F
N     F
F     F
N     N
NNFFFNN
|----Layer 5|
NNNNNNN
N    NN
N     N
N     N
N     N
N     N
NNNNNNN
|----Layer 6|
NNNNNNN
N     N
NNNNNNN
NNNNNNN
NNNNNNN
NNNNNNN
NNNNNNN
|----Layer 7|
NNNNNNN
N     N
      N
      N
      N
N     N
NNNNNNN
}}<noinclude>
[[fr:Forteresse du Nether/Structure/Escaliers de pont]]
[[zh:下界要塞/结构/桥间楼梯]]
</noinclude>