<noinclude>{{structure info}}</noinclude>
These are made in 5×5 segments.
==== Materials ====
{| class="wikitable"
|-
! Name !! Total !! Stack
|-
|{{BlockLink|Nether Bricks}}
|82
|1 + 24
|-
|{{BlockLink|Nether Brick Fence}}
|8
|
|-
|}

==== Blueprints ====
{{layered blueprint|name=Straight Corridor|default=Layer 2-3
|N=Nether Bricks|F=Nether Brick Fence
|----Layer 0 to ground|
NNNNN
NNNNN
NNNNN
NNNNN
NNNNN
|----Layer 1|
N   N
N   N
N   N
N   N
N   N
|----Layer 2-3|
N   N
F   F
N   N
F   F
N   N
|----Layer 4|
N   N
N   N
N   N
N   N
N   N
|----Layer 5|
NNNNN
NNNNN
NNNNN
NNNNN
NNNNN
}}<noinclude>
[[fr:Forteresse du Nether/Structure/Corridor droit]]
[[zh:下界要塞/结构/直走廊]]
</noinclude>