<noinclude>{{structure info}}</noinclude>
These intersections connect four bridges and are somewhat closed-in.
====Materials====
{| class="wikitable"
|-
! Name!!Total!!Stack
|-
|{{BlockLink|Nether Bricks}}
|121
|1 + 57 blocks
|-
| {{BlockLink|Nether Brick Fence}}
|12
|
|-
|}

==== Blueprint====
{{layered blueprint|name=Bridge Closed Intersection|default=Layer 1-3
|N=Nether Bricks|F=Nether Brick Fence
|----Layer 0 to ground|
NNNNNNN
NNNNNNN
NNNNNNN
NNNNNNN
NNNNNNN
NNNNNNN
NNNNNNN
|----Layer 1-3|
NN   NN
N     N
       
       
       
N     N
NN   NN
|----Layer 4|
NNFFFNN
N     N
F     F
F     F
F     F
N     N
NNFFFNN
|----Layer 5|
NNNNNNN
N     N
N     N
N     N
N     N
N     N
NNNNNNN
}}<noinclude>
[[fr:Forteresse du Nether/Structure/Intersection du pont fermé]]
[[zh:下界要塞/结构/闭桥十字]]
</noinclude>