<noinclude>{{structure info}}</noinclude>
These staircases connect to corridors.
==== Materials ====
{| class="wikitable"
|-
! Name !! Total !! Stack
|-
|{{BlockLink|Nether Bricks}}
|289
|4 + 33
|-
|{{BlockLink|Nether Brick Fence}}
|20
|
|-
|{{BlockLink|Nether Brick Stairs}}
|21
|
|-
|}

==== Blueprints ====
{{layered blueprint|name=Corridor Staircase|default=Layer 5
|N=Nether Bricks|F=Nether Brick Fence|S=Nether Brick Stairs
|----Layer 0 to ground|
NNNNN
NNNNN
NNNNN
NNNNN
NNNNN
NNNNN
NNNNN
NNNNN
NNNNN
NNNNN
|----Layer 1|
N   N
N   N
N   N
NSSSN
NNNNN
NNNNN
NNNNN
NNNNN
NNNNN
NNNNN
|----Layer 2|
N   N
F   F
N   N
F   F
NSSSN
NNNNN
NNNNN
NNNNN
NNNNN
NNNNN
|----Layer 3|
N   N
F   F
N   N
F   F
N   N
FSSSF
NNNNN
NNNNN
NNNNN
NNNNN
|----Layer 4|
N   N
N   N
N   N
N   N
N   N
F   F
NSSSN
NNNNN
NNNNN
NNNNN
|----Layer 5|
NNNNN
NNNNN
N   N
N   N
N   N
N   N
N   N
FSSSF
NNNNN
NNNNN
|----Layer 6|
     
    
NNNNN
N   N
N   N
N   N
N   N
F   F
NSSSN
NNNNN
|----Layer 7|
     
     
     
NNNNN
N   N
N   N
N   N
N   N
N   N
FSSSF
|----Layer 8|
     
     
     
     
NNNNN
N   N
N   N
N   N
N   N
F   F
|----Layer 9|
     
     
     
     
     
NNNNN
N   N
N   N
N   N
N   N
|----Layer 10|
     
     
     
     
     
     
NNNNN
N   N
N   N
N   N
|----Layer 11|
     
     
     
     
     
     
     
NNNNN
NNNNN
NNNNN
}}<noinclude>
[[fr:Forteresse du Nether/Structure/Escaliers de corridor]]
[[zh:下界要塞/结构/走廊楼梯]]
</noinclude>