<noinclude>{{structure info}}</noinclude>
These connect to four corridors.
====Materials====
{| class="wikitable"
|-
!Name!!Total!!Stack
|-
|{{BlockLink|Nether Bricks}}
| 66
| 1 + 2 blocks
|-
|}

====Blueprint====
{{layered blueprint|name=Corridor Intersection|default=Layer 1-4
|N=Nether Bricks
|----Layer 0 to ground|
NNNNN
NNNNN
NNNNN
NNNNN
NNNNN
|----Layer 1-4|
N   N
      
      
      
N   N
|----Layer 5|
NNNNN
NNNNN
NNNNN
NNNNN
NNNNN
}}<noinclude>
[[fr:Forteresse du Nether/Structure/Intersection du corridor]]
[[zh:下界要塞/结构/走廊十字]]
</noinclude>