<noinclude>{{structure info}}</noinclude>
Layer 9 is split in two because there is a possibility of an exit going up the stairs. These connect to three corridors.
==== Materials ====
{| class="wikitable"
|-
! Name !! Total !! Stack
|-
|{{BlockLink|Nether Bricks}}
|1,479 (-2 if stair exit)
|22 + 51 blocks
|-
|{{BlockLink|Nether Brick Fence}}
|93 (-1 if stair exit)
|1 + 29 blocks
|-
|{{BlockLink|Nether Wart}}
|20
|
|-
|{{BlockLink|Nether Brick Stairs}}
|32
|
|-
|{{BlockLink|Soul Sand}}
|20
|
|-
|}

==== Blueprints ====
{{layered blueprint|name=Nether Wart Farm|default=Layer 2
|N=Nether Bricks|F=Nether Brick Fence|W=Nether Wart|S=Nether Brick Stairs|$=Soul Sand
|----Layer -5 to ground|
    NNNNN    
    NNNNN    
    NNNNN    
             
NNN       NNN
NNN       NNN
NNN       NNN
NNN       NNN
NNN       NNN
             
    NNNNN    
    NNNNN    
    NNNNN    
|----Layer -4 & -3|
    NNNNN    
    NNNNN    
    NNNNN    
    NNNNN    
NNNN     NNNN
NNNN     NNNN
NNNN     NNNN
NNNN     NNNN
NNNN     NNNN
    NNNNN    
    NNNNN    
    NNNNN    
    NNNNN    
|----Layer -2|
    NNNNN    
    NNNNN    
    NNNNN    
    NNNNN    
NNNNNNNNNNNNN
NNNNNNNNNNNNN
NNNNNNNNNNNNN
NNNNNNNNNNNNN
NNNNNNNNNNNNN
    NNNNN    
    NNNNN    
    NNNNN    
    NNNNN    
|----Layer -1|
NNNNNNNNNNNNN
NNNNNNNNNNNNN
NNNNNNNNNNNNN
NNNNNNNNNNNNN
NNNNNNNNNNNNN
NNNNNNNNNNNNN
NNNNNNNNNNNNN
NNNNNNNNNNNNN
NNNNNNNNNNNNN
NNNNNNNNNNNNN
NNNNNNNNNNNNN
NNNNNNNNNNNNN
NNNNNNNNNNNNN
|----Layer 0|
NNNNNNNNNNNNN
NNNNNNNNNNNNN
NNNNNNNNNNNNN
NNNNNNNNNNNNN
NNN$$NNN$$NNN
NNN$$NNN$$NNN
NNN$$NNN$$NNN
NNN$$NNN$$NNN
NNN$$NNN$$NNN
NNNNNNNNNNNNN
NNNNNNNNNNNNN
NNNNNNNNNNNNN
NNNNNNNNNNNNN
|----Layer 1|
NNNNN   NNNNN
NNNNN   NNNNN
NNNNS   SNNNN
NNNNS   SNNNN
NNNWWNNNWWNNN
NNNWWNNNWWNNN
NNNWWNNNWWNNN
NNNWWNNNWWNNN
NNNWWSSSWWNNN
NNNNS   SNNNN
NNNNS   SNNNN
NNNNN   NNNNN
NNNNN   NNNNN
|----Layer 2|
NNNNN   NNNNN
NNNNN   NNNNN
NN         NN
NN         NN
NN   NNN   NN
NN   FNF   NN
NN   NNN   NN
NN   SSS   NN
NN         NN
NN         NN
NN         NN
NNNNN   NNNNN
NNNNN   NNNNN
|----Layer 3|
NNNNN   NNNNN
NNNNN   NNNNN
NN         NN
NF         FN
NN   NNN   NN
NF   FNF   FN
NN   SSS   NN
NF         FN
NN         NN
NF         FN
NN         NN
NNNNN   NNNNN
NNNNN   NNNNN
|----Layer 4|
NNNNN   NNNNN
NNNNN   NNNNN
NN   NNN   NN
NF   NNN   FN
NN   NNN   NN
NF   SSS   FN
NN         NN
NF         FN
NN         NN
NF         FN
NN         NN
NNNNN   NNNNN
NNNNN   NNNNN
|----Layer 5|
NNNNNNNNNNNNN
NNNNNNNNNNNNN
NN   NNN   NN
NN   NNN   NN
NN   SSS   NN
NN         NN
NN         NN
NN         NN
NN         NN
NN         NN
NN         NN
NNNNNNNNNNNNN
NNNNNNNNNNNNN
|----Layer 6|
NFNFNFNFNFNFN
FNNNNNNNNNNNF
NN   NNN   NN
FN   SSS   NF
NN         NN
FN         NF
NN         NN
FN         NF
NN         NN
FN         NF
NN         NN
FNNNNNNNNNNNF
NFNFNFNFNFNFN
|----Layer 7|
NFNFNFNFNFNFN
FNNNNNNNNNNNF
NNNNNSSSNNNNN
FNNNN   NNNNF
NNNNN   NNNNN
FNNNN   NNNNF
NNNNN   NNNNN
FNNNNNNNNNNNF
NNNNNNNNNNNNN
FNNNNNNNNNNNF
NNNNNNNNNNNNN
FNNNNNNNNNNNF
NFNFNFNFNFNFN
|----Layer 8|
NNNNNNNNNNNNN
NNNNNSSSNNNNN
NNNNN   NNNNN
NNNNN   NNNNN
NNNNN   NNNNN
NNNNN   NNNNN
NNNNNNNNNNNNN
NNNNNNNNNNNNN
NNNNNNNNNNNNN
NNNNNNNNNNNNN
NNNNNNNNNNNNN
NNNNNNNNNNNNN
NNNNNNNNNNNNN
|----Layer 9a|
FNFNFNFNFNFNF
N           N
F           F
N           N
F           F
N           N
F           F
N           N
F           F
N           N
F           F
N           N
FNFNFNFNFNFNF
|----Layer 9b|
FNFNF   FNFNF
N           N
F           F
N           N
F           F
N           N
F           F
N           N
F           F
N           N
F           F
N           N
FNFNFNFNFNFNF
}}<noinclude>
[[fr:Forteresse du Nether/Structure/Ferme de verrues du Nether]]
[[zh:下界要塞/结构/下界疣农场]]
</noinclude>