<noinclude>{{structure info}}</noinclude>
====Materials====
{| class="wikitable"
|-
! Name!!Total!!Stack
|-
|{{BlockLink|Nether Bricks}}
|374
|5 + 54 blocks
|-
|{{BlockLink|Nether Brick Fence}}
|24
|
|-
|}

==== Blueprint====
{{layered blueprint|name=Bridge|default=Layer 1
|N=Nether Bricks|F=Nether Brick Fence
|----Layer -5 to ground|
NNNNN
NNNNN
NNNNN
     
     
     
     
     
     
     
     
     
     
     
     
     
NNNNN
NNNNN
NNNNN
|----Layer -4|
NNNNN
NNNNN
NNNNN
NNNNN
     
     
     
     
     
     
     
     
     
     
     
NNNNN
NNNNN
NNNNN
NNNNN
|----Layer -3|
NNNNN
FNNNF
NNNNN
NNNNN
     
     
     
     
     
     
     
     
     
     
     
NNNNN
NNNNN
FNNNF
NNNNN
|----Layer -2|
NNNNN
FNNNF
NNNNN
NNNNN
NNNNN
NNNNN
     
     
     
     
     
     
     
NNNNN
NNNNN
NNNNN
NNNNN
FNNNF
NNNNN
|----Layer -1 & 0|
NNNNN
FNNNF
NNNNN
NNNNN
FNNNF
NNNNN
NNNNN
NNNNN
NNNNN
NNNNN
NNNNN
NNNNN
NNNNN
NNNNN
FNNNF
NNNNN
NNNNN
FNNNF
NNNNN
|----Layer 1|
N   N
N   N
N   N
N   N
N   N
N   N
N   N
N   N
N   N
N   N
N   N
N   N
N   N
N   N
N   N
N   N
N   N
N   N
N   N
}}<noinclude>
[[fr:Forteresse du Nether/Structure/Ponts]]
[[zh:下界要塞/结构/桥]]
</noinclude>