{{structure info}}
{{outdated|edition=bedrock}}
[[File:Nether Spire.png|thumb|A nether spire]]

== Nether Reactor ==
=== Materials ===
{| class="wikitable sortable mw-collapsible"
|-
!Name !!Layer 1 !!Layer 2 !!Layer 3 !!Total
|-
| {{LegacyBlockSprite|cobblestone-je3-be2|link=Cobblestone|text=Cobblestone}} || 5 || 4 || 5 || 14
|-
| {{LegacyBlockSprite|block-of-gold-be2|link=Block of Gold|text=Block of Gold}} || 4 || — || — || 4
|-
| {{LegacyBlockSprite|nether-reactor-stage-0|link=Nether Reactor Core|text=Nether Reactor Core}} || — || 1 || — || 1
|}

=== Blueprint ===
{{layered blueprint|name=Nether Reactor|default=Layer 0|R=LegacyBlockSprite:+nether-reactor-stage-0|C=LegacyBlockSprite:+cobblestone-je3-be2|G=LegacyBlockSprite:+block-of-gold-be2
|----Layer 0|
GCG
CCC
GCG
|----Layer 1|
C C
 R 
C C
|----Layer 2|
 C 
CCC
 C 
}}

== Nether Spire ==
=== Materials ===
{| class="wikitable sortable mw-collapsible"
|-
!Name !!Total !! Stack
|-
| {{LegacyBlockSprite|netherrack-je2-be1|link=Netherrack|text=Netherrack}} || 3,142 || 49 stacks & 6 blocks
|-
| {{BlockSprite|glowing-obsidian|link=Glowing Obsidian|text=Glowing Obsidian}} || 18 ||
|-
| {{LegacyBlockSprite|nether-reactor-stage-3|link=Nether Reactor Core|text=Nether Reactor Core}} || 1 ||
|}

=== Blueprint ===
'''Note:''' Some of the netherrack blocks on layers 0–32 disappear once the Nether reactor's spawn cycle ends.
{{layered blueprint|name=Nether Spire|default=Layer 0|R=LegacyBlockSprite:+nether-reactor-stage-3|O=+glowing-obsidian|N=LegacyBlockSprite:+netherrack-je2-be1
|----Layers −2–−1|
NNNNNNNNNNNNNNNNN
NNNNNNNNNNNNNNNNN
NNNNNNNNNNNNNNNNN
NNNNNNNNNNNNNNNNN
NNNNNNNNNNNNNNNNN
NNNNNNNNNNNNNNNNN
NNNNNNNNNNNNNNNNN
NNNNNNNNNNNNNNNNN
NNNNNNNNNNNNNNNNN
NNNNNNNNNNNNNNNNN
NNNNNNNNNNNNNNNNN
NNNNNNNNNNNNNNNNN
NNNNNNNNNNNNNNNNN
NNNNNNNNNNNNNNNNN
NNNNNNNNNNNNNNNNN
NNNNNNNNNNNNNNNNN
NNNNNNNNNNNNNNNNN
|----Layer 0|
NNNNNNNNNNNNNNNNN
N               N
N               N
N               N
N               N
N               N
N               N
N      OOO      N
N      OOO      N
N      OOO      N
N               N
N               N
N               N
N               N
N               N
N               N
NNNNNNNNNNNNNNNNN
|----Layer 1|
NNNNNNNNNNNNNNNNN
N               N
N               N
N               N
N               N
N               N
N               N
N      O O      N
N       R       N
N      O O      N
N               N
N               N
N               N
N               N
N               N
N               N
NNNNNNNNNNNNNNNNN
|----Layer 2|
NNNNNNNNNNNNNNNNN
N               N
N               N
N               N
N               N
N               N
N               N
N       O       N
N      OOO      N
N       O       N
N               N
N               N
N               N
N               N
N               N
N               N
NNNNNNNNNNNNNNNNN
|----Layer 3|
NNNNNNNNNNNNNNNNN
N               N
N               N
N               N
N               N
N               N
N               N
N               N
N               N
N               N
N               N
N               N
N               N
N               N
N               N
N               N
NNNNNNNNNNNNNNNNN
|----Layer 4|
NNNNNNNNNNNNNNNNN
NNNNNNNNNNNNNNNNN
NNNNNNNNNNNNNNNNN
NNNNNNNNNNNNNNNNN
NNNNNNNNNNNNNNNNN
NNNNNNNNNNNNNNNNN
NNNNNNNNNNNNNNNNN
NNNNNNNNNNNNNNNNN
NNNNNNNNNNNNNNNNN
NNNNNNNNNNNNNNNNN
NNNNNNNNNNNNNNNNN
NNNNNNNNNNNNNNNNN
NNNNNNNNNNNNNNNNN
NNNNNNNNNNNNNNNNN
NNNNNNNNNNNNNNNNN
NNNNNNNNNNNNNNNNN
NNNNNNNNNNNNNNNNN
|----Layer 5|
NNNNNNNNNNNNNNNNN
N               N
N               N
N               N
N               N
N               N
N               N
N               N
N               N
N               N
N               N
N               N
N               N
N               N
N               N
N               N
NNNNNNNNNNNNNNNNN
|----Layer 6|
NNNNNNNNNNNNNNNNN
N               N
N               N
N  NNNNNNNNNNN  N
N  N         N  N
N  N         N  N
N  N         N  N
N  N         N  N
N  N         N  N
N  N         N  N
N  N         N  N
N  N         N  N
N  N         N  N
N  NNNNNNNNNNN  N
N               N
N               N
NNNNNNNNNNNNNNNNN
|----Layer 7|
NNNNNNNNNNNNNNNNN
N               N
N               N
N  NNNNNNNNNNN  N
N  N         N  N
N  N         N  N
N  N         N  N
N  N         N  N
N  N         N  N
N  N         N  N
N  N         N  N
N  N         N  N
N  N         N  N
N  NNNNNNNNNNN  N
N              NN
N             NNN
NNNNNNNNNNNNNNNN 
|----Layer 8|
NNNNNNNNNNNNNNNNN
N               N
N               N
N  NNNNNNNNNNN  N
N  N         N  N
N  N         N  N
N  N         N  N
N  N         N  N
N  N         N  N
N  N         N  N
N  N         N  N
N  N         N  N
N  N         N NN
N  NNNNNNNNNNNNNN
N            NNN 
N           NNN  
NNNNNNNNNNNNNN   
|----Layer 9|
NNNNNNNNNNNNNNNNN
N               N
N               N
N  NNNNNNNNNNN  N
N  N         N  N
N  N         N  N
N  N         N  N
N  N         N  N
N  N         N  N
N  N         N  N
N  N         N NN
N  N         NNNN
N  N         NNN 
N  NNNNNNNNNNNN  
N          NNN   
N         NNN    
NNNNNNNNNNNN     
|----Layer 10|
NNNNNNNNNNNNNNNNN
N               N
N               N
N  NNNNNNNNNNN  N
N  N         N  N
N  N         N  N
N  N         N  N
N  N         N  N
N  N         N NN
N  N         NNNN
N  N         NNN 
N  N        NNN  
N  N       NNN   
N  NNNNNNNNNNN   
N        NNN     
N       NNN      
NNNNNNNNNN       
|----Layer 11|
NNNNNNNNNNNNNNNNN
N               N
N               N
N  NNNNNNNNNNN  N
N  N         N  N
N  N         N  N
N  N         N NN
N  N         NNNN
N  N         NNN 
N  N        NNN  
N  N       NNN   
N  N      NNNN   
N  N     NNN N   
N  NNNNNNNNNNN   
N      NNN       
N     NNN        
NNNNNNNN         
|----Layer 12|
NNNNNNNNNNNNNNNNN
N               N
N               N
N  NNNNNNNNNNN  N
N  N         N NN
N  N NNNNNNN NNNN
N  N N     N NNN 
N  N N     NNNN  
N  N N     NNN   
N  N N    NNNN   
N  N N   NNN N   
N  N NNNNNNN N   
N  N   NNN   N   
N  NNNNNNNNNNN   
N    NNN         
N   NNN          
NNNNNN           
|----Layer 13|
NNNNNNNNNNNNNNNNN
N               N
N              NN
N  NNNNNNNNNNNNNN
N  N         NNN 
N  N NNNNNNNNNN  
N  N N     NNN   
N  N N    NNNN   
N  N N   NNN N   
N  N N  NNNN N   
N  N N NNN N N   
N  N NNNNNNN N   
N  N NNN     N   
N  NNNNNNNNNNN   
N  NNN           
N NNN            
NNNN             
|----Layer 14|
NNNNNNNNNNNNNNNNN
N             NNN
N            NNN 
N  NNNNNNNNNNNN  
N  NN      NNN   
N  N NNNNNNNNN   
N  N N   NNN N   
N  N N  NNNN N   
N  N N NNN N N   
N  N NNNN  N N   
N  N NNN   N N   
N  NNNNNNNNN N   
N  NNN       N   
N NNNNNNNNNNNN   
NNNN             
NNN              
NN               
|----Layer 15|
NNNNNNNNNNNNNNNN 
N           NNN  
N          NNN   
N    NNNNNNNNN   
N   NNN  NNN N   
N  NNNNNNNNN N   
N  NNN NNN N N   
N  N NNNN  N N   
N  N NNN   N N   
N  NNNN    N N   
N  NNN     N N   
N NNNNNNNNNN N   
NNNN         N   
NNNNNNNNNNNNNN   
NN               
N                
                 
|----Layer 16|
NNNNNNNNNNNNNN   
N         NNN    
N        NNN     
N      NNNNNNN   
N     NNNN   N   
N    NNNNNNN N   
N   NNNN   N N   
N  NNNN    N N   
N  NNN     N N   
N NNNN     N N   
NNNN N     N N   
NNNN NNNNNNN N   
NN N         N   
N  NNNNNNNNNNN   
                 
                 
                 
|----Layer 17|
NNNNNNNNNNNN     
N       NNN      
N      NNN       
N     NNNNNNNN   
N    NNNNNN  N   
N   NNNNNNNN N   
N  NNNNNN  N N   
N NNNNNN   N N   
NNNNNNN    N N   
NNNNNN     N N   
NN NNN     N N   
N  N NNNNNNN N   
   N         N   
   NNNNNNNNNNN   
                 
                 
                 
|----Layer 18|
NNNNNNNNNN       
N     NNN        
N    NNN         
N   NNN    NNN   
N  NNN    NNNN   
N NNNNNNNNNN N   
NNNN N  NNNN N   
NNN  N NNN N N   
NN   NNNN  N N   
N    NNN   N N   
    NNN    N N   
   NNNNNNNNN N   
   NN        N   
   NNNNNNNNNNN   
                 
                 
                 
|----Layer 19|
NNNNNNNN         
N   NNN          
N  NNN           
N NNN        N   
NNNN        NN   
NNN  NNNNNNNNN   
NN   N    NNNN   
N    N   NNN N   
     N  NNNN N   
     N NNN N N   
     NNNN  N N   
     NNNNNNN N   
    NNN      N   
   NNNNNNNNNNN   
                 
                 
                 
|----Layer 20|
NNNNNN           
N NNN            
NNNN             
NNN              
NN               
N    NNNNNNN N   
     N     NNN   
     N     NNN   
     N    NNNN   
     N   NNN N   
     N  NNNN N   
     NNNNNNN N   
      NNN    N   
     NNNNNNNNN   
                 
                 
                 
|----Layer 21|
NNNN             
NNN              
NN               
N                
                 
     NNNNNNN     
     N     N     
     N     N N   
     N     NNN   
     N     NNN   
     N    NNNN   
     NNNNNNN N   
        NNN  N   
       NNNNNNN   
                 
                 
                 
|----Layer 22|
NN               
N                
                 
                 
                 
     NNNNNNN     
     N     N     
     N     N     
     N     N     
     N     N N   
     N     NNN   
     NNNNNNNNN   
          NNNN   
         NNNNN   
                 
                 
                 
|----Layer 23|
                 
                 
                 
                 
                 
     NNNNNNN     
     N     N     
     N     N     
     N     N     
     N     N     
     N     N     
     NNNNNNN N   
            NN   
           NNN   
                 
                 
                 
|----Layers 24–26|
                 
                 
                 
                 
                 
     NNNNNNN     
     N     N     
     N     N     
     N     N     
     N     N     
     N     N     
     NNNNNNN     
                 
                 
                 
                 
                 
|----Layer 27|
                 
                 
                 
                 
                 
     NNNNNNN     
     N     N     
     N     N     
     N     N     
     N    NN     
     N   NNN     
     NNNNNN      
                 
                 
                 
                 
                 
|----Layer 28|
                 
                 
                 
                 
                 
     NNNNNNN     
     N     N     
     N    NN     
     N   NNN     
     N  NNN      
     N NNN       
     NNNN        
                 
                 
                 
                 
                 
|----Layer 29|
                 
                 
                 
                 
                 
     NNNNNNN     
     N   NNN     
     N  NNN      
     N NNN       
     NNNN        
     NNN         
     NN          
                 
                 
                 
                 
                 
|----Layer 30|
                 
                 
                 
                 
                 
     NNNNNN      
     N NNN       
     NNNN        
     NNN         
     NN          
     N           
                 
                 
                 
                 
                 
                 
|----Layer 31|
                 
                 
                 
                 
                 
     NNNN        
     NNN         
     NN          
     N           
                 
                 
                 
                 
                 
                 
                 
                 
|----Layer 32|
                 
                 
                 
                 
                 
     NN          
     N           
                 
                 
                 
                 
                 
                 
                 
                 
                 
                 
}}

== Extinguished Nether Reactor ==
=== Materials ===
{| class="wikitable sortable mw-collapsible"
|-
!Name !!Layer 1 !!Layer 2 !!Layer 3 !!Total
|-
| {{LegacyBlockSprite|obsidian-je1-be1|link=Obsidian|text=Obsidian}} || 9 || 8 || 9 || 26
|-
| {{LegacyBlockSprite|nether-reactor-stage-1|link=Nether Reactor Core|text=Nether Reactor Core}} || — || 1 || — || 1
|}

=== Blueprint ===
{{layered blueprint|name=Extinguished Nether Reactor|default=Layer 0|R=LegacyBlockSprite:+nether-reactor-stage-1|O=LegacyBlockSprite:+obsidian-je1-be1
|----Layer 0|
OOO
OOO
OOO
|----Layer 1|
OOO
ORO
OOO
|----Layer 2|
OOO
OOO
OOO
}}

[[Category:Structure Blueprints]]

[[fr:Réacteur du Nether/Structure]]
[[ru:Замок Нижнего мира]]
[[zh:下界塔/结构]]