<noinclude>{{structure info}}</noinclude>
These connect to three corridors.
==== Materials ====
{| class="wikitable"
|-
! Name !! Total !! Stack
|-
|{{BlockLink|Nether Bricks}}
|348
|5 + 28 blocks
|-
|{{BlockLink|Nether Brick Fence}}
|21
|
|-
|}

==== Blueprints ====
{{layered blueprint|name=Corridor Balcony|default=Layer 2
|N=Nether Bricks|F=Nether Brick Fence
|----Layer -2 to ground|
         
         
         
NNNNNNNNN
NNNNNNNNN
NNNNNNNNN
NNNNNNNNN
NNNNNNNNN
NNNNNNNNN
|----Layer -1|
NNNNNNNNN
NNNNNNNNN
NNNNNNNNN
NNNNNNNNN
NNNNNNNNN
NNNNNNNNN
NNNNNNNNN
NNNNNNNNN
NNNNNNNNN
|----Layer 0|
NNNNNNNNN
NNNNNNNNN
NNNNNNNNN
NNNNNNNNN
N  NNN  N
NNNNNNNNN
NNNNNNNNN
NNNNNNNNN
NNNNNNNNN
|----Layer 1|
NNNNNNNNN
NNNNNNNNN
NNNNNNNNN
NNNNNNNNN
N  NNN  N
         
         
         
NNN   NNN
|----Layer 2|
FFFFFFFFF
F       F
F       F
NNN   NNN
N       N
         
         
         
NFN   NFN
|----Layer 3|
         
         
         
NFN   NFN
N       N
         
         
         
NFN   NFN
|----Layer 4|
         
         
         
NFN   NFN
N       N
         
         
         
NNN   NNN
|----Layer 5|
         
         
         
NNNNNNNNN
NNNNNNNNN
NNNNNNNNN
NNNNNNNNN
NNNNNNNNN
NNNNNNNNN
}}<noinclude>
[[fr:Forteresse du Nether/Structure/Balcon du corridor]]
[[zh:下界要塞/结构/走廊阳台]]
</noinclude>