{{structure info}}
==Fossil 1==
<table><tr><td style="width:300px;">
{| class="wikitable"
|-
! Name !! Total
|-
| {{BlockLink|Bone Block}}
| 10
|-
|}

This fossil is 5×4×4 blocks.
{{layered blueprint|name=Fossil 1|default=Layer 4
|v=Bone Block
|h=Bone Block-rot90
|t=Bone Block+top
|----Layer 1|
 t  t

 t  t

 t
|----Layer 2|
 t  t

 t
|----Layer 3|
 t
|----Layer 4|
  h
}}
</td><td style="vertical-align:top;">
[[File:Nether fossil 1.png|300px|right]]
</td></tr></table>

==Fossil 2==
<table><tr><td style="width:300px;">
{| class="wikitable"
|-
! Name !! Total
|-
| {{BlockLink|Bone Block}}
| 10
|-
|}

This fossil is 5×1×5 blocks.
{{layered blueprint|name=Fossil 2
|v=Bone Block
|h=Bone Block-rot90
|t=Bone Block+top
|----Layer 1|
   v  
   v  
  hv  
   v  
 hhvhh
}}
</td><td style="vertical-align:top;">
[[File:Nether fossil 2.png|300px|right]]
</td></tr></table>
==Fossil 3==
<table><tr><td style="width:300px;">
{| class="wikitable"
|-
! Name !! Total
|-
| {{BlockLink|Bone Block}}
| 6
|-
|}

This fossil is 2×4×3 blocks.
{{layered blueprint|name=Fossil 3|default=Layer 4
|v=Bone Block
|h=Bone Block-rot90
|t=Bone Block+top
|----Layer 1|
t
t
|----Layer 2-3|
t
|----Layer 4|
 hh
}}
</td><td style="vertical-align:top;">
[[File:Nether fossil 3.png|200px|right]]
</td></tr></table>
==Fossil 4==
<table><tr><td style="width:300px;">
{| class="wikitable"
|-
! Name !! Total
|-
| {{BlockLink|Bone Block}}
| 6
|-
|}

This fossil is 2×4×1 blocks.
{{layered blueprint|name=Fossil 4|default=Layer 4
|v=Bone Block
|h=Bone Block-rot90
|t=Bone Block+top
|----Layer 1-2|
t t
|----Layer 3|
t
|----Layer 4|
 h
}}
</td><td style="vertical-align:top;">
[[File:Nether fossil 4.png|200px|right]]
</td></tr></table>
==Fossil 5==
<table><tr><td style="width:300px;">
{| class="wikitable"
|-
! Name !! Total
|-
| {{BlockLink|Bone Block}}
| 5
|-
|}

This fossil is 1×5×2 blocks.
{{layered blueprint|name=Fossil 5|default=Layer 1-4
|v=Bone Block
|h=Bone Block-rot90
|t=Bone Block+top
|----Layer 1-4|
t
|----Layer 5|
 h
}}
</td><td style="vertical-align:top;">
[[File:Nether fossil 5.png|150px|right]]
</td></tr></table>

==Fossil 6==
<table><tr><td style="width:300px;">
{| class="wikitable"
|-
! Name !! Total
|-
| {{BlockLink|Bone Block}}
| 21
|-
|}

This fossil is 6×5×7 blocks.
{{layered blueprint|name=Fossil 6|default=Layer 1
|v=Bone Block
|h=Bone Block-rot90
|t=Bone Block+top
|----Layer 1|
  t t

t     t

t     t
|----Layer 2|
    t

t     t

t     t
|----Layer 3|
    t

t     t

t
|----Layer 4|
 
 
t     t

t
|----Layer 5|
 
 
 hhh
}}
</td><td style="vertical-align:top;">
[[File:Nether fossil 6.png|300px|right]]
</td></tr></table>
==Fossil 7==
<table><tr><td style="width:300px;">
{| class="wikitable"
|-
! Name !! Total
|-
| {{BlockLink|Bone Block}}
| 18
|-
|}

This fossil is 5×6×4 blocks.
{{layered blueprint|name=Fossil 7|default=Layer 1-4
|v=Bone Block
|h=Bone Block-rot90
|t=Bone Block+top
|----Layer 1-4|
 t
 
t
 
t
|----Layer 5|
  hh
 
 
 
t
|----Layer 6|
 
 
 
 
 hhh
}}
</td><td style="vertical-align:top;">
[[File:Nether fossil 7.png|300px|right]]
</td></tr></table>

==Fossil 8==
<table><tr><td style="width:300px;">
{| class="wikitable"
|-
! Name !! Total
|-
| {{BlockLink|Bone Block}}
| 6
|-
|}

This fossil is 1×5×3 blocks.
{{layered blueprint|name=Fossil 8|default=Layer 1-4
|v=Bone Block
|h=Bone Block-rot90
|t=Bone Block+top
|----Layer 1-4|
t
|----Layer 5|
 hh
}}
</td><td style="vertical-align:top;">
[[File:Nether fossil 8.png|150px|right]]
</td></tr></table>

==Fossil 9==
<table><tr><td style="width:300px;">
{| class="wikitable"
|-
! Name !! Total
|-
| {{BlockLink|Bone Block}}
| 15
|-
|}

This fossil is 5×5×3 blocks.
{{layered blueprint|name=Fossil 9|default=Layer 1-2
|v=Bone Block
|h=Bone Block-rot90
|t=Bone Block+top
|----Layer 1-2|
t
 
t
 
t
|----Layer 3|
t
 
t
 
 hh
|----Layer 4|
t
 
 hh
|----Layer 5|
 hh
}}
</td><td style="vertical-align:top;">
[[File:Nether fossil 9.png|300px|right]]
</td></tr></table>

==Fossil 10==
<table><tr><td style="width:300px;">
{| class="wikitable"
|-
! Name !! Total
|-
| {{BlockLink|Bone Block}}
| 8
|-
|}

This fossil is 1×7×3 blocks.
{{layered blueprint|name=Fossil 10|default=Layer 1-6
|v=Bone Block
|h=Bone Block-rot90
|t=Bone Block+top
|----Layer 1-6|
t
|----Layer 7|
 hh
}}
</td><td style="vertical-align:top;">
[[File:Nether fossil 10.png|150px|right]]
</td></tr></table>

==Fossil 11==
<table><tr><td style="width:300px;">
{| class="wikitable"
|-
! Name !! Total
|-
| {{BlockLink|Bone Block}}
| 24
|-
|}

This fossil is 7×5×5 blocks.
{{layered blueprint|name=Fossil 11|default=Layer 1-2
|v=Bone Block
|h=Bone Block-rot90
|t=Bone Block+top
|----Layer 1-2|
 t   t


 t   t


 t   t
|----Layer 3|
 t   t


 t   t


  h h
|----Layer 4|
 t   t


  h h
|----Layer 5|
  h h
}}
</td><td style="vertical-align:top;">
[[File:Nether fossil 11.png|300px|right]]
</td></tr></table>

==Fossil 12==
<table><tr><td style="width:300px;">
{| class="wikitable"
|-
! Name !! Total
|-
| {{BlockLink|Bone Block}}
| 11
|-
|}

This fossil is 3×5×4 blocks.
{{layered blueprint|name=Fossil 12|default=Layer 5
|v=Bone Block
|h=Bone Block-rot90
|t=Bone Block+top
|----Layer 1|
t  t

t  t
|----Layer 2|
t

 hh
|----Layer 3-4|
t
|----Layer 5|
 hh
}}
</td><td style="vertical-align:top;">
[[File:Nether fossil 12.png|300px|right]]
</td></tr></table>
==Fossil 13==
<table><tr><td style="width:300px;">
{| class="wikitable"
|-
! Name !! Total
|-
| {{BlockLink|Bone Block}}
| 17
|-
|}

This fossil is 6×5×4 blocks.
{{layered blueprint|name=Fossil 13|default=Layer 5
|v=Bone Block
|h=Bone Block-rot90
|t=Bone Block+top
|----Layer 1-3|
t

 
 t
 
  t
|----Layer 4|
t
 
 
 t
 
   h
|----Layer 5|
 hhh
 
 
  hh
}}
</td><td style="vertical-align:top;">
[[File:Nether fossil 13.png|300px|right]]
</td></tr></table>
==Fossil 14==
<table><tr><td style="width:300px;">
{| class="wikitable"
|-
! Name !! Total
|-
| {{BlockLink|Bone Block}}
| 26
|-
|}

This fossil is 6×7×7 blocks.
{{layered blueprint|name=Fossil 14|default=Layer 5
|v=Bone Block
|h=Bone Block-rot90
|t=Bone Block+top
|----Layer 1-2|
t     t


t     t

 t   t
|----Layer 3-4|
t


t     t
|----Layer 5|
t


t    h
|----Layer 6|
t


 hh
|----Layer 7|
 hh
}}
</td><td style="vertical-align:top;">
[[File:Nether fossil 14.png|300px|right]]
</td></tr></table>

[[fr:Fossile du Nether/Structure]]
[[ja:ネザーの化石/構造]]
[[uk:Незерські копалини/Структура]]
[[zh:下界化石/结构]]