<noinclude>{{structure info}}</noinclude>
These intersections connect four bridges.
====Materials====
{| class="wikitable"
|-
! Name!!Total!!Stack
|-
|{{BlockLink|Nether Bricks}}
|730
|11 + 26 blocks
|-
|}

==== Blueprint====
{{layered blueprint|name=Bridge Open Intersection|default=Layer 1
|N=Nether Bricks
|----Layer -5 to ground|
       NNNNN       
       NNNNN       
       NNNNN       
                   
                   
                   
                   
NNN             NNN
NNN             NNN
NNN             NNN
NNN             NNN
NNN             NNN
                   
                   
                   
                   
       NNNNN       
       NNNNN       
       NNNNN       
|----Layer -4 & -3|
       NNNNN       
       NNNNN       
       NNNNN       
       NNNNN       
                   
                   
                   
NNNN           NNNN
NNNN           NNNN
NNNN           NNNN
NNNN           NNNN
NNNN           NNNN
                   
                   
                   
       NNNNN       
       NNNNN       
       NNNNN       
       NNNNN       
|----Layer -2|
       NNNNN       
       NNNNN       
       NNNNN       
       NNNNN       
       NNNNN       
       NNNNN       
                   
NNNNNN       NNNNNN
NNNNNN       NNNNNN
NNNNNN       NNNNNN
NNNNNN       NNNNNN
NNNNNN       NNNNNN
                   
       NNNNN       
       NNNNN       
       NNNNN       
       NNNNN       
       NNNNN       
       NNNNN       
|----Layer -1 & 0|
       NNNNN       
       NNNNN       
       NNNNN       
       NNNNN       
       NNNNN       
       NNNNN       
       NNNNN       
NNNNNNNNNNNNNNNNNNN
NNNNNNNNNNNNNNNNNNN
NNNNNNNNNNNNNNNNNNN
NNNNNNNNNNNNNNNNNNN
NNNNNNNNNNNNNNNNNNN
       NNNNN       
       NNNNN       
       NNNNN       
       NNNNN       
       NNNNN       
       NNNNN       
       NNNNN       
|----Layer 1|
       N   N       
       N   N       
       N   N       
       N   N       
       N   N       
       N   N       
       N   N       
NNNNNNNN   NNNNNNNN
                   
                   
                   
NNNNNNNN   NNNNNNNN
       N   N       
       N   N       
       N   N       
       N   N       
       N   N       
       N   N       
       N   N       
}}<noinclude>
[[fr:Forteresse du Nether/Structure/Intersection du pont ouvert]]
[[zh:下界要塞/结构/开桥十字]]
</noinclude>