<noinclude>{{structure info}}</noinclude>
The entrance is on the bottom side of the blueprints. They can connect to a bridge or a corridor.
====Materials====
{| class="wikitable"
|-
! Name!!Total!!Stack
|-
|{{BlockLink|Nether Bricks}}
|252
|3 + 60 blocks
|-
|{{BlockLink|Nether Brick Fence}}
|27
|
|-
|{{BlockLink|Monster Spawner}}
|1
|
|-
|}

==== Blueprint====
* The monster spawner spawns blazes.
{{layered blueprint|name=Blaze|default=Layer 5
|N=Nether Bricks|F=Nether Brick Fence|M=Monster Spawner
|----Layer -2 to ground|
       
       
NNNNNNN
NNNNNNN
NNNNNNN
NNNNNNN
NNNNNNN
NNNNNNN
NNNNNNN
|----Layer -1 & 0|
       
 NNNNN 
 NNNNN 
 NNNNN 
 NNNNN 
 NNNNN 
 NNNNN 
 NNNNN 
 NNNNN 
|----Layer 1|
       
 NNNNN 
 NNNNN 
 NNNNN 
 NNNNN 
 NNNNN 
 NNNNN 
 NNNNN 
 N   N 
|----Layer 2|
       
 NNNNN 
 NNNNN 
 NNNNN 
 NNNNN 
 NNNNN 
 NNNNN 
 N   N 
 N   N 
|----Layer 3|
       
 NNNNN 
 NNNNN 
 NNNNN 
 NNNNN 
 NNNNN 
 N   N 
 N   N 
 N   N 
|----Layer 4|
NNNNNNN
N     N
N     N
N  M  N
N     N
NN   NN
 N   N 
       
       
|----Layer 5|
FFFFFFF
F     F
F     F
F     F
F     F
FF   FF
       
          
         
         
         
         
|----Layer 6|
 FFFFF  
         
         
         
         
         
         
         
         
|----Layer 7|
  FFF   
         
         
         
         
         
         
         
         
}}<noinclude>
[[fr:Forteresse du Nether/Structure/Générateur de Blazes]]
[[zh:下界要塞/结构/瞭望台]]
</noinclude>