<noinclude>{{structure info}}</noinclude>
<table><tr><td style="width:400px;">
{{layered blueprint|name=Core|default=Layer 0
|p=Prismarine|b=Prismarine Bricks|d=Dark Prismarine|g=Block of Gold|l=Sea Lantern
|----Layer -1|
pppppppppppppppp
pppppppppppppppp
pppppppppppppppp
pppppppppppppppp
pppppppppppppppp
pppppppppppppppp
pppppppppppppppp
pppppppppppppppp
pppppppppppppppp
pppppppppppppppp
pppppppppppppppp
pppppppppppppppp
pppppppppppppppp
pppppppppppppppp
pppppppppppppppp
pppppppppppppppp
|----Layer 0|
bb    bbbb    bb
b              b
  bb        bb  
  b          b  
                
      b  b      
b    b    b    b
b              b
b              b
b    b    b    b
      b  b      
                
  b          b  
  bb        bb  
b              b
bbbbbbbbbbbbbbbb
|----Layer 1|
pp    pppp    pp
p              p
                
                
                
     bb  bb     
p    b    b    p
p              p
p              p
p    b    b    p
     bb  bb     
                
                
                
p              p
pppppppppppppppp
|----Layer 2|
bb    bbbb    bb
b              b
                
                
                
     b    b     
b     lddl     b
b     dddd     b
b     dddd     b
b     lddl     b
     b    b     
                
                
                
b              b
bbbbbbbbbbbbbbbb
|----Layer 3-4|
bb    bbbb    bb
b              b
                
                
                
     b    b     
b     dddd     b
b     dggd     b
b     dggd     b
b     dddd     b
     b    b     
                
                
                
b              b
bbbbbbbbbbbbbbbb
|----Layer 5|
pp    pppp    pp
p              p
                
                
                
     b    b     
p     lddl     p
p     dddd     p
p     dddd     p
p     lddl     p
     b    b     
                
                
                
p              p
pppppppppppppppp
|----Layer 6|
bbbbbbbbbbbbbbbb
b    b    b    b
b    b    b    b
b    b    b    b
b    b    b    b
bbbbbbb  bbbbbbb
b    b    b    b
b              b
b              b
b    b    b    b
bbbbbbb  bbbbbbb
b    b    b    b
b    b    b    b
b    b    b    b
b    b    b    b
bbbbbbbbbbbbbbbb
|----Layer 7|
pppppppppppppppp
pppppppppppppppp
pppppppppppppppp
pppppppppppppppp
pppppppppppppppp
pppppppppppppppp
pppppppppppppppp
pppppppppppppppp
pppppppppppppppp
pppppppppppppppp
pppppppppppppppp
pppppppppppppppp
pppppppppppppppp
pppppppppppppppp
pppppppppppppppp
pppppppppppppppp
}}
</td></tr></table><noinclude>
[[fr:Monument sous-marin/Structure/Coeur]]
[[uk:Океанічний монумент/Структура/План середини]]
[[zh:海底神殿/结构/核心藏宝室]]
</noinclude>