<noinclude>{{structure info}}</noinclude>
No exits
<table><tr><td style="width:400px;">
{{layered blueprint|name=Entry No Exits|default=Layer 0
|p=Prismarine|b=Prismarine Bricks
|----Layer -1|
        
pppppppp
pppppppp
pppppppp
pppppppp
pppppppp
pppppppp
pppppppp
pppppppp
pppppppp
|----Layer 0|
        
b      b
bbb  bbb
b      b
b      b
b      b
b      b
b      b
b      b
bbbbbbbb
|----Layer 1|
        
pb    bp
bbb  bbb
bb    bb
bb    bb
bb    bb
bb    bb
bb    bb
bb    bb
bbbbbbbb
|----Layer 2|
        
ppb  bpp
bbb  bbb
bbb  bbb
bbb  bbb
bbb  bbb
bbb  bbb
bbb  bbb
bbb  bbb
bbbbbbbb
|----Layer 3|
   bb   
pppbbppp
pppppppp
pppppppp
pppppppp
pppppppp
pppppppp
pppppppp
pppppppp
pppppppp
}}
</td></tr></table>
All possible exits
<table><tr><td style="width:400px;">
{{layered blueprint|name=Entry Exits|default=Layer 0
|p=Prismarine|b=Prismarine Bricks
|----Layer -1|
        
pppppppp
pppppppp
pppppppp
pppppppp
pppppppp
pppppppp
pppppppp
pppppppp
pppppppp
|----Layer 0|
        
b      b
bbb  bbb
b      b
b      b
        
        
b      b
b      b
bbb  bbb
|----Layer 1|
        
pb    bp
bbb  bbb
bb    bb
bb    bb
        
        
bb    bb
bb    bb
bbb  bbb
|----Layer 2|
        
ppb  bpp
bbb  bbb
bbb  bbb
bbb  bbb
bbb  bbb
bbb  bbb
bbb  bbb
bbb  bbb
bbbbbbbb
|----Layer 3|
   bb   
pppbbppp
pppppppp
pppppppp
pppbbppp
ppb  bpp
ppb  bpp
pppbbppp
pppppppp
pppppppp
}}
</td></tr></table><noinclude>
[[fr:Monument sous-marin/Structure/Salle de l'entrée]]
[[uk:Океанічний монумент/Структура/План вхідної кімнати]]
[[zh:海底神殿/结构/入口房间]]
</noinclude>