{{layered blueprint|name=ruin1_mossy|default=Layer 0|g=gravel|S=Mossy Stone Bricks|M=magma block|m=Mossy cobblestone|l=sea lantern
|----Layer 1|
ggggggg
gggmggg
ggggggg
gggMgmg
ggggggg
gmggggg
|----Layer 2|
 SSSSS
Smm  mS
Sm    S
S     S
 S S S
   m
|----Layer 3|
 S S S
Sm   lS

S     S
 m S S
|----Layer 4|
  SSSS
S    mS
S     S
m     S
|----Layer 5|
    m
    mm
     mm
      m
|----Layer 6|
 
     m
}}<noinclude>
[[Category:Ocean Ruins structure subpages]]

[[fr:Ruines sous-marines/Structure/Ruine 1 moussue]]
[[zh:海底废墟/结构/ruin1 mossy]]
</noinclude>