<noinclude>{{structure info}}</noinclude>
{{layered blueprint|name=ruin_warm8|default=Layer 1|s=Sand|L=cut Sandstone|S=Sandstone stairs|c=chest|M=magma block
|----Layer 1|
 ssssss
sssMsss
ssscsss
ssMssMs
sMssMss
ssssss
|----Layer 2|
   sss 
 ss sss
LsLsLsL
 s ss s
  ss s 
 s     
|----Layer 3|
       
    s  
L LsLsL
       
       
       
|----Layer 4|
       
       
L L L L
       
       
       
|----Layer 5|
       
       
SLL LLS
       
       
       
|----Layer 6|
       
       
 SLLLS 






}}<noinclude>
[[fr:Ruines sous-marines/Structure/Ruine chaude 8]]
[[zh:海底废墟/结构/ruin warm8]]
</noinclude>