<noinclude>{{structure info}}</noinclude>
{{layered blueprint|name=ruin_warm3|default=Layer 0|c=chest|s=sand|S=cut sandstone|H=polished granite|M=magma block
|----Layer 1|
  ss
 sssss
 scsss
ssssss
ssssMs
 ssssM
  ssss
|----Layer 2|
     
  S S
 SsssS
  ss
 S   S
  S S
|----Layer 3|
     
  S S
 Ss  S
    
 S   S
  S S
|----Layer 4|
     
  HSH
 H   H
 S   S
 H   H
  HSH
|----Layer 5|
     
     
  HSH
  SHS
  HSH
}}<noinclude>
[[fr:Ruines sous-marines/Structure/Ruine chaude 3]]
[[zh:海底废墟/结构/ruin warm3]]
</noinclude>