<noinclude>{{structure info}}</noinclude>
{{layered blueprint|name=ruin_warm7|default=Layer 0|c=chest|s=sand|S=cut sandstone|g=polished granite
|----Layer 1|
  ss
 ssss
ssssss
sscsss
sssss
 sssss
    ss
|----Layer 2|
     
 S  S
   ss
 sS s
    S
 S
     g
|----Layer 3|
   
 g  g
    s
  S
}}<noinclude>
[[fr:Ruines sous-marines/Structure/Ruine chaude 7]]
[[zh:海底废墟/结构/ruin warm7]]
</noinclude>