{{layered blueprint|name=ruin6_cracked|default=Layer 1|g=gravel|c=chest|S=Cracked Stone Bricks|C=chiseled Stone Bricks|s=sand|b=stone brick stairs|p=polished granite
|----Layer 1|
  gg
ggggg
gggcgg
gggggg
gggggg
 gggg
|----Layer 2|
 
 SSSS
gSggS
  ggSg
 SSSS
   g
|----Layer 3|
 
 SSSS
 SggS
   gS
 SSSS
|----Layer 4|
 
 SSSS
 S gS
 S gS
 SSSS
|----Layer 5|
 
 SSSS
 S gS
 S  S
 SSSS
|----Layer 6|
 bbbb
bSSSSb
bSpCSb
bSCpSb
bSSSSb
 bbbb
|----Layer 7|
  bb
 
b    b
b    b
 
  bb
}}<noinclude>
[[Category:Ocean Ruins structure subpages]]

[[zh:海底废墟/结构/ruin6 cracked]]
</noinclude>