<noinclude>{{structure info}}</noinclude>
{{layered blueprint|name=ruin_warm4|default=Layer 0|c=chest|s=sand|S=cut sandstone|C=sandstone stairs|G=chiseled sandstone|M=magma block
|----Layer 1|
 s  s 
ssssss
ssssss
ssssss
sMsscs
ssssss
  sss
|----Layer 2|
     
CSs SC
 s ss
CS  SC
s s s
CS  SC
    s
|----Layer 3|
    
 Ss S
     
 S  S
     
 S  S
|----Layer 4|
      
 SSSS
     
 S  S
    
 SSSS
|----Layer 5|
      
 CSSC
      
 S  S
     
 CSSC
|----Layer 6|
     
     
     
 G  G

}}<noinclude>
[[fr:Ruines sous-marines/Structure/Ruine chaude 4]]
[[zh:海底废墟/结构/ruin warm4]]
</noinclude>