{{layered blueprint|name=ruin3_mossy|default=Layer 0|g=gravel|S=Mossy Stone Bricks|M=magma block|m=Mossy cobblestone|C=chiseled Stone Bricks|s=sand|c=cobblestone|t=stone brick stairs
|----Layer 1|
ggggg
g ggsg
ggcssgg
ggMgggg
gsCggg
 gggg
|----Layer 2|
 
 S  S
  Sgg
   g  S
 S  S
|----Layer 3|
 
 S  S
 
 
 S  S
|----Layer 4|
 
 S  S
 
 
    S
|----Layer 5|
    S
    S
    S
    S
    S
    S
|----Layer 6|
 
    t
    S
    S
    t
}}<noinclude>
[[Category:Ocean Ruins structure subpages]]

[[zh:海底废墟/结构/ruin3 mossy]]
</noinclude>