{{layered blueprint|name=ruin7_mossy|default=Layer 0|g=gravel|S=Mossy Stone Bricks|M=magma block|m=Mossy cobblestone|C=chiseled Stone Bricks|c=chest|p=polished granite
|----Layer 1|
 ggggg
 gmcggg
gggmmgg
ggmmmgg
gMgggg
 gggg
|----Layer 2|
  SSS
 SgggS
 Sg
 Sg gS
  SSS
|----Layer 3|
  S S
 S  gS
 
 Sg  S
  S S
|----Layer 4|
  SSS
 S   S
 S   S
 S   S
  SSS
|----Layer 5|
 
  SSS
  SSS
  SSS
|----Layer 6|
 
   C
  CpC
   C
}}<noinclude>
[[Category:Ocean Ruins structure subpages]]

[[zh:海底废墟/结构/ruin7 mossy]]
</noinclude>