<noinclude>{{structure info}}</noinclude>
{{layered blueprint|name=ruin_warm6|default=Layer 0|c=chest|s=sand|S=cut sandstone|C=Blue Terracotta|M=magma block
|----Layer 1|
  ssss
ssssss
ssMss 
sssss
ssssss
 sssss
  sss
|----Layer 2|
    s
 SSSs
Scs S
SsssS
Sss S
 S Ss
|----Layer 3|
   
 SCSs
Sss S
Cs  C
S s S
 S S
|----Layer 4|
   
 SSS
Ss  S
S   S
S   S
 SSS
|----Layer 5|
   
   
 SSS
 SCS
 SSS

}}<noinclude>
[[fr:Ruines sous-marines/Structure/Ruine chaude 6]]
[[zh:海底废墟/结构/ruin warm6]]
</noinclude>