<noinclude>{{structure info}}</noinclude>
Sponge room with all possible sponges
<table><tr><td style="width:400px;">
{{layered blueprint|name=Sponges|default=Layer 0
|p=Prismarine|b=Prismarine Bricks|d=Dark Prismarine|w=Wet Sponge
|----Layer -1|
pppppppp
pppppppp
pppbbppp
ppb  bpp
ppb  bpp
pppbbppp
pppppppp
pppppppp
|----Layer 0|
bbbddbbb
b      b
b      b
d      d
d      d
b      b
b      b
bbbddbbb
|----Layer 1|
dddddddd
dwwwwwwd
dwwwwwwd
dwwwwwwd
dwwwwwwd
dwwwwwwd
dwwwwwwd
dddddddd
|----Layer 2|
bbbbbbbb
bwwwwwwb
bwwwwwwb
bwwwwwwb
bwwwwwwb
bwwwwwwb
bwwwwwwb
bbbbbbbb
|----Layer 3|
pppppppp
pppppppp
pppppppp
pppppppp
pppppppp
pppppppp
pppppppp
pppppppp
}}
</td></tr></table><noinclude>
[[fr:Monument sous-marin/Structure/Salle des éponges]]
[[uk:Океанічний монумент/Структура/План кімнати з губками]]
[[zh:海底神殿/结构/海绵房]]
</noinclude>