<noinclude>{{structure info}}</noinclude>
No exits
<table><tr><td style="width:400px;">
{{layered blueprint|name=Dark Pillar No Exits|default=Layer 0
|p=Prismarine|b=Prismarine Bricks|d=Dark Prismarine|l=Sea Lantern
|----Layer -1|
pppppppp
pppppppp
pppppppp
pppppppp
pppppppp
pppppppp
pppppppp
pppppppp
pppppppp
pppppppp
pppppppp
pppppppp
pppppppp
pppppppp
pppppppp
pppppppp
|----Layer 0|
bbbbbbbb
b      b
b      b
b      b
b      b
b      b
b      b
b  dd  b
b  dd  b
b      b
b      b
b      b
b      b
b      b
b      b
bbbbbbbb
|----Layer 1|
pppppppp
p      p
p      p
p      p
p      p
p      p
p      p
p  ll  p
p  ll  p
p      p
p      p
p      p
p      p
p      p
p      p
pppppppp
|----Layer 2|
bbbbbbbb
b      b
b      b
b      b
b      b
b      b
b      b
b  dd  b
b  dd  b
b      b
b      b
b      b
b      b
b      b
b      b
bbbbbbbb
|----Layer 3|
bbbbbbbb
b      b
b      b
b      b
b      b
b      b
b      b
b  dd  b
b  dd  b
b      b
b      b
b      b
b      b
b      b
b      b
bbbbbbbb
|----Layer 4|
bbbbbbbb
b      b
b      b
b      b
b      b
b      b
b      b
b  dd  b
b  dd  b
b      b
b      b
b      b
b      b
b      b
b      b
bbbbbbbb
|----Layer 5|
pppppppp
p      p
p      p
p      p
p      p
p      p
p      p
p  ll  p
p  ll  p
p      p
p      p
p      p
p      p
p      p
p      p
pppppppp
|----Layer 6|
bbbbbbbb
b      b
b      b
b      b
b      b
b      b
b      b
b  dd  b
b  dd  b
b      b
b      b
b      b
b      b
b      b
b      b
bbbbbbbb
|----Layer 7|
pppppppp
pppppppp
pppppppp
pppppppp
pppppppp
pppppppp
pppppppp
pppppppp
pppppppp
pppppppp
pppppppp
pppppppp
pppppppp
pppppppp
pppppppp
pppppppp
}}
</td></tr></table>
All possible exits
<table><tr><td style="width:400px;">
{{layered blueprint|name=Dark Pillar All Exits|default=Layer 0
|p=Prismarine|b=Prismarine Bricks|d=Dark Prismarine|l=Sea Lantern
|----Layer -1|
pppppppp
pppppppp
pppbbppp
ppb  bpp
ppb  bpp
pppbbppp
pppppppp
pppppppp
pppppppp
pppppppp
pppbbppp
ppb  bpp
ppb  bpp
pppbbppp
pppppppp
pppppppp
|----Layer 0|
bbb  bbb
b      b
bb    bb
       
       
bb    bb
b      b
b  dd  b
b  dd  b
b      b
bb    bb
       
       
bb    bb
b      b
bbb  bbb
|----Layer 1|
ppp  ppp
p      p
pb    bp
       
       
pb    bp
p      p
p  ll  p
p  ll  p
p      p
pb    bp
       
       
pb    bp
p      p
ppp  ppp
|----Layer 2|
bbbbbbbb
b      b
bb    bb
b      b
b      b
bb    bb
b      b
b  dd  b
b  dd  b
b      b
bb    bb
b      b
b      b
bb    bb
b      b
bbbbbbbb
|----Layer 3|
bbbbbbbb
b      b
bbb  bbb
bbb  bbb
bbb  bbb
bbb  bbb
b      b
b  dd  b
b  dd  b
b      b
bbb  bbb
bbb  bbb
bbb  bbb
bbb  bbb
b      b
bbbbbbbb
|----Layer 4|
bbb  bbb
b      b
b      b
       
       
b      b
b      b
b  dd  b
b  dd  b
b      b
b      b
       
       
b      b
b      b
bbb  bbb
|----Layer 5|
ppp  ppp
p      p
p      p
       
       
p      p
p      p
p  ll  p
p  ll  p
p      p
p      p
       
       
p      p
p      p
ppp  ppp
|----Layer 6|
bbbbbbbb
b      b
b      b
b      b
b      b
b      b
b      b
b  dd  b
b  dd  b
b      b
b      b
b      b
b      b
b      b
b      b
bbbbbbbb
|----Layer 7|
pppppppp
pppppppp
pppbbppp
ppb  bpp
ppb  bpp
pppbbppp
pppppppp
pppppppp
pppppppp
pppppppp
pppbbppp
ppb  bpp
ppb  bpp
pppbbppp
pppppppp
pppppppp
}}
</td></tr></table><noinclude>
[[fr:Monument sous-marin/Structure/Salle DYZ]]
[[uk:Океанічний монумент/Структура/План кімнати DYZ]]
[[zh:海底神殿/结构/DYZ房间]]
</noinclude>