<noinclude>{{structure info}}</noinclude>
{{layered blueprint|name=ruin_warm5|default=Layer 0|c=chest|s=sand|S=cut sandstone
|----Layer 1|
   ss
 sssss
sscsss
ssssss
ssssss
ssssss
 ssss
|----Layer 2|
     
 S  S
 ss
 S  S
   
 S  S
|----Layer 3|
     
 S  S
     
 S  S
     
 S  S
|----Layer 4|
     
 SSSS
 S  S
 SSSS
 S  S
 SSSS
|----Layer 5|
   
   
  SS
  SS
  SS 
}}<noinclude>
[[fr:Ruines sous-marines/Structure/Ruine chaude 5]]
[[zh:海底废墟/结构/ruin warm5]]
</noinclude>