<noinclude>{{structure info}}</noinclude>
{{layered blueprint|name=big_ruin_warm6|default=layer 1|s=sand|S=cut sandstone|D=chiseled sandstone|C=Sandstone|c=chest|M=magma block|d=sea lantern
|----Layer 1|
  s         s  
  ssss   ssssss 
 ssssss ssssssss
 sssssssssssssss
  sssssssssss   
 ssssssMssssss  
ssssscsssMsssss 
 ssssssssssssss 
ssssssssssssssss
 ssssssssssssss
ssssssssssssssss
MsssssssssssssMs
ssssssssssssssss
 ssssssssssssss
   sssssssssss
    ss  s   s  
|----Layer 2|
             
  s s           
  S  S    S sS
   SSS    SSS
      C
     C
  SSds    SSSS
  s            
 s            s
  SSSS    SSSS
 ss           s
  s         s
   SdS s  SSSss
  S  Ss   S  S
     ss s  s
              
|----Layer 3|
                 
                
  S  D    D  S
   SS      SS
     
     
  SSS      SSS
       
       
  SSS      SSS
  s
       
   SS      SSs
  S  Ds   D  S
                
        
|----Layer 4|
     
     
  S          S
   SS      SS
     
     
  SSS      SSS
     
     
  SSS      SSS
     
     
   SS      SS
  S          S
      
     
     
|----Layer 5|
      
      
      
    SS    SS
     
     
    SS    SS
     
     
    SS    SS 
     
     
    SS    SS
    
     
     
|----Layer 6|
     
     
     
     SS  SS
     
     
     SS  SS
     
     
     SS  SS
     
     
     SS  SS
     
     
     
|----Layer 7|
     
     
     
      SSSS
     
     
      SSSS
     
     
      SSSS
     
     
      SSSS
     
     
     

}}<noinclude>
[[fr:Ruines sous-marines/Structure/Grande ruine chaude 6]]
[[zh:海底废墟/结构/big ruin warm6]]
</noinclude>