<noinclude>{{structure info}}</noinclude>
{{layered blueprint|name=big_ruin2_brick|default=Layer 0|T=purple glazed terracotta|c=chest|g=gravel|S=stone bricks|C=chiseled stone bricks|p=prismarine|M=magma block|D=sea lantern|G=polished granite
|----Layer 1|
   ggg g
  gggggggg  ggg
  Sgggggpgg gggg
 ggggpggggggggg
 gggggggggggMg
  ggSSSggggggggg
 ggSSCSggggggCg
 ggSSCSggggggg
gpgSSCSggSSgggg
ggpgSSSSSTTSggg
 gggggggSTTSgggg
gggggggpgSSggggg
gggggggggggggggg
gggggggggggggSgg
 ggpggggggggggg
  gggg  g ggg
|----Layer 2|
     
    g         G
  S   S gS   S
  g  gg
    SSSg
   S  cS
  S    SS    S
       SS S
 gS    SS  S
  gS        SS
    SSSS    S
 g     gS  Sg g
        gSSg
  Sg  S  Sgg S
   g G  g Gg
          
|----Layer 3|
     
             
  S   S  S   S
      g
    SSS 
   S   S
  S    SS    S
       SS S
  S    SS  S
   S        SS
    SSSS    S
        S  S   
         SS 
  S   S  Sg  S
         
          
|----Layer 4|
     
             
  G   G  G    
      
    SSS 
   S   S
  S    SS    G
  S    SSSS
  S    SS  S
   S   S    SG
    SSSS    S
        S  S   
         SS 
  G          G
         
          
  
|----Layer 5|
     
             
              
      
    SSS 
   S   S
  S    SS     
  S    SSSS
  S    SD  S
   S   S    S 
    SSSS    S
        S  S   
         SS 
              
         
          
  
|----Layer 6|
     
             
    
     
    S S 
   S   S
  S    SS     
           
  S    SSCC   
   S   SCSSC     
    S S CSSC     
         CC       
           
              
         
          
|----Layer 7|   
     
             
    
    SGS 
   S   S
  S    SS     
  G    GG  
  S    SS   
   S   S     
    SGS     
               
           
              
         
          
|----Layer 8|
     
             
    
       
    CCC 
   SSSSS
  CS   SC     
  CS D SC  
  CS   SC   
   SSSSS     
    CCC     
               
           
              
         
          
|----Layer 9|
     
             
    
       
        
    CCC 
   CCSCC      
   CSSSC   
   CCSCC    
    CCC      
            
               
           
              
         
          
}}<noinclude>
[[fr:Ruines sous-marines/Structure/Grande ruine 2 pierre taillée]]
[[zh:海底废墟/结构/big ruin2 brick]]
</noinclude>