{{layered blueprint|name=ruin1_cracked|default=Layer 1|g=gravel|S=Cracked Stone Bricks|c=chest|m=mossy cobblestone|s=sea lantern
|----Layer 1|
ggggggg
gggmggg
ggggggm
gggggmg
ggggggg
 gmmggg
|----Layer 2|
 SSSSS
S    mm
S     S
Sc  mmS
 mmS S
|----Layer 3|
 S S S
S    sS
 
S     S
 S S S
|----Layer 4|
  SSSS
S    mS
S     S
S     S
   SSS
|----Layer 5|
    m
 
m     m
      m
    m
}}<noinclude>
[[Category:Ocean Ruins structure subpages]]

[[zh:海底废墟/结构/ruin1 cracked]]
</noinclude>