<noinclude>{{structure info}}</noinclude>
{{layered blueprint|name=ruin8_mossy|default=Layer 0|g=gravel|c=chest|w=dark oak planks|S= Mossy Stone Bricks|P=Polished Granite|C=chiseled Stone Bricks|M=magma block|m=Mossy cobblestone|o=obsidian
|----Layer 1|
  gg
 gggg
gwwwgg
gggggg
ogggMg
ggwgg
 ggg
|----Layer 2|
   
 SSS
S c S
S   S
 S S
 S S
 S S
|----Layer 3|
   
 S S
S   S
S   S
 S S
    
 S S
|----Layer 4|
   
 SSS
S   S
S   S
 S S
 S S
 SSS
|----Layer 5|
   
  
 SCS
 CCC
 CCC
 SCS
  C
|----Layer 6|
   
  
    
  C 
  C 
    
   




      
 



}}<noinclude>
[[fr:Ruines sous-marines/Structure/Ruine 8 moussue]]
[[zh:海底废墟/结构/ruin8 mossy]]
</noinclude>