<noinclude>{{structure info}}</noinclude>
{{layered blueprint|name=big_ruin1_mossy|default=Layer 0|G=gravel|S=Mossy Stone Bricks|C=Chiseled Stone Bricks|M=Magma Block|P=Prismarine|c=chest|s=sand
|----Layer 0|
    G   G GGGG
 GSGGGSGGSGGGSG
GSSGGGSGGSGGGSS
 GGGGGGGGG GGGGG
GGGMGcGGGGGPGGGG
GGPGGGGGGGGGGGGG
 GGGGGGGGGGsGSS
 GGGGGGGGGGGGGG
 GGGGGGGMGPGGG
GGSGGGGGGGGGGGS
 GGGGGGGGGGGGGGG
   GSGGGGGGPGGGG
  GGGGGGGSGGGGMG
 GGGGGSGGSGGMSSG
 GGGGGSG SGGGSG
  GGGG   GGGGG
|----Layer 1|
           G    
  S G S GS  GS  
 SSGGGS  S   SS 
 GG G           
  G SG G   S  G 
 G GG G    G    
 SS G      GGSS 
   G     GG     
       G GG     
 SS     G    SS 
    G     G     
    SG   GGS  G 
            GG G
 SS  GS  SGG SS 
  SGG S  SG  S  
   G        G   
|----Layer 2|
 
            G   
  S G S  S   S  
 
  G S      S    
   G
  S          S  
   G     G      
 
  S          S  
    G
    S     GS    
             G  
  S   S  S G S  
    G
|----Layer 3|
 
 
  S   S  S   S  
 
    S      S    
 
  S          S  
 
 
             S  
 
    S      S    
 
  S   S  S
|----Layer 4|
 
 
 
 
 
     S    S
      S  S
 
 
      S  S
     S    S
|----Layer 5|
 
 
 
 
 
 
      S  S
 
 
      S  S
|----Layer 6|
 
 
 
 
 
 
       CC
      C  C
      C  C
       CC

}}<noinclude>
[[fr:Ruines sous-marines/Structure/Grande ruine 1 moussue]]
[[zh:海底废墟/结构/big ruin1 mossy]]
</noinclude>