<noinclude>{{structure info}}</noinclude>
{{layered blueprint|name=ruin_warm1|default=Layer 0|c=chest|s=sand|S=cut sandstone|H=polished granite
|----Layer 1|
 sssss
sssssss
ssSHSss
ssHSHss
sssssss
 sssss
|----Layer 2|
  S S
 s sss
Scs ssS
Ss  s S
   ss
  S S
|----Layer 3|
  S S
    s
Hs   sH
H     H
    s
  S S
|----Layer 4|
  S S
     
S     S
S     S
     
  S s
|----Layer 5|
  SSS
 SSSSS
SSSSSSS
SSSSSSS
 SSSSS
  SSS
|----Layer 6|
      
  SSS
 SSSSS
 SSSSS
  SSS
|----Layer 7|
      
      
  SSS
  SSS


}}<noinclude>
[[fr:Ruines sous-marines/Structure/Ruine chaude 1]]
[[zh:海底废墟/结构/ruin warm1]]
</noinclude>