<noinclude>{{structure info}}</noinclude>
No exits
<table><tr><td style="width:400px;">
{{layered blueprint|name=U-shaped No Exits|default=Layer 0
|p=Prismarine|b=Prismarine Bricks|l=Sea Lantern
|----Layer -1|
pppppppppppppppp
pppppppppppppppp
pppppppppppppppp
pppppppppppppppp
pppppppppppppppp
pppppppppppppppp
pppppppppppppppp
pppppppppppppppp
|----Layer 0|
bbbbbbbbbbbbbbbb
b    bbbbbb    b
b    bbbbbb    b
b    bbbbbb    b
b    bbbbbb    b
b              b
b              b
bbbbbbbbbbbbbbbb
|----Layer 1|
pppppppppppppppp
p     pppp     p
p     pppp     p
p     lppl     p
p              p
p              p
p              p
pppppppppppppppp
|----Layer 2|
bbbbbbbbbbbbbbbb
b    bbbbbb    b
b    bbbbbb    b
b    bbbbbb    b
b    bbbbbb    b
b              b
b              b
bbbbbbbbbbbbbbbb
|----Layer 3|
pppppppppppppppp
pppppppppppppppp
pppppppppppppppp
pppppppppppppppp
pppppppppppppppp
pppppppppppppppp
pppppppppppppppp
pppppppppppppppp
}}
</td></tr></table>
All possible exits
<table><tr><td style="width:400px;">
{{layered blueprint|name=U-shaped Exits|default=Layer 0
|p=Prismarine|b=Prismarine Bricks|l=Sea Lantern
|----Layer -1|
pppppppppppppppp
pppppppppppppppp
pppbbppppppbbppp
ppb  bppppb  bpp
ppb  bppppb  bpp
pppbbppppppbbppp
pppppppppppppppp
pppppppppppppppp
|----Layer 0|
bbb  bbbbbb  bbb
b    bbbbbb    b
b    bbbbbb    b
     bbbbbb     
     bbbbbb     
b              b
b              b
bbb  bbbbbb  bbb
|----Layer 1|
ppp  pppppp  ppp
p     pppp     p
p     pppp     p
      lppl      
                
p              p
p              p
ppp  pppppp  ppp
|----Layer 2|
bbbbbbbbbbbbbbbb
b    bbbbbb    b
b    bbbbbb    b
b    bbbbbb    b
b    bbbbbb    b
b              b
b              b
bbbbbbbbbbbbbbbb
|----Layer 3|
pppppppppppppppp
pppppppppppppppp
pppbbppppppbbppp
ppb  bppppb  bpp
ppb  bppppb  bpp
pppbbppppppbbppp
pppppppppppppppp
pppppppppppppppp
}}
</td></tr></table><noinclude>
[[fr:Monument sous-marin/Structure/Salle DX]]
[[uk:Океанічний монумент/Структура/План кімнати DX]]
[[zh:海底神殿/结构/DX房间]]
</noinclude>