<noinclude>{{structure info}}</noinclude>
{{layered blueprint|name=ruin2_cracked|default=Layer 0|g=gravel|c=chest|S=Cracked Stone Bricks|P=Polished Granite|C=chiseled Stone Bricks|M=magma block|m=Mossy cobblestone
|----Layer 1|
ggggggg
ggggggg
ggggMgg
gcggggg
ggggggg
 ggMggg
|----Layer 2|
m      
 S mSS 
       
 g  m S 
 mS    
    m S 
|----Layer 3|
       
 m  mS 
       
       
  S    
      S



}}<noinclude>
[[fr:Ruines sous-marines/Structure/Ruine 2 craquelée]]
[[zh:海底废墟/结构/ruin2 cracked]]
</noinclude>