<noinclude>{{structure info}}</noinclude>
No exits
<table><tr><td style="width:400px;">
{{layered blueprint|name=Four Pillars No Exits|default=Layer 0
|p=Prismarine|b=Prismarine Bricks|l=Sea Lantern
|----Layer -1|
pppppppp
pppppppp
pppppppp
pppppppp
pppppppp
pppppppp
pppppppp
pppppppp
|----Layer 0|
bbbbbbbb
b      b
b b  b b
b      b
b      b
b b  b b
b      b
bbbbbbbb
|----Layer 1|
bppppppb
p      p
p l  l p
p      p
p      p
p l  l p
p      p
bppppppb
|----Layer 2|
bbbbbbbb
b      b
b b  b b
b      b
b      b
b b  b b
b      b
bbbbbbbb
|----Layer 3|
pppppppp
pppppppp
pppppppp
pppppppp
pppppppp
pppppppp
pppppppp
pppppppp
}}
</td></tr></table>
All possible exits
<table><tr><td style="width:400px;">
{{layered blueprint|name=Four Pillars Exits|default=Layer 0
|p=Prismarine|b=Prismarine Bricks|l=Sea Lantern
|----Layer -1|
pppppppp
pppppppp
pppbbppp
ppb  bpp
ppb  bpp
pppbbppp
pppppppp
pppppppp
|----Layer 0|
bb    bb
b      b
  b  b  
        
        
  b  b  
b      b
bb    bb
|----Layer 1|
bp    pb
p      p
  l  l  
        
        
  l  l  
p      p
bp    pb
|----Layer 2|
bb    bb
b      b
  b  b  
        
        
  b  b  
b      b
bb    bb
|----Layer 3|
pppppppp
pppppppp
pppbbppp
ppb  bpp
ppb  bpp
pppbbppp
pppppppp
pppppppp
}}
</td></tr></table><noinclude>
[[fr:Monument sous-marin/Structure/Petite salle quatre piliers]]
[[uk:Океанічний монумент/Структура/План невеликої чотирьохколонної кімнати]]
[[zh:海底神殿/结构/细支柱房间]]
</noinclude>