<noinclude>{{structure info}}</noinclude>
{{layered blueprint|name=ruin3_brick|default=Layer 0|g=gravel|c=chest|S=Stone Bricks|M=magma block|s=sand|C=cobblestone|b=stone brick stairs|y=chiseled Stone Bricks
|----Layer 1|
 gggg
 gggcg
gygCgg
gMgggg
ggggsg
 ggggg
  ggMg
|----Layer 2|
     
 S  S
   S
   
 S  S
   
  y
|----Layer 3|
  
 S  S
   
   
 S  S
|----Layer 4|
  
    S
   
   
 S  S
|----Layer 5|
  
     
   
   
SSSSSS
|----Layer 6|
  
     
   
   
 bSSb


}}<noinclude>
[[fr:Ruines sous-marines/Structure/Ruine 3 pierre taillée]]
[[zh:海底废墟/结构/ruin3 brick]]
</noinclude>