{{layered blueprint|name=ruin3_cracked|default=Layer 1|g=gravel|c=chest|S=Cracked Stone Bricks|C=chiseled Stone Bricks|M=magma block|m=cobblestone|s=sand|b=stone brick stairs|o=obsidian
|----Layer 1|
 ggggg
gcgssgg
ggmMsgg
ggggsog
gsggggg
 ggggg
|----Layer 2|
 
 S gS
  S gg
    g C
 Sg S
|----Layer 3|
 
 S  S
    g
 
 S  S
|----Layer 4|
 
 S  S
 
 
    S
|----Layer 5|
    S
    S
    S
    S
    S
    S
|----Layer 6|
 
    b
    S
    S
    b
}}<noinclude>
[[Category:Ocean Ruins structure subpages]]

[[zh:海底废墟/结构/ruin3 cracked]]
</noinclude>