<noinclude>{{structure info}}</noinclude>
No exits
<table><tr><td style="width:400px;">
{{layered blueprint|name=Dark Prismarine Walls No Exits|default=Layer 0
|p=Prismarine|b=Prismarine Bricks|d=Dark Prismarine
|----Layer -1|
pppppppp
pppppppp
pppppppp
pppppppp
pppppppp
pppppppp
pppppppp
pppppppp
|----Layer 0|
bbbddbbb
b      b
b      b
d      d
d      d
b      b
b      b
bbbddbbb
|----Layer 1|
dddddddd
d      d
d      d
d      d
d      d
d      d
d      d
dddddddd
|----Layer 2|
bbbbbbbb
b      b
b      b
b      b
b      b
b      b
b      b
bbbbbbbb
|----Layer 3|
pppppppp
pppppppp
pppppppp
pppppppp
pppppppp
pppppppp
pppppppp
pppppppp
}}
</td></tr></table>
All possible exits
<table><tr><td style="width:400px;">
{{layered blueprint|name=Dark Prismarine Walls Exits|default=Layer 0
|p=Prismarine|b=Prismarine Bricks|d=Dark Prismarine
|----Layer -1|
pppppppp
pppppppp
pppbbppp
ppb  bpp
ppb  bpp
pppbbppp
pppppppp
pppppppp
|----Layer 0|
bbb  bbb
b      b
b      b
        
        
b      b
b      b
bbb  bbb
|----Layer 1|
ddd  ddd
d      d
d      d
        
        
d      d
d      d
ddd  ddd
|----Layer 2|
bbbbbbbb
b      b
b      b
b      b
b      b
b      b
b      b
bbbbbbbb
|----Layer 3|
pppppppp
pppppppp
pppbbppp
ppb  bpp
ppb  bpp
pppbbppp
pppppppp
pppppppp
}}
</td></tr></table><noinclude>
[[fr:Monument sous-marin/Structure/Petite salle de prismarine sombre]]
[[uk:Океанічний монумент/Структура/План невеликої кімнати з темного призмарину]]
[[zh:海底神殿/结构/暗海晶石小房间]]
</noinclude>