<noinclude>{{structure info}}</noinclude>
No exits
<table><tr><td style="width:400px;">
{{layered blueprint|name=No Exits|default=Layer 0
|p=Prismarine|b=Prismarine Bricks|d=Dark Prismarine|l=Sea Lantern
|----Layer -1|
pppppppp
pppppppp
pppppppp
pppppppp
pppppppp
pppppppp
pppppppp
pppppppp
pppppppp
pppppppp
pppppppp
pppppppp
pppppppp
pppppppp
pppppppp
pppppppp
|----Layer 0|
bbbbbbbb
bb    bb
bb    bb
b      b
b      b
b      b
b b  b b
b      b
b      b
b b  b b
b      b
b      b
b      b
bb    bb
bb    bb
bbbbbbbb
|----Layer 1|
pppppppp
p      p
p      p
p      p
p      p
p l  l p
p bbbb p
p b  b p
p b  b p
p bbbb p
p l  l p
p      p
p      p
p      p
p      p
pppppppp
|----Layer 2|
bbbbbbbb
bb    bb
bb    bb
b      b
b      b
b b  b b
b b  b b
b      b
b      b
b b  b b
b b  b b
b      b
b      b
bb    bb
bb    bb
bbbbbbbb
|----Layer 3|
pppppppp
pppppppp
pppppppp
pppppppp
pppppppp
pppppppp
pppppppp
pppppppp
pppppppp
pppppppp
pppppppp
pppppppp
pppppppp
pppppppp
pppppppp
pppppppp
}}
</td></tr></table>
All possible exits
<table><tr><td style="width:400px;">
{{layered blueprint|name=Exits|default=Layer 0
|p=Prismarine|b=Prismarine Bricks|d=Dark Prismarine|l=Sea Lantern
|----Layer -1|
pppppppp
pppppppp
pppbbppp
ppb  bpp
ppb  bpp
pppbbppp
pppppppp
pppppppp
pppppppp
pppppppp
pppbbppp
ppb  bpp
ppb  bpp
pppbbppp
pppppppp
pppppppp
|----Layer 0|
bbb  bbb
bb    bb
bb    bb
        
        
b      b
b b  b b
b      b
b      b
b b  b b
b      b
        
        
bb    bb
bb    bb
bbb  bbb
|----Layer 1|
ppp  ppp
p      p
p      p
        
        
p l  l p
p bbbb p
p b  b p
p b  b p
p bbbb p
p l  l p
        
        
p      p
p      p
ppp  ppp
|----Layer 2|
bbbbbbbb
bb    bb
bb    bb
b      b
b      b
b b  b b
b b  b b
b      b
b      b
b b  b b
b b  b b
b      b
b      b
bb    bb
bb    bb
bbbbbbbb
|----Layer 3|
pppppppp
pppppppp
pppbbppp
ppb  bpp
ppb  bpp
pppbbppp
pppppppp
pppppppp
pppppppp
pppppppp
pppbbppp
ppb  bpp
ppb  bpp
pppbbppp
pppppppp
pppppppp
}}
</td></tr></table><noinclude>
[[fr:Monument sous-marin/Structure/Salle DZ]]
[[uk:Океанічний монумент/Структура/План кімнати DZ]]
[[zh:海底神殿/结构/DZ房间]]
</noinclude>