{{layered blueprint|name=ruin4_mossy|default=Layer 0|g=gravel|s=sand|M=magma block|S=Mossy Stone Bricks|d=dark oak planks|p=spruce planks|c=chest
|----Layer 1|
ggggggM
sMdsdsg
gdMspsM
sdggggg
gdgdpgg
ggggggg
|----Layer 2|
 SSSS
S cSgS
S  S S
S  Sg
Sg   S
 SSSS
|----Layer 3|
 SSSS
S  S S
   S S
S  S
S    S
 S SS
|----Layer 4|
 SSSS
S  S S
S  S S
S  S S
S    S
 SSSS
|----Layer 5|
 
 SSSS
 S SS
 S SS
 SSSS
|----Layer 6|
 
 
   S
  SS
}}<noinclude>
[[Category:Ocean Ruins structure subpages]]

[[zh:海底废墟/结构/ruin4 mossy]]
</noinclude>