<noinclude>{{structure info}}</noinclude>
{{layered blueprint|name=big_ruin8_cracked|default=Layer 0|w=dark oak planks|g=gravel|W=spruce planks|M=magma block|s=sand|c=chest|S=cracked stone bricks
|----Layer 1|
  gggg  ggg    
 ggggggggggg
 gggggggggggg
 gggggggMgMggggg
gggggggggsgggggg
gggggggggsgggggg
ggggggggggggwggg
ggWgWWgWgsggswg
gggggWggggggggg
ggWgsgWggggwgggg
ggWWggsgggggwggg
gggggggssgcggggg
 gggggggssgwgwgg
 ggggggssgggwwg
  Mgggggggggggg
   ggggg gggg M
|----Layer 2|
     
 g S SS  g
   S  S g
   S  S      g S
   S  S  g
 ggS  SSSSSSSSS
 SSS     S    S
 S       S    S
 S           gS
       g S  ggS
 S       S   gS
 SSSS    Sg   S
  g S    S    S
    S    S    S
    SS SSSSS SS
         S
|----Layer 3|
            
   S S
   S    g
     
     
  gS    SSS   S
  SS     S
       
 S
          
              S
 SS S    S
    S    S    S
         S    S
       S SS   S
          

|----Layer 4|
      
      
      
      
      
        
   S
      
       
       
       
       
      
      
      SSS
       
|----Layer 5|
      
      
      
      
      
        
    
      
       
       
       
       
      
      
       S 
      

}}<noinclude>
[[fr:Ruines sous-marines/Structure/Grande ruine 8 craquelée]]
[[zh:海底废墟/结构/big ruin8 cracked]]
</noinclude>