<noinclude>{{structure info}}</noinclude>
No exits
<table><tr><td style="width:400px;">
{{layered blueprint|name=Plus No Exits|default=Layer 0
|p=Prismarine|b=Prismarine Bricks|l=Sea Lantern
|----Layer -1|
pppppppp
pppppppp
pppppppp
pppppppp
pppppppp
pppppppp
pppppppp
pppppppp
|----Layer 0|
bbbbbbbb
bbbbbbbb
bbb  bbb
bb    bb
bb    bb
bbb  bbb
bbbbbbbb
bbbbbbbb
|----Layer 1|
pppppppp
pl    lp
p      p
p      p
p      p
p      p
pl    lp
pppppppp
|----Layer 2|
bbbbbbbb
bbbbbbbb
bbb  bbb
bb    bb
bb    bb
bbb  bbb
bbbbbbbb
bbbbbbbb
|----Layer 3|
pppppppp
pppppppp
pppppppp
pppppppp
pppppppp
pppppppp
pppppppp
pppppppp
}}
</td></tr></table>
All possible exits
<table><tr><td style="width:400px;">
{{layered blueprint|name=Plus Exits|default=Layer 0
|p=Prismarine|b=Prismarine Bricks|l=Sea Lantern
|----Layer -1|
pppppppp
pppppppp
pppbbppp
ppb  bpp
ppb  bpp
pppbbppp
pppppppp
pppppppp
|----Layer 0|
bbb  bbb
bbb  bbb
bbb  bbb
        
        
bbb  bbb
bbb  bbb
bbb  bbb
|----Layer 1|
ppp  ppp
pl    lp
p      p
        
        
p      p
pl    lp
ppp  ppp
|----Layer 2|
bbbbbbbb
bbb  bbb
bbb  bbb
b      b
b      b
bbb  bbb
bbb  bbb
bbbbbbbb
|----Layer 3|
pppppppp
pppppppp
pppbbppp
ppb  bpp
ppb  bpp
pppbbppp
pppppppp
pppppppp
}}
</td></tr></table><noinclude>
[[fr:Monument océanique/Structure/Petite salle en forme de plus]]
[[uk:Океанічний монумент/Структура/План невеликої кімнати плюсової форми]]
[[zh:海底神殿/结构/十字形房间]]
</noinclude>