<noinclude>{{structure info}}</noinclude>
No exits
<table><tr><td style="width:400px;">
{{layered blueprint|name=Inset No Exits|default=Layer 0
|p=Prismarine|b=Prismarine Bricks
|----Layer -1|
pppppppp
pppppppp
pppppppp
pppppppp
pppppppp
pppppppp
pppppppp
pppppppp
|----Layer 0|
bbbbbbbb
b      b
b      b
b      b
b      b
b      b
b      b
bbbbbbbb
|----Layer 1|
pppppppp
p      p
p      p
p      p
p      p
p      p
p      p
pppppppp
|----Layer 2|
bbbbbbbb
b      b
b      b
b      b
b      b
b      b
b      b
bbbbbbbb
|----Layer 3|
bbbbbbbb
b b  b b
bbb  bbb
b      b
b      b
bbb  bbb
b b  b b
bbbbbbbb
|----Layer 4|
bbbbbbbb
b      b
b      b
b      b
b      b
b      b
b      b
bbbbbbbb
|----Layer 5|
pppppppp
p      p
p      p
p      p
p      p
p      p
p      p
pppppppp
|----Layer 6|
bbbbbbbb
b      b
b      b
b      b
b      b
b      b
b      b
bbbbbbbb
|----Layer 7|
pppppppp
pppppppp
pppppppp
pppppppp
pppppppp
pppppppp
pppppppp
pppppppp
}}
</td></tr></table>
All possible exits
<table><tr><td style="width:400px;">
{{layered blueprint|name=Inset All Exits|default=Layer 0
|p=Prismarine|b=Prismarine Bricks
|----Layer -1|
pppppppp
pppppppp
pppbbppp
ppb  bpp
ppb  bpp
pppbbppp
pppppppp
pppppppp
|----Layer 0|
  b  b 
       
b      b
       
       
b      b
       
  b  b 
|----Layer 1|
  b  b 
       
b      b
       
       
b      b
       
  b  b 
|----Layer 2|
  bbbb 
       
b      b
b      b
b      b
b      b
       
  bbbb 
|----Layer 3|
bbbbbbbb
b b  b b
bbb  bbb
b      b
b      b
bbb  bbb
b b  b b
bbbbbbbb
|----Layer 4|
  b  b 
       
b      b
       
       
b      b
       
  b  b 
|----Layer 5|
  b  b 
       
b      b
       
       
b      b
       
  b  b 
|----Layer 6|
  bbbb 
       
b      b
b      b
b      b
b      b
       
  bbbb 
|----Layer 7|
pppppppp
pppppppp
pppbbppp
ppb  bpp
ppb  bpp
pppbbppp
pppppppp
pppppppp
}}
</td></tr></table><noinclude>
[[fr:Monument sous-marin/Structure/Salle DY]]
[[uk:Океанічний монумент/Структура/План кімнати DY]]
[[zh:海底神殿/结构/DY房间]]
</noinclude>