<noinclude>{{structure info}}</noinclude>
{{layered blueprint|name=ruin8_brick|default=Layer 0|g=gravel|c=chest|S=Stone Bricks|P=Polished Granite|C=chiseled Stone Bricks|M=magma block|w=dark oak planks
|----Layer 1|
  gg
 gggg
ggwwgg
gwwggg
MgggMg
ggwgg
 ggg
|----Layer 2|
   
 SSS
S c S
S   S
 S S
 S S
 S S
|----Layer 3|
   
 S S
S   S
S   S
 S S
    
 S S
|----Layer 4|
   
 SSS
S   S
S   S
 S S
 S S
 SSS
|----Layer 5|
   
  
 SCS
 CCC
 CCC
 SCS
  C
|----Layer 6|
   
  
    
  C 
  C 
    
   



}}<noinclude>
[[fr:Ruines sous-marines/Structure/Ruine 8 pierre taillée]]
[[zh:海底废墟/结构/ruin8 brick]]
</noinclude>