<noinclude>{{structure info}}</noinclude>
{{layered blueprint|name=big_ruin2_cracked|default=Layer 0|S=Cracked Stone Bricks|v=Chiseled Stone Bricks|m=Magma Block|P=Prismarine|h=chest|T=purple glazed terracotta|c=chest|g=gravel|C=chiseled stone bricks|p=prismarine|M=magma block|D=sea lantern|G=polished granite
|----Layer 1|
   ggg g
  gggggggg  ggg
  Sgggggpgg gggg
 ggggpggggggggg
 gggggggggggmg
  ggSSSggggggggg
 ggSSCSggggggvg
 ggSSCSggggggg
gpgSSCSggSSgggg
ggpgSSSSSTTSggg
 gggggggSTTSgggg
gggggggpgSSggggg
gggggggggggggggg
gggggggggggggSgg
 ggpggggggggggg
  gggg  g ggg
|----Layer 2|
     
    g         G
  S   S gS   S
  g  gg
    SSSg
   S  hS
  S    SS    S
       SS S
 gS    SS  S
  gS        SS
    SSSS    S
 g     gS  Sg g
        gSSg
  Sg  S  Sgg S
   g G  g Gg
          
|----Layer 3|
     
             
  S   S  S   S
      g
    SSS 
   S   S
  S    SS    S
       SS S
  S    SS  S
   S        SS
    SSSS    S
        S  S   
         SS 
  S   S  Sg  S
         
          
|----Layer 4|
     
             
  G   G  G    
      
    SSS 
   S   S
  S    SS    G
  S    SSSS
  S    SS  S
   S   S    SG
    SSSS    S
        S  S   
         SS 
  G          G
          
          
               
|----Layer 5|
     
             
              
      
    SSS 
   S   S
  S    SS     
  S    SSSS
  S    SD  S
   S   S    S 
    SSSS    S
        S  S   
         SS 
              
         
          
  
|----Layer 6|
     
             
    
     
    S S 
   S   S
  S    SS     
           
  S    SSvv   
   S   SvSSv     
    S S vSSv     
         vv       
           
              
         
          
|----Layer 7|   
     
             
    
    SGS 
   S   S
  S    SS     
  G    GG  
  S    SS   
   S   S     
    SGS     
               
           
              
         
          
|----Layer 8|
     
             
    
       
    vvv 
   SSSSS
  vS   Sv     
  vS D Sv  
  vS   Sv   
   SSSSS     
    vvv     
               
           
              
         
          
|----Layer 9|
     
             
    
       
        
    vvv 
   vvSvv      
   vSSSv   
   vvSvv    
    vvv      
            
               
           
              
         
          

}}<noinclude>
[[fr:Ruines sous-marines/Structure/Grande ruine 2 craquelée]]
[[zh:海底废墟/结构/big ruin2 cracked]]
</noinclude>