<noinclude>{{structure info}}</noinclude>
{{layered blueprint|name=big_ruin_warm5|default=Layer 1|s=sand|c=chest|S=cut sandstone|C=Sandstone|d=polished diorite|g=Polished granite|D=sea lantern|M=magma block
|----Layer 1|
  ssss       s  
 ssMsssssss sss 
ssssssssssssssss
ssssssssssssssss
 sssssssssssMsss
  ssMssssssssss
 ssssssssDsssss 
ssssssssssssss  
sssssssscMssss
 sssssDssssssss
  ssssssssssssss
 sssssssssssssss
ssssssssssssssss
sssssssssssMsss 
 ssssss sssssss 
  ss     ss
|----Layer 2|
     
    s   s
  C   SssSs  S
 s       ss   s
  s      s
      SSSS
  S  S    S  S
 s s C CSsS C
     S SS s 
  C  S    S  C
  s   SSSS s
               
 g             
  S  sS  S   S  
               
|----Layer 3|
          
           
  S   S  S   S
         s
          
          
  S          
       CC       
       SS
  S          C
          
          
          
  S   C  S   S
          
           
|----Layer 4|
            
            
  g          g
         
         
         
          
       SS
       SS
        
        
       
             
             g
          
           
|----Layer 5|
      
       
        
        
        
         
         
       gd
       dg
       
       
       
       
    
       
         
|----Layer 6|
      
       
        
        
        
         
         
       dg
       gd
       
       
       
       
    
       
         
|----Layer 7|
      
       
        
        
        
         
         
       SS
       SS
       
       
       
       
    
       
         

}}<noinclude>
[[fr:Ruines sous-marines/Structure/Grande ruine chaude 5]]
[[zh:海底废墟/结构/big ruin warm5]]
</noinclude>