<noinclude>{{structure info}}</noinclude>
{{layered blueprint|name=ruin7_brick|default=Layer 0|g=gravel|c=chest|S=Stone Bricks|P=Polished Granite|C=chiseled Stone Bricks|M=magma block|m=Mossy cobblestone
|----Layer 1|
 ggg  
gMgggg
ggmgmg
ggmmcg
ggmmgg
 ggggg
  ggg
|----Layer 2|
      
  SSS 
 SgggS
 S  gS
 Sg gS
  S S
      
|----Layer 3|
      
  S S 
 Sg  S
      
 S  gS
  S S 
      
|----Layer 4|
      
  SSS 
 S   S
 S   S
 S   S
  SSS 
      
|----Layer 5|
      
      
  SSS 
  SSS 
  SSS 
      
|----Layer 6|
      
      
   C  
  CPC 
   C  
      
 



}}<noinclude>
[[fr:Ruines sous-marines/Structure/Ruine 7 pierre taillée]]
[[zh:海底废墟/结构/ruin7 brick]]
</noinclude>