<noinclude>{{structure info}}</noinclude>
No exits
<table><tr><td style="width:400px;">
{{layered blueprint|name=Hollow Pillar No Exits|default=Layer 0
|p=Prismarine|b=Prismarine Bricks|l=Sea Lantern
|----Layer -1|
pppppppppppppppp
pppppppppppppppp
pppppppppppppppp
pppppppppppppppp
pppppppppppppppp
pppppppppppppppp
pppppppppppppppp
pppppppppppppppp
|----Layer 0|
bbbbbbbbbbbbbbbb
b              b
b  bb      bb  b
b b  b    b  b b
b b  b    b  b b
b  bb      bb  b
b              b
bbbbbbbbbbbbbbbb
|----Layer 1|
pppppppppppppppp
p              p
p  bb      bb  p
p b  b    b  b p
p b  b    b  b p
p  bb      bb  p
p              p
pppppppppppppppp
|----Layer 2|
bbbbbbbbbbbbbbbb
b              b
b  bb      bb  b
b b  b    b  b b
b b  b    b  b b
b  bb      bb  b
b              b
bbbbbbbbbbbbbbbb
|----Layer 3|
bbbbbbbbbbbbbbbb
b              b
b  bbl    lbb  b
b b  bb  bb  b b
b b  bb  bb  b b
b  bbl    lbb  b
b              b
bbbbbbbbbbbbbbbb
|----Layer 4|
bbbbbbbbbbbbbbbb
b              b
b  bb      bb  b
b b          b b
b b          b b
b  bb      bb  b
b              b
bbbbbbbbbbbbbbbb
|----Layer 5|
pppppppppppppppp
p              p
p  bbb    bbb  p
p b          b p
p b          b p
p  bbb    bbb  p
p              p
pppppppppppppppp
|----Layer 6|
bbbbbbbbbbbbbbbb
b              b
b  bbbbbbbbbb  b
b b  bbbbbb  b b
b b  bbbbbb  b b
b  bbbbbbbbbb  b
b              b
bbbbbbbbbbbbbbbb
|----Layer 7|
pppppppppppppppp
pppppppppppppppp
pppppppppppppppp
pppppppppppppppp
pppppppppppppppp
pppppppppppppppp
pppppppppppppppp
pppppppppppppppp
}}
</td></tr></table>
All possible exits
<table><tr><td style="width:400px;">
{{layered blueprint|name=Hollow Pillar Exits|default=Layer 0
|p=Prismarine|b=Prismarine Bricks|l=Sea Lantern
|----Layer -1|
pppppppppppppppp
pppppppppppppppp
pppbbppppppbbppp
ppb  bppppb  bpp
ppb  bppppb  bpp
pppbbppppppbbppp
pppppppppppppppp
pppppppppppppppp
|----Layer 0|
bbb  bbbbbb  bbb
b              b
b  bb      bb  b
  b  b    b  b  
  b  b    b  b  
b  bb      bb  b
b              b
bbb  bbbbbb  bbb
|----Layer 1|
ppp  pppppp  ppp
p              p
p  bb      bb  p
  b  b    b  b  
  b  b    b  b  
p  bb      bb  p
p              p
ppp  pppppp  ppp
|----Layer 2|
bbbbbbbbbbbbbbbb
b              b
b  bb      bb  b
b b  b    b  b b
b b  b    b  b b
b  bb      bb  b
b              b
bbbbbbbbbbbbbbbb
|----Layer 3|
bbbbbbbbbbbbbbbb
b              b
b  bbl    lbb  b
b b  bb  bb  b b
b b  bb  bb  b b
b  bbl    lbb  b
b              b
bbbbbbbbbbbbbbbb
|----Layer 4|
bbb  bbbbbb  bbb
b              b
b  bb      bb  b
  b          b  
  b          b  
b  bb      bb  b
b              b
bbb  bbbbbb  bbb
|----Layer 5|
ppp  pppppp  ppp
p              p
p  bbb    bbb  p
  b          b  
  b          b  
p  bbb    bbb  p
p              p
ppp  pppppp  ppp
|----Layer 6|
bbbbbbbbbbbbbbbb
b              b
b  bbbbbbbbbb  b
b b  bbbbbb  b b
b b  bbbbbb  b b
b  bbbbbbbbbb  b
b              b
bbbbbbbbbbbbbbbb
|----Layer 7|
pppppppppppppppp
pppppppppppppppp
pppbbppppppbbppp
ppb  bppppb  bpp
ppb  bppppb  bpp
pppbbppppppbbppp
pppppppppppppppp
pppppppppppppppp
}}
</td></tr></table><noinclude>
[[fr:Monument sous-marin/Structure/Salle DXY]]
[[uk:Океанічний монумент/Структура/План кімнати DXY]]
[[zh:海底神殿/结构/DXY房间]]
</noinclude>