<noinclude>{{structure info}}</noinclude>
{{layered blueprint|name=big_ruin3_brick|default=Layer 0|c=chest|g=gravel|S=stone bricks|C=chiseled stone bricks|p=prismarine|M=magma block|D=sea lantern|G=polished granite|B=bricks|s=sand
|----Layer 1|
   gg gg
  gggggggg   gg
 gggggggggg gggg
gggggggggggggggg
ggsggggggggggggg
 gggggMgggBgggsg
  gggggggBgBgBg
 ggggggggBggBBg
ggggggggggggggg
 ggggggggggBggg
 ggggBggggggssg
ggggggMggggggsg
gggBgggggggggggg
 ggggggsggggggg
  gggggggg ggg
   gg gg   g
|----Layer 2|
          
       G
  S   S  S   S
   G g
  g       S S
    gg   S   Sg
  Sgggg S     S
   S SSgS     S
  SS SSSS     S
 SS   SSSS   S
 SS   SSSgSSSg
 SS    SSg   g
 SSc  SSS
  SSSSSS S   S
   SSSSg
          
|----Layer 3|
          
       
  S      G   S
         
          S S
         S   S
  G  g  S     S
   S SS S     S
  SS   SS     S
 S     SSS   S
 S     SSgSSS
 S     SS
 S     SS
  S    S G   S
   SSSS
          
|----Layer 4|
          
       
             G
         
          SSS
         S   S
        S     S
   SSSS S     
  S    SS     S
 S     SSS   S
 S     SS SSS
 S     SS
 S      S
  S    S     G
   SSSS
          
|----Layer 5|
          
       
              
         
          SSS
         S   S
        S     S
   SSSS S     S
  S    SS     S
 S     SSS   S
 S     SS SSS
 S      S
 S      S
  S    S      
   SSSS
          
|----Layer 6|
          
       
              
         
             
          SSS 
         SCGCS 
   SSSS  SGCGS 
  SSSSSS SCGCS
 SS    SS SSS 
 SS     S    
 SS     S
 SS     S
  SSSSSS      
   SSSS
          
|----Layer 7|
          
       
              
         
             
              
          CCC  
   SSSS   CGC  
  CSSSSC  CCC 
 SSSSSS S     
 SSSSS  S    
 SSSSS  S
 SSSSSS S
  CSSSSC      
   SSSS
          
|----Layer 8|
          
       
              
         
             
              
               
    SS         
  C    C      
             
 S      S    
 S      S
     
  C    C      
    SS 
          
|----Layer 9-10|
          
       
              
         
             
              
               
               
  C    C      
             
             
         
     
  C    C      
       
          
|----Layer 11|
          
       
              
         
             
              
               
   S  S        
  S    S      
 S      S   
             
         
 S      S
  S    S      
   S  S 
          
|----Layer 12|
          
       
              
         
             
              
               
    SS         
   CSSC       
  CD   C    
 SS    SS    
 SS    SS
  C   DC 
   CSSS       
    SS  
          
|----Layer 13|
          
       
              
         
             
              
               
               
    CC        
   CCCC     
  CCGGCC     
  CCGGCC 
   CCCC  
    CC        
      
          
}}<noinclude>
[[fr:Ruines sous-marines/Structure/Grande ruine 3 pierre taillée]]
[[zh:海底废墟/结构/big ruin3 brick]]
</noinclude>