<noinclude>{{structure info}}</noinclude>
{{layered blueprint|name=Wings|default=Layer 0
|a=Prismarine Bricks|b=Sea Lantern|c=Prismarine|d=Dark Prismarine
|----Layer -1|
aaaacccccccccccccccccccccc
aaaaccccccccccccccccccccc 
aaaaccccccccccccccccccccc 
aaaaccccccccccccccccccccc 
ccccccccccccccccccccccccc 
ccccccccccccccccccccccccc 
ccccccccccccccccccccccccc 
ccccccccccccccccccccccccc 
ccccccccccccccccccccccccc 
aaaaccccccccccccccccccccc 
aaaaccccccccccccccccccccc 
aaaaccccccccccccccccccccc 
aaaaccccccccccccccccccccc 
ccccccccccccccccccccccccc 
ccccccccccccccccccccccccc 
ccccccccccccccccccccccccc 
ccccccccccccccccccccccccc 
ccccccccccccccccccccccccc 
aaaacccccaaaacccccaaaaccc 
aaaacccccaaaacccccaaaaccc 
aaaacccccaaaacccccaaaaccc 
aaaacccccaaaacccccaaaaccc 
|----Layer 0|
a                         
a                       a 
a         a   a         a 
a                       a 
a                       a 
a                       a 
a        a     a        a 
a                       a 
a          bcb          a 
a          ccc          a 
a          bcb          a 
a                       a 
a                       a 
a        a     a        a 
a                       a 
a                       a 
a                       a 
a                       a 
a                       a
a                       a
a                       a
aaaaaaaaaaaaaaaaaaaaaaaaa 
|----Layer 1|
 a                     ccc
 a                     a  
 a        a   a        a  
 a                     a  
 a                     aa 
 a                     a  
 a       a     a       a  
 a                     a  
 a         aca         aa 
 a         ccc         a  
 a         aca         a  
 a                     a  
 a                     aa 
 a       a     a       a  
 a                     a  
 a                     a  
 a                     aa 
 a                     a  
 a                     a  
 a                     a  
 aaaaaaaaaaaaaaaaaaaaaaa  
                          
|----Layer 2|
  a                   cccc
  a                   a   
  a       a   a       a   
  a                   a   
  a                   a a 
  a                   a   
  a      a     a      a   
  a                   a   
  a        aca        a a 
  a        ccc        a   
  a        aca        a   
  a                   a   
  a                   a a 
  a      a     a      a   
  a                   a   
  a                   a   
  a                   a a 
  a                   a   
  a                   a   
  aaaaaaaaaaaaaaaaaaaaa   
                          
                          
|----Layer 3|
   accc   aaaaa      ccccc
   accc   aaaaa   ccca    
   accc   aaaaa   ccca    
   accc           ccca    
   accc           cccaaaa 
   accc           ccca    
   accc aaaaaaaaa ccca    
   accc adaaaaada ccca    
   accc adaaaaada cccaaaa 
   accc adaaaaada ccca    
   accc adaaaaada ccca    
   accc adaaaaada ccca    
   accc adaaaaada cccaaaa 
   accc aaaaaaaaa ccca     
   accc           ccca    
   accccccccccccccccca    
   acccccccccccccccccaaaa 
   accccccccccccccccca    
   aaaaaaaaaaaaaaaaaaa    
                          
                          
                          
|----Layer 4|
       a  a   a  ccccccccc
     a a         a        
       a         a a      
       a         a        
     a a         a        
       a         a a      
       a         a        
     a a         a        
       a   bcb   a a      
       a   ccc   a        
     a a   bcb   a        
       a         a a      
       a         a        
     a a         a        
       aaaaaaaaaaa a      
                          
     a  a  a  a  a a      
                          
                          
                          
                          
                          
|----Layer 5|
        a b   b cccccccccc
        a       a         
        a       a         
        a       a         
        a       a         
        a       a         
        a       a         
        a       a         
        a  aca  a         
        a  ccc  a         
        a  aca  a         
        a       a         
        a       a         
        aaaaaaaaa         
                          
                          
                          
                          
                          
                          
                          
                          
|----Layer 6|
         aa   accccccccccc
         a     a          
         a     a          
         a     a          
         a     a          
         a     a          
         a     a          
         a     a          
         a aca a          
         a ccc a          
         a aca a          
         a     a          
         aaaaaaa           
                          
                          
                          
                          
                          
                          
                          
                          
                          
|----Layer 7|
          accc cccdcdcdccc
          accca           
          accca           
          accca           
          accca           
          accca           
          accca           
          accca           
          accca           
          accca           
          accca           
          aaaaa           
                          
                          
                          
                          
                          
                          
                          
                          
                          
                          
|----Layer 8|
            a acccdcdcdccd
                          
                          
            a             
                          
                          
            a             
                          
                          
            a             
                          
                          
                          
                          
                          

                          
                          
                          
                          
                          
                          
}}<noinclude>
[[uk:Океанічний монумент/Структура/План крила з відкритою територією]]
[[zh:海底神殿/结构/侧翼2]]
</noinclude>