{{layered blueprint|name=ruin6_mossy|default=Layer 0|g=gravel|S=Mossy Stone Bricks|M=magma block|m=Mossy cobblestone|C=chiseled Stone Bricks|t=stone brick stairs|c=chest|p=polished granite
|----Layer 1|
ggggg
gMgggg
ggggcgg
ggggggg
 ggggg
 ggggg
|----Layer 2|
 ggg
g SSSS
 gS mS
    mS
  SSSS
  ggg
|----Layer 3|
  g
  SSSS
  S mS
     S
  SSSS
   g
|----Layer 4-5|
 
  SSSS
  S  S
  S  S
  SSSS
|----Layer 6|
  tttt
 tSSSSt
 tSpCSt
 tSCpSt
 tSSSSt
  tttt
|----Layer 7|
   tt
 
 t    t
 t    t
 
   tt
}}<noinclude>
[[Category:Ocean Ruins structure subpages]]

[[zh:海底废墟/结构/ruin6 mossy]]
</noinclude>