<noinclude>{{structure info}}</noinclude>
{{layered blueprint|name=ruin_warm2|default=Layer 0|c=chest|s=sand|S=cut sandstone|H=polished granite|C=Blue Terracotta
|----Layer 1|
  s
 ssss
sssss
ssssss
 sssss
 sssss
  sss
|----Layer 2|
    
  SS
 ScsS
 Css
 Hsss
 SssS
  SS
|----Layer 3|
    
  SS
 SssS
 Hs 
 C  s
 Ss S
  SS
|----Layer 4|
    
  SS
 Ss S
 S  S
 S  S
 S  S
  SS
|----Layer 5|
     
     
  SS
  SS
  SS
  SS
}}<noinclude>
[[fr:Ruines sous-marines/Structure/Ruine chaude 2]]
[[zh:海底废墟/结构/ruin warm2]]
</noinclude>