<noinclude>{{structure info}}</noinclude>
{{layered blueprint|name=ruin6_brick|default=Layer 0|g=gravel|c=chest|m=mossy cobblestone|S=stone bricks|w=stone brick stairs|M=magma block|P=polished granite|C=chiseled stone bricks
|----Layer 1|
  gggg
 gggMg
gggggg
gggggg
gggcgg
ggggg
 ggg
|----Layer 2|
    g
   g g
 S SSg
 S  Sg
gSmmS
 SSSS
  g
|----Layer 3|
   
   
 S SSg
 S  S
 S mS
 SSSS
|----Layer 4-5|
   
   
 SSSS
 S  S
 S  S
 SSSS
|----Layer 6|
     
 wwww
wSSSSw
wSCPSw
wSPCSw
wSSSSw
 wwww
|----Layer 7|
   
  ww
     
w    w
w    w
     
  ww
}}<noinclude>
[[fr:Ruines sous-marines/Structure/Ruine 6 pierre taillée]]
[[zh:海底废墟/结构/ruin6 brick]]
</noinclude>