<noinclude>{{structure info}}</noinclude>
Both wings example - open area left, large pillar room right 
<table><tr><td style="width:800px;">
{{layered blueprint|name=Wings example|default=Layer 0
|a=Prismarine Bricks|b=Sea Lantern|c=Prismarine|d=Dark Prismarine
|----Layer -1|
cccccccccccccccccccccccccaaaa
    cccccccccccccccccccccaaaa
    cccccccccccccccccccccaaaa
    cccccccccccccccccccccaaaa
    ccccccccccccccccccccccccc
    ccccccccccccccccccccccccc
    ccccccccccccccccccccccccc
    ccccccccccccccccccccccccc
    ccccccccccccccccccccccccc
    cccccccccccccccccccccaaaa
    cccccccccccccccccccccaaaa
    cccccccccccccccccccccaaaa
    cccccccccccccccccccccaaaa
    ccccccccccccccccccccccccc
    ccccccccccccccccccccccccc
    ccccccccccccccccccccccccc
    ccccccccccccccccccccccccc
    ccccccccccccccccccccccccc
    cccaaaacccccaaaacccccaaaa
    cccaaaacccccaaaacccccaaaa
    cccaaaacccccaaaacccccaaaa
    cccaaaacccccaaaacccccaaaa
|----Layer 0|
   a       aaaaaaaaaaa      a
    a      aaaaaaaaaaa      a
    a    a aaaaaaaaaaa a    a
    a      aaaaaaaaaaa      a
    a      aaaaaaaaaaa      a
    a      aaaaaaaaaaa      a
    a      aaaaaaaaaaa      a
    a      aaaaaaaaaaa      a
    a      aadababadaa      a
    a      aadaaaaadaa      a
    a      aadababadaa      a
    a      aaaaaaaaaaa      a
    a      aaaaaaaaaaa      a
    a      aaaadddaaaa      a
    a      aaaaaaaaaaa      a
    a         aaaaa         a
    a    a             a    a
    a                       a
    a                       a
    a                       a
    a                       a
    aaaaaaaaaaaaaaaaaaaaaaaaa
|----Layer 1|
  accc     aaaaaaaaaaa     a 
     a     aaaaaaaaaaa     a 
     a   b aaaaaaaaaaa b   a 
     a     aa       aa     a 
    aa     aa       aa     a 
     a     aa       aa     a 
     a     aa       aa     a 
     a     aa       aa     a 
    aa     aa   c   aa     a 
     a     aa  ccc  aa     a 
     a     aa   c   aa     a 
     a     aa       aa     a 
    aa     aa       aa     a 
     a     aaaa   aaaa     a 
     a     aaaa   aaaa     a 
     a                     a 
    aa   b             b   a 
     a                     a 
     a                     a 
     a                     a 
     aaaaaaaaaaaaaaaaaaaaaaa 
|----Layer 2|
 accccc    a  aaaaa  a    a  
      a    a  aaaaa  a    a  
      a  a a         a a  a  
      a    a         a    a  
    a a    a         a    a  
      a    a         a    a  
      a    a         a    a  
      a    a         a    a  
    a a    a    c    a    a  
      a    a   ccc   a    a  
      a    a    c    a    a  
      a    a         a    a  
    a a    a         a    a  
      a    a         a    a  
      a    aaaa   aaaa    a  
      a                   a  
    a a  a             a  a  
      a                   a  
      a                   a  
      aaaaaaaaaaaaaaaaaaaaa  
|----Layer 3|
accccccc   a   aaa   accca   
a      accca         accca   
       acccb         bccca   
       accca         accca   
    aaaaccca         accca   
       acccb         bccca   
       accca         accca   
       accca         accca   
    aaaacccb    c    bccca   
       accca   ccc   accca   
       accca    c    accca   
       acccb         bccca   
    aaaaccca         accca   
       accca         accca   
       acccaaba   abaaccca   
       accccccccccccccccca   
    aaaaccccccccccccccccca   
       accccccccccccccccca   
       aaaaaaaaaaaaaaaaaaa   
|----Layer 4|
cccccccccccc         a       
           a         a a     
         a a         a       
           a         a       
  ba       a         a a     
         a a         a       
           a         a       
           a         a a     
  ba     a a    c    a       
           a   ccc   a       
           a    c    a a     
         a a         a       
  ba       a         a       
           a         a a     
         a aaaaaaaaaaa       
                             
  ba     a a  a  a  a  a     
|----Layer 5|
dcccccccccccc       a        
            a       a        
            a       a        
            a       a        
cca         a       a        
            a       a        
            a       a        
            a       a        
cca         a   c   a        
            a  ccc  a        
            a   c   a        
            a       a        
cca         a       a        
            aaaaaaaaa        
                             
                             
cca                          
|----Layer 6|
cdcccccccccccc     a         
             a     a         
             a     a         
             a     a         
             a     a         
             a     a         
             a     a         
             a     a         
             a  c  a         
             a ccc a         
             a  c  a         
             a     a         
             aaaaaaa         
|----Layer 7|
ccdcccdcdcdcccaccca          
              accca          
              accca          
              accca          
              accca          
              accca          
              accca          
              accca          
              accca          
              accca          
              accca          
              aaaaa          
|----Layer 8|
dccdccdcdcdccca a            
                             
                             
                a            
                             
                             
                a            
                             
                             
                a            
|----Layer 9|
cdccdcccccccca               
|----Layer 10|
ccdccdcccccca                
|----Layer 11|
dccdccdcaaaa                 
|----Layer 12|
aaaaaaaa                     
}}
</td></tr></table><noinclude>
[[uk:Океанічний монумент/Структура/План крила з кімнатою]]
[[zh:海底神殿/结构/侧翼1]]
</noinclude>