<noinclude>{{structure info}}</noinclude>
{{layered blueprint|name=big_ruin_warm7|default=Layer 0|g=gravel|s=sand|S=cut sandstone|M=magma block|C=chiseled sandstone|D=Sandstone|c=chest|L=sea lantern|G=polished granite
|----Layer 1|
         s s    
  ss s ssssssss 
 sssssssssssggs
Msssssgssgssssss
ssssssssssssssss
sssssssssssssss
 gggssssssssss
 ssssssssMsssss
 ssgcsssgssssss
 sggssssssssssss
sgsssgssssssssss
 ssssssssgsssss
  ssgsggsgsssss 
 sgsssgggssssss
  sssgsgs ssss
    ss ss ss
|----Layer 2|
     
            s G
  Ss  S  S  sS
    s S  S s
             s
            s 
 sSS  D     SS
       
   ss   s
  SS        SS
 s   D
        s
    s Ss Ss
  Ss  SssSss S
     s s
         
|----Layer 3|
          
          
  S   S  S   S
      S  S
               
             
  SS        SS
        
            
  SS        SS
       
       
      S  S
  S   Ss Ss  S
            
             
|----Layer 4|
            
         
  G   C  C    
      S  S
               
             
  CS        SC
        
            
  CS        SC
       
       
      S  S
  G   C  C   G
        
          
|----Layer 5|
            
         
               
      S  S
               
             
   S        S
        
            
   S        S
       
       
      S  S
                
        
          
            
         
|----Layer 6|
            
         
               
           
      SSSS
     S    S    
    S      S
    S      S
    S      S
    S      S
          S
      SSSS
                
        
          
            
         
|----Layer 7|
            
         
               
           
          
      SSSS    
     S    S 
     S    S 
     S    S
     SL   S
      SSSS
       
      
                
        
          
            
         
|----Layer 8|
            
         
               
           
          
                
       SS 
      SS 
      SSS
       SS
           
       
      
                
        
          
            
         
}}<noinclude>
[[fr:Ruines sous-marines/Structure/Grande ruine chaude 7]]
[[zh:海底废墟/结构/big ruin warm7]]
</noinclude>