<noinclude>{{structure info}}</noinclude>
{{layered blueprint|name=ruin8_cracked|default=Layer 0|g=gravel|c=chest|S= Cracked Stone Bricks|P=Polished Granite|C=chiseled Stone Bricks|M=magma block|m=Mossy cobblestone|w=dark oak planks
|----Layer 1|
  gg
 gggg
ggwwgg
gwwggg
ggggMg
ggwgg
 ggg
|----Layer 2|
   
 SSS
S c S
S   S
gS S
 S S
 S S
|----Layer 3|
   
 S S
S   S
S   S
 S S
    
 S S
|----Layer 4|
   
 SSS
S   S
S   S
 S S
 S S
 SSS
|----Layer 5|
   
  
 SCS
 CCC
 CCC
 SCS
  C
|----Layer 6|
   
  
    
  C 
  C 
    

      
 




}}<noinclude>
[[fr:Ruines sous-marines/Structure/Ruine 8 craquelée]]
[[zh:海底废墟/结构/ruin8 cracked]]
</noinclude>