<noinclude>{{structure info}}</noinclude>
{{layered blueprint|name=ruin5_mossy|default=Layer 0|g=gravel|c=chest|S=Mossy Stone Bricks|P=Polished Granite|C=chiseled Stone Bricks
|----Layer 1|
    g
 gg gg
 gcgggg
 gggggg
 g gggg
 gggggg
  gggg
|----Layer 2|
         
 CSSSC  
 Sgg S
 Sg  S
 S   S
 CS SC 
|----Layer 3|
        
 CS SC
 Sg  S
            
 S   S
 CS SC
|----Layer 4|
        
 PSSSP
 S   S 
 S   S
 S   S
 PSSSP
|----Layer 5|
       
       
  PSP   
  SPS    
  PSP  
       
    

}}<noinclude>
[[fr:Ruines sous-marines/Structure/Ruine 5 moussue]]
[[zh:海底废墟/结构/ruin5 mossy]]
</noinclude>