<noinclude>{{structure info}}</noinclude>
{{layered blueprint|name=ruin5_brick|default=Layer 0|g=gravel|c=chest|S=Stone Bricks|P=Polished Granite|C=chiseled Stone Bricks
|----Layer 0|
    g
 gg gg
 gcgggg
 gggggg
 g gggg
 gggggg
  gggg
|----Layer 1|
         
 CSSSC  
 Sgg S
 Sg  S
 S   S
 CS SC 
|----Layer 2|
        
 CS SC
 Sg  S
             
 S   S
 CS SC
|----Layer 3|
        
 PSSSP
 S   S 
 S   S
 S   S
 PSSSP
|----Layer 4|
        
        
  PSP   
  SPS    
  PSP  
        


       
}}<noinclude>
[[fr:Ruines sous-marines/Structure/Ruine 5 pierre taillée]]
[[zh:海底废墟/结构/ruin5 brick]]
</noinclude>