<noinclude>{{structure info}}</noinclude>
{{layered blueprint|name=big_ruin_warm4|default=Layer 1|s=sand|c=chest|M=magma block|g=polished granite|S=cut sandstone|C=chiseled sandstone|d=sea lantern
|----Layer 1|
   s  s   s ss    
  sssssss ssssss 
 ssssssssssssssss
ssssssssMssssssss
ssssssssssMsssss 
 sssssssssssssss 
 sssssssssssssss 
sssscsssssssssss 
 sssssssssssssss 
 ssssssssssssssss
ssssssssssssssss 
 ssssMsssssssss  
sssssssssssssss 
 sssssssssssssss
 ssssss   ssssss
   ss       ss 
|----Layer 2|
                 
    s  ss  sg   
  S  S  s S  S   
         g     s  
              s   
                  
  SSSS    SSSS    
   SCS   sS S    
   SCS  s S S    
  SSSS    SSSS    
 g     s  ss    
       s  s  s    
      s     s     
  S  S    S  S    
              g  
                 
|----Layer 3|
                 
                 
  S  S    S  S    
                   
                 
                 
  SS S    S SS    
    C      C    
    C      C
  SS S    S SS
                
          s     
                
  S  S    S  S    
                 
                 
|----Layer 4|
                
                
  g  g           
                
  
               
  gS S    S Sg     
    C      C      
    C      C        
   S S    S Sg    
                  
                  
                  
  g  g    g       
 
|----Layer 5-6|
                 
                   
                 
                 
                 
               
   S S    S S
    C      C
    C      C   
   S S    S S
                      
                  
                
                     
                   
                   
|----Layer 7|
                   
               
               
            
          
             
   SSSS  SSSS
   SSdS  SdSS
   SSdS  SdSS
   SSSS  SSSS
|----Layer 8|
                
              
            
           
             
             
    SSSSSSSS
   gSSSSSSSSg
   gSSSSSSSSg
    SSSSSSSS
|----Layer 9|
         
         
       
         
           
           
      SSSS
     gSSSSg
     gSSSSg
      SSSS
|----Layer 10|
               
            
              
             
             
    
                      
       gg
       gg




}}<noinclude>
[[fr:Ruines sous-marines/Structure/Grande ruine chaude 4]]
[[zh:海底废墟/结构/big ruin warm4]]
</noinclude>