<noinclude>{{structure info}}</noinclude>
{{layered blueprint|name=ruin1_brick|default=Layer 0|g=gravel|c=chest|S=Stone Bricks|m=mossy cobblestone|s=sea lantern
|----Layer 1|
 ggggg
 ggggg
 ggggg
ggggmg
gggggg
ggmggg
ggggg
|----Layer 2|
 mSSS
 Sc  S
 m   S
 S   S
     S
 S  mS
mmSSS
|----Layer 3|
  S S
 S   S
   
 S   S
   
 S  sS
 mS S
|----Layer 4|
  SSS
 m
     S
 S   S
 S   S
 S  mS
  SSS
|----Layer 5|
   
   
   
   
    mm
   mm
  mm
|----Layer 6|
   
   
   
   
      
    m
    

}}<noinclude>
[[fr:Ruines sous-marines/Structure/Ruine 1 pierre taillée]]
[[zh:海底废墟/结构/ruin1 brick]]
</noinclude>