<noinclude>{{structure info}}</noinclude>
{{layered blueprint|name=ruin4_brick|default=Layer 0|w=dark oak planks|g=gravel|W=spruce planks|M=magma block|s=sand|c=chest|S=stone bricks
|----Layer 1|
gggggg
gwgwMg
gggwwg
gggssg
gWgWgg
gggsgg
 gggg
|----Layer 2|
 SSSS
S    S
S   cS
S SSSS
S    S
 S SS
|----Layer 3|
 SS S
S    S
     S
S SSSS
S    S
 S SS
|----Layer 4|
 SSSS
S    S
S    S
S SSSS
S    S
 SSSS
|----Layer 5|
   
 SSSS
 S  S
 SSSS
 SSSS
|----Layer 6|
     
   
  SS
  SS


}}<noinclude>
[[fr:Ruines sous-marines/Structure/Ruine 4 pierre taillée]]
[[zh:海底废墟/结构/ruin4 brick]]
</noinclude>