{{layered blueprint|name=ruin4_cracked|default=Layer 1|g=gravel|c=chest|S=Cracked Stone Bricks|s=sand|b=stone bricks|p=spruce planks
|----Layer 1|
gggggg
ggpsgsg
gggsgsg
ggggggg
ggggggg
gggggg
|----Layer 2|
 SSSS
S cS S
S  S S
S  S
S    S
 SSSS
|----Layer 3|
 SSSS
S  S S
S  S S
S  S
S    S
 S SS
|----Layer 4|
 SSSS
S  S S
S  S S
S  S S
S    S
 SSSS
|----Layer 5|
 
 SSSS
 S SS
 S bS
 SSSS
|----Layer 6|
 
 
  SS
  SS
}}<noinclude>
[[Category:Ocean Ruins structure subpages]]

[[zh:海底废墟/结构/ruin4 cracked]]
</noinclude>