<noinclude>{{structure info}}</noinclude>
<table><tr><td style="width:400px;">
{{layered blueprint|name=Penthouse|default=Layer 0
|p=Prismarine|b=Prismarine Bricks|d=Dark Prismarine|l=Sea Lantern
|----Layer -1|
pppppppppppppppp
 pppppppppppppp 
pppppppppppppppp
pppbbbbbbbbbbppp
pppbbbb  bbbbppp
pppbbbb  bbbbppp
pppbbbbbbbbbbppp
pppbbbbbbbbbbppp
 ppbbbbddbbbbppp
 ppbbbbddbbbbppp
pppbbbbbbbbbbppp
pppbbbbbbbbbbppp
pppbbbbbbbbbbppp
pppppppppppppppp
pppppppppppppppp
ppp  pppppp  ppp
|----Layer 0|
bbbbbbbbbbbbbbbb
bbblbblbblbblbbb
bb            bb
bl  b      b  lb
bb bdb    bdb bb
bb bdb    bdb bb
bl bbb    bbb lb
bb bdb    bdb bb
bb bdb    bdb bb
bl bbbb  bbbb lb
bb bbbbbbbbbb bb
bb  bbbddbbb  bb
bl   bbbbbb   lb
bb            bb
bbbbbbbbbbbbbbbb
bbbbbbbbbbbbbbbb
|----Layer 1|
                
 bbbbbbbbbbbbbb 
 b            b 
 b  b      b  b 
 b            b 
 b            b 
 b  b      b  b 
 b            b 
 b            b 
 b            b 
 b            b 
 b    b  b    b 
 b            b 
 b            b 
 bbbbbbbbbbbbbb 
                
|----Layer 2|
                
                
  bbbbbbbbbbbb  
  b b      b b  
  b          b  
  b          b  
  b b      b b  
  b          b  
  b          b  
  b          b  
  b          b  
  b   b  b   b  
  b          b  
  bbbbbbbbbbbb  
                
                
|----Layer 3|
                
                
                
   bbbbbbbbbb   
   bppppppppb   
   bppppppppb   
   bppppppppb   
   bppppppppb   
   bppppppppb   
   bppppppppb   
   bppppppppb   
   bppppppppb   
   bbbbbbbbbb   
                
                
                
}}
</td></tr></table><noinclude>
[[fr:Monument sous-marin/Structure/Penthouse]]
[[uk:Океанічний монумент/Структура/План пентхауса]]
[[zh:海底神殿/结构/顶层房间]]
</noinclude>