{{Missing information|portal blueprints}}
{{project|Structure Blueprints}}
{{structure info}}
Note: Some blocks may be added, replaced or removed during the actual generation, see [[Ruined Portal#Generation]] for more info.

To make the Nether version, replace [[iron bars]] with [[chain]]s and stone blocks with blackstone variants (normal stone with polished blackstone). {{Info needed}}

== Variants ==
=== Giant portal 1 ===
[[File:Overworld Giant portal 1.png|462x462px|right]]
{| class="wikitable"
|-
! Name !! Total !! Stack
|-
| {{BlockLink|Netherrack}}
| 263
| 4 + 7 blocks
|-
| {{BlockLink|Stone Bricks}}
| 63
| 
|-
| {{BlockLink|Stone Brick Slab}}
| 38
| 
|-
| {{BlockLink|Obsidian}}
| 31
|
|-
| {{BlockLink|Stone Brick Stairs}}
| 20
|
|-
| {{BlockLink|Iron Bars}}
| 18
|
|-
| {{BlockLink|Lava}}
| 11
|
|-
| {{BlockLink|Chiseled Stone Bricks}}
| 4
|
|-
| {{BlockLink|Block of Gold}}
| 2
|
|-
| {{BlockLink|Chest}}
| 1
|
|}

Stone Brick Slabs on layer 15 take the upper part of their block space.

Stone Brick Stairs on layer 16 face the second Block of Gold with their higher part.
<table><tr><td style="width:550px;">
{{layered blueprint|name=Giant Ruined Portal 1|default=Layer 1
|B=Stone Bricks|C=Chiseled Stone Bricks|c=Chest|G=Block of Gold|I=Iron Bars|L=Lava|N=Netherrack|O=Obsidian|S=Stone Brick Slab|s=Stone Brick Stairs
|----Layer 0|
 NNNNNNNNNNN    
NNNNNNNNNNNNN   
NNNNNNNNNNNNNNN 
NNNNNNNNNNNNNNNN
NNNNNNNNNNNNNNNN
NNNNNNNNNNNNNNNN
NNNNNNNNNNNNNNNN
NNNNNNNNNNNNNNNN
NNNNNNNNNNNNNNNN
 NNNNNNNNNNNNNN 
  NNNNNNNNNNNN  
|----Layer 1|
   NNNNNOS      
  NLNNNNNOSSO   
 NNNNNLNNNNSO   
 NNNNNNNNNNNNB 
 NNNNNNNNNNNNN 
 NNNNNNNNNNNNNN
 NNNNNNNNNNNNNN
  NNNNNNNNNNNNN
   NLNNLNNLLNN 
    NNNNNNNNN   

|----Layer 2|
               
    sssS O  O   
 O sBBBBS       
 OssLLLLBssss
  sBBBBLBBBBBS 
  SBBBBBBBBBBS
  SBBBBBBBBBBS
   SSsssssssSS
     SS SS  S 


|----Layer 3|
                
                
                
                
    SSS SSSS 
  BBOOOOOOOOBB
   cSSSSSSSS




|----Layer 4|
                
                
                
                
                
  BIO      OIB
                




|----Layer 5|
                
                
                
                
                
  B        OIB
                




|----Layer 6|
                
                
                
                
                
  B        OCB
                




|----Layer 7|
                
                
                
                
                
  BI       OIB
                




|----Layer 8|
                
                
                
                
                
  BIO      OIB
                




|----Layer 9|
                
                
                
                
                
  BCO      OC
                




|----Layer 10|
                
                
                
                
                
  BIO       IB
                




|----Layer 11|
                
                
                
                
                
   IO       IB
                




|----Layer 12|
                
                
                
                
                
  BBOOOO    C
                




|----Layer 13|
                
                
                
                
                
  BII III   I
                




|----Layer 14|
                
                
                
                
                
  sBBBIBB
                




|----Layer 15|
                
                
                
                
       SS       
     BBGG
       S        




|----Layer 16|
                
                
                
                
                
       s 
                




}}
</td></tr></table>

=== Giant portal 2 ===
{| class="wikitable"
|-
! Name !! Total !! Stack
|-
| {{BlockLink|Netherrack}}
| 237
| 3 + 45 blocks
|-
| {{BlockLink|Stone Bricks}}
| 55
| 
|-
| {{BlockLink|Stone Brick Slab}}
| 30
| 
|-
| {{BlockLink|Obsidian}}
| 29
|
|-
| {{BlockLink|Iron Bars}}
| 22
|
|-
| {{BlockLink|Lava}}
| 19
|
|-
| {{BlockLink|Chiseled Stone Bricks}}
| 6
|
|-
| {{BlockLink|Block of Gold}}
| 2
|
|-
| {{BlockLink|Chest}}
| 1
|
|}
=== Giant portal 3 ===
{| class="wikitable"
|-
! Name !! Total !! Stack
|-
| {{BlockLink|Netherrack}}
| 324
| 5 + 4 blocks
|-
| {{BlockLink|Stone Bricks}}
| 51
| 
|-
| {{BlockLink|Stone Brick Slab}}
| 40
| 
|-
| {{BlockLink|Lava}}
| 33
|
|-
| {{BlockLink|Obsidian}}
| 25
|
|-
| {{BlockLink|Iron Bars}}
| 22
|
|-
| {{BlockLink|Chiseled Stone Bricks}}
| 6
|
|-
| {{BlockLink|Block of Gold}}
| 6
|
|-
| {{BlockLink|Stone Brick Stairs}}
| 6
|
|-
| {{BlockLink|Chest}}
| 1
|
|}
=== Portal 1 ===
[[File:Overworld portal 1.png|462x462px|right]]
{| class="wikitable"
|-
! Name !! Total !! Stack
|-
| {{BlockLink|Netherrack}}
| 55
| 
|-
| {{BlockLink|Obsidian}}
| 11
|
|-
| {{BlockLink|Stone Slab}}
| 10
|
|-
| {{BlockLink|Stone Bricks}}
| 9
| 
|-
| {{BlockLink|Stone}}
| 7
|
|-
| {{BlockLink|Stone Brick Stairs}}
| 6
| 
|-
| {{BlockLink|Chiseled Stone Bricks}}
| 3
|
|-
| {{BlockLink|Block of Gold}}
| 2
|
|-
| {{BlockLink|Cracked Stone Bricks}}
| 1
|
|-
| {{BlockLink|Chest}}
| 1
|
|-
| {{BlockLink|Stone Brick Slab}}
| 1
|
|}

<table><tr><td style="width:550px;">
{{layered blueprint|name=Ruined Portal 1|default=Layer 1
|B=Stone Bricks|C=Chiseled Stone Bricks|c=Chest|G=Block of Gold|N=Netherrack|O=Obsidian|S=Stone Brick Slab|s=Stone Brick Stairs|$=Smooth Stone Slab|R=stone|r=Stone Slab|b=Cracked Stone Bricks 
|----Layer 0|
NNNNNN    
NNNNNN   
NNNNNN 
NNNNNN
NNNNNN
NNNNNN
|----Layer 1|
 NNNNN
rNNNNN
BN NbB
rRRRrr
rRRRRr
 rrrr 
|----Layer 2|
      
  NNNN
BOOOOB
cssss 
      
      
|----Layer 3|
      
   NN 
CO  OC
      
      
      
|----Layer 4|
      
    N 
BO   B
      
      
      
|----Layer 5|
      
      
CO    
      
      
      
|----Layer 6|
      
      
BOOO  
      
      
      
|----Layer 7|
      
      
BBGG  
  S   
      
      
|----Layer 8|
      
      
  ss  
      
      
      
}}
</td></tr></table>

=== Portal 2 ===
{| class="wikitable"
|-
! Name !! Total !! Stack
|-
| {{BlockLink|Netherrack}}
| 115
| 1 + 51 blocks
|-
| {{BlockLink|Lava}}
| 26
|
|-
| {{BlockLink|Stone Bricks}}
| 19
|
|-
| {{BlockLink|Stone Brick Slab}}
| 14
| 
|-
| {{BlockLink|Obsidian}}
| 11
| 
|-
| {{BlockLink|Smooth Stone Slab}}
| 10
|
|-
| {{BlockLink|Stone Brick Stairs}}
| 4
| 
|-
| {{BlockLink|Iron Bars}}
| 2
|
|-
| {{BlockLink|Block of Gold}}
| 2
|
|-
| {{BlockLink|Mossy Stone Bricks}}
| 1
|
|-
| {{BlockLink|Chest}}
| 1
|
|-
| {{BlockLink|Chiseled Stone Bricks}}
| 1
|
|}

<table><tr><td style="width:550px;">
{{layered blueprint|name=Ruined Portal 2|default=Layer 1
|B=Stone Bricks|C=Chiseled Stone Bricks|c=Chest|G=Block of Gold|N=Netherrack|O=Obsidian|s=Stone Brick Slab|S=Stone Brick Stairs|$=Smooth Stone Slab|L=Lava|I=Iron Bars|M=Mossy Stone Bricks
|----Layer 0|
NNNNNNNNN
NNNNNNNNN
NNNNNNNNN
NNNNNNNNN
NNNNNNNNN
NNNNNNNNN
NNNNNNNNN
NNNNNNNNN
NNNNNNNNN
|----Layer 1|
  NNNNN
NNNLGLNN 
NLLLLLLN 
NNLLLLLNN
NNLLLLLNN
 NNLLLOLN
NNNLLLNLN
 NNBBMNN 
 N$SS$N  
|----Layer 2|
      c  
     BBB 
         
B      B 
         
      O  
  $ss$   
  $ss$   
         
|----Layer 3|
         
         
         
B      B 
  $ss$   
  $ss$   
|----Layer 4|
         
         
         
B O    B 
|----Layer 5|
         
         
         
C O
|----Layer 6|
         
         
         
B O
|----Layer 7|
         
         
         
B O  O
|----Layer 8|
         
         
         
B OOOO
|----Layer 9|
         
         
         
B I  I
|----Layer 10|
         
         
         
BBBG B
  ssss
|----Layer 11|
         
         
         
  sSSs
}}
</td></tr></table>

=== Portal 3 ===
{| class="wikitable"
|-
! Name !! Total !! Stack
|-
| {{BlockLink|Netherrack}}
| 132
| 2 + 4 blocks
|-
| {{BlockLink|Stone Bricks}}
| 36
|
|-
| {{BlockLink|Stone Brick Slab}}
| 16
|
|-
| {{BlockLink|Obsidian}}
| 11
| 
|-
| {{BlockLink|Lava}}
| 2
|
|-
| {{BlockLink|Chest}}
| 1
|
|}

<table><tr><td style="width:550px;">
{{layered blueprint|name=Ruined Portal 3|default=Layer 1
|B=Stone Bricks|C=Chest|N=Netherrack|O=Obsidian|S=Stone Brick Slab|L=Lava 
|----Layer 0|
NNNNNNNNN
NNNNNNNNN
NNNNNNNNN
NNNNNNNNN
NNNNNNNNN
NNNNNNNNN
NNNNNNNNN
NNNNNNNNN
|----Layer 1|
 NNNNNN  
NNNNNNNN 
NNNNNNNNN
NNNNNNNLN
NNNNNNNNN
NLNNNNNNN
 NNNNNNNN
  NNNNBN 
|----Layer 2|
         
  OBBB   
SBBBBBBS 
SBBBBBB  
 BBBBBBB 
  BBBBBBS
   SBBBBS
     SBS 
|----Layer 3|
         
   O     
  SSSS   
SBOOOOBS  
  SSSSC
|----Layer 4|
         
         
         
     O
|----Layer 5|
         
         
         
     O
|----Layer 6|
         
        
         
     O
|----Layer 7|
         
         
         
    OO
}}
</td></tr></table>

=== Portal 4 ===
{| class="wikitable"
|-
! Name !! Total !! Stack
|-
| {{BlockLink|Netherrack}}
| 130
| 2 + 2 blocks
|-
| {{BlockLink|Stone Bricks}}
| 36
|
|-
| {{BlockLink|Stone Brick Slab}}
| 16
|
|-
| {{BlockLink|Obsidian}}
| 11
| 
|-
| {{BlockLink|Lava}}
| 3
|
|-
| {{BlockLink|Block of Gold}}
| 1
|
|-
| {{BlockLink|Chest}}
| 1
|
|}
=== Portal 5 ===
{| class="wikitable"
|-
! Name !! Total !! Stack
|-
| {{BlockLink|Netherrack}}
| 145
| 2 + 17 blocks
|-
| {{BlockLink|Stone Bricks}}
| 22
|
|-
| {{BlockLink|Obsidian}}
| 15
|
|-
| {{BlockLink|Stone Brick Slab}}
| 12
| 
|-
| {{BlockLink|Stone}}
| 6
|
|-
| {{BlockLink|Stone Slab}}
| 5
| 
|-
| {{BlockLink|Block of Gold}}
| 3
|
|-
| {{BlockLink|Mossy Stone Bricks}}
| 2
|
|-
| {{BlockLink|Chest}}
| 1
|
|-
| {{BlockLink|Cracked Stone Bricks}}
| 1
|
|-
| {{BlockLink|Lava}}
| 1
|
|-
| {{BlockLink|Stone Brick Stairs}}
| 1
|
|}
=== Portal 6 ===
{| class="wikitable"
|-
! Name !! Total !! Stack
|-
| {{BlockLink|Netherrack}}
| 41
| 
|-
| {{BlockLink|Obsidian}}
| 16
| 
|-
| {{BlockLink|Stone Brick Slab}}
| 4
|
|-
| {{BlockLink|Stone Brick Stairs}}
| 2
| 
|-
| {{BlockLink|Block of Gold}}
| 1
|
|-
| {{BlockLink|Chest}}
| 1
|
|}
=== Portal 7 ===
{| class="wikitable"
|-
! Name !! Total !! Stack
|-
| {{BlockLink|Netherrack}}
| 92
| 1 + 28 blocks
|-
| {{BlockLink|Lava}}
| 21
|
|-
| {{BlockLink|Obsidian}}
| 12
|
|-
| {{BlockLink|Stone Brick Slab}}
| 7
|
|-
| {{BlockLink|Block of Gold}}
| 2
|
|-
| {{BlockLink|Stone Bricks}}
| 1
|
|-
| {{BlockLink|Chest}}
| 1
|
|-
| {{BlockLink|Stone Brick Stairs}}
| 1
|
|}
=== Portal 8 ===
{| class="wikitable"
|-
! Name !! Total !! Stack
|-
| {{BlockLink|Netherrack}}
| 144
| 2 + 16 blocks
|-
| {{BlockLink|Lava}}
| 26
|
|-
| {{BlockLink|Obsidian}}
| 17
| 
|-
| {{BlockLink|Stone Bricks}}
| 14
|
|-
| {{BlockLink|Stone Brick Stairs}}
| 6
| 
|-
| {{BlockLink|Stone Brick Wall}}
| 4
|
|-
| {{BlockLink|Block of Gold}}
| 3
|
|-
| {{BlockLink|Chiseled Stone Bricks}}
| 2
|
|-
| {{BlockLink|Chest}}
| 1
|
|-
| {{BlockLink|Stone Brick Slab}}
| 1
|
|}
=== Portal 9 ===
{| class="wikitable"
|-
! Name !! Total !! Stack
|-
| {{BlockLink|Netherrack}}
| 63
| 
|-
| {{BlockLink|Obsidian}}
| 12
| 
|-
| {{BlockLink|Stone Brick Stairs}}
| 11
|
|-
| {{BlockLink|Block of Gold}}
| 2
|
|-
| {{BlockLink|Magma Block}}
| 1
|
|-
| {{BlockLink|Chest}}
| 1
|
|-
| {{BlockLink|Stone Brick Slab}}
| 1
|
|}
=== Portal 10 ===
{| class="wikitable"
|-
! Name !! Total !! Stack
|-
| {{BlockLink|Netherrack}}
| 123
| 1 + 59 blocks
|-
| {{BlockLink|Lava}}
| 19
|
|-
| {{BlockLink|Obsidian}}
| 13
| 
|-
| {{BlockLink|Stone Bricks}}
| 13
|
|-
| {{BlockLink|Chiseled Stone Bricks}}
| 3
|
|-
| {{BlockLink|Iron Bars}}
| 3
|
|-
| {{BlockLink|Stone Brick Stairs}}
| 3
|

|-
| {{BlockLink|Block of Gold}}
| 2
|
|-
| {{BlockLink|Chest}}
| 1
|
|}

[[Category:Structure Blueprints]]

[[pt:Portal em ruínas/Estrutura]]
[[zh:废弃传送门/结构]]