The structure is called "with_mast." The chests have random loot.

{{layered blueprint|name=Shipwreck With Mast|default=Layer 1|S=Spruce Planks|O=Oak Planks|T=Spruce Trapdoor|F=Oak Fence|M=Spruce Log|o=Oak Stairs|s=Spruce Stairs|C=chest|L=Oak Slab|l=Spruce Slab|d=Spruce Door+bottom|D=Spruce Door+top|f=Spruce Fence
|----Layer 1|
 
    O    
    O
 
 
 
    o
    O
    O
    O
    O
    O
    O
    O
    O
    O
    O
    O
    O
    o
|----Layer 2|
 
    O
    O
    o
   sOs
   sOs
   sSs
  sOSOs
  sOOOs
  sOOOs
  sOOOs
  sOSOs
  sOOOs
  sOOOs
  sOOOs
  sOOOs
  sOSOs
  sOOOs
  sOOOs
   sSs
    O
    o
|----Layer 3|
 
    O
    F
  lsOsl
  sSSSs
  sSSSs
  sSSSs
 sSSSSSs
 sSsssSs
 ssC  ss
 sS   Ss
 sSSMdSs
 ss   ss
 sS   Ss
 sS   Ss
 ss   ss
 sS M Ss
 sS   Ss
 sS C Ss
  sSSSs
   sSs
    O
    o
|----Layer 4|
 
 
  ssFss
 sOOOOOs
 sOOOOOs
 sOOOOOs
 sOOOOOs
 SSOOOSS
 SSsssSS
 
 SS   SS
 SSSMDSS
 
 SS   SS
 SS   SS
 
 SS M SS
 SS   SS
 SS   SS
 sSsssSs
  sSSSs
   sSs
   sSs
    o
|----Layer 5|
 
    s
  SSSSS
 SC    S
 S sls S
 S     S
 S     S
sSs   sSs
sSSSLSSSs
sOLLLLLOs
sOLLLLLOs
sLLLMLLLs
sLLTTTLLs
sLLT TLLs
sLLT TLLs
sLLTTTLLs
sLLLMLLLs
sLLTTTLLs
sLLTTTLLs
 SSOOOSS
 sSSMSSs
  sSSSs
  sSSSs
   sOs
    o
|----Layer 6|
 
   sSs
 sSSSSSs
 S     S
sS     Ss
ss     ss
sS     Ss
SS     SS
SSSS SSSS
So     oS
F       F
F   M   F
F       F
 
F       F
F       F
F   M   F
S       S
S       S
sS     Ss
 SSoMoSS
 sOOOOOs
  SOOOS
   SSS
   sOs
|----Layer 7|
 
  sS Ss
 Sf   fS
 S     S
Sf     fS
 
Sf     fS
SOLLLLLOS
SoSS SSLS
s       s
 
    M
 
 
 
 
    M
 
s       s
Ss     sS
 S  M  S
 S     S
  S   S
   SoS
   sOs
   FoF
|----Layer 8|
   sSs
  SSLSS
 SOOLOOS
 SLLLLLS
SOLLLLLOS
SoLLLLLoS
SOoOOOoOS
s   s   s
  FFlFF
 
 
    M
 
 
 
        
    M
 
 
 
    M
 
 
   F F
   FoF
   FOF
    o
|----Layer 9|
   FFF
  SF FS
 S     S
 F     F
sF     Fs
s       s
sS SSS Ss
 
 
 
 
    M
 
 
       
     
    M
 
 
 
    M
 
    
    


    o
    o
|----Layer 10|
 
 
 
 
 
 
 
 
 
 
 
    M
 
 
 
 
    M
 
 
 
    M
|----Layer 11|
 
 
 
 
 
 
 
 
 
 
 
    M
 
 
 
 
    M
 
 
 
    M
  MMMMMM
|----Layers 12–14|
 
 
 
 
 
 
 
 
 
 
 
    M
 
 
 
 
    M
 
 
 
    M
|----Layer 15|
 
 
 
 
 
 
 
 
 
 
 
    M
 MMMMMMM
 
 
 
    M
 
 
 
    M
 MMMMM  
|----Layers 16–18|
 
 
 
 
 
 
 
 
 
 
 
    M
 
 
 
 
    M
 
 
 
    M
|----Layer 19-21|
 
 
 
 
 
 
 
 
 
 
 
 
 
 
 
 
    M
}}
<div style="margin-left: 6rem;">[[File:Shipwreck Oak (With Mast).png|400px|right]]</div>

[[Category:Shipwreck structure subpages]]

[[fr:Épave de navire/Structure/With mast]]