The structure is called "upsidedown_backhalf_degraded."

{{layered blueprint|name=Upside Down Back Half Degraded|default=Layer 1|f=spruce fence|P=jungle planks|R=jungle stairs-rot180|r=jungle stairs-rot90|S=jungle stairs|p=spruce planks|Q=spruce stairs-rot180|A=jungle slab|F=jungle fence|C=chest|a=spruce slab|q=jungle stairs-rot270|L=jungle log+top|T=jungle trapdoor|W=spruce stairs-rot270|w=chest-rot90
|----Layer 1|
   fff   
  Pf fP  
 P     P 
 f     f
Rf     fr
R       r
RP PPP Pr
         
         
         
         
         
         
         
         
         
|----Layer 2|
   SPS   
  PPpPP  
 PpppppP 
 PpppppP 
PppppppPP
PpppppppP
PPQPPPQPP
R  ASA  R
         
         
         
         
         
         
         
         
|----Layer 3|
         
  SP PS  
 PF   FP 
 P    CP 
PP     PP
         
PPaaaaaPP
Pppa aqPP
PQPP PPQP
R       R
         
         
         
         
         
         
|----Layer 4|
         
   SPS   
 SPRRRPS 
 P     P 
SP     PS
qr     RS
qP     PS
PP     PP
PPPP PPPP
PQ     QP
    L         
         
         
         
         
|----Layer 5|
         
    S    
  SPPPS  
 q     S 
 q     S 
 P     P 
 P     P 
qPr   RPS
qPPPAPPPS
qPppQppPS
qpppppppS
qpppLpppS
qppTTTW  
qppT     
qp       
         
|----Layer 6|
         
         
   SfS    
  SPpPS  
  PPPPP  
 qPPPPPS 
 qPPPPPS 
 PPPPPPP 
 PP   PP 
         
 PP  wPP 
 PP LPPP 
         
 P       
         
         
|----Layer 7|
         
         
         
   SpS   
  SPPPS  
  qPPPS  
  qPPPS  
 qPPP  S 
 qP    S 
 qr   RS 
 qP   PS 
 qP LPPS 
 qr   RS 
 qP   P  
         
         
|----Layer 8|
        
        
         
        
        
        
   q    
  qP    
  qP     
  qPPP   
  qPPPP  
  qPPPPS
  qPPPPS
  q PP
  q  P
  q
|----Layer 9|
         
         
         
         
         
         
         
         
         
         
    p
    p
    p
    p
    p
}}

[[Category:Shipwreck structure subpages]]

[[fr:Épave de navire/Structure/Upside down back half degraded]]