The structure is called "rightsideup_backhalf_degraded."

{{layered blueprint|name=Right-side-up back half degraded|default=Layer 1|P=jungle planks|p=spruce planks|S=jungle stairs|s=spruce stairs|F=jungle fence|f=spruce fence|c=chest|L=jungle log|D=jungle door+top|d=jungle door+bottom|H=jungle slab|h=spruce slab|T=jungle trapdoor
|----Layer 1|
 
    P    
    P
 
 
 
    s
    p
    p
    p
    p
    p
    p
    p
    p
    p
|----Layer 2|
 
    P    
    P
    s
   SpS
   SpS
   SpS
   SPS
  SPPPS
  SPPPS
  SPPPS
  SPPPS
  SPPPS
  SPPPS
  SPP S
  S   S
|----Layer 3|
 
    P    
    f
  SSpSS
  SPPPS
  SPPPS
  SPPPS
 SPPPPPS
 SP   PS
 SSc  SS
 SP   PS
 SPPLdPS
 SS   SS
 SP   PS
  P
 
|----Layer 4|
 
 
  SSfSS
 SpppppS
 SpppppS
 SpppppS
 SpppppS
 PPpppPP
 PPSSSPP
 
 PP   PP
 PPPLDPP
|----Layer 5|
 
    S    
  PPPPP
 Pc    P
 P SHS P
 P     P
 P     P
SPS   SPS
SPPPhPPPS
SPppsppPS
Sppppp pS
Spp Lp
 p  TT
|----Layer 6|
 
   SPS   
 SPSSSPS
 P     P
SP     PS
SS     SS
SP     PS
PP     PP
PPPP PPPP
Ps     sP
f       f
f   L
|----Layer 7|
 
  SP P   
 PF   FP
 P     P
PF     FP
 
PF hhh FP
Pphhhhh P
PsPP PP P
S       S
|----Layer 8|
   SpS   
   PpPP
   ssspP
 PhhhhhP
PphhhhhpP
Ppppp hpP
PPsPP   P
S   S
    H
|----Layer 9|
   fff   
   f fP
       P
 f     f
Sf     fS
S       S
SP      S
}}

[[Category:Shipwreck structure subpages]]

[[fr:Épave de navire/Structure/Right side up back half degraded]]