The structure is called "with_mast_degraded." The chests have random loot.

{{layered blueprint|name=Shipwreck With Mast Degraded|default=Layer 1|S=Spruce Planks|O=Oak Planks|s=Spruce Stairs|o=Oak Stairs|L=Oak Slab|l=Spruce Slab|F=Oak Fence|f=Spruce Fence|T=Oak Trapdoor|C=Chest|M=Oak Log|d=Oak Door+Bottom|D=Oak Door+Top
|----Layer 1|
 
    
    
 
 
 
    s
    S
    S
    S
    S
    S
    S
    S
    S
    S
    S
    S
    S
    s
|----Layer 2|
 
    
     
    s
   oSo
   oSo
   oOo
  oSOSo
  oSSSo
  oSSSo
  oSSSo
  oSOSo
  oSSSo
  oSSSo
  oSSSo
  oSSSo
  oSOSo
  oSSSo
  oSSSo
   oOo
    S
    s
|----Layer 3|
 
    S
    f
  LoSoL
  oOOOo
  oOOOo
  oOOOo
 oOOOOOo
 oOoooOo
 oo  Coo
 oO   Oo
 oOdMOOo
 oo   oo
 oO   Oo
 oO   Oo
 oo   oo
 oO M Oo
 oO   Oo
 oO C Oo
  oOOOo
   oOo
    S
    s
|----Layer 4|
 
 
  oofoo
 oSSSSSo
 oSSSSSo
 oSSSSSo
 oSSSSSo
 OOSSSOO
 OOoooOO
 
 OO   OO
 OODMOOO
 
 OO   OO
 OO   OO
 
    M OO
 OO   OO
 OO   OO
 oOoooOo
  oOOOo
   oOo
   oOo
    s
|----Layer 5|
 
    s
  OOOOO
 OC    O
 O oLo O
 O     O
 O     O
oOo   oOo
oOOOlOOOo
oSlllllSo
oSlllllSo
olllMlllo
 llTTTllo
  lT Tllo
  lT Tllo
o  TTTllo
olllMl
ollTTTl
ollTTTllo
 OOSSSOO
 oOOMOOo
  oOOOo
  oOOOo
   oSo
    s
|----Layer 6|
 
   oOo
 oOoooOo
 O     O
oO     Oo
oo     oo
oO     Oo
OO     OO
OOOO OOOO
Os     sO
f       f
    M   f
        f
 
        f
f
f   M
O
O
oO     Oo
 OOSMSOO
 osSSSso
  OSSSO
   OOO
   oSo
|----Layer 7|
 
  oO Oo
 OF   FO
 O     O
OF     FO
 
OF     FO
OSlllllSO
OlOO OOs
s
 
    M
 
 
 
 
    M
 
o
Oo     o
 O  M  O
 O     O
  O   O
   O O
   oSo
   fsf
|----Layer 8|
   oOo
  OOlOO
 OSSlSSO
 OlllllO
OSlllllSO
OslllllsO
OSsSSSs
o   o
  ffLff
 
 
    M
 
 
 
 
    M
 
 
 
    M
 
 
     f
    sf
   fSf
    s
|----Layer 9|
   fff
  Of fO
 O     O
 f     f
of     fo
o
oO OOO
 
 
 
 
    M
 
 
 
 
    M
 
 
 
    M
 
 
 
 
 
    s
    s
|----Layer 10|
 
 
 
 
 
 
 
 
 
 
 
 
 
 
 
 
    M
 
 
 
    M
|----Layers 11–13|
 
 
 
 
 
 
 
 
 
 
 
 
 
 
 
 
    M
}}

[[Category:Shipwreck structure subpages]]

[[fr:Épave de navire/Structure/With mast degraded]]