The structure is called "rightsideup_backhalf."

{{layered blueprint|name=Right-side-up back half|default=Layer 1|L=oak log|P=oak planks|p=spruce planks|S=oak stairs|s=spruce stairs|B=oak slab|b=spruce slab|D=oak door+top|d=oak door+bottom|T=oak trapdoor|F=oak fence|f=spruce fence|C=chest
|----Layer 1|
 
    P
    P
 
 
 
    s
    p
    p
    p
    p
    p
    p
    p
    p
    p
|----Layer 2|
 
    P
    P
    s
   SpS
   SpS
   SPS
  SPPPS
  SPPPS
  SPPPS
  SPPPS
  SPPPS
  SPPPS
  SPPPS
  S PPS
  S  PS
|----Layer 3|
 
    P
    f
  SSpSS
  SPPPS
  SPPPS
  SPPPS
 SPPPPPS
 SP   PS
 SSC  SS
 SP   PS
 SPPLdPS
 SS   SS
 SP   PS
  P   P
 
|----Layer 4|
 
 
  SSfSS
 SpppppS
 SpppppS
 SpppppS
 SpppppS
 PPpppPP
 PPSSSPP
 
 PP   PP
 PPPLDPP
 
      P
 
 
|----Layer 5|
 
    S
  PPPPP
 PC    P
 P SBS P
 P     P
 P     P
SPS   SPS
SPPPsPPPS
SpppppppS
Spp LpppS
 p  TTpp
     Tp
 
 
|----Layer 6|
 
   SPS
 SPPPPPS
 P     P
SP     PS
SS     SS
SP     PS
PP     PP
PPPP PPPP
Ps     sP
f       f
f   L   f
 
 
 
 
|----Layer 7|
 
  SP PS
 PF   FP
 P     P
PF     FP
 
PF bbb FP
PpbbbbbpP
PsPP PPsP
S       S
 
 
 
 
 
 
|----Layer 8|
   SPS
  PPpPP
 PpssspP
 PbbbbbP
PpbbbbbpP
PpppppbpP
PPsPPPsPP
S   S   S
    B
S       S
 
 
 
 
 
 
|----Layer 9|
   fff
  Pf fP
 P     P
 f     f
Sf     fS
S       S
SP PPP PS
 
 
 
 
 
 
 
 
 
}}

[[Category:Shipwreck structure subpages]]

[[fr:Épave de navire/Structure/Right side up back half]]