The structure is called {{Code|rightsideup_fronthalf_degraded}}.

{{layered blueprint|name=Right-side-up front half degraded|default=Layer 1|W=oak planks|b=birch planks|S=oak stairs|s=birch stairs|f=birch fence|l=oak log|c=chest|t=oak door+bottom|T=oak door+top|O=oak trapdoor
|----Layer 1|
   
   
    s
    b
    b
    b 
    b
    b
    b
    b
    b
    b
    b
    b
    b
    s
|----Layer 2|
   S
   SW
   S W
  SW WS
  SWW S
  SW WS
  SWWWS
  SWWWS
  SWWWS
  SWWWS
  SWWWS
  SWWWS
  SWWWS
  SWWWS
  SWWWS
   SWS
    b
    s
|----Layer 3|
   
   
   
 SWW 
 SW   W
 SS   SS
 SW   WS
 SWWltWS
 SS   SS
 SW   WS
 SW   WS
 SS   SS
 SW l WS
 SW   WS
 SW   WS
  SWcWS
   SWS
    b
    s
|----Layer 4|
   
    
   
   
 W  
  
 W    WW
 WWWlTWW
  
 WW   WW
 WW   WW
   
 WW l WW
 WW   WW
 WW   WW
 SW   WS
  SWWWS
   SWS
   SWS
    b
|----Layer 5|
  
  
  
  
  
S
S
Sb b   bS
SbsO   bS
SbbO   bS
SbbO ObbS 
SbsOOOsbS
SbbblbbbS
SbbO ObbS
SbbO ObbS
 WbbbbbW
 SWWlWWS
  SW WS
  S  WS
     S
|----Layer 6|
  
  
  
  
  
  
f
f
f       f
  
f       f
f       f
f   l   f
W       W
W       W
SW
 W s
 S     S
      W
|----Layer 7|
  
  
  
  
  
  
  
  
  
  
  
  
  
  
S
WS
 W


}}

[[Category:Shipwreck structure subpages]]

[[fr:Épave de navire/Structure/Right side up front half degraded]]