The structure is called "rightsideup_full_degraded."

{{layered blueprint|name=Right-side-up degraded|default=Layer 1|S=Spruce planks|J=Jungle planks|M=Spruce log|T=Spruce trapdoor|s=spruce stairs|j=jungle stairs|L=spruce slab|l=jungle slab|F=spruce fence|f=jungle fence|C=Chest|D=spruce door+bottom|d=spruce door+top
|----Layer 1|
 
    S
    S
 
 
 
    j
    J
    J
    J
    J
    J
    J
    J
    J
    J
    J
    J
    J
    j
|----Layer 2|
 
    S
    S
    j
   sJs
   sJs
   sSs
  sSSSs
  sSSSs
  sSSSs
  sSSSs
  sSSSs
  sSSSs
  sSSSs
  sSSSs
  sSSSs
  sSSSs
  sSSSs
  sSSSs
  sSSSs
   sSs
    J
    j
|----Layer 3|
 
    S
    f
  ssJss
  sSSSs
  sSSSs
  sSSSs
 sSSSSSs
 sS   Ss
 ssC  ss
 sS   Ss
 sSSMDSs
 ss   ss
 sS
 sS    s
 ss   ss
 sS M Ss
 sS   Ss
 sS   Ss
  sSCSs
   sSs
    J
    j
|----Layer 4|
 
 
  ssfss
 sJJJJJs
 sJJJJJs
 sJJJJJs
 sJJJJJs
 SSJJJSS
 SSsssSS
 
 SS   SS
 SSSMdSS
 
 SS
 
 
 S  M SS
 SS   SS
 SS   SS
 sS   Ss
  sSSSs
   sSs
   sSs
    j
|----Layer 5|
 
    s
  SSSSS
 SC    S
 S sLs S
 S     S
 S     S
sSs   sSs
sSSSlSSSs
sSJJjJJSs
sJJJJJJJs
sJ JMJJJs
sJ TTTjJs
 

   TT
s  JMJJJs
s  T TJJs
sJJT TJJs
 SJJJJJS
 sSSMSSs
  sSSSs
  sSSSs
   sJs
    j
|----Layer 6|
 
   sSs
 sSsssSs
 S     S
sS     Ss
ss     ss
sS     Ss
SS     SS
SSSS SSSS
Sj     jS
f       f
f   M   f
f       f
 
 
 
f   M   f
S       S
S       S
sS     Ss
 SJjMjJS
 sJJJJJs
  SJJJS
   SSS
   sJs
|----Layer 7|
 
  sS Ss
 SF   FS
 S     S
SF     FS
 
SF lll FS
SJlllllJS
SjSS SSjS
s       s
 
 
 
 
 
 
 
 
s       s
Ss     sS
 S     S
 S     S
  S   S
   SjS
   sJs
   fjf
|----Layer 8|
   sSs
  SSlSS
 SlllllS
 SlllllS
SlllllllS
SllSSSllS
SSjSSSjSS
s   s   s
    L
 
 
 
 
 
 
 
 
 
 
 
 
 
 
   f f
   fjf
   fJf
    j
|----Layer 9|
   fff
  Sf fS
 S     S
 f     f
sf     fs
s       s
sS SSS Ss
 
 
 
 
 
 
 
 
 
 
 
 
 
 
 
 
 
 
 
    j
    j
}}

[[Category:Shipwreck structure subpages]]

[[fr:Épave de navire/Structure/Right side up degraded]]