The structure is called "sideways_full_degraded."

{{layered blueprint|name=Sideways degraded|default=Layer 1
|S=Spruce planks|D=Dark oak planks|s=spruce stairs|d=dark oak stairs|M=Dark oak log|T=Dark oak trapdoor|F=Spruce fence|f=dark oak fence|C=Chest
|----Layer 1|
 
 
 
 
     dDDd
     d Dd
     dDDd
    dDDd
    dDD
    dDd
    dF
    dF
    dF
    d
    dF
    dF
    dF
    dD
    dDd
     dD
|----Layer 2|
 
 
     dDD
   dDDDDF
   dDDfSF
   dDd S
   dDDfDD
  dDDDS
  dDDSs
  d Ss
  dDS
  dDS
  d S
  dDS
  dDS
  d S
  dDS
  dDS
  dDS
   dDDd
    dDD
     dD
|----Layer 3|
 
      dDD
   ddDfS
  dSdC S
  dS   S
  dS   S
  dS   S
 dDDd S
 dDDSDD
 dd S
 dDDS
 dDDS
 dd s
 dDDS
 dDDS
 dd s
 dDDS
 dDDS
 dDDS
  dDS
   dDS
    dS
    dDD
|----Layer 4|
       dF
     dDSF
   DDd S
  DS   S
 dDS   S
 dDS   S
 dDS   SD
 DSS  S
 DC SD
 D  S
 D  S
 D  S
 D  T
 D  T
 D  T
 D  T
 D  S
 D  T
 D  T
 dDCS
  dDSs
   dDS
   dDS
    dDDF
     ddF
      FF
|----Layer 5|
       SF
    dD S
   FD  S
  SS   S
 SDS   S
 SDS   S
sSDS   SD
SDSS
SD  S
SD  S
SD  S
SDMMMM
 D  T
 
SD
SD  T
SDMMMM
SD
SD
sSD S
 SDDMM
 sSDDS
  sSDS
   sSSs
    sSSs
      sS
       ss
        s
|----Layer 6|
       sF
     dDSF
   DDd S
  DS   S
 dDS   S
 dDS   S
 dDS   SD
 DSS  S
 D  SD
 D  S
 D  S
  DDS
 
 
 
 D  T
 D  S
 D  T
 D  T
 dD S
  dDSs
   dDS
   dDS
    dDDF
     ddF
      FF
|----Layer 7|
 
      dDD
   ddDfS
  dSd  S
  dS   S
  dS   S
  dS   S
 dDDd S
 dDDSDD
 dd S
  D S
 
 
 
    S
  d s
 dDDS
 dDDS
 dDDS
  dDS
   dDS
    dS
    dDD
|----Layer 8|
 
 
     dDDD
   dDDDDF
   dDDfSF
   dDd S
   dDDfDD
  dDDDS
  dDDSs
  d Ss
 
 
 
 
 
    S
  dDS
  dDS
  dDS
   dDDd
    dDD
     dD
|----Layer 9|
 
 
 
 
     dDDd
     d Dd
     dDDd
    dDDd
     DD
 
 
 
 
 
 
 
    d
    dD
    dDd
     dD
}}

[[Category:Shipwreck structure subpages]]

[[fr:Épave de navire/Structure/Sideways degraded]]