The structure is called "rightsideup_fronthalf."

{{layered blueprint|name=Right-side-up front half|default=Layer 1|L=oak log|P=oak planks|p=spruce planks|S=oak stairs|s=spruce stairs|B=oak slab|b=spruce slab|D=oak door+top|d=oak door+bottom|T=oak trapdoor|F=oak fence|f=spruce fence|C=chest
|----Layer 1|
 
 
    s
    p
    p
    p
    p
    p
    p
    p
    p
    p
    p
    p
    p
    p
    s
 
 
 
 
 
 
 
 
|----Layer 2|
   S
   SP
   S S
  SP PS
  SPP S
  SP PS
  SPPPS
  SPPPS
  SPPPS
  SPPPS
  SPPPS
  SPPPS
  SPPPS
  SPPPS
  SPPPS
   SPS
    p
    s
 
 
 
 
 
 
|----Layer 3|
 
 
 
 SPP
 SP   P
 SS   SS
 SP   PS
 SPPLdPS
 SS   SS
 SP   PS
 SP   PS
 SS   SS
 SP L PS
 SP   PS
 SP   PS
  SPCPS
   SPS
    p
    s
 
 
 
 
 
|----Layer 4|
 
 
 
 
 P
 
 P    PP
 PPPLDPP
 
 PP   PP
 PP   PP
 
 PP L PP
 PP   PP
 PP   PP
 SP   PS
  SPPPS
   SPS
   SPS
    s
 
 
 
 
|----Layer 5|
 
 
 
 
 
S
S
Sp p   pS
SpsT   pS
SppT   pS
SppT TppS
SpsTTTspS
SpppLpppS
SppT TppS
SppT Tpps
 PpssspP
 SPPLPPS
  SPPPS
  SPPPS
   SpS
    s
 
 
 
|----Layer 6|
 
 
 
 
 
 
f
f
f       f
 
f       f
f       f
f   L   f
P       P
P       P
SP     PS
 PpsLspP
 SpppppS
  PpppP
   PPP
   SpS
 
 
 
|----Layer 7|
 
 
 
 
 
 
 
 
 
 
 
 
 
 
S       S
PS     SP
 P     P
 P     P
  P   P
   PsP
   SpS
   fSf
 
 
|----Layer 8|
 
 
 
 
 
 
 
 
 
 
 
 
 
 
 
 
 
 
 
   f f
   fsf
   fpf
    s
 
|----Layer 9|
 
 
 
 
 
 
 
 
 
 
 
 
 
 
 
 
 
 
 
 
 
 
    s
    s
}}

[[Category:Shipwreck structure subpages]]

[[fr:Épave de navire/Structure/Right side up front half]]