The structure is called "rightsideup_full."

{{layered blueprint|name=Right-side-up|default=Layer 1|O=dark oak planks|J=jungle planks|o=dark oak stairs|j=jungle stairs|S=dark oak slab|s=jungle slab|F=dark oak fence|f=jungle fence|M=dark oak log|T=dark oak trapdoor|C=chest|D=dark oak door+bottom|d=dark oak door+top
|----Layer 1|
 
    O
    O
 
 
 
    j
    J
    J
    J
    J
    J
    J
    J
    J
    J
    J
    J
    J
    j
|----Layer 2|
 
    O
    O
    j
   oJo
   oJo
   oOo
  oOOOo
  oOOOo
  oOOOo
  oOOOo
  oOOOo
  oOOOo
  oOOOo
  oOOOo
  oOOOo
  oOOOo
  oOOOo
  oOOOo
   oOo
    J
    j
|----Layer 3|
 
    O
    f
  ooJoo
  oOOOo
  oOOOo
  oOOOo
 oOOOOOo
 oO   Oo
 ooC  oo
 oO   Oo
 oOOMDOo
 oo   oo
 oO   Oo
 oO   Oo
 oo   oo
 oO M Oo
 oO   Oo
 oO   Oo
  oOCOo
   oOo
    J
    j
|----Layer 4|
 
 
  oofoo
 oJJJJJo
 oJJJJJo
 oJJJJJo
 oJJJJJo
 OOJJJOO
 OOOOOOO
 
 OO   OO
 OOOMdOO
 
 OO   OO
 OO   OO
 
 OO M OO
 OO   OO
 OO   OO
 oO   Oo
  oOOOo
   oOo
   oOo
    j
|----Layer 5|
 
    o
  OOOOO
 OC    O
 O oSo O
 O     O
 O     O
oOo   oOo
oOOOsOOOo
oOJJjJJOo
oJJJJJJJo
oJJJMJJJo
oJjTTTjJo
oJJT TJJo
oJJT TJJo
oJjTTTjJo
oJJJMJJJo
oJJT TJJo
oJJT TJJo
 OJJJJJO
 oOOMOOo
  oOOOo
  oOOOo
   oJo
    j
|----Layer 6|
        
   oOo
 oOoooOo
 O     O
oO     Oo
oo     oo
oO     Oo
OO     OO
OOOO OOOO
Oj     jO
f       f
f   M   f
f       f
 
f       f
f       f
f   M   f
O       O
O       O
oO     Oo
 OJjMjJO
 oJJJJJo
  OJJJO
   OOO
   oJo
|----Layer 7|
 
  oO Oo
 OF   FO
 O     O
OF     FO
 
OF sss FO
OJsssssJO
OjOO OOjO
o       o
 
 
 
 
 
 
 
 
o       o
Oo     oO
 O     O
 O     O
  O   O
   OjO
   oJo
   fjf
|----Layer 8|
   oOo
  OOsOO
 OsssssO
 OsssssO
OsssssssO
OssOOOssO
OOjOOOjOO
o   o   o
    S
 
 
 
 
 
 
 
 
 
 
 
 
 
 
   f f
   fjf
   fJf
    j
|----Layer 9|
   fff
  Of fO
 O     O
 f     f
of     fo
o       o
oO OOO Oo
 
 
 
 
 
 
 
 
 
 
 
 
 
 
 
 
 
 
 
    j
    j
}}
[[Category:Structure Blueprints]]

[[fr:Épave de navire/Structure/Right side up]]