The structure is called "upsidedown_full."

{{layered blueprint|name=Upside Down|default=Layer 1|O=spruce planks|J=jungle planks|o=spruce stairs|j=jungle stairs|S=spruce slab|s=jungle slab|F=dark oak fence|f=jungle fence|M=spruce log|T=spruce trapdoor|C=chest
|----Layer 1|
   fff
  Of fO
 O     O
 f     f
of     fo
o       o
oO OOO Oo
 
 
 
 
 
 
 
 
 
 
 
 
 
 
 
 
 
 
 
    j
    j
|----Layer 2|
   oOo
  OOJOO
 OJJJJJO
 OJJJJJO
OJJJJJJJO
OJJJJJJJO
OOjOOOjOO
o  SoS  o
 
 
 
 
 
 
 
 
 
 
 
 
 
 
   f f
   fjf
   fJf
    j
|----Layer 3|
 
  oO Oo
 OF   FO
 O    CO
OF     FO
 
OOsssssOO
OJJs sJJO
OjOO OOjO
o       o
 
 
 
 
 
 
 
 
o       o
Oo     oO
 O     O
 O     O
  O   O
   OjO
   oJo
   fjf
|----Layer 4|
 
   oOo
 oOoooOo
 O     O
oO     Oo
oo     oo
oO     Oo
OO     OO
OOOO OOOO
Oj     jO
f       f
f   M   f
f       f
 
f       f
f       f
f   M   f
O       O
O       O
oO     Oo
 OJjMjJO
 oJJJJJo
  OJJJO
   OOO
    J
|----Layer 5|
 
    o
  oOOOo
 oss sso
 os   so
 O     O
 O     O
oOjsssjOo
oOOOjOOOo
oJJJjJJJo
oJJJJJJJo
oJJJMJJJo
oJjTTTjJo
oJJT TJJo
oJJT TJJo
oJjTTTjJo
oJJJMJJJo
oJJT TJJo
oJJT TJJo
 OJJJJJO
 oOOMOOo
  oOOOo
  oOOOo
   oJo
    j
|----Layer 6|
 
 
   ofo
  oOJOo
  OJJJO
 OJJJJJO
 OJJJJJO
 OOOOOOO
 OOs sOO
 
 OO  COO
  O MOOO
 
 OO    O
      OO
 
 OO M OO
 OO   OO
 OO   OO
 oO C Oo
  oOOOo
   oOo
   oOo
    j
|----Layer 7|
 
 
 
   oJo
  oOOOo
  oOOOo
  oOOOo
 oOOOOOo
 oO   Oo
 oo   oo
 oO   Oo
 oO M
 oo
 
       o
      oo
 oO M Oo
 oO   Oo
 oO   Oo
  oO Oo
   oOo
    J
    j
|----Layer 8|
 
 
 
    j
   oJo
   oJo
   oOo
  oOOOo
  oOOOo
  oO  o
  oO
  oO
 
 
 
  oO Oo
  oOOOo
  oOOOo
  oOOOo
   oOo
    J
    j
|----Layer 9|
 
 
 
 
 
 
    j
    J
 
 
 
 
 
 
 
 
    J
    J
    J
    j
}}

[[Category:Shipwreck structure subpages]]

[[fr:Épave de navire/Structure/Upside down]]