The structure is called "sideways_full."

{{layered blueprint|name=Sideways|default=Layer 1|P=spruce planks|O=Jungle Planks|p=spruce stairs|o=jungle stairs|S=Spruce slabs|s=jungle slabs|M=Spruce log|F=Spruce fence|f=jungle fence|C=Chest|T=Spruce trapdoor
|----Layer 1|
    ppp
    PPPp
    P PPPp       pP
    pppPPPfff fffPPp
       pppppppppppp
|----Layer 2|
  Pff P
  PPOOP
  PPF FOo          pPP
  pPPpPPOo         PPp
   PPPPPPOOOOOOOOOOPp
   ppppPP PP PP PPPp
       pppppppppppp
|----Layer 3|
 P
 POOOOO
 pF    OP             P
  PC    P           OOP
  pp   pOOOOoOOoOOOOPpp
  pOOOOPP PP PP PPPPp
   ppppPPpPPpPPpPPPp
       pppppppppppp
|----Layer 4|
ff    P
pOOOOOO                fff
 P     O               Ppf
 pp     P           oOOPp
  P     OOOOTTTTPTTOOPPp
  POOOOO           CPpp
   PPPPOC          Pp
    pppPPPPPPPPPPPPp
|----Layer 5|
f     P                   oo
POOOOOO                 oOo
                       oOo
 P         M    M   MOOOO
 pP     OOOMT  TM  OMPPOo
  fOOOOO   M    M   PPOo
   OPPPO   M    M  PPOo
    OOOPPPPPPPPPPPPOOo
      oOOOOOOOOOOOOo
|----Layer 6|
ff    P
pOOOOOO                fff
 P     O               Ppf
 pp     P           oOOPp
  P     OOOOTTTTOTTOOPPp
  POOOOO   P        Ppp
   PPPPO   P       Pp
    pppPPPPPPPPPPPPp
|----Layer 7|
 P
 POOOOO
 pF    OP             P
  P     P           OOP
  pp   pOOOOoOOoOOOOPpp
  pOOOOPP PP PP PPPPp
   ppppPPpPPpPPpPPPp
       pppppppppppp
|----Layer 8|
  PFF P
  PPOOP
  PPF FOo          pPP
  pPPpPPOo         PPp
   PPPPPPOOOOOOOOOOPp
   ppppPP PP PP PPPp
       pppppppppppp
|----Layer 9|
    ppp
    PPPp
    P PPPp        pP
    pppPPPfff fffPPp
       pppppppppppp
}}

[[Category:Shipwreck structure subpages]]

[[fr:Épave de navire/Structure/Sideways]]