<noinclude>{{structure info}}</noinclude>
The [[end portal]] room is the only room guaranteed to generate in a [[stronghold]]. It generates never within five rooms of the starting staircase, althought it is less likely to generate farther away, and its entrance is always a grate of iron bars.

They are composed of [[stone bricks]], [[stone brick stairs]], [[lava]], [[iron bars]], [[end portal frames]] and one siverfish [[monster spawner]]. Compared to every other room in the stronghold, the portal room is the only one that always generates the entire outer wall, therefore being the only room to always result complete after generation.

Each portal frame has a 10% chance to generate containing an [[eye of ender]]; this means that the average number of portal frames already filled is 1.2, while the chance of the portal being completely filled and activated upon generation is one in a ''trillion'' (1:1,000,000,000,000 or 10<sup>-12</sup>).

==== Materials ====
{| class="wikitable"
|-
! Name
! Amount
|-
| Stone bricks
| 1-704
|-
| Stone brick stairs
| 8
|-
| Iron bars
| 39
|-
| Lava
| 15
|-
| End portal frame
| 12
|-
| Silverfish monster spawner
| 1
|-
|Mossy Stone Bricks
|1-704
|}

==== Blueprint ====
<table><tr><td style="width:300px;">
{{layered blueprint|name=End Portal Room|default=Ground Layer|S=Stone Bricks|L=Lava|T=Stone Brick Stairs|I=Iron Bars|E=End Portal Frame|s=Monster Spawner
|----Ground Layer|
SSSSSSSSSSS
SSSSSSSSSSS
SSSSSSSSSSS
SSSSSSSSSSS
SSSSSSSSSSS
SSSSSSSSSSS
SSSSSSSSSSS
SSSSSSSSSSS
SSSSSSSSSSS
SSSSSSSSSSS
SSSSSSSSSSS
SSSSSSSSSSS
SSSSSSSSSSS
SSSSSSSSSSS
SSSSSSSSSSS
SSSSSSSSSSS
|----Layer 1|
SSSSSSSSSSS
S         S
S         S
S  SSSSS  S
S  SLLLS  S
S  SLLLS  S
S  SLLLS  S
S  SSSSS  S
S   SSS   S
S   SSS   S
S   SSS   S
SSS TTT SSS
SLS     SLS
SLS     SLS
SLS     SLS
SSSSI ISSSS
|----Layer 2|
SSSSSSSSSSS
S         S
S         S
S         S
S         S
S         S
S         S
S         S
S   SSS   S
S   SSS   S
S   TTT   S
S         S
S         S
S         S
S         S
SSSSI ISSSS
|----Layer 3|
SSISISISISS
S         S
I         I
S   EEE   S
I  E   E  I
S  E   E  S
I  E   E  I
S   EEE   S
I   SSS   I
S   TsT   S
I         I
S         S
I         I
S         S
S         S
SSSSIIISSSS
|----Layer 4|
SSISISISISS
S         S
I         I
S         S
I         I
S         S
I         I
S         S
I         I
S         S
I         I
S         S
I         I
S         S
S         S
SSSSSSSSSSS
|----Layer 5|
SSSSSSSSSSS
S         S
S         S
S         S
S         S
S         S
S         S
S         S
S         S
S         S
S         S
S         S
S         S
S         S
S         S
SSSSSSSSSSS
|----Layer 6|
SSSSSSSSSSS
SSSSSSSSSSS
SS       SS
SS       SS
SS       SS
SS       SS
SS       SS
SS       SS
SS       SS
SS       SS
SS       SS
SS       SS
SS       SS
SSSSSSSSSSS
SSSSSSSSSSS
SSSSSSSSSSS
|----Layer 7|
SSSSSSSSSSS
SSSSSSSSSSS
SSSSSSSSSSS
SSSSSSSSSSS
SSSSSSSSSSS
SSSSSSSSSSS
SSSSSSSSSSS
SSSSSSSSSSS
SSSSSSSSSSS
SSSSSSSSSSS
SSSSSSSSSSS
SSSSSSSSSSS
SSSSSSSSSSS
SSSSSSSSSSS
SSSSSSSSSSS
SSSSSSSSSSS
}}
</td><td style="vertical-align:top;">
[[File:StrongholdPortalRoom.png|400px|right]]
</td></tr></table><noinclude>
[[fr:Fort/Structure/Salle du portail]]
[[th:สตรองโฮลด์/โครงสร้าง/Portal Room]]
[[zh:要塞/结构/传送门房间]]
</noinclude>