<noinclude>{{structure info}}</noinclude>
Large rooms are sometimes found in strongholds, up to 6 per stronghold can generate. They have four exits (including the entrance to the room) and come in four variants: empty room, pillar room, fountain room and storeroom. The probability for each variant is not the same: the empty room has double the chance to generate compared to each of the other variants.

Of the four exits, only the entrance to the room generates one of the doors at random, while the others are always plain 3×3 openings.

'''Pillar''' and '''fountain''' room variants are exactly like the '''empty''' room, but with a decoration in the middle (respectevly, a pillar and a fountain); the '''store''' room variant, instead, is separated into two levels by a layer of oak planks and cobblestone, with a cobblestone structure in the middle connecting the two. The second floor contains a single loot chest, and can be accessed by ladders placed against one side of the wall.

==== Blueprints ====
Of the layers below, "E" is for "empty", "P" is for "pillar", "F" is for "fountain" and "S" is for "store" room variants. They are laid out as if the player enters from the bottom of the room

{{layered blueprint|name=Large Room|default=Ground Layer, all variants|S=Stone Bricks|s=Smooth Stone Slab+bottom|C=Cobblestone|T=Torch|O=Oak Planks|W=Water|L=Ladder|c=Chest
|----Ground Layer, all variants|
SSSSSSSSSSS
SSSSSSSSSSS
SSSSSSSSSSS
SSSSSSSSSSS
SSSSSSSSSSS
SSSSSSSSSSS
SSSSSSSSSSS
SSSSSSSSSSS
SSSSSSSSSSS
SSSSSSSSSSS
SSSSSSSSSSS

|----Layer 1E|
SSSS   SSSS
S         S
S         S
S         S
           
           
           
S         S
S         S
S         S
SSSS   SSSS
|----Layer 1P|
SSSS   SSSS
S         S
S         S
S         S
    sss    
    sSs    
    sss    
S         S
S         S
S         S
SSSS   SSSS
|----Layer 1F|
SSSS   SSSS
S         S
S         S
S  SSSSS  S
   S   S   
   S S S   
   S   S   
S  SSSSS  S
S         S
S         S
SSSS   SSSS
|----Layer 1S|
SSSS   SSSS
S         S
S         S
S         S
    CCC    
    C C    
    CCC    
S         S
SL        S
S         S
SSSS   SSSS

|----Layer 2E|
SSSS   SSSS
S         S
S         S
S         S
           
           
           
S         S
S         S
S         S
SSSS   SSSS
|----Layer 2P|
SSSS   SSSS
S         S
S         S
S         S
           
     S     
           
S         S
S         S
S         S
SSSS   SSSS
|----Layer 2F|
SSSS   SSSS
S         S
S         S
S         S
           
     S     
           
S         S
S         S
S         S
SSSS   SSSS
|----Layer 2S|
SSSS   SSSS
S         S
S         S
S         S
    C C    
           
    C C    
S         S
SL        S
S         S
SSSS   SSSS

|----Layer 3E|
SSSS   SSSS
S         S
S         S
S         S
           
           
           
S         S
S         S
S         S
SSSS   SSSS
|----Layer 3P|
SSSS   SSSS
S         S
S         S
S         S
     T     
    TST    
     T     
S         S
S         S
S         S
SSSS   SSSS
|----Layer 3F|
SSSS   SSSS
S         S
S         S
S         S
           
     S     
           
S         S
S         S
S         S
SSSS   SSSS
|----Layer 3S|
SSSS   SSSS
SCCCCCCCCCS
SCOOOOOOOCS
SCOOOOOOOCS
 COOCCCOOC 
 COOC COOC 
 COOCCCOOC 
SCOOOOOOOCS
SLOOOOOOOCS
SCCCCCCCCCS
SSSS   SSSS

|----Layer 4E & 4P|
SSSSSSSSSSS
S         S
S         S
S         S
S         S
S         S
S         S
S         S
S         S
S         S
SSSSSSSSSSS
|----Layer 4F|
SSSSSSSSSSS
S         S
S         S
S         S
S         S
S    W    S
S         S
S         S
S         S
S         S
SSSSSSSSSSS
|----Layer 4S|
SSSSSSSSSSS
S         S
S      c  S
S         S
S         S
S         S
S         S
S         S
S         S
S         S
SSSSSSSSSSS

|----Layer 5, all variants|
SSSSSSSSSSS
S         S
S         S
S         S
S         S
S         S
S         S
S         S
S         S
S         S
SSSSSSSSSSS

|----Layer 6, all variants|
SSSSSSSSSSS
SSSSSSSSSSS
SSSSSSSSSSS
SSSSSSSSSSS
SSSSSSSSSSS
SSSSSSSSSSS
SSSSSSSSSSS
SSSSSSSSSSS
SSSSSSSSSSS
SSSSSSSSSSS
SSSSSSSSSSS
}}

<noinclude>
[[fr:Fort/Structure/Grande salle]]
[[th:สตรองโฮลด์/โครงสร้าง/Large Room]]
[[zh:要塞/结构/大房间]]
</noinclude>