<noinclude>{{structure info}}</noinclude>
Libraries are sometimes found in [[strongholds]], up to 2 per stronghold can generate and never within four rooms of the starting staircase. Stronghold libraries are composed of [[stone bricks]], [[oak planks]], [[Wooden Fence|oak fences]], [[torches]], [[bookshelves]], [[cobwebs]], one loot [[chest]]; it may include [[ladders]] and an additional loot chest if it is a two-story library.

The entrance of the library is chosen randomly between the stronghold doors. Every air block in layers 1-4 has a 7% chance to generate as a cobweb instead, therefore the table below shows the average number of cobwebs.

If the library is generated partially or totally floating in a cave and the wall on which the ladders are normally supported is not generated, the ladders will also not generate.

If the two story library collides with other parts of the stronghold during generation due to its height (it is the biggest room of the stronghold, it is not a rare occurrence), then a one-story one is generated in its place.

==== Materials ====

{| class="wikitable"
|-
!
! Two-story library
! One-story library
|-
! Name
! Total amount
! Total amount
|-
| Stone Bricks
| 895
| 627
|-
| Bookshelf
| 233
| 161
|-
| Oak Planks
| 166
| 32
|-
| Oak Fence
| 46
| /
|-
| Torch
| 14
| 8
|-
| Ladder
| 7
| /
|-
| Chest
| 2
| 1
|-
| Cobweb
| 30 (estimated)
| 30 (estimated)
|-
|}

==== Blueprint ====
{{layered blueprint|name=Library|default=Ground Layer|S=Stone Bricks|W = Oak Planks|B = Bookshelf|L = Ladder|T = Torch|C = Chest|F = Oak Fence|I = Iron Bars
|----Ground Layer|
SSSSSSSSSSSSSS
SSSSSSSSSSSSSS
SSSSSSSSSSSSSS
SSSSSSSSSSSSSS
SSSSSSSSSSSSSS
SSSSSSSSSSSSSS
SSSSSSSSSSSSSS
SSSSSSSSSSSSSS
SSSSSSSSSSSSSS
SSSSSSSSSSSSSS
SSSSSSSSSSSSSS
SSSSSSSSSSSSSS
SSSSSSSSSSSSSS
SSSSSSSSSSSSSS
SSSSSSSSSSSSSS
|----Layer 1 & 2|
SSSSSSSSSSSSSS
SW L        WS
SB          BS
SB BB BB BB BS
SB          BS
SW BB BB BB WS
SB          BS
SB BB BB BB BS
SB          BS
SW BB BB BB WS
SB          BS
SB BB BB BB BS
SB          BS
SW          WS
SSSSSSSSS   SS
|----Layer 3|
SSSSSSSSSSSSSS
SWTL       TWS
SB          BS
SB BB BB BB BS
SB          BS
SWTBB BB BBTWS
SB          BS
SB BB BB BB BS
SB          BS
SWTBB BB BCTWS
SB          BS
SB BB BB BB BS
SB          BS
SWT        TWS
SSSSSSSSS   SS
|----Layer 4|
SSSSSSSSSSSSSS
SW L        WS
SB          BS
SB          BS
SB          BS
SW          WS
SB          BS
SB          BS
SB          BS
SW          WS
SB          BS
SB          BS
SB          BS
SW          WS
SSSSSSSSSSSSSS
|----Layer 5, one-story|
SSSSSSSSSSSSSS
SSSSSSSSSSSSSS
SSSSSSSSSSSSSS
SSSSSSSSSSSSSS
SSSSSSSSSSSSSS
SSSSSSSSSSSSSS
SSSSSSSSSSSSSS
SSSSSSSSSSSSSS
SSSSSSSSSSSSSS
SSSSSSSSSSSSSS
SSSSSSSSSSSSSS
SSSSSSSSSSSSSS
SSSSSSSSSSSSSS
SSSSSSSSSSSSSS
SSSSSSSSSSSSSS
|----Layer 5, two-story|
SSSSSSSSSSSSSS
SWWLWWWWWWWWWS
SWWWWWWWWWWWWS
SWWWWW    WWWS
SWWWW     WWWS
SWWW      WWWS
SWWW      WWWS
SWWW      WWWS
SWWW      WWWS
SWWW      WWWS
SWWW      WWWS
SWWW      WWWS
SWWWWWWWWWWWWS
SWWWWWWWWWWWWS
SSSSSSSSSSSSSS
|----Layer 6|
SSSSSSSSSSSSSS
SW L        WS
SB   FFFFFF BS
SB  FF    F BS
SB FF     F BS
SW F      F WS
SB F      F BS
SB F      F BS
SB F      F BS
SW F      F WS
SB F      F BS
SB F      F BS
SB FFFFFFFF BS
SW          WS
SSSSSSSSSSSSSS
|----Layer 7|
SSSSSSSSSSSSSS
SW L        WS
SB          BS
SB          BS
SB          BS
SW          WS
SB    FF    BS
SB   FFFF   BS
SB    FF    BS
SW          WS
SB          BS
SB          BS
SB          BS
SW          WS
SSSSSSSSSSSSSS
|----Layer 8|
SSSSSSSSSSSSSS
SW          WS
SB          BS
SB          BS
SB          BS
SW          WS
SB    TT    BS
SB   TFFT   BS
SB    TT    BS
SW          WS
SB          BS
SB          BS
SB          BS
SC          WS
SSSSSSSSSSSSSS
|----Layer 9|
SSSSSSSSSSSSSS
SW          WS
SB          BS
SB          BS
SB          BS
SW          WS
SB          BS
SB    FF    BS
SB          BS
SW          WS
SB          BS
SB          BS
SB          BS
S           WS
SSSSSSSSSSSSSS
|----Layer 10|
SSSSSSSSSSSSSS
SSSSSSSSSSSSSS
SSSSSSSSSSSSSS
SSSSSSSSSSSSSS
SSSSSSSSSSSSSS
SSSSSSSSSSSSSS
SSSSSSSSSSSSSS
SSSSSSSSSSSSSS
SSSSSSSSSSSSSS
SSSSSSSSSSSSSS
SSSSSSSSSSSSSS
SSSSSSSSSSSSSS
SSSSSSSSSSSSSS
SSSSSSSSSSSSSS
SSSSSSSSSSSSSS
}}<noinclude>
[[fr:Fort/Structure/Librairie]]
[[th:สตรองโฮลด์/โครงสร้าง/Library]]
[[zh:要塞/结构/图书馆]]
</noinclude>