{{Work in progress}}{{Structure info}}
== Materials ==
<!-- WHY ARE ALL THE MATERIALS HAVING PLUS?! Because it depends on how big the tree you will build. -->
=== Oak Tree ===
==== Normal ====
{| class="wikitable"
! Name !! Total !! Stack
|-
| {{BlockLink|Oak Log}}
| 5+
|
|-
| {{BlockLink|Oak Leaves}}
| 56+
|
|-
|}
==== Balloon ====
{| class="wikitable"
! Name !! Total !! Stack
|-
| {{BlockLink|Oak Log}}
| 4
|
|-
| {{BlockLink|Oak Leaves}}
| 25
|
|-
|}
==== [[Swampland]] ====
{| class="wikitable"
! Name !! Total !! Stack
|-
| {{BlockLink|Oak Log}}
| 5+
| 
|-
| {{BlockLink|Oak Leaves}}
| 137+
| 2 + 9+ blocks
|-
|}

=== Spruce Tree ===
==== Normal ====
{| class="wikitable"
! Name !! Total !! Stack
|-
| {{BlockLink|Spruce Log}}
| 7+
| 
|-
| {{BlockLink|Spruce Leaves}}
| 97+
| 1 + 33+ blocks
|-
|}
==== Matchstick ====
{| class="wikitable"
! Name !! Total !! Stack
|-
| {{BlockLink|Spruce Log}}
| 7+
| 
|-
| {{BlockLink|Spruce Leaves}}
| 10+
| 
|-
|}
==== Lollipop ====
{| class="wikitable"
! Name !! Total !! Stack
|-
| {{BlockLink|Spruce Log}}
| 5+
|
|-
| {{BlockLink|Spruce Leaves}}
| 37+
|
|-
|}

=== Birch Tree ===
{| class="wikitable"
! Name !! Total !! Stack
|-
| {{BlockLink|Birch Log}}
| 5+
|
|-
| {{BlockLink|Birch Leaves}}
| 57+
|
|-
|}

=== Jungle Tree ===
{| class="wikitable"
! Name !! Total !! Stack
|-
|{{BlockLink|Jungle Log}}
| 7+
| 
|-
|{{BlockLink|Jungle Leaves}}
| 49+
| 
|}

=== Jungle Bush ===
{| class="wikitable"
! Name !! Total !! Stack
|-
|{{BlockLink|Jungle Log}}
| 1
| 
|-
|{{BlockLink|Oak Leaves}}{{only|je|short=1}}<br>{{BlockLink|Jungle Leaves}}{{only|be|short=1}}
| 25-34
| 
|}

=== Acacia Tree ===
{| class="wikitable"
! Name !! Total !! Stack
|-
| {{BlockLink|Acacia Log}}
| 9+
| 
|-
| {{BlockLink|Acacia Leaves}}
| 84
| 1 + 20 blocks
|-
|}

=== Dark Oak Tree ===
{| class="wikitable"
! Name !! Total !! Stack
|-
| {{BlockLink|Dark Oak Log}}
| 24+
| 
|-
| {{BlockLink|Dark Oak Leaves}}
| 79
|
|-
|}

=== Azalea Tree ===
{| class="wikitable"
! Name !! Total !! Stack
|-
| {{BlockLink|Oak Log}}
| 6+
| 
|-
| {{BlockLink|Azalea Leaves}}
| 58+
|
|-
|}

=== Mangrove Tree ===
{| class="wikitable"
! Name !! Total !! Stack
|-
| {{BlockLink|Mangrove Log}}
| 10+
| 
|-
| {{BlockLink|Mangrove Roots}}
| 20+
|
|-
| {{BlockLink|Mangrove Leaves}}
| 100+
|
|-
| {{BlockLink|Mangrove Propagule}}
| 1+
|
|-
| {{BlockLink|Vines}}
| 50+ 
|
|-
|}

=== Cherry Tree ===
{{empty section}}

=== Pale Oak Tree ===
{| class="wikitable"
! Name !! Total !! Stack
|-
| {{BlockLink|Pale Oak Log}}
| 24+
| 
|-
| {{BlockLink|Pale Oak Leaves}}
| 79
|
|-
| {{BlockLink|Pale Hanging Moss}}
| 7
|
|-
| {{BlockLink|Creaking Heart}}
| {{Tooltip|1|Only on creaking pale oaks.}}
|
|-
|}

== Blueprint ==

=== Oak Tree ===
==== Normal ====
<table><tr><td style="width:200px;">
{{layered blueprint|name=Oak Tree|default=Layer 6
|W=Oak Log+top|L=Oak Leaves
|----Layers 1-2|
 
 
  W
 
 

|----Layers 3-4|
LLLLL
LLLLL
LLWLL
LLLLL
LLLLL
|----Layer 5|
 
 LLL
 LWL
 LLL
 
|----Layer 6|
 
  L
 LLL
  L
 
}}
</td><td style="vertical-align:top;">
[[File:Oak JE12.png|200px|right]]
</td></tr></table>

==== Balloon ====
<table><tr><td style="width:200px;">
{{layered blueprint|name=Balloon Oak Tree|default=Layer 5
|W=Oak Log+top|L=Oak Leaves
|----Layer 1|
     
     
  W  
     
     
|----Layers 2-4|
 LLL
LLLLL
LLWLL
LLLLL
 LLL
|----Layer 5|
     
  L  
 LLL 
  L  
     
}}
</td><td style="vertical-align:top;position:relative;left:20px;">
[[File:Balloon Oak Tree.png|160px|right]]
</td></tr></table>

==== Swampland ====
<table><tr><td style="width:200px;">
{{layered blueprint|name=Swampland Oak Tree|default=Layer 6
|W=Oak Log+top|L=Oak Leaves
|----Layers 1-2|
       
       
       
   W   
       
       
       

|----Layer 3|
LLLLLLL
LLLLLLL
LLLLLLL
LLLWLLL
LLLLLLL
LLLLLLL
LLLLLLL
|----Layer 4|
LLLLLLL
LLLLLLL
LLLLLLL
LLLWLLL
LLLLLLL
LLLLLLL
LLLLLLL
|----Layer 5|
       
  LLL  
 LLLLL 
 LLWLL 
 LLLLL 
  LLL  
       
|----Layer 6|
       
  LLL  
 LLLLL 
 LLLLL 
 LLLLL 
  LLL  
       
}}
</td><td style="vertical-align:top;">
[[File:Swamp_Tree.png|200px|right]]
</td></tr></table>

=== Spruce Tree ===
==== Normal ====
<table><tr><td style="width:200px;">
{{layered blueprint|name=Normal Spruce Tree|default=Layer 4
|W=Spruce Log+top|L=Spruce Leaves
|----Layer 1|
 
 
 
   W
 
 
 
|----Layer 2|
 LLLLL
LLLLLLL
LLLLLLL
LLLWLLL
LLLLLLL
LLLLLLL
 LLLLL
|----Layer 3|
 
  LLL
 LLLLL
 LLWLL
 LLLLL
  LLL
 
|----Layer 4|
 
 
   L
  LWL
   L
 
 
|----Layer 5|
 
  LLL
 LLLLL
 LLWLL
 LLLLL
  LLL
 
|----Layer 6|
 
 
   L
  LWL
   L
 
 
|----Layer 7|
 
 
 
   W
 
 
 
|----Layer 8|
 
 
   L
  LLL
   L
 
 
}}
</td><td style="vertical-align:top;">
[[File:Spruce Tree.png|200px|right]]
</td></tr></table>
==== Matchstick ====
<table><tr><td style="width:200px;">
{{layered blueprint|name=Matchstick Spruce Tree|default=Layer 7
|W=Spruce Log+top|L=Spruce Leaves
|----Layers 1-6|
   
 W 
   
|----Layer 7|
 L 
LWL
 L 
|----Layer 8|
 L 
LLL
 L 
|----Layer 9|
   
 L 
   
}}
</td><td style="vertical-align:top;position:relative;left:20px;">
[[File:Pine Tree.png|100px|right]]
</td></tr></table>
==== Lollipop ====
<table><tr><td style="width:200px;">
{{layered blueprint|name=Lollipop Spruce Tree|default=Layer 3
|W=Spruce Log+top|L=Spruce Leaves
|----Layers 1-2|
     
     
  W  
     
     
|----Layer 3|
     
 LLL 
 LWL 
 LLL 
     
|----Layer 4|
 LLL
LLLLL
LLWLL
LLLLL
 LLL
|----Layer 5|
     
 LLL 
 LWL 
 LLL 
     
|----Layer 6|
     
     
  L  
     
     
}}
</td><td style="vertical-align:top;position:relative;left:20px;">
[[File:LollipopSpruceTree.png|175px|right]]
</td></tr></table>
=== Birch Tree ===
<table><tr><td style="width:200px;">
{{layered blueprint|name=Birch Tree|default=Layer 6
|W=Birch Log+top|L=Birch Leaves
|----Layers 1-2|
 
 
  W
 
 
 
|----Layer 3|
LLLL
LLLLL
LLWLL
LLLLL
 LLLL
|----Layer 4|
 LLLL
LLLLL
LLWLL
LLLLL
LLLL
|----Layer 5|
 
 LLL
 LWL
 LLL
 
|----Layer 6|
 
  L
 LLL
  L
 
}}
</td><td style="vertical-align:top;">
[[File:Birch Tree.png|200px|right]]
</td></tr></table>

=== Jungle Tree ===
<table><tr><td style="width:200px;">
{{layered blueprint|name=Jungle Tree|default=Layer 8
|W=Jungle Log+top|L=Jungle Leaves
|----Layers 1-4|
     
     
  W  
     
     

|----Layer 5|
 LLL 
LLLLL
LLWLL
LLLLL
LLLL 
|----Layer 6|
LLLLL
LLLLL
LLWLL
LLLLL
 LLL 
|----Layer 7|
     
  LL 
 LWL 
  LL 
     
|----Layer 8|
     
  L  
 LLL 
  L  
     
}}
</td><td style="vertical-align:top;">
[[File:Jungle_Tree.png|200px|right]]
</td></tr></table>

=== Jungle Bush ===
<table><tr><td style="width:200px;">
{{layered blueprint|name=Jungle Bush|default=Layer 1
|W=Jungle Log+top|L=Oak Leaves
|----Layer 1|
LLLLL
LLLLL
LLWLL
LLLLL
LLLLL

|----Layer 2|
     
 LLL
 LLL
 LLL
     
|----Layer 3|
     
     
  L
     
      
}}
</td><td>[[File:Jungle Bush.png|right|200px]]</td></tr></table>

=== Acacia Tree ===
<table><tr><td style="width:250px;">
{{layered blueprint|name=Acacia Tree|default=Layer 7
|W=Acacia Log+top|L=Acacia Leaves
|----Layers 1-3|
         
         
         
    W    
         
         
         
|----Layer 4|
         
         
         
   WW    
         
         
         
|----Layer 5|
         
 LLL      
LLLLL    
LLWLW    
LLLLL    
 LLL     
|----Layer 6|
         
         
 LLL     
 LLL W   
 LLL     
|----Layer 7|
   LLLLL 
  LLLLLLL
  LLLLLLL
  LLLWLLL
  LLLLLLL
  LLLLLLL
   LLLLL 
|----Layer 8|
         
     L   
    LLL  
   LLLLL 
    LLL  
     L   
         
}}
</td><td style="vertical-align:top;">
[[File:Acacia_Tree.png|200px|right]]
</td></tr></table>

=== Dark Oak Tree ===
<table><tr><td style="width:250px;">
{{layered blueprint|name=Dark Oak Tree|default=Layer 10
|W=Dark Oak Log+top|L=Dark Oak Leaves|A=air
|----Layers 1-3|
A
A
A
   WW 
   WW 

|----Layers 4-5|
A
A
A
   WW 
   WWW

|----Layers 6-7|
A
A
  W WW
   WW 
   WWW
  WWW

|----Layer 8|
 LLLLL
 LLLLLL
LLLLLLLL
LLLWWLLL
LLLWWLLL
LLLLLLLL
LLLLLLL
 LLLLL
|----Layer 9|
A
   LL
  LLLL
 LLLLLL
 LLLLLL
  LLLL
   LL
|----Layer 10|
A
A
A
   LL
   LL

}}
</td><td style="vertical-align:top;">
[[File:Dark_Oak_Tree.png|200px|right]]
</td></tr></table>

=== Azalea Tree ===
<table><tr><td style="width:200px;">
{{layered blueprint|name=Azalea Tree|default=Layer 10
|W=Oak Log+top|L=Azalea Leaves|A=air
|----Layers 1-2|       
       
     
   W   
       
       
       
|----Layer 3|       
     
       
    W  
       
|----Layer 4|     
       
       
     W 
|----Layer 5|       
       
       
     WW
|----Layer 6|
|----Layer 7|}}
</td><td style="vertical-align:top;">
[[File:Azalea Tree.png|200px|right]]
</td></tr></table>

=== Mangrove Tree ===
{{empty section}}

=== Cherry Tree ===
{{empty section}}

=== Pale Oak Tree ===
==== Normal ====
<table><tr><td style="width:250px;">
{{layered blueprint|name=Pale Oak Tree|default=Layer 10
|W=Pale Oak Log+top|L=Pale Oak Leaves|A=air|M=Pale Hanging Moss
|----Layers 1-3|
A
A
A
   WW 
   WW 

|----Layer 4|
A
A
A
   WW 
   WWW

|----Layer 5|
A
A   M M
A    
   WW 
   WWW
 M  M
|----Layer 6|
A
A   MMM
  W WW
   WW 
   WWW
 MWWW
 M  MM
|----Layers 7-8|
 LLLLL
 LLLLLL
LLLLLLLL
LLLWWLLL
LLLWWLLL
LLLLLLLL
LLLLLLL
 LLLLL
|----Layer 9|
A
   LL
  LLLL
 LLLLLL
 LLLLLL
  LLLL
   LL
|----Layer 10|
A
A
A
   LL
   LL

}}
</td><td style="vertical-align:top;">
[[File:Pale_Oak_Tree.png|200px|right]]
</td></tr></table>
==== Creaking ====
<table><tr><td style="width:250px;">
{{layered blueprint|name=Creaking Pale Oak Tree|default=Layer 10
|W=Pale Oak Log+top|L=Pale Oak Leaves|A=air|M=Pale Hanging Moss|H=Creaking Heart
|----Layers 1-3|
A
A
A
   WW 
   WW 

|----Layer 4|
A
A
A
   WW 
   WWW

|----Layer 5|
A
A   M M
A    
   WW 
   WWW
 M  M
|----Layer 6|
A
A   MMM
  W WW
   WW 
   WHW
 MWWW
 M  MM
|----Layers 7-8|
 LLLLL
 LLLLLL
LLLLLLLL
LLLWWLLL
LLLWWLLL
LLLLLLLL
LLLLLLL
 LLLLL
|----Layer 9|
A
   LL
  LLLL
 LLLLLL
 LLLLLL
  LLLL
   LL
|----Layer 10|
A
A
A
   LL
   LL

}}

</td><td style="vertical-align:top;position:relative;">
[[File:Pale_Oak_Tree.png|200px|right]]
</td></tr></table>

[[es:Árbol/Estructura]]
[[pt:Árvore/Estrutura]]
[[zh:树木/结构]]