==== Spiral Staircase ====
The structure is called "corner_staircase".{{layered blueprint|name=Stairs|T=Tuff Bricks|D=Chiseled Tuff Bricks|P=Polished Tuff
|C=Block of Copper|c=Oxidized Copper|S=Cut Copper Stairs|s=Oxidized Cut Copper Stairs|U=Cut Copper|u=Oxidized Cut Copper|B=Copper Bulb|b=Oxidized Copper Bulb
|----Layer 1|
     
   u 
  uu 
 ccu 
 ucu 
 ucu 
 ucu 
 ucu 
 ucu 
 ucu 
|----Layer 2|
CCCCC
Ccc C
Cs  C
C   C
C   C
C   C
C   C
C   C
C   C
C   C
|----Layer 3|
TTTTT
T scT
T  cT
T   T
T   T
T   T
T   T
T   T
T   T
T   T
|----Layer 4|
DDDDD
D   D
D  sD
D ccD
D   D
D   D
D   D
D   D
D   D
D   D
|----Layer 5|
TTTTT
T   T
Tc  T
Tcs T
T   T
T   T
T   T
T   T
T   T
TCBCT
|----Layer 6|
TTTTT
Tcc T
Ts  T
T   T
T   T
T   T
TPPPT
TPPPT
TPPPT
TPPPT
|----Layer 7|
TTTTT
T scT
T  cT
T   T
TPPPT
TPPPT
TPPPT
TPPPT
TPPPT
TPPPT
|----Layer 8|

}}