{{Structure info}}{{WIP}}

<!-- In the blueprints, unknown blocks are not included. Feel free to add them ! -->
== Blueprints ==
=== Corridors ===
All corridors can be rotated. 
==== Straight ====
{{layered blueprint|name=Straight Corridor|T=Tuff Bricks|H=Chiseled Tuff Bricks|X=Oxidized Copper Bulb|P=Polished Tuff|B=Block of Copper|b=Oxidized Copper|C=Cut Copper|c=Oxidized Cut Copper
|----Layer 1|
          
cccccccccc
bbbbbbbbbb
cccccccccc

|----Layer 2|
BBBBBBBBBB
          
          
          
BBBBBBBBBB
|----Layer 3|
TTXTTTTXTT
          
          
          
TTXTTTTXTT
|----Layer 4|
HHHHHHHHHH



HHHHHHHHHH
|----Layer 5|
PPPPPPPPPP
PPPPPPPPPP
PPPPPPPPPP
PPPPPPPPPP
PPPPPPPPPP
}}

==== Curve ====
{{layered blueprint|name=Corridor Curve|T=Tuff Bricks|H=Chiseled Tuff Bricks|X=Oxidized Copper Bulb|P=Polished Tuff|B=Block of Copper|b=Oxidized Copper|C=Cut Copper|c=Oxidized Cut Copper
|----Layer 1|
   cbc
   cbc
   cbc
ccccbc 
bbbbbc 
cccccc 

|----Layer 2|
  B   B
  B   B
BBB   B
      B
      B
      B
BBBBBBB
|----Layer 3|
  T   T
  T   T
TTT   X
      T
      T
      T
TTXTTTT
|----Layer 4|
  H   H
  H   H
HHH   H
      H
      H
      H
HHHHHHH
|----Layer 5|
  PPPPP
  PPPPP
PPPPPPP
PPPPPPP
PPPPPPP
PPPPPPP
PPPPPPP
}}

=== Staircases ===
==== Spiral Staircase ====
The structure is called "corner_staircase".{{layered blueprint|name=Stairs|T=Tuff Bricks|D=Chiseled Tuff Bricks|P=Polished Tuff
|C=Block of Copper|c=Oxidized Copper|S=Cut Copper Stairs|s=Oxidized Cut Copper Stairs|U=Cut Copper|u=Oxidized Cut Copper|B=Copper Bulb|b=Oxidized Copper Bulb
|----Layer 1|
     
   u 
  uu 
 ccu 
 ucu 
 ucu 
 ucu 
 ucu 
 ucu 
 ucu 
|----Layer 2|
CCCCC
Ccc C
Cs  C
C   C
C   C
C   C
C   C
C   C
C   C
C   C
|----Layer 3|
TTTTT
T scT
T  cT
T   T
T   T
T   T
T   T
T   T
T   T
T   T
|----Layer 4|
DDDDD
D   D
D  sD
D ccD
D   D
D   D
D   D
D   D
D   D
D   D
|----Layer 5|
TTTTT
T   T
Tc  T
Tcs T
T   T
T   T
T   T
T   T
T   T
TCBCT
|----Layer 6|
TTTTT
Tcc T
Ts  T
T   T
T   T
T   T
TPPPT
TPPPT
TPPPT
TPPPT
|----Layer 7|
TTTTT
T scT
T  cT
T   T
TPPPT
TPPPT
TPPPT
TPPPT
TPPPT
TPPPT
|----Layer 8|

}}

=== Chest rooms ===
==== Corridor chest room ====
The structure is called "cache_1".

The [[Copper Bulb]] behind the chest generates with one level of oxidization and appears to be waxed.
{{layered blueprint|name=Chest Room|E=Waxed Exposed Copper Bulb|F=Oxidized Copper Bulb|C=Block of Copper|O=Waxed Oxidized Copper|B=Tuff Bricks|X=Chest|P=Polished Tuff|Y=Polished Tuff|J=Chiseled Tuff Bricks Top?Chiseled Tuff Bricks
|----Layer 1|
    OOOOOOO
    OOOOOOO
    OOJYJOO
    OOYJYOO
    OOJYJOO
    OOOOOOO
OOOOOOOOOOOOOOO
OOOOOOOOOOOOOOO
OOOOOOOOOOOOOOO

|----Layer 2|
    CCCCCCC
    C     C
    C     C
    C  X  C
    C     C
CCCCC     CCCCC



CCCCCCCCCCCCCCC
|----Layer 3|
    BBBEBBB
    B     B
    B     B
    B     B
    B     B
BBFBB     BBFBB



BBFBBBBFBBBBFBB
|----Layer 4-5|
    JJJJJJJ
    J     J
    J     J
    J     J
    J     J
JJJJJ     JJJJJ



JJJJJJJJJJJJJJJ
|----Layer 6|
PPPPPPPPPPPPPPP
PPPPPPPPPPPPPPP
PPPPPPPPPPPPPPP
PPPPPPPPPPPPPPP
PPPPPPPPPPPPPPP
PPPPPPPPPPPPPPP
PPPPPPPPPPPPPPP
PPPPPPPPPPPPPPP
PPPPPPPPPPPPPPP
PPPPPPPPPPPPPPP
}}

=== "Central Room" ? ===
{{layered blueprint|name=Central Room|X=Copper Bulb|B=Tuff Bricks|C=Block of Copper|c=Oxidized Copper|S=Cut Copper Stairs|s=Oxidized Cut Copper Stairs|D=Chiseled Tuff Bricks
|----Layer 1|

}}

=== Trial Chambers ===
==== Corner Trial Spawner Room ====
The structure was in an early video but is now no longer in the game.<ref>{{ytl|8jwAtfyxhlk|t=332s}}</ref>{{layered blueprint|name=Corner Trial Spawner|S=Trial Spawner|B=Oxidized Copper Bulb|C=Block of Copper|c=Oxidized Copper|d=Oxidized Cut Copper|I=Packed Ice|T=Tuff Bricks|P=Polished Tuff Bricks|D=Chiseled Tuff Bricks
|----Layer 1|
cccccccccccc
ccccccdddddc
cccccccICIdc
cccccccCCCdc
cccccccICIdc
ccccccccccdc
cccccccccccc
cccccccccccc
cccccccccccc
cccccccccccc
cccccccccccc
cccccccccccc
|----Layer 2|
CCCCCCCCCCCC
CC   CC   CC
C          C
C       S  C
C          C
C         CC
          CC
           C
           C
           C
          CC
      CCCCCC
|----Layer 3|
TTTBTTTTBTTT
TT   TT   TT
T          T
T          B
T          T
T         TT
          TT
           T
           B
           T
          TT
      TTTTTT
|----Layer 4|
DDDDDDDDDDDD
DD   DD   DD
D          D
D          D
D          D
D         DD
          DD
           D
           D
           D
          DD
      DDDDDD
|----Layer 5|
TTTTTTTTTTTT
TT   TT   TT
T          T
T          T
T          T
T         TT
T         TT
T          T
T          T
T          T
T         TT
TTTTTTTTTTTT
|----Layer 6|
TTTTTTTTTTTT
TT   TT   TT
C          T
C          T
C          T
C         TT
C         TT
C          T
C          T
C          T
C         TT
CCCCCCCCCCTT
|----Layer 7|
CCCCCCCCCCCC
CC   CC   CC
           C
           C
           C
          CC
          CC
           C
           C
           C
          CC
          CC
|----Layer 8|
TTTBTTTTBTTT
TT   TT   TT
           T
           B
           T
          TT
          TT
           T
           B
           T
          TT
          TT
}}

== References ==
<references />

[[pt:Câmaras do desafio/Estrutura/Plantas]]