All corridors can be rotated.
==== Straight ====
{{layered blueprint|name=Straight Corridor|T=Tuff Bricks|H=Chiseled Tuff Bricks|X=Oxidized Copper Bulb|P=Polished Tuff|B=Block of Copper|b=Oxidized Copper|C=Cut Copper|c=Oxidized Cut Copper
|----Layer 1|
          
cccccccccc
bbbbbbbbbb
cccccccccc

|----Layer 2|
BBBBBBBBBB
          
          
          
BBBBBBBBBB
|----Layer 3|
TTXTTTTXTT
          
          
          
TTXTTTTXTT
|----Layer 4|
HHHHHHHHHH



HHHHHHHHHH
|----Layer 5|
PPPPPPPPPP
PPPPPPPPPP
PPPPPPPPPP
PPPPPPPPPP
PPPPPPPPPP
}}

==== Curve ====
{{layered blueprint|name=Corridor Curve|T=Tuff Bricks|H=Chiseled Tuff Bricks|X=Oxidized Copper Bulb|P=Polished Tuff|B=Block of Copper|b=Oxidized Copper|C=Cut Copper|c=Oxidized Cut Copper
|----Layer 1|
   cbc
   cbc
   cbc
ccccbc 
bbbbbc 
cccccc 

|----Layer 2|
  B   B
  B   B
BBB   B
      B
      B
      B
BBBBBBB
|----Layer 3|
  T   T
  T   T
TTT   X
      T
      T
      T
TTXTTTT
|----Layer 4|
  H   H
  H   H
HHH   H
      H
      H
      H
HHHHHHH
|----Layer 5|
  PPPPP
  PPPPP
PPPPPPP
PPPPPPP
PPPPPPP
PPPPPPP
PPPPPPP
}}