<noinclude>{{structure info}}</noinclude>

[[File:Desert Large Farm 1.png|thumb|Large farm 1 (Desert)]]



==== Blueprint ====

{{layered blueprint|name=Desert Large Farm 1
|default=Layer 1
|S=Sand
|H=Hay Bale
|h=Hay Bale-rot90
|z=Hay Bale+top
|M=Smooth Sandstone
|O=Smooth Sandstone Stairs
|W=Water+top
|F=Farmland+moist
|E=Wheat
|C=Composter
               
|----Layer -1|
               
 SSSSSSSSSSSSS 
 SSSSSSSSSSSSS 
 SSSSSSSSSSSSS 
 SSSSSSSSSSSSS 
 SSSSSSSSSSSSS 
 SSSSSSSSSSSSS 
 SSSSSSSSSSSSS 
 SSSSSSSSSSSSS 
 SSSSSSSSSSSSS 
 SSSSSSSSSSSSS 
 SSSSSSSSSSSSS 
               
|----Layer 0|
               
   SSSSSSSS    
  SSSSSSSSSS   
  SMMMSFFFFSSS 
  SSSSSSFWFFFS 
  SSFFFFFFFFSS 
  SSSFFFFFSSSS 
  SSSSFFFFFSSS 
  SSSFFFFFSSSS 
   SFFFWFFFSSS 
   SSSFFFSSS   
   S  SSS      
               
|----Layer 1|
               
        z      
  OMMMOH  h    
  MWWWMEEEE    
  OMMMO E EEEh 
    EEEEEEEE   
  z  EEEEECz z 
   hChEEEEEHzh 
  h HEEEEEh z  
    EEE EEE  H 
      EEE      
   h           
               
|----Layer 2|
               
               
               
               
               
               
               
   z        h  
               
               
               
               
               
}}

==== Materials ====

{| class="wikitable sortable mw-collapsible"
|-
! Name !! Total !! Layer 1 !! Layer 2 !! Layer 3 !! Layer 4 
|-
| {{BlockLink|Composter}} || 2 || - || - || 2 || - 
|-
| {{BlockLink|Farmland}} || 40 || - || 40 || - || - 
|-
| {{BlockLink|Hay Bale}} || 20 || - || - || 18 || 2 
|-
| {{BlockLink|Sand}} || 212 || 143 || 69 || - || - 
|-
| {{BlockLink|Smooth Sandstone}} || 11 || - || 3 || 8 || - 
|-
| {{BlockLink|Smooth Sandstone Stairs}} || 4 || - || - || 4 || - 
|-
| {{BlockLink|Water}} || 5 || - || 2 || 3 || - 
|-
| {{BlockLink|Wheat}} || 40 || - || - || 40 || - 
|}<noinclude>
[[Category:Village blueprints]]

[[fr:Village/Structure/Désert Grande Ferme 1 plan]]
[[ja:村/構造/設計図/砂漠の大きな畑1]]
[[zh:村庄/结构/图示/沙漠大型农田]]
</noinclude>