<noinclude>
{{project|Structure Blueprints}}
{{structure info}}
</noinclude>

== Large House (L-shaped house) == 

[[File:Village_Large_House.png|thumb|Large House (Plains, Old)]]

A common house made up of cobblestone, oak logs, oak planks, an oak door, glass panes, and oak stairs. This can be mirrored and the oak can be swapped out with spruce or acacia if it is the taiga or savanna variant, respectively.

=== Blueprint ===

{{layered blueprint|name=Large House|default=Layer 3
|c=Cobblestone|b=Oak Planks|o=Cobblestone Stairs|d=Oak Door+bottom|e=Oak Door+top|w=Oak Log+top|g=Glass Pane|G=Glass Pane-rot90|s=Oak Stairs|t=Torch
|----Layer 1|
ccccccc 
cbbbbbc 
cbbbbbc 
cbbbbbc 
cbbbbbc 
cbbbbbccc 
cbbbbbbbc 
cbbbbbbbc 
cbbbbbbbc 
cbbbbbbbc 
ccccccccc 
      s
|----Layer 2|
ccccccc
c     c
c     c
c     c
c     c
c     ccc
c       c
c       c
c       c
c       c
ccccccdcc
|----Layer 3|
ccccccc
w     w
g     g
g     g
w     w
b     bbc
w       w
g       g
g       g
w       w
cbwGwbebc
|----Layer 4|
cccccccs
c     cs
c     cs
c     cs
c     cbs
c     bbc
c       c
c       c
c       c
c     t c
cbbbbbbbc
sssssssss
|----Layer 5|
sbwGwbs
sb   bs
sb   bs
sb   bs
sb   bs
sb   bbss
bb   bbbb
bb      b
bb      b
bbbbbbbbb
sssssssss
|----Layer 6|
 sbbbs
 sb bs
 sb bs
 sb bs
 sb bs
 sb bs
sbb bbsss
bbbbbbbbb
bbbbbbbbb
sssssssss
|----Layer 7|
  sbs
  sbs
  sbs
  sbs
  sbs
  sbs
  sbs
ssbbbssss
sssssssss
}}

Note: the oak stairs are ''optional'' for the first layer and generates only if the house was spawned above street level. <br />
Another Note: If the house was spawned level with the street, this floor has the cobblestone and planks in the ground instead of above the ground.

=== Materials ===

{| class="wikitable"
|-
! Name !! Total
|-
| Cobblestone || 108
|-
| Glass Pane || 10
|-
| Oak Door || 1
|-
| Oak Logs || 12
|-
| Oak Planks || 148
|-
| Oak Stairs || 91
|-
| Torch || 1
|-
|}

About 83 Logs to have the 12 Logs, make the Oak Stairs, and the Oak Planks.

Build after the [https://web.archive.org/web/20190711071259/https://imgur.com/a/JOnOo#4 plans] by [[User:Merdink]]


== Desert Large House (L-shaped house) ==

[[File:Village_Desert_Large_House.png|thumb|Large House (Desert, Old)]]

A common house made up of sandstone, smooth sandstone, a door, glass panes, and sandstone stairs.


===Blueprint===

{{layered blueprint|name=Desert Large House|default=Layer 3
|c=Sandstone|b=Smooth Sandstone|d=Oak Door+bottom|e=Oak Door+top|g=Glass Pane|G=Glass Pane-rot90|s=Sandstone Stairs|t=Torch
|----Layer 1|
ccccccc
cbbbbbc
cbbbbbc
cbbbbbc
cbbbbbc
cbbbbbccc 
cbbbbbbbc 
cbbbbbbbc 
cbbbbbbbc 
cbbbbbbbc 
ccccccccc 
      s
|----Layer 2|
ccccccc
c     c
c     c
c     c
c     c
c     ccc
c       c
c       c
c       c
c       c
ccccccdcc
|----Layer 3|
ccccccc
c     c
g     g
g     g
c     c
b     bbc
c       c
g       g
g       g
c       c
cbcGcbebc
|----Layer 4|
cccccccs
c     cs
c     cs
c     cs
c     cbs
c     bbc
c       c
c       c
c       c
c     t c
cbbbbbbbc
sssssssss
|----Layer 5|
sbcGcbs
sb   bs
sb   bs
sb   bs
sb   bs
sb   bbss
bb   bbbb
bb      b
bb      b
bbbbbbbbb
sssssssss
|----Layer 6|
 sbbbs
 sb bs
 sb bs
 sb bs
 sb bs
 sb bs
sbb bbsss
bbbbbbbbb
bbbbbbbbb
sssssssss
|----Layer 7|
  sbs
  sbs
  sbs
  sbs
  sbs
  sbs
  sbs
ssbbbssss
sssssssss
}}

Note: the sandstone stairs are ''optional'' for the first layer and generates only if the house was spawned above the street level. <br />
Another Note: If the house was spawned level with the street, this floor has the sandstone in the ground instead of above the ground.


=== Materials ===

{| class="wikitable"
|-
! Name !! Total
|-
| Sandstone || 120
|-
| Sandstone Stairs || 91
|-
| Cut Sandstone || 148
|-
| Glass Pane || 10
|-
| Torch || 1
|-
| Wooden Door || 1
|-
|}


== Video ==

{{yt|-iR4dAzPlJU}}


== Gallery ==

<gallery>
File:Villagehouse1.png|The sides of a large house.
</gallery><noinclude>
[[Category:Village blueprints]]

[[zh:村庄/结构（旧版）/图示/大型房屋]]
</noinclude>