<noinclude>{{structure info}}</noinclude>

[[File:Savanna Butchers Shop 2.png|thumb|Butchers Shop 2 (Savanna)]]



==== Blueprint ====

{{layered blueprint|name=
Savanna Butchers Shop 2|default=Layer 1
|G=Grass Block+top
|A=Acacia Planks
|C=Acacia Wood
|D=Dirt
|S=Smoker
|H=Chest-rot-270
|R=Short Grass
|I=Acacia Fence
|T=Torch
|c=Acacia Stairs
|L=Glass Pane
|B=Acacia Slab
|W=Wall Torch-rot-180
|O=Acacia Door+bottom
|a=Acacia Door+top
|l=Wall Torch
           
|----Layer 1|
           
 GGGGGGGGG 
 GGGGGGGGG 
 GGGGGGDGG 
 GGGGGGGGG 
 GGGGGGGGG 
 GGGGGGGGG 
 GGGGGGGGG 
 GGGGGGGGG 
 GGGGGGGGG 
 GGGGGGG G 
 GGGGGGG R 
 GGGDDDG R 
 GGGDDDGR  
           
|----Layer 2|
           
 IIIIIIIII 
 I RR RR I 
 IR RRRcRI 
 IR R RBRI 
 IR  RI RI 
 IRI I I I 
 I    RRRI 
 IR RT RRI 
 III I III 
  RI   I   
  RI   I   
 R IAAAI   
  RRcccR   
           
|----Layer 3|
           
 T       T 
           
           
       c   
      IB   
   I I I   
           
           
   I I I T 
           
    BBB    
    ccc    
           
           
|----Layer 4|
           
           
           
           
           
    BBc    
   AACAA   
   AAAAA   
   AAAAA   
   AACAA   
    AAA    
    ccc    
           
           
           
|----Layer 5|
           
           
           
           
           
    S      
   CCOCC   
   Cc HC   
   Cc  C   
   CCOCC   
           
           
           
           
           
|----Layer 6|
           
           
           
           
           
           
   CCaCC   
   L   L   
   L   L   
   CCaCC   
    W W    
           
           
           
           
|----Layer 7|
           
           
           
           
           
     l     
   CCCCC   
   C W C   
   C   C   
   CCCCC   
           
           
           
           
           
|----Layer 8|
           
           
           
           
           
   ccccc   
  cAAAAAc  
  cA   Ac  
  cA   Ac  
  cAAAAAc  
   ccccc   
           
           
           
           
|----Layer 9|
           
           
           
           
           
           
   ccccc   
   cAAAc   
   cAAAc   
   ccccc   
           
           
           
           
           
}}



==== Materials ====

{| class="wikitable sortable mw-collapsible"
|-
! Name !! Total !! Layer 1 !! Layer 2 !! Layer 3 !! Layer 4 !! Layer 5 !! Layer 6 !! Layer 7 !! Layer 8 !! Layer 9 
|-
| {{BlockLink|Acacia Door}} || 2 || - || - || - || - || 2 || - || - || - || - 
|-
| {{BlockLink|Acacia Fence}} || 47 || - || 40 || 7 || - || - || - || - || - || - 
|-
| {{BlockLink|Acacia Planks}} || 44 || - || 3 || - || 21 || - || - || - || 14 || 6 
|-
| {{BlockLink|Acacia Slab}} || 7 || - || 1 || 4 || 2 || - || - || - || - || - 
|-
| {{BlockLink|Acacia Stairs}} || 46 || - || 4 || 4 || 4 || 2 || - || - || 18 || 14 
|-
| {{BlockLink|Acacia Wood}} || 36 || - || - || - || 2 || 12 || 8 || 14 || - || - 
|-
| {{BlockLink|Chest}} || 1 || - || - || - || - || 1 || - || - || - || - 
|-
| {{BlockLink|Dirt}} || 7 || 7 || - || - || - || - || - || - || - || - 
|-
| {{BlockLink|Glass Pane}} || 4 || - || - || - || - || - || 4 || - || - || - 
|-
| {{BlockLink|Short Grass}} || 33 || 3 || 30 || - || - || - || - || - || - || - 
|-
| {{BlockLink|Grass Block}} || 103 || 103 || - || - || - || - || - || - || - || - 
|-
| {{BlockLink|Smoker}} || 1 || - || - || - || - || 1 || - || - || - || - 
|-
| {{BlockLink|Torch}} || 8 || - || 1 || 3 || - || - || 2 || 2 || - || - 
|}<noinclude>
[[Category:Village blueprints]]

[[fr:Village/Structure/Savane Échoppe de Boucher 2 plan]]
[[ja:村/構造/設計図/サバンナの肉屋2]]
[[zh:村庄/结构/图示/热带草原肉铺2]]
</noinclude>