<noinclude>{{structure info}}</noinclude>

[[File:Plains Small House 1.png|thumb|Small House 1 (Plains)]]



==== Blueprint ====

{{layered blueprint
|name=Village Plains Houses plains_small_house_1'''
|default=Layer 2
|S=Stripped Oak Log+top
|C=Cobblestone
|P=Oak Planks
|B=White Bed+top foot-rot270'''
|b=White Bed+top head-rot270
|<=Oak Stairs-rot90
|^=Oak Stairs-rot270
|g=glass Pane
|s=Oak Stairs-rot180
|T=torch-rot180
|d=Oak Door+bottom
|D=Oak Door+top
|G=glass Pane-rot90
|>=Oak Stairs
|----Layer 1|
         
         
  SCCCS  
  CPPPC  
  CPPPC  
  CPPPC  
  SCCCS  
    s    
|----Layer 2|
         
         
  SCCCS  
  Cb sC  
  CB  C  
  C   C  
  SCdCS  
         
|----Layer 3|
         
         
  SCGCS  
  C   C  
  g   g  
  C   C  
  SCDCS  
   T T   
|----Layer 4|
         
         
  SCCCS  
  C T C  
  C   C  
  C   C  
  SCCCS  
         
|----Layer 5|
         
 ^^^^^^> 
 <PPPPP> 
 <P   P> 
 <P   P> 
 <P   P> 
 <PPPPP> 
 <ssssss 
|----Layer 6|
         
         
  <^^^>  
  <PPP>  
  <P P>  
  <PPP>  
  sssss  
         
|----Layer 7|
         
         
         
   <^^   
   <P>   
   sss   
         
         
}}

==== Materials ====

{| class="wikitable sortable mw-collapsible"
|-
! Name !! Total !! Layer 1 !! Layer 2 !! Layer 3 !! Layer 4 !! Layer 5 !! Layer 6 !! Layer 7 
|-
| {{BlockLink|Cobblestone}} || 43 || 12 || 11 || 8 || 12 || - || - || - 
|-
| {{BlockLink|Glass Pane}} || 3 || - || - || 3 || - || - || - || - 
|-
| {{ItemLink|Oak Door}} || 1 || - || 1 || - || - || - || - || - 
|-
| {{BlockLink|Oak Planks}} || 34 || 9 || - || - || - || 16 || 8 || 1 
|-
| {{BlockLink|Oak Stairs}} || 50 || 1 || 1 || - || - || 24 || 16 || 8 
|-
| {{BlockLink|Stripped Oak Log}} || 16 || 4 || 4 || 4 || 4 || - || - || - 
|-
| {{BlockLink|Torch}} || 3 || - || - || 2 || 1 || - || - || - 
|-
| {{BlockLink|White Bed}} || 1 || - || 1 || - || - || - || - || - 
|}<noinclude>
[[Category:Village blueprints]]

[[fr:Village/Structure/Plaines Petite Maison 1 plan]]
[[ja:村/構造/設計図/平原の小さな家1]]
[[zh:村庄/结构/图示/平原小型房屋1]]
</noinclude>