<noinclude>{{structure info}}</noinclude>

[[File:Taiga Large Farm 1.png|thumb|Large Farm 1 (Taiga)]]



==== Blueprint ====

{{layered blueprint|name=
Taiga Large Farm 1|default=Layer 1
|D=Dirt
|P=Pumpkin
|G=Grass Block+top
|S=Spruce Trapdoor
|F=Farmland
|W=Wheat
|A=Water+top
|C=Cobblestone Wall
|T=Torch
|R=Dirt Path+top
|O=Composter
|B=Cobblestone Stairs
            
|----Layer 1|
            
   D   R    
  GGGGGRDGG 
 D  GGRRGG  
   GDGRGGG  
  GGGGRGGG  
  GGGRRGGGD 
  GGGRRGG   
  GGDRGDG   
  DGRRGGGG  
    DD  D   
            
|----Layer 2|
            
   P SS SS  
   CSFF DFS 
 P SFF  FFS 
  SFAF FAFS 
 SFFFF BFS  
 SFFB  FFSP 
 SFAF  FFS  
 SFFO FAFS  
 SDF  FFSC  
  SS PSSP   
            
|----Layer 3|
            
            
   C WW PW  
    WW  WW  
   W W W W  
  WWWW  W   
  WW   WW   
  W W  WW   
  WW  W W   
  PW  WW C  
            
            
|----Layer 4|
            
            
   C        
            
            
            
            
            
            
         C  
            
            
|----Layer 5|
            
            
   T        
            
            
            
            
            
            
         T  
            
            
}}



==== Materials ====

{| class="wikitable sortable mw-collapsible"
|-
! Name !! Total !! Layer 1 !! Layer 2 !! Layer 3 !! Layer 4 !! Layer 5 
|-
| {{BlockLink|Cobblestone Stairs}} || 2 || - || 2 || - || - || - 
|-
| {{BlockLink|Cobblestone Wall}} || 6 || - || 2 || 2 || 2 || - 
|-
| {{BlockLink|Composter}} || 1 || - || 1 || - || - || - 
|-
| {{BlockLink|Dirt}} || 13 || 11 || 2 || - || - || - 
|-
| {{BlockLink|Farmland}} || 31 || - || 31 || - || - || - 
|-
| {{BlockLink|Grass Block}} || 43 || 43 || - || - || - || - 
|-
| {{BlockLink|Dirt Path}} || 13 || 13 || - || - || - || - 
|-
| {{BlockLink|Pumpkin}} || 7 || - || 5 || 2 || - || - 
|-
| {{BlockLink|Spruce Trapdoor}} || 24 || - || 24 || - || - || - 
|-
| {{BlockLink|Torch}} || 2 || - || - || - || - || 2 
|-
| {{BlockLink|Water}} || 4 || - || 4 || - || - || - 
|-
| {{BlockLink|Wheat}} || 31 || - || - || 31 || - || - 
|}<noinclude>
[[Category:Village blueprints]]

[[fr:Village/Structure/Taïga Grande Ferme 1 plan]]
[[zh:村庄/结构/图示/针叶林大型农田1]]
</noinclude>