<noinclude>{{structure info}}</noinclude>

[[File:Taiga Animal Pen 1.png|thumb|Animal Pen 1 (Taiga)]]



==== Blueprint ====

{{layered blueprint|name=
Taiga Animal Pen 1|default=Layer 1
|G=Grass Block+top
|S=Spruce Planks
|P=Spruce Trapdoor
|R=Spruce Fence
|U=Spruce Fence Gate
|T=Torch
|C=Spruce Stairs
          
|----Layer 1|
          
  PPPPPP  
 PGGGGGGP 
 PGGGGGGP 
 PGGGGGGP 
 PGGGGGGP 
 PGGGGGGP 
 PGGGGGGC 
 PGGGGGGP 
 PGGGGGGP 
 PGGGGGGP 
 PGGGGGGP 
 PGGGGGGP 
  PPPPPP  
          
|----Layer 2|
          
          
  RRRRRR  
  R    R  
  R    R  
  R    R  
  R    R  
  R    U  
  R P  R  
  RP P R  
  RP P R  
  R P  R  
  RRRRRR  
          
          
|----Layer 3|
          
          
  R    R  
          
          
          
       R  
          
       R  
          
          
          
  R    R  
          
          
|----Layer 4|
          
          
          
          
          
          
       R  
      PSP 
       R  
          
          
          
          
          
          
|----Layer 5|
          
          
          
          
          
          
          
       T  
          
          
          
          
          
          
          
}}



==== Materials ====

{| class="wikitable sortable mw-collapsible"
|-
! Name !! Total !! Layer 1 !! Layer 2 !! Layer 3 !! Layer 4 !! Layer 5 
|-
| {{BlockLink|Grass Block}} || 66 || 66 || - || - || - || - 
|-
| {{BlockLink|Spruce Fence}} || 37 || - || 29 || 6 || 2 || - 
|-
| {{BlockLink|Spruce Fence Gate}} || 1 || - || 1 || - || - || - 
|-
| {{BlockLink|Spruce Planks}} || 1 || - || - || - || 1 || - 
|-
| {{BlockLink|Spruce Stairs}} || 1 || 1 || - || - || - || - 
|-
| {{BlockLink|Spruce Trapdoor}} || 41 || 33 || 6 || - || 2 || - 
|-
| {{BlockLink|Torch}} || 1 || - || - || - || - || 1 
|}<noinclude>
[[Category:Village blueprints]]

[[fr:Village/Structure/Taïga Enclos 1 plan]]
[[ja:村/構造/設計図/タイガの牧柵1]]
[[zh:村庄/结构/图示/针叶林牲畜栏]]
</noinclude>