<noinclude>{{structure info}}</noinclude>

[[File:Savanna Meeting Point 3.png|thumb|Meeting Point 3 (Savanna)]]



==== Blueprint ====

{{layered blueprint|name=
Savanna Meeting Point 3|default=Layer 1
|A=Acacia Wood
|S=Acacia Slab
|C=Double Acacia Slab
|B=Bell
|D=Dirt Path+top
|T=Torch
|W=Water+top
|I=Acacia Fence
|R=Grass Block+top
             
|----Layer 1|
             
     DDD  R  
  R DDDDD    
  DDDDDDDDD  
 DDDDDDDDDDD 
 DDDADDDADDD 
 DDDDDDDDDDD 
  DDDDDDDDD  
   RDDDDD    
     DDD     
             
|----Layer 2|
             
             
             
             
   AAA AAA   
   AWA AWA   
   AAA AAA   
             
             
             
             
|----Layer 3|
             
             
             
             
   T I I T   
             
   T I I T   
             
             
             
             
|----Layer 4|
             
             
             
             
     I I     
      B      
     I I     
             
             
             
             
|----Layer 5|
             
             
             
             
     SSS     
     SCS     
     SSS     
             
             
             
             
|----Layer 6|
             
             
             
             
             
      T      
             
             
             
             
             
}}



==== Materials ====

{| class="wikitable sortable mw-collapsible"
|-
! Name !! Total !! Layer 1 !! Layer 2 !! Layer 3 !! Layer 4 !! Layer 5 !! Layer 6 
|-
| {{BlockLink|Acacia Fence}} || 8 || - || - || 4 || 4 || - || - 
|-
| {{BlockLink|Acacia Slab}} || 10 || - || - || - || - || 10 || - 
|-
| {{BlockLink|Acacia Wood}} || 18 || 2 || 16 || - || - || - || - 
|-
| {{BlockLink|Bell}} || 1 || - || - || - || 1 || - || - 
|-
| {{BlockLink|Grass Block}} || 3 || 3 || - || - || - || - || - 
|-
| {{BlockLink|Dirt Path}} || 65 || 65 || - || - || - || - || - 
|-
| {{BlockLink|Torch}} || 5 || - || - || 4 || - || - || 1 
|-
| {{BlockLink|Water}} || 2 || - || 2 || - || - || - || - 
|}<noinclude>
[[Category:Village blueprints]]

[[fr:Village/Structure/Savane Lieu de Rassemblement 3 plan]]
[[ja:村/構造/設計図/サバンナの集会所3]]
[[zh:村庄/结构/图示/热带草原会合点3]]
</noinclude>