<noinclude>{{structure info}}</noinclude>

[[File:Taiga Medium House 1.png|thumb|Medium House 1 (Taiga)]]



==== Blueprint ====

{{layered blueprint|name=
Taiga Medium House 1|default=Layer 1
|D=Dirt
|G=Grass Block+top
|S=Spruce Planks
|P=Spruce Log-rot-90
|R=Spruce Log+top
|C=Cobblestone
|U=Purple Bed+side+head-rot-180
|L=Purple Bed+side+foot-rot-180
|H=Chest-rot-180
|B=Blue Bed+side+foot
|E=Blue Bed+side+head
|T=Spruce Stairs
|W=Wall Torch-rot-270
|A=Dirt Path+top
|F=Spruce Fence
|p=Spruce Slab
|O=Wall Torch-rot-90
|I=Spruce Stairs-rot-180
|r=Spruce Door+bottom
|u=Spruce Door+top
|N=Cobblestone Stairs
|a=Wall Torch-rot-180
|l=Wall Torch
|c=Spruce Pressure Plate
|g=Large Fern
|h=Large Fern+bottom
|e=Fern
|s=Glass Pane
|d=Spruce Trapdoor
         
|----Layer 1|
         
 DDDDDDD 
 DDDDDDD 
 DDDDDDD 
 UL CDGD 
    NCGG 
 TTHCDGG 
 DDDDDDD 
 DDDDDDD 
         
|----Layer 2|
         
 DDDDGDG 
 DGDDDDD 
 DGGGDDD 
    CC N 
 W   r   
    CC   
 GGGGDDG 
 GGGGGGG 
         
|----Layer 3|
         
 AAAG G  
 D AAAAA 
 G   GGN 
 GGDCC   
 GG  u   
 GGDCC   
     GG  
         
         
|----Layer 4|
         
      e  
 T       
 p   he  
   CCC   
 F COCW  
   CCC   
     hh  
         
         
|----Layer 5|
         
         
         
 T  lg   
 p CCC   
 F C C   
   CCC   
    agg  
         
         
|----Layer 6|
         
         
         
  IIIII  
 TISSSI  
 SISSSI  
  ISSSI  
  IIIII  
         
         
|----Layer 7|
         
         
         
  RSSSR  
  STFTS  
  r   S  
  S BES  
  RSSSR  
         
         
|----Layer 8|
         
         
 PPPPPPP 
  RSSSR  
  S c Sd 
  u   s  
  S   Sd 
  RSSSR  
 PPPPPPP 
         
|----Layer 9|
         
         
         
 PPPPPPP 
  S   S  
 OS  OS  
  S   S  
 PPPPPPP 
         
         
|----Layer 10|
         
         
         
         
 PPPPPPP 
  S   S  
 PPPPPPP 
         
         
         
|----Layer 11|
         
         
         
         
         
 PPPPPPP 
         
         
         
         
}}



==== Materials ====

{| class="wikitable sortable mw-collapsible"
|-
! Name !! Total !! Layer 1 !! Layer 2 !! Layer 3 !! Layer 4 !! Layer 5 !! Layer 6 !! Layer 7 !! Layer 8 !! Layer 9 !! Layer 10 !! Layer 11 
|-
| {{BlockLink|Blue Bed}} || 1 || - || - || - || - || - || - || 1 || - || - || - || - 
|-
| {{BlockLink|Chest}} || 1 || 1 || - || - || - || - || - || - || - || - || - || - 
|-
| {{BlockLink|Cobblestone}} || 27 || 3 || 4 || 4 || 8 || 8 || - || - || - || - || - || - 
|-
| {{BlockLink|Cobblestone Stairs}} || 3 || 1 || 1 || 1 || - || - || - || - || - || - || - || - 
|-
| {{BlockLink|Dirt}} || 58 || 38 || 17 || 3 || - || - || - || - || - || - || - || - 
|-
| {{BlockLink|Fern}} || 2 || - || - || - || 2 || - || - || - || - || - || - || - 
|-
| {{BlockLink|Glass Pane}} || 1 || - || - || - || - || - || - || - || 1 || - || - || - 
|-
| {{BlockLink|Grass Block}} || 36 || 5 || 18 || 13 || - || - || - || - || - || - || - || - 
|-
| {{BlockLink|Dirt Path}} || 8 || - || - || 8 || - || - || - || - || - || - || - || - 
|-
| {{BlockLink|Large Fern}} || 6 || - || - || - || 3 || 3 || - || - || - || - || - || - 
|-
| {{BlockLink|Purple Bed}} || 1 || 1 || - || - || - || - || - || - || - || - || - || - 
|-
| {{BlockLink|Spruce Door}} || 2 || - || 1 || - || - || - || - || 1 || - || - || - || - 
|-
| {{BlockLink|Spruce Fence}} || 3 || - || - || - || 1 || 1 || - || 1 || - || - || - || - 
|-
| {{BlockLink|Spruce Log}} || 57 || - || - || - || - || - || - || 4 || 18 || 14 || 14 || 7 
|-
| {{BlockLink|Spruce Planks}} || 39 || - || - || - || - || - || 10 || 11 || 10 || 6 || 2 || - 
|-
| {{BlockLink|Spruce Pressure Plate}} || 1 || - || - || - || - || - || - || - || 1 || - || - || - 
|-
| {{BlockLink|Spruce Slab}} || 2 || - || - || - || 1 || 1 || - || - || - || - || - || - 
|-
| {{BlockLink|Spruce Stairs}} || 23 || 2 || - || - || 1 || 1 || 17 || 2 || - || - || - || - 
|-
| {{BlockLink|Spruce Trapdoor}} || 2 || - || - || - || - || - || - || - || 2 || - || - || - 
|-
| {{BlockLink|Torch}} || 7 || - || 1 || - || 2 || 2 || - || - || - || 2 || - || - 
|}
<noinclude>
[[Category:Village blueprints]]

[[fr:Village/Structure/Taïga Maison Moyenne 1 plan]]
[[zh:村庄/结构/图示/针叶林中型房屋1]]
</noinclude>