<noinclude>{{structure info}}</noinclude>

[[File:Snowy Tundra Meeting Point 1.png|thumb|Meeting point 1 (Snowy tundra)]]



==== Blueprint ====

{{layered blueprint
|name=Snowy Meeting Point 1 snowy_meeting_point_1
|default=Layer 2
|g=Grass Block+top
|d=Dirt
|p=Dirt Path+top
|w=Stripped Spruce Wood
|P=Packed Ice
|s=Snow
|b=Bell
              
|----Layer 0|
              
 ggpppggggggg 
 pppppppppppp 
 ppdppddddppp 
 pppppddddppp 
 gppppddddppg 
 ggpppddddppg 
 gggppppppppg 
 ggggggggpppg 
              
|----Layer 1|
              
              
 s       s ss 
   P  wwww    
      wPPw    
 s    wPPw  s 
 s    wwww  s 
 s          s 
 ssssss     s 
              
|----Layer 2|
              
              
              
   b  ssss    
      sPPs    
      sPPs    
      ssss    
|----Layer 3-5|
              
              
              
              
       P      
        P     
|----Layer 6-7|
              
              
              
              
       P      
              
}}

==== Materials ====

{| class="wikitable sortable mw-collapsible"
|-
! Name !! Total !! Layer 0 !! Layer 1 !! Layer 2 !! Layer 3 !! Layer 4 !! Layer 5 !! Layer 6 !! Layer 7 
|-
| {{BlockLink|Bell}} || 1 || - || - || 1 || - || - || - || - || - 
|-
| {{BlockLink|Dirt}} || 17 || 17 || - || - || - || - || - || - || - 
|-
| {{BlockLink|Dirt Path}} || 52 || 52 || - || - || - || - || - || - || - 
|-
| {{BlockLink|Grass Block}} || 27 || 27 || - || - || - || - || - || - || - 
|-
| {{BlockLink|Packed Ice}} || 17 || - || 5 || 4 || 2 || 2 || 2 || 1 || 1 
|-
| {{BlockLink|Snow}} || 29 || - || 17 || 12 || - || - || - || - || - 
|-
| {{BlockLink|Stripped Spruce Wood}} || 12 || - || 12 || - || - || - || - || - || - 
|}<noinclude>
[[Category:Village blueprints]]

[[fr:Village/Structure/Toundra enneigée Lieu de Rassemblement 1 plan]]
[[ja:村/構造/設計図/雪原の集会所1]]
[[zh:村庄/结构/图示/雪原会合点1]]
</noinclude>