<noinclude>{{structure info}}</noinclude>

[[File:Snowy Tundra Fletcher House 1.png|thumb|Fletcher house 1 (Snowy tundra)]]



==== Blueprint ====

{{layered blueprint
|name=Snowy Fletcher House 1 snowy_fletcher_house_1
|default=Layer 2
|l=Stripped Spruce Log+top
|a=Stripped Spruce Log
|A=Stripped Spruce Log-rot90
|w=Stripped Spruce Wood
|s=Snow
|p=Spruce Planks
|o=Spruce Door+bottom
|O=Spruce Door+top
|F=Fletching Table
|f=Spruce Fence
|b=Blue Carpet
|g=Glass Pane-rot90
|t=Torch
|T=Torch-rot180
|h=Spruce Stairs
|i=Spruce Stairs-rot90
|j=Spruce Stairs-rot180
|k=Spruce Stairs-rot270
         
|----Layer 1|
         
 sssssss 
 slwwwls 
 swplpws 
 swlplws 
 swplpw  
 swlplws 
 swplpws 
 slawal  
 ssihkss 
         
|----Layer 2|
         
         
  llall  
  A F A  
  l   l  
  A  hA  
  l  fl  
  A  jA  
  laoal  
         
|----Layer 3|
         
 p     p 
 plagalp 
 pl   lp 
 pA   Ap 
 pl   lp 
 pA  bAp 
 pl   lp 
 plaOalp 
 p     p 
         
|----Layer 4|
         
  p   p  
  pagap  
  p   p  
  p   p  
  p   p  
  p   p  
  p   p  
  paaap  
  p   p  
         
|----Layer 5|
         
  p   p  
  plalp  
  p T p  
  p   p  
  p   p  
  p   p  
  p t p  
  plalp  
  p   p  
         
|----Layer 6|
         
   p p   
   plp   
   p p   
   p p   
   p p   
   p p   
   p p   
   pap   
   p p   
         
|----Layer 7|
         
    p    
    p    
    p    
    p    
    p    
    p    
    p    
    p    
    p    
         
}}



==== Materials ====

{| class="wikitable sortable mw-collapsible"
|-
! Name !! Total !! Layer 1 !! Layer 2 !! Layer 3 !! Layer 4 !! Layer 5 !! Layer 6 !! Layer 7 
|-
| {{BlockLink|Blue Carpet}} || 1 || - || - || 1 || - || - || - || - 
|-
| {{BlockLink|Fletching Table}} || 1 || - || 1 || - || - || - || - || - 
|-
| {{BlockLink|Glass Pane}} || 2 || - || - || 1 || 1 || - || - || - 
|-
| {{BlockLink|Snow}} || 23 || 23 || - || - || - || - || - || - 
|-
| {{ItemLink|Spruce Door}} || 1 || - || 1 || - || - || - || - || - 
|-
| {{BlockLink|Spruce Fence}} || 1 || - || 1 || - || - || - || - || - 
|-
| {{BlockLink|Spruce Planks}} || 89 || 8 || - || 18 || 18 || 18 || 18 || 9 
|-
| {{BlockLink|Spruce Stairs}} || 5 || 3 || 2 || - || - || - || - || - 
|-
| {{BlockLink|Stripped Spruce Log}} || 63 || 13 || 19 || 18 || 5 || 6 || 2 || - 
|-
| {{BlockLink|Stripped Spruce Wood}} || 16 || 16 || - || - || - || - || - || - 
|-
| {{BlockLink|Torch}} || 2 || - || - || - || - || 2 || - || - 
|}<noinclude>
[[Category:Village blueprints]]

[[fr:Village/Structure/Toundra enneigée Maison de Fléchier 1 plan]]
[[ja:村/構造/設計図/雪原の矢師の家1]]
[[zh:村庄/结构/图示/雪原制箭师房屋]]
</noinclude>