<noinclude>{{structure info}}</noinclude>

[[File:Desert Medium House 1.png|thumb|Medium house 1 (Desert)]]



==== Blueprint ====

{{layered blueprint|name=Desert Medium House 1
|default=Layer 1
|S=Sand
|M=Smooth Sandstone
|C=Cut Sandstone
|T=Terracotta
|H=Chest-rot270
|L=Lime Bed+top+foot-rot-90
|I=Lime Bed+top+head-rot-90
|A=Sandstone Slab+Bottom
|a=Sandstone Slab+Top
|P=Potted Cactus
|W=Wall Torch-rot-180
|J=Jungle Door+up+left
|U=Jungle Door+top
|O=Wall Torch
         
|----Layer 0|
         
 SSSSSSS 
 SMMMMMS 
 SMMMMMS 
 SMMMMMS 
 SSSMSSS 
 SSSSSSS 
         
|----Layer 1|
         
 MMMMMMM 
 MI T IM 
 ML   LM 
 MH    M 
 MMMJMMM 
  P      
         
|----Layer 2|
         
 MMAMAMM 
 M  P  M 
 A     A 
 M     M 
 MAMUMAM 
   W W   
         
|----Layer 3|
         
 MMaMaMM 
 MW   WM 
 a     a 
 M  O  M 
 MaMMMaM 
         
         
|----Layer 4|
         
 CCCCCCC 
 CCCCCCC 
 CCCCCCC 
 CCCCCCC 
 CCCCCCC 
         
         
|----Layer 5|
         
 A  A  A 
         
 A     A 
         
 A  A  A 
         
         
}}



==== Materials ====

{| class="wikitable sortable mw-collapsible"
|-
! Name !! Total !! Layer 0 !! Layer 1 !! Layer 2 !! Layer 3 !! Layer 4 !! Layer 5 
|-
| {{BlockLink|Chest}} || 1 || - || 1 || - || - || - || - 
|-
| {{BlockLink|Cut Sandstone}} || 35 || - || - || - || - || 35 || - 
|-
| {{ItemLink|Jungle Door}} || 1 || - || 1 || - || - || - || - 
|-
| {{BlockLink|Lime Bed}} || 2 || - || 2 || - || - || - || - 
|-
| {{BlockLink|Potted Cactus}} || 2 || - || 1 || 1 || - || - || - 
|-
| {{BlockLink|Sand}} || 26 || 26 || - || - || - || - || - 
|-
| {{BlockLink|Sandstone Slab}} || 20 || - || - || 6 || 6 || - || 8 
|-
| {{BlockLink|Smooth Sandstone}} || 62 || 16 || 19 || 13 || 14 || - || - 
|-
| {{BlockLink|Terracotta}} || 1 || - || 1 || - || - || - || - 
|-
| {{BlockLink|Torch}} || 5 || - || - || 2 || 3 || - || - 
|}<noinclude>
[[Category:Village blueprints]]

[[fr:Village/Structure/Désert Maison Moyenne 1 plan]]
[[ja:村/構造/設計図/砂漠の中くらいの家1]]
[[zh:村庄/结构/图示/沙漠中型房屋1]]
</noinclude>