<noinclude>{{structure info}}</noinclude>

[[File:Plains temple 3.png|thumb|Temple 2 (Plains)]]



==== Blueprint ====

{{layered blueprint
|name=Plains Temple 2
|default=Layer 2
|O=Oak Log+top
|o=Oak Log-rot90
|C=Cobblestone
|W=White Terracotta
|A=Oak Planks
|B=Brewing Stand
|K=Oak Stairs
|i=Oak Stairs-rot90
|S=Oak Stairs-rot-180
|r=Oak Stairs-rot270
|L=Cobblestone Wall
|T=Torch
|Y=Yellow Stained Glass Pane
|H=White Stained Glass Pane
|E=Cobblestone Stairs
|<=Cobblestone Stairs-rot90
|>=Cobblestone Stairs-rot270
|D=Oak Door+bottom
|R=Oak Door+top
|I=Yellow Stained Glass Pane-rot-90
|a=Wall Torch
|l=Wall Torch-rot-180
         
|----Layer 1|
         
         
  OCCCO  
  CAAAC  
  CAAAC  
  CAAAC  
  OAAAO  
  CAAAC  
  CAAAC  
  CAAAC  
  OCCCO  
  L<E>L  
         
|----Layer 2|
         
         
  OWWWO  
  W   W  
  W B W  
  W   W  
  Or iO  
  Wr iW  
  Wr iW  
  Wr iW  
  OWDWO  
  T   T  
         
|----Layer 3|
         
         
  OWIWO  
  W   W  
  Y   Y  
  W   W  
  O   O  
  W   W  
  Y   Y  
  W   W  
  OWRWO  
         
         
|----Layer 4|
         
    a    
  OWWWO  
  W   W  
  H   H  
  W   W  
  O   O  
  W   W  
  H   H  
  W   W  
  OWWWO  
         
         
|----Layer 5|
         
 ir   ir 
 iOOWOOr 
 KW l WK 
  W   W  
 SW   WS 
 iO   Or 
 KW   WK 
  W   W  
 SW a WS 
 iOOWOOr 
 ir   ir 
         
|----Layer 6|
         
  ir ir  
  iooor  
 SA   AS 
 iA   Ar 
 KA   AK 
  i   r  
 SA   AS 
 iA   Ar 
 KA   AK 
  iooor  
  ir ir  
         
|----Layer 7|
         
   iAr   
   iAr   
   iAr   
   iAr   
   iAr   
   iAr   
   iAr   
   iAr   
   iAr   
   iAr   
   iAr   
         
}}



==== Materials ====

{| class="wikitable sortable mw-collapsible"
|-
! Name !! Total !! Layer 1 !! Layer 2 !! Layer 3 !! Layer 4 !! Layer 5 !! Layer 6 !! Layer 7 
|-
| {{BlockLink|Brewing Stand}} || 1 || - || 1 || - || - || - || - || - 
|-
| {{BlockLink|Cobblestone}} || 18 || 18 || - || - || - || - || - || - 
|-
| {{BlockLink|Cobblestone Stairs}} || 3 || 3 || - || - || - || - || - || - 
|-
| {{BlockLink|Cobblestone Wall}} || 2 || 2 || - || - || - || - || - || - 
|-
| {{ItemLink|Oak Door}} || 1 || - || 1 || - || - || - || - || - 
|-
| {{BlockLink|Oak Log}} || 40 || 6 || 6 || 6 || 6 || 10 || 6 || - 
|-
| {{BlockLink|Oak Planks}} || 44 || 21 || - || - || - || - || 12 || 11 
|-
| {{BlockLink|Oak Stairs}} || 78 || - || 8 || - || - || 22 || 26 || 22 
|-
| {{BlockLink|Torch}} || 5 || - || 2 || - || 1 || 2 || - || - 
|-
| {{BlockLink|White Stained Glass Pane}} || 4 || - || - || - || 4 || - || - || - 
|-
| {{BlockLink|White Terracotta}} || 57 || - || 17 || 12 || 14 || 14 || - || - 
|-
| {{BlockLink|Yellow Stained Glass Pane}} || 5 || - || - || 5 || - || - || - || - 
|}<noinclude>
[[Category:Village blueprints]]

[[fr:Village/Structure/Plaines Temple 3 plan]]
[[ja:村/構造/設計図/平原の礼拝所2]]
[[zh:村庄/结构/图示/平原教堂1]]
</noinclude>