<noinclude>{{structure info}}</noinclude>

[[File:Savanna Animal Pen 1.png|thumb|Animal Pen 1 (Savanna)]]



==== Blueprint ====

{{layered blueprint|name=
Savanna Animal Pen 1|default=Layer 2
|A=acacia log+top
|D=dirt
|G=grass block+top
|C=acacia planks
|I=acacia slab
|J=jigsaw
|S=jigsaw
|F=acacia fence
|E=acacia fence
|N=acacia fence gate
|a=acacia fence
|c=acacia fence
|i=acacia fence
|f=acacia fence
|L=acacia slab
|B=acacia slab
|W=water+top
|e=acacia fence
|n=acacia fence
|!=acacia fence
|T=acacia stairs
           
|----Layer 1|
           
  AAAAAAAA 
  AGGGDGGA 
  AGGGDDDA 
  ADDGGGDA 
 TADGGDGDA 
  AGGDGGDA 
  ADGGDDDA 
  ADDDDDDA 
  AAAAAAAA 
           
|----Layer 2|
           
  acccccc! 
  E      E 
  E   CCAn 
  E   CWAn 
  N  iCWAn 
  E   CWAn 
  E   CCAn 
  E      E 
  Fcccccce 
           
|----Layer 3|
           
     f  BL 
        BL 
        IL 
        IL 
     f  IL 
        IL 
        IL 
        BL 
     f  BL 
           
|----Layer 4|
           
     fBL   
      BL   
      BL   
      BL   
     fBL   
      BL   
      BL   
      BL   
     fBL   
           
|----Layer 5|
           
     L     
     L     
     L     
     L     
     L     
     L     
     L     
     L     
     L     
           
}}



==== Materials ====

{| class="wikitable sortable mw-collapsible"
|-
! Name !! Total !! Layer 1 !! Layer 2 !! Layer 3 !! Layer 4 !! Layer 5 
|-
| {{BlockLink|Acacia Fence}} || 36 || - || 30 || 3 || 3 || - 
|-
| {{BlockLink|Acacia Fence Gate}} || 1 || - || 1 || - || - || - 
|-
| {{BlockLink|Acacia Log}} || 35 || 30 || 5 || - || - || - 
|-
| {{BlockLink|Acacia Planks}} || 7 || - || 7 || - || - || - 
|-
| {{BlockLink|Acacia Slab}} || 45 || - || - || 18 || 18 || 9 
|-
| {{BlockLink|Acacia Stairs}} || 1 || 1 || - || - || - || - 
|-
| {{BlockLink|Dirt}} || 22 || 22 || - || - || - || - 
|-
| {{BlockLink|Grass Block}} || 20 || 20 || - || - || - || - 
|-
| {{BlockLink|Water}} || 3 || - || 3 || - || - || - 
|}<noinclude>
[[Category:Village blueprints]]

[[fr:Village/Structure/Savane Enclos 1 plan]]
[[ja:村/構造/設計図/サバンナの牧柵1]]
[[zh:村庄/结构/图示/热带草原牲畜栏1]]
</noinclude>