<noinclude>{{structure info}}</noinclude>

[[File:Desert Weaponsmith 1.png|thumb|Weaponsmith 1 (Desert)]]



==== Blueprint ====

{{layered blueprint|name=Desert Weaponsmith 1
|default=Layer 1
|C=Cut Sandstone
|S=Smooth Sandstone
|O=Cobblestone
|H=Chest-rot-180
|F=Furnace
|M=Smooth Sandstone Stairs
|A=Sandstone Slab+Bottom
|a=Sandstone Slab+Top
|T=Smooth Sandstone Slab
|N=Sandstone Wall
|D=Smooth Sandstone Stairs-rot-180
|I=Iron Bars
|P=Potted Cactus
|W=Wall Torch-rot-180
|G=Grindstone
|L=Lava+top
         
|----Layer 1|
         
  CCCCCC 
  CCCCCC 
 MCCCCCC 
 MCCCCCC 
 MCCCCCC 
 CCCCCCC 
 CSSSSC  
 CSSSSC  
 CSSSSC  
 CCCCCC  
         
|----Layer 2|
         
  CCCCCC 
  COOOOS 
    OLOS 
    OLOS 
    OOOS 
 C  CSCC 
 S    S  
 S   GS  
 SMH  S  
 CSSSSC  
         
|----Layer 3|
         
   P  CC 
  NIIIOS 
      OS 
      OS 
     FOS 
 C  CSCC 
 S    S  
 A    A  
 S    S  
 CSSSSC  
         
|----Layer 4|
         
      CC 
  NIIIOS 
      OS 
      OS 
     FOS 
 CDDCSCC 
 S  W S  
 a    a  
 S    S  
 CSSSSC  
         
|----Layer 5|
         
      CC 
  NIIIOS 
      OS 
      OS 
      OS 
 CSSCSSC 
 S    S  
 S    S  
 S    S  
 CSSSSC  
         
|----Layer 6|
         
      CC 
  TTTTTT 
  TT  TT 
  TT  TT 
  TTTTTT 
 CTTTTTC 
 TTTTTT  
 TTTTTT  
 TTTTTT  
 CTTTTC  
         
}}



==== Materials ====

{| class="wikitable sortable mw-collapsible"
|-
! Name !! Total !! Layer 1 !! Layer 2 !! Layer 3 !! Layer 4 !! Layer 5 !! Layer 6 
|-
| {{BlockLink|Chest}} || 1 || - || 1 || - || - || - || - 
|-
| {{BlockLink|Cobblestone}} || 23 || - || 11 || 4 || 4 || 4 || - 
|-
| {{BlockLink|Cut Sandstone}} || 91 || 49 || 13 || 8 || 8 || 7 || 6 
|-
| {{BlockLink|Furnace}} || 2 || - || - || 1 || 1 || - || - 
|-
| {{BlockLink|Grindstone}} || 1 || - || 1 || - || - || - || - 
|-
| {{BlockLink|Iron Bars}} || 9 || - || - || 3 || 3 || 3 || - 
|-
| {{BlockLink|Lava}} || 2 || - || 2 || - || - || - || - 
|-
| {{BlockLink|Potted Cactus}} || 1 || - || - || 1 || - || - || - 
|-
| {{BlockLink|Sandstone Slab}} || 4 || - || - || 2 || 2 || - || - 
|-
| {{BlockLink|Sandstone Wall}} || 3 || - || - || 1 || 1 || 1 || - 
|-
| {{BlockLink|Smooth Sandstone}} || 71 || 12 || 15 || 13 || 13 || 18 || - 
|-
| {{BlockLink|Smooth Sandstone Slab}} || 47 || - || - || - || - || - || 47 
|-
| {{BlockLink|Smooth Sandstone Stairs}} || 6 || 3 || 1 || - || 2 || - || - 
|-
| {{BlockLink|Torch}} || 1 || - || - || - || 1 || - || - 
|}
<noinclude>
[[Category:Village blueprints]]

[[fr:Village/Structure/Désert Forge d'Armes 1 plan]]
[[ja:村/構造/設計図/砂漠の武器鍛冶屋1]]
[[zh:村庄/结构/图示/沙漠铁匠铺]]
</noinclude>