<noinclude>{{structure info}}</noinclude>

[[File:Desert Farm 2.png|thumb|Farm 2 (Desert)]]



==== Blueprint ====

{{layered blueprint|name=Village Desert Houses desert_farm_2
|default=Layer 2
|S=Smooth Sandstone Stairs
|R=Smooth Sandstone Stairs-rot90
|B=Smooth Sandstone Stairs-rot180
|r=Smooth Sandstone Stairs-rot270
|c=Composter
|s=Smooth Sandstone
|T=Jungle Trapdoor
|F=Farmland+moist
|W=Water+top
|w=Wheat
|----Layer 0|
            
            
            
    s       
    s       
    s       
            
            
            
|----Layer 1|
            
 RBBBBBr    
 RFFFFFr    
 RFFFFFrBBB 
 RFFWFFsssr 
 RFFFFFrSSr 
 RFFFFFr    
 SSSSSSr    
            
|----Layer 2|
            
            
  wwwww     
  wwwww  T  
  ww ww TcT 
  wwwww  T  
  wwwww     
            
            
}}



==== Materials ====

{| class="wikitable sortable mw-collapsible"
|-
! Name !! Total !! Layer 0 !! Layer 1 !! Layer 2 
|-
| {{BlockLink|Composter}} || 1 || - || - || 1 
|-
| {{BlockLink|Farmland}} || 24 || - || 24 || - 
|-
| {{BlockLink|Jungle Trapdoor}} || 4 || - || - || 4 
|-
| {{BlockLink|Smooth Sandstone}} || 6 || 3 || 3 || - 
|-
| {{BlockLink|Smooth Sandstone Stairs}} || 30 || - || 30 || - 
|-
| {{BlockLink|Water}} || 1 || - || 1 || - 
|-
| {{BlockLink|Wheat}} || 24 || - || - || 24 
|}<noinclude>
[[Category:Village blueprints]]

[[fr:Village/Structure/Désert Ferme 2 plan]]
[[ja:村/構造/設計図/砂漠の畑2]]
[[zh:村庄/结构/图示/沙漠小型农田2]]
</noinclude>