<noinclude>{{structure info}}</noinclude>

[[File:Snowy Tundra Butchers Shop 2.png|thumb|Butchers shop 2 (Snowy tundra)]]



==== Blueprint ====

{{layered blueprint
|name=Snowy Butchers Shop 2 snowy_butchers_shop_2
|default=Layer 1
|g=Grass Block+top
|d=Dirt
|S=Snow
|s=Snow Block
|o=Spruce Door+bottom
|O=Spruce Door+top
|f=Spruce Fence
|p=Spruce Planks
|a=Spruce Stairs-rot270
|t=Torch
|l=Lantern
|m=Smoker
       
|----Layer 0|
       
 ggggg 
 ggdgg 
 ggggg 
 ggggg 
 gdgdg 
 ddggd 
 ddggd 
 ddggd 
 gdgdg 
       
|----Layer 1|
       
 fffff 
 f m f 
 fS  f 
 fS  f 
 fsosf 
 sa fs 
 spS s 
 spSSs 
 SsosS 
       
|----Layer 2|
       
       
       
     f 
       
  sOs  
 s  ts 
 s   s 
 s   s 
  sOs  
       
|----Layer 3|
       
       
       
    lf 
       
  sss  
  s s  
  s s  
  s s  
  sss  
       
|----Layer 4|
       
       
       
    ff 
       
       
   s   
   s   
   s   
       
}}

==== Materials ====

{| class="wikitable sortable mw-collapsible"
|-
! Name !! Total !! Layer 0 !! Layer 1 !! Layer 2 !! Layer 3 !! Layer 4 
|-
| {{BlockLink|Dirt}} || 14 || 14 || - || - || - || - 
|-
| {{BlockLink|Grass Block}} || 32 || 32 || - || - || - || - 
|-
| {{BlockLink|Lantern}} || 1 || - || - || - || 1 || - 
|-
| {{BlockLink|Smoker}} || 1 || - || 1 || - || - || - 
|-
| {{BlockLink|Snow}} || 7 || - || 7 || - || - || - 
|-
| {{BlockLink|Snow Block}} || 35 || - || 10 || 10 || 12 || 3 
|-
| {{ItemLink|Spruce Door}} || 2 || - || 2 || - || - || - 
|-
| {{BlockLink|Spruce Fence}} || 17 || - || 13 || 1 || 1 || 2 
|-
| {{BlockLink|Spruce Planks}} || 2 || - || 2 || - || - || - 
|-
| {{BlockLink|Spruce Stairs}} || 1 || - || 1 || - || - || - 
|-
| {{BlockLink|Torch}} || 1 || - || - || 1 || - || - 
|}<noinclude>
[[Category:Village blueprints]]

[[fr:Village/Structure/Toundra enneigée Échoppe de Boucher 2 plan]]
[[ja:村/構造/設計図/雪原の肉屋2]]
[[zh:村庄/结构/图示/雪原肉铺2]]
</noinclude>