<noinclude>{{structure info}}</noinclude>

[[File:Plains Fletcher House 1.png|thumb|Fletcher House 1 (Plains)]]



==== Blueprint ====

{{layered blueprint
|name=Village Plains Fletcher House 1 plains_fletcher_house_1
|default=Layer 1
|c=Cobblestone
|e=Potted Dandelion
|d=Dirt
|D=Dirt Path+top
|F=Fletching Table-rot270
|P=Glass Pane
|a=Glass Pane-rot90
|g=Grass Block+top
|k=Oak Door+bottom
|K=Oak Door+top
|f=Oak Fence
|l=Oak Log
|O=Oak Log-rot90
|o=Oak Log+top
|p=Oak Planks
|s=Oak Slab
|v=Oak Stairs
|x=Oak Stairs-rot180
|y=Oak Stairs-rot270
|z=Oak Stairs-rot90
|t=Torch
|T=Torch-rot180
|W=White Wool
|r=Yellow Carpet
|Y=Yellow Wool
|b=Short Grass
|B=Tall Grass
|A=Tall Grass+bottom
             
|----Layer 0|
             
 ggggggggggg 
 gdddddddddg 
 gdpppppppdg 
 gdpppppppdg 
 gddpppppddg 
 gggdpppdggg 
 ggggdpdgggg 
 gggggDggggg 
 gggggDggggg 
             
|----Layer 1|
             
             
  occccccco  
  cF     pc  
  c  rrr pc  
  oc     co  
    p   p    
     pkp     
         b b 
     f f bAA 
             
|----Layer 2|
             
     t t     
  ocacacaco  
  P      eP  
  P       P  
  oc     co  
    p   p    
     pKp     
             
     f f  BB 
             
|----Layer 3|
             
             
  occccccco  
  c       c  
  c       c  
  oc     co  
    p t p    
     ppp     
      T      
     f f     
             
|----Layer 4|
             
 yyyz   xyyy 
 voOOOOOOOov 
  l  T T  l  
  l       l  
 yoc     coy 
 vvxp   pzvv 
    xpppz    
     sWs     
     sYs     
             
|----Layer 5|
             
    xz xz    
 yyyycccyyyy 
 vc x   z cv 
 yc x   z cy 
 vvvv   vvvv 
    xp pz    
     xpz     
             
             
             
|----Layer 6|
             
     xpz     
     xpz     
 yyyyxpzyyyy 
 vvvvvpvvvvv 
     xpz     
     xpz     
             
             
             
             
}}

All oak slabs in layer 4 are bottom slabs.



==== Materials ====

{|class="wikitable sortable mw-collapsible"
|-
! Name !! Total !! Layer 0 !! Layer 1 !! Layer 2 !! Layer 3 !! Layer 4 !! Layer 5 !! Layer 6 
|-
| {{BlockLink|Cobblestone}} || 41 || - || 13 || 6 || 13 || 2 || 7 || - 
|-
| {{BlockLink|Dirt}} || 21 || 21 || - || - || - || - || - || - 
|-
| {{BlockLink|Dirt Path}} || 2 || 2 || - || - || - || - || - || - 
|-
| {{BlockLink|Fletching Table}} || 1 || - || 1 || - || - || - || - || - 
|-
| {{BlockLink|Glass Pane}} || 7 || - || - || 7 || - || - || - || - 
|-
| {{BlockLink|Short Grass}} || 3 || - || 3 || - || - || - || - || - 
|-
| {{BlockLink|Grass Block}} || 53 || 53 || - || - || - || - || - || - 
|-
| {{ItemLink|Oak Door}} || 1 || - || 1 || - || - || - || - || - 
|-
| {{BlockLink|Oak Fence}} || 6 || - || 2 || 2 || 2 || - || - || - 
|-
| {{BlockLink|Oak Log}} || 27 || - || 4 || 4 || 4 || 15 || - || - 
|-
| {{BlockLink|Oak Planks}} || 52 || 23 || 6 || 4 || 5 || 5 || 3 || 6 
|-
| {{BlockLink|Oak Slab}} || 4 || - || - || - || - || 4 || - || - 
|-
| {{BlockLink|Oak Stairs}} || 80 || - || - || - || - || 20 || 32 || 28 
|-
| {{BlockLink|Potted Dandelion}} || 1 || - || - || 1 || - || - || - || - 
|-
| {{BlockLink|Tall Grass}} || 2 || - || 2 || - || - || - || - || - 
|-
| {{BlockLink|Torch}} || 6 || - || - || 2 || 2 || 2 || - || - 
|-
| {{BlockLink|White Wool}} || 1 || - || - || - || - || 1 || - || - 
|-
| {{BlockLink|Yellow Carpet}} || 3 || - || 3 || - || - || - || - || - 
|-
| {{BlockLink|Yellow Wool}} || 1 || - || - || - || - || 1 || - || - 
|}

<noinclude>
[[Category:Village blueprints]]

[[fr:Village/Structure/Plaines Maison de Fléchier 1 plan]]
[[ja:村/構造/設計図/平原の矢細工師の家1]]
[[zh:村庄/结构/图示/平原制箭师房屋]]
</noinclude>