<noinclude>{{structure info}}</noinclude>

[[File:Savanna Tool Smith 1.png|thumb|Tool Smith 1 (Savanna)]]



==== Blueprint ====

{{layered blueprint|name=
Savanna Tool Smith 1|default=Layer 1
|G=Grass Block+top
|A=Acacia Planks
|D=Dirt
|C=Acacia Log+top
|I=Acacia Log
|S=Smithing Table
|B=Brown Wall Banner
|R=Short Grass
|F=Acacia Fence
|L=Acacia Slab
|O=Acacia Door+bottom
|c=Acacia Door+top
|T=Acacia Stairs
|P=Dirt Path+top
|N=Glass Pane-rot-90
|W=Wall Torch-rot-180
             
|----Layer 1|
             
 GGGGGGGGGGG 
 GGGGDDDGGGG 
 GGGDAAADGGG 
 GGGAAAAAGGG 
 GGGDAAADGGG 
 GGGGDADGGGG 
 GGGGDPGGGGG 
             
|----Layer 2|
             
     RRRR  R 
   R CCCRRRR 
  FRCTSTCRFR 
  R O   OR R 
  F C   CRF  
    RCOCR RR 
 R  R   RRR  
             
|----Layer 3|
             
             
     CNC     
  F C   C F  
    c   c    
  F C   C F  
     CcC     
             
             
|----Layer 4|
             
             
     CIC     
  F C W C F  
    I   I    
  F C   C F  
     CIC     
      W      
             
|----Layer 5|
             
    TTTTT    
  BBAAAAABB  
 BAAA   AAAB 
 BALA   ALAB 
 BAAA   AAAB 
  BBAAAAABB  
    TTTTT    
             
|----Layer 6|
             
             
    TTTTT    
    TAAAT    
    TAAAT    
    TAAAT    
    TTTTT    
             
             
|----Layer 7|
             
             
             
     TTT     
     TAT     
     TTT     
             
             
             
}}



==== Materials ====

{| class="wikitable sortable mw-collapsible"
|-
! Name !! Total !! Layer 1 !! Layer 2 !! Layer 3 !! Layer 4 !! Layer 5 !! Layer 6 !! Layer 7 
|-
| {{BlockLink|Acacia Door}} || 3 || - || 3 || - || - || - || - || - 
|-
| {{BlockLink|Acacia Fence}} || 12 || - || 4 || 4 || 4 || - || - || - 
|-
| {{BlockLink|Acacia Log}} || 29 || - || 9 || 8 || 12 || - || - || - 
|-
| {{BlockLink|Acacia Planks}} || 48 || 12 || - || - || - || 26 || 9 || 1 
|-
| {{BlockLink|Acacia Slab}} || 2 || - || - || - || - || 2 || - || - 
|-
| {{BlockLink|Acacia Stairs}} || 36 || - || 2 || - || - || 10 || 16 || 8 
|-
| {{BlockLink|Brown Wall Banner}} || 14 || - || - || - || - || 14 || - || - 
|-
| {{BlockLink|Dirt}} || 10 || 10 || - || - || - || - || - || - 
|-
| {{BlockLink|Glass Pane}} || 1 || - || - || 1 || - || - || - || - 
|-
| {{BlockLink|Short Grass}} || 26 || - || 26 || - || - || - || - || - 
|-
| {{BlockLink|Grass Block}} || 54 || 54 || - || - || - || - || - || - 
|-
| {{BlockLink|Dirt Path}} || 1 || 1 || - || - || - || - || - || - 
|-
| {{BlockLink|Smithing Table}} || 1 || - || 1 || - || - || - || - || - 
|-
| {{BlockLink|Torch}} || 2 || - || - || - || 2 || - || - || - 
|}<noinclude>
[[Category:Village blueprints]]

[[fr:Village/Structure/Savane Forge d'Outils 1 plan]]
[[ja:村/構造/設計図/サバンナの道具鍛冶場1]]
[[zh:村庄/结构/图示/热带草原工具匠房屋]]
</noinclude>