<noinclude>{{structure info}}</noinclude>

[[File:Savanna Shepherd 1.png|thumb|Shepherd 1 (Savanna)]]



==== Blueprint ====

{{layered blueprint|name=
Savanna Shepherd 1|default=Layer 1
|G=Grass Block+top
|D=Dirt
|A=Acacia Log+top
|C=Acacia Log
|I=Acacia Planks
|W=Acacia Wood
|L=Loom
|F=Acacia Fence
|R=Short Grass
|T=Water+top
|S=Tall Grass
|s=Tall Grass+bottom
|c=Acacia Stairs
|P=Glass Pane
|O=Wall Torch-rot-180
|H=Dirt Path+top
|a=Acacia Door+bottom
|i=Acacia Door+top
|o=Torch
             
|----Layer 1|
             
 DDDDDDDDDDD 
 DDDDGDDDDDD 
 DDDDDDDDDDD 
 DDDDDDDDDDD 
 DDDDDDDDDDD 
 DDDDDDDDDDD 
 DDDDDDDDDDD 
 DDDDDDDDDDD 
 DDDDDDDDDDD 
  DDDDDDDDDD 
 DDDDDDDDDDD 
 GDDDDDDDDDD 
 GGDDDDDDDDD 
             
|----Layer 2|
             
 GGGGGGGGGGG 
 GGGGTGGGGGG 
 GGGTTTGGDGG 
 GGTTTGGGGGG 
 GGGTGGGGGGG 
 GGGGGGGGGGG 
 GGGGGGGGGGG 
 GGGGDCDGGGG 
 GGGDIIIDGGG 
 GGGDIAIDGGG 
 GGGDIIIDGGG 
  GGGDCDGGGG 
   GGGHGGGGG 
             
|----Layer 3|
             
 FFFFFFFFFFF 
 F s  RR RRF 
 FRR    R RF 
 FR     R  F 
 F R RRRRRRF 
 F RR R RRRF 
 F  R   R  F 
 F   AaAR RF 
 FFFA  WAFFF 
    A  LA    
    A  WA    
     AaA     
             
             
|----Layer 4|
             
       o   o 
   S         
             
             
           o 
             
             
     AiA     
    A   A    
    P   P    
    A   A    
     AiA     
     O O     
             
|----Layer 5|
             
             
             
             
             
             
             
             
     ACA     
    A O A    
    C   C    
    A   A    
     ACA     
             
             
|----Layer 6|
             
             
             
             
             
             
             
    ccccc    
   cIIIIIc   
   cI   Ic   
   cI   Ic   
   cI   Ic   
   cIIIIIc   
    ccccc    
             
|----Layer 7|
             
             
             
             
             
             
             
             
    ccccc    
    cIIIc    
    cIIIc    
    cIIIc    
    ccccc    
             
             
|----Layer 8|
             
             
             
             
             
             
             
             
             
     ccc     
     cIc     
     ccc     
             
             
             
}}



==== Materials ====

{| class="wikitable sortable mw-collapsible"
|-
! Name !! Total !! Layer 1 !! Layer 2 !! Layer 3 !! Layer 4 !! Layer 5 !! Layer 6 !! Layer 7 !! Layer 8 
|-
| {{BlockLink|Acacia Door}} || 2 || - || - || 2 || - || - || - || - || - 
|-
| {{BlockLink|Acacia Fence}} || 31 || - || - || 31 || - || - || - || - || - 
|-
| {{BlockLink|Acacia Log}} || 33 || - || 3 || 10 || 8 || 12 || - || - || - 
|-
| {{BlockLink|Acacia Planks}} || 34 || - || 8 || - || - || - || 16 || 9 || 1 
|-
| {{BlockLink|Acacia Stairs}} || 44 || - || - || - || - || - || 20 || 16 || 8 
|-
| {{BlockLink|Acacia Wood}} || 2 || - || - || 2 || - || - || - || - || - 
|-
| {{BlockLink|Dirt}} || 149 || 138 || 11 || - || - || - || - || - || - 
|-
| {{BlockLink|Glass Pane}} || 2 || - || - || - || 2 || - || - || - || - 
|-
| {{BlockLink|Short Grass}} || 27 || - || - || 27 || - || - || - || - || - 
|-
| {{BlockLink|Grass Block}} || 113 || 4 || 109 || - || - || - || - || - || - 
|-
| {{BlockLink|Dirt Path}} || 1 || - || 1 || - || - || - || - || - || - 
|-
| {{BlockLink|Loom}} || 1 || - || - || 1 || - || - || - || - || - 
|-
| {{BlockLink|Tall Grass}} || 1 || - || - || 1 || - || - || - || - || - 
|-
| {{BlockLink|Torch}} || 6 || - || - || - || 5 || 1 || - || - || - 
|-
| {{BlockLink|Water}} || 8 || - || 8 || - || - || - || - || - || - 
|}<noinclude>
[[Category:Village blueprints]]

[[fr:Village/Structure/Savane Berger 1 plan]]
[[ja:村/構造/設計図/サバンナの羊飼いの家1]]
[[zh:村庄/结构/图示/热带草原牧羊人小屋]]
</noinclude>