<noinclude>
{{project|Structure Blueprints}}
{{structure info}}
</noinclude>

== Church ==

[[File:Village_Plains_church.png|thumb|Church (Plains, Old)]]

Churches in minecraft are the only structure with a high tower where you can go to the top and look to its surroundings. In a village, church is the only main stone structure.

A church like structure made of cobblestone, cobblestone stairs, torches, ladders, and glass panes. There is no difference in the churches in wooded biomes other than the type of door.

=== Blueprint ===

{{layered blueprint|name=Plains church|default=Layer 3
|C=cobblestone|S=cobblestone Stairs|s=cobblestone Stairs-rot90|$=cobblestone Stairs-rot180|L=ladder|D=Oak Door+bottom|G=glass Pane|g=glass Pane-rot90|O=Oak Door+top|T=torch|t=torch-rot90|H=torch-rot180|h=torch-rot270
|----Layer 1|
  CCC 
 CCCCC 
 CCCCC 
 CCCCC 
 CCCCC 
  CCC 
  CCC 
  CCC 
  CCC 
   S 
|----Layer 2|
  CCC 
 CCCCC 
 CCSCC 
 CS SC 
 C   C 
 CL  C 
 C   C 
 C   C 
  CDC 
|----Layer 3|
  CCC  
 Cs $C 
 C   C 
 C   C 
 C   C 
 CL  C 
 G   G 
 C   C 
  COC 
|----Layer 4|
  CgC 
 C   C 
 G   G 
 C   C 
 C   C 
 CL  C 
 G   G 
 C   C 
  CCC 
|----Layer 5|
  CCC 
 C H C 
 Ct hC 
 C T C 
 CCCCC 
 CLCCC 
 CCCCC 
 CCCCC 
 CCCCC 
|----Layer 6|
   
  CCC 
  CCC 
  CCC 
  CCC 
 CL  C 
 C   C 
 C   C 
  CCC 
|----Layer 7 - 8|
   
   
   
   
  CgC 
 CL  C 
 G   G 
 C   C 
  CgC 
|----Layer 9|
   
   
   
   
  CCC 
 CL  C 
 C   C 
 C   C 
  CCC 
|----Layer 10|
   
   
   
   
 CCCCC 
 CLCCC 
 CCCCC 
 CCCCC 
 CCCCC 
|----Layer 11|
   
   
   
   
  CCC 
 C   C 
 C   C 
 C   C 
  CCC 
|----Layer 12|
   
   
   
   
   C 
   
 C   C 
   
   C 
}}


=== Materials ===

{| class="wikitable sortable"
! Name !! Total !! Layer1 !! Layer2 !! Layer3 !! Layer4 !! Layer5 !! Layer6 !! Layer7 !! Layer8 !! Layer9 !! Layer10 !! Layer11 !! Layer12
|-
| Cobblestone || 213 || 35 || 24 || 17 || 15 || 33 || 21 || 8 || 8 || 12 || 24 || 12 || 4
|-
| Cobblestone Stairs || 6 || 1 || 3 || 2 || - || - || - || - || - || - || - || - || -
|-
| Ladders || 9 || - || 1 || 1 || 1 || 1 || 1 || 1 || 1 || 1 || 1 || - || - 
|-
| Glass Pane || 15 || - || - || 2 || 5 || - || - || 4 || 4 || - || - || - || -
|-
| Oak Door || 1 || - || 1 || - || - || - || - || - || - || - || - || - || -
|-
| Torch || 4 || - || - || - || - || 4 || - || - || - || - || - || - || -
|-
|}

<gallery>
File:Village_Taiga_church.png|Taiga Church
File:Village_Savanna_church.png|Savanna Church
</gallery>

== Desert Church ==

=== Blueprint ===

[[File:Village_Desert_church.png|thumb|Church (Desert, Old)]]

{{layered blueprint|name=Desert church|default=Layer 3
|C=cobblestone|S=sandstone Stairs|s=sandstone Stairs-rot90|$=sandstone Stairs-rot180|L=ladder|D=Oak Door+bottom|G=glass Pane|g=glass Pane-rot90|O=Oak Door+top|T=torch|t=torch-rot90|H=torch-rot180|h=torch-rot270
|----Layer 1|
 CCC 
CCCCC 
CCCCC 
CCCCC 
CCCCC 
 CCC 
 CCC 
 CCC 
 CCC 
  S 
|----Layer 2|
 CCC 
CCCCC 
CCSCC 
CS SC 
C   C 
CL  C 
C   C 
C   C 
 CDC 
|----Layer 3|
 CCC 
Cs $C 
C   C 
C   C 
C   C 
CL  C 
G   G 
C   C 
 COC  
|----Layer 4|
 CgC  
C   C 
G   G 
C   C 
C   C 
CL  C 
G   G 
C   C 
 CCC 
|----Layer 5|
 CCC  
C H C 
Ct hC 
C T C 
CCCCC 
CLCCC 
CCCCC 
CCCCC 
CCCCC 
|----Layer 6|
  
 CCC 
 CCC 
 CCC 
 CCC 
CL  C 
C   C 
C   C 
 CCC 
|----Layer 7 - 8|
  
  
  
  
 CgC 
CL  C 
G   G 
C   C 
 CgC 
|----Layer 9|
  
  
  
  
 CCC 
CL  C 
C   C 
C   C 
 CCC 
|----Layer 10|
  
  
  
  
CCCCC 
CLCCC 
CCCCC 
CCCCC 
CCCCC 
|----Layer 11|
  
  
  
  
 CCC 
C   C 
C   C 
C   C 
 CCC 
|----Layer 12|
  
  
 
  
  C 
  
C   C 
  
  C 
}}


=== Materials ===
{| class="wikitable"
! Name !! Total !! Layer1 !! Layer2 !! Layer3 !! Layer4 !! Layer5 !! Layer6 !! Layer7 !! Layer8 !! Layer9 !! Layer10 !! Layer11 !! Layer12
|-
| Cobblestone || 213 || 35 || 24 || 17 || 15 || 33 || 21 || 8 || 8 || 12 || 24 || 12 || 4
|-
| Ladders || 9 || - || 1 || 1 || 1 || 1 || 1 || 1 || 1 || 1 || 1 || - || -
|-
| Glass Pane || 15 || - || - || 2 || 5 || - || - || 4 || 4 || - || - || - || -
|-
| Sandstone Stairs || 6 || 1 || 3 || 2 || - || - || - || - || - || - || - || - || -
|-
| Oak Door || 1 || - || 1 || - || - || - || - || - || - || - || - || - || -
|-
| Torch || 4 || - || - || - || - || 4 || - || - || - || - || - || - || -
|-
|}


== Video ==

Video how-to {{yt|J20vHdROlYQ}}

== Gallery ==
<gallery mode="packed">
File:Church front.png|The Front
File:Church left.png|The Left
File:Church right.png|The Right
File:Church back.png|The Back
File:Church top.png|The Top floor of church
</gallery><noinclude>
[[Category:Village blueprints]]

[[zh:村庄/结构（旧版）/图示/教堂]]
</noinclude>