<noinclude>{{structure info}}</noinclude>

[[File:Desert Mason 1.png|thumb|Mason 1 (Desert)]]



==== Blueprint ====

{{layered blueprint|name=Desert Mason 1
|default=Layer 1
|S=Sand
|C=Cut Sandstone
|M=Smooth Sandstone
|L=Lime Terracotta
|A=Clay
|W=White Glazed Terracotta
|O=Smooth Sandstone Slab+bottom
|T=Wall Torch-rot-270
|N=Sandstone Wall
|R=Wall Torch-rot-180
|J=Jungle Door+bottom
|U=Jungle Door+top
|E=Stonecutter
|H=Wall Torch-rot-90
          
|----Layer 0|
          
 SSSSSSSS 
 SMMMMMMS 
 SMMMMMMS 
 SMMMMMMS 
 SSSMMSSS 
    MM    
   SMMS   
          
|----Layer 1|
          
 CMMMMMMC 
 MA     M 
 ML    EM 
 MLW    M 
 CMCJJCMC 
          
   N  N   
          
|----Layer 2|
          
 CMOOOOMC 
 M      M 
 O      O 
 ML     M 
 CMCUUCMC 
   R  R   
   N  N   
          
|----Layer 3|
          
 CMMMMMMC 
 M      M 
 MT    HM 
 M      M 
 CMCCCCMC 
          
   N  N   
          
|----Layer 4|
          
 COOOOOOC 
 OOOOOOOO 
 OOOOOOOO 
 OOOOOOOO 
 COOOOOOC 
   OOOO   
   OOOO   
          
}}



==== Materials ====

{| class="wikitable sortable mw-collapsible"
|-
! Name !! Total !! Layer 0 !! Layer 1 !! Layer 2 !! Layer 3 !! Layer 4 
|-
| {{BlockLink|Clay}} || 1 || - || 1 || - || - || - 
|-
| {{BlockLink|Cut Sandstone}} || 24 || - || 6 || 6 || 8 || 4 
|-
| {{ItemLink|Jungle Door}} || 2 || - || 2 || - || - || - 
|-
| {{BlockLink|Lime Terracotta}} || 3 || - || 2 || 1 || - || - 
|-
| {{BlockLink|Sand}} || 22 || 22 || - || - || - || - 
|-
| {{BlockLink|Sandstone Wall}} || 6 || - || 2 || 2 || 2 || - 
|-
| {{BlockLink|Smooth Sandstone}} || 60 || 24 || 14 || 8 || 14 || - 
|-
| {{BlockLink|Smooth Sandstone Slab}} || 50 || - || - || 6 || - || 44 
|-
| {{BlockLink|Stonecutter}} || 1 || - || 1 || - || - || - 
|-
| {{BlockLink|Torch}} || 4 || - || - || 2 || 2 || - 
|-
| {{BlockLink|White Glazed Terracotta}} || 1 || - || 1 || - || - || - 
|}<noinclude>
[[Category:Village blueprints]]

[[fr:Village/Structure/Désert Maçon 1 plan]]
[[ja:村/構造/設計図/砂漠の石工の家1]]
[[zh:村庄/结构/图示/沙漠石匠屋]]
</noinclude>