<noinclude>{{structure info}}</noinclude>

[[File:Desert Medium House 2.png|thumb|Medium house 2 (Desert)]]



==== Blueprint ====

{{layered blueprint|name=Desert Medium House 2
|default=Layer 1
|S=Sand
|M=Smooth Sandstone
|O=Smooth Sandstone Slab
|o=Double Smooth Sandstone Slab
|B=Smooth Sandstone Slab+bottom
|b=Smooth Sandstone Slab+top
|G=Green Bed+top-foot-rot270
|L=Lime Bed+top-head
|I=Lime Bed+top-foot
|C=Chest
|R=Green Bed+top-head-rot270
|P=Potted Cactus
|T=Smooth Sandstone Stairs-rot90
|t=Smooth Sandstone Stairs-rot270
|J=Jungle Button
|W=Wall Torch-rot270
|U=Jungle Door+bottom
|N=Jungle Door+top
|A=Wall Torch-rot90
|H=Wall Torch
|h=Wall Torch-rot180
|D=Ladder
             
|----Layer 0|
             
 SSSSSSSSSSS 
 SSSSSSSSSSS 
 SSSSSSMMMSS 
 SSSSSSMMMSS 
 SSSSSSMMMSS 
 SSSSSSMSSSS 
 SSSSSSMSSSS 
             
|----Layer 1|
             
             
      MMMMM  
  MMMMM  RM  
  MMMMM  GM  
  MMMMM   M  
  MMMMMUMMM  
  TMMMt P    
             
|----Layer 2|
             
             
      MMMMM  
  MMMMMD  M  
  MMMMM  WM  
  MMMMM   M  
  MMMMMNMMM  
   TMt       
             
|----Layer 3|
             
      JJJJJ  
  JJJJMMMMMJ 
 JMMMMMDMMMJ 
 JMCILMMMMMJ 
 JM   MMMMMJ 
 JMMUMMMMMMJ 
  JJ JJJJJJ  
             
|----Layer 4|
             
             
      MMMMM  
  MMMMM   M  
  M   MMUMM  
  MH HMP  B  
  MMNMMBBBB  
             
|----Layer 5|
             
             
      MMMMM  
  MMMMM  WM  
  MbbbMMNMM  
  MbbbM      
  MMMMM      
    h        
             
|----Layer 6|
             
      JJJJJ  
     JMMMMMJ 
  B  BM   MJ 
     JMMMMMJ 
      JJJJJ  
  B   B      
             
|----Layer 7|
             
             
      oBBBo  
      BBBBB  
      oBBBo  
             
}}



==== Materials ====

{| class="wikitable sortable mw-collapsible"
|-
! Name !! Total !! Layer 0 !! Layer 1 !! Layer 2 !! Layer 3 !! Layer 4 !! Layer 5 !! Layer 6 !! Layer 7 
|-
| {{BlockLink|Chest}} || 1 || - || - || - || 1 || - || - || - || - 
|-
| {{BlockLink|Green Bed}} || 1 || - || 1 || - || - || - || - || - || - 
|-
| {{BlockLink|Jungle Button}} || 41 || - || - || - || 26 || - || - || 15 || - 
|-
| {{ItemLink|Jungle Door}} || 3 || - || 1 || - || 1 || 1 || - || - || - 
|-
| {{BlockLink|Ladder}} || 2 || - || - || 1 || 1 || - || - || - || - 
|-
| {{BlockLink|Lime Bed}} || 1 || - || - || - || 1 || - || - || - || - 
|-
| {{BlockLink|Potted Cactus}} || 2 || - || 1 || - || - || 1 || - || - || - 
|-
| {{BlockLink|Sand}} || 77 || 77 || - || - || - || - || - || - || - 
|-
| {{BlockLink|Smooth Sandstone}} || 167 || 11 || 34 || 32 || 33 || 22 || 23 || 12 || - 
|-
| {{BlockLink|Smooth Sandstone Slab}} || 34 || - || - || - || - || 5 || 6 || 4 || 19 
|-
| {{BlockLink|Smooth Sandstone Stairs}} || 4 || - || 2 || 2 || - || - || - || - || - 
|-
| {{BlockLink|Torch}} || 5 || - || - || 1 || - || 2 || 2 || - || - 
|}<noinclude>
[[Category:Village blueprints]]

[[fr:Village/Structure/Désert Maison Moyenne 2 plan]]
[[ja:村/構造/設計図/砂漠の中くらいの家2]]
[[zh:村庄/结构/图示/沙漠中型房屋2]]
</noinclude>