<noinclude>{{structure info}}</noinclude>

[[File:Snowy Tundra Small House 6.png|thumb|Small house 6 (Snowy tundra)]]



==== Blueprint ====

{{layered blueprint
|name=Snowy Small House 6 snowy_small_house_6
|default=Layer 2
|l=Stripped Spruce Log+top
|L=Stripped Spruce Log
|u=Stripped Spruce Log-rot90
|d=Spruce Door+bottom
|D=Spruce Door+top
|s=Snow
|p=Spruce Planks
|c=Chest
|f=Furnace-rot270
|b=Blue Bed+top-head-rot270
|B=Blue Bed+top-foot-rot270
|w=Cobblestone Wall
|C=Cobblestone
|t=Torch
|T=Torch-rot180
|a=Lantern
|g=Glass Pane-rot90
|G=Short Grass
|x=Spruce Stairs-rot90
|y=Spruce Stairs
|z=Spruce Stairs-rot270
         
|----Layer 1|
         
 sssGsss 
 sllllls 
 slplpls 
 sllplls 
 slplpls 
 slLlLlG 
 ssxyzss 
         
|----Layer 2|
         
 p     p 
 pllLllp 
 plc blp 
 pu  Bup 
 plf  lp 
 plLdLlp 
 p     p 
         
|----Layer 3|
         
 p     p 
 plLgLlp 
 pl   lp 
 pu   up 
 plw  lp 
 plLDLlp 
 p     p 
         
|----Layer 4|
         
  p   p  
  plLlp  
  p   p  
  p   p  
  pw  p  
  pLLLp  
  p   p  
         
|----Layer 5|
         
  p   p  
  plLlp  
  p T p  
  p   p  
  pwt p  
  plLlp  
  p   p  
         
|----Layer 6|
         
   p p   
   plp   
   p p   
   p p   
   C p   
   plp   
   pap   
         
|----Layer 7|
         
    p    
    p    
    p    
    p    
   wp    
    p    
    p    
         
|----Layer 8|
         
         
         
         
         
   w     
         
         
         
}}



==== Materials ====

{| class="wikitable sortable mw-collapsible"
|-
! Name !! Total !! Layer 1 !! Layer 2 !! Layer 3 !! Layer 4 !! Layer 5 !! Layer 6 !! Layer 7 !! Layer 8 
|-
| {{BlockLink|Blue Bed}} || 1 || - || 1 || - || - || - || - || - || - 
|-
| {{BlockLink|Chest}} || 1 || - || 1 || - || - || - || - || - || - 
|-
| {{BlockLink|Cobblestone}} || 1 || - || - || - || - || - || 1 || - || - 
|-
| {{BlockLink|Cobblestone Wall}} || 5 || - || - || 1 || 1 || 1 || - || 1 || 1 
|-
| {{BlockLink|Furnace}} || 1 || - || 1 || - || - || - || - || - || - 
|-
| {{BlockLink|Glass Pane}} || 1 || - || - || 1 || - || - || - || - || - 
|-
| {{BlockLink|Short Grass}} || 2 || 2 || - || - || - || - || - || - || - 
|-
| {{BlockLink|Lantern}} || 1 || - || - || - || - || - || 1 || - || - 
|-
| {{BlockLink|Snow}} || 19 || 19 || - || - || - || - || - || - || - 
|-
| {{ItemLink|Spruce Door}} || 1 || - || 1 || - || - || - || - || - || - 
|-
| {{BlockLink|Spruce Planks}} || 81 || 5 || 14 || 14 || 14 || 14 || 13 || 7 || - 
|-
| {{BlockLink|Spruce Stairs}} || 3 || 3 || - || - || - || - || - || - || - 
|-
| {{BlockLink|Stripped Spruce Log}} || 61 || 18 || 15 || 14 || 6 || 6 || 2 || - || - 
|-
| {{BlockLink|Torch}} || 2 || - || - || - || - || 2 || - || - || - 
|}<noinclude>
[[Category:Village blueprints]]

[[fr:Village/Structure/Toundra enneigée Petite Maison 6 plan]]
[[ja:村/構造/設計図/雪原の小さな家6]]
[[zh:村庄/结构/图示/雪原小型房屋6]]
</noinclude>