<noinclude>{{structure info}}</noinclude>

[[File:Plains Small House 2.png|thumb|Small House 2 (Plains)]]



==== Blueprint ====

{{layered blueprint
|name=Village Plains Houses plains_small_house_2
|default=Layer 2
|P=Oak Planks
|S=Stripped Oak Log+top
|C=Cobblestone
|W=White Terracotta
|B=Yellow Bed+top foot-rot270
|b=Yellow Bed+top head-rot270
|g=Glass Pane
|^=Oak Stairs-rot270
|s=Oak Stairs-rot180
|d=Oak Door+bottom
|D=Oak Door+top
|G=glass Pane-rot90
|T=torch-rot180
         
|----Layer 1|
         
         
  SCCCS  
  CPPPC  
  CPPPC  
  CPPPC  
  SCCCS  
    s    
         
|----Layer 2|
         
         
  SWWWS  
  Ws bW  
  WP BW  
  W^  W  
  SWdWS  
         
         
|----Layer 3|
         
         
  SWGWS  
  W   W  
  g   g  
  W   W  
  SWDWS  
         
         
|----Layer 4|
         
         
  SWWWS  
  W T W  
  W   W  
  W   W  
  SWWWS  
    T    
         
|----Layer 5|
         
 PPPPPPP 
 PPPPPPP 
 PP   PP 
 PP   PP 
 PP   PP 
 PPPPPPP 
 PPPPPPP 
         
|----Layer 6|
         
         
  PPPPP  
  PPPPP  
  PP PP  
  PPPPP  
  PPPPP  
         
         
|----Layer 7|
         
         
         
   PPP   
   PPP   
   PPP   
         
         
         
}}



==== Materials ====

{| class="wikitable sortable mw-collapsible"
|-
! Name !! Total !! Layer 1 !! Layer 2 !! Layer 3 !! Layer 4 !! Layer 5 !! Layer 6 !! Layer 7 
|-
| {{BlockLink|Cobblestone}} || 12 || 12 || - || - || - || - || - || - 
|-
| {{BlockLink|Glass Pane}} || 3 || - || - || 3 || - || - || - || - 
|-
| {{ItemLink|Oak Door}} || 1 || - || 1 || - || - || - || - || - 
|-
| {{BlockLink|Oak Planks}} || 83 || 9 || 1 || - || - || 40 || 24 || 9 
|-
| {{BlockLink|Oak Stairs}} || 3 || 1 || 2 || - || - || - || - || - 
|-
| {{BlockLink|Stripped Oak Log}} || 16 || 4 || 4 || 4 || 4 || - || - || - 
|-
| {{BlockLink|Torch}} || 2 || - || - || - || 2 || - || - || - 
|-
| {{BlockLink|White Terracotta}} || 31 || - || 11 || 8 || 12 || - || - || - 
|-
| {{BlockLink|Yellow Bed}} || 1 || - || 1 || - || - || - || - || - 
|}<noinclude>
[[Category:Village blueprints]]

[[fr:Village/Structure/Plaines Petite Maison 2 plan]]
[[ja:村/構造/設計図/平原の小さな家2]]
[[zh:村庄/结构/图示/平原小型房屋2]]
</noinclude>