<noinclude>{{structure info}}</noinclude>

[[File:Savanna Library 1.png|thumb|Library 1 (Savanna)]]



==== Blueprint ====

{{layered blueprint|name=
Savanna Library 1|default=Layer 1
|G=Grass Block+top
|D=Dirt
|A=Acacia Log+top
|C=Acacia Planks
|O=Orange Terracotta
|I=Acacia Log
|B=Bookshelf
|L=Lectern
|R=Short Grass
|S=Acacia Stairs
|T=Torch
|P=Acacia Sapling
|Y=Poppy
|a=Tall Grass
|t=Tall Grass+bottom
|c=Acacia Door+bottom
|i=Acacia Door+top
|W=White Carpet
|N=Orange Carpet
|H=Wall Torch-rot-90
|E=Glass Pane
          
|----Layer 1|
          
 GGGGGGR  
 GDDGDDGG 
 DDDDGGDG 
 DDDDGGDG 
 DDDGGGDG 
 GDDGGGDG 
 DDDDGGDG 
 DDDDGGDG 
 GDDGDDGG 
 GGGGGGGG 
          
|----Layer 2|
          
  R RR    
 RAARAI   
 AGGAR A  
 AGGAR I  
 SCCR  A  
 SCCRRRI  
 AGGA  A  
 AGGAR IR 
 RAA AI R 
  R RR  R 
          
|----Layer 3|
          
          
     AI   
  PYACCI  
 TRtACCA  
  SAACCI  
  SAACCA  
 TYtACCI  
  PRACCA  
     AI   
          
          
|----Layer 4|
          
          
     OO   
    OBLO  
   aA  O  
    cNWO  
    cWNO  
   aA  O  
    OSBO  
     OO   
          
          
|----Layer 5|
          
          
     OO   
    OB O  
    A  E  
    i  O  
    i  O  
    A  E  
    O BO  
     OO   
          
          
|----Layer 6|
          
          
     OO   
    OB O  
    A HO  
    I  O  
    I  O  
    A HO  
    O BO  
     OO   
          
          
|----Layer 7|
          
    SSSS  
   SCCCCS 
   SCB CS 
   SC  CS 
   SC  CS 
   SC  CS 
   SC  CS 
   SC BCS 
   SCCCCS 
    SSSS  
          
|----Layer 8|
          
          
    SSSS  
    SCCS  
    SCCS  
    SCCS  
    SCCS  
    SCCS  
    SCCS  
    SSSS  
          
          
}}



==== Materials ====

{| class="wikitable sortable mw-collapsible"
|-
! Name !! Total !! Layer 1 !! Layer 2 !! Layer 3 !! Layer 4 !! Layer 5 !! Layer 6 !! Layer 7 !! Layer 8 
|-
| {{BlockLink|Acacia Door}} || 2 || - || - || - || 2 || - || - || - || - 
|-
| {{BlockLink|Acacia Log}} || 48 || - || 22 || 18 || 2 || 2 || 4 || - || - 
|-
| {{BlockLink|Acacia Planks}} || 48 || - || 4 || 12 || - || - || - || 20 || 12 
|-
| {{BlockLink|Acacia Sapling}} || 2 || - || - || 2 || - || - || - || - || - 
|-
| {{BlockLink|Acacia Stairs}} || 49 || - || 2 || 2 || 1 || - || - || 24 || 20 
|-
| {{BlockLink|Bookshelf}} || 8 || - || - || - || 2 || 2 || 2 || 2 || - 
|-
| {{BlockLink|Dirt}} || 35 || 35 || - || - || - || - || - || - || - 
|-
| {{BlockLink|Glass Pane}} || 2 || - || - || - || - || 2 || - || - || - 
|-
| {{BlockLink|Short Grass}} || 22 || 1 || 19 || 2 || - || - || - || - || - 
|-
| {{BlockLink|Grass Block}} || 51 || 43 || 8 || - || - || - || - || - || - 
|-
| {{BlockLink|Lectern}} || 1 || - || - || - || 1 || - || - || - || - 
|-
| {{BlockLink|Orange Carpet}} || 2 || - || - || - || 2 || - || - || - || - 
|-
| {{BlockLink|Orange Terracotta}} || 34 || - || - || - || 12 || 10 || 12 || - || - 
|-
| {{BlockLink|Poppy}} || 2 || - || - || 2 || - || - || - || - || - 
|-
| {{BlockLink|Tall Grass}} || 2 || - || - || 2 || - || - || - || - || - 
|-
| {{BlockLink|Torch}} || 4 || - || - || 2 || - || - || 2 || - || - 
|-
| {{BlockLink|White Carpet}} || 2 || - || - || - || 2 || - || - || - || - 
|}<noinclude>
[[Category:Village blueprints]]

[[fr:Village/Structure/Savane Bibliothèque 1 plan]]
[[ja:村/構造/設計図/サバンナの図書室1]]
[[zh:村庄/结构/图示/热带草原图书馆]]
</noinclude>