<noinclude>{{structure info}}</noinclude>

[[File:Plains masons house 1.png|thumb|Mason’s House 1 (Plains)]]



==== Blueprint ====

{{layered blueprint
|name=Village Plains Houses plains_masons_house_1
|default=Layer 3
|P=Oak Planks
|C=Cobblestone
|E=Terracotta
|W=White Terracotta
|G=Glass Pane
|g=Glass Pane-rot90
|d=Oak Door+bottom
|D=Oak Door+top
|O=Oak Log+top
|L=Oak Log-rot90
|<=Oak Stairs-rot90
|>=Oak Stairs-rot270
|c=Cobblestone Stairs
|T=Torch
|X=Oak Trapdoor
|H=Grass Block+top
|b=Dandelion
|F=Oak Fence
|r=Clay
|Y=Stonecutter
|----Layer 1|
           
          
  CCCCCCC  
  CCCCCCC  
  CCPPPCC  
  CCCCCCC  
  CCCCCCC  
  XHCCCCC  
   XcCCCC  

|----Layer 2|
           
          
  OWWWWWO  
  WrrE  W  
  Wr   YW  
  W     W  
  OWdWWWO  
   b    F  
     FFFF  

|----Layer 3|
           
           
  OWgWgWO  
  Wr    W  
  G     G  
  W     W  
  OWDWgWO  
     T  T  

|----Layer 4|
           
 <>     <> 
 <OWWWWWO> 
 <WE    W> 
 <W     W> 
 <W     W> 
 <OWWWWWO> 
 <>     <> 

|----Layer 5|
           
  <>   <>  
  <LLLLL>  
  <  T  >  
  <     >  
  <  T  >  
  <LLLLL>  
  <>   <>  

|----Layer 6|
           
   <> <>   
   <WWW>   
   <   >   
   <   >   
   <   >   
   <WWW>   
   <> <>   

|----Layer 7|
           
    <P>    
    <P>    
    <P>    
    <P>    
    <P>    
    <P>    
    <P>    

}}



==== Materials ====

{| class="wikitable sortable mw-collapsible"
|-
! Name !! Total !! Layer 1 !! Layer 2 !! Layer 3 !! Layer 4 !! Layer 5 !! Layer 6 !! Layer 7 
|-
| {{BlockLink|Clay}} || 4 || - || 3 || 1 || - || - || - || - 
|-
| {{BlockLink|Cobblestone}} || 41 || 41 || - || - || - || - || - || - 
|-
| {{BlockLink|Cobblestone Stairs}} || 1 || 1 || - || - || - || - || - || - 
|-
| {{BlockLink|Dandelion}} || 1 || - || 1 || - || - || - || - || - 
|-
| {{BlockLink|Glass Pane}} || 5 || - || - || 5 || - || - || - || - 
|-
| {{BlockLink|Grass Block}} || 1 || 1 || - || - || - || - || - || - 
|-
| {{ItemLink|Oak Door}} || 1 || - || 1 || - || - || - || - || - 
|-
| {{BlockLink|Oak Fence}} || 5 || - || 5 || - || - || - || - || - 
|-
| {{BlockLink|Oak Log}} || 22 || - || 4 || 4 || 4 || 10 || - || - 
|-
| {{BlockLink|Oak Planks}} || 10 || 3 || - || - || - || - || - || 7 
|-
| {{BlockLink|Oak Stairs}} || 68 || - || - || - || 18 || 18 || 18 || 14 
|-
| {{BlockLink|Oak Trapdoor}} || 2 || 2 || - || - || - || - || - || - 
|-
| {{BlockLink|Stonecutter}} || 1 || - || 1 || - || - || - || - || - 
|-
| {{BlockLink|Terracotta}} || 2 || - || 1 || - || 1 || - || - || - 
|-
| {{BlockLink|Torch}} || 4 || - || - || 2 || - || 2 || - || - 
|-
| {{BlockLink|White Terracotta}} || 47 || - || 15 || 10 || 16 || - || 6 || - 
|}
<noinclude>
[[Category:Village blueprints]]

[[fr:Village/Structure/Plaines Maison de Maçon 1 plan]]
[[ja:村/構造/設計図/平原の石工の家1]]
[[zh:村庄/结构/图示/平原石匠屋]]
</noinclude>