<noinclude>{{structure info}}</noinclude>

[[File:Savanna Temple 1.png|thumb|Temple 1 (Savanna)]]



==== Blueprint ====

{{layered blueprint|name=
Savanna Temple 1|default=Layer 1
|G=Grass Block+top
|D=Dirt
|O=Orange Terracotta
|Y=Yellow Terracotta
|A=Acacia Log+top
|C=Acacia Log
|I=Acacia Planks
|W=Acacia Wood
|B=Brewing Stand
|R=Brown Wall Banner
|S=Short Grass
|T=Acacia Stairs
|N=Orange Stained Glass Pane
|E=Yellow Stained Glass Pane
|P=Red Carpet
|H=Dirt Path+top
|L=Orange Stained Glass Pane-rot-90
|e=Yellow Stained Glass Pane-rot-90
|a=Wall Torch-rot-180
|c=Acacia Door+bottom
|i=Acacia Door+top
|l=Wall Torch
           
|----Layer 1|
           
 GGGGGGGGG 
 GGDDDDDGG 
 GDIIIIIDG 
 GDIIIIIDG 
 GDIIIIIDG 
 GGDDCDDGG 
 GGGGHGGGG 
 GGGHHHGGG 
 DGGHGHGGD 
 GGGHHHGGG 
 GGGGHGGGG 
 GGDGHGDGG 
 GGGGHGGGG 
           
|----Layer 2|
           
  SS SSSSS 
 S AAAAAS  
  AW   TA  
 SAW   WA  
 SAW   TAS 
 SSAAcAAS  
 S  S S  S 
 SS     S  
 O S     O 
 SS    SSS 
  SSS   S  
 S O   OSS 
  S S S    
           
|----Layer 3|
           
           
   ALALA   
  AB    A  
  NP   PN  
  AP    A  
   AAiAA   
           
           
 O       O 
           
           
   O   O   
           
           
|----Layer 4|
           
           
   AeAeA   
  A     A  
  E     E  
  A  l  A  
   AAAAA   
           
           
 Y       Y 
           
           
   Y   Y   
   R   R   
           
|----Layer 5|
           
           
   ACACA   
  A a a A  
  C     C  
  A     A  
   CCCCC   
           
           
           
           
           
           
           
           
|----Layer 6|
           
  TTTTTTT  
 TIIIIIIIT 
 TI     IT 
 TI     IT 
 TI     IT 
 TIIIIIIIT 
  TTTTTTT  
           
           
           
           
           
           
           
|----Layer 7|
           
           
  TTTTTTT  
  TIIIIIT  
  TIIIIIT  
  TIIIIIT  
  TTTTTTT  
           
           
           
           
           
           
           
           
}}



==== Materials ====

{| class="wikitable sortable mw-collapsible"
|-
! Name !! Total !! Layer 1 !! Layer 2 !! Layer 3 !! Layer 4 !! Layer 5 !! Layer 6 !! Layer 7 
|-
| {{BlockLink|Acacia Door}} || 1 || - || 1 || - || - || - || - || - 
|-
| {{BlockLink|Acacia Log}} || 55 || 1 || 15 || 11 || 12 || 16 || - || - 
|-
| {{BlockLink|Acacia Planks}} || 50 || 15 || - || - || - || - || 20 || 15 
|-
| {{BlockLink|Acacia Stairs}} || 46 || - || 2 || - || - || - || 24 || 20 
|-
| {{BlockLink|Acacia Wood}} || 4 || - || 4 || - || - || - || - || - 
|-
| {{BlockLink|Brewing Stand}} || 1 || - || - || 1 || - || - || - || - 
|-
| {{BlockLink|Brown Wall Banner}} || 2 || - || - || - || 2 || - || - || - 
|-
| {{BlockLink|Dirt}} || 19 || 19 || - || - || - || - || - || - 
|-
| {{BlockLink|Short Grass}} || 38 || - || 38 || - || - || - || - || - 
|-
| {{BlockLink|Grass Block}} || 70 || 70 || - || - || - || - || - || - 
|-
| {{BlockLink|Dirt Path}} || 12 || 12 || - || - || - || - || - || - 
|-
| {{BlockLink|Orange Stained Glass Pane}} || 4 || - || - || 4 || - || - || - || - 
|-
| {{BlockLink|Orange Terracotta}} || 8 || - || 4 || 4 || - || - || - || - 
|-
| {{BlockLink|Red Carpet}} || 3 || - || - || 3 || - || - || - || - 
|-
| {{BlockLink|Torch}} || 3 || - || - || - || 1 || 2 || - || - 
|-
| {{BlockLink|Yellow Stained Glass Pane}} || 4 || - || - || - || 4 || - || - || - 
|-
| {{BlockLink|Yellow Terracotta}} || 4 || - || - || - || 4 || - || - || - 
|}<noinclude>
[[Category:Village blueprints]]

[[fr:Village/Structure/Savane Temple 1 plan]]
[[ja:村/構造/設計図/サバンナの礼拝所1]]
[[zh:村庄/结构/图示/热带草原教堂1]]
</noinclude>