<noinclude>{{structure info}}</noinclude>

[[File:Plains Meeting Point 2.png|thumb|Meeting Point 2 (Plains)]]



==== Blueprint ====

{{layered blueprint
|name=Meeting Point 2 meeting_point_2
|default=Layer 2
|p=Dirt Path+top
|g=Grass Block+top
|G=Short Grass
|d=Dirt
|o=Oak Planks
|s=Oak Slab
|f=Oak Fence
|t=Torch
|w=White Wool
|y=Yellow Wool
|b=Bell
                 
|----Layer 0|
                 
 ggppggggggggggg 
 pgpppggggggggpp 
 ppppgddddgdgppp 
 pppgpggpgpppppg 
 gdgpppppgpgggdg 
 gdppppgppgpgpdg 
 gdppgpgppggppdg 
 gdgpppppppgpgdg 
                 
|----Layer 1|
                 
         G       
      f Gf   G   
      oooo o     
      f  f       
 fof       GGfof 
  o           o  
  o           o  
 fof         fof 
                 
|----Layer 2|
                 
                 
      f  f       
      t  t b     
      f  f       
 ftf         ftf 
                 
                 
 ftf         ftf 
                 
|----Layer 3|
                 
                 
      f  f       
                 
      f  f       
 f f         f f 
                 
                 
 f f         f f 
                 
|----Layer 4|
                 
                 
      syws       
      swys       
      syws       
 sss         sss 
 ywy         ywy 
 wyw         wyw 
 sss         sss 
                 
}}

All oak slabs are bottom slabs.



==== Materials ====

{| class="wikitable sortable mw-collapsible"
|-
! Name !! Total !! Layer 0 !! Layer 1 !! Layer 2 !! Layer 3 !! Layer 4 
|-
| {{BlockLink|Bell}} || 1 || - || - || 1 || - || - 
|-
| {{BlockLink|Dirt}} || 13 || 13 || - || - || - || - 
|-
| {{BlockLink|Dirt Path}} || 53 || 53 || - || - || - || - 
|-
| {{BlockLink|Short Grass}} || 5 || - || 5 || - || - || - 
|-
| {{BlockLink|Grass Block}} || 54 || 54 || - || - || - || - 
|-
| {{BlockLink|Oak Fence}} || 36 || - || 12 || 12 || 12 || - 
|-
| {{BlockLink|Oak Planks}} || 13 || - || 13 || - || - || - 
|-
| {{BlockLink|Oak Slab}} || 18 || - || - || - || - || 18 
|-
| {{BlockLink|Torch}} || 6 || - || - || 6 || - || - 
|-
| {{BlockLink|White Wool}} || 9 || - || - || - || - || 9 
|-
| {{BlockLink|Yellow Wool}} || 9 || - || - || - || - || 9 
|}<noinclude>
[[Category:Village blueprints]]

[[fr:Village/Structure/Plaines Lieu de Rassemblement 2 plan]]
[[ja:村/構造/設計図/平原の集会所2]]
[[zh:村庄/结构/图示/平原会合点2]]
</noinclude>