<noinclude>{{structure info}}</noinclude>

[[File:Savanna Small House 1.png|thumb|Small House 1 (Savanna)]]



==== Blueprint ====

{{layered blueprint|name=Savanna Small House 1|default=Layer 1
|G=grass block+top
|D=dirt
|Y=Yellow Terracotta
|A=Acacia Planks
|C=Acacia Wood
|I=Acacia Wood-rot-90
|O=Orange Bed+side-head-rot-180
|R=Orange Bed+side-foot-rot-180
|S=Short Grass
|L=Glass Pane
|s=Acacia Stairs
|>=Acacia Stairs-rot-90
|^=Acacia Stairs-rot-180
|<=Acacia Stairs-rot-270
|t=Tall Grass
|T=Tall Grass+bottom
|F=Acacia Fence
|P=Acacia Pressure Plate
|W=Wall Torch-rot-270
|N=Glass Pane-rot-90
|d=Acacia Door+bottom
|o=Acacia Door+top
|H=Dirt Path+top
         
|----Layer 1|
         
 GGGGGGG 
 GGDDDGG 
 GDCCCDG 
 GDCCCIH 
 GDCICDG 
 GGDDDGG 
 GGGGGGG 
         
|----Layer 2|
         
 S S S   
 SSYYY   
 SYOR YS 
 SY   d  
  YF  Y  
 SSYYYSS 
 S TS    
         
|----Layer 3|
         
         
   YNY   
  Y   Y  
  L   o  
  YP  Y  
   YNY   
   t     
         
|----Layer 4|
         
         
   YYY   
  Y   Y  
  YW  Y  
  Y   Y  
   YYY   
         
         
|----Layer 5|
         
  ^^^^^  
 <AAAAA> 
 <A   A> 
 <A   A> 
 <A   A> 
 <AAAAA> 
  sssss  
         
|----Layer 6|
         
         
  <^^^>  
  <AAA>  
  <AAA>  
  <AAA>  
  sssss  
         
         
|----Layer 7|
         
         
         
   ^^>   
   <A>   
   <ss   
         
         
         
}}



==== Materials ====

{| class="wikitable sortable mw-collapsible"
|-
! Name !! Total !! Layer 1 !! Layer 2 !! Layer 3 !! Layer 4 !! Layer 5 !! Layer 6 !! Layer 7 
|-
| {{BlockLink|Acacia Door}} || 1 || - || 1 || - || - || - || - || - 
|-
| {{BlockLink|Acacia Fence}} || 1 || - || 1 || - || - || - || - || - 
|-
| {{BlockLink|Acacia Planks}} || 26 || - || - || - || - || 16 || 9 || 1 
|-
| {{BlockLink|Acacia Pressure Plate}} || 1 || - || - || 1 || - || - || - || - 
|-
| {{BlockLink|Acacia Stairs}} || 44 || - || - || - || - || 20 || 16 || 8 
|-
| {{BlockLink|Acacia Wood}} || 10 || 10 || - || - || - || - || - || - 
|-
| {{BlockLink|Dirt}} || 11 || 11 || - || - || - || - || - || - 
|-
| {{BlockLink|Glass Pane}} || 3 || - || - || 3 || - || - || - || - 
|-
| {{BlockLink|Short Grass}} || 14 || - || 14 || - || - || - || - || - 
|-
| {{BlockLink|Grass Block}} || 27 || 27 || - || - || - || - || - || - 
|-
| {{BlockLink|Dirt Path}} || 1 || 1 || - || - || - || - || - || - 
|-
| {{BlockLink|Orange Bed}} || 1 || - || 1 || - || - || - || - || - 
|-
| {{BlockLink|Tall Grass}} || 1 || - || 1 || - || - || - || - || - 
|-
| {{BlockLink|Torch}} || 1 || - || - || - || 1 || - || - || - 
|-
| {{BlockLink|Yellow Terracotta}} || 31 || - || 11 || 8 || 12 || - || - || - 
|}<noinclude>
[[Category:Village blueprints]]

[[fr:Village/Structure/Savane Petite Maison 1 plan]]
[[ja:村/構造/設計図/サバンナの小さな家1]]
[[zh:村庄/结构/图示/热带草原小型房屋1]]
</noinclude>