<noinclude>{{structure info}}</noinclude>

[[File:Taiga Fisher Cottage 1.png|thumb|Fisher Cottage 1 (Taiga)]]



==== Blueprint ====

{{layered blueprint|name=
Taiga Fisher Cottage 1|default=Layer 1
|D=Dirt
|S=Sand
|G=Gravel
|R=Grass Block+top
|P=Spruce Planks
|U=Spruce Log-rot-90
|C=Spruce Log+top
|E=Spruce Log
|L=Clay
|O=Cobblestone
|B=Barrel
|W=Water+top
|A=Large Fern
|b=Large Fern+bottom
|T=Spruce Trapdoor
|H=Wall Torch-rot-90
|p=Spruce Door+bottom
|r=Spruce Door+top
|F=Spruce Fence
|a=Wall Torch-rot-270
|N=Fern
|s=Dirt Path+top
|Y=Poppy
              
|----Layer 1|
              
 DGSSSSSSRRRD 
 GGGGRRRSRRRR 
 GGGGRSRLRDRR 
 GGGGGLLDDDDD 
 SGGGDLDDDDRD 
 SGGGDDDDDDRR 
 DGDDDDDDDDDR 
 DDDDDDDDDDDR 
 DDDDDDDDRDDR 
 DRDDRDDRDRRR 
              
|----Layer 2|
              
 RRRRDRRR   R 
 RDRWWWWR     
 RDWWWCWR D   
 RWWWCODDDDDR 
 RWWWWOOPOD R 
 RWPPPOOPOOss 
 RWWWWOOPODR  
 RWWWCDDDDDD  
 RRWWRD   DR  
 R RR RR R    
              
|----Layer 3|
              
     B        
  B           
      C   C   
     COOOOOCb 
     TOWWWO   
      pTTTp   
     TOF  OY  
     COOOOOC  
  b   C   Cb  
       b N    
              
|----Layer 4|
              
              
              
      C   C   
     COOOOOCA 
     HO  HOa  
      r   r   
     HOT HOa  
     COOOOOC  
  A   C   CA  
       A      
              
|----Layer 5|
              
              
              
    UUUUUUUUU 
     COOOOOC  
      O   O   
      O   O   
      O   O   
     COOOOOC  
    UUUUUUUUU 
              
              
|----Layer 6|
              
              
              
              
    UUUUUUUUU 
     EO   O   
     EOa  F   
     EO   O   
    UUUUUUUUU 
              
              
              
|----Layer 7|
              
              
              
              
              
    UUUUUUUUU 
      O   O   
    UUUUUUUUU 
              
              
              
              
|----Layer 8|
              
              
              
              
              
              
    UUUUUUUUU 
              
              
              
              
              
}}



==== Materials ====

{| class="wikitable sortable mw-collapsible"
|-
! Name !! Total !! Layer 1 !! Layer 2 !! Layer 3 !! Layer 4 !! Layer 5 !! Layer 6 !! Layer 7 !! Layer 8 
|-
| {{BlockLink|Barrel}} || 2 || - || - || 2 || - || - || - || - || - 
|-
| {{BlockLink|Clay}} || 4 || 4 || - || - || - || - || - || - || - 
|-
| {{BlockLink|Cobblestone}} || 62 || - || 11 || 14 || 14 || 16 || 5 || 2 || - 
|-
| {{BlockLink|Dirt}} || 76 || 57 || 19 || - || - || - || - || - || - 
|-
| {{BlockLink|Fern}} || 1 || - || - || 1 || - || - || - || - || - 
|-
| {{BlockLink|Grass Block}} || 59 || 28 || 31 || - || - || - || - || - || - 
|-
| {{BlockLink|Dirt Path}} || 2 || - || 2 || - || - || - || - || - || - 
|-
| {{BlockLink|Gravel}} || 21 || 21 || - || - || - || - || - || - || - 
|-
| {{BlockLink|Large Fern}} || 8 || - || - || 4 || 4 || - || - || - || - 
|-
| {{BlockLink|Poppy}} || 1 || - || - || 1 || - || - || - || - || - 
|-
| {{BlockLink|Sand}} || 10 || 10 || - || - || - || - || - || - || - 
|-
| {{BlockLink|Spruce Door}} || 2 || - || - || 2 || - || - || - || - || - 
|-
| {{BlockLink|Spruce Fence}} || 2 || - || - || 1 || - || - || 1 || - || - 
|-
| {{BlockLink|Spruce Log}} || 89 || - || 3 || 8 || 8 || 22 || 21 || 18 || 9 
|-
| {{BlockLink|Spruce Planks}} || 6 || - || 6 || - || - || - || - || - || - 
|-
| {{BlockLink|Spruce Trapdoor}} || 6 || - || - || 5 || 1 || - || - || - || - 
|-
| {{BlockLink|Torch}} || 7 || - || - || - || 6 || - || 1 || - || - 
|-
| {{BlockLink|Water}} || 28 || - || 25 || 3 || - || - || - || - || - 
|}<noinclude>
[[Category:Village blueprints]]

[[fr:Village/Structure/Taïga Cabanon de Pêcheur 1 plan]]
[[zh:村庄/结构/图示/针叶林渔夫小屋]]
</noinclude>