<noinclude>{{structure info}}</noinclude>

[[File:Desert Small House 7.png|thumb|Small house 7 (Desert)]]



==== Blueprint ====

{{layered blueprint
|name=Desert Small House 7 desert_small_house_7
|default=Layer 1
|a=Sand
|s=Smooth Sandstone
|L=Lime Bed+top-head
|l=Lime Bed+top-foot
|w=Sandstone Wall
|c=Cactus
|C=Cut Sandstone
|p=Potted Dead Bush
|S=Smooth Sandstone Slab+bottom
|T=Smooth Sandstone Slab+top
|j=Jungle Door+up+left
|J=Jungle Door+top
|U=Jungle Door+up+right
|t=Torch
|x=Smooth Sandstone Stairs-rot90
|y=Smooth Sandstone Stairs-rot270
         
|----Layer 0|
         
 aaaaaaa 
 asssssa 
 asssssa 
 asaasaa 
 asa   a 
 asa a a 
 asa   a 
 asaaaaa 
         
|----Layer 1|
         
 sssssss 
 syCxlLs 
 s     s 
 sUssjss 
 w w   w 
 w w c w 
 w w   w 
 w wwwww 
         
|----Layer 2|
         
 ssSsSss 
 S t   S 
 S     S 
 sJssJss 
  
 t t c p 
  
     p   
         
|----Layer 3|
         
 sssssss 
 sTTTTTs 
 sTTTTTs 
 sssssss 
  
     c   
         
|----Layer 4|
         
 S S S S 
  
  
 S S S S 
         
}}

==== Materials ====

{| class="wikitable sortable mw-collapsible"
|-
! Name !! Total !! Layer 0 !! Layer 1 !! Layer 2 !! Layer 3 !! Layer 4 
|-
| {{BlockLink|Cactus}} || 3 || - || 1 || 1 || 1 || - 
|-
| {{BlockLink|Cut Sandstone}} || 1 || - || 1 || - || - || - 
|-
| {{ItemLink|Jungle Door}} || 2 || - || 2 || - || - || - 
|-
| {{BlockLink|Lime Bed}} || 1 || - || 1 || - || - || - 
|-
| {{BlockLink|Potted Dead Bush}} || 2 || - || - || 2 || - || - 
|-
| {{BlockLink|Sand}} || 32 || 32 || - || - || - || - 
|-
| {{BlockLink|Sandstone Wall}} || 15 || - || 15 || - || - || - 
|-
| {{BlockLink|Smooth Sandstone}} || 60 || 16 || 16 || 10 || 18 || - 
|-
| {{BlockLink|Smooth Sandstone Slab}} || 24 || - || - || 6 || 10 || 8 
|-
| {{BlockLink|Smooth Sandstone Stairs}} || 2 || - || 2 || - || - || - 
|-
| {{BlockLink|Torch}} || 3 || - || - || 3 || - || - 
|}<noinclude>
[[Category:Village blueprints]]

[[fr:Village/Structure/Désert Petite Maison 7 plan]]
[[ja:村/構造/設計図/砂漠の小さな家7]]
[[zh:村庄/结构/图示/沙漠小型房屋7]]
</noinclude>