<noinclude>{{structure info}}</noinclude>

[[File:Taiga Small House 4.png|thumb|Small House 4 (Taiga)]]



==== Blueprint ====

{{layered blueprint|name=
Taiga Small House 4|default=Layer 1
|S=Spruce Log
|I=Spruce Log-rot-90
|D=Dirt
|C=Cobblestone
|R=Crafting Table
|P=Spruce Planks
|B=Blue Bed+side+head-rot-180
|L=Blue Bed+side+foot-rot-180
|U=Spruce Trapdoor
|G=Glass Pane
|W=Wall Torch-rot-270
|A=Wall Torch-rot-90
|E=Spruce Door+bottom
|O=Spruce Door+top
|T=Dirt Path+top
|K=Grass Block+top
          
|----Layer 1|
          
          
  DDDD    
  DCCDDD  
  DCCCPPT 
  DCCDDD  
  DDDD    
       K  
          
|----Layer 2|
          
          
  CCCC    
  CBLCPP  
  C  E E  
  CR CPP  
  CCCC    
          
          
|----Layer 3|
          
          
 UCCCC    
  G  CPP  
 UC  O O  
  G  CPP  
 UCCCC    
          
          
|----Layer 4|
          
 S    S   
 SCCCCIII 
 SC  CPP  
 SC  CPPW 
 SC  CPP  
 SCCCCIII 
 S    S   
          
|----Layer 5|
          
  S  S    
  SCCS    
  S  SIII 
  SWASPP  
  S  SIII 
  SCCS    
  S  S    
          
|----Layer 6|
          
   SS     
   SS     
   SS     
   SSIIII 
   SS     
   SS     
   SS     
          
}}



==== Materials ====

{| class="wikitable sortable mw-collapsible"
|-
! Name !! Total !! Layer 1 !! Layer 2 !! Layer 3 !! Layer 4 !! Layer 5 !! Layer 6 
|-
| {{BlockLink|Blue Bed}} || 1 || - || 1 || - || - || - || - 
|-
| {{BlockLink|Cobblestone}} || 49 || 7 || 13 || 11 || 14 || 4 || - 
|-
| {{BlockLink|Crafting Table}} || 1 || - || 1 || - || - || - || - 
|-
| {{BlockLink|Dirt}} || 17 || 17 || - || - || - || - || - 
|-
| {{BlockLink|Glass Pane}} || 2 || - || - || 2 || - || - || - 
|-
| {{BlockLink|Grass Block}} || 1 || 1 || - || - || - || - || - 
|-
| {{BlockLink|Dirt Path}} || 1 || 1 || - || - || - || - || - 
|-
| {{BlockLink|Spruce Door}} || 2 || - || 2 || - || - || - || - 
|-
| {{BlockLink|Spruce Log}} || 53 || - || - || - || 15 || 20 || 18 
|-
| {{BlockLink|Spruce Planks}} || 18 || 2 || 4 || 4 || 6 || 2 || - 
|-
| {{BlockLink|Spruce Trapdoor}} || 3 || - || - || 3 || - || - || - 
|-
| {{BlockLink|Torch}} || 3 || - || - || - || 1 || 2 || - 
|}<noinclude>
[[Category:Village blueprints]]

[[fr:Village/Structure/Taïga Petite Maison 4 plan]]
[[zh:村庄/结构/图示/针叶林小型房屋4]]
</noinclude>