<noinclude>{{structure info}}</noinclude>

[[File:Desert Butcher Shop 1.png|thumb|Butcher shop 1 (Desert)]]



==== Blueprint ====

{{layered blueprint|name=Desert Butcher Shop 1|default=Layer 2
|C=Cut Sandstone
|S=Smooth Sandstone
|G=Grass Block+top
|T=Terracotta
|M=Double Smooth Stone Slab
|O=Smoker
|A=Sandstone Wall
|H=Smooth Sandstone Slab
|R=Torch
|N=Smooth Sandstone Stairs
|J=Jungle Door+bottom
|U=Jungle Door+top
|W=Wall Torch-rot-180
          
|----Layer 1|
          
 CCCCCCCC 
 CGGGGGGC 
 CGGGGGGC 
 CSSSCGGC 
 CSMSCGGC 
 CSMSCGGC 
 CCSCCCCC 
   N      
          
|----Layer 2|
          
 AAAAAAAA 
 A      A 
 A      A 
 CSJSC  A 
 SO MS  A 
 S  MS  A 
 CSJSCAAA 
          
          
|----Layer 3|
          
 R      R 
          
          
 CSUSC    
 HT  H    
 H   H    
 CSUSC  R 
          
          
|----Layer 4|
          
          
          
          
 CSSSC    
 STW S    
 S   S    
 CSSSC    
   W      
          
|----Layer 5|
          
          
          
          
 HCCCH    
 CTHHC    
 CHHHC    
 HCCCH    
          
          
}}

==== Materials ====

{| class="wikitable sortable mw-collapsible"
|-
! Name !! Total !! Layer 1 !! Layer 2 !! Layer 3 !! Layer 4 !! Layer 5 
|-
| {{BlockLink|Cut Sandstone}} || 50 || 28 || 4 || 4 || 4 || 10 
|-
| {{BlockLink|Grass Block}} || 18 || 18 || - || - || - || - 
|-
| {{ItemLink|Jungle Door}} || 2 || - || 2 || - || - || - 
|-
| {{BlockLink|Sandstone Wall}} || 18 || - || 18 || - || - || - 
|-
| {{BlockLink|Smoker}} || 1 || - || 1 || - || - || - 
|-
| {{BlockLink|Smooth Sandstone}} || 30 || 8 || 8 || 4 || 10 || - 
|-
| {{BlockLink|Smooth Sandstone Slab}} || 13 || - || - || 4 || - || 9 
|-
| {{BlockLink|Smooth Sandstone Stairs}} || 1 || 1 || - || - || - || - 
|-
| {{BlockLink|Smooth Stone Slab}} || 8 || 4 || 4 || - || - || - 
|-
| {{BlockLink|Terracotta}} || 3 || - || - || 1 || 1 || 1 
|-
| {{BlockLink|Torch}} || 5 || - || - || 3 || 2 || - 
|}<noinclude>
[[Category:Village blueprints]]

[[fr:Village/Structure/Désert Échoppe de Boucher 1 plan]]
[[ja:村/構造/設計図/砂漠の肉屋1]]
[[zh:村庄/结构/图示/沙漠肉铺]]
</noinclude>