<noinclude>{{structure info}}</noinclude>

[[File:Savanna Meeting Point 2.png|thumb|Meeting Point 2 (Savanna)]]



==== Blueprint ====

{{layered blueprint|name=
Savanna Meeting Point 2|default=Layer 1
|D=Dirt
|G=Grass Block+top
|Y=Yellow Terracotta
|O=Orange Terracotta
|B=Bell
|R=Brown Wall Banner
|A=Dirt Path+top
|T=Torch
|W=Water+top
|S=Short Grass
             
|----Layer 1|
             
    GAAAG    
  DGGAAAGGD  
  GGAAAAAGG  
  GAADDDAAGG 
 AAADGGGDAAA 
 AAADGAGDAAA 
 AAADGGGDAAA 
   AADDDAAGG 
    AAAAAGG  
  D GAAAGGA  
     AAAG    
             
|----Layer 2|
             
             
  Y       Y  
             
     OYO     
    OWWWO    
    YWYWY    
    OWWWO    
     OYO   S 
         SS  
  Y     S Y  
        S    
             
|----Layer 3|
             
             
  T       B  
             
             
             
      Y      
             
             
             
  B       T  
             
             
|----Layer 4|
             
             
             
             
             
             
      Y      
             
             
             
             
             
             
|----Layer 5|
             
             
             
             
             
      R      
     ROR     
      R      
             
             
             
             
             
|----Layer 6|
             
             
             
             
             
             
      Y      
             
             
             
             
             
             
}}



==== Materials ====

{| class="wikitable sortable mw-collapsible"
|-
! Name !! Total !! Layer 1 !! Layer 2 !! Layer 3 !! Layer 4 !! Layer 5 !! Layer 6 
|-
| {{BlockLink|Bell}} || 2 || - || - || 2 || - || - || - 
|-
| {{BlockLink|Brown Wall Banner}} || 4 || - || - || - || - || 4 || - 
|-
| {{BlockLink|Dirt}} || 15 || 15 || - || - || - || - || - 
|-
| {{BlockLink|Short Grass}} || 5 || - || 5 || - || - || - || - 
|-
| {{BlockLink|Grass Block}} || 29 || 29 || - || - || - || - || - 
|-
| {{BlockLink|Dirt Path}} || 50 || 50 || - || - || - || - || - 
|-
| {{BlockLink|Orange Terracotta}} || 9 || - || 8 || - || - || 1 || - 
|-
| {{BlockLink|Torch}} || 2 || - || - || 2 || - || - || - 
|-
| {{BlockLink|Water}} || 8 || - || 8 || - || - || - || - 
|-
| {{BlockLink|Yellow Terracotta}} || 12 || - || 9 || 1 || 1 || - || 1 
|}<noinclude>
[[Category:Village blueprints]]

[[fr:Village/Structure/Savane Lieu de Rassemblement 2 plan]]
[[ja:村/構造/設計図/サバンナの集会所2]]
[[zh:村庄/结构/图示/热带草原会合点2]]
</noinclude>