<noinclude>{{structure info}}</noinclude>

[[File:Snowy Tundra Meeting Point 3.png|thumb|Meeting point 3 (Snowy tundra)]]



==== Blueprint ====

{{layered blueprint
|name=Snowy Meeting Point 3 snowy_meeting_point_3
|default=Layer 3
|g=Grass Block+top
|p=Dirt Path+top
|f=Spruce Fence
|s=Stripped Spruce Wood
|b=Bell+ceiling
|l=Lantern
         
|----Layer 0|
         
 g ppp   
  ppppp  
 ppgpgpp 
 ppppppp 
 ppgpgpp 
  pppppg 
   ppp   
|----Layer 1-2|
         
   f f   
   f f   
         
|----Layer 3|
         
         
    l    
   f f   
  l b l  
   f f   
    l    
         
|----Layer 4|
         
         
    f    
   sss   
  fsssf  
   sss   
    f    
         
|----Layer 5|
         
         
    s    
         
}}



==== Materials ====

{| class="wikitable sortable mw-collapsible"
|-
! Name !! Total !! Layer 0 !! Layer 1 !! Layer 2 !! Layer 3 !! Layer 4 !! Layer 5 
|-
| {{BlockLink|Bell}} || 1 || - || - || - || 1 || - || - 
|-
| {{BlockLink|Dirt Path}} || 33 || 33 || - || - || - || - || - 
|-
| {{BlockLink|Grass Block}} || 6 || 6 || - || - || - || - || - 
|-
| {{BlockLink|Lantern}} || 4 || - || - || - || 4 || - || - 
|-
| {{BlockLink|Spruce Fence}} || 16 || - || 4 || 4 || 4 || 4 || - 
|-
| {{BlockLink|Stripped Spruce Wood}} || 10 || - || - || - || - || 9 || 1 
|}<noinclude>
[[Category:Village blueprints]]

[[fr:Village/Structure/Toundra enneigée Lieu de Rassemblement 3 plan]]
[[ja:村/構造/設計図/雪原の集会所3]]
[[zh:村庄/结构/图示/雪原会合点3]]
</noinclude>