<noinclude>{{structure info}}</noinclude>

[[File:Plains weaponsmith 1.png|thumb|Weaponsmith 1 (Plains)]]



==== Blueprint ====

{{layered blueprint
|name=Village Plains Houses plains_weaponsmith_1
|default=Layer 2
|C=Cobblestone
|c=Cobblestone Stairs
|O=Oak Log+top
|L=Oak Log-rot90
|l=Oak Log
|P=Oak Planks
|g=glass Pane
|G=glass Pane-rot90
|d=Oak Door+bottom
|D=Oak Door+top
|s=Oak Stairs
|>=Oak Stairs-rot270
|<=Oak Stairs-rot90
|o=Cobblestone Wall
|$=Smooth Stone Slab
|T=torch
|t=Torch-rot180
|[=Torch-rot90
|]=Torch-rot270
|I=Iron Bars
|f=Oak Fence
|R=Oak Pressure Plate
|B=Furnace
|n=Grindstone
|V=Lava+top
|U=Chest
            
|----Layer 1|
             
             
 CCCCCCOCCO  
 CCCCCCCCCC  
 CCCCCCCCCC  
 CCCCCCCCCC  
 CCCCCCCCCC  
 CCCCCCCCCC  
 CCCCCCOCCO  
  ccc        
            
|----Layer 2|
            
             
 CCCCCCOPPO  
 CVVCU  sPP  
 CCCC   f<P  
    CCO   P  
       P  P  
  n    d  P  
 f   f OPPO  
             
            
|----Layer 3|
            
  T         
 CCCLGLOPPO  
 I  C    tP  
 I  C   R g  
    BCO   P[ 
      ]P  g  
       D  P  
 f   f OPPO  
             
            
|----Layer 4|
            
            
 CCCCCCOPPO  
 CCCC     P  
 CCCC     P  
    BCO   P  
       P  P  
       P  P  
 f   f OPPO  
             
|----Layer 5|
            
            
 CCCCCCOLLO  
 CCCCCCCCCl  
 CCCCCCCCCl  
 CCCCCCCCCl  
 CCCCCCCCCl  
 CCCCCCCCCl  
 CCCCCCOLLO  
             
|----Layer 6|
            
      <>  <> 
 $$$$$<OPPO> 
 $CC  <   P> 
 $    <   P> 
 $  T <   P> 
 $    <   P> 
 $    <   P> 
 $$$$$<OPPO> 
      <>  <> 
            
|----Layer 7|
            
       <><>  
       <PP>  
  o    <  >  
       <  >  
       <  >  
       <  >  
       <  >  
       <PP>  
       <><>  
            
|----Layer 8|
            
        <>   
        <>   
        <>   
        <>   
        <>   
        <>   
        <>   
        <>   
        <>   
            
}}

This structure resembles the [[Village/Structure (old)/Blueprints/Blacksmith|old Blacksmith]] seen in [[Village/Structure (old)/Blueprints |pre-1.14 villages]], with some changes like the addition of a roof. All of the slabs on layer 6 are bottom slabs.



==== Materials ====

{| class="wikitable sortable mw-collapsible"
|-
! Name !! Total !! Layer 1 !! Layer 2 !! Layer 3 !! Layer 4 !! Layer 5 !! Layer 6 !! Layer 7 !! Layer 8 
|-
| {{BlockLink|Chest}} || 1 || - || 1 || - || - || - || - || - || - 
|-
| {{BlockLink|Cobblestone}} || 160 || 66 || 14 || 6 || 15 || 57 || 2 || - || - 
|-
| {{BlockLink|Cobblestone Stairs}} || 3 || 3 || - || - || - || - || - || - || - 
|-
| {{BlockLink|Cobblestone Wall}} || 1 || - || - || - || - || - || - || 1 || - 
|-
| {{BlockLink|Furnace}} || 2 || - || - || 1 || 1 || - || - || - || - 
|-
| {{BlockLink|Glass Pane}} || 3 || - || - || 3 || - || - || - || - || - 
|-
| {{BlockLink|Grindstone}} || 1 || - || 1 || - || - || - || - || - || - 
|-
| {{BlockLink|Iron Bars}} || 2 || - || - || 2 || - || - || - || - || - 
|-
| {{BlockLink|Lava}} || 2 || - || 2 || - || - || - || - || - || - 
|-
| {{ItemLink|Oak Door}} || 1 || - || 1 || - || - || - || - || - || - 
|-
| {{BlockLink|Oak Log}} || 38 || 4 || 5 || 7 || 5 || 13 || 4 || - || - 
|-
| {{BlockLink|Oak Fence}} || 7 || - || 3 || 2 || 2 || - || - || - || - 
|-
| {{BlockLink|Oak Planks}} || 43 || - || 11 || 8 || 11 || - || 9 || 4 || - 
|-
| {{BlockLink|Oak Pressure Plate}} || 1 || - || - || 1 || - || - || - || - || - 
|-
| {{BlockLink|Oak Stairs}} || 64 || - || 2 || - || - || - || 22 || 22 || 18 
|-
| {{BlockLink|Smooth Stone Slab}} || 15 || - || - || - || - || - || 15 || - || - 
|-
| {{BlockLink|Torch}} || 5 || - || - || 4 || - || - || 1 || - || - 
|}
<noinclude>
[[Category:Village blueprints]]

[[fr:Village/Structure/Plaines Forge d'Armes 1 plan]]
[[ja:村/構造/設計図/平原の武器鍛冶屋1]]
[[zh:村庄/结构/图示/平原铁匠铺]]
</noinclude>