<noinclude>{{structure info}}</noinclude>

[[File:Snowy Tundra Animal Pen 1.png|thumb|Animal pen 1 (Snowy tundra)]]



==== Blueprint ====

{{layered blueprint
|name=Snowy Animal Pen 1 snowy_animal_pen_1
|default=Layer 2
|d=Dirt
|g=Grass Block+top
|s=Stripped Spruce Log+top
|S=Snow
|f=Spruce Fence
|G=Spruce Fence Gate
|t=Torch
|b=Snow Block
|w=Spruce Stairs
|x=Spruce Stairs-rot90
|y=Spruce Stairs-rot180
|z=Spruce Stairs-rot270
           
|----Layer 1|
           
 SSsssssss 
 SSsgggggs 
 Sbsggddgs 
 bbsggddgs 
 Sbsgggggs 
 SSsgggggs 
 SSsssssss 
 SSSSxwzSS 
           
|----Layer 2|
           
   fffffff 
   fSSSSSf 
  SfSSxySf 
  bfSSwzSf 
   fSSSSSf 
   fSSSSSf 
   fffGfff 
           
|----Layer 3|
           
           
           
           
           
           
           
     f f   
           
|----Layer 4|
           
           
           
           
           
           
           
     t t   
           
}}

The stairs in layer 2 should be waterlogged.

==== Materials ====

{| class="wikitable sortable mw-collapsible"
|-
! Name !! Total !! Layer 1 !! Layer 2 !! Layer 3 !! Layer 4 
|-
| {{BlockLink|Dirt}} || 4 || 4 || - || - || - 
|-
| {{BlockLink|Grass Block}} || 21 || 21 || - || - || - 
|-
| {{BlockLink|Snow}} || 65 || 62 || 3 || - || - 
|-
| {{BlockLink|Snow Block}} || 5 || 4 || 1 || - || - 
|-
| {{BlockLink|Spruce Fence}} || 25 || - || 23 || 2 || - 
|-
| {{BlockLink|Spruce Fence Gate}} || 1 || - || 1 || - || - 
|-
| {{BlockLink|Spruce Stairs}} || 7 || 3 || 4 || - || - 
|-
| {{BlockLink|Stripped Spruce Log}} || 24 || 24 || - || - || - 
|-
| {{BlockLink|Torch}} || 2 || - || - || - || 2 
|-
| {{BlockLink|Water}} || 4 || - || 4 || - || - 
|}<noinclude>
[[Category:Village blueprints]]

[[fr:Village/Structure/Toundra enneigée Enclos 1 plan]]
[[ja:村/構造/設計図/雪原の牧柵1]]
[[zh:村庄/结构/图示/雪原牲畜栏1]]
</noinclude>