<noinclude>{{structure info}}</noinclude>

[[File:Savanna Medium House 1.png|thumb|Medium House 1 (Savanna)]]



==== Blueprint ====

{{layered blueprint|name=
Savanna Medium House 1|default=Layer 1
|D=Dirt
|A=Acacia Log+top
|C=Acacia Log
|c=Acacia Log-rot-90
|I=Acacia Planks
|G=Grass Block+top
|R=Crafting Table
|W=Acacia Wood
|H=Chest-rot-90
|O=Orange Bed+top+foot-rot-90
|N=Orange Bed+top+head-rot-90
|s=Acacia Stairs
|>=Acacia Stairs-rot-90
|^=Acacia Stairs-rot-180
|<=Acacia Stairs-rot-270
|L=Glass Pane
|P=Dirt Path+top
|d=Acacia Door+bottom
|a=Acacia Door+top
|E=Glass Pane-rot-90
|T=Wall Torch-rot-180
|F=Acacia Fence
|o=Torch
|M=Farmland
|h=Wheat
|l=Wall Torch-rot-270
|t=Water+top
|r=Short Grass
|!=Wall Torch-rot-90
                
|----Layer 1|
                
    GGGGGGG     
    GMMtMMG     
  DDDMMMMMDDD   
 DIIIDGGGDIIID  
 DIIIIGGGIIIID  
 DIIIDGGGDIIID  
  DIDGGGG DID   
   PGGGDG  P    
                
|----Layer 2|
                
    FFFFFFF     
    Fhh hhF     
  AAAhhhhhAAA   
 AN RA   AW NA  
 AO  d   d  OA  
 AH  AFFFA   A  
  AdA  r  AdA   
                
                
|----Layer 3|
                
    o     o     
                
  AEA     AEA   
 A   A   Ao  A  
 L   a   a   L  
 A   A   A   A  
  AaA     AaA   
                
                
|----Layer 4|
                
                
                
  AcA     AcA   
 A T A   A   A  
 C   Cl !C   C  
 A   A   A   A  
  AcA     AcA   
   T       T    
                
|----Layer 5|
                
                
 ^^^^^   ^^^^^  
<IIIII> <IIIII> 
<I   I> <I   I> 
<I   I> <I   I> 
<I   I> <I   I> 
<IIIII> <IIIII> 
 sssss   sssss  
                
|----Layer 6|
                
                
                
 ^^^^^   ^^^^^  
 <III>   <III>  
 <III>   <III>  
 <III>   <III>  
 sssss   sssss  
                
                
|----Layer 7|
                
                
                
                
  <^>     ^^>   
  <I>     <I>   
  ss>     sss   
                
                
                
}}



==== Materials ====

{| class="wikitable sortable mw-collapsible"
|-
! Name !! Total !! Layer 1 !! Layer 2 !! Layer 3 !! Layer 4 !! Layer 5 !! Layer 6 !! Layer 7 
|-
| {{BlockLink|Acacia Door}} || 4 || - || 4 || - || - || - || - || - 
|-
| {{BlockLink|Acacia Fence}} || 12 || - || 12 || - || - || - || - || - 
|-
| {{BlockLink|Acacia Log}} || 60 || - || 20 || 16 || 24 || - || - || - 
|-
| {{BlockLink|Acacia Planks}} || 74 || 22 || - || - || - || 32 || 18 || 2 
|-
| {{BlockLink|Acacia Stairs}} || 88 || - || - || - || - || 40 || 32 || 16 
|-
| {{BlockLink|Acacia Wood}} || 1 || - || 1 || - || - || - || - || - 
|-
| {{BlockLink|Chest}} || 1 || - || 1 || - || - || - || - || - 
|-
| {{BlockLink|Crafting Table}} || 1 || - || 1 || - || - || - || - || - 
|-
| {{BlockLink|Dirt}} || 21 || 21 || - || - || - || - || - || - 
|-
| {{BlockLink|Farmland}} || 9 || 9 || - || - || - || - || - || - 
|-
| {{BlockLink|Glass Pane}} || 4 || - || - || 4 || - || - || - || - 
|-
| {{BlockLink|Short Grass}} || 1 || - || 1 || - || - || - || - || - 
|-
| {{BlockLink|Grass Block}} || 26 || 26 || - || - || - || - || - || - 
|-
| {{BlockLink|Dirt Path}} || 2 || 2 || - || - || - || - || - || - 
|-
| {{BlockLink|Orange Bed}} || 2 || - || 2 || - || - || - || - || - 
|-
| {{BlockLink|Torch}} || 8 || - || - || 3 || 5 || - || - || - 
|-
| {{BlockLink|Water}} || 1 || 1 || - || - || - || - || - || - 
|-
| {{BlockLink|Wheat}} || 9 || - || 9 || - || - || - || - || - 
|}<noinclude>
[[Category:Village blueprints]]

[[fr:Village/Structure/Savane Maison Moyenne 1 plan]]
[[ja:村/構造/設計図/サバンナの中くらいの家1]]
[[zh:村庄/结构/图示/热带草原中型房屋1]]
</noinclude>