<noinclude>{{structure info}}</noinclude>

[[File:Desert Small House 2.png|thumb|Small house 2 (Desert)]]



==== Blueprint ====

{{layered blueprint
|name=Desert Small House 2 desert_small_house_2
|default=Layer 1
|a=Sand
|s=Smooth Sandstone
|c=Cut Sandstone
|C=Chiseled Sandstone
|g=Green Bed+top-head
|F=Green Bed+top-foot
|G=Green Carpet
|w=Sandstone Wall
|S=Smooth Sandstone Slab
|D=Double Smooth Sandstone Slab
|B=Smooth Sandstone Slab+bottom
|b=Smooth Sandstone Slab+top
|j=Jungle Door+up+left
|J=Jungle Door+top
|p=Potted Cactus
|t=Torch
|T=Wall Torch-rot180
       
|----Layer 0|
       
 aaaaa 
 asssa 
 asssa 
 asssa 
 aasaa 
 aasaa 
 aasaa 
       
|----Layer 1|
       
 csssc 
 sCFgs 
 s   s 
 sG Gs 
 csjsc
 
 w   w 
       
|----Layer 2|
       
 cspsc 
 st  s 
 s   s 
 s   s 
 csJsc 
 
 w   w 
       
|----Layer 3|
       
 csbsc 
 s   s 
 s   s 
 s   s 
 csssc 
   T   
 w   w 
       
|----Layer 4|
       
 ccccc 
 c   c 
 c   c 
 c   c 
 csssc 
 DbbbD 
 BBBBB 
       
|----Layer 5|
       
  BDB  
  BBB  
  BBB  
  BBB  
  BDB  
       
}}

==== Materials ====

{| class="wikitable sortable mw-collapsible"
|-
! Name !! Total !! Layer 0 !! Layer 1 !! Layer 2 !! Layer 3 !! Layer 4 !! Layer 5 
|-
| {{BlockLink|Chiseled Sandstone}} || 1 || - || 1 || - || - || - || - 
|-
| {{BlockLink|Cut Sandstone}} || 25 || - || 4 || 4 || 4 || 13 || - 
|-
| {{BlockLink|Green Bed}} || 1 || - || 1 || - || - || - || - 
|-
| {{BlockLink|Green Carpet}} || 2 || - || 2 || - || - || - || - 
|-
| {{ItemLink|Jungle Door}} || 1 || - || 1 || - || - || - || - 
|-
| {{BlockLink|Potted Cactus}} || 1 || - || - || 1 || - || - || - 
|-
| {{BlockLink|Sand}} || 23 || 23 || - || - || - || - || - 
|-
| {{BlockLink|Sandstone Wall}} || 6 || - || 2 || 2 || 2 || - || - 
|-
| {{BlockLink|Smooth Sandstone}} || 47 || 12 || 11 || 10 || 11 || 3 || - 
|-
| {{BlockLink|Smooth Sandstone Slab}} || 30 || - || - || - || 1 || 12 || 17 
|-
| {{BlockLink|Torch}} || 2 || - || - || 1 || 1 || - || - 
|}<noinclude>
[[Category:Village blueprints]]

[[fr:Village/Structure/Désert Petite Maison 2 plan]]
[[ja:村/構造/設計図/砂漠の小さな家2]]
[[zh:村庄/结构/图示/沙漠小型房屋2]]
</noinclude>