<noinclude>{{structure info}}</noinclude>

[[File:Taiga Library 1.png|thumb|Library 1 (Taiga)]]



==== Blueprint ====

{{layered blueprint|name=
Taiga Library 1|default=Layer 1
|G=Grass Block+top
|D=Dirt
|S=Spruce Log-rot-90
|C=Cobblestone
|B=Bookshelf
|L=Lectern
|R=Dirt Path+top
|P=Spruce Trapdoor
|O=Cobblestone Wall
|T=Torch
|A=Large Fern
|b=Large Fern+bottom
|Y=Poppy
|W=Wall Torch-rot-90
|U=Spruce Door+bottom
|N=Glass Pane
|E=Spruce Door+top
|e=Red Carpet
|I=Spruce Stairs
|H=Wall Torch-rot-270
|u=Purple Carpet
|o=Cobblestone Stairs
|l=Glass Pane-rot-90
|a=Wall Torch
|r=Wall Torch-rot-180
|F=Fern
          
|----Layer 1|
          
          
 GDDDDDD  
 GDDCCCDG 
 GDDCCCD  
 GGDCCCD  
 RRCCCCD  
 GGDCCCD  
 GDDCCCDG 
 GDDCCCD  
 GDDDDDDG 
 G        
          
|----Layer 2|
          
  P       
 PGCCCCC  
 PGCIILCF 
 PGCeeeC  
 OPC   C  
   U C C  
 OPC C C  
 PGC o C  
 PGC   C  
 PGCCCCC  
  P       
          
|----Layer 3|
          
          
  bCClCC  
  PC   C  
  YN   N  
 T CH WC  
   E C N  
 T C o C  
   N   N  
  PC  WC  
  bCClCC  
          
          
|----Layer 4|
          
          
  ACCCCC  
   CCCCC  
   CCCCC  
   CCCCC  
   CCoCC  
   CC CC  
   CC CC  
   CC CC  
  ACCCCC  
          
          
|----Layer 5|
          
  SSSSSSS 
   CCCCC  
   CBBBC  
  PCuuuC  
 PGCuuuC  
 PGC   C  
 PGC   C  
  PC   C  
   C   C  
   CCCCC  
  SSSSSSS 
          
|----Layer 6|
          
          
  SSSSSSS 
   CBBBC  
  PC   N  
   N   C  
  PC   N  
  YN   C  
  PC   N  
   C   C  
  SSSSSSS 
          
          
|----Layer 7|
          
          
          
  SSSSSSS 
   C r C  
   C   C  
   C   C  
   C   C  
   C a C  
  SSSSSSS 
          
          
          
|----Layer 8|
          
          
          
          
  SSSSSSS 
   C   C  
  WCH WCH 
   C   C  
  SSSSSSS 
          
          
          
          
|----Layer 9|
          
          
          
          
          
  SSSSSSS 
   C   C  
  SSSSSSS 
          
          
          
          
          
|----Layer 10|
          
          
          
          
          
          
  SSSSSSS 
          
          
          
          
          
          
}}



==== Materials ====

{| class="wikitable sortable mw-collapsible"
|-
! Name !! Total !! Layer 1 !! Layer 2 !! Layer 3 !! Layer 4 !! Layer 5 !! Layer 6 !! Layer 7 !! Layer 8 !! Layer 9 !! Layer 10 
|-
| {{BlockLink|Bookshelf}} || 6 || - || - || - || - || 3 || 3 || - || - || - || - 
|-
| {{BlockLink|Cobblestone}} || 156 || 22 || 25 || 17 || 41 || 24 || 9 || 10 || 6 || 2 || - 
|-
| {{BlockLink|Cobblestone Stairs}} || 3 || - || 1 || 1 || 1 || - || - || - || - || - || - 
|-
| {{BlockLink|Cobblestone Wall}} || 2 || - || 2 || - || - || - || - || - || - || - || - 
|-
| {{BlockLink|Dirt}} || 29 || 29 || - || - || - || - || - || - || - || - || - 
|-
| {{BlockLink|Fern}} || 1 || - || 1 || - || - || - || - || - || - || - || - 
|-
| {{BlockLink|Glass Pane}} || 12 || - || - || 7 || - || - || 5 || - || - || - || - 
|-
| {{BlockLink|Grass Block}} || 23 || 14 || 6 || - || - || 3 || - || - || - || - || - 
|-
| {{BlockLink|Dirt Path}} || 2 || 2 || - || - || - || - || - || - || - || - || - 
|-
| {{BlockLink|Large Fern}} || 4 || - || - || 2 || 2 || - || - || - || - || - || - 
|-
| {{BlockLink|Lectern}} || 1 || - || 1 || - || - || - || - || - || - || - || - 
|-
| {{BlockLink|Poppy}} || 2 || - || - || 1 || - || - || 1 || - || - || - || - 
|-
| {{BlockLink|Purple Carpet}} || 6 || - || - || - || - || 6 || - || - || - || - || - 
|-
| {{BlockLink|Red Carpet}} || 3 || - || 3 || - || - || - || - || - || - || - || - 
|-
| {{BlockLink|Spruce Door}} || 1 || - || 1 || - || - || - || - || - || - || - || - 
|-
| {{BlockLink|Spruce Log}} || 77 || - || - || - || - || 14 || 14 || 14 || 14 || 14 || 7 
|-
| {{BlockLink|Spruce Stairs}} || 2 || - || 2 || - || - || - || - || - || - || - || - 
|-
| {{BlockLink|Spruce Trapdoor}} || 20 || - || 10 || 2 || - || 5 || 3 || - || - || - || - 
|-
| {{BlockLink|Torch}} || 11 || - || - || 5 || - || - || - || 2 || 4 || - || - 
|}<noinclude>
[[Category:Village blueprints]]

[[fr:Village/Structure/Taïga Bibliothèque 1 plan]]
[[zh:村庄/结构/图示/针叶林图书馆]]
</noinclude>