<noinclude>{{structure info}}</noinclude>

[[File:Desert Small House 3.png|thumb|Small house 3 (Desert)]]



==== Blueprint ====

{{layered blueprint
|name=Desert Small House 3 desert_small_house_3
|default=Layer 1
|a=Sand
|s=Smooth Sandstone
|c=Cut Sandstone
|j=Jungle Door+up+right
|J=Jungle Door+top
|x=Smooth Sandstone Stairs
|X=Smooth Sandstone Stairs-rot180
|G=Green Bed+top-head-rot270
|g=Green Bed+top-foot-rot270
|S=Smooth Sandstone Slab+top
|B=Smooth Sandstone Slab+bottom
|b=Jungle Button
|y=Smooth Sandstone Stairs-rot90
|Y=Smooth Sandstone Stairs-rot270
|p=Potted Dead Bush
|t=Torch
       
|----Layer 0|
       
 aaaaa 
 asssa 
 asssa 
 asssa 
 aasaa 
 aasaa 
       
|----Layer 1|
       
 csssc 
 sx Gs 
 sc gs 
 sX  s 
 csjsc 
       
|----Layer 2|
       
 csssc 
 s   s 
 sp  s 
 st ts 
 csJsc 
       
|----Layer 3|
       
 csSsc 
 sSSSs 
 SSSSS 
 sSSSs 
 csssc 
  bbb  
       
|----Layer 4|
       
 yYByY 
  
  
  
 yYByY 
       
}}

==== Materials ====

{| class="wikitable sortable mw-collapsible"
|-
! Name !! Total !! Layer 0 !! Layer 1 !! Layer 2 !! Layer 3 !! Layer 4 
|-
| {{BlockLink|Cut Sandstone}} || 13 || - || 5 || 4 || 4 || - 
|-
| {{BlockLink|Green Bed}} || 1 || - || 1 || - || - || - 
|-
| {{BlockLink|Jungle Button}} || 3 || - || - || - || 3 || - 
|-
| {{ItemLink|Jungle Door}} || 1 || - || 1 || - || - || - 
|-
| {{BlockLink|Potted Dead Bush}} || 1 || - || - || 1 || - || - 
|-
| {{BlockLink|Sand}} || 19 || 19 || - || - || - || - 
|-
| {{BlockLink|Smooth Sandstone}} || 42 || 11 || 11 || 11 || 9 || - 
|-
| {{BlockLink|Smooth Sandstone Slab}} || 14 || - || - || - || 12 || 2 
|-
| {{BlockLink|Smooth Sandstone Stairs}} || 10 || - || 2 || - || - || 8 
|-
| {{BlockLink|Torch}} || 2 || - || - || 2 || - || - 
|}<noinclude>
[[Category:Village blueprints]]

[[fr:Village/Structure/Désert Petite Maison 3 plan]]
[[ja:村/構造/設計図/砂漠の小さな家3]]
[[zh:村庄/结构/图示/沙漠小型房屋3]]
</noinclude>