<noinclude>{{structure info}}</noinclude>

[[File:Snowy Tundra Medium House 3.png|thumb|Medium house 3 (Snowy tundra)]]



==== Blueprint ====

{{layered blueprint
|name=Snowy Medium House 3 snowy_medium_house_3
|default=Layer 1
|i=Dirt
|g=Grass Block+top
|s=Snow
|p=Packed Ice
|b=Blue Ice
|d=Spruce Door+bottom
|D=Spruce Door+top
|f=Furnace
|t=Torch-rot90
|T=Torch-rot270
|B=Blue Bed+top-head-rot270
|z=Blue Bed+top-foot-rot270
         
|----Layer 0|
         
 giiiiig 
 iggiggi 
 igggggi 
 igggggi 
 giigiig 
         
|----Layer 1|
         
 sbpppbs 
 bB f Bb 
 pz   zp 
 b     b 
 sbpdpbs 
         
|----Layer 2|
         
  bpppb  
 b     b 
 pt   Tp 
 b     b 
  bpDpb  
         
|----Layer 3|
         
   ppp   
  bp pb  
 ppp ppp 
  bp pb  
   ppp   
         
|----Layer 4|
         
         
    b    
   bpb   
    b    
         
}}



==== Materials ====

{| class="wikitable sortable mw-collapsible"
|-
! Name !! Total !! Layer 0 !! Layer 1 !! Layer 2 !! Layer 3 !! Layer 4 
|-
| {{BlockLink|Blue Bed}} || 2 || - || 2 || - || - || - 
|-
| {{BlockLink|Blue Ice}} || 24 || - || 8 || 8 || 4 || 4 
|-
| {{BlockLink|Dirt}} || 16 || 16 || - || - || - || - 
|-
| {{BlockLink|Furnace}} || 1 || - || 1 || - || - || - 
|-
| {{BlockLink|Grass Block}} || 19 || 19 || - || - || - || - 
|-
| {{BlockLink|Packed Ice}} || 31 || - || 7 || 7 || 16 || 1 
|-
| {{BlockLink|Snow}} || 4 || 4 || - || - || - || - 
|-
| {{ItemLink|Spruce Door}} || 1 || - || 1 || - || - || - 
|-
| {{BlockLink|Torch}} || 2 || - || - || 2 || - || - 
|}<noinclude>
[[Category:Village blueprints]]

[[fr:Village/Structure/Toundra enneigée Maison Moyenne 3 plan]]
[[ja:村/構造/設計図/雪原の中くらいの家3]]
[[zh:村庄/结构/图示/雪原中型房屋3]]
</noinclude>