<noinclude>{{structure info}}</noinclude>

[[File:Desert Animal Pen 1.png|thumb|Animal pen 1 (Desert)]]



==== Blueprint ====

{{layered blueprint|name=Village Desert Houses animal_pen_1|default=Layer 1
|C=Cut Sandstone
|S=Smooth Sandstone Stairs
|w=Waterlogged Smooth Sandstone Stairs
|s=Waterlogged Smooth Sandstone Stairs-rot90
|R=Waterlogged Smooth Sandstone Stairs-rot180
|r=Waterlogged Smooth Sandstone Stairs-rot270
|G=Grass Block+top
|W=Sandstone Wall
|L=Smooth Sandstone Slab+bottom
|g=Jungle Fence Gate
|----Layer 1|
            
 CCCCCCCCCC 
 CGGGGGGGGC 
 CGGGGGGGGC 
 CGGGGGGGGC 
 CGGGGGGGGC 
 CCCCCCCCCC 
     SS     
            
|----Layer 2|
            
 WWWWWWWWWW 
 W        W 
 W   sR   W 
 W W wr   W 
 W        W 
 WWWWggWWWW 
            
|----Layer 3-4|
            
 W W        
            
            
 W W        
            
            
            
|----Layer 5|
            
 LLL        
 LLL        
 LLL        
 LLL        
            
            
            
}}

All smooth sandstone slabs are bottom slabs. The water inside the stairs forms a square.



==== Materials ====

{| class="wikitable sortable mw-collapsible"
|-
! Name !! Total !! Layer 1 !! Layer 2 !! Layer 3 !! Layer 4 !! Layer 5 
|-
| {{BlockLink|Cut Sandstone}} || 28 || 28 || - || - || - || - 
|-
| {{BlockLink|Grass Block}} || 32 || 32 || - || - || - || - 
|-
| {{BlockLink|Jungle Fence Gate}} || 2 || - || 2 || - || - || - 
|-
| {{BlockLink|Sandstone Wall}} || 35 || - || 27 || 4 || 4 || - 
|-
| {{BlockLink|Smooth Sandstone Slab}} || 12 || - || - || - || - || 12 
|-
| {{BlockLink|Smooth Sandstone Stairs}} || 6 || 2 || 4 || - || - || - 
|-
| {{BlockLink|Water}} || 4 || - || 4 || - || - || - 
|}<noinclude>
[[Category:Village blueprints]]

[[fr:Village/Structure/Désert Enclos 1 plan]]
[[ja:村/構造/設計図/砂漠の牧柵1]]
[[zh:村庄/结构/图示/沙漠牲畜栏1]]
</noinclude>