<noinclude>{{structure info}}</noinclude>

[[File:Snowy Tundra Temple 1.png|thumb|Church 1 (Snowy tundra)]]



==== Blueprint ====

{{layered blueprint
|name=Snowy Church 1 snowy_church_1
|default=Layer 2
|w=Stripped Spruce Wood
|p=Spruce Planks
|s=Snow Block
|S=Snow
|x=Spruce Stairs
|y=Spruce Stairs-rot90
|z=Spruce Stairs-rot270
|b=Brewing Stand
|o=Spruce Door+bottom
|O=Spruce Door+top
|t=Torch
|T=Torch-rot180
|l=Lantern
|f=Spruce Fence
         
|----Layer 1|
         
 SssSsSS 
 SSsssSS 
 Swwwww  
 Swpppw  
 SwpppwS 
 SwpppwS 
 SwpppwS 
 SwpppwS 
 SwwwwwS 
 SSsxSsS 
         
|----Layer 2|
         
  SS S   
 p sss p 
 pwwwwwp 
 pz b yp 
 pz   yp 
 pz   yp 
 pz   yp 
 pz   yp 
 pwwowwp 
 p S   p 
         
|----Layer 3|
         
         
 p Ss  p 
 pwwwwwp 
 p     p 
 p     p 
 p     p 
 p     p 
 p     p 
 pwwOwwp 
 p     p 
         
|----Layer 4|
         
         
 Sp   pS 
 SpwwwpS 
 Sp   pS 
 Sp   pS 
 Sp   pS 
 Sp   pS 
 Sp   pS 
 SpwwwpS 
 Sp T pS 
         
|----Layer 5|
         
         
  p   p  
  pwwwp  
  p l p  
  p   p  
  p   p  
  p   p  
  p l p  
  pwwwp  
  p   p  
         
|----Layer 6|
         
         
  Sp pS  
  SpwpS  
  Spfp   
  Sw w   
   p pS  
   w wS  
   pfp   
  SpwpS  
  Sp pS  
         
|----Layer 7|
         
         
   SpS   
   SpS   
    p    
   wpw   
    p    
   wpw   
   SpS   
   SpS   
   SpS   
         
|----Layer 8|
         
         
         
         
         
   w w   
    t    
   w w   
    S    
    S    
|----Layer 9-10|
         
         
         
         
         
   w w   
   
   w w   
         
|----Layer 11|
         
         
         
         
  ppppp  
  pw wp  
  p   p  
  pw wp  
  ppppp  
         
|----Layer 12|
         
         
         
         
  SSSSS  
  SpppS  
  SpppS  
  SpppS  
  SSSSS  
         
|----Layer 13|
         
         
         
         
         
   SSS   
   SpS   
   SSS   
         
|----Layer 14|
         
         
         
         
         
         
    S    
         
}}

==== Materials ====

{| class="wikitable sortable mw-collapsible"
|-
! Name !! Total !! Layer 1 !! Layer 2 !! Layer 3 !! Layer 4 !! Layer 5 !! Layer 6 !! Layer 7 !! Layer 8 !! Layer 9 !! Layer 10 !! Layer 11 !! Layer 12 !! Layer 13 !! Layer 14 
|-
| {{BlockLink|Brewing Stand}} || 1 || - || 1 || - || - || - || - || - || - || - || - || - || - || - || - 
|-
| {{BlockLink|Lantern}} || 2 || - || - || - || - || 2 || - || - || - || - || - || - || - || - || - 
|-
| {{BlockLink|Snow}} || 163 || 60 || 9 || 1 || 24 || - || 19 || 22 || 3 || - || - || - || 16 || 8 || 1 
|-
| {{BlockLink|Snow Block}} || 12 || 8 || 3 || 1 || - || - || - || - || - || - || - || - || - || - || - 
|-
| {{ItemLink|Spruce Door}} || 1 || - || 1 || - || - || - || - || - || - || - || - || - || - || - || - 
|-
| {{BlockLink|Spruce Fence}} || 2 || - || - || - || - || - || 2 || - || - || - || - || - || - || - || - 
|-
| {{BlockLink|Spruce Planks}} || 136 || 15 || 18 || 18 || 18 || 18 || 14 || 9 || - || - || - || 16 || 9 || 1 || - 
|-
| {{BlockLink|Spruce Stairs}} || 11 || 1 || 10 || - || - || - || - || - || - || - || - || - || - || - || - 
|-
| {{BlockLink|Stripped Spruce Wood}} || 76 || 20 || 9 || 9 || 6 || 6 || 6 || 4 || 4 || 4 || 4 || 4 || - || - || - 
|-
| {{BlockLink|Torch}} || 2 || - || - || - || 1 || - || - || - || 1 || - || - || - || - || - || - 
|}<noinclude>
[[Category:Village blueprints]]

[[fr:Village/Structure/Toundra enneigée Temple 1 plan]]
[[ja:村/構造/設計図/雪原の礼拝所1]]
[[zh:村庄/结构/图示/雪原教堂]]
</noinclude>