<noinclude>{{structure info}}</noinclude>

[[File:Plains meeting point 5.png|thumb|Meeting Point 5 (Plains)]]



==== Blueprint ====

{{layered blueprint
|name=Meeting Point 5 meeting_point_5
|default=Layer 1
|p=Dirt Path+top
|g=Grass Block+top
|G=Short Grass
|d=Dirt
|o=Oak Planks
|b=Bell+ceiling
|f=Oak Fence
|w=White Wool
|y=Yellow Wool
|t=Torch-rot180
|r=Torch-rot90
|R=Torch-rot270
|s=Oak Slab
|z=Tall Grass
|T=Tall Grass+bottom
             
|----Layer 0|
             
 ggggggggggg 
 ggggggggggg 
 ggggdddgpgp 
 ggpggpgpppg 
 gggpppgpgpg 
 gdggppppgdg 
 gdpppgpppdg 
 gdgpppppgdg 
 ggggppgppgg 
 gpgpgpppgpg 
             
|----Layer 1|
             
 G  G  GG G  
  G GfTfT    
  G  oooG G  
 GG  f f     
  GG     G   
 fof     fof 
  o       o  
 fof     fof 
  G       GG 
 G G     G   
             
|----Layer 2|
             
             
     fzfz    
             
     f f     
             
 f f     f f 
             
 f f     f f 
             
             
             
|----Layer 3|
             
             
     f f     
      b      
     f f     
             
 f f     f f 
             
 f f     f f 
             
             
             
|----Layer 4|
             
             
     sws     
     sys     
     sws     
      t      
 sss     sss 
 ywyr   Rywy 
 sss     sss 
             
             
             
}}

All oak slabs are bottom slabs. Some of [[grass block]]s are not included, therefore some of the those blocks could be replaced by other blocks such as [[sand]].



==== Materials ====

{| class="wikitable sortable mw-collapsible"
|-
! Name !! Total !! Layer 0 !! Layer 1 !! Layer 2 !! Layer 3 !! Layer 4 
|-
| {{BlockLink|Bell}} || 1 || - || - || - || 1 || - 
|-
| {{BlockLink|Dirt}} || 9 || 9 || - || - || - || - 
|-
| {{BlockLink|Dirt Path}} || 37 || 37 || - || - || - || - 
|-
| {{BlockLink|Short Grass}} || 21 || - || 21 || - || - || - 
|-
| {{BlockLink|Grass Block}} || 64 || 64 || - || - || - || - 
|-
| {{BlockLink|Oak Fence}} || 36 || - || 12 || 12 || 12 || - 
|-
| {{BlockLink|Oak Planks}} || 9 || - || 9 || - || - || - 
|-
| {{BlockLink|Oak Slab}} || 18 || - || - || - || - || 18 
|-
| {{BlockLink|Tall Grass}} || 2 || - || 2 || - || - || - 
|-
| {{BlockLink|Torch}} || 3 || - || - || - || - || 3 
|-
| {{BlockLink|White Wool}} || 4 || - || - || - || - || 4 
|-
| {{BlockLink|Yellow Wool}} || 5 || - || - || - || - || 5 
|}<noinclude>
[[Category:Village blueprints]]

[[fr:Village/Structure/Plaines Lieu de Rassemblement 5 plan]]
[[ja:村/構造/設計図/平原の集会所5]]
[[zh:村庄/结构/图示/平原会合点5]]
</noinclude>