<noinclude>{{structure info}}</noinclude>

[[File:Snowy Tundra Meeting Point 2.png|thumb|Meeting point 2 (Snowy tundra)]]



==== Blueprint ====

{{layered blueprint
|name=Snowy Meeting Point 2 snowy_meeting_point_2
|default=Layer 1
|g=Grass Block+top
|d=Dirt
|p=Dirt Path+top
|i=Packed Ice
|B=Stone Bricks
|b=Bell
|s=Snow
|P=Spruce Planks
|t=Torch
|w=Spruce Stairs
|x=Spruce Stairs-rot90
|y=Spruce Stairs-rot180
|z=Spruce Stairs-rot270
             
|----Layer 0|
             
 ggggpppgggg 
 ggpppppppgg 
 gpppdddpppg 
 pppdBdddppp 
 pPpdddddppp 
 pppdddddppp 
 gpppdddpppg 
 gppppppppgg 
 ggggpppgggg 
             
|----Layer 1|
             
             
             
     yyz     
    yxizy    
  b xiiiz    
    wxiwz    
     xwz     
        s    
             
|----Layer 2|
             
             
             
             
      i      
     iii     
      i      
             
|----Layer 3|
             
             
             
             
             
      i      
             
|----Layer 4|             
             

             
             
      t      
             
}}

==== Materials ====

{| class="wikitable sortable mw-collapsible"
|-
! Name !! Total !! Layer 0 !! Layer 1 !! Layer 2 !! Layer 3 !! Layer 4 
|-
| {{BlockLink|Bell}} || 1 || - || 1 || - || - || - 
|-
| {{BlockLink|Dirt}} || 20 || 20 || - || - || - || - 
|-
| {{BlockLink|Dirt Path}} || 50 || 50 || - || - || - || - 
|-
| {{BlockLink|Grass Block}} || 27 || 27 || - || - || - || - 
|-
| {{BlockLink|Packed Ice}} || 11 || - || 5 || 5 || 1 || - 
|-
| {{BlockLink|Snow}} || 1 || - || 1 || - || - || - 
|-
| {{BlockLink|Spruce Planks}} || 1 || 1 || - || - || - || - 
|-
| {{BlockLink|Spruce Stairs}} || 16 || - || 16 || - || - || - 
|-
| {{BlockLink|Stone Bricks}} || 1 || 1 || - || - || - || - 
|-
| {{BlockLink|Torch}} || 1 || - || - || - || - || 1 
|}<noinclude>
[[Category:Village blueprints]]

[[fr:Village/Structure/Toundra enneigée Lieu de Rassemblement 2 plan]]
[[ja:村/構造/設計図/雪原の集会所2]]
[[zh:村庄/结构/图示/雪原会合点2]]
</noinclude>