<noinclude>{{structure info}}</noinclude>

[[File:Plains Small House 8.png|thumb|Small House 8 (Plains)]]



==== Blueprint ====

{{layered blueprint
|name=Village Plains Houses plains_small_house_8
|default=Layer 2
|O=Oak Log+top
|L=Oak Log-rot90
|l=Oak Log
|C=Cobblestone
|c=Cobblestone Stairs
|d=Oak Door+bottom
|D=Oak Door+top
|)=Cobblestone Stairs-rot270
|(=Cobblestone Stairs-rot90
|T=torch-rot180
|t=torch
|\=Oak Stairs
|<=Oak Stairs-rot90
|/=Oak Stairs-rot270
|>=Oak Stairs-rot180
|g=glass Pane
|G=glass Pane-rot90
|P=Oak Planks
|W=White Bed+top foot-rot270
|o=White Bed+top head-rot270
|f=Farmland+moist
|w=Water+top
|q=Dirt
|b=Grass Block+top
|X=Oak Stairs
|z=Wheat
            
|----Layer 0|
           
     b     
    fwf    
   qqqqq   
  fqqqqqf  
 bwqqqqqwb 
  fqqqqqf  
    qqq    
    qqq    
           
|----Layer 1|
           
           
    z z    
   OCCCO   
  zCPPPCz  
   CPPPC   
  zCPPPCz  
   OCCCO   
    (c)    
            
|----Layer 2|
           
           
           
   OCCCO   
   Co XC   
   CW  C   
   C   C   
   OCdCO   
           
|----Layer 3|
           
           
           
   OCgCO   
   C   C   
   g   g   
   C   C   
   OCDCO   
           
|----Layer 4|
           
           
           
   OCCCO   
   C   C   
   C   C   
   C   C   
   OCCCO   
     T     
           
|----Layer 5|
           
           
  /<   >\  
  /OLLLO\  
  /C T C\  
  /C   C\  
  /C   C\  
  /OLLLO\  
  /<   >\  
           
|----Layer 6|
           
           
   /< >\   
   /CCC\   
   P   P   
   g   g   
   P   P   
   /CCC\   
   /< >\   
           
|----Layer 7|
           
           
    /P\    
    /P\    
   /PPP\   
   /PPP\   
   /PPP\   
    /P\    
    /P\    
           
}}

The wheat crops won't replace to the [[carrot]], [[potato]], or [[beetroot]] crops. Also, the wheat crops are always mature.

==== Materials ====

{| class="wikitable sortable mw-collapsible"
|-
! Name !! Total !! Layer 0 !! Layer 1 !! Layer 2 !! Layer 3 !! Layer 4 !! Layer 5 !! Layer 6 !! Layer 7 
|-
| {{BlockLink|Cobblestone}} || 55 || - || 12 || 11 || 8 || 12 || 6 || 6 || - 
|-
| {{BlockLink|Cobblestone Stairs}} || 3 || - || 3 || - || - || - || - || - || - 
|-
| {{BlockLink|Dirt}} || 26 || 26 || - || - || - || - || - || - || - 
|- 
| {{BlockLink|Farmland}} || 6 || 6 || - || - || - || - || - || - || - 
|-
| {{BlockLink|Glass Pane}} || 5 || - || - || - || 3 || - || - || 2 || - 
|-
| {{BlockLink|Grass Block}} || 3 || 3 || - || - || - || - || - || - || - 
|-
| {{ItemLink|Oak Door}} || 1 || - || - || 1 || - || - || - || - || - 
|-
| {{BlockLink|Oak Log}} || 26 || - || 4 || 4 || 4 || 4 || 10 || - || - 
|-
| {{BlockLink|Oak Planks}} || 26 || - || 9 || - || - || - || - || 4 || 13 
|-
| {{BlockLink|Oak Stairs}} || 45 || - || - || 1 || - || - || 18 || 12 || 14 
|-
| {{BlockLink|Torch}} || 2 || - || - || - || - || 1 || 1 || - || - 
|-
| {{BlockLink|Water}} || 3 || 3 || - || - || - || - || - || - || - 
|-
| {{BlockLink|Wheat}} || 6 || - || 6 || - || - || - || - || - || - 
|-
| {{BlockLink|White Bed}} || 1 || - || - || 1 || - || - || - || - || - 
|}
<noinclude>
[[Category:Village blueprints]]

[[fr:Village/Structure/Plaines Petite Maison 8 plan]]
[[ja:村/構造/設計図/平原の小さな家8]]
[[zh:村庄/结构/图示/平原小型房屋8]]
</noinclude>