<noinclude>{{structure info}}</noinclude>

[[File:Savanna Meeting Point 4.png|thumb|Meeting Point 4 (Savanna)]]



==== Blueprint ====

{{layered blueprint|name=
Savanna Meeting Point 4|default=Layer 1
|A=Acacia Wood
|C=Double Acacia Slab
|B=Bell
|D=Dirt Path+top
|T=Torch
|W=Water+top
|I=Acacia Fence
|S=Acacia Stairs
|R=Grass Block+top
           
|----Layer 1|
           
 R  DDD    
  DDDDDDDR 
  DDDDDDD  
 DDDDADDDD 
 DDDAAADDD 
 DDDDADDDD 
  DDDDDDD  
  DDDDDDD  
    DDD    
           
|----Layer 2|
           
           
           
    AAA    
   AAWAA   
   AWWWA   
   AAWAA   
    AAA    
           
           
           
|----Layer 3|
           
           
           
     T     
    I I    
   T   T   
    I I    
     T     
           
           
           
|----Layer 4|
           
           
           
           
    I I    
     B     
    I I    
           
           
           
           
|----Layer 5|
           
           
           
           
    SSS    
    SCS    
    SSS    
           
           
           
           
}}



==== Materials ====

{| class="wikitable sortable mw-collapsible"
|-
! Name !! Total !! Layer 1 !! Layer 2 !! Layer 3 !! Layer 4 !! Layer 5 
|-
| {{BlockLink|Acacia Fence}} || 8 || - || - || 4 || 4 || - 
|-
| {{BlockLink|Acacia Slab}} || 2 || - || - || - || - || 2 
|-
| {{BlockLink|Acacia Stairs}} || 8 || - || - || - || - || 8 
|-
| {{BlockLink|Acacia Wood}} || 21 || 5 || 16 || - || - || - 
|-
| {{BlockLink|Bell}} || 1 || - || - || - || 1 || - 
|-
| {{BlockLink|Grass Block}} || 2 || 2 || - || - || - || - 
|-
| {{BlockLink|Dirt Path}} || 56 || 56 || - || - || - || - 
|-
| {{BlockLink|Torch}} || 4 || - || - || 4 || - || - 
|-
| {{BlockLink|Water}} || 5 || - || 5 || - || - || - 
|}<noinclude>
[[Category:Village blueprints]]

[[fr:Village/Structure/Savane Lieu de Rassemblement 4 plan]]
[[ja:村/構造/設計図/サバンナの集会所4]]
[[zh:村庄/结构/图示/热带草原会合点4]]
</noinclude>