<noinclude>{{structure info}}</noinclude>

[[File:Savanna Large Farm 2.png|thumb|Large Farm 2 (Savanna)]]



==== Blueprint ====

{{layered blueprint|name=
Savanna Large Farm 2|default=Layer 1
|G=Grass Block+top
|D=Dirt
|F=Farmland
|W=Wheat
|T=Tall Grass
|t=Tall Grass+bottom
|A=Water+top
|R=Dirt Path+top
|S=Short Grass
|C=Composter
          
|----Layer 1|
          
   GGGGGD 
  GGDDGGG 
  DGGGGGD 
 DGGDDGGG 
 DDGGGDGG 
 GGGDGGDD 
  DDGDGGG 
  DGGGGGD 
 GGGDGDGG 
  D DG    
          
|----Layer 2|
          
   RFFRRG 
  RFAGRFA 
  GFFFFFG 
 GFFGGFFR 
 DAFFFARF 
 FFFFFRGG 
  GGRFFFF 
  GRFFFFA 
 FFFARGFF 
  G GR    
          
|----Layer 3|
          
    WW  S 
   W t W  
  SWWWWWt 
 tWW SWW  
   WWW  W 
 WWWWW tS 
  tC WWWW 
  S WWWW  
 WWW  tWW 
  S S     
          
|----Layer 4|
          
          
     T    
        T 
 T        
          
       T  
  T       
          
      T   
          
          
}}

Note: This farm follows the topography of the existing terrain. The water sources may end up washing away planted crops that spawn down-hill.



==== Materials ====

{| class="wikitable sortable mw-collapsible"
|-
! Name !! Total !! Layer 1 !! Layer 2 !! Layer 3 
|-
| {{BlockLink|Composter}} || 1 || - || - || 1 
|-
| {{BlockLink|Dirt}} || 24 || 23 || 1 || - 
|-
| {{BlockLink|Farmland}} || 35 || - || 35 || - 
|-
| {{BlockLink|Short Grass}} || 7 || - || - || 7 
|-
| {{BlockLink|Grass Block}} || 61 || 46 || 15 || - 
|-
| {{BlockLink|Dirt Path}} || 12 || - || 12 || - 
|-
| {{BlockLink|Tall Grass}} || 6 || - || - || 6 
|-
| {{BlockLink|Water}} || 6 || - || 6 || - 
|-
| {{BlockLink|Wheat}} || 35 || - || - || 35 
|}<noinclude>
[[Category:Village blueprints]]

[[fr:Village/Structure/Savane Grande Ferme 2 plan]]
[[ja:村/構造/設計図/サバンナの大きな畑2]]
[[zh:村庄/结构/图示/热带草原大型农田2]]
</noinclude>