<noinclude>{{structure info}}</noinclude>

[[File:Plains Meeting Point 4.png|thumb|Meeting Point 4 (Plains)]]



==== Blueprint ====

{{layered blueprint
|name=Meeting Point 4 meeting_point_4
|default=Layer 1
|p=Dirt Path+top
|g=Grass Block+top
|G=Short Grass
|c=Cobblestone
|d=Dirt
|o=Oak Planks
|b=Bell
|f=Oak Fence
|w=White Wool
|y=Yellow Wool
|t=Torch
|D=Dandelion
|s=Oak Slab
|z=Tall Grass
|T=Tall Grass+bottom
                  
|----Layer 0|
                  
 gggggggggggggggg 
 gggggpgpggpggpgg 
 ggpppgdgggcgpggp 
 gggcgpcgpgpgcppg 
 ggdgppppcpgpgdgg 
 ggdpccpgcgcgcdgg 
 ggdcpgpppggcpdpg 
 ggdgpppcgpcpgdgg 
 ggpgcgpgpgpgpcgg 
 gpgggpgpcgppgggg 
                  
|----Layer 1|
                  
  G GGTGG    G GG 
 T   G G G  G     
 G    Go G        
   T G  D         
 Gfof        fof  
  Go          oGG 
  Go          o G 
 Gfof        fofG 
               GT 
 G  G        GGDT 
                  
|----Layer 2|
                  
      z           
 z                
       b          
   z              
  ftf        ftf  
                  
                  
  ftf        ftf  
                z 
                z 
                  
|----Layer 3|
                  
                  
                  
                  
                  
  f f        f f  
                  
                  
  f f        f f  
                  
                  
                  
|----Layer 4|
                  
                  
                  
                  
                  
  sss        sss  
  ywy        wyw  
  wyw        ywy  
  sss        sss  
                  
                  
                  
}}

All oak slabs are bottom slabs.



==== Materials ====

{| class="wikitable sortable mw-collapsible"
|-
! Name !! Total !! Layer 0 !! Layer 1 !! Layer 2 !! Layer 3 !! Layer 4 
|-
| {{BlockLink|Bell}} || 1 || - || - || 1 || - || - 
|-
| {{BlockLink|Cobblestone}} || 17 || 17 || - || - || - || - 
|-
| {{BlockLink|Dandelion}} || 2 || - || 2 || - || - || - 
|-
| {{BlockLink|Dirt}} || 9 || 9 || - || - || - || - 
|-
| {{BlockLink|Dirt Path}} || 42 || 42 || - || - || - || - 
|-
| {{BlockLink|Short Grass}} || 29 || - || 29 || - || - || - 
|-
| {{BlockLink|Grass Block}} || 91 || 91 || - || - || - || - 
|-
| {{BlockLink|Oak Fence}} || 24 || - || 8 || 8 || 8 || - 
|-
| {{BlockLink|Oak Planks}} || 9 || - || 9 || - || - || - 
|-
| {{BlockLink|Oak Slab}} || 12 || - || - || - || - || 12 
|-
| {{BlockLink|Tall Grass}} || 5 || - || 5 || - || - || - 
|-
| {{BlockLink|Torch}} || 4 || - || - || 4 || - || - 
|-
| {{BlockLink|White Wool}} || 6 || - || - || - || - || 6 
|-
| {{BlockLink|Yellow Wool}} || 6 || - || - || - || - || 6 
|}<noinclude>
[[Category:Village blueprints]]

[[fr:Village/Structure/Plaines Lieu de Rassemblement 4 plan]]
[[ja:村/構造/設計図/平原の集会所4]]
[[zh:村庄/结构/图示/平原会合点4]]
</noinclude>