<noinclude>{{structure info}}</noinclude>

[[File:Taiga Tannery 1.png|thumb|Tannery 1 (Taiga)]]



==== Blueprint ====

{{layered blueprint|name=
Taiga Tannery 1|default=Layer 1
|S=Spruce Log
|G=Grass Block+top
|C=Cobblestone
|H=Chest
|P=Spruce Trapdoor
|L=Large Fern
|l=Large Fern+bottom
|O=Poppy
|A=Glass Pane-rot-90
|F=Fern
|W=Wall Torch-rot-180
|T=Wall Torch
|R=Torch
|B=Cobblestone Stairs
|U=Spruce Door+bottom
|w=Water Cauldron
|E=Spruce Door+top
          
|----Layer 1|
          
          
  CCCCCCC 
  CCCCCCC 
  CCCCCCC 
  CCCCCCC 
  CCCCCCC 
  CCCCCCC 
 PGGGGCBC 
  PPPP    
          
|----Layer 2|
          
          
  CCCCCCC 
  CHP  wC 
  CP P wC 
  CP P  C 
  C P   C 
  CCCCCUC 
  lOlFR R 
          
          
|----Layer 3|
          
 S P P P S
 SCCACACCS
 SC     CS
 SC     CS
 SC     CS
 SC     CS
 SCCACCECS
 SLPLP   S
          
          
|----Layer 4|
          
  S     S 
  SCCCCCS 
  S     S 
  S     S 
  S     S 
  S     S 
  SCCCCCS 
  S     S 
          
          
|----Layer 5|
          
   S   S  
   SCCCS  
   S T S  
   S C S  
   S C S  
   S W S  
   SCCCS  
   S   S  
          
          
|----Layer 6|
          
    SSS   
    SSS   
    SSS   
    SSS   
    SSS   
    SSS   
    SSS   
    SSS   
          
          
}}



==== Materials ====

{| class="wikitable sortable mw-collapsible"
|-
! Name !! Total !! Layer 1 !! Layer 2 !! Layer 3 !! Layer 4 !! Layer 5 !! Layer 6 
|-
| {{BlockLink|Chest}} || 1 || - || 1 || - || - || - || - 
|-
| {{BlockLink|Cobblestone}} || 101 || 44 || 21 || 18 || 10 || 8 || - 
|-
| {{BlockLink|Cobblestone Stairs}} || 1 || 1 || - || - || - || - || - 
|-
| {{BlockLink|Fern}} || 1 || - || 1 || - || - || - || - 
|-
| {{BlockLink|Glass Pane}} || 3 || - || - || 3 || - || - || - 
|-
| {{BlockLink|Grass Block}} || 4 || 4 || - || - || - || - || - 
|-
| {{BlockLink|Large Fern}} || 4 || - || 2 || 2 || - || - || - 
|-
| {{BlockLink|Poppy}} || 1 || - || 1 || - || - || - || - 
|-
| {{BlockLink|Spruce Door}} || 1 || - || 1 || - || - || - || - 
|-
| {{BlockLink|Spruce Log}} || 72 || - || - || 16 || 16 || 16 || 24 
|-
| {{BlockLink|Spruce Trapdoor}} || 16 || 5 || 6 || 5 || - || - || - 
|-
| {{BlockLink|Torch}} || 4 || - || 2 || - || - || 2 || - 
|-
| {{BlockLink|Water Cauldron}} || 2 || - || 2 || - || - || - || - 
|}<noinclude>
[[Category:Village blueprints]]

[[fr:Village/Structure/Taïga Tannerie 1 plan]]
[[zh:村庄/结构/图示/针叶林皮匠屋]]
</noinclude>