<noinclude>{{structure info}}</noinclude>

[[File:Desert Library 1.png|thumb|Library 1 (Desert)]]



==== Blueprint ====

{{layered blueprint|name=Desert Library 1
|default=Layer 1
|S=Sand
|M=Smooth Sandstone
|C=Cut Sandstone
|A=Sandstone Slab
|a=Sandstone
|B=Bookshelf
|L=Lectern-rot90
|J=Jungle Door+bottom
|P=Potted Cactus
|U=Jungle Door+top
|O=Smooth Sandstone Stairs-rot90
|W=White Carpet
|I=Lime Carpet
|T=Wall Torch-rot180
|R=Wall Torch-rot270
           
|----Layer 0|
           
 SSSSSSSSS 
 SSMMMMMSS 
 SSMMMMMSS 
 SSMMMMMSS 
 SSSSMSSSS 
           
|----Layer 1|
           
 CMMMMMMMC 
 MB     OM 
 MB WIW LM 
 MB     OM 
 CMMMJMMMC 
           
|----Layer 2|
           
 CMPMMMPMC 
 MB  T   M 
 MB     RM 
 MB      M 
 CMPMUMPMC 
           
|----Layer 3|
           
 CMAMMMAMC 
 MB      M 
 MB      M 
 MB      M 
 CMAMaMAMC 
           
|----Layer 4|
           
 CMMMMMMMC 
 MMMMMMMMM 
 MMMMMMMMM 
 MMMMMMMMM 
 CMMMMMMMC 
           
|----Layer 5|
           
 CCCCCCCCC 
 C       C 
 C       C 
 C       C 
 CCCCCCCCC 
           
|----Layer 6|
           
 C       C 
           
           
           
 C       C 
           
}}



==== Materials ====

{| class="wikitable sortable mw-collapsible"
|-
! Name !! Total !! Layer 0 !! Layer 1 !! Layer 2 !! Layer 3 !! Layer 4 !! Layer 5 !! Layer 6 
|-
| {{BlockLink|Bookshelf}} || 9 || - || 3 || 3 || 3 || - || - || - 
|-
| {{BlockLink|Cut Sandstone}} || 44 || - || 4 || 4 || 4 || 4 || 24 || 4 
|-
| {{ItemLink|Jungle Door}} || 1 || - || 1 || - || - || - || - || - 
|-
| {{BlockLink|Lectern}} || 1 || - || 1 || - || - || - || - || - 
|-
| {{BlockLink|Lime Carpet}} || 1 || - || 1 || - || - || - || - || - 
|-
| {{BlockLink|Potted Cactus}} || 4 || - || - || 4 || - || - || - || - 
|-
| {{BlockLink|Sand}} || 29 || 29 || - || - || - || - || - || - 
|-
| {{BlockLink|Sandstone}} || 1 || - || - || - || 1 || - || - || - 
|-
| {{BlockLink|Sandstone Slab}} || 4 || - || - || - || 4 || - || - || - 
|-
| {{BlockLink|Smooth Sandstone}} || 106 || 16 || 19 || 15 || 15 || 41 || - || - 
|-
| {{BlockLink|Smooth Sandstone Stairs}} || 2 || - || 2 || - || - || - || - || - 
|-
| {{BlockLink|Torch}} || 2 || - || - || 2 || - || - || - || - 
|-
| {{BlockLink|White Carpet}} || 2 || - || 2 || - || - || - || - || - 
|}<noinclude>
[[Category:Village blueprints]]

[[fr:Village/Structure/Désert Bibliothèque 1 plan]]
[[ja:村/構造/設計図/砂漠の図書室1]]
[[zh:村庄/结构/图示/沙漠图书馆]]
</noinclude>