<noinclude>{{structure info}}</noinclude>

[[File:Savanna Armorer 1.png|thumb|Armorer 1 (Savanna)]]



==== Blueprint ====

{{layered blueprint|name=
Savanna Armorer 1|default=Layer 1
|G=Grass Block+top
|D=Dirt
|A=Acacia Log+top
|C=Acacia Planks
|O=Orange Terracotta
|I=Acacia Log
|R=Orange Glazed Terracotta
|B=Blast Furnace
|S=Short Grass
|T=Acacia Stairs
|P=Dirt Path+top
|c=Acacia Door+bottom
|a=Acacia Door+top
|W=Wall Torch
         
|----Layer 1|
         
 GGGGGGG 
 GGDDDGG 
 GDDDDDG 
 GDOOODG 
 GDCCCDG 
 GGDIDGG 
 GGGPGGG 
         
|----Layer 2|
         
 SSS     
 S AAA   
 SAOBOA  
 SA   A  
 SA   A  
 SSAcA   
 SS      
         
|----Layer 3|
         
         
   AAA   
  AOROA  
  A   A  
  A   A  
   AaA   
         
         
|----Layer 4|
         
         
   AAA   
  A O A  
  A   A  
  A W A  
   AIA   
         
         
|----Layer 5|
         
  TTTTT  
 TCCCCCT 
 TC O CT 
 TC   CT 
 TC   CT 
 TCCCCCT 
  TTTTT  
         
|----Layer 6|
         
         
  TTTTT  
  TCOCT  
  TCCCT  
  TCCCT  
  TTTTT  
         
         
}}



==== Materials ====

{| class="wikitable sortable mw-collapsible"
|-
! Name !! Total !! Layer 1 !! Layer 2 !! Layer 3 !! Layer 4 !! Layer 5 !! Layer 6 
|-
| {{BlockLink|Acacia Door}} || 1 || - || 1 || - || - || - || - 
|-
| {{BlockLink|Acacia Log}} || 35 || 1 || 11 || 11 || 12 || - || - 
|-
| {{BlockLink|Acacia Planks}} || 27 || 3 || - || - || - || 16 || 8 
|-
| {{BlockLink|Acacia Stairs}} || 36 || - || - || - || - || 20 || 16 
|-
| {{BlockLink|Blast Furnace}} || 1 || - || 1 || - || - || - || - 
|-
| {{BlockLink|Dirt}} || 14 || 14 || - || - || - || - || - 
|-
| {{BlockLink|Short Grass}} || 11 || - || 11 || - || - || - || - 
|-
| {{BlockLink|Grass Block}} || 27 || 27 || - || - || - || - || - 
|-
| {{BlockLink|Dirt Path}} || 1 || 1 || - || - || - || - || - 
|-
| {{BlockLink|Orange Glazed Terracotta}} || 1 || - || - || 1 || - || - || - 
|-
| {{BlockLink|Orange Terracotta}} || 10 || 3 || 2 || 2 || 1 || 1 || 1 
|-
| {{BlockLink|Torch}} || 1 || - || - || - || 1 || - || - 
|}<noinclude>
[[Category:Village blueprints]]

[[fr:Village/Structure/Savane Armurier 1 plan]]
[[ja:村/構造/設計図/サバンナの防具鍛冶の家1]]
[[zh:村庄/结构/图示/热带草原盔甲匠房屋]]
</noinclude>