<noinclude>{{structure info}}</noinclude>

[[File:Savanna Mason 1.png|thumb|Mason 1 (Savanna)]]



==== Blueprint ====

{{layered blueprint|name=
Savanna Mason 1|default=Layer 1
|G=Grass Block+top
|D=Dirt
|A=Acacia Log+top
|C=Acacia Log
|I=Acacia Planks
|Y=Yellow Glazed Terracotta-rot-90
|Z=Yellow Glazed Terracotta-rot-180
|L=Clay
|H=Chest-rot-90
|R=Short Grass
|S=Acacia Stairs
|P=Glass Pane
|T=Stonecutter
|F=Acacia Fence
|E=Acacia Pressure Plate
|N=Glass Pane-rot-90
|W=Wall Torch-rot-180
|O=Acacia Door+bottom
|c=Acacia Door+top
            
|----Layer 1|
            
 GGDDDDDDGG 
 GDIIIIIIDG 
 GDIIIIIIDG 
 GDIIIIIIDG 
 GGDIIIIDGG 
 GGGDCCDGGG 
 GGGGGDGGGG 
            
|----Layer 2|
            
   AAAAAA   
  A  LHLLA  
  AT    LA  
  A      A  
 RRAF  FAR  
 R  AOOAR R 
 RRRR  RRR  
            
|----Layer 3|
            
   ANAANA   
  A     LA  
  P      P  
  A      A  
   AE  EA   
    AccA    
            
            
|----Layer 4|
            
   ACAACA   
  A W  WLA  
  C      C  
  A      A  
   Y    Z   
    YZYZ    
            
            
|----Layer 5|
            
  SIIIIIIS  
 SI      IS 
 SI      IS 
 SI      IS 
  SI    IS  
   SIIIIS   
    SSSS    
            
|----Layer 6|
            
   SSSSSS   
  SIIIIIIS  
  SIIIIIIS  
  SIIIIIIS  
   SIIIIS   
    SSSS    
            
            
}}



==== Materials ====

{| class="wikitable sortable mw-collapsible"
|-
! Name !! Total !! Layer 1 !! Layer 2 !! Layer 3 !! Layer 4 !! Layer 5 !! Layer 6 
|-
| {{BlockLink|Acacia Door}} || 2 || - || 2 || - || - || - || - 
|-
| {{BlockLink|Acacia Fence}} || 2 || - || 2 || - || - || - || - 
|-
| {{BlockLink|Acacia Log}} || 42 || 2 || 16 || 12 || 12 || - || - 
|-
| {{BlockLink|Acacia Planks}} || 62 || 22 || - || - || - || 18 || 22 
|-
| {{BlockLink|Acacia Pressure Plate}} || 2 || - || - || 2 || - || - || - 
|-
| {{BlockLink|Acacia Stairs}} || 34 || - || - || - || - || 16 || 18 
|-
| {{BlockLink|Chest}} || 1 || - || 1 || - || - || - || - 
|-
| {{BlockLink|Clay}} || 6 || - || 4 || 1 || 1 || - || - 
|-
| {{BlockLink|Dirt}} || 17 || 17 || - || - || - || - || - 
|-
| {{BlockLink|Glass Pane}} || 4 || - || - || 4 || - || - || - 
|-
| {{BlockLink|Short Grass}} || 13 || - || 13 || - || - || - || - 
|-
| {{BlockLink|Grass Block}} || 29 || 29 || - || - || - || - || - 
|-
| {{BlockLink|Stonecutter}} || 1 || - || 1 || - || - || - || - 
|-
| {{BlockLink|Torch}} || 2 || - || - || - || 2 || - || - 
|-
| {{BlockLink|Yellow Glazed Terracotta}} || 6 || - || - || - || 6 || - || - 
|}<noinclude>
[[Category:Village blueprints]]

[[fr:Village/Structure/Savane Maçon 1 plan]]
[[ja:村/構造/設計図/サバンナの石工場1]]
[[zh:村庄/结构/图示/热带草原石匠屋]]
</noinclude>