<noinclude>{{structure info}}</noinclude>

[[File:Savanna Small House 5.png|thumb|Small House 5 (Savanna)]]



==== Blueprint ====

{{layered blueprint|name=Savanna Small House 5|default=Layer 1
|G=Grass Block+top
|D=Dirt
|A=Acacia Log+top
|C=Acacia Log
|c=Acacia Log-rot-90
|Y=Yellow Terracotta
|I=Acacia Planks
|O=Orange Bed+side+foot
|R=Orange Bed+side+head
|F=Acacia Fence
|S=Short Grass
|L=Acacia Slab
|P=Glass Pane
|s=Acacia Stairs
|>=Acacia Stairs-rot-90
|^=Acacia Stairs-rot-180
|<=Acacia Stairs-rot-270
|E=Acacia Pressure Plate
|H=Dirt Path+top
|d=Acacia Door+bottom
|N=Glass Pane-rot-90
|a=Acacia Door+top
|W=Wall Torch
|l=Wall Torch-rot-180
         
|----Layer 1|
         
 GGGHGGG 
 GGDIDGG 
 GDIIIDG 
 GDIIIDG 
 GDIIIDG 
 GGDDDGG 
 GGGGGGG 
         
|----Layer 2|
         
 SFS SFS 
 F AdASF 
  A   AS 
 SC   A  
  AFORAS 
 F AAA F 
  F   FS 
         
|----Layer 3|
         
  F   F  
 F AaA F 
  A   A  
  P   P  
  AE  A  
 F ANA F 
  F   F  
         
|----Layer 4|
         
  F W F  
 F AcA F 
  A l A  
  C   C  
  A W A  
 F AcA F 
  F   F  
         
|----Layer 5|
         
  F   F  
 F YYY F 
  Y   Y  
  Y   Y  
  Y   Y  
 F YYY F 
  F   F  
         
|----Layer 6|
         
  LLLLL  
 LLLLLLL 
 LLYYYLL 
 LLY YLL 
 LLYYYLL 
 LLLLLLL 
  LLLLL  
         
|----Layer 7|
         
         
         
   YFY   
   F F   
   YFY   
         
         
         
|----Layer 8|
         
         
         
   YYY   
   Y Y   
   YYY   
         
         
         
|----Layer 9|
         
         
  ^^^^>  
  <III>  
  <III>  
  <III>  
  <ssss  
         
         
|----Layer 10|
         
         
         
   <^^   
   <I>   
   ss>   
         
         
         
}}



==== Materials ====

{| class="wikitable sortable mw-collapsible"
|-
! Name !! Total !! Layer 1 !! Layer 2 !! Layer 3 !! Layer 4 !! Layer 5 !! Layer 6 !! Layer 7 !! Layer 8 !! Layer 9 !! Layer 10 
|-
| {{BlockLink|Acacia Door}} || 1 || - || 1 || - || - || - || - || - || - || - || - 
|-
| {{BlockLink|Acacia Fence}} || 37 || - || 9 || 8 || 8 || 8 || - || 4 || - || - || - 
|-
| {{BlockLink|Acacia Log}} || 31 || - || 11 || 8 || 12 || - || - || - || - || - || - 
|-
| {{BlockLink|Acacia Planks}} || 20 || 10 || - || - || - || - || - || - || - || 9 || 1 
|-
| {{BlockLink|Acacia Pressure Plate}} || 1 || - || - || 1 || - || - || - || - || - || - || - 
|-
| {{BlockLink|Acacia Slab}} || 36 || - || - || - || - || - || 36 || - || - || - || - 
|-
| {{BlockLink|Acacia Stairs}} || 24 || - || - || - || - || - || - || - || - || 16 || 8 
|-
| {{BlockLink|Dirt}} || 11 || 11 || - || - || - || - || - || - || - || - || - 
|-
| {{BlockLink|Glass Pane}} || 3 || - || - || 3 || - || - || - || - || - || - || - 
|-
| {{BlockLink|Short Grass}} || 9 || - || 9 || - || - || - || - || - || - || - || - 
|-
| {{BlockLink|Grass Block}} || 27 || 27 || - || - || - || - || - || - || - || - || - 
|-
| {{BlockLink|Dirt Path}} || 1 || 1 || - || - || - || - || - || - || - || - || - 
|-
| {{BlockLink|Orange Bed}} || 1 || - || 1 || - || - || - || - || - || - || - || - 
|-
| {{BlockLink|Torch}} || 3 || - || - || - || 3 || - || - || - || - || - || - 
|-
| {{BlockLink|Yellow Terracotta}} || 32 || - || - || - || - || 12 || 8 || 4 || 8 || - || - 
|}<noinclude>
[[Category:Village blueprints]]

[[fr:Village/Structure/Savane Petite Maison 5 plan]]
[[ja:村/構造/設計図/サバンナの小さな家5]]
[[zh:村庄/结构/图示/热带草原小型房屋5]]
</noinclude>