<noinclude>{{structure info}}</noinclude>

[[File:Savanna Small House 3.png|thumb|Small House 3 (Savanna)]]



==== Blueprint ====

{{layered blueprint|name=Savanna Small House 3|default=Layer 1
|G=grass block+top
|D=dirt
|O=orange terracotta
|A=acacia planks
|C=acacia wood
|R=crafting table
|I=acacia wood-rot-90
|N=Orange Bed+side+head-rot-180
|E=Orange Bed+side+foot-rot-180
|S=short grass
|L=glass pane
|s=acacia stairs
|>=acacia stairs-rot-90
|^=acacia stairs-rot-180
|<=acacia stairs-rot-270
|W=Wall Torch-rot-270
|P=glass pane-rot-90
|d=acacia door+bottom
|o=acacia door+top
|H=dirt path+top
         
|----Layer 1|
         
 GGGGGGG 
 GGDDDGG 
 GDCCCDG 
 GDCCCIH 
 GDCICDG 
 GGDDDGG 
 GGGGGGG 
         
|----Layer 2|
         
 S S S   
 SSOOO   
 SOR  OS 
  O   d  
  ONE O  
 SSOOOSS 
 S     S 
         
|----Layer 3|
         
         
   OPO   
  O   O  
  L   o  
  O   O  
   OPO   
         
         
|----Layer 4|
         
         
   OOO   
  O   O  
  OW  O  
  O   O  
   OOO   
         
         
|----Layer 5|
         
  ^^^^^  
 <AAAAA> 
 <A   A> 
 <A   A> 
 <A   A> 
 <AAAAA> 
  sssss  
         
|----Layer 6|
         
         
  <^^^>  
  <AAA>  
  <AAA>  
  <AAA>  
  sssss  
         
         
|----Layer 7|
         
         
         
   ^^>   
   <A>   
   <ss   
         
         
         
}}



==== Materials ====

{| class="wikitable sortable"
|-
! Name !! Total !! Layer 1 !! Layer 2 !! Layer 3 !! Layer 4 !! Layer 5 !! Layer 6 !! Layer 7 
|-
| {{BlockLink|Acacia Door}} || 1 || - || 1 || - || - || - || - || - 
|-
| {{BlockLink|Acacia Planks}} || 26 || - || - || - || - || 16 || 9 || 1 
|-
| {{BlockLink|Acacia Stairs}} || 44 || - || - || - || - || 20 || 16 || 8 
|-
| {{BlockLink|Acacia Wood}} || 10 || 10 || - || - || - || - || - || - 
|-
| {{BlockLink|Crafting Table}} || 1 || - || 1 || - || - || - || - || - 
|-
| {{BlockLink|Dirt}} || 11 || 11 || - || - || - || - || - || - 
|-
| {{BlockLink|Glass Pane}} || 3 || - || - || 3 || - || - || - || - 
|-
| {{BlockLink|Short Grass}} || 13 || - || 13 || - || - || - || - || - 
|-
| {{BlockLink|Grass Block}} || 27 || 27 || - || - || - || - || - || - 
|-
| {{BlockLink|Dirt Path}} || 1 || 1 || - || - || - || - || - || - 
|-
| {{BlockLink|Orange Bed}} || 1 || - || 1 || - || - || - || - || - 
|-
| {{BlockLink|Orange Terracotta}} || 31 || - || 11 || 8 || 12 || - || - || - 
|-
| {{BlockLink|Torch}} || 1 || - || - || - || 1 || - || - || - 
|}<noinclude>
[[Category:Village blueprints]]

[[fr:Village/Structure/Savane Petite Maison 3 plan]]
[[ja:村/構造/設計図/サバンナの小さな家3]]
[[zh:村庄/结构/图示/热带草原小型房屋3]]
</noinclude>