<noinclude>{{structure info}}</noinclude>

[[File:Desert Fisher 1.png|thumb|Fisher 1 (Desert)]]



==== Blueprint ====
* [[Java Edition]]
{{layered blueprint|name=Village Desert Houses desert_fisher_1 (JE)|default=Layer 1
|s=Sand
|S=Smooth Sandstone
|H=Hay Bale
|h=Hay Bale-rot90
|z=Hay Bale+top
|C=Cut Sandstone
|W=Water+top
|F=Potted Dead Bush
|f=Potted Cactus
|d=Jungle Door+bottom
|D=Jungle Door+top
|L=Smooth Sandstone Slab
|T=torch-rot270
|t=torch-rot180
|w=Barrel
|b=Barrel-rot90
|B=Barrel+top
|+=torch
|----Layer 0|
          
 ssssssss 
 ssssssss 
 sCCCssss 
 sCCCssss 
 sssssSSs 
 s ssSSSs 
 s ssSSSs 
 SSSSSSSs 
  sssSSSs 
 s ssssss 
 s        
|----Layer 1|
          
 CCCCC    
 CWWWC    
 CWWWC    
 CWWWCCSC 
 CCCCCSBS 
 F wCS  S 
   fS   S 
    d   S 
  h S bbS 
   zCSSSC 
 H        
|----Layer 2|
          
    FC    
          
 f   C    
      CSC 
 C C CStS 
   BCS  S 
    S   S 
    D   S 
    S +wS 
   HCSSSC 
          
|----Layer 3|
          
     C    
          
     C    
      CSC 
 C C CS S 
    CS  L 
    S   S 
   TS   L 
    S   S 
    CSLSC 
          
|----Layer 4|
          
     C    
          
     C    
      CLC 
 C C CLLL 
    CLLLL 
    LLLLL 
    LLLLL 
    LLLLL 
    CLLLC 
          
|----Layer 5|
          
     C    
     L    
     C    
     L    
 CLCLC    
          
          
          
          
          
          
          
}}

* [[Bedrock Edition]]
{{layered blueprint|name=Village Desert Houses desert_fisher_1 (BE)|default=Layer 1
|s=Sand
|S=Smooth Sandstone
|H=Hay Bale
|h=Hay Bale-rot90
|z=Hay Bale+top
|C=Cut Sandstone
|W=Water+top
|F=Potted Dead Bush
|f=Potted Cactus
|d=Jungle Door+bottom
|D=Jungle Door+top
|L=Smooth Sandstone Slab
|T=torch-rot270
|t=torch-rot180
|w=Barrel
|b=Barrel-rot90
|B=Barrel+top
|+=torch
|----Layer 0|
          
 ssssssss 
 ssssssss 
 sCCCssss 
 sCCCssss 
 sssssSSs 
 s ssSSSs 
 s ssSSSs 
 SSSSSSSs 
  sssSSSs 
 s ssssss 
 s        
|----Layer 1|
          
 CCCCC    
 CWWWC    
 CWWWC    
 CWWWCCSC 
 CCCCCS S 
 F wCS  S 
   fS   S 
    d   S 
  h S  BS 
   zCSSSC 
 H        
|----Layer 2|
          
    FC    
          
 f   C    
      CSC 
 C C CStS 
    CS  S 
    S   S 
    D   S 
    S + S 
   HCSSSC 
          
|----Layer 3|
          
     C    
          
     C    
      CSC 
 C C CS S 
    CS  L 
    S   S 
   TS   L 
    S   S 
    CSLSC 
          
|----Layer 4|
          
     C    
          
     C    
      CLC 
 C C CLLL 
    CLLLL 
    LLLLL 
    LLLLL 
    LLLLL 
    CLLLC 
          
|----Layer 5|
          
     C    
     L    
     C    
     L    
 CLCLC    
          
          
          
          
          
          
          
}}

==== Materials ====

{| class="wikitable sortable mw-collapsible"
|-
! Name !! Total !! Layer 0 !! Layer 1 !! Layer 2 !! Layer 3 !! Layer 4 !! Layer 5 
|-
| {{BlockLink|Barrel}} || 6{{only|JE|short=1}} 2{{only|BE|short=1}} || - || 4{{only|JE|short=1}} 2{{only|BE|short=1}} || 2{{only|JE|short=1}} 0{{only|BE|short=1}} || - || - || - 
|-
| {{BlockLink|Cut Sandstone}} || 62 || 6 || 21 || 10 || 10 || 10 || 5 
|-
| {{BlockLink|Hay Bale}} || 4 || - || 3 || 1 || - || - || - 
|-
| {{ItemLink|Jungle Door}} || 1 || - || 1 || - || - || - || - 
|-
| {{BlockLink|Potted Cactus}} || 2 || - || 1 || 1 || - || - || - 
|-
| {{BlockLink|Potted Dead Bush}} || 2 || - || 1 || 1 || - || - || - 
|-
| {{BlockLink|Sand}} || 53 || 53 || - || - || - || - || - 
|-
| {{BlockLink|Smooth Sandstone}} || 55 || 18 || 13 || 13 || 11 || - || - 
|-
| {{BlockLink|Smooth Sandstone Slab}} || 33 || - || - || - || 3 || 26 || 4 
|-
| {{BlockLink|Torch}} || 3 || - || - || 2 || 1 || - || - 
|-
| {{BlockLink|Water}} || 9 || - || 9 || - || - || - || - 
|}<noinclude>
[[Category:Village blueprints]]

[[fr:Village/Structure/Désert Pêcheur 1 plan]]
[[ja:村/構造/設計図/砂漠の釣り人の家1]]
[[zh:村庄/结构/图示/沙漠渔夫小屋]]
</noinclude>