<noinclude>{{structure info}}</noinclude>

[[File:Plains Small House 3.png|thumb|Small House 3 (Plains)]]



==== Blueprint ====

{{layered blueprint
|name=Village Plains Houses plains_small_house_3
|default=Layer 2
|P=Oak Planks
|O=Oak Log+top
|L=Oak Log-rot90
|l=Oak Log
|B=Yellow Bed+top foot-rot270
|b=Yellow Bed+top head-rot270
|C=Cobblestone
|s=Oak Stairs
|<=Oak Stairs-rot90
|^=Oak Stairs-rot180
|>=Oak Stairs-rot270
|d=Oak Door+bottom
|D=Oak Door+top
|g=glass Pane
|G=glass Pane-rot90
|T=torch-rot180
|----Layer 1|
         
         
  OCCCO  
  CPPPC  
  CPPPC  
  CPPPC  
  OCCCO  
    s    
|----Layer 2|
         
         
  OCCCO  
  Cb sC  
  CB  C  
  C   C  
  OCdCO  
         
|----Layer 3|
         
         
  OLGLO  
  l   l  
  g   g  
  l   l  
  OCDCO  
         
|----Layer 4|
         
         
  OCCCO  
  C T C  
  C   C  
  C   C  
  OCCCO  
    T    
|----Layer 5|
         
 ^^^^^^> 
 <PPPPP> 
 <P   P> 
 <P   P> 
 <P   P> 
 <PPPPP> 
 <ssssss 
|----Layer 6|
         
         
  <^^^>  
  <PPP>  
  <P P>  
  <PPP>  
  sssss  
|----Layer 7|
         
         
         
   <^^   
   <P>   
   sss   
         
         
         
}}

==== Materials ====

{| class="wikitable sortable mw-collapsible"
|-
! Name !! Total !! Layer 1 !! Layer 2 !! Layer 3 !! Layer 4 !! Layer 5 !! Layer 6 !! Layer 7 
|-
| {{BlockLink|Cobblestone}} || 37 || 12 || 11 || 2 || 12 || - || - || - 
|-
| {{BlockLink|Glass Pane}} || 3 || - || - || 3 || - || - || - || - 
|-
| {{ItemLink|Oak Door}} || 1 || - || 1 || - || - || - || - || - 
|-
| {{BlockLink|Oak Log}} || 22 || 4 || 4 || 10 || 4 || - || - || - 
|-
| {{BlockLink|Oak Planks}} || 34 || 9 || - || - || - || 16 || 8 || 1 
|-
| {{BlockLink|Oak Stairs}} || 50 || 1 || 1 || - || - || 24 || 16 || 8 
|-
| {{BlockLink|Torch}} || 2 || - || - || - || 2 || - || - || - 
|-
| {{BlockLink|Yellow Bed}} || 1 || - || 1 || - || - || - || - || - 
|}<noinclude>
[[Category:Village blueprints]]

[[fr:Village/Structure/Plaines Petite Maison 3 plan]]
[[ja:村/構造/設計図/平原の小さな家3]]
[[zh:村庄/结构/图示/平原小型房屋3]]
</noinclude>