<noinclude>{{structure info}}</noinclude>

[[File:Snowy Tundra Small House 5.png|thumb|Small house 5 (Snowy tundra)]]



==== Blueprint ====

{{layered blueprint
|name=Snowy Small House 5 snowy_small_house_5
|default=Layer 1
|i=Dirt
|g=Grass Block+top
|b=Blue Ice
|s=Snow Block
|S=Snow
|r=Red Bed+top-head-rot270
|R=Red Bed+top-foot-rot270
|c=Chest
|d=Spruce Door+bottom
|D=Spruce Door+top
|t=Torch
|T=Torch-rot180
       
|----Layer 0|
       
 ggigg 
 gigig 
 igggi 
 igggi 
 igggi 
 igggi 
  igi  
       
|----Layer 1|
       
 SSbSS 
 Sb bS 
 sr cs 
 sR  s 
 s   s 
 s   s 
  bdb  
       
|----Layer 2|
       
   b   
  bTb  
 s   s 
 s   s 
 s   s 
 s   s 
  bDb  
       
|----Layer 3|
       
       
   s   
  b b  
 s   s 
 s   s 
  btb  
   s   
       
|----Layer 4|
       
 
       
   s   
  sss  
  sss  
   s   
       
}}

==== Materials ====

{| class="wikitable sortable mw-collapsible"
|-
! Name !! Total !! Layer 0 !! Layer 1 !! Layer 2 !! Layer 3 !! Layer 4 
|-
| {{BlockLink|Blue Ice}} || 14 || - || 5 || 5 || 4 || - 
|-
| {{BlockLink|Chest}} || 1 || - || 1 || - || - || - 
|-
| {{BlockLink|Dirt}} || 13 || 13 || - || - || - || - 
|-
| {{BlockLink|Grass Block}} || 20 || 20 || - || - || - || - 
|-
| {{BlockLink|Red Bed}} || 1 || - || 1 || - || - || - 
|-
| {{BlockLink|Snow}} || 6 || - || 6 || - || - || - 
|-
| {{BlockLink|Snow Block}} || 30 || - || 8 || 8 || 6 || 8 
|-
| {{ItemLink|Spruce Door}} || 1 || - || 1 || - || - || - 
|-
| {{BlockLink|Torch}} || 2 || - || - || 1 || 1 || - 
|}<noinclude>
[[Category:Village blueprints]]

[[fr:Village/Structure/Toundra enneigée Petite Maison 5 plan]]
[[ja:村/構造/設計図/雪原の小さな家5]]
[[zh:村庄/结构/图示/雪原小型房屋5]]
</noinclude>