<noinclude>{{structure info}}</noinclude>

[[File:Savanna Butchers Shop 1.png|thumb|Butchers Shop 1 (Savanna)]]



==== Blueprint ====

{{layered blueprint|name=
Savanna Butchers Shop 1|default=Layer 1
|A=Acacia Log+top
|C=Acacia Planks
|Y=Yellow Terracotta
|O=Orange Terracotta
|B=Cobblestone
|G=Grass Block+top
|I=Acacia Log
|S=Smooth Stone Slab
|M=Smoker
|R=Short Grass
|T=Acacia Stairs
|F=Acacia Fence
|L=Cobblestone Wall
|H=Torch
|W=Wall Torch-rot-180
|P=Glass Pane-rot-90
|D=Acacia Door+bottom
|c=Acacia Door+top
|a=Wall Torch
|i=Dirt
             
|----Layer 1|
             
 R AAAAAAR   
  RAGGGGAR   
 RRAGGiGA    
  RAGGGGAR R 
  RAAAAAAAR  
 RAOYOYOSOAR 
 RAYOYOYSYAR 
  RAYOYAAA R 
 RRAOYA      
   RAIAR RRR 
 R RTTT      
             
|----Layer 2|
             
   FFFFFF    
   F    F    
   F    F    
   F    F    
   AAADAAA   
  AB     SA  
  AM     SA  
   A   AAA   
   A  A      
    ADA      
             
             
|----Layer 3|
             
   H    H    
             
             
             
   APAcAPA   
  A       A  
  AL      A  
   A   APA   
   A  A      
    AcA      
    W W      
             
|----Layer 4|
             
             
             
             
             
   AIAIAIA   
  A   W   A  
  AL      A  
   A   AIA   
   A aA      
    AIA      
             
             
|----Layer 5|
             
             
             
             
  TTTTTTTTT  
 TCCCCCCCCCT 
 TC       CT 
 TCL      CT 
 TCC   CCCCT 
 TTC  CCTTT  
  TCCCCT     
  TTTTTT     
             
|----Layer 6|
             
             
             
             
             
  TTTTTTTTT  
  TCCCCCCCT  
  TLCCCCCCT  
  TTCCCTTTT  
   TCCTT     
   TTTT      
             
             
|----Layer 7|
             
             
             
             
             
             
             
   L         
             
             
             
             
             
}}

==== Materials ====

{| class="wikitable sortable mw-collapsible"
|-
! Name !! Total !! Layer 1 !! Layer 2 !! Layer 3 !! Layer 4 !! Layer 5 !! Layer 6 !! Layer 7 
|-
| {{BlockLink|Acacia Door}} || 2 || - || 2 || - || - || - || - || - 
|-
| {{BlockLink|Acacia Fence}} || 12 || - || 12 || - || - || - || - || - 
|-
| {{BlockLink|Acacia Log}} || 85 || 32 || 18 || 15 || 20 || - || - || - 
|-
| {{BlockLink|Acacia Planks}} || 44 || - || - || - || - || 26 || 18 || - 
|-
| {{BlockLink|Acacia Stairs}} || 59 || 3 || - || - || - || 30 || 26 || - 
|-
| {{BlockLink|Cobblestone}} || 1 || - || 1 || - || - || - || - || - 
|-
| {{BlockLink|Cobblestone Wall}} || 5 || - || - || 1 || 1 || 1 || 1 || 1 
|-
| {{BlockLink|Dirt}} || 1 || 1 || - || - || - || - || - || - 
|-
| {{BlockLink|Glass Pane}} || 3 || - || - || 3 || - || - || - || - 
|-
| {{BlockLink|Short Grass}} || 26 || 26 || - || - || - || - || - || - 
|-
| {{BlockLink|Grass Block}} || 11 || 11 || - || - || - || - || - || - 
|-
| {{BlockLink|Orange Terracotta}} || 8 || 8 || - || - || - || - || - || - 
|-
| {{BlockLink|Smoker}} || 1 || - || 1 || - || - || - || - || - 
|-
| {{BlockLink|Smooth Stone Slab}} || 6 || 2 || 4 || - || - || - || - || - 
|-
| {{BlockLink|Torch}} || 6 || - || - || 4 || 2 || - || - || - 
|-
| {{BlockLink|Yellow Terracotta}} || 9 || 9 || - || - || - || - || - || - 
|}<noinclude>
[[Category:Village blueprints]]

[[fr:Village/Structure/Savane Échoppe de Boucher 1 plan]]
[[ja:村/構造/設計図/サバンナの肉屋1]]
[[zh:村庄/结构/图示/热带草原肉铺1]]
</noinclude>