<noinclude>{{structure info}}</noinclude>

[[File:Snowy Tundra Fisher Cottage.png|thumb|Fisher cottage (Snowy tundra)]]



==== Blueprint ====
* [[Java Edition]]
{{layered blueprint
|name=Snowy Fisher Cottage snowy_fisher_cottage (JE)
|default=Layer 2
|l=Stripped Spruce Log+top
|a=Stripped Spruce Log
|S=Spruce Slab
|t=Spruce Slab+top
|D=Dirt
|s=Snow
|p=Spruce Planks
|o=Spruce Door+bottom
|O=Spruce Door+top
|f=Spruce Fence
|B=Barrel
|z=Barrel+bottom
|b=Barrel-rot90
|G=Grass Block+top
|P=Dirt Path+top
|g=Glass Pane-rot90
|h=Spruce Stairs
|w=Water+top
|L=Lantern
         
|----Layer 0|
         
 GGGGGGG 
 GDDDDDG 
 GDDDDDG 
 GDDDDDG 
 GDDDDDG 
 GDDDDGG 
 GDDDDGG 
 GDDDDDG 
 GDDDDGG 
         
|----Layer 1|
         
 sssssss 
 sllllls 
 slpppls 
 slpppls 
 sllllls 
 sGGPPss 
 sGwwPss 
  GwwPhs 
 sGGGGss 
         
|----Layer 2|
         
 t     t 
  llall  
 tlB  lt 
 tlz  lt 
  lloll  
 t     t 
  f  f   
         
|----Layer 3|
         
 p     p 
 plagalp 
 plb  lp 
 pl   lp 
 pllOllp 
 p     p 
  L      
  fL f   
         
|----Layer 4|
         
 Sp   pS 
  plalp  
 Sp   pS 
 Sp   pS 
  plalp  
 Sp   pS 
  f      
  f      
  ffff   
         
|----Layer 5|
         
  Sp pS  
   plp   
  SpLpS  
  Sp pS  
   plp   
  Sp pS  
         
|----Layer 6|
         
   SpS   
    p    
   SpS   
   SpS   
    p    
   SpS   
         
|----Layer 7|
         
    S    
    S    
    S    
    S    
         
}}

* [[Bedrock Edition]]
{{layered blueprint
|name=Snowy Fisher Cottage snowy_fisher_cottage (BE)
|default=Layer 2
|l=Stripped Spruce Log+top
|a=Stripped Spruce Log
|S=Spruce Slab
|t=Spruce Slab+top
|D=Dirt
|s=Snow
|p=Spruce Planks
|o=Spruce Door+bottom
|O=Spruce Door+top
|f=Spruce Fence
|B=Barrel
|z=Barrel+bottom
|b=Barrel-rot90
|T=Barrel+top
|G=Grass Block+top
|P=Dirt Path+top
|g=Glass Pane-rot90
|h=Spruce Stairs
|w=Water+top
|L=Lantern
         
|----Layer 0|
         
 GGGGGGG 
 GDDDDDG 
 GDDDDDG 
 GDDDDDG 
 GDDDDDG 
 GDDDDGG 
 GDDDDGG 
 GDDDDDG 
 GDDDDGG 
         
|----Layer 1|
         
 sssssss 
 sllllls 
 slpppls 
 slpppls 
 sllllls 
 sGGPPss 
 sGwwPss 
  GwwPhs 
 sGGGGss 
         
|----Layer 2|
         
 t     t 
  llall  
 tlT  lt 
 tlz  lt 
  lloll  
 t     t 
  f  f   
         
|----Layer 3|
         
 p     p 
 plagalp 
 pl   lp 
 pl   lp 
 pllOllp 
 p     p 
  L      
  fL f   
         
|----Layer 4|
         
 Sp   pS 
  plalp  
 Sp   pS 
 Sp   pS 
  plalp  
 Sp   pS 
  f      
  f      
  ffff   
         
|----Layer 5|
         
  Sp pS  
   plp   
  SpLpS  
  Sp pS  
   plp   
  Sp pS  
         
|----Layer 6|
         
   SpS   
    p    
   SpS   
   SpS   
    p    
   SpS   
         
|----Layer 7|
         
    S    
    S    
    S    
    S    
         
}}


All of the spruce slabs in layer 2 are top slabs, while the rest are bottom slabs.



==== Materials ====

{| class="wikitable sortable mw-collapsible"
|-
! Name !! Total !! Layer 0 !! Layer 1 !! Layer 2 !! Layer 3 !! Layer 4 !! Layer 5 !! Layer 6 !! Layer 7 
|-
| {{BlockLink|Barrel}} || 3{{only|JE|short=1}} 2{{only|BE|short=1}} || - || - || 2 || 1{{only|JE|short=1}} 0{{only|BE|short=1}} || - || - || - || - 
|-
| {{BlockLink|Lantern}} || 3 || - || - || - || 2 || - || 1 || - || - 
|-
| {{BlockLink|Dirt}} || 32 || 32 || - || - || - || - || - || - || - 
|-
| {{BlockLink|Dirt Path}} || 4 || - || 4 || - || - || - || - || - || - 
|-
| {{BlockLink|Glass Pane}} || 1 || - || - || - || 1 || - || - || - || - 
|-
| {{BlockLink|Grass Block}} || 38 || 30 || 8 || - || - || - || - || - || - 
|-
| {{BlockLink|Snow}} || 25 || - || 25 || - || - || - || - || - || - 
|-
| {{ItemLink|Spruce Door}} || 1 || - || - || 1 || - || - || - || - || - 
|-
| {{BlockLink|Spruce Fence}} || 10 || - || - || 2 || 2 || 6 || - || - || - 
|-
| {{BlockLink|Spruce Planks}} || 48 || - || 6 || - || 12 || 12 || 12 || 6 || - 
|-
| {{BlockLink|Spruce Slab}} || 36 || - || - || 8 || - || 8 || 8 || 8 || 4 
|-
| {{BlockLink|Spruce Stairs}} || 1 || - || 1 || - || - || - || - || - || - 
|-
| {{BlockLink|Stripped Spruce Log}} || 47 || - || 14 || 13 || 12 || 6 || 2 || - || - 
|-
| {{BlockLink|Water}} || 4 || - || 4 || - || - || - || - || - || - 
|}<noinclude>
[[Category:Village blueprints]]

[[fr:Village/Structure/Toundra enneigée Cabanon de Pêcheur plan]]
[[ja:村/構造/設計図/雪原の釣り小屋1]]
[[zh:村庄/结构/图示/雪原渔夫小屋]]
</noinclude>