<noinclude>{{structure info}}</noinclude>

[[File:Taiga Large Farm 2.png|thumb|Large Farm 2 (Taiga)]]



==== Blueprint ====

{{layered blueprint|name=
Taiga Large Farm 2|default=Layer 1
|G=Grass Block+top
|D=Dirt
|P=Pumpkin
|L=Large Fern
|l=Large Fern+bottom
|S=Spruce Trapdoor
|F=Farmland
|W=Wheat
|A=Water+top
|R=Dirt Path+top
|C=Cobblestone Stairs
|E=Fern
|O=Cobblestone Wall
|T=Torch
|M=Composter
           
|----Layer 1|
           
   D  GGR  
  G     RG 
 DGGGGGGRG 
  GGGGDGRG 
  GDGGGRRD 
 GGGGGRRD  
 GGGGRRG   
  D  RDGG  
           
|----Layer 2|
           
   P  E    
  l SSSS O 
 P SFFFF M 
  SFFFAF l 
 SFAFFF    
 SFFFC  P  
 lSFF  O   
  PSS P l  
           
|----Layer 3|
           
           
  L      O 
    WWWW   
   WWW W L 
  W WWW    
  WWW      
 L WW  O   
        L  
           
|----Layer 4|
           
           
         T 
           
           
           
           
       T   
           
           
}}



==== Materials ====

{| class="wikitable sortable mw-collapsible"
|-
! Name !! Total !! Layer 1 !! Layer 2 !! Layer 3 !! Layer 4 
|-
| {{BlockLink|Cobblestone Stairs}} || 1 || - || 1 || - || - 
|-
| {{BlockLink|Cobblestone Wall}} || 4 || - || 2 || 2 || - 
|-
| {{BlockLink|Composter}} || 1 || - || 1 || - || - 
|-
| {{BlockLink|Dirt}} || 8 || 8 || - || - || - 
|-
| {{BlockLink|Farmland}} || 17 || - || 17 || - || - 
|-
| {{BlockLink|Fern}} || 1 || - || 1 || - || - 
|-
| {{BlockLink|Grass Block}} || 33 || 33 || - || - || - 
|-
| {{BlockLink|Dirt Path}} || 11 || 11 || - || - || - 
|-
| {{BlockLink|Large Fern}} || 8 || - || 4 || 4 || - 
|-
| {{BlockLink|Pumpkin}} || 5 || - || 5 || - || - 
|-
| {{BlockLink|Spruce Trapdoor}} || 11 || - || 11 || - || - 
|-
| {{BlockLink|Torch}} || 2 || - || - || - || 2 
|-
| {{BlockLink|Water}} || 2 || - || 2 || - || - 
|-
| {{BlockLink|Wheat}} || 17 || - || - || 17 || - 
|}<noinclude>
[[Category:Village blueprints]]

[[fr:Village/Structure/Taïga Grande Ferme 2 plan]]
[[zh:村庄/结构/图示/针叶林大型农田2]]
</noinclude>