<noinclude>{{structure info}}</noinclude>

[[File:Desert Fletcher House 1.png|thumb|Fletcher house 1 (Desert)]]



==== Blueprint ====

{{layered blueprint|name=Desert Fletcher House 1
|default=Layer 1
|S=Sand
|C=Cut Sandstone
|M=Smooth Sandstone
|F=Fletching Table
|o=Smooth Sandstone Slab+bottom
|O=Smooth Sandstone Slab+top
|D=Double Smooth Sandstone Slab
|P=Potted Cactus
|W=Wall Torch-rot-180
|J=Jungle Door+bottom
|U=Jungle Door+top
|T=Smooth Sandstone Stairs-rot90
|L=Ladder
|A=Wall Torch-rot-90
|N=Sandstone Wall
|R=Torch
              
|----Layer 0|
              
 SSSSSSSSS    
 SMMMMMMMMSSS 
 SMMMMMMMMMMS 
 SMMMMMMMMSSS 
 SSSMSSSSS    
    M         
              
|----Layer 1|
              
 CMMMMMMMC    
 MM      TCMC 
 MF       J M 
 MM      TCMC 
 CMMJMMMMC    
              
              
|----Layer 2|
              
 CMMMPMMMC    
 M W   W  CMC 
 P        ULM 
 M        CMC 
 CMMUMMPMC    
   W          
              
|----Layer 3|
              
 CMMMOMMMC    
 MOOOOOOOOCMC 
 OOOOOOOOOMLM 
 MOOOOOOOOCMC 
 CMMMMMOMC    
              
              
|----Layer 4|
              
 C o o o C    
          CMC 
 o        MLM 
          CMC 
 C o o o C    
              
|----Layer 5-6|
              
              
          CMC 
          MLM 
          CMC 
              
              
|----Layer 7|
              
              
          CMC 
          MAM 
          CMC 
              
              
              
|----Layer 8|
              
              
          CMC 
          M M 
          CMC 
              
              
              
|----Layer 9|
              
              
          CoC 
          oDo 
          CoC 
              
              
              
|----Layer 10|
              
              
              
           N  
              
              
              
              
|----Layer 11|
              
              
              
           R  
              
              
              
              
}}

==== Materials ====

{| class="wikitable sortable mw-collapsible"
|-
! Name !! Total !! Layer 0 !! Layer 1 !! Layer 2 !! Layer 3 !! Layer 4 !! Layer 5 !! Layer 6 !! Layer 7 !! Layer 8 !! Layer 9 !! Layer 10 !! Layer 11 
|-
| {{BlockLink|Cut Sandstone}} || 52 || - || 8 || 8 || 8 || 8 || 4 || 4 || 4 || 4 || 4 || - || - 
|-
| {{BlockLink|Fletching Table}} || 1 || - || 1 || - || - || - || - || - || - || - || - || - || - 
|-
| {{ItemLink|Jungle Door}} || 2 || - || 2 || - || - || - || - || - || - || - || - || - || - 
|-
| {{BlockLink|Ladder}} || 5 || - || - || 1 || 1 || 1 || 1 || 1 || - || - || - || - || - 
|-
| {{BlockLink|Potted Cactus}} || 3 || - || - || 3 || - || - || - || - || - || - || - || - || - 
|-
| {{BlockLink|Sand}} || 27 || 27 || - || - || - || - || - || - || - || - || - || - || - 
|-
| {{BlockLink|Sandstone Wall}} || 1 || - || - || - || - || - || - || - || - || - || - || 1 || - 
|-
| {{BlockLink|Smooth Sandstone}} || 103 || 28 || 21 || 16 || 18 || 4 || 4 || 4 || 4 || 4 || - || - || - 
|-
| {{BlockLink|Smooth Sandstone Slab}} || 40 || - || - || - || 27 || 7 || - || - || - || - || 6 || - || - 
|-
| {{BlockLink|Smooth Sandstone Stairs}} || 2 || - || 2 || - || - || - || - || - || - || - || - || - || - 
|-
| {{BlockLink|Torch}} || 5 || - || - || 3 || - || - || - || - || 1 || - || - || - || 1 
|}<noinclude>
[[Category:Village blueprints]]

[[fr:Village/Structure/Désert Maison de Fléchier 1 plan]]
[[ja:村/構造/設計図/砂漠の矢師の家1]]
[[zh:村庄/结构/图示/沙漠制箭师房屋]]
</noinclude>