<noinclude>{{structure info}}</noinclude>

[[File:Desert Meeting Point 1.png|thumb|Meeting point 1 (Desert)]]



==== Blueprint ====

{{layered blueprint|name=Desert Meeting Point 1
|default=Layer 1
|S=Smooth Sandstone
|A=Sand
|C=Cut Sandstone
|T=Terracotta
|B=Bell
|P=Potted Cactus
|W=Water+top
|O=Torch
           
|----Layer 0|
           
    SSS    
  SSSSSSS  
  SSAAASS  
 SSASSSASS 
 SSASASASS 
 SSASSSASS 
 SSSAAASSS 
 SSSSSSSSS 
 SSSSSSSSS 
 SSSSSSSSS 
           
|----Layer 1|
           
           
           
    CCC    
   CWWWC   
   CWCWC   
   CWWWC   
    CCC    
           
           
           
           
|----Layer 2|
           
           
           
           
           
     C     
   P       
     B     
           
           
           
           
|----Layer 3|
           
           
           
           
           
     C     
           
           
           
           
           
           
|----Layer 4|
           
           
           
           
           
     T     
           
           
           
           
           
           
|----Layer 5|
           
           
           
           
           
     O     
           
           
           
           
           
           
}}

==== Materials ====

{| class="wikitable sortable mw-collapsible"
|-
! Name !! Total !! Layer 0 !! Layer 1 !! Layer 2 !! Layer 3 !! Layer 4 !! Layer 5 
|-
| {{BlockLink|Bell}} || 1 || - || - || 1 || - || - || - 
|-
| {{BlockLink|Cut Sandstone}} || 15 || - || 13 || 1 || 1 || - || - 
|-
| {{BlockLink|Potted Cactus}} || 1 || - || - || 1 || - || - || - 
|-
| {{BlockLink|Sand}} || 13 || 13 || - || - || - || - || - 
|-
| {{BlockLink|Smooth Sandstone}} || 67 || 67 || - || - || - || - || - 
|-
| {{BlockLink|Terracotta}} || 1 || - || - || - || - || 1 || - 
|-
| {{BlockLink|Torch}} || 1 || - || - || - || - || - || 1 
|-
| {{BlockLink|Water}} || 8 || - || 8 || - || - || - || - 
|}<noinclude>
[[Category:Village blueprints]]

[[fr:Village/Structure/Désert Lieu de Rassemblement 1 plan]]
[[ja:村/構造/設計図/砂漠の集会所1]]
[[zh:村庄/结构/图示/沙漠会合点1]]
</noinclude>