<noinclude>{{structure info}}</noinclude>

[[File:Savanna Small House 4.png|thumb|Small House 4 (Savanna)]]



==== Blueprint ====

{{layered blueprint|name=Savanna Small House 4|default=Layer 1
|G=Grass Block+top
|D=Dirt
|A=Acacia Log+top
|C=Acacia Log
|c=Acacia Log-rot-90
|I=Acacia Planks
|W=Acacia Wood
|w=Acacia Wood-rot-90
|B=Brown Wall Banner
|O=Orange Bed+side+head-rot-180
|R=Orange Bed+side+foot-rot-180
|H=Chest
|S=Short Grass
|T=Tall Grass
|t=Tall Grass+bottom
|s=Acacia Stairs
|>=Acacia Stairs-rot-90
|^=Acacia Stairs-rot-180
|<=Acacia Stairs-rot-270
|F=Acacia Fence
|L=Glass Pane
|a=Acacia Slab
|l=Wall Torch-rot-270
|i=Acacia Door+bottom
|o=Acacia Door+top
|P=Glass Pane-rot-90
|r=Wall Torch-rot-90
|p=Dirt Path+top
         
|----Layer 1|
         
 GGGGGGG 
 GGDDDGG 
 GDIIIDG 
 GDIIIwp 
 GDIIIDD 
 GGDWDGG 
 GGGGGGG 
 GGGGGGG 
 GGGGGGG 
 GGGGGGG 
         
|----Layer 2|
         
 tSS   S 
 SSAcA   
 SAORHA  
  A   i  
 SA   A  
  SAiA   
  SS     
    S S  
  FS  F  
 S S S S 
         
|----Layer 3|
         
 T       
   APA   
  A   A  
  L   o  
  A   A  
   AoA   
         
         
  F   F  
         
         
|----Layer 4|
         
         
   AcA   
  A   A  
  Cl rCl 
  A   A  
   AcA   
         
         
  F   F  
         
         
|----Layer 5|
         
         
   AFA   
  A   A  
  F   F  
  A   A  
   AFA   
 Ba   aB 
 BaaaaaB 
 BIaaaIB 
  BBBBB  
         
|----Layer 6|
         
  ^^^^^  
 <IIIII> 
 <I   I> 
 <I   I> 
 <I   I> 
 <IIIII> 
  sssss  
         
         
         
         
|----Layer 7|
         
         
  ^^^^^  
  <III>  
  <III>  
  <III>  
  sssss  
         
         
         
         
         
|----Layer 8|
         
         
         
   ^^>   
   <I>   
   <ss   
         
         
         
         
         
         
}}



==== Materials ====

{| class="wikitable sortable mw-collapsible"
|-
! Name !! Total !! Layer 1 !! Layer 2 !! Layer 3 !! Layer 4 !! Layer 5 !! Layer 6 !! Layer 7 !! Layer 8 
|-
| {{BlockLink|Acacia Door}} || 2 || - || 2 || - || - || - || - || - || - 
|-
| {{BlockLink|Acacia Fence}} || 10 || - || 2 || 2 || 2 || 4 || - || - || - 
|-
| {{BlockLink|Acacia Log}} || 38 || - || 10 || 8 || 12 || 8 || - || - || - 
|-
| {{BlockLink|Acacia Planks}} || 37 || 9 || - || - || - || 2 || 16 || 9 || 1 
|-
| {{BlockLink|Acacia Slab}} || 10 || - || - || - || - || 10 || - || - || - 
|-
| {{BlockLink|Acacia Stairs}} || 44 || - || - || - || - || - || 20 || 16 || 8 
|-
| {{BlockLink|Acacia Wood}} || 2 || 2 || - || - || - || - || - || - || - 
|-
| {{BlockLink|Brown Wall Banner}} || 11 || - || - || - || - || 11 || - || - || - 
|-
| {{BlockLink|Chest}} || 1 || - || 1 || - || - || - || - || - || - 
|-
| {{BlockLink|Dirt}} || 11 || 11 || - || - || - || - || - || - || - 
|-
| {{BlockLink|Glass Pane}} || 2 || - || - || 2 || - || - || - || - || - 
|-
| {{BlockLink|Short Grass}} || 17 || - || 17 || - || - || - || - || - || - 
|-
| {{BlockLink|Grass Block}} || 47 || 47 || - || - || - || - || - || - || - 
|-
| {{BlockLink|Dirt Path}} || 1 || 1 || - || - || - || - || - || - || - 
|-
| {{BlockLink|Orange Bed}} || 1 || - || 1 || - || - || - || - || - || - 
|-
| {{BlockLink|Tall Grass}} || 1 || - || 1 || - || - || - || - || - || - 
|-
| {{BlockLink|Torch}} || 3 || - || - || - || 3 || - || - || - || - 
|}<noinclude>
[[Category:Village blueprints]]

[[fr:Village/Structure/Savane Petite Maison 4 plan]]
[[ja:村/構造/設計図/サバンナの小さな家4]]
[[zh:村庄/结构/图示/热带草原小型房屋4]]
</noinclude>