<noinclude>{{structure info}}</noinclude>

[[File:Snowy Tundra Small House 7.png|thumb|Small house 7 (Snowy tundra)]]



==== Blueprint ====

{{layered blueprint
|name=Snowy Small House 7 snowy_small_house_7
|default=Layer 2
|l=Stripped Spruce Log+top
|L=Stripped Spruce Log
|S=Snow
|s=Spruce Slab
|f=Spruce Fence
|d=Spruce Door+bottom
|D=Spruce Door+top
|a=Lantern
|w=White Bed+top-head-rot270
|W=White Bed+top-foot-rot270
|g=Glass Pane-rot90
|p=Spruce Planks
|x=Spruce Stairs-rot90
|y=Spruce Stairs
|z=Spruce Stairs-rot270
         
|----Layer 1|
         
 SSSSSSS 
 SlllllS 
 SlllllS 
 SlllllS 
  lllll  
  fxyzf  
         
|----Layer 2|
         
 s     s 
  llLll  
 slw xls 
 slW xls 
  lldll  
 sa   as 
         
|----Layer 3|
         
 p     p 
 plLgLlp 
 pl   lp 
 pl   lp 
 pllDllp 
 p     p 
         
|----Layer 4|
         
 sp   ps 
  plLlp  
 sp   ps 
 sp   ps 
  plllp  
 sp   ps 
         
|----Layer 5|
         
  sp ps  
   plp   
  spaps  
  sp ps  
   plp   
  sp ps  
         
|----Layer 6|
         
   sps   
    p    
   sps   
   sps   
    p    
   sps   
         
|----Layer 7|
         
    s    
         
    s    
    s    
         
    s    
         
}}

All spruce slabs in layer 2 are top slabs, while the rest are bottom slabs.



==== Materials ====

{| class="wikitable sortable mw-collapsible"
|-
! Name !! Total !! Layer 1 !! Layer 2 !! Layer 3 !! Layer 4 !! Layer 5 !! Layer 6 !! Layer 7 
|-
| {{BlockLink|Glass Pane}} || 1 || - || - || 1 || - || - || - || - 
|-
| {{BlockLink|Lantern}} || 3 || - || 2 || - || - || 1 || - || - 
|-
| {{BlockLink|Snow}} || 13 || 13 || - || - || - || - || - || - 
|-
| {{ItemLink|Spruce Door}} || 1 || - || 1 || - || - || - || - || - 
|-
| {{BlockLink|Spruce Fence}} || 2 || 2 || - || - || - || - || - || - 
|-
| {{BlockLink|Spruce Planks}} || 42 || - || - || 12 || 12 || 12 || 6 || - 
|-
| {{BlockLink|Spruce Slab}} || 36 || - || 8 || - || 8 || 8 || 8 || 4 
|-
| {{BlockLink|Spruce Stairs}} || 5 || 3 || 2 || - || - || - || - || - 
|-
| {{BlockLink|Stripped Spruce Log}} || 53 || 20 || 13 || 12 || 6 || 2 || - || - 
|-
| {{BlockLink|White Bed}} || 1 || - || 1 || - || - || - || - || - 
|}<noinclude>
[[Category:Village blueprints]]

[[fr:Village/Structure/Toundra enneigée Petite Maison 7 plan]]
[[ja:村/構造/設計図/雪原の小さな家7]]
[[zh:村庄/结构/图示/雪原小型房屋7]]
</noinclude>