<noinclude>{{structure info}}</noinclude>

[[File:Plains Medium House 2.png|thumb|Medium House 2 (Plains)]]



==== Blueprint ====

{{layered blueprint
|name=Village Plains Houses plains_medium_house_2
|default=Layer 1
|C=Cobblestone
|c=Cobblestone Stairs-rot90
|O=Oak Log+top
|l=Oak Log-rot90
|P=Oak Planks
|L=Oak Stairs
|F=Oak Stairs-rot90
|>=Oak Stairs-rot180
|V=Oak Stairs-rot270
|A=Oak Slab-rot180
|I=Oak Fence
|h=Oak Pressure Plate
|D=Oak Door+bottom
|d=Oak Door+top
|i=Torch
|T=Torch-rot90
|t=Torch-rot180
|q=torch-rot270
|G=Glass Pane
|g=Glass Pane-rot90
|Y=Yellow Bed+top-head
|B=Yellow Bed+top-foot
|y=Yellow Bed+top-head-rot180
|b=Yellow Bed+top-foot-rot180
|o=Chest-rot90
              
|----Layer 1|
               
               
  OCCCOCOCCCO  
  CPPPPCPPPPC  
  CPCCPCPCCPC  
  CPPPPCPPPPC  
  OCCCOCOCCCO  
       c       
               
|----Layer 2|
              
               
  OCCCOCOCCCO  
  CLI     BYC  
  C         C  
  Cyb      oC  
  OCCCODOCCCO  
               
               
|----Layer 3|
              
       i       
  OCgCOCOCgCO  
  C h t t   C  
  G         G  
  C         C  
  OCgCOdOCgCO  
      t t      
               
|----Layer 4|
              
 >L    A    >L 
 >OCCCOCOCCCOL 
 >C         CL 
 >C         CL 
 >C         CL 
 >OCCCOCOCCCOL 
 >L    A    >L 
               
|----Layer 5|
              
  >L >LP>L >L  
  >lllLP>lllL  
  >   LP>   L  
  >   LP>   L  
  >   LP>   L  
  >lllLP>lllL  
  >L >LP>L >L  
               
|----Layer 6|
              
   >PL   >PL   
   >PL   >PL   
   >PL   >PL   
   >PL   >PL   
   >PL   >PL   
   >PL   >PL   
   >PL   >PL   
               
}}

==== Materials ====

{| class="wikitable sortable mw-collapsible"
|-
! Name !! Total !! Layer 1 !! Layer 2 !! Layer 3 !! Layer 4 !! Layer 5 !! Layer 6 
|-
| {{BlockLink|Chest}} || 1 || - || 1 || - || - || - || - 
|-
| {{BlockLink|Cobblestone}} || 79 || 27 || 19 || 13 || 20 || - || - 
|-
| {{BlockLink|Cobblestone Stairs}} || 1 || 1 || - || - || - || - || - 
|-
| {{BlockLink|Glass Pane}} || 6 || - || - || 6 || - || - || - 
|-
| {{ItemLink|Oak Door}} || 1 || - || 1 || - || - || - || - 
|-
| {{BlockLink|Oak Fence}} || 1 || - || 1 || - || - || - || - 
|-
| {{BlockLink|Oak Log}} || 44 || 8 || 8 || 8 || 8 || 12 || - 
|-
| {{BlockLink|Oak Planks}} || 41 || 20 || - || - || - || 7 || 14 
|-
| {{BlockLink|Oak Pressure Plate}} || 1 || - || - || 1 || - || - || - 
|-
| {{BlockLink|Oak Slab}} || 2 || - || - || - || 2 || - || - 
|-
| {{BlockLink|Oak Stairs}} || 83 || - || 1 || - || 18 || 36 || 28 
|-
| {{BlockLink|Torch}} || 5 || - || - || 5 || - || - || - 
|-
| {{BlockLink|Yellow Bed}} || 2 || - || 2 || - || - || - || - 
|}<noinclude>
[[Category:Village blueprints]]

[[fr:Village/Structure/Plaines Maison Moyenne 2 plan]]
[[ja:村/構造/設計図/平原の中くらいの家2]]
[[zh:村庄/结构/图示/平原中型房屋2]]
</noinclude>