<noinclude>{{structure info}}</noinclude>

[[File:Savanna Large Farm 1.png|thumb|Large Farm 1 (Savanna)]]



==== Blueprint ====

{{layered blueprint|name=
Savanna Large Farm 1|default=Layer 1
|G=Grass Block+top
|D=Dirt
|A=Acacia Log+top
|C=Acacia Planks
|O=Composter
|I=Acacia Stairs
|F=Farmland
|W=Wheat
|T=Water+top
|R=Short Grass
           
|----Layer 1|
           
 GDDDGDDDG 
 DGGGDGGGD 
 DGGGDGGGD 
 DGGGDGGGD 
 GDDDDDDDG 
 DGGGDGGGD 
 DGGGDGGGD 
 DGGGDGGGD 
 GDDDGDDDG 
           
|----Layer 2|
           
  AAAIAAAO 
 AFFFCFFFA 
 AFFFCFFFA 
 AFFTCTFFA 
 ICCCCCCCI 
 AFFTCTFFA 
 AFFFCFFFA 
 AFFFCFFFA 
 OAAAIAAAR 
           
|----Layer 3|
           
           
  WWW WWW  
  WWW WWW  
  WW   WW  
           
  WW   WW  
  WWW WWW  
  WWW WWW  
           
           
}}



==== Materials ====

{| class="wikitable sortable mw-collapsible"
|-
! Name !! Total !! Layer 1 !! Layer 2 !! Layer 3 
|-
| {{BlockLink|Acacia Log}} || 24 || - || 24 || - 
|-
| {{BlockLink|Acacia Planks}} || 13 || - || 13 || - 
|-
| {{BlockLink|Acacia Stairs}} || 4 || - || 4 || - 
|-
| {{BlockLink|Composter}} || 2 || - || 2 || - 
|-
| {{BlockLink|Dirt}} || 37 || 37 || - || - 
|-
| {{BlockLink|Farmland}} || 32 || - || 32 || - 
|-
| {{BlockLink|Short Grass}} || 1 || - || 1 || - 
|-
| {{BlockLink|Grass Block}} || 44 || 44 || - || - 
|-
| {{BlockLink|Water}} || 4 || - || 4 || - 
|-
| {{BlockLink|Wheat}} || 32 || - || - || 32 
|}<noinclude>
[[Category:Village blueprints]]

[[fr:Village/Structure/Savane Grande Ferme 1 plan]]
[[ja:村/構造/設計図/サバンナの大きな畑1]]
[[zh:村庄/结构/图示/热带草原大型农田1]]
</noinclude>