<noinclude>{{structure info}}</noinclude>

[[File:Savanna Fisher Cottage 1.png|thumb|Fisher Cottage 1 (Savanna)]]



==== Blueprint ====
* [[Java Edition]]
{{layered blueprint|name=
Savanna Fisher Cottage 1 (JE)|default=Layer 1
|D=Dirt
|G=Grass Block+top
|A=Acacia Planks
|C=Acacia Slab
|I=Acacia Wood
|L=Acacia Log
|O=Acacia Log-rot-90
|B=Barrel+top
|b=Barrel
|r=Barrel-rot-90
|S=Acacia Stairs
|R=Short Grass
|F=Acacia Fence
|W=Wall Torch-rot-90
|T=Water+top
|c=Acacia Door+bottom
|a=Acacia Door+top
|H=Wall Torch-rot-270
|P=Glass Pane
           
|----Layer 1|
           
    DDDDDD 
   DDDDDDD 
   DDDDDDD 
 DDDDDDDDD 
 DDDDDDDDD 
 DDDDDDDDD 
    DDDDDD 
      DDDD 
           
|----Layer 2|
           
    GGGGGG 
   DGTTTTG 
   GGTTFTG 
 GDGGTTTTG 
 DDGGGTFTG 
 GDGGDGTTG 
    GGGGGG 
      GGGG 
           
|----Layer 3|
           
    R      
   rR      
    F  F   
 SA        
 SA F  F   
 SAR b   R 
    F  FR  
       R   
           
|----Layer 4|
           
           
           
    F  F   
  SA       
  SAF  F   
  SA B     
    F  F   
           
           
|----Layer 5|
           
           
           
    F  F   
   SA      
   SF  F   
   SA      
    F  F   
           
           
|----Layer 6|
           
           
           
    AAAA   
    CAAA   
    CAAA   
    CAAA   
    AAAA   
           
           
|----Layer 7|
           
           
           
    ILLI   
     O O   
     c O   
     O O   
    ILLI   
           
           
|----Layer 8|
           
           
           
    ILLI   
    WO O   
     a P   
    WO O   
    ILLI   
           
           
|----Layer 9|
           
           
           
    ILLI   
     O O   
     OHO   
     O O   
    ILLI   
           
           
|----Layer 10|
           
           
   SSSSSS  
   SAAAAS  
   SAA AS  
   SAA AS  
   SAA AS  
   SAAAAS  
   SSSSSS  
           
|----Layer 11|
           
           
           
    SSSS   
    SAAS   
    SAAS   
    SAAS   
    SSSS   
           
           
}}

* [[Bedrock Edition]]
{{layered blueprint|name=
Savanna Fisher Cottage 1 (BE)|default=Layer 1
|D=Dirt
|G=Grass Block+top
|A=Acacia Planks
|C=Acacia Slab
|I=Acacia Wood
|L=Acacia Log
|O=Acacia Log-rot-90
|B=Barrel+top
|S=Acacia Stairs
|R=Short Grass
|F=Acacia Fence
|W=Wall Torch-rot-90
|T=Water+top
|c=Acacia Door+bottom
|a=Acacia Door+top
|H=Wall Torch-rot-270
|P=Glass Pane
           
|----Layer 1|
           
    DDDDDD 
   DDDDDDD 
   DDDDDDD 
 DDDDDDDDD 
 DDDDDDDDD 
 DDDDDDDDD 
    DDDDDD 
      DDDD 
           
|----Layer 2|
           
    GGGGGG 
   DGTTTTG 
   GGTTFTG 
 GDGGTTTTG 
 DDGGGTFTG 
 GDGGGGTTG 
    GDGGGG 
      GGGG 
           
|----Layer 3|
           
    R      
   BR      
    F  F   
 SA        
 SA F  F   
 SAR     R 
    FB FR  
       R   
           
|----Layer 4|
           
           
           
    F  F   
  SA       
  SAF  F   
  SA       
    F  F   
           
           
|----Layer 5|
           
           
           
    F  F   
   SA      
   SF  F   
   SA      
    F  F   
           
           
|----Layer 6|
           
           
           
    AAAA   
    CAAA   
    CAAA   
    CAAA   
    AAAA   
           
           
|----Layer 7|
           
           
           
    ILLI   
     O O   
     c O   
     O O   
    ILLI   
           
           
|----Layer 8|
           
           
           
    ILLI   
    WO O   
     a P   
    WO O   
    ILLI   
           
           
|----Layer 9|
           
           
           
    ILLI   
     O O   
     OHO   
     O O   
    ILLI   
           
           
|----Layer 10|
           
           
   SSSSSS  
   SAAAAS  
   SAA AS  
   SAA AS  
   SAA AS  
   SAAAAS  
   SSSSSS  
           
|----Layer 11|
           
           
           
    SSSS   
    SAAS   
    SAAS   
    SAAS   
    SSSS   
           
           
}}

==== Materials ====

{| class="wikitable sortable mw-collapsible"
|-
! Name !! Total !! Layer 1 !! Layer 2 !! Layer 3 !! Layer 4 !! Layer 5 !! Layer 6 !! Layer 7 !! Layer 8 !! Layer 9 !! Layer 10 !! Layer 11 
|-
| {{BlockLink|Acacia Door}} || 1 || - || - || - || - || - || - || 1 || - || - || - || - 
|-
| {{BlockLink|Acacia Fence}} || 20 || - || 2 || 6 || 6 || 6 || - || - || - || - || - || - 
|-
| {{BlockLink|Acacia Log}} || 27 || - || - || - || - || - || - || 9 || 8 || 10 || - || - 
|-
| {{BlockLink|Acacia Planks}} || 31 || - || - || 3 || 3 || 2 || - || - || - || - || 17 || 6 
|-
| {{BlockLink|Acacia Slab}} || 37 || - || - || - || - || - || 37 || - || - || - || - || - 
|-
| {{BlockLink|Acacia Stairs}} || 45 || - || - || 3 || 3 || 3 || - || - || - || - || 22 || 14 
|-
| {{BlockLink|Acacia Wood}} || 12 || - || - || - || - || - || - || 4 || 4 || 4 || - || - 
|-
| {{BlockLink|Barrel}} || 3{{only|JE|short=1}} 2{{only|BE|short=1}} || - || - || 2 || 1{{only|JE|short=1}} 0{{only|BE|short=1}} || - || - || - || - || - || - || - 
|-
| {{BlockLink|Dirt}} || 63 || 57 || 6 || - || - || - || - || - || - || - || - || - 
|-
| {{BlockLink|Glass Pane}} || 1 || - || - || - || - || - || - || - || 1 || - || - || - 
|-
| {{BlockLink|Short Grass}} || 6 || - || - || 6 || - || - || - || - || - || - || - || - 
|-
| {{BlockLink|Grass Block}} || 34 || - || 34 || - || - || - || - || - || - || - || - || - 
|-
| {{BlockLink|Torch}} || 3 || - || - || - || - || - || - || - || 2 || 1 || - || - 
|-
| {{BlockLink|Water}} || 15 || - || 15 || - || - || - || - || - || - || - || - || - 
|}<noinclude>
[[Category:Village blueprints]]

[[fr:Village/Structure/Savane Cabanon de Pêcheur 1 plan]]
[[ja:村/構造/設計図/サバンナの釣り小屋1]]
[[zh:村庄/结构/图示/热带草原渔夫小屋]]
</noinclude>