<noinclude>{{structure info}}</noinclude>

[[File:Snowy Tundra Small House 8.png|thumb|Small house 8 (Snowy tundra)]]



==== Blueprint ====

{{layered blueprint
|name=Snowy Small House 8 snowy_small_house_8
|default=Layer 1
|i=Dirt
|w=Light Gray Wool
|s=Snow Block
|l=Stripped Spruce Log+top
|b=White Bed+top-head-rot270
|B=White Bed+top-foot-rot270
|t=Torch
|d=Spruce Door+bottom
|D=Spruce Door+top
|x=Spruce Stairs
|y=Spruce Stairs-rot180
       
|----Layer 0|
       
   i   
  iii  
 iwwwi 
 iwwwi 
 iwwwi 
  iwi  
       
|----Layer 1|
       
   s   
  sss  
 sx bs 
 sl Bs 
 sy ls 
  sds  
       
|----Layer 2|
       
   s   
  sss  
 s   s 
 st  s 
 s   s 
  sDs  
       
|----Layer 3|
       
       
  sss  
  sss  
  sss  
  sss  
  sss  
       
|----Layer 4|
       
       
      
   s   
   s   
   s   
}}



==== Materials ====

{| class="wikitable sortable mw-collapsible"
|-
! Name !! Total !! Layer 0 !! Layer 1 !! Layer 2 !! Layer 3 !! Layer 4 
|-
| {{BlockLink|Dirt}} || 12 || 12 || - || - || - || - 
|-
| {{BlockLink|Light Gray Wool}} || 10 || 10 || - || - || - || - 
|-
| {{BlockLink|Snow}} || 8 || - || 8 || - || - || - 
|-
| {{BlockLink|Snow Block}} || 42 || - || 12 || 12 || 15 || 3 
|-
| {{ItemLink|Spruce Door}} || 1 || - || 1 || - || - || - 
|-
| {{BlockLink|Spruce Stairs}} || 2 || - || 2 || - || - || - 
|-
| {{BlockLink|Stripped Spruce Log}} || 2 || - || 2 || - || - || - 
|-
| {{BlockLink|Torch}} || 1 || - || - || 1 || - || - 
|-
| {{BlockLink|White Bed}} || 1 || - || 1 || - || - || - 
|}<noinclude>
[[Category:Village blueprints]]

[[fr:Village/Structure/Toundra enneigée Petite Maison 8 plan]]
[[ja:村/構造/設計図/雪原の小さな家8]]
[[zh:村庄/结构/图示/雪原小型房屋8]]
</noinclude>