<noinclude>{{structure info}}</noinclude>

[[File:Snowy Tundra Tannery.png|thumb|Tannery (Snowy tundra)]]



==== Blueprint ====

{{layered blueprint|name=Village Snowy Houses snowy_tannery_1
|default=Layer 2
|x=Snow
|y=Snow Block
|z=Short Grass
|S=Stripped Spruce Log+top
|L=Stripped Spruce Log-rot180
|P=Spruce Planks
|s=Spruce Slab
|o=Spruce Stairs
|(=Spruce Stairs-rot90
|)=Spruce Stairs-rot270
|f=Spruce Fence
|h=Spruce Door+bottom
|H=Spruce Door+top
|D=Diorite
|d=Diorite Wall
|g=Glass Pane
|t=Torch
|l=Lantern
|w=Water Cauldron
|c=Chest
|F=Furnace
|----Layer 1|
           
 xxxzzxxxx 
 xSSSSSSSx 
 xSSDDDSSx 
 ySSDDDSSx 
 xSSDDDSSx 
 xSSSSSSSx 
 xLSSSSSLx 
 yxxxoyyxx 
           
|----Layer 2|
           
 s       s 
 PSSSSSSSP 
 PS) S cSP 
 sS) F  Ss 
 sS     Ss 
 PSw   wSP 
 PSLShSLSP 
 s     y s 
           
|----Layer 3|
           
 P       P 
 PSSLSLSSP 
 PS     SP 
 PS  d  SP 
 PS     SP 
 PS     SP 
 PSSLHLSSP 
 P       P 
           
|----Layer 4|
           
 sP     Ps 
  PLgLgLP  
  P     P  
 xP  d  P  
  P     P  
 xP     P  
 yPSLLLSP  
 sP  l  Ps 
           
|----Layer 5|
           
  Ps   sP  
  PSLSLSP  
  P  t  P  
  P  d  P  
  P     P  
  P  t  P  
  PSSLSSP  
  Ps f sP  
           
|----Layer 6|
           
   P   P   
   PSSSP   
   P   P   
   P d P   
   P   Px  
   P   Py  
   PLLLPx  
  xP   P   
           
|----Layer 7|
           
   sP Ps   
    PSP    
    PSP    
    PdP    
    PSP    
   xPSP    
    PLP    
   sP Ps   
           
|----Layer 8|
           
    sPs    
     P     
    )P(    
    )D(    
    )P(    
     P     
     P     
    sPs    
           
|----Layer 9|
           
           
           
           
     d     
           
}}



==== Materials ====

{| class="wikitable sortable mw-collapsible"
|-
! Name !! Total !! Layer 1 !! Layer 2 !! Layer 3 !! Layer 4 !! Layer 5 !! Layer 6 !! Layer 7 !! Layer 8 !! Layer 9 
|-
| {{BlockLink|Chest}} || 1 || - || 1 || - || - || - || - || - || - || - 
|-
| {{BlockLink|Diorite}} || 10 || 9 || - || - || - || - || - || - || 1 || - 
|-
| {{BlockLink|Diorite Wall}} || 6 || - || - || 1 || 1 || 1 || 1 || 1 || - || 1 
|-
| {{BlockLink|Furnace}} || 1 || - || 1 || - || - || - || - || - || - || - 
|-
| {{BlockLink|Short Grass}} || 2 || 2 || - || - || - || - || - || - || - || - 
|-
| {{BlockLink|Glass Pane}} || 2 || - || - || - || 2 || - || - || - || - || - 
|-
| {{BlockLink|Lantern}} || 1 || - || - || - || 1 || - || - || - || - || - 
|-
| {{BlockLink|Snow}} || 64 || 46 || - || - || 5 || - || 9 || 4 || - || - 
|-
| {{BlockLink|Snow Block}} || 7 || 4 || 1 || - || 1 || - || 1 || - || - || - 
|-
| {{ItemLink|Spruce Door}} || 1 || - || 1 || - || - || - || - || - || - || - 
|-
| {{BlockLink|Spruce Fence}} || 1 || - || - || - || - || 1 || - || - || - || - 
|-
| {{BlockLink|Spruce Planks}} || 95 || - || 8 || 16 || 16 || 16 || 16 || 16 || 7 || - 
|-
| {{BlockLink|Spruce Slab}} || 24 || - || 8 || - || 4 || 4 || - || 4 || 4 || - 
|-
| {{BlockLink|Spruce Stairs}} || 9 || 1 || 2 || - || - || - || - || - || 6 || - 
|-
| {{BlockLink|Stripped Spruce Log}} || 102 || 33 || 22 || 21 || 8 || 10 || 6 || 5 || - || - 
|-
| {{BlockLink|Torch}} || 2 || - || - || - || - || 2 || - || - || - || - 
|-
| {{BlockLink|Water Cauldron}} || 2 || - || 2 || - || - || - || - || - || - || - 
|}<noinclude>
[[Category:Village blueprints]]

[[fr:Village/Structure/Toundra enneigée Tannerie plan]]
[[ja:村/構造/設計図/雪原の革加工場1]]
[[zh:村庄/结构/图示/雪原皮匠屋]]
</noinclude>