<noinclude>{{structure info}}</noinclude>

[[File:Savanna Temple 2.png|thumb|Temple 2 (Savanna)]]



==== Blueprint ====

{{layered blueprint|name=
Savanna Temple 2|default=Layer 1
|D=Dirt
|A=Acacia Wood
|C=Acacia Planks
|R=Red Terracotta
|Y=Yellow Terracotta
|B=Brewing Stand
|I=Acacia Stairs
|G=Glass Pane
|W=Wall Torch
|L=Glass Pane-rot-90
|S=Dirt Path+top
|O=Acacia Door+bottom
|c=Acacia Door+top
|T=Wall Torch-rot-180
           
|----Layer 1|
           
           
   DDDDD   
  DAARAAD  
  DAARAAD  
  DAARAAD  
   DDADD   
     S     
           
|----Layer 2|
           
           
   AAAAA   
  A    IA  
  AB   IA  
  A    IA  
   AAOAA   
           
           
|----Layer 3|
           
           
   ALALA   
  A  T  A  
  G     G  
  A W W A  
   AAcAA   
           
           
|----Layer 4|
           
           
   AAAAA   
  A     A  
  A     A  
  A     A  
   AAAAA   
           
           
|----Layer 5|
           
  II W II  
 ICCRYRCCI 
 ICCY YCCI 
 ICCR RCCI 
 ICCY YCCI 
 ICCRYRCCI 
  II T II  
           
|----Layer 6|
           
           
    AAA    
    A A    
    A A    
    A A    
    AAA    
           
           
|----Layer 7|
           
    III    
   ICCCI   
   ICCCI   
   ICCCI   
   ICCCI   
   ICCCI   
    III    
           
}}



==== Materials ====

{| class="wikitable sortable mw-collapsible"
|-
! Name !! Total !! Layer 1 !! Layer 2 !! Layer 3 !! Layer 4 !! Layer 5 !! Layer 6 !! Layer 7 
|-
| {{BlockLink|Acacia Door}} || 1 || - || 1 || - || - || - || - || - 
|-
| {{BlockLink|Acacia Planks}} || 35 || - || - || - || - || 20 || - || 15 
|-
| {{BlockLink|Acacia Stairs}} || 37 || - || 3 || - || - || 18 || - || 16 
|-
| {{BlockLink|Acacia Wood}} || 67 || 13 || 15 || 11 || 16 || - || 12 || - 
|-
| {{BlockLink|Brewing Stand}} || 1 || - || 1 || - || - || - || - || - 
|-
| {{BlockLink|Dirt}} || 15 || 15 || - || - || - || - || - || - 
|-
| {{BlockLink|Glass Pane}} || 4 || - || - || 4 || - || - || - || - 
|-
| {{BlockLink|Dirt Path}} || 1 || 1 || - || - || - || - || - || - 
|-
| {{BlockLink|Red Terracotta}} || 9 || 3 || - || - || - || 6 || - || - 
|-
| {{BlockLink|Torch}} || 5 || - || - || 3 || - || 2 || - || - 
|-
| {{BlockLink|Yellow Terracotta}} || 6 || - || - || - || - || 6 || - || - 
|}<noinclude>
[[Category:Village blueprints]]

[[fr:Village/Structure/Savane Temple 2 plan]]
[[ja:村/構造/設計図/サバンナの礼拝所2]]
[[zh:村庄/结构/图示/热带草原教堂2]]
</noinclude>