<noinclude>{{structure info}}</noinclude>

[[File:Savanna Weaponsmith 1.png|thumb|Weaponsmith 1 (Savanna)]]



==== Blueprint ====

{{layered blueprint|name=
Savanna Weaponsmith 1|default=Layer 1
|G=Grass Block+top
|D=Dirt
|A=Acacia Log+top
|C=Acacia Planks
|S=Stripped Acacia Log+top
|T=Stripped Acacia Log
|I=Acacia Log
|B=Brown Wall Banner
|R=Short Grass
|c=Acacia Stairs
|F=Acacia Fence
|W=White Carpet
|L=Glass Pane-rot-90
|O=Wall Torch
|P=Dirt Path+top
|a=Acacia Door+bottom
|i=Acacia Door+top
|N=Grindstone
           
|----Layer 1|
           
 GGGGPGGGG 
 GGGGPGGGG 
 GGGGPGGGG 
 GGDDSDDG  
 GDSTSTSD  
 GDSTSTSDR 
 GGDDDDDG  
 GGGGGGG R 
           
|----Layer 2|
           
 R FF FF   
   F  RF   
 RRFR RFR  
  RAAaAA   
  Ac    A  
  AF   NA  
   AAAAA   
           
           
|----Layer 3|
           
           
           
           
   AAiAA   
  A     A  
  AW    A  
   ALALA   
           
           
|----Layer 4|
           
           
           
    B B    
   AAIAA   
  A     A  
  A O O A  
   AIAIA   
           
           
|----Layer 5|
           
           
           
  ccccccc  
 cCCCCCCCc 
 cC     Cc 
 cC     Cc 
 cCCCCCCCc 
  ccccccc  
           
|----Layer 6|
           
           
           
           
  ccccccc  
  cCCCCCc  
  cCCCCCc  
  ccccccc  
           
           
}}



==== Materials ====

{| class="wikitable sortable mw-collapsible"
|-
! Name !! Total !! Layer 1 !! Layer 2 !! Layer 3 !! Layer 4 !! Layer 5 !! Layer 6 
|-
| {{BlockLink|Acacia Door}} || 1 || - || 1 || - || - || - || - 
|-
| {{BlockLink|Acacia Fence}} || 9 || - || 9 || - || - || - || - 
|-
| {{BlockLink|Acacia Log}} || 38 || - || 13 || 11 || 14 || - || - 
|-
| {{BlockLink|Acacia Planks}} || 28 || - || - || - || - || 18 || 10 
|-
| {{BlockLink|Acacia Stairs}} || 41 || - || 1 || - || - || 22 || 18 
|-
| {{BlockLink|Brown Wall Banner}} || 2 || - || - || - || 2 || - || - 
|-
| {{BlockLink|Dirt}} || 13 || 13 || - || - || - || - || - 
|-
| {{BlockLink|Glass Pane}} || 2 || - || - || 2 || - || - || - 
|-
| {{BlockLink|Short Grass}} || 10 || 2 || 8 || - || - || - || - 
|-
| {{BlockLink|Grass Block}} || 39 || 39 || - || - || - || - || - 
|-
| {{BlockLink|Dirt Path}} || 3 || 3 || - || - || - || - || - 
|-
| {{BlockLink|Grindstone}} || 1 || - || 1 || - || - || - || - 
|-
| {{BlockLink|Stripped Acacia Log}} || 11 || 11 || - || - || - || - || - 
|-
| {{BlockLink|Torch}} || 2 || - || - || - || 2 || - || - 
|-
| {{BlockLink|White Carpet}} || 1 || - || - || 1 || - || - || - 
|}<noinclude>
[[Category:Village blueprints]]

[[fr:Village/Structure/Savane Forge d'Armes 1 plan]]
[[ja:村/構造/設計図/サバンナの武器鍛冶場1]]
[[zh:村庄/结构/图示/热带草原铁匠铺1]]
</noinclude>