<noinclude>{{structure info}}</noinclude>

[[File:Plains Butcher Shop 1.png|thumb|Butcher Shop 1 (Plains)]]



==== Blueprint ====

{{layered blueprint
|name=Village Plains Butcher Shop 1 plains_butcher_shop_1
|default=Layer 1
|A=Cobblestone
|B=Cobblestone Wall
|C=Potted Dandelion
|D=Dirt
|E=Double Smooth Stone Slab
|F=Glass Pane
|G=Glass Pane-rot90
|H=Grass Block+top
|I=Hay Bale+top
|J=Oak Door+bottom
|K=Oak Door+top
|L=Oak Fence
|M=Oak Log+top
|N=Oak Log-rot90
|O=Oak Planks
|P=Oak Pressure Plate
|Q=Oak Stairs
|R=Oak Stairs-rot180
|S=Oak Stairs-rot270
|T=Oak Stairs-rot90
|U=Smoker-rot270
|V=Torch
|W=Torch-rot180
|X=Torch-rot270
            
|----Layer 1|
             
             
  MAAAMAAAM  
  AOOOOEEEA  
 TAOOOOEEEA  
 TAOOOOEEEA  
  AOOOOOOOA  
  MAAAAAAAM  
    MHDDAHM  
    MHHHHHM  
    MHHHHHM  
    MHHHHHM  
    MMMMMMM  
             
|----Layer 2|
            
            
  MAAAMAAAM 
  ASLT  E A 
  J     E A 
  J       A 
  AO     UA 
  MAAAAAJAM 
    L II  L 
    L     L 
    L     L 
    L     L 
    LLLLLLL 
            
|----Layer 3|
            
      V     
  MMGMMMGMM 
 XM P     M 
  K       F 
  K       F 
 XMC     BM 
  MNGGNNKAM 
            
            
            
            
    V     V 
            
|----Layer 4|
             
 RRRRRRRRRRR 
 QMOOOOOOOMQ 
  A W     A  
  A       A  
  A       A  
  A     VBA  
 RMOOOOOOOMR 
 QQQQQQQQQQQ 
             
             
            
            
            
|----Layer 5|
            
            
 RRRRRRRRRRR
 QAOOOOOOOAQ
  A       A 
  A       A 
 RAOOOOOOBAR
 QQQQQQQQQQQ
            
            
            
            
            
            
|----Layer 6|
            
            
            
 RRRRRRRRRRR
 QAOOOOOOOAQ
 RAOOOOOOOAR
 QQQQQQQQAQQ
            
            
            
            
            
            
            
|----Layer 7|
            
            
            
            
 RRRRRRRRRRR
 QQQQQQQQQQQ
         B  
            
            
            
            
            
            
            
|----Layer 8|
            
            
            
            
            
            
         B  
            
            
            
            
            
            
            
}}

This structure resembles the [[Village/Structure_(old)/Blueprints/Butcher_shop|old Butcher Shop]] seen in [[Village/Structure (old)/Blueprints |pre-1.14 villages]], with some minor changes.

==== Materials ====

{|class="wikitable sortable mw-collapsible"
|-
! Name !! Total !! Layer 1 !! Layer 2 !! Layer 3 !! Layer 4 !! Layer 5 !! Layer 6 !! Layer 7 !! Layer 8 
|-
| {{BlockLink|Cobblestone}} || 62 || 22 || 18 || 1 || 8 || 8 || 5 || - || - 
|-
| {{BlockLink|Cobblestone Wall}} || 5 || - || - || 1 || 1 || 1 || - || 1 || 1 
|-
| {{BlockLink|Dirt}} || 2 || 2 || - || - || - || - || - || - || - 
|-
| {{BlockLink|Glass Pane}} || 6 || - || - || 6 || - || - || - || - || - 
|-
| {{BlockLink|Grass Block}} || 17 || 17 || - || - || - || - || - || - || - 
|-
| {{BlockLink|Hay Bale}} || 2 || - || 2 || - || - || - || - || - || - 
|-
| {{ItemLink|Oak Door}} || 3 || - || 3 || - || - || - || - || - || - 
|-
| {{BlockLink|Oak Fence}} || 16 || - || 16 || - || - || - || - || - || - 
|-
| {{BlockLink|Oak Log}} || 45 || 20 || 5 || 16 || 4 || - || - || - || - 
|-
| {{BlockLink|Oak Planks}} || 61 || 19 || 1 || - || 14 || 13 || 14 || - || - 
|-
| {{BlockLink|Oak Pressure Plate}} || 1 || - || - || 1 || - || - || - || - || - 
|-
| {{BlockLink|Oak Stairs}} || 103 || 2 || 2 || - || 26 || 26 || 25 || 22 || - 
|-
| {{BlockLink|Potted Dandelion}} || 1 || - || - || 1 || - || - || - || - || - 
|-
| {{BlockLink|Smoker}} || 1 || - || 1 || - || - || - || - || - || - 
|-
| {{BlockLink|Smooth Stone Slab}} || 22 || 18 || 4 || - || - || - || - || - || - 
|-
| {{BlockLink|Torch}} || 7 || - || - || 5 || 2 || - || - || - || - 
|}

<noinclude>
[[Category:Village blueprints]]

[[fr:Village/Structure/Plaines Échoppe de Boucher 1 plan]]
[[ja:村/構造/設計図/平原の肉屋1]]
[[zh:村庄/结构/图示/平原肉铺1]]
</noinclude>