<noinclude>{{structure info}}</noinclude>

[[File:Plains Small House 4.png|thumb|Small House 4 (Plains)]]



==== Blueprint ====

{{layered blueprint
|name=Village Plains Houses plains_small_house_4
|default=Layer 2
|P=Oak Planks
|O=Oak Log+top
|L=Oak Log-rot90
|l=Oak Log
|B=White Bed+top foot-rot270
|b=White Bed+top head-rot270
|C=Cobblestone
|c=Cobblestone Stairs-rot90
|s=Oak Stairs
|<=Oak Stairs-rot90
|>=Oak Stairs-rot270
|d=Oak Door+bottom
|D=Oak Door+top
|g=glass Pane
|G=glass Pane-rot90
|T=torch-rot180
|----Layer 1|
         
         
  OCCCO  
  CPPPC  
  CPPPC  
  CPPPC  
  OCCCO  
    s    
|----Layer 2|
         
         
  OCCCO  
  Cb cC  
  CB cC  
  C  cC  
  OCdCO  
         
|----Layer 3|
         
         
  OCGCO  
  l   l  
  g   g  
  l   l  
  OCDCO  
         
|----Layer 4|
         
         
  OCCCO  
  C T C  
  C   C  
  C   C  
  OCCCO  
    T    
|----Layer 5|
         
 <>   <> 
 <OLLLO> 
 <P   P> 
 <P   P> 
 <P   P> 
 <OLLLO> 
 <>   <> 
|----Layer 6|
         
  <> <>  
  <CCC>  
  <PPP>  
  <P P>  
  <PPP>  
  <CCC>  
  <> <>  
|----Layer 7|
         
   <P>   
   <P>   
   <P>   
   <P>   
   <P>   
   <P>   
   <P>   
}}


This structure resembles the [[Village/Structure (old)/Blueprints/Small house|old Small House]] seen in [[Village/Structure (old)/Blueprints |pre-1.14 villages]], with multiple changes, such as the gable roof, furniture and a bed.



==== Materials ====

{| class="wikitable sortable mw-collapsible"
|-
! Name !! Total !! Layer 1 !! Layer 2 !! Layer 3 !! Layer 4 !! Layer 5 !! Layer 6 !! Layer 7 
|-
| {{BlockLink|Cobblestone}} || 45 || 12 || 11 || 4 || 12 || - || 6 || - 
|-
| {{BlockLink|Cobblestone Stairs}} || 3 || - || 3 || - || - || - || - || - 
|-
| {{BlockLink|Glass Pane}} || 3 || - || - || 3 || - || - || - || - 
|-
| {{ItemLink|Oak Door}} || 1 || - || 1 || - || - || - || - || - 
|-
| {{BlockLink|Oak Log}} || 30 || 4 || 4 || 8 || 4 || 10 || - || - 
|-
| {{BlockLink|Oak Planks}} || 30 || 9 || - || - || - || 6 || 8 || 7 
|-
| {{BlockLink|Oak Stairs}} || 51 || 1 || - || - || - || 18 || 18 || 14 
|-
| {{BlockLink|Torch}} || 2 || - || - || - || 2 || - || - || - 
|-
| {{BlockLink|White Bed}} || 1 || - || 1 || - || - || - || - || - 
|}<noinclude>
[[Category:Village blueprints]]

[[fr:Village/Structure/Plaines Petite Maison 4 plan]]
[[ja:村/構造/設計図/平原の小さな家4]]
[[zh:村庄/结构/图示/平原小型房屋4]]
</noinclude>