<noinclude>{{structure info}}</noinclude>

[[File:Plains tool smith house 1.png|thumb|Tool Smith House (Plains)]]



==== Blueprint ====

{{layered blueprint
|name=Village Plains Houses plains_tool_smith_house_1
|default=Layer 100
|O=Oak Log+top
|L=Oak Log-rot90
|l=Oak Log
|P=Oak Planks
|d=Oak Door+bottom
|D=Oak Door+top
|s=Oak Stairs
|<=Oak Stairs-rot90
|^=Oak Stairs-rot180
|>=Oak Stairs-rot270
|C=Cobblestone
|c=Cobblestone Stairs
|T=torch
|t=torch-rot180
|k=torch-rot270
|G=glass Pane-rot90
|Q=Smithing Table-rot270
|----Layer 1|
              
              
  OCCCCCCCCO  
  CCCCCCCCCC  
  CCCCCCCCCC  
  OCCCCCOCCC  
        CCCC  
        OCCO  
         cc   
              
|----Layer 2|
              
              
  OPPPPPPPPO  
  PQ       P  
  PP       P  
  OPPPPPO  P  
        P  P  
        OddO  
              
              
|----Layer 3|
              
              
 kOPLGLLGLPO  
  P        P  
  P        P  
 kOPLGLPO  P  
        P  P  
        ODDO  
        t  t  
              
|----Layer 4|
              
 ^^^^^^^^^^^^ 
 sOPPPPPPPPOs 
  P  t  t  P  
  P        P  
 ^OPPPPPO  P^ 
 sssssssP  P> 
       <OPPO> 
       <>  <> 
              
|----Layer 5|
              
              
 ^^^^^^^^^^^^ 
 sP        Ps 
 ^P        P^ 
 ssssssssTTss 
        <PP>  
        <PP>  
        <><>  
|----Layer 6|
              
              
              
 ^^^^^^^^^^^^ 
 sssssssss>ss 
         <>   
         <>   
         <>   
         <>   
              
}}

==== Materials ====

{| class="wikitable sortable mw-collapsible"
|-
! Name !! Total !! Layer 1 !! Layer 2 !! Layer 3 !! Layer 4 !! Layer 5 !! Layer 6 
|-
| {{BlockLink|Cobblestone}} || 42 || 42 || - || - || - || - || - 
|-
| {{BlockLink|Cobblestone Stairs}} || 2 || 2 || - || - || - || - || - 
|-
| {{BlockLink|Glass Pane}} || 3 || - || - || 3 || - || - || - 
|-
| {{ItemLink|Oak Door}} || 2 || - || 2 || - || - || - || - 
|-
| {{BlockLink|Oak Log}} || 30 || 6 || 6 || 12 || 6 || - || - 
|-
| {{BlockLink|Oak Planks}} || 62 || - || 21 || 11 || 22 || 8 || - 
|-
| {{BlockLink|Oak Stairs}} || 96 || - || - || - || 30 || 34 || 32 
|-
| {{BlockLink|Smithing Table}} || 1 || - || 1 || - || - || - || - 
|-
| {{BlockLink|Torch}} || 8 || - || - || 4 || 2 || 2 || - 
|}<noinclude>
[[Category:Village blueprints]]

[[fr:Village/Structure/Plaines Maison de Forgeron d'Outil 1 plan]]
[[ja:村/構造/設計図/平原の道具鍛冶屋1]]
[[zh:村庄/结构/图示/平原工具匠房屋]]
</noinclude>