<noinclude>{{structure info}}</noinclude>

[[File:Taiga Armorer House 1.png|thumb|Armorer House 1 (Taiga)]]



==== Blueprint ====

{{layered blueprint|name=
Taiga Armorer House 1|default=Layer 1
|S=Spruce Log
|G=Grass Block+top
|D=Dirt
|C=Cobblestone
|P=Spruce Planks
|B=Blast Furnace
|O=Poppy
|R=Spruce Trapdoor
|A=Dirt Path+top
|U=Spruce Door+bottom
|E=Spruce Door+top
|L=Glass Pane-rot-90
|W=Wall Torch-rot-180
|T=Wall Torch
|N=Cobblestone Stairs
|o=Cobblestone Wall
         
|----Layer 1|
         
         
  DDDDD  
  DPPPD  
  DPCDD  
  DPCDD  
  DPCDD  
  DPCDD  
  DPPPD  
  DDCDD  
  G A  G 
         
|----Layer 2|
         
         
  CCCCC  
  C   C  
  C  CC  
  C  BC  
  C  BC  
  C  CC  
  C   C  
  CCUCC  
  O    O 
         
|----Layer 3|
         
 S R R S 
 SCCLCCS 
 SC   CS 
 SC  NCS 
 SC  CCS 
 SC  CCS 
 SC  NCS 
 SC   CS 
 SCCECCS 
 S     S 
         
|----Layer 4|
         
  S   S  
  SCCCS  
  S W S  
  S   S  
  S  CS  
  S  CS  
  S   S  
  S T S  
  SCCCS  
  S W S  
         
|----Layer 5|
         
   S S   
   SCS   
   S S   
   S S   
   S C   
   S S   
   S S   
   S S   
   SCS   
   S S   
         
|----Layer 6|
         
    S    
    S    
    S    
    S    
    So   
    S    
    S    
    S    
    S    
    S    
         
|----Layer 7|
         
         
         
         
         
     o   
         
         
         
         
         
         
}}



==== Materials ====

{| class="wikitable sortable mw-collapsible"
|-
! Name !! Total !! Layer 1 !! Layer 2 !! Layer 3 !! Layer 4 !! Layer 5 !! Layer 6 !! Layer 7 
|-
| {{BlockLink|Blast Furnace}} || 2 || - || 2 || - || - || - || - || - 
|-
| {{BlockLink|Cobblestone}} || 61 || 5 || 23 || 22 || 8 || 3 || - || - 
|-
| {{BlockLink|Cobblestone Stairs}} || 2 || - || - || 2 || - || - || - || - 
|-
| {{BlockLink|Cobblestone Wall}} || 2 || - || - || - || - || - || 1 || 1 
|-
| {{BlockLink|Dirt}} || 25 || 25 || - || - || - || - || - || - 
|-
| {{BlockLink|Glass Pane}} || 1 || - || - || 1 || - || - || - || - 
|-
| {{BlockLink|Grass Block}} || 2 || 2 || - || - || - || - || - || - 
|-
| {{BlockLink|Dirt Path}} || 1 || 1 || - || - || - || - || - || - 
|-
| {{BlockLink|Poppy}} || 2 || - || 2 || - || - || - || - || - 
|-
| {{BlockLink|Spruce Door}} || 1 || - || 1 || - || - || - || - || - 
|-
| {{BlockLink|Spruce Log}} || 69 || - || - || 20 || 20 || 19 || 10 || - 
|-
| {{BlockLink|Spruce Planks}} || 10 || 10 || - || - || - || - || - || - 
|-
| {{BlockLink|Spruce Trapdoor}} || 2 || - || - || 2 || - || - || - || - 
|-
| {{BlockLink|Torch}} || 3 || - || - || - || 3 || - || - || - 
|}<noinclude>
[[Category:Village blueprints]]

[[fr:Village/Structure/Taïga Maison d'Armurier 1 plan]]
[[ja:村/構造/設計図/タイガの防具鍛冶の家1]]
[[zh:村庄/结构/图示/针叶林盔甲匠房屋]]
</noinclude>