<noinclude>{{structure info}}</noinclude>

[[File:Taiga Cartographer House 1.png|thumb|Cartographer House 1 (Taiga)]]



==== Blueprint ====

{{layered blueprint|name=
Taiga Cartographer House 1|default=Layer 1
|G=Grass Block+top
|S=Spruce Log-rot-90
|D=Dirt
|P=Spruce Log+top
|C=Cobblestone
|R=Spruce Planks
|A=Cartography Table
|H=Chest
|T=Dirt Path+top
|O=Cobblestone Wall
|o=Torch
|U=Spruce Trapdoor
|Y=Poppy
|W=Wall Torch-rot-90
|E=Spruce Door+bottom
|p=Spruce Door+top
|L=Glass Pane
|a=Wall Torch
|l=Wall Torch-rot-180
|I=Spruce Stairs
|r=Wall Torch-rot-270
|N=Glass Pane-rot-90
|F=Spruce Fence
|d=Ladder
          
|----Layer 1|
          
          
   DDDDD  
 GDDCCCD  
 TTCCCCD  
 GDDCCCD  
   DDDDD  
          
|----Layer 2|
          
          
   CCCCC  
 OPC  AC  
   E   C  
 OPC   C  
   CCCCC  
          
          
|----Layer 3|
          
    U U   
   CCNCC  
 oPCl  CU 
   p   L  
 oPCa dCU 
   CCNCC  
    U U   
          
|----Layer 4|
          
          
   CCCCC  
  PCCCCC  
  UCCCCC  
  PCCCdC  
   CCCCC  
          
          
|----Layer 5|
          
          
   RPRPR  
  PPIFIP  
 UGR   R  
  PPH  P  
   RPRPR  
          
          
|----Layer 6|
          
          
   RPNPR  
  PP U P  
  YL   L  
  PP   P  
   RPNPR  
          
          
|----Layer 7|
          
 SSSSSSSS 
   RPRPR  
  PP   P  
   Rr WR  
  PP   P  
   RPRPR  
 SSSSSSSS 
          
|----Layer 8|
          
          
 SSSSSSSS 
  PP   P  
   L   R  
  PP   P  
 SSSSSSSS 
          
          
|----Layer 9|
          
          
          
 SSSSSSSS 
  WR   R  
 SSSSSSSS 
          
          
          
|----Layer 10|
          
          
          
          
 SSSSSSSS 
          
          
          
          
}}



==== Materials ====

{| class="wikitable sortable mw-collapsible"
|-
! Name !! Total !! Layer 1 !! Layer 2 !! Layer 3 !! Layer 4 !! Layer 5 !! Layer 6 !! Layer 7 !! Layer 8 !! Layer 9 !! Layer 10 
|-
| {{BlockLink|Cartography Table}} || 1 || - || 1 || - || - || - || - || - || - || - || - 
|-
| {{BlockLink|Chest}} || 1 || - || - || - || - || 1 || - || - || - || - || - 
|-
| {{BlockLink|Cobblestone}} || 61 || 10 || 15 || 12 || 24 || - || - || - || - || - || - 
|-
| {{BlockLink|Cobblestone Wall}} || 2 || - || 2 || - || - || - || - || - || - || - || - 
|-
| {{BlockLink|Dirt}} || 17 || 17 || - || - || - || - || - || - || - || - || - 
|-
| {{BlockLink|Glass Pane}} || 8 || - || - || 3 || - || - || 4 || - || 1 || - || - 
|-
| {{BlockLink|Grass Block}} || 4 || 3 || - || - || - || 1 || - || - || - || - || - 
|-
| {{BlockLink|Dirt Path}} || 2 || 2 || - || - || - || - || - || - || - || - || - 
|-
| {{BlockLink|Ladder}} || 2 || - || - || 1 || 1 || - || - || - || - || - || - 
|-
| {{BlockLink|Poppy}} || 1 || - || - || - || - || - || 1 || - || - || - || - 
|-
| {{BlockLink|Spruce Door}} || 1 || - || 1 || - || - || - || - || - || - || - || - 
|-
| {{BlockLink|Spruce Fence}} || 1 || - || - || - || - || 1 || - || - || - || - || - 
|-
| {{BlockLink|Spruce Log}} || 98 || - || 2 || 2 || 2 || 10 || 10 || 26 || 22 || 16 || 8 
|-
| {{BlockLink|Spruce Planks}} || 23 || - || - || - || - || 8 || 4 || 8 || 1 || 2 || - 
|-
| {{BlockLink|Spruce Stairs}} || 2 || - || - || - || - || 2 || - || - || - || - || - 
|-
| {{BlockLink|Spruce Trapdoor}} || 9 || - || - || 6 || 1 || 1 || 1 || - || - || - || - 
|-
| {{BlockLink|Torch}} || 7 || - || - || 4 || - || - || - || 2 || - || 1 || - 
|}<noinclude>
[[Category:Village blueprints]]

[[fr:Village/Structure/Taïga Maison de Cartographe 1 plan]]
[[ja:村/構造/設計図/タイガの製図家の家1]]
[[zh:村庄/结构/图示/针叶林制图师房屋]]
</noinclude>