<noinclude>{{structure info}}</noinclude>

[[File:Savanna Small House 8.png|thumb|Small House 8 (Savanna)]]



==== Blueprint ====

{{layered blueprint|name=Savanna Small House 8|default=Layer 1
|D=Dirt
|Y=Yellow Terracotta
|A=Acacia Wood
|C=Acacia Planks
|I=Acacia Log
|L=Acacia Log+top
|O=Orange Bed+top+foot-rot-90
|R=Orange Bed+top+head-rot-90
|s=Acacia Stairs
|>=Acacia Stairs-rot-90
|^=Acacia Stairs-rot-180
|<=Acacia Stairs-rot-270
|d=Dirt Path+top
|c=Acacia Door+bottom
|a=Acacia Door+top
|P=Glass Pane-rot-90
|W=Wall Torch-rot-180
|T=Wall Torch
|----Layer 1|
        
  DDD   
 DILID  
 DILID  
  DID   
   d    
|----Layer 2|
        
  YYY   
 YR <Y  
 YO <Y  
  YcY   
        
|----Layer 3|
        
  APA   
 A   A  
 A   A  
  AaA   
        
|----Layer 4|
        
  YYY   
 Y   Y  
 Y T Y  
  YYY   
   W    
|----Layer 5|
 ^^^^^  
<CCCCC> 
<C   C> 
<C   C> 
<CCCCC> 
 sssss  
|----Layer 6|
        
 <^^^^  
 <CCC>  
 <CCC>  
 <sss>  
        
}}



==== Materials ====

{| class="wikitable sortable mw-collapsible"
|-
! Name !! Total !! Layer 1 !! Layer 2 !! Layer 3 !! Layer 4 !! Layer 5 !! Layer 6 
|-
| {{BlockLink|Acacia Door}} || 1 || - || 1 || - || - || - || - 
|-
| {{BlockLink|Acacia Log}} || 7 || 7 || - || - || - || - || - 
|-
| {{BlockLink|Acacia Planks}} || 20 || - || - || - || - || 14 || 6 
|-
| {{BlockLink|Acacia Stairs}} || 34 || - || 2 || - || - || 18 || 14 
|-
| {{BlockLink|Acacia Wood}} || 8 || - || - || 8 || - || - || - 
|-
| {{BlockLink|Dirt}} || 9 || 9 || - || - || - || - || - 
|-
| {{BlockLink|Glass Pane}} || 1 || - || - || 1 || - || - || - 
|-
| {{BlockLink|Dirt Path}} || 1 || 1 || - || - || - || - || - 
|-
| {{BlockLink|Orange Bed}} || 1 || - || 1 || - || - || - || - 
|-
| {{BlockLink|Torch}} || 2 || - || - || - || 2 || - || - 
|-
| {{BlockLink|Yellow Terracotta}} || 19 || - || 9 || - || 10 || - || - 
|}<noinclude>
[[Category:Village blueprints]]

[[fr:Village/Structure/Savane Petite Maison 8 plan]]
[[ja:村/構造/設計図/サバンナの小さな家8]]
[[zh:村庄/结构/图示/热带草原小型房屋8]]
</noinclude>