<noinclude>{{structure info}}</noinclude>

[[File:Plains Small House 7.png|thumb|Small House 7 (Plains)]]



==== Blueprint ====

{{layered blueprint
|name=Village Plains Houses plains_small_house_7
|default=Layer 2
|O=Oak Log+top
|L=Oak Log-rot90
|l=Oak Log
|C=Cobblestone
|c=Cobblestone Stairs
|U=Chest-rot90
|d=Oak Door+bottom
|D=Oak Door+top
|)=Cobblestone Stairs-rot270
|(=Cobblestone Stairs-rot90
|T=torch-rot180
|t=torch
|<=Oak Stairs-rot90
|>=Oak Stairs-rot270
|g=glass Pane
|G=glass Pane-rot90
|P=Oak Planks
|Y=Yellow Bed+top foot-rot90
|y=Yellow Bed+top head-rot90
|----Layer 1|
          
          
  OCCCCO  
  COPPOC  
  CPPPPC  
  COPPOC  
  OCCCCO  
   (cc)   
          
|----Layer 2|
          
          
  OCCCCO  
  C>  UC  
  CY   C  
  Cy   C  
  OCddCO  
          
|----Layer 3|
          
          
  OLGGLO  
  l    l  
  g    g  
  l    l  
  OLDDLO  
   T  T   
          
|----Layer 4|
          
 <>    <> 
 <OCCCCO> 
 <C    C> 
 <C    C> 
 <C tt C> 
 <OCCCCO> 
 <>    <> 
          
|----Layer 5|
          
  <>  <>  
  <CCCC>  
  <    >  
  <    >  
  <    >  
  <CCCC>  
  <>  <>  
          
|----Layer 6|
          
   <><>   
   <CC>   
   <  >   
   <  >   
   <  >   
   <CC>   
   <><>   
|----Layer 7|
          
    <>    
    <>    
    <>    
    <>    
    <>    
    <>    
    <>    
          
}}


This structure has a lot of similarities with the [[Village/Structure/Blueprints/Plains armorer house 1 blueprint|Armorer House]].

==== Materials ====

{| class="wikitable sortable mw-collapsible"
|-
! Name !! Total !! Layer 1 !! Layer 2 !! Layer 3 !! Layer 4 !! Layer 5 !! Layer 6 !! Layer 7 
|-
| {{BlockLink|Chest}} || 1 || - || 1 || - || - || - || - || - 
|-
| {{BlockLink|Cobblestone}} || 52 || 14 || 12 || - || 14 || 8 || 4 || - 
|-
| {{BlockLink|Cobblestone Stairs}} || 4 || 4 || - || - || - || - || - || - 
|-
| {{BlockLink|Glass Pane}} || 4 || - || - || 4 || - || - || - || - 
|-
| {{ItemLink|Oak Door}} || 2 || - || 2 || - || - || - || - || - 
|-
| {{BlockLink|Oak Log}} || 28 || 8 || 4 || 12 || 4 || - || - || - 
|-
| {{BlockLink|Oak Planks}} || 8 || 8 || - || - || - || - || - || - 
|-
| {{BlockLink|Oak Stairs}} || 69 || - || 1 || - || 18 || 18 || 18 || 14 
|-
| {{BlockLink|Torch}} || 4 || - || - || 2 || 2 || - || - || - 
|-
| {{BlockLink|Yellow Bed}} || 1 || - || 1 || - || - || - || - || - 
|}<noinclude>
[[Category:Village blueprints]]

[[fr:Village/Structure/Plaines Petite Maison 7 plan]]
[[ja:村/構造/設計図/平原の小さな家7]]
[[zh:村庄/结构/图示/平原小型房屋7]]
</noinclude>