<noinclude>{{structure info}}</noinclude>

[[File:Savanna Small House 2.png|thumb|Small House 2 (Savanna)]]



==== Blueprint ====

{{layered blueprint|name=Savanna Small House 2|default=Layer 1
|G=grass block+top
|D=dirt
|R=red terracotta
|A=acacia planks
|C=acacia wood
|I=acacia wood-rot-90
|H=chest-rot-90
|E=Red Bed+side+head-rot-180
|B=Red Bed+side+foot-rot-180
|S=short grass
|L=glass pane
|s=acacia stairs
|>=acacia stairs-rot-90
|^=acacia stairs-rot-180
|<=acacia stairs-rot-270
|W=Wall Torch-rot-270
|P=glass pane-rot-90
|O=acacia door+bottom
|d=acacia door+top
|g=Dirt path+top
         
|----Layer 1|
         
 GGGGGGG 
 GGDDDGG 
 GDCCCDD 
 GDCCCIg 
 GDCICDG 
 GGDDDGG 
 GGGGGGG 
         
|----Layer 2|
         
 S S S   
 SSRRR   
 SREB R  
 SR   O  
  RH  R  
 SSRRRSS 
 S     S 
         
|----Layer 3|
         
         
   RPR   
  R   R  
  L   d  
  R   R  
   RPR   
         
         
|----Layer 4|
         
         
   RRR   
  R   R  
  RW  RW 
  R   R  
   RRR   
         
         
|----Layer 5|
         
  ^^^^^  
 <AAAAA> 
 <A   A> 
 <A   A> 
 <A   A> 
 <AAAAA> 
  sssss  
         
|----Layer 6|
         
         
  <^^^>  
  <AAA>  
  <AAA>  
  <AAA>  
  sssss  
         
         
|----Layer 7|
         
         
         
   ^^>   
   <A>   
   <ss   
         
         
         
}}



==== Materials ====

{| class="wikitable sortable mw-collapsible"
|-
! Name !! Total !! Layer 1 !! Layer 2 !! Layer 3 !! Layer 4 !! Layer 5 !! Layer 6 !! Layer 7 
|-
| {{BlockLink|Acacia Door}} || 1 || - || 1 || - || - || - || - || - 
|-
| {{BlockLink|Acacia Planks}} || 26 || - || - || - || - || 16 || 9 || 1 
|-
| {{BlockLink|Acacia Stairs}} || 44 || - || - || - || - || 20 || 16 || 8 
|-
| {{BlockLink|Acacia Wood}} || 10 || 10 || - || - || - || - || - || - 
|-
| {{BlockLink|Chest}} || 1 || - || 1 || - || - || - || - || - 
|-
| {{BlockLink|Dirt}} || 12 || 12 || - || - || - || - || - || - 
|-
| {{BlockLink|Glass Pane}} || 3 || - || - || 3 || - || - || - || - 
|-
| {{BlockLink|Short Grass}} || 13 || - || 13 || - || - || - || - || - 
|-
| {{BlockLink|Grass Block}} || 26 || 26 || - || - || - || - || - || - 
|-
| {{BlockLink|Dirt Path}} || 1 || 1 || - || - || - || - || - || - 
|-
| {{BlockLink|Red Bed}} || 1 || - || 1 || - || - || - || - || - 
|-
| {{BlockLink|Red Terracotta}} || 31 || - || 11 || 8 || 12 || - || - || - 
|-
| {{BlockLink|Torch}} || 2 || - || - || - || 2 || - || - || - 
|}<noinclude>
[[Category:Village blueprints]]

[[fr:Village/Structure/Savane Petite Maison 2 plan]]
[[ja:村/構造/設計図/サバンナの小さな家2]]
[[zh:村庄/结构/图示/热带草原小型房屋2]]
</noinclude>