<noinclude>{{structure info}}</noinclude>

[[File:Plains library 2.png|thumb|Library 2 (Plains)]]



==== Blueprint ====

{{layered blueprint
|name=Plains Library 2
|default=Layer 1
|D=Dirt
|O=Oak Log+top
|b=Oak Log-rot90
|c=Oak Log
|C=Cobblestone
|A=Oak Planks
|G=Grass Block+top
|B=Bookshelf
|L=Lectern
|W=Wall Torch-rot-90
|K=Oak Stairs
|S=Oak Stairs-rot-180
|P=Glass Pane
|F=Oak Fence
|R=Dirt Path+top
|a=Oak Door+bottom
|k=Oak Door+top
|N=Glass Pane-rot-90
|T=Wall Torch-rot-180
|H=Wall Torch
|l=Wall Torch-rot-270
           
|----Layer 0|
           
           
  DDDDDDD  
  DCCDDCD  
  DCCCCCD  
  DCCCCCD  
  DDCDCDD  
    R R    
   GRDRG   
           
|----Layer 1|
           
           
  OCCCCCO  
  CBBAK C  
  C     C  
  CL    C  
  OCaCaCO  
           
   F F F   
           
|----Layer 2|
           
     H     
  OCNCNCO  
  CB K  C  
  P     P  
  C  H  C  
  OCkCkCO  
           
   F F F   
           
|----Layer 3|
           
           
  OCCCCCO  
  CBK   C  
  C     C  
  C     C  
  OCCCCCO  
    T T    
   FFFFF   
           
|----Layer 4|
           
           
  bbbbbbb  
  cK   Ac  
 WcAAAAAcl 
  cAAAAAc  
  bbbbbbb  
  cAAAAAc  
   bbbbb   
           
|----Layer 5|
           
           
  OAAAAAO  
  A     A  
  A     A  
  A     A  
  OAaAaAO  
  F     F  
   FFFFF   
           
|----Layer 6|
           
 KS  H  SK 
 KOANANAOK 
 SA  T  AS 
  P     P  
 SA     AS 
 KOAkAkAOK 
 KS     SK 
           
           
|----Layer 7|
           
  KS   SK  
  KAAAAAK  
 KA     AK 
 KA     AK 
 KA     AK 
  KAAAAAK  
  KST TSK  
           
           
|----Layer 8|
           
   KS SK   
   KbbbK   
   K   K   
   K   K   
   K   K   
   KbbbK   
   KS SK   
           
           
|----Layer 9|
           
    KcK    
    KcK    
    KcK    
    KcK    
    KcK    
    KcK    
    KcK    
           
           
}}



==== Materials ====

{| class="wikitable sortable mw-collapsible"
|-
! Name !! Total !! Layer 0 !! Layer 1 !! Layer 2 !! Layer 3 !! Layer 4 !! Layer 5 !! Layer 6 !! Layer 7 !! Layer 8 !! Layer 9 
|-
| {{BlockLink|Bookshelf}} || 4 || - || 2 || 1 || 1 || - || - || - || - || - || - 
|-
| {{BlockLink|Cobblestone}} || 55 || 15 || 14 || 10 || 16 || - || - || - || - || - || - 
|-
| {{BlockLink|Dirt}} || 21 || 21 || - || - || - || - || - || - || - || - || - 
|-
| {{BlockLink|Dirt Path}} || 4 || 4 || - || - || - || - || - || - || - || - || - 
|-
| {{BlockLink|Glass Pane}} || 8 || - || - || 4 || - || - || - || 4 || - || - || - 
|-
| {{BlockLink|Grass Block}} || 2 || 2 || - || - || - || - || - || - || - || - || - 
|-
| {{BlockLink|Lectern}} || 1 || - || 1 || - || - || - || - || - || - || - || - 
|-
| {{ItemLink|Oak Door}} || 4 || - || 2 || - || - || - || 2 || - || - || - || - 
|-
| {{BlockLink|Oak Fence}} || 18 || - || 3 || 3 || 5 || - || 7 || - || - || - || - 
|-
| {{BlockLink|Oak Log}} || 60 || - || 4 || 4 || 4 || 27 || 4 || 4 || - || 6 || 7 
|-
| {{BlockLink|Oak Planks}} || 57 || - || 1 || - || - || 16 || 14 || 10 || 16 || - || - 
|-
| {{BlockLink|Oak Stairs}} || 70 || - || 1 || 1 || 1 || 1 || - || 16 || 18 || 18 || 14 
|-
| {{BlockLink|Torch}} || 10 || - || - || 2 || 2 || 2 || - || 2 || 2 || - || - 
|}

<noinclude>
[[Category:Village blueprints]]

[[fr:Village/Structure/Plaines Bibliothèque 2 plan]]
[[ja:村/構造/設計図/平原の図書室2]]
[[zh:村庄/结构/图示/平原图书馆2]]
</noinclude>