<noinclude>{{structure info}}</noinclude>

[[File:Taiga Temple 1.png|thumb|Temple 1 (Taiga)]]



==== Blueprint ====

{{layered blueprint|name=
Taiga Temple 1|default=Layer 1
|D=Dirt
|G=Grass Block+top
|C=Cobblestone
|S=Spruce Planks
|P=Spruce Wood
|R=Spruce Log
|U=Spruce Log-rot-90
|E=Spruce Log+top
|B=Brewing Stand
|T=Spruce Trapdoor
|L=Large Fern
|f=Large Fern+bottom
|O=Cobblestone Wall
|H=Torch
|F=Spruce Fence
|A=Purple Carpet
|a=Ladder
|N=Glass Pane
|Y=Potted Poppy
|I=Cobblestone Stairs
|W=Wall Torch
|l=Wall Torch-rot-180
|s=Glass Pane-rot-90
|p=Spruce Door+bottom
|r=Spruce Door+top
|o=Poppy
|t=Dirt Path+top
            
|----Layer 1|
            
 GGGGDG     
 GSGGDG     
 GGGDDDG    
  GDCCCDGG  
 DDDCCCDDD  
   DCCCDDD t
   GDDCCCCtt
   GGDCCCCGt
   GGDCCCDDG
     DCCCDDG
     DCCCDDG
     DDDDDGG
          GG
            
|----Layer 2|
            
 fT  Cf     
 T T C      
  TfCCCf    
   CACACTT  
 CCCAAACGGT 
   C   CCC  
    CC   p  
     C   CT 
   f C   CGT
     C   CGT
     CIBICGT
     CCCCCT 
           O
            
|----Layer 3|
            
 L   CL     
     I      
   LCCCL    
   C Y C    
 CCC   Cfo  
   Ca  CCC  
    CC   r  
    TC   C  
   L N   CT 
    TC   No 
     N   CT 
    TCCsCC  
      T T  H
            
|----Layer 4|
            
     O      
            
    CCC     
   C   C    
 O C   CL   
   Ca WCCC  
    CCC  C  
     C   C  
     C   C  
     C   C  
     C   C  
     CCCCC  
            
            
|----Layer 5|
            
     H      
            
    CCC     
   C   C    
 H C   C    
   Ca  CC   
    CCClC   
      C C   
      C C   
      C C   
      CWC   
      CCC   
            
            
|----Layer 6|
            
            
            
    CCC     
   CCCCC    
   CCCCC    
   CaCCC    
    CCCC    
       C    
       C    
       C    
       C    
       C    
            
            
|----Layer 7|
            
            
            
    CCC     
   C   C    
   C   C    
   C   C    
    CCC     
            
            
            
            
            
            
            
|----Layer 8|
            
            
    T T     
    CFC     
  TC   CT   
   F   F    
  TC   CT   
    CFC     
    T T     
            
            
            
            
            
            
|----Layer 9|
            
            
            
    CCC     
   C   C    
   C   C    
   C   C    
    CCC     
            
            
            
            
            
            
            
|----Layer 10|
            
            
    T T     
    CFC     
  TC   CT   
   F   F    
  TC   CT   
    CFC     
    T T     
            
            
            
            
            
            
|----Layer 11|
            
            
            
    CCC     
   C l C    
   C   C    
   C W C    
    CCC     
            
            
            
            
            
            
            
|----Layer 12|
            
            
   PUUUP    
  PEUEUEP   
  EE   EE   
  EE   EE   
  EE   EE   
  PUUUUEP   
   PUUUP    
            
            
            
            
            
            
|----Layer 13|
            
            
            
   PUUUP    
   EEPUE    
   EP EE    
   EE EE    
   PUUUP    
            
            
            
            
            
            
            
|----Layer 14|
            
            
            
            
    PPP     
    PPP     
    PPP     
            
            
            
            
            
            
            
            
}}



==== Materials ====

{| class="wikitable sortable mw-collapsible"
|-
! Name !! Total !! Layer 1 !! Layer 2 !! Layer 3 !! Layer 4 !! Layer 5 !! Layer 6 !! Layer 7 !! Layer 8 !! Layer 9 !! Layer 10 !! Layer 11 !! Layer 12 !! Layer 13 !! Layer 14 
|-
| {{BlockLink|Brewing Stand}} || 1 || - || 1 || - || - || - || - || - || - || - || - || - || - || - || - 
|-
| {{BlockLink|Cobblestone}} || 213 || 26 || 31 || 25 || 28 || 25 || 26 || 12 || 8 || 12 || 8 || 12 || - || - || - 
|-
| {{BlockLink|Cobblestone Stairs}} || 3 || - || 2 || 1 || - || - || - || - || - || - || - || - || - || - || - 
|-
| {{BlockLink|Cobblestone Wall}} || 3 || - || 1 || - || 2 || - || - || - || - || - || - || - || - || - || - 
|-
| {{BlockLink|Dirt}} || 34 || 34 || - || - || - || - || - || - || - || - || - || - || - || - || - 
|-
| {{BlockLink|Glass Pane}} || 4 || - || - || 4 || - || - || - || - || - || - || - || - || - || - || - 
|-
| {{BlockLink|Grass Block}} || 34 || 29 || 5 || - || - || - || - || - || - || - || - || - || - || - || - 
|-
| {{BlockLink|Dirt Path}} || 4 || 4 || - || - || - || - || - || - || - || - || - || - || - || - || - 
|-
| {{BlockLink|Ladder}} || 4 || - || - || 1 || 1 || 1 || 1 || - || - || - || - || - || - || - || - 
|-
| {{BlockLink|Large Fern}} || 12 || - || 5 || 6 || 1 || - || - || - || - || - || - || - || - || - || - 
|-
| {{BlockLink|Poppy}} || 2 || - || - || 2 || - || - || - || - || - || - || - || - || - || - || - 
|-
| {{BlockLink|Potted Poppy}} || 1 || - || - || 1 || - || - || - || - || - || - || - || - || - || - || - 
|-
| {{BlockLink|Purple Carpet}} || 5 || - || 5 || - || - || - || - || - || - || - || - || - || - || - || - 
|-
| {{BlockLink|Spruce Door}} || 1 || - || 1 || - || - || - || - || - || - || - || - || - || - || - || - 
|-
| {{BlockLink|Spruce Fence}} || 8 || - || - || - || - || - || - || - || 4 || - || 4 || - || - || - || - 
|-
| {{BlockLink|Spruce Log}} || 45 || - || - || - || - || - || - || - || - || - || - || - || 28 || 17 || - 
|-
| {{BlockLink|Spruce Planks}} || 1 || 1 || - || - || - || - || - || - || - || - || - || - || - || - || - 
|-
| {{BlockLink|Spruce Trapdoor}} || 35 || - || 12 || 7 || - || - || - || - || 8 || - || 8 || - || - || - || - 
|-
| {{BlockLink|Spruce Wood}} || 23 || - || - || - || - || - || - || - || - || - || - || - || 8 || 6 || 9 
|-
| {{BlockLink|Torch}} || 8 || - || - || 1 || 1 || 4 || - || - || - || - || - || 2 || - || - || - 
|}<noinclude>
[[Category:Village blueprints]]

[[fr:Village/Structure/Taïga Temple 1 plan]]
[[zh:村庄/结构/图示/针叶林教堂]]
</noinclude>