<noinclude>{{structure info}}</noinclude>

[[File:Taiga Small House 2.png|thumb|Small House 2 (Taiga)]]



==== Blueprint ====

{{layered blueprint|name=
Taiga Small House 2|default=Layer 1
|S=Spruce Log-rot-90
|C=Cobblestone
|P=Spruce Log+top
|R=Spruce Planks
|U=Purple Bed+side+foot
|L=Purple Bed+side+head
|F=Fern
|O=Cobblestone Wall
|A=Large Fern
|a=Large Fern+bottom
|T=Torch
|E=Spruce Door+bottom
|D=Spruce Door+top
|I=Spruce Stairs
|p=Spruce Trapdoor
|G=Glass Pane-rot-90
|N=Glass Pane
|B=Cobblestone Stairs
         
|----Layer 1|
         
         
 aCCCCC  
 OCPRPC  
 BCRRRC  
 OCPRPC  
 FCCCCC  
         
         
|----Layer 2|
         
         
 ACCCCC  
 TC ULC  
  E   C  
 TCIRIC  
  CCCCC  
         
         
|----Layer 3|
         
   p p   
  CCGCC  
  C   Cp 
  D   N  
  C T Cp 
  CCGCC  
   p p   
         
|----Layer 4|
         
 SSSSSSS 
  CCCCC  
  C   C  
  C   C  
  C   C  
  CCCCC  
 SSSSSSS 
         
|----Layer 5|
         
         
 SSSSSSS 
  C   C  
  C   C  
  C   C  
 SSSSSSS 
         
         
|----Layer 6|
         
         
         
 SSSSSSS 
  C   C  
 SSSSSSS 
         
         
         
|----Layer 7|
         
         
         
         
 SSSSSSS 
         
         
         
         
}}



==== Materials ====

{| class="wikitable sortable mw-collapsible"
|-
! Name !! Total !! Layer 1 !! Layer 2 !! Layer 3 !! Layer 4 !! Layer 5 !! Layer 6 !! Layer 7 
|-
| {{BlockLink|Cobblestone}} || 67 || 16 || 15 || 12 || 16 || 6 || 2 || - 
|-
| {{BlockLink|Cobblestone Stairs}} || 1 || 1 || - || - || - || - || - || - 
|-
| {{BlockLink|Cobblestone Wall}} || 2 || 2 || - || - || - || - || - || - 
|-
| {{BlockLink|Fern}} || 1 || 1 || - || - || - || - || - || - 
|-
| {{BlockLink|Glass Pane}} || 3 || - || - || 3 || - || - || - || - 
|-
| {{BlockLink|Large Fern}} || 2 || 1 || 1 || - || - || - || - || - 
|-
| {{BlockLink|Purple Bed}} || 1 || - || 1 || - || - || - || - || - 
|-
| {{BlockLink|Spruce Door}} || 1 || - || 1 || - || - || - || - || - 
|-
| {{BlockLink|Spruce Log}} || 53 || 4 || - || - || 14 || 14 || 14 || 7 
|-
| {{BlockLink|Spruce Planks}} || 6 || 5 || 1 || - || - || - || - || - 
|-
| {{BlockLink|Spruce Stairs}} || 2 || - || 2 || - || - || - || - || - 
|-
| {{BlockLink|Spruce Trapdoor}} || 6 || - || - || 6 || - || - || - || - 
|-
| {{BlockLink|Torch}} || 3 || - || 2 || 1 || - || - || - || - 
|}<noinclude>
[[Category:Village blueprints]]

[[fr:Village/Structure/Taïga Petite Maison 2 plan]]
[[zh:村庄/结构/图示/针叶林小型房屋2]]
</noinclude>