<noinclude>{{structure info}}</noinclude>

[[File:Savanna Small House 7.png|thumb|Small House 7 (Savanna)]]



==== Blueprint ====

{{layered blueprint|name=Savanna Small House 7|default=Layer 1
|G=Grass Block+top
|D=Dirt
|A=Acacia Log+top
|C=Acacia Log
|c=Acacia Log-rot-90
|I=Acacia Planks
|W=Acacia Wood
|w=Acacia Wood-rot-90
|O=Orange Bed+side+head-rot-180
|R=Orange Bed+side+foot-rot-180
|H=Chest-rot-180
|S=Short Grass
|s=Acacia Stairs
|>=Acacia Stairs-rot-90
|^=Acacia Stairs-rot-180
|<=Acacia Stairs-rot-270
|L=Glass Pane
|P=Glass Pane-rot-90
|o=Torch
|d=Acacia Door+bottom
|a=Acacia Door+top
|r=Dirt Path+top
|l=Wall Torch-rot-270
         
|----Layer 1|
         
 GGGGGGG 
 GGDDDGG 
 GDWWWDG 
 GDWWWwr 
 GDWwWDD 
 GGDDDGG 
 GGGGGGG 
         
|----Layer 2|
         
 S S     
 SSAcA   
  A>W<AS 
  C   d  
  AORHA  
 SSAcASS 
 S  S  S 
         
|----Layer 3|
         
         
   APA   
  A o A  
  L   a  
  A   A  
   APA   
         
         
|----Layer 4|
         
         
   AcA   
  A   A  
  C   Cl 
  A   A  
   AcA   
         
         
|----Layer 5|
         
  ^^^^^  
 <IIIII> 
 <I   I> 
 <I   I> 
 <I   I> 
 <IIIII> 
  sssss  
         
|----Layer 6|
         
         
  <^^^>  
  <III>  
  <III>  
  <III>  
  sssss  
         
         
|----Layer 7|
         
         
         
   ^^>   
   <I>   
   <ss   
         
         
         
}}



==== Materials ====

{| class="wikitable sortable mw-collapsible"
|-
! Name !! Total !! Layer 1 !! Layer 2 !! Layer 3 !! Layer 4 !! Layer 5 !! Layer 6 !! Layer 7 
|-
| {{BlockLink|Acacia Door}} || 1 || - || 1 || - || - || - || - || - 
|-
| {{BlockLink|Acacia Log}} || 31 || - || 11 || 8 || 12 || - || - || - 
|-
| {{BlockLink|Acacia Planks}} || 26 || - || - || - || - || 16 || 9 || 1 
|-
| {{BlockLink|Acacia Stairs}} || 46 || - || 2 || - || - || 20 || 16 || 8 
|-
| {{BlockLink|Acacia Wood}} || 11 || 10 || 1 || - || - || - || - || - 
|-
| {{BlockLink|Chest}} || 1 || - || 1 || - || - || - || - || - 
|-
| {{BlockLink|Dirt}} || 12 || 12 || - || - || - || - || - || - 
|-
| {{BlockLink|Glass Pane}} || 3 || - || - || 3 || - || - || - || - 
|-
| {{BlockLink|Short Grass}} || 12 || - || 12 || - || - || - || - || - 
|-
| {{BlockLink|Grass Block}} || 26 || 26 || - || - || - || - || - || - 
|-
| {{BlockLink|Dirt Path}} || 1 || 1 || - || - || - || - || - || - 
|-
| {{BlockLink|Orange Bed}} || 1 || - || 1 || - || - || - || - || - 
|-
| {{BlockLink|Torch}} || 2 || - || - || 1 || 1 || - || - || - 
|}<noinclude>
[[Category:Village blueprints]]

[[fr:Village/Structure/Savane Petite Maison 7 plan]]
[[ja:村/構造/設計図/サバンナの小さな家7]]
[[zh:村庄/结构/图示/热带草原小型房屋7]]
</noinclude>