<noinclude>{{structure info}}</noinclude>

[[File:Taiga Small House 1.png|thumb|Small House 1 (Taiga)]]



==== Blueprint ====

{{layered blueprint|name=
Taiga Small House 1|default=Layer 1
|S=Spruce Log-rot-90
|q=Spruce Log
|D=Dirt
|G=Grass Block+top
|P=Spruce Log+top
|C=Cobblestone
|R=Spruce Planks
|U=Spruce Wall Sign
|L=Purple Bed+side+foot
|E=Purple Bed+side+head
|A=Dirt Path+top
|O=Cobblestone Wall
|B=Cobblestone Stairs
|T=Torch
|p=Spruce Door+bottom
|r=Spruce Door+top
|u=Spruce Trapdoor
|W=Wall Torch-rot-270
|I=Spruce Stairs
|N=Glass Pane-rot-90
|l=Glass Pane
           
|----Layer 1|
           
           
  DDDDDDD  
  GDDDDD   
 AGDDDDD   
  GDDDDD   
  DDDDDDD  
           
           
|----Layer 2|
           
           
  PPCCCPP  
  OCRRRC   
  BCRRRC   
  OCRRRC   
  PPCCCPP  
           
           
|----Layer 3|
           
           
  PPCCCPP  
  TCUIUC   
   p   C   
  TC LEC   
  PPCCCPP  
           
           
|----Layer 4|
           
    u u    
  PPCNCPP  
   C   Cu  
   r   l   
   C   Cu  
  PPCNCPP  
    u u    
           
|----Layer 5|
           
 SSSSSSSSS 
  PPCCCPP  
   C   C   
   C   C   
   C   C   
  PPCCCPP  
 SSSSSSSSS 
           
|----Layer 6|
           
           
 SSSSSSSSS 
  qq   qq  
  qqW  qq  
  qq   qq  
 SSSSSSSSS 
           
           
|----Layer 7|
           
           
           
 SSSSSSSSS 
   C   C   
 SSSSSSSSS 
           
           
           
|----Layer 8|
           
           
           
           
 SSSSSSSSS 
           
           
           
           
}}



==== Materials ====

{| class="wikitable sortable mw-collapsible"
|-
! Name !! Total !! Layer 1 !! Layer 2 !! Layer 3 !! Layer 4 !! Layer 5 !! Layer 6 !! Layer 7 !! Layer 8 
|-
| {{BlockLink|Cobblestone}} || 45 || - || 12 || 11 || 8 || 12 || - || 2 || - 
|-
| {{BlockLink|Cobblestone Stairs}} || 1 || - || 1 || - || - || - || - || - || - 
|-
| {{BlockLink|Cobblestone Wall}} || 2 || - || 2 || - || - || - || - || - || - 
|-
| {{BlockLink|Dirt}} || 29 || 29 || - || - || - || - || - || - || - 
|-
| {{BlockLink|Glass Pane}} || 3 || - || - || - || 3 || - || - || - || - 
|-
| {{BlockLink|Grass Block}} || 3 || 3 || - || - || - || - || - || - || - 
|-
| {{BlockLink|Dirt Path}} || 1 || 1 || - || - || - || - || - || - || - 
|-
| {{BlockLink|Purple Bed}} || 1 || - || - || 1 || - || - || - || - || - 
|-
| {{BlockLink|Spruce Door}} || 1 || - || - || 1 || - || - || - || - || - 
|-
| {{BlockLink|Spruce Log}} || 107 || - || 8 || 8 || 8 || 26 || 30 || 18 || 9 
|-
| {{BlockLink|Spruce Planks}} || 9 || - || 9 || - || - || - || - || - || - 
|-
| {{BlockLink|Spruce Stairs}} || 1 || - || - || 1 || - || - || - || - || - 
|-
| {{BlockLink|Spruce Trapdoor}} || 6 || - || - || - || 6 || - || - || - || - 
|-
| {{BlockLink|Spruce Wall Sign}} || 2 || - || - || 2 || - || - || - || - || - 
|-
| {{BlockLink|Torch}} || 3 || - || - || 2 || - || - || 1 || - || - 
|}<noinclude>
[[Category:Village blueprints]]

[[fr:Village/Structure/Taïga Petite Maison 1 plan]]
[[zh:村庄/结构/图示/针叶林小型房屋1]]
</noinclude>