<noinclude>{{structure info}}</noinclude>

[[File:Desert Shepherd House 1.png|thumb|Shepherd house 1 (Desert)]]



==== Blueprint ====

{{layered blueprint|name=Desert Shepherd House 1
|default=Layer 1
|S=Sand
|C=Cut Sandstone
|M=Smooth Sandstone
|H=Hay Bale
|h=Hay Bale+top
|L=Loom
|A=Sandstone Wall
|N=Sandstone Slab+Bottom
|n=Sandstone Slab+Top
|W=Wall Torch-rot-180
|T=Water+top
|O=Wall Torch
|J=Jungle Door+bottom
|U=Jungle Door+top
|P=Potted Cactus
|R=Wall Torch-rot-270
       
|----Layer 0|
       
 SSSSS 
 SSMSS 
 SMMSS 
 SMMSS 
 SMMMS 
 SSMSS 
 SSMSS 
 SSSSS 
 SSSSS 
 STSSS 
 SSSSS 
       
|----Layer 1|
       
 CMMC  
 MLLM  
 M  MC 
 M  M  
 M  J  
 MH M  
 Ch CC 
 A  A  
 A  A  
 A  A  
 CAAC  
       
|----Layer 2|
       
 CMMC  
 M  M  
 N  NP 
 M  M  
 N  U  
 M  M  
 C  CP 
       
       
       
 C  C  
       
|----Layer 3|
       
 CMMC  
 MWWM  
 n  n  
 M  M  
 n  MR 
 MO M  
 CMMC  
 W  W  
       
       
 C  C  
       
|----Layer 4|
       
 CMMC  
 M  M  
 M  M  
 M  M  
 M  M  
 M  M  
 CMMC  
 NNNN  
 NNNN  
 NNNN  
 CNNC  
       
|----Layer 5|
       
 CNNC  
 NNNN  
 NNNN  
 NNNN  
 NNNN  
 NNNN  
 CNNC  
       
       
       
       
       
}}



==== Materials ====

{| class="wikitable sortable mw-collapsible"
|-
! Name !! Total !! Layer 0 !! Layer 1 !! Layer 2 !! Layer 3 !! Layer 4 !! Layer 5 
|-
| {{BlockLink|Cut Sandstone}} || 30 || - || 8 || 6 || 6 || 6 || 4 
|-
| {{BlockLink|Hay Bale}} || 2 || - || 2 || - || - || - || - 
|-
| {{ItemLink|Jungle Door}} || 1 || - || 1 || - || - || - || - 
|-
| {{BlockLink|Loom}} || 2 || - || 2 || - || - || - || - 
|-
| {{BlockLink|Potted Cactus}} || 2 || - || - || 2 || - || - || - 
|-
| {{BlockLink|Sand}} || 44 || 44 || - || - || - || - || - 
|-
| {{BlockLink|Sandstone Slab}} || 44 || - || - || 3 || 3 || 14 || 24 
|-
| {{BlockLink|Sandstone Wall}} || 8 || - || 8 || - || - || - || - 
|-
| {{BlockLink|Smooth Sandstone}} || 54 || 10 || 11 || 8 || 11 || 14 || - 
|-
| {{BlockLink|Torch}} || 6 || - || - || - || 6 || - || - 
|-
| {{BlockLink|Water}} || 1 || 1 || - || - || - || - || - 
|}<noinclude>
[[Category:Village blueprints]]

[[fr:Village/Structure/Désert Maison de Berger 1 plan]]
[[ja:村/構造/設計図/砂漠の羊飼いの家1]]
[[zh:村庄/结构/图示/沙漠牧羊人小屋]]
</noinclude>