<noinclude>{{structure info}}</noinclude>

[[File:Snowy Tundra Masons House 1.png|thumb|Masons house 1 (Snowy tundra)]]



==== Blueprint ====

{{layered blueprint
|name=Snowy Masons House 1 snowy_masons_house_1
|default=Layer 3
|S=Snow
|s=Snow Block
|w=Stripped Spruce Log
|p=Spruce Planks
|f=Furnace-rot270
|T=Stonecutter
|o=Spruce Door+bottom
|O=Spruce Door+top
|b=Blue Carpet
|r=Red Carpet
|x=Spruce Stairs
|g=Glass Pane-rot90
|l=Lantern
            
|----Layer 1|
            
 SSSsSSsSsS 
 SSsssssSss 
 SSwwwwwwss 
 SSwSSSSwSS 
 SSwSSSSwSS 
 sSwSSSSwSS 
 SswwwwwwSS 
 ssssppsssS 
 SssSxxSssS 
            
|----Layer 2|
            
    S    s  
  psS  s ps 
  pwwwwwwps 
  pppppppp  
  pppppppp  
 Spppppppp  
  pwwwwwwp  
 spSsxx sp  
  SS     S  
            
|----Layer 3|
            
         S  
  p      ps 
  pwwwwwwp  
  pf brppp  
  pf rbTpp  
  pf brppp  
  pwwoowwp  
  p      p  
            
|----Layer 4|
            
            
  Sp    pSS 
  SpwggwpS  
  Sp    pS  
  Sp    p   
  Sp    pS  
  spwOOwps  
  Sp    pS  
            
|----Layer 5|
            
            
   p    p   
   pwwwwp   
   p    p   
   pl  lp   
   p    p   
  spwwwwpS  
   p    p   
            
|----Layer 6|
            
            
   Sp  pS   
   SpwwpS   
   Sp  pS   
   Sp  pS   
   Sp  pS   
  SspwwpS   
   Sp  pS   
            
|----Layer 7|
            
            
    SppS    
    SppS    
    SppS    
    SppS    
    SppS    
   SSppS    
    SppS    
            
|----Layer 8|
            
            
     SS     
     SS     
     SS     
     SS     
     SS     
     SS     
     SS     
            
}}



==== Materials ====

{| class="wikitable sortable mw-collapsible"
|-
! Name !! Total !! Layer 1 !! Layer 2 !! Layer 3 !! Layer 4 !! Layer 5 !! Layer 6 !! Layer 7 !! Layer 8 
|-
| {{BlockLink|Blue Carpet}} || 3 || - || - || 3 || - || - || - || - || - 
|-
| {{BlockLink|Furnace}} || 3 || - || - || 3 || - || - || - || - || - 
|-
| {{BlockLink|Glass Pane}} || 2 || - || - || - || 2 || - || - || - || - 
|-
| {{BlockLink|Lantern}} || 2 || - || - || - || - || 2 || - || - || - 
|-
| {{BlockLink|Red Carpet}} || 3 || - || - || 3 || - || - || - || - || - 
|-
| {{BlockLink|Snow}} || 190 || 84 || 22 || 1 || 26 || 1 || 23 || 16 || 17 
|-
| {{BlockLink|Snow Block}} || 38 || 25 || 8 || 1 || 2 || 1 || 1 || - || - 
|-
| {{ItemLink|Spruce Door}} || 2 || - || - || 2 || - || - || - || - || - 
|-
| {{BlockLink|Spruce Planks}} || 123 || 2 || 46 || 19 || 14 || 14 || 14 || 14 || - 
|-
| {{BlockLink|Spruce Stairs}} || 4 || 2 || 2 || - || - || - || - || - || - 
|-
| {{BlockLink|Stonecutter}} || 1 || - || - || 1 || - || - || - || - || - 
|-
| {{BlockLink|Stripped Spruce Wood}} || 56 || 18 || 12 || 10 || 4 || 8 || 4 || - || - 
|}<noinclude>
[[Category:Village blueprints]]

[[fr:Village/Structure/Toundra enneigée Maison de Maçon 1 plan]]
[[ja:村/構造/設計図/雪原の石工の家1]]
[[zh:村庄/结构/图示/雪原石匠屋1]]
</noinclude>