<noinclude>{{structure info}}</noinclude>

[[File:Snowy Tundra Armorer House 1.png|thumb|Armorer house 1 (Snowy tundra)]]



==== Blueprint ====

{{layered blueprint
|name=Snowy Armorer House 1 snowy_armorer_house_1
|default=Layer 2
|s=Snow
|t=Torch
|T=Torch-rot180
|d=Diorite
|F=Blast Furnace
|l=Stripped Spruce Log+top
|L=Stripped Spruce Log
|p=Spruce Planks
|c=Chest-rot90
|a=Lantern
|g=Short Grass
|f=Spruce Fence
|A=Diorite Wall
|w=Spruce Stairs
|x=Spruce Stairs-rot90
|y=Spruce Stairs-rot180
|z=Spruce Stairs-rot270
|X=Diorite Stairs-rot90
|Z=Diorite Stairs-rot270
|o=Spruce Door+bottom
|O=Spruce Door+top
         
|----Layer 1|
         
 sssssss 
  LlLlLs 
 sldddls 
 sldddls 
 sllllls 
  llllls 
 sllllls 
 ssswsgs 
         
|----Layer 2|
         
 p     p 
 plLlLlp 
 ptdFdtp 
 p     p 
 p     p 
 p    cp 
 plLoLlp 
 p     p 
         
|----Layer 3|
         
 p     p 
 pLlLlLp 
 p XdZ p 
 p     p 
 p     p 
 p     p 
 plLOLlp 
 p     p 
         
|----Layer 4|
         
  p   p  
  pLlLp  
  p d p  
  p   p  
  p   p  
  p   p  
  plLlp  
  p a p  
         
|----Layer 5|
         
  p   p  
  plLlp  
  p d p  
  p T p  
  p   p  
  p   p  
  plllp  
  p f p  
         
|----Layer 6|
         
   p p   
   plp   
   pdp   
   p p   
   p p   
   p p   
   plp   
   pfp   
         
|----Layer 7|
         
    p    
   ypy   
   xdz   
   wpw   
    p    
    p    
    p    
    p    
         
|----Layer 8|
         
         
         
    A    
         
}}

==== Materials ====

{| class="wikitable sortable mw-collapsible"
|-
! Name !! Total !! Layer 1 !! Layer 2 !! Layer 3 !! Layer 4 !! Layer 5 !! Layer 6 !! Layer 7 !! Layer 8 
|-
| {{BlockLink|Blast Furnace}} || 1 || - || 1 || - || - || - || - || - || - 
|-
| {{BlockLink|Chest}} || 1 || - || 1 || - || - || - || - || - || - 
|-
| {{BlockLink|Diorite}} || 13 || 6 || 2 || 1 || 1 || 1 || 1 || 1 || - 
|-
| {{BlockLink|Diorite Stairs}} || 2 || - || - || 2 || - || - || - || - || - 
|-
| {{BlockLink|Diorite Wall}} || 1 || - || - || - || - || - || - || - || 1 
|-
| {{BlockLink|Short Grass}} || 1 || 1 || - || - || - || - || - || - || - 
|-
| {{BlockLink|Lantern}} || 1 || - || - || - || 1 || - || - || - || - 
|-
| {{BlockLink|Snow}} || 22 || 22 || - || - || - || - || - || - || - 
|-
| {{ItemLink|Spruce Door}} || 1 || - || 1 || || - || - || - || - || - 
|-
| {{BlockLink|Spruce Fence}} || 2 || - || - || - || - || 1 || 1 || - || - 
|-
| {{BlockLink|Spruce Planks}} || 87 || - || 16 || 16 || 16 || 16 || 16 || 7 || - 
|-
| {{BlockLink|Spruce Stairs}} || 7 || 1 || - || - || - || - || - || 6 || - 
|-
| {{BlockLink|Stripped Spruce Log}} || 56 || 24 || 9 || 9 || 6 || 6 || 2 || - || - 
|-
| {{BlockLink|Torch}} || 3 || - || 2 || - || - || 1 || - || - || - 
|}
<noinclude>
[[Category:Village blueprints]]

[[fr:Village/Structure/Toundra enneigée Maison d'Armurier 1 plan]]
[[ja:村/構造/設計図/雪原の防具鍛冶の家1]]
[[zh:村庄/结构/图示/雪原盔甲匠房屋1]]
</noinclude>