<noinclude>{{structure info}}</noinclude>

[[File:Plains animal pen 2.png|thumb|Animal Pen 2 (Plains)]]



==== Blueprint ====

{{layered blueprint
|name=Animal Pen 2 animal_pen_2
|default=Layer 1
|g=Grass Block+top
|f=Oak Fence
|F=Oak Fence Gate
|h=Hay bale+top
|G=Short Grass
|t=Tall Grass+bottom
|T=Tall Grass
|d=Dandelion
             
|----Layer 0|
             
 ggggggggggg 
 ggggggggggg 
 ggggggggggg 
 ggggggggggg 
 ggggggggggg 
 ggggggggggg 
 ggggggggggg 
             
|----Layer 1|
             
 fffffffffff 
 fG   G  G f 
 f  G     Gf 
 fGt    h  f 
 fG  G    df 
 ftG    G tf 
 fffffFfffff 
             
|----Layer 2|
             
             
             
             
   T         
             
  T       T  
             
             
}}



==== Materials ====

{| class="wikitable sortable mw-collapsible"
|-
! Name !! Total !! Layer 0 !! Layer 1 
|-
| {{BlockLink|Dandelion}} || 1 || - || 1 
|-
| {{BlockLink|Short Grass}} || 10 || - || 10 
|-
| {{BlockLink|Grass Block}} || 77 || 77 || - 
|-
| {{BlockLink|Hay Bale}} || 1 || - || 1 
|-
| {{BlockLink|Oak Fence}} || 31 || - || 31 
|-
| {{BlockLink|Oak Fence Gate}} || 1 || - || 1 
|-
| {{BlockLink|Tall Grass}} || 3 || - || 3 
|}

<noinclude>
[[Category:Village blueprints]]

[[fr:Village/Structure/Plaines Enclos 2 plan]]
[[ja:村/構造/設計図/平原の牧柵2]]
[[ko:마을/구조물/청사진/평원/동물 우리 2]]
[[zh:村庄/结构/图示/平原牲畜栏2]]
</noinclude>