<noinclude>{{structure info}}</noinclude>

[[File:Plains Fountain 01.png|thumb|Fountain 01 (Plains)]]



==== Blueprint ====

{{layered blueprint
|name=Fountain 01 fountain_01
|default=Layer 2
|d=Dirt Path+top
|c=Cobblestone
|w=Water+top
|b=Bell
|t=Torch
           
|----Layer 0|
           
  ddddddd  
 ddddddddd 
 ddcccccdd 
 ddcccccdd 
 ddcccccdd 
 ddcccccdd 
 ddcccccdd 
 ddddddddd 
  ddddddd  
           
|----Layer 1|
           
           
           
   tccct   
   c   c   
   c c c   
   c   c   
   tccct   
           
           
           
|----Layer 2|
           
           
           
           
           
   b c     
           
           
           
           
           
|----Layer 3|
           
           
           
           
           
     w     
           
           
           
           
           
}}



==== Materials ====
{| class="wikitable sortable mw-collapsible"
|-
! Name !! Total !! Layer 0 !! Layer 1 !! Layer 2 !! Layer 3 
|-
| {{BlockLink|Bell}} || 1 || - || - || 1 || - 
|-
| {{BlockLink|Cobblestone}} || 39 || 25 || 13 || 1 || - 
|-
| {{BlockLink|Dirt Path}} || 52 || 52 || - || - || - 
|-
| {{BlockLink|Torch}} || 4 || - || 4 || - || - 
|-
| {{BlockLink|Water}} || 1 || - || - || - || 1 
|}

<noinclude>
[[Category:Village blueprints]]

[[fr:Village/Structure/Plaines Fontaine 01 plan]]
[[ja:村/構造/設計図/平原の噴水1]]
[[zh:村庄/结构/图示/平原喷泉]]
</noinclude>