<noinclude>{{structure info}}</noinclude>

[[File:Plains big house 1.png|thumb|Big House 1 (Plains)]]



==== Blueprint ====

{{layered blueprint
|name=Village Plains Houses plains_big_house_
|default=Layer 2
|O=Oak Log+top
|L=Oak Log-rot90
|l=Oak Log
|P=Oak Planks
|d=Oak Door+bottom
|D=Oak Door+top
|C=Cobblestone
|c=Cobblestone Stairs
|t=Torch-rot90
|^=Torch-rot180
|T=Torch-rot270
|G=Glass Pane-rot90
|w=White Bed+top-foot
|W=White Bed+top-head
|m=White Bed+top-foot-rot180
|M=White Bed+top-head-rot180
|b=White Bed+top-foot-rot270
|B=White Bed+top-head-rot270
|U=Chest-rot90
|p=Dirt
|g=Glass Pane
|----Layer 0|
             
             
  ppppppppp  
  pCCCCCCCp  
  pCCCCCCCp  
  pCCCCCCCp  
  ppppCpppp  
             
|----Layer 1|
             
             
  OCCCOCCCO  
  CB CCc  C  
  Cb      C  
  C     wWC  
  OCCCdCCCO  
             
             
|----Layer 2|
             
             
  OCGCOCGCO  
  C  Cc   C  
  g       g  
  C       C  
  OCGCDCGCO  
             
             
|----Layer 3|
             
             
  OCCCOCCCO  
  CCCc    C  
  Ct     TC  
  C       C  
  OCCCCCCCO  
             
             
|----Layer 4|
             
             
  OOOOOOOOO  
  OPc   PPl  
  OPPPPPPPl  
  OPPPPPPPl  
  OLLLLLLLO  
             
             
|----Layer 5|
             
             
  OPPPOPPPO  
  P      UP  
  P       P  
  PMm   wWP  
  OPPPOPPPO  
             
             
|----Layer 6|
             
             
  OPGPOPGPO  
  P   ^   P  
  g       g  
  P       P  
  OPGPOPGPO  
             
             
|----Layer 7|
             
 PPPPPPPPPPP 
  OPPPOPPPO  
  P       P  
  Pt     TP  
  P       P  
  OPPPOPPPO  
 PPPPPPPPPPP 
             
|----Layer 8|
             
             
 PPPPPPPPPPP 
  P       P  
  P       P  
  P       P  
 PPPPPPPPPPP 
             
             
|----Layer 9|
             
             
             
 PPPPPPPPPPP 
  P       P  
 PPPPPPPPPPP 
             
             
             
|----Layer 10|
             
             
             
             
 PPPPPPPPPPP 
             
             
             
             
}}



==== Materials ====

{| class="wikitable sortable mw-collapsible"
|-
! Name !! Total !! Layer 0 !! Layer 1 !! Layer 2 !! Layer 3 !! Layer 4 !! Layer 5 !! Layer 6 !! Layer 7 !! Layer 8 !! Layer 9 !! Layer 10 
|-
| {{BlockLink|Chest}} || 1 || - || - || - || - || - || 1 || - || - || - || - || - 
|-
| {{BlockLink|Cobblestone}} || 76 || 22 || 20 || 13 || 21 || - || - || - || - || - || - || - 
|-
| {{BlockLink|Cobblestone Stairs}} || 4 || - || 1 || 1 || 1 || 1 || - || - || - || - || - || - 
|-
| {{BlockLink|Glass Pane}} || 12 || - || - || 6 || - || - || - || 6 || - || - || - || - 
|-
| {{ItemLink|Oak Door}} || 1 || - || 1 || - || - || - || - || - || - || - || - || - 
|-
| {{BlockLink|Oak Log}} || 57 || - || 5 || 5 || 5 || 24 || 6 || 6 || 6 || - || - || - 
|-
| {{BlockLink|Oak Planks}} || 150 || - || - || - || - || 17 || 18 || 12 || 40 || 28 || 24 || 11 
|-
| {{BlockLink|Torch}} || 5 || - || - || - || 2 || - || - || 1 || 2 || - || - || - 
|-
| {{BlockLink|White Bed}} || 4 || - || 2 || - || - || - || 2 || - || - || - || - || - 
|}

<noinclude>
[[Category:Village blueprints]]

[[fr:Village/Structure/Plaines Grande Maison 1 plan]]
[[ja:村/構造/設計図/平原の大きな家1]]
[[zh:村庄/结构/图示/平原大型房屋]]
</noinclude>