<noinclude>{{structure info}}</noinclude>

[[File:Savanna Weaponsmith 2.png|thumb|Weaponsmith 2 (Savanna)]]



==== Blueprint ====

{{layered blueprint|name=
Savanna Weaponsmith 2|default=Layer 1
|D=Dirt
|A=Acacia Wood
|S=Smooth Stone
|C=Acacia Planks
|G=Grass Block+top
|I=Acacia Log
|L=Acacia Log+top
|H=Chest-rot-180
|R=Short Grass
|M=Smooth Stone Slab
|T=Acacia Stairs
|O=Iron Bars
|V=Lava
|N=Grindstone
|P=Glass Pane-rot-90
|W=Wall Torch-rot-180
|c=Acacia Door+bottom
|a=Acacia Door+top
|F=Acacia Fence
|E=Acacia Pressure Plate
|l=Wall Torch
|s=Glass Pane
               
|----Layer 1|
               
 RRRR          
   DDDDDDDDD   
  DDDDDDDDDDD  
  DDDDDDDDDDD  
   DDDDDDDDDD  
   DDDDDDDDDD  
   DDDDDDDDDD  
     GDDDGDD   
     GGDGG     
               
|----Layer 2|
               
               
   AAAAAAAAA   
  ASSSCCCCCCA  
  ASSSCCCCCCA  
   SSSAAACCCA  
   SSSSSSACCA  
   SSSSSSACCA  
     MSSSMAA   
     MMMMM     
               
|----Layer 3|
               
               
   AAAAAAAAA   
  A      TFTA  
  A N       A  
   SSSAcA   A  
   SVS   A  A  
   SSS N AH A  
          AA   
               
               
|----Layer 4|
               
               
   AAPAAAPAA   
  A       E A  
  S         A  
   SSSSaL   s  
   O     A  A  
   OOO   A  A  
          AAW  
               
               
|----Layer 5|
               
               
   AAAAAAAAA   
  A  W   W  A  
  S         A  
   SSSSIL   A  
   O   W A  A  
   OOO   Al A  
          AA   
               
               
|----Layer 6|
               
  TTTTTTTTTTT  
 TCCCCCCCCCCCT 
 TC         CT 
 MS         CT 
 MSSSSSCCC  CT 
  MMMMMTTC  CT 
   MMM  TC  CT 
        TCCCCT 
         TTTT  
               
|----Layer 7|
               
               
  TTTTTTTTTTT  
  TCCCCCCCCCT  
  TCCCCCCCCCT  
  TTTTTTTTCCT  
         TCCT  
         TCCT  
         TTTT  
               
               
}}



==== Materials ====

{| class="wikitable sortable mw-collapsible"
|-
! Name !! Total !! Layer 1 !! Layer 2 !! Layer 3 !! Layer 4 !! Layer 5 !! Layer 6 !! Layer 7 
|-
| {{BlockLink|Acacia Door}} || 1 || - || - || 1 || - || - || - || - 
|-
| {{BlockLink|Acacia Fence}} || 1 || - || - || 1 || - || - || - || - 
|-
| {{BlockLink|Acacia Log}} || 81 || - || 23 || 22 || 16 || 20 || - || - 
|-
| {{BlockLink|Acacia Planks}} || 69 || - || 19 || - || - || - || 26 || 24 
|-
| {{BlockLink|Acacia Pressure Plate}} || 1 || - || - || - || 1 || - || - || - 
|-
| {{BlockLink|Acacia Stairs}} || 62 || - || - || 2 || - || - || 28 || 32 
|-
| {{BlockLink|Chest}} || 1 || - || - || 1 || - || - || - || - 
|-
| {{BlockLink|Dirt}} || 67 || 67 || - || - || - || - || - || - 
|-
| {{BlockLink|Glass Pane}} || 3 || - || - || - || 3 || - || - || - 
|-
| {{BlockLink|Short Grass}} || 4 || 4 || - || - || - || - || - || - 
|-
| {{BlockLink|Grass Block}} || 6 || 6 || - || - || - || - || - || - 
|-
| {{BlockLink|Grindstone}} || 2 || - || - || 2 || - || - || - || - 
|-
| {{BlockLink|Iron Bars}} || 8 || - || - || - || 4 || 4 || - || - 
|-
| {{BlockLink|Lava}} || 1 || - || - || 1 || - || - || - || - 
|-
| {{BlockLink|Smooth Stone}} || 48 || - || 24 || 8 || 5 || 5 || 6 || - 
|-
| {{BlockLink|Smooth Stone Slab}} || 17 || - || 7 || - || - || - || 10 || - 
|-
| {{BlockLink|Torch}} || 5 || - || - || - || 1 || 4 || - || - 
|}<noinclude>
[[Category:Village blueprints]]

[[fr:Village/Structure/Savane Forge d'Armes 2 plan]]
[[ja:村/構造/設計図/サバンナの武器鍛冶場2]]
[[zh:村庄/结构/图示/热带草原铁匠铺2]]
</noinclude>