<noinclude>{{structure info}}</noinclude>

[[File:Plains Meeting Point 3.png|thumb|Meeting Point 3 (Plains)]]



==== Blueprint ====

{{layered blueprint
|name=Meeting Point 3 meeting_point_3
|default=Layer 3
|p=Dirt Path+top
|g=Grass Block+top
|G=Short Grass
|c=Cobblestone
|d=Dirt
|o=Oak Log+top
|D=Dandelion
|l=Oak Leaves
|t=Torch
|T=Torch-rot180
|r=Torch-rot90
|R=Torch-rot270
|f=Oak Fence
|B=Bell+ceiling
|C=Cobblestone Stairs
|s=Cobblestone Stairs-rot90
|b=Cobblestone Stairs-rot180
|S=Cobblestone Stairs-rot270
             
|----Layer 0|
             
 ggcgpcgpggg 
 pgpcgpcgpcg 
 pcppcpgcgpg 
 gpcgppgpggc 
 ggpcdddppcg 
 pccpdddcgpp 
 cpcgdddpcgp 
 gpgccpccgpg 
 pgppgccgcpg 
 cpcggcgcpgp 
 gpppgppgggg 
             
|----Layer 1|
             
    G        
     f f     
       G G   
       G     
  G  sbb     
     soS G   
    GCCC     
 G         G 
  G  G       
    Df f     
        GG G 
             
|----Layer 2|
             
             
     f f     
             
             
             
      o      
             
             
             
     f f     
             
             
|----Layer 3|
             
             
     fBf     
             
             
      t      
     Ror     
      T      
             
             
     fBf     
             
             
|----Layer 4|
             
             
     fcf     
             
             
             
      o      
             
             
             
     fcf     
             
             
|----Layer 5|
             
             
             
             
      l      
    lllll    
    lloll    
    lllll    
      ll     
             
             
             
             
|----Layer 6|
             
             
             
             
     l l     
    lllll    
    lloll    
    lllll    
     lll     
             
             
             
             
|----Layer 7|
             
             
             
             
             
     lll     
     lol     
     lll     
             
             
             
             
             
|----Layer 8|
             
             
             
             
             
      l      
     lll     
      l      
             
             
             
             
             
}}

The oak tree in this structure is always the same. The bells in layer 3 hang beneath the cobblestone above them.



==== Materials ====

{| class="wikitable sortable mw-collapsible"
|-
! Name !! Total !! Layer 0 !! Layer 1 !! Layer 2 !! Layer 3 !! Layer 4 !! Layer 5 !! Layer 6 !! Layer 7 !! Layer 8 
|-
| {{BlockLink|Bell}} || 2 || - || - || - || 2 || - || - || - || - || - 
|-
| {{BlockLink|Cobblestone}} || 31 || 29 || - || - || - || 2 || - || - || - || - 
|-
| {{BlockLink|Cobblestone Stairs}} || 8 || - || 8 || - || - || - || - || - || - || - 
|-
| {{BlockLink|Dandelion}} || 1 || - || 1 || - || - || - || - || - || - || - 
|-
| {{BlockLink|Dirt}} || 9 || 9 || - || - || - || - || - || - || - || - 
|-
| {{BlockLink|Dirt Path}} || 38 || 38 || - || - || - || - || - || - || - || - 
|-
| {{BlockLink|Short Grass}} || 14 || - || 14 || - || - || - || - || - || - || - 
|-
| {{BlockLink|Grass Block}} || 43 || 43 || - || - || - || - || - || - || - || - 
|-
| {{BlockLink|Oak Fence}} || 16 || - || 4 || 4 || 4 || 4 || - || - || - || - 
|-
| {{BlockLink|Oak Leaves}} || 49 || - || - || - || - || - || 17 || 19 || 8 || 5 
|-
| {{BlockLink|Oak Log}} || 7 || - || 1 || 1 || 1 || 1 || 1 || 1 || 1 || - 
|-
| {{BlockLink|Torch}} || 4 || - || - || - || 4 || - || - || - || - || - 
|}<noinclude>
[[Category:Village blueprints]]

[[fr:Village/Structure/Plaines Lieu de Rassemblement 3 plan]]
[[ja:村/構造/設計図/平原の集会所3]]
[[zh:村庄/结构/图示/平原会合点3]]
</noinclude>