<noinclude>{{structure info}}</noinclude>

[[File:Plains Animal Pen 3.png|thumb|Animal Pen 3 (Plains)]]



==== Blueprint ====

{{layered blueprint
|name=Animal Pen 3 animal_pen_3
|default=Layer 1
|g=Grass Block+top
|f=Oak Fence
|F=Oak Fence Gate
|w=Water+top
|t=Torch
             
|----Layer 0|
             
 ggggggggggg 
 gggggggwggg 
 ggggggwwwgg 
 gggggggwggg 
 ggggggggggg 
 ggggggggggg 
 ggggggggggg 
 ggggggggggg 
             
|----Layer 1|
             
    ffffffff 
 ffff      f 
 f         f 
 f         f 
 f       fff 
 fff     f   
   f     f   
   fffFfff   
             
|----Layer 2|
             
             
             
             
             
             
             
             
     t t     
             
}}



==== Materials ====

{| class="wikitable sortable mw-collapsible"
|-
! Name !! Total !! Layer 0 !! Layer 1 !! Layer 2
|-
| {{BlockLink|Grass Block}} || 83 || 83 || - || - 
|-
| {{BlockLink|Oak Fence}} || 33 || - || 33 || - 
|-
| {{BlockLink|Oak Fence Gate}} || 1 || - || 1 || - 
|-
| {{BlockLink|Torch}} || 2 || - || - || 2 
|-
| {{BlockLink|Water}} || 5 || 5 || - || - 
|}

<noinclude>
[[Category:Village blueprints]]

[[fr:Village/Structure/Plaines Enclos 3 plan]]
[[ja:村/構造/設計図/平原の牧柵3]]
[[ko:마을/구조물/청사진/동물 우리 3]]
[[zh:村庄/结构/图示/平原牲畜栏3]]
</noinclude>