<noinclude>{{structure info}}</noinclude>

[[File:Desert Temple 1.png|thumb|Temple 1 (Desert)]]



==== Blueprint ====

{{layered blueprint|name=Desert Temple 1
|default=Layer 1
|C=Cut Sandstone
|S=Smooth Sandstone
|W=White Glazed Terracotta-rot-180
|X=White Glazed Terracotta-rot-90
|Y=White Glazed Terracotta-rot-270
|Z=White Glazed Terracotta
|B=Brewing Stand
|H=Chest-rot-180
|P=Potted Cactus
|A=Sandstone Slab+top
|a=Sandstone Slab+bottom
|m=Smooth Sandstone Slab+bottom
|L=Wall Torch-rot-270
|T=Wall Torch-rot-180
|O=Smooth Sandstone Stairs
|N=Smooth Sandstone Stairs-rot-180
|R=Wall Torch-rot-90
            
|----Layer 0|
            
 CCC    CCC 
 CSSCCCCSSC 
 CSSSSSSSSC 
  CSSSSSSC  
  CSSWXSSC  
  CSSYZSSC  
  CSSSSSSC  
  CSSOOSSC  
 CSSSmmSSSC 
 CSSCmmCSSC 
 CCC    CCC 
            
|----Layer 1|
            
 SSS    SSS 
 S  SSSS  S 
 S        S 
  S      S  
  S      S  
  S      S  
  S      S  
  S      S  
 S        S 
 SB S  S HS 
 SSS    SSS 
            
|----Layer 2|
            
 SPS    SPS 
 P  SSSS  P 
 S   TT   S 
  S      S  
  SL    RS  
  S      S  
  SL    RS  
  S      S  
 S        S 
 P  SNNS  P 
 SPST  TSPS 
            
|----Layer 3|
            
 SAS    SAS 
 A  SSSS  A 
 S        S 
  S      S  
  S      S  
  S      S  
  S      S  
  S      S  
 S        S 
 A  SSSS    
 SAS    SAS 
            
|----Layer 4|
            
 SSS    SSS 
 S SaaaaS S 
 SSSaaaaSSS 
  aaaaaaaa  
  aamaamaa  
  aaammaaa  
  aamaamaa  
  aaaaaaaa  
 SSSaaaaSSS 
 S SaaaaS S 
 SSS    SSS 
            
|----Layer 5|
            
 SmS    SmS 
 mam    mam 
 SmS    SmS 
            
            
            
            
            
 SmS    SmS 
 mam    mam 
 SmS    SmS 
            
|----Layer 6|
            
 a a    a a 
            
 a a    a a 
            
            
            
            
            
 a a    a a 
            
 a a    a a 
            
}}

This temple has a castle-like look.



==== Materials ====

{| class="wikitable sortable mw-collapsible"
|-
! Name !! Total !! Layer 0 !! Layer 1 !! Layer 2 !! Layer 3 !! Layer 4 !! Layer 5 !! Layer 6 
|-
| {{BlockLink|Brewing Stand}} || 1 || - || 1 || - || - || - || - || - 
|-
| {{BlockLink|Chest}} || 1 || - || 1 || - || - || - || - || - 
|-
| {{BlockLink|Cut Sandstone}} || 36 || 36 || - || - || - || - || - || - 
|-
| {{BlockLink|Potted Cactus}} || 8 || - || - || 8 || - || - || - || - 
|-
| {{BlockLink|Sandstone Slab}} || 81 || - || - || - || 7 || 54 || 4 || 16 
|-
| {{BlockLink|Smooth Sandstone}} || 188 || 46 || 36 || 28 || 30 || 32 || 16 || - 
|-
| {{BlockLink|Smooth Sandstone Slab}} || 26 || 4 || - || - || - || 6 || 16 || - 
|-
| {{BlockLink|Smooth Sandstone Stairs}} || 4 || 2 || - || 2 || - || - || - || - 
|-
| {{BlockLink|Torch}} || 8 || - || - || 8 || - || - || - || - 
|-
| {{BlockLink|White Glazed Terracotta}} || 4 || 4 || - || - || - || - || - || - 
|}<noinclude>
[[Category:Village blueprints]]

[[fr:Village/Structure/Désert Temple 1 plan]]
[[ja:村/構造/設計図/砂漠の礼拝所1]]
[[zh:村庄/结构/图示/沙漠教堂1]]
</noinclude>