<noinclude>{{structure info}}</noinclude>

[[File:Desert Small House 6.png|thumb|Small house 6 (Desert)]]



==== Blueprint ====

{{layered blueprint
|name=Desert Small House 6 desert_small_house_6
|default=Layer 1
|a=Sand
|s=Smooth Sandstone
|C=Chest
|j=Jungle Door+up+left
|J=Jungle Door+top
|c=Cut Sandstone
|G=Green Bed+Top+Head
|g=Green Bed+Top+Foot
|w=Smooth Sandstone Stairs
|x=Smooth Sandstone Stairs-rot90
|y=Smooth Sandstone Stairs-rot180
|z=Smooth Sandstone Stairs-rot270
|W=Torch
|X=Torch-rot90
|Y=Torch-rot180
|Z=Torch-rot270
       
|----Layer 0|
       
 aaaaa 
 aaaaa 
 asssa 
 asssa 
 aasaa 
 aasaa 
       
|----Layer 1|
       
 csssc 
 sssss 
 swgGs 
 s   s 
 csjsc 
       
|----Layer 2|
       
 csssc 
 s xss 
 s   s 
 sW  s 
 csJsc 
       
|----Layer 3|
       
 csssc 
 s   s 
 s  ys 
 s  ss 
 cscsc 
   Y   
       
|----Layer 4|
       
 csssc 
 s  Ys 
 s   s 
 ssz s 
 csssc 
       
|----Layer 5|
       
 csssc 
 ss  s 
 sws s 
 s   s 
 cs sc 
       
|----Layer 6|
       
 csssc 
 s xss 
 s   s 
 s   s 
 csssc 
       
|----Layer 7|
       
 csssc 
 sX  s 
 s  ys 
 s  ss 
 cscsc 
       
|----Layer 8|
       
 csssc 
 s   s 
 s   s 
 ssz s 
 csssc 
       
|----Layer 9|
       
 csssc 
 ss  s 
 sw  s 
 s  Zs 
 cs sc 
       
|----Layer 10|
       
 csssc 
 s xss 
 s   s 
 s   s 
 csssc 
       
|----Layer 11|
       
 csssc 
 s   s 
 s  ys 
 s  ss 
 cscsc 
       
|----Layer 12|
       
 csssc 
 s  Zs 
 s s s 
 ssz s 
 csssc 
       
|----Layer 13|
       
 csssc 
 ss  s 
 swC s 
 s   s 
 cs sc 
       
|----Layer 14|
       
 csssc 
 s x s 
 s   s 
 s   s 
 csssc 
       
|----Layer 15|
       
 ccccc 
 c  xc 
 c ccc 
 c ccc 
 ccccc 
       
|----Layer 16|
       
 c c c 
      
 c   c
      
 c c c 
       
|----Layer 17|
       
 W   W
      
      
      
 W   W 
       
}}



==== Materials ====

{| class="wikitable sortable mw-collapsible"
|-
! Name !! Total !! Layer 0 !! Layer 1 !! Layer 2 !! Layer 3 !! Layer 4 !! Layer 5 !! Layer 6 !! Layer 7 !! Layer 8 !! Layer 9 !! Layer 10 !! Layer 11 !! Layer 12 !! Layer 13 !! Layer 14 !! Layer 15 !! Layer 16 !! Layer 17 
|-
| {{BlockLink|Chest}} || 1 || - || - || - || - || - || - || - || - || - || - || - || - || - || 1 || - || - || - || - 
|-
| {{BlockLink|Cut Sandstone}} || 87 || - || 4 || 4 || 5 || 4 || 4 || 4 || 5 || 4 || 4 || 4 || 5 || 4 || 4 || 4 || 20 || 8 || - 
|-
| {{BlockLink|Green Bed}} || 1 || - || 1 || - || - || - || - || - || - || - || - || - || - || - || - || - || - || - || - 
|-
| {{ItemLink|Jungle Door}} || 1 || - || 1 || - || - || - || - || - || - || - || - || - || - || - || - || - || - || - || - 
|-
| {{BlockLink|Sand}} || 22 || 22 || - || - || - || - || - || - || - || - || - || - || - || - || - || - || - || - || - 
|-
| {{BlockLink|Smooth Sandstone}} || 185 || 8 || 14 || 12 || 12 || 13 || 13 || 13 || 12 || 13 || 12 || 13 || 12 || 14 || 12 || 12 || - || - || - 
|-
| {{BlockLink|Smooth Sandstone Stairs}} || 15 || - || 1 || 1 || 1 || 1 || 1 || 1 || 1 || 1 || 1 || 1 || 1 || 1 || 1 || 1 || 1 || - || - 
|-
| {{BlockLink|Torch}} || 10 || - || - || 1 || 1 || 1 || - || - || 1 || - || 1 || - || - || 1 || - || - || - || - || 4 
|}<noinclude>
[[Category:Village blueprints]]

[[fr:Village/Structure/Désert Petite Maison 6 plan]]
[[ja:村/構造/設計図/砂漠の小さな家6]]
[[zh:村庄/结构/图示/沙漠小型房屋6]]
</noinclude>