<noinclude>{{structure info}}</noinclude>

[[File:Taiga Shepherds House 1.png|thumb|Shepherds House 1 (Taiga)]]



==== Blueprint ====

{{layered blueprint|name=
Taiga Shepherds House 1|default=Layer 1
|S=Spruce Log
|D=Dirt
|P=Spruce Log+top
|C=Cobblestone
|R=Spruce Planks
|L=Loom
|U=Spruce Log-rot-90
|G=Grass Block+top
|E=Spruce Fence
|T=Spruce Trapdoor
|O=Torch
|A=Dirt Path+top
|B=Cobblestone Stairs
|p=Spruce Door+bottom
|r=Spruce Door+top
|N=Glass Pane-rot-90
|W=Wall Torch-rot-180
|u=Purple Carpet
|H=White Carpet
|a=Wall Torch-rot-90
|l=Wall Torch-rot-270
|c=Spruce Pressure Plate
             
|----Layer 1|
             
   DDDDDDD   
 G DDDDDDD   
   DDDDDDD   
   DDDDDDD   
  DDDDDDDDD  
  DDDDDDDDD  
  DDDDDDDDD  
  DDDDDDDDD  
  D G D G D  
    A   A    
             
|----Layer 2|
             
   CCCCCCC   
   CGGGGGC   
   CGGGGGC   
   CGGGGGC   
  CCCCCCCCC  
  CRRRRRRRC  
  CRRRRRRRC  
  CCCCCCCCC  
  P B P B P  
             
             
|----Layer 3|
             
   EEEEEEE   
   E     E   
   E     E   
   E     E   
  CCCCpCCCC  
  CL HuH EC  
  CL uHu EC  
  CCpCCCpCC  
  P   P   P  
             
             
|----Layer 4|
             
   O     O   
             
             
 S T T T T S 
 SRRNRrRNRRS 
 SR      cRS 
 SR      cRS 
 SRRrRRRrRRS 
 SP   P   PS 
 S         S 
             
|----Layer 5|
             
             
             
             
  S   S   S  
  SRRRSRRRS  
  S   S   S  
  S  aSl  S  
  SRRRSRRRS  
  SUUUSUUUS  
  S   S   S  
             
|----Layer 6|
             
             
             
             
   S S S S   
   SRS SRS   
   S S S S   
   S S S S   
   SRS SRS   
   SWS SWS   
   S S S S   
             
|----Layer 7|
             
             
             
             
    S   S    
    S   S    
    S   S    
    S   S    
    S   S    
    S   S    
    S   S    
             
}}



==== Materials ====

{| class="wikitable sortable mw-collapsible"
|-
! Name !! Total !! Layer 1 !! Layer 2 !! Layer 3 !! Layer 4 !! Layer 5 !! Layer 6 !! Layer 7 
|-
| {{BlockLink|Cobblestone}} || 54 || - || 35 || 19 || - || - || - || - 
|-
| {{BlockLink|Cobblestone Stairs}} || 2 || - || 2 || - || - || - || - || - 
|-
| {{BlockLink|Dirt}} || 67 || 67 || - || - || - || - || - || - 
|-
| {{BlockLink|Glass Pane}} || 2 || - || - || - || 2 || - || - || - 
|-
| {{BlockLink|Grass Block}} || 18 || 3 || 15 || - || - || - || - || - 
|-
| {{BlockLink|Dirt Path}} || 2 || 2 || - || - || - || - || - || - 
|-
| {{BlockLink|Loom}} || 2 || - || - || 2 || - || - || - || - 
|-
| {{BlockLink|Purple Carpet}} || 3 || - || - || 3 || - || - || - || - 
|-
| {{BlockLink|Spruce Door}} || 3 || - || - || 3 || - || - || - || - 
|-
| {{BlockLink|Spruce Fence}} || 15 || - || - || 15 || - || - || - || - 
|-
| {{BlockLink|Spruce Log}} || 92 || - || 3 || 3 || 17 || 27 || 28 || 14 
|-
| {{BlockLink|Spruce Planks}} || 47 || - || 14 || - || 17 || 12 || 4 || - 
|-
| {{BlockLink|Spruce Pressure Plate}} || 2 || - || - || - || 2 || - || - || - 
|-
| {{BlockLink|Spruce Trapdoor}} || 4 || - || - || - || 4 || - || - || - 
|-
| {{BlockLink|Torch}} || 6 || - || - || - || 2 || 2 || 2 || - 
|-
| {{BlockLink|White Carpet}} || 3 || - || - || 3 || - || - || - || - 
|}<noinclude>
[[Category:Village blueprints]]

[[fr:Village/Structure/Taïga Maison de Berger 1 plan]]
[[zh:村庄/结构/图示/针叶林牧羊人小屋]]
</noinclude>