<noinclude>{{structure info}}</noinclude>

[[File:Snowy Tundra Small House 3.png|thumb|Small house 3 (Snowy tundra)]]



==== Blueprint ====

{{layered blueprint
|name=Snowy Small House 3 snowy_small_house_3
|default=Layer 2
|w=Stripped Spruce Wood
|p=Spruce Planks
|s=Snow
|S=Snow Block
|x=Spruce Stairs
|y=Spruce Stairs-rot90
|z=Spruce Stairs-rot270
|d=Spruce Door+bottom
|D=Spruce Door+top
|b=Blue Bed+top-head-rot270
|B=Blue Bed+top-foot-rot270
|F=Furnace-rot90
|t=Torch
|l=Lantern
|f=Spruce Fence
|a=Spruce Slab
         
|----Layer 1|
         
 p    p  
 pwwwwp  
 pppppp  
 pppppp  
 pwwwwpS 
 p xxSpS 
      S  
         
|----Layer 2|
         
 p    p  
 pwwwwp  
 ppb Fp  
 ppB Fp  
 pwddwpS 
 ps  sps 
      s  
         
|----Layer 3|
         
 yp  pz  
 ypwwpz  
 sp  ps  
 sp  ps  
 ywDDwzs 
 yz  yz  
  l  l   
         
|----Layer 4|
         
  p  p   
  pwwp   
  p  p   
  pttp   
  pwwp   
  p  p   
  f  f   
         
|----Layer 5|
         
  yppz   
  yppz   
  spps   
  spps   
  ywwz   
  yzyz   
         
|----Layer 6|
         
   aa    
   aa    
   aa    
   aa    
   aa    
   aa    
         
}}

All spruce slabs are bottom slabs.



==== Materials ====

{| class="wikitable sortable mw-collapsible"
|-
! Name !! Total !! Layer 1 !! Layer 2 !! Layer 3 !! Layer 4 !! Layer 5 !! Layer 6 
|-
| {{BlockLink|Blue Bed}} || 1 || - || 1 || - || - || - || - 
|-
| {{BlockLink|Furnace}} || 2 || - || 2 || - || - || - || - 
|-
| {{BlockLink|Lantern}} || 2 || - || - || 2 || - || - || - 
|-
| {{BlockLink|Snow}} || 25 || - || 9 || 9 || - || 7 || - 
|-
| {{BlockLink|Snow Block}} || 5 || 4 || 1 || - || - || - || - 
|-
| {{ItemLink|Spruce Door}} || 2 || - || 2 || - || - || - || - 
|-
| {{BlockLink|Spruce Fence}} || 2 || - || - || - || 2 || - || - 
|-
| {{BlockLink|Spruce Planks}} || 62 || 20 || 14 || 8 || 12 || 8 || - 
|-
| {{BlockLink|Spruce Slab}} || 12 || - || - || - || - || - || 12 
|-
| {{BlockLink|Spruce Stairs}} || 22 || 2 || - || 10 || - || 10 || - 
|-
| {{BlockLink|Stripped Spruce Wood}} || 24 || 8 || 6 || 4 || 4 || 2 || - 
|-
| {{BlockLink|Torch}} || 2 || - || - || - || 2 || - || - 
|}<noinclude>
[[Category:Village blueprints]]

[[fr:Village/Structure/Toundra enneigée Petite Maison 3 plan]]
[[ja:村/構造/設計図/雪原の小さな家3]]
[[zh:村庄/结构/图示/雪原小型房屋3]]
</noinclude>