<noinclude>{{structure info}}</noinclude>

[[File:Plains Cartographer 1.png|thumb|Cartographer 1 (Plains)]]



==== Blueprint ====

{{layered blueprint
|name=Cartographer House
|default=Layer 1
|d=Dirt
|D=Dirt Path+top
|G=Grass Block+top
|C=Cobblestone
|O=Oak Log+top
|P=Oak Planks
|L=Oak Stairs
|F=Oak Stairs-rot90
|Z=Oak Stairs-rot180
|>=Oak Stairs-rot270
|N=Oak Slab
|E=Oak Trapdoor
|H=Oak Fence
|U=Oak Pressure Plate
|z=Oak Door+top
|B=Oak Door+bottom
|I=Glass Pane
|t=Glass Pane-rot90
|R=White Carpet
|r=Yellow Carpet
|i=Torch
|o=Torch-rot180
|p=Poppy
|b=Dandelion
|c=Chest-rot90
|T=Cartography Table
         
|----Layer 0|
         
         
  ddddd  
  dPPPd  
  dPPPd  
  dPPPd  
  dPPPd  
  dPPPd  
  ddCdd  
  ddDdd  
    D    
         
|----Layer 1|
         
         
  OCCCO  
  CrRrC  
  CRTRC  
  CrRrC  
  C   C  
  CH cC  
  OCBCO  
 EGG GGE 
  EE EE  
         
|----Layer 2|
         
         
  OCtCO  
  C   C  
  I   I  
  C   C  
  I   I  
  CU  C  
  OCzCO  
  bp bp  
         
         
|----Layer 3|
         
         
  OCCCO  
  C   C  
  C   C  
  C   C  
  C   C  
  C   C  
  OCCCO  
         
         
         
|----Layer 4|
         
 ZL   ZL 
 ZOOOOOL 
 ZO o OL 
 ZO   OL 
 ZO   OL 
 ZO   OL 
 ZO i OL 
 ZOOOOOL 
 ZL o ZL 
         
         
|----Layer 5|
         
  ZL ZL  
  ZCCCL  
  Z   L  
  Z   L  
  Z   L  
  Z   L  
  Z   L  
  ZCCCL  
  ZL ZL  
         
         
|----Layer 6|
         
   ZPL   
   ZPL   
   ZPL   
   ZPL   
   ZPL   
   ZPL   
   ZPL   
   ZPL   
   ZPL   
         
         
|----Layer 7|
         
    N    
    N    
    N    
    N    
    N    
    N    
    N    
    N    
    N    
         
}}



==== Materials ====

{| class="wikitable sortable mw-collapsible"
|-
! Name !! Total !! Layer 0 !! Layer 1 !! Layer 2 !! Layer 3 !! Layer 4 !! Layer 5 !! Layer 6 !! Layer 7 
|-
| {{BlockLink|Cartography Table}} || 1 || - || 1 || - || - || - || - || - || - 
|-
| {{BlockLink|Chest}} || 1 || - || 1 || - || - || - || - || - || - 
|-
| {{BlockLink|Cobblestone}} || 48 || 1 || 15 || 10 || 16 || - || 6 || - || - 
|-
| {{BlockLink|Dandelion}} || 2 || - || - || 2 || - || - || - || - || - 
|-
| {{BlockLink|Dirt}} || 23 || 23 || - || - || - || - || - || - || - 
|-
| {{BlockLink|Dirt Path}} || 2 || 2 || - || - || - || - || - || - || - 
|-
| {{BlockLink|Glass Pane}} || 5 || - || - || 5 || - || - || - || - || - 
|-
| {{BlockLink|Grass Block}} || 4 || - || 4 || - || - || - || - || - || - 
|-
| {{ItemLink|Oak Door}} || 1 || - || 1 || - || - || - || - || - || - 
|-
| {{BlockLink|Oak Fence}} || 1 || - || 1 || - || - || - || - || - || - 
|-
| {{BlockLink|Oak Log}} || 32 || - || 4 || 4 || 4 || 20 || - || - || - 
|-
| {{BlockLink|Oak Planks}} || 24 || 15 || - || - || - || - || - || 9 || - 
|-
| {{BlockLink|Oak Pressure Plate}} || 1 || - || - || 1 || - || - || - || - || - 
|-
| {{BlockLink|Oak Slab}} || 9 || - || - || - || - || - || - || - || 9 
|-
| {{BlockLink|Oak Stairs}} || 62 || - || - || - || - || 22 || 22 || 18 || - 
|-
| {{BlockLink|Oak Trapdoor}} || 6 || - || 6 || - || - || - || - || - || - 
|-
| {{BlockLink|Poppy}} || 2 || - || - || 2 || - || - || - || - || - 
|-
| {{BlockLink|Torch}} || 3 || - || - || - || - || 3 || - || - || - 
|-
| {{BlockLink|White Carpet}} || 4 || - || 4 || - || - || - || - || - || - 
|-
| {{BlockLink|Yellow Carpet}} || 4 || - || 4 || - || - || - || - || - || - 
|}

<noinclude>
[[Category:Village blueprints]]

[[fr:Village/Structure/Plaines Cartographe 1 plan]]
[[ja:村/構造/設計図/平原の製図所1]]
[[zh:村庄/结构/图示/平原制图师房屋]]
</noinclude>