<noinclude>{{structure info}}</noinclude>

[[File:Taiga Medium House 4.png|thumb|Medium House 4 (Taiga)]]



==== Blueprint ====

{{layered blueprint|name=
Taiga Medium House 4|default=Layer 1
|S=Spruce Log-rot-90
|D=Dirt
|P=Spruce Log+top
|C=Cobblestone
|R=Spruce Log
|U=Spruce Planks
|L=Purple Bed+top+head-rot-270
|E=Purple Bed+top+foot-rot-270
|B=Purple Bed+top+foot-rot-90
|u=Purple Bed+top+head-rot-90
|F=Furnace
|A=Campfire
|T=Spruce Trapdoor
|W=Wall Torch-rot-90
|G=Glass Pane
|O=Cobblestone Stairs-rot-180
|N=Cobblestone Stairs
|H=Wall Torch-rot-180
|a=Wall Torch
|I=Spruce Stairs
|l=Wall Torch-rot-270
|p=Spruce Door+bottom
|r=Spruce Door+top
|s=Dirt Path+top
           
|----Layer 1|
           
           
  DDDDDDD  
  DUUUUUD  
  DUUUUUD  
  DUUDCUCs 
  DUUUUUD  
  DUUUUUD  
  DDDDDDD  
           
           
|----Layer 2|
           
           
  PCCCCCP  
  Cu  IIC  
  CB T  C  
  CUTF  p  
  CE T  C  
  CL  IIC  
  PCCCCCP  
           
           
|----Layer 3|
           
 SSSSSSSSS 
  PCCCCCP  
 TC     C  
  G  a  C  
 TC  Cl r  
  G  H  C  
 TC     C  
  PCCCCCP  
 SSSSSSSSS 
           
|----Layer 4|
           
           
 SSSSSSSSS 
  R     P  
  C     C  
  C  C  C  
  C     C  
  R     P  
 SSSSSSSSS 
           
           
|----Layer 5|
           
           
           
 SSSSSSSSS 
  R OOO R  
 WR OAO Rl 
  R OOO R  
 SSSSSSSSS 
           
           
           
|----Layer 6|
           
           
           
           
 SSSCCCSSS 
 SSSC CSSS 
 SSSCCCSSS 
           
           
           
           
|----Layer 7|
           
           
           
           
    NNN    
    N N    
    NNN    
           
           
           
           
}}



==== Materials ====

{| class="wikitable sortable mw-collapsible"
|-
! Name !! Total !! Layer 1 !! Layer 2 !! Layer 3 !! Layer 4 !! Layer 5 !! Layer 6 !! Layer 7 
|-
| {{BlockLink|Campfire}} || 1 || - || - || - || - || 1 || - || - 
|-
| {{BlockLink|Cobblestone}} || 54 || 2 || 19 || 18 || 7 || - || 8 || - 
|-
| {{BlockLink|Cobblestone Stairs}} || 16 || - || - || - || - || 8 || - || 8 
|-
| {{BlockLink|Dirt}} || 24 || 24 || - || - || - || - || - || - 
|-
| {{BlockLink|Furnace}} || 1 || - || 1 || - || - || - || - || - 
|-
| {{BlockLink|Glass Pane}} || 2 || - || - || 2 || - || - || - || - 
|-
| {{BlockLink|Dirt Path}} || 1 || 1 || - || - || - || - || - || - 
|-
| {{BlockLink|Purple Bed}} || 2 || - || 2 || - || - || - || - || - 
|-
| {{BlockLink|Spruce Door}} || 1 || - || 1 || - || - || - || - || - 
|-
| {{BlockLink|Spruce Log}} || 90 || - || 4 || 22 || 22 || 24 || 18 || - 
|-
| {{BlockLink|Spruce Planks}} || 24 || 23 || 1 || - || - || - || - || - 
|-
| {{BlockLink|Spruce Stairs}} || 4 || - || 4 || - || - || - || - || - 
|-
| {{BlockLink|Spruce Trapdoor}} || 6 || - || 3 || 3 || - || - || - || - 
|-
| {{BlockLink|Torch}} || 5 || - || - || 3 || - || 2 || - || - 
|}<noinclude>
[[Category:Village blueprints]]

[[fr:Village/Structure/Taïga Maison Moyenne 4 plan]]
[[zh:村庄/结构/图示/针叶林中型房屋4]]
</noinclude>