<noinclude>{{structure info}}</noinclude>

[[File:Desert Small House 5.png|thumb|Small house 5 (Desert)]]



==== Blueprint ====

{{layered blueprint
|name=Desert Small House 5 desert_small_house_5
|default=Layer 1
|a=Sand
|s=Smooth Sandstone
|t=Terracotta
|T=Torch-rot180
|L=Lime Bed+Top+Head-rot270
|l=Lime Bed+Top+Foot-rot270
|c=Cut Sandstone
|C=Crafting Table
|j=Jungle Door+up+right
|J=Jungle Door+top
|b=Jungle Button
|p=Potted Cactus
       
|----Layer 0|
       
 aaaaa 
 atsta 
 astsa 
 atsta 
 aasaa 
 aasaa 
       
|----Layer 1|
       
 scscs 
 c  Lc 
 s  ls 
 c  Cc 
 ssjss 
    p  
       
|----Layer 2|
       
 scscs 
 c   c 
 s   s 
 c   c 
 ssJss 
       
|----Layer 3|
       
 s s s 
 c T c 
 s   s 
 c   c 
 sssss 
  bbb  
       
|----Layer 4|
       
 ccccc 
 ccccc 
 ccccc 
 ccccc 
 ccccc 
       
|----Layer 5|
       
 c c c 

 c   c 

 c c c 
       
}}

==== Materials ====

{| class="wikitable sortable mw-collapsible"
|-
! Name !! Total !! Layer 0 !! Layer 1 !! Layer 2 !! Layer 3 !! Layer 4 !! Layer 5 
|-
| {{BlockLink|Crafting Table}} || 1 || - || 1 || - || - || - || - 
|-
| {{BlockLink|Cut Sandstone}} || 49 || - || 6 || 6 || 4 || 25 || 8 
|-
| {{ItemLink|Jungle Door}} || 1 || - || 1 || - || - || - || - 
|-
| {{BlockLink|Jungle Button}} || 3 || - || - || - || 3 || - || - 
|-
| {{BlockLink|Lime Bed}} || 1 || - || 1 || - || - || - || - 
|-
| {{BlockLink|Potted Cactus}} || 1 || - || 1 || - || - || - || - 
|-
| {{BlockLink|Sand}} || 19 || 19 || - || - || - || - || - 
|-
| {{BlockLink|Smooth Sandstone}} || 34 || 6 || 9 || 9 || 10 || - || - 
|-
| {{BlockLink|Terracotta}} || 5 || 5 || - || - || - || - || - 
|-
| {{BlockLink|Torch}} || 1 || - || - || - || 1 || - || - 
|}<noinclude>
[[Category:Village blueprints]]

[[fr:Village/Structure/Désert Petite Maison 5 plan]]
[[ja:村/構造/設計図/砂漠の小さな家5]]
[[zh:村庄/结构/图示/沙漠小型房屋5]]
</noinclude>