<noinclude>{{structure info}}</noinclude>

[[File:Snowy Tundra Small House 2.png|thumb|Small house 2 (Snowy tundra)]]



==== Blueprint ====

{{layered blueprint
|name=Snowy Small House 2 snowy_small_house_2
|default=Layer 2
|w=Stripped Spruce Wood
|s=Snow
|p=Spruce Planks
|C=Cobblestone
|c=Cobblestone Wall
|b=Blue Bed+top-head-rot270
|B=Blue Bed+top-foot-rot270
|q=Spruce Slab
|S=Spruce Slab+top
|d=Spruce Door+bottom
|D=Spruce Door+top
|f=Furnace
|t=Torch
|T=Torch-rot180
|G=Glass Pane
|g=Glass Pane-rot90
|x=Spruce Stairs-rot90
|y=Spruce Stairs
|z=Spruce Stairs-rot270
         
|----Layer 1|
         
 sssssss 
 swwwwws 
 swpppws 
 swCppws 
 swpppws 
 swwwwws 
 ssxyzss 
         
|----Layer 2|
         
 S     S 
 pwwwwwp 
 Swf bwS 
 pw  Bwp 
 Sw   wS 
 pwwdwwp 
 S     S 
         
|----Layer 3|
         
 pS   Sp 
 pwwwwwp 
 pwc  wp 
 pw   wp 
 pw   wp 
 pwwDwwp 
 pS   Sp 
         
|----Layer 4|
         
 qp   pq 
 spwgwps 
 qpc  pq 
 sG   Gs 
 qp   pq 
 spwwwps 
 qp T pq 
         
|----Layer 5|
         
  pS Sp  
  pwwwp  
  pc  p  
  p   p  
  p   p  
  pwwwp  
  pS Sp  
         
|----Layer 6|
         
  spSps  
  spwps  
   CTps  
  qp pq  
  sptps  
  spwps  
  spSps  
         
|----Layer 7|
         
    p    
    p    
   cp    
    p    
    p    
    p    
    p    
         
|----Layer 8|
         
    s    
    s    
   cs    
    s    
    s    
    s    
    s    
         
}}

All spruce slabs in layer 4 and 2 lying next to the roof in layer 6 are bottom slabs, while the rests are top slabs.



==== Materials ====

{| class="wikitable sortable mw-collapsible"
|-
! Name !! Total !! Layer 1 !! Layer 2 !! Layer 3 !! Layer 4 !! Layer 5 !! Layer 6 !! Layer 7 !! Layer 8 
|-
| {{BlockLink|Blue Bed}} || 1 || - || 1 || - || - || - || - || - || - 
|-
| {{BlockLink|Cobblestone}} || 2 || 1 || - || - || - || - || 1 || - || - 
|-
| {{BlockLink|Cobblestone Wall}} || 5 || - || - || 1 || 1 || 1 || - || 1 || 1 
|-
| {{BlockLink|Furnace}} || 1 || - || 1 || - || - || - || - || - || - 
|-
| {{BlockLink|Glass Pane}} || 3 || - || - || - || 3 || - || - || - || - 
|-
| {{BlockLink|Snow}} || 58 || 21 || - || - || 6 || - || 11 || 13 || 7 
|-
| {{ItemLink|Spruce Door}} || 1 || - || 1 || - || - || - || - || - || - 
|-
| {{BlockLink|Spruce Slab}} || 28 || - || 8 || 4 || 8 || 4 || 4 || - || - 
|-
| {{BlockLink|Spruce Planks}} || 74 || 8 || 6 || 14 || 12 || 14 || 13 || 7 || - 
|-
| {{BlockLink|Spruce Stairs}} || 3 || 3 || - || - || - || - || - || - || - 
|-
| {{BlockLink|Stripped Spruce Wood}} || 59 || 16 || 15 || 15 || 5 || 6 || 2 || - || - 
|-
| {{BlockLink|Torch}} || 3 || - || - || - || 1 || - || 2 || - || - 
|}<noinclude>
[[Category:Village blueprints]]

[[fr:Village/Structure/Toundra enneigée Petite Maison 2 plan]]
[[ja:村/構造/設計図/雪原の小さな家2]]
[[zh:村庄/结构/图示/雪原小型房屋2]]
</noinclude>