<noinclude>{{structure info}}</noinclude>

[[File:Taiga Small House 3.png|thumb|Small House 3 (Taiga)]]



==== Blueprint ====

{{layered blueprint|name=
Taiga Small House 3|default=Layer 1
|W=Wall Torch-rot-270
|I=Spruce Stairs
|G=Glass Pane-rot-90
|a=Wall Torch-rot-90
|N=Glass Pane
|o=Cobblestone Stairs
|S=Spruce Log-rot-90
|C=Cobblestone
|O=Cobblestone Wall
|P=Spruce Log+top
|Y=Poppy
|U=Spruce Door+bottom
|E=Spruce Door+top
|A=Spruce Trapdoor
|T=Torch
|R=Crafting+Table
|H=Chest
|B=Blue Bed+side+foot
|L=Blue Bed+side+head
         
|----Layer 1|
         
 Y       
  PCCCP  
 OCCCCC  
 oCCCCC  
 OCCCCC  
  PCCCP  
         
         
|----Layer 2|
         
         
  PCCCP  
 OCRIIC  
  U   C  
 OCHBLC  
  PCCCP  
         
         
|----Layer 3|
         
   A A   
  PCGCP  
 TC   CA 
  E   N  
 TC   CA 
  PCGCP  
   A A   
         
|----Layer 4|
         
 SSSSSSS 
  PCCCP  
  C   C  
  C   C  
  C   C  
  PCCCP  
 SSSSSSS 
         
|----Layer 5|
         
         
 SSSSSSS 
  C   C  
  CW aC  
  C   C  
 SSSSSSS 
         
         
|----Layer 6|
         
         
         
 SSSSSSS 
  C   C  
 SSSSSSS 
         
         
         
|----Layer 7|
         
         
         
         
 SSSSSSS 
         
         
         
         
}}



==== Materials ====

{| class="wikitable sortable mw-collapsible"
|-
! Name !! Total !! Layer 1 !! Layer 2 !! Layer 3 !! Layer 4 !! Layer 5 !! Layer 6 !! Layer 7 
|-
| {{BlockLink|Blue Bed}} || 1 || - || 1 || - || - || - || - || - 
|-
| {{BlockLink|Chest}} || 1 || - || 1 || - || - || - || - || - 
|-
| {{BlockLink|Cobblestone}} || 60 || 21 || 11 || 8 || 12 || 6 || 2 || - 
|-
| {{BlockLink|Cobblestone Stairs}} || 1 || 1 || - || - || - || - || - || - 
|-
| {{BlockLink|Cobblestone Wall}} || 4 || 2 || 2 || - || - || - || - || - 
|-
| {{BlockLink|Crafting Table}} || 1 || - || 1 || - || - || - || - || - 
|-
| {{BlockLink|Glass Pane}} || 3 || - || - || 3 || - || - || - || - 
|-
| {{BlockLink|Poppy}} || 1 || 1 || - || - || - || - || - || - 
|-
| {{BlockLink|Spruce Door}} || 1 || - || 1 || - || - || - || - || - 
|-
| {{BlockLink|Spruce Log}} || 65 || 4 || 4 || 4 || 18 || 14 || 14 || 7 
|-
| {{BlockLink|Spruce Stairs}} || 2 || - || 2 || - || - || - || - || - 
|-
| {{BlockLink|Spruce Trapdoor}} || 6 || - || - || 6 || - || - || - || - 
|-
| {{BlockLink|Torch}} || 4 || - || - || 2 || - || 2 || - || - 
|}<noinclude>
[[Category:Village blueprints]]

[[fr:Village/Structure/Taïga Petite Maison 3 plan]]
[[zh:村庄/结构/图示/针叶林小型房屋3]]
</noinclude>