<noinclude>{{structure info}}</noinclude>

[[File:Snowy Tundra Cartographer House 1.png|thumb|Cartographer house 1 (Snowy tundra)]]



==== Blueprint ====

{{layered blueprint
|name=Snowy Cartographer House 1 snowy_cartographer_house_1
|default=Layer 2
|l=Stripped Spruce Log+top
|L=Stripped Spruce Log
|t=Stripped Spruce Log-rot90
|p=Spruce Planks
|S=Snow
|s=Spruce Slab
|c=Cartography Table-rot180
|C=Chest-rot180
|g=Glass Pane-rot90
|o=Spruce Door+bottom
|O=Spruce Door+top
|w=Spruce Stairs
|x=Spruce Stairs-rot90
|y=Spruce Stairs-rot180
|z=Spruce Stairs-rot270
|W=Torch
|X=Torch-rot90
|Y=Torch-rot180
|Z=Torch-rot270
             
|----Layer 1|
             
             
  lllllllll  
  tlllllllt  
  llpplppll  
  tlplllplt  
  lllppplll  
 S  xwwwz    
             
|----Layer 2|
             
             
  lLllLllLl  
  l       l  
  t       t  
  lcClolyyl  
  lLl   lLl  
             
             
|----Layer 3|
             
             
  lgllgllgl  
  t       t  
  l       l  
  t  lOl  t  
  lglY Ylgl  
             
             
|----Layer 4|
             
 p   s s   p 
 plLllLllLlp 
 pt   Y   tp 
 pt       tp 
 pt  lLl  tp 
 plLl   lLlp 
 p   s s   p 
             
|----Layer 5|
             
 ps spsps sp 
 plllptplllp 
 pl  p p  lp 
 ptX p p Ztp 
 pt  plp  tp 
 plllp plllp 
 ps spsps sp 
             
|----Layer 6|
             
  pspspspsp  
  plp p plp  
  p p p p p  
  p p p p p  
  p p p p p  
  plp p plp  
  pspspspsp  
             
|----Layer 7|
             
   p     p   
   p     p   
   p     p   
   p     p   
   p     p   
   p     p   
   p     p   
             
}}

4 middle spruce slabs in layer 6 are bottom slabs, while the rest are top slabs.



==== Materials ====

{| class="wikitable sortable mw-collapsible"
|-
! Name !! Total !! Layer 1 !! Layer 2 !! Layer 3 !! Layer 4 !! Layer 5 !! Layer 6 !! Layer 7 
|-
| {{BlockLink|Cartography Table}} || 1 || - || 1 || - || - || - || - || - 
|-
| {{BlockLink|Chest}} || 1 || - || 1 || - || - || - || - || - 
|-
| {{BlockLink|Glass Pane}} || 5 || - || - || 5 || - || - || - || - 
|-
| {{BlockLink|Snow}} || 1 || 1 || - || - || - || - || - || - 
|-
| {{ItemLink|Spruce Door}} || 1 || - || 1 || - || - || - || - || - 
|-
| {{BlockLink|Spruce Planks}} || 100 || 9 || - || - || 14 || 28 || 35 || 14 
|-
| {{BlockLink|Spruce Slab}} || 22 || - || - || - || 4 || 10 || 8 || - 
|-
| {{BlockLink|Spruce Stairs}} || 7 || 5 || 2 || - || - || - || - || - 
|-
| {{BlockLink|Stripped Spruce Log}} || 125 || 36 || 23 || 18 || 24 || 20 || 4 || - 
|-
| {{BlockLink|Torch}} || 5 || - || - || 2 || 1 || 2 || - || - 
|}<noinclude>
[[Category:Village blueprints]]

[[fr:Village/Structure/Toundra enneigée Maison de Cartographe 1 plan]]
[[ja:村/構造/設計図/雪原の製図家の家1]]
[[zh:村庄/结构/图示/雪原制图师房屋]]
</noinclude>