<noinclude>{{structure info}}</noinclude>

[[File:Taiga Meeting Point 1.png|thumb|Meeting Point 1 (Taiga)]]



==== Blueprint ====

{{layered blueprint|name=
Taiga Meeting Point 1|default=Layer 1
|G=Grass Block+top
|S=Spruce Planks
|B=Bell
|R=Dirt Path+top
|P=Spruce Trapdoor
         
|----Layer 1|
         
  RGRRRR 
  RRGRRR 
  GGRGRG 
  GRGRGR 
 RRRRRRR 
 RRGRRGR 
 RRRGRRR 
  RRRRRR 
  GRGRGR 
  RGRRRR 
  RRGRGG 
   RRR   
         
|----Layer 2|
         
         
    P    
   PSP   
    P    
         
         
         
         
         
         
         
         
         
|----Layer 3|
         
         
         
    B    
         
         
         
         
         
         
         
         
         
         
}}



==== Materials ====

{| class="wikitable sortable mw-collapsible"
|-
! Name !! Total !! Layer 1 !! Layer 2 !! Layer 3 
|-
| {{BlockLink|Bell}} || 1 || - || - || 1 
|-
| {{BlockLink|Grass Block}} || 19 || 19 || - || - 
|-
| {{BlockLink|Dirt Path}} || 53 || 53 || - || - 
|-
| {{BlockLink|Spruce Planks}} || 1 || - || 1 || - 
|-
| {{BlockLink|Spruce Trapdoor}} || 4 || - || 4 || - 
|}<noinclude>
[[Category:Village blueprints]]

[[fr:Village/Structure/Taïga Lieu de Rassemblement 1 plan]]
[[zh:村庄/结构/图示/针叶林会合点1]]
</noinclude>