<noinclude>{{structure info}}</noinclude>

[[File:Snowy Tundra Medium House 1.png|thumb|Medium house 1 (Snowy tundra)]]



==== Blueprint ====

{{layered blueprint
|name=Snowy Medium House 1 snowy_medium_house_1
|default=Layer 1
|i=Dirt
|g=Grass Block+top
|S=Snow
|s=Snow Block
|w=White Bed+top-head-rot270
|W=White Bed+top-foot-rot270
|d=Spruce Door+bottom
|D=Spruce Door+top
|t=Torch-rot180
|l=Lantern
          
|----Layer 0|
          
 gggiiigg 
 ggigggig 
 gigggggi 
 gigggggi 
 giigggii 
 ggigggig 
 gggigigg 
          
|----Layer 1|
          
 SSSsssSS 
 SSsw wsS 
 Ss W W s 
 Ss     s 
 Sss   ss 
 SSs   sS 
 SSSsdsSS 
          
|----Layer 2|
          
    sss   
   s   s  
  s     s 
  s     s 
  ss   ss 
   s   s  
    sDs   
          
|----Layer 3|
          
    sss   
   s   s  
  Ss l sS 
   s   sS 
   s   sS 
   s t s  
    sss   
          
|----Layer 4|
          
    SSS   
   SsssS  
   SsssS  
    sssS  
    sssS  
    sssS  
     S    
          
|----Layer 5|
          
          
    SSS   
    SSS   
    SSS   
    SSS   
     SS   
          
}}



==== Materials ====

{| class="wikitable sortable mw-collapsible"
|-
! Name !! Total !! Layer 0 !! Layer 1 !! Layer 2 !! Layer 3 !! Layer 4 !! Layer 5 
|-
| {{BlockLink|Dirt}} || 17 || 17 || - || - || - || - || - 
|-
| {{BlockLink|Grass Block}} || 39 || 39 || - || - || - || - || - 
|-
| {{BlockLink|Lantern}} || 1 || - || - || 1 || - || - || - 
|-
| {{BlockLink|Snow}} || 48 || 19 || - || - || 4 || 11 || 14 
|-
| {{BlockLink|Snow Block}} || 65 || - || 17 || 17 || 16 || 15 || - 
|-
| {{ItemLink|Spruce Door}} || 1 || - || 1 || - || - || - || - 
|-
| {{BlockLink|Torch}} || 1 || - || - || 1 || - || - || - 
|-
| {{BlockLink|White Bed}} || 2 || - || 2 || - || - || - || - 
|}<noinclude>
[[Category:Village blueprints]]

[[fr:Village/Structure/Toundra enneigée Maison Moyenne 1 plan]]
[[ja:村/構造/設計図/雪原の中くらいの家1]]
[[zh:村庄/结构/图示/雪原中型房屋1]]
</noinclude>