<noinclude>{{structure info}}</noinclude>

[[File:Desert Cartographer 1.png|thumb|Cartographer 1 (Desert)]]



==== Blueprint ====

{{layered blueprint
|default=Layer 3
|name=Village Desert Houses desert_cartographer_1
|S=Smooth Sandstone
|s=Smooth Sandstone Stairs
|p=Smooth Sandstone Stairs-rot90
|R=Smooth Sandstone Stairs-rot180
|r=Smooth Sandstone Stairs-rot270
|C=Cut Sandstone
|P=Potted Cactus
|L=Smooth Sandstone Slab
|t=Torch
|T=Torch-rot90
|l=Torch-rot270
|D=Jungle Door+bottom
|d=Jungle Door+top
|W=Cartography Table
|----Layer 1|
         
 RLLCSSC 
 SSSS  S 
 CSSS  S 
 S S   C 
 S SS SS 
 C SSSSC 
 PSSSr   
         
|----Layer 2|
         
    CSSC 
  pSS  S 
 CSSS  S 
 SSS   C 
 SSSSTSS 
 CSSSSSC 
  SSr    
         
|----Layer 3|
         
    CSSC 
   pSSSS 
 CSSSSSS 
 S WSSSC 
 S  sSSS 
 CDCSSSC 
         
         
|----Layer 4|
         
    CSSC 
       S 
 CSC   S 
 S lCDSC 
 S    PL 
 CdCLLLC 
         
         
|----Layer 5|
         
    CSSC 
       S 
 CSC   S 
 S  CdSC 
 S       
 CSC     
         
         
|----Layer 6|
         
    CSSC 
    ST S 
 CLCS  S 
 LLLCSSC 
 LLL     
 CLC     
         
         
|----Layer 7|
         
    CLLC 
    LLLL 
    LLLL 
    CLLC 
         
         
         
         
}}



==== Materials ====

{| class="wikitable sortable mw-collapsible"
|-
! Name !! Total !! Layer 1 !! Layer 2 !! Layer 3 !! Layer 4 !! Layer 5 !! Layer 6 !! Layer 7 
|-
| {{BlockLink|Cartography Table}} || 1 || - || - || 1 || - || - || - || - 
|-
| {{BlockLink|Cut Sandstone}} || 48 || 6 || 6 || 7 || 9 || 8 || 8 || 4 
|-
| {{ItemLink|Jungle Door}} || 2 || - || - || 1 || 1 || - || - || - 
|-
| {{BlockLink|Potted Cactus}} || 2 || 1 || - || - || 1 || - || - || - 
|-
| {{BlockLink|Smooth Sandstone}} || 98 || 25 || 25 || 23 || 8 || 9 || 8 || - 
|-
| {{BlockLink|Smooth Sandstone Slab}} || 26 || 2 || - || - || 4 || - || 8 || 12 
|-
| {{BlockLink|Smooth Sandstone Stairs}} || 6 || 2 || 2 || 2 || - || - || - || - 
|-
| {{BlockLink|Torch}} || 3 || - || 1 || - || 1 || - || 1 || - 
|}<noinclude>
[[Category:Village blueprints]]

[[fr:Village/Structure/Désert Cartographe 1 plan]]
[[ja:村/構造/設計図/砂漠の製図家の家1]]
[[zh:村庄/结构/图示/沙漠制图师房屋]]
</noinclude>