<noinclude>{{structure info}}</noinclude>

[[File:Savanna Cartographer 1.png|thumb|Cartographer 1 (Savanna)]]



==== Blueprint ====

{{layered blueprint|name=
Savanna Cartographer 1|default=Layer 1
|A=Acacia Slab
|C=Acacia Wood
|I=Acacia Log
|P=Acacia Planks
|R=Cartography Table
|B=Brown Wall Banner
|H=Chest-rot-270
|S=Acacia Stairs
|F=Acacia Fence
|T=Torch
|G=Glass Pane-rot-90
|D=Acacia Door+bottom
|O=Acacia Door+top
|W=Wall Torch-rot-180
|U=Double Acacia Slab
           
|----Layer 1|
           
           
  F F F F  
           
  F     F  
           
  F F F F  
    PPP    
    SSS    
           
|----Layer 2|
           
           
  F F F F  
           
  F     F  
           
  F FPF F  
    SSS    
           
           
|----Layer 3|
           
           
  UUUUUUU  
  UUUUUUU  
  UUUUUUU  
  UUUUUUU  
  UAAAAAU  
           
           
           
|----Layer 4|
           
           
  CIIIIIC  
 BIR   CIB 
 BIC   HIB 
 BIIIDIIIB 
  C     C  
           
           
           
|----Layer 5|
           
           
  CIGIGIC  
  I    TI  
  IT    I  
  IIIOIII  
  C     C  
           
           
           
|----Layer 6|
           
           
  CIIIIIC  
  I     I  
  I     I  
  IIIIIII  
  C BWB C  
           
           
           
|----Layer 7|
           
 SSSSSSSSS 
 SPPPPPPPS 
 SP     PS 
 SP     PS 
 SPPPPPPPS 
 SPPPPPPPS 
 SSSSSSSSS 
           
           
|----Layer 8|
           
           
  SSSSSSS  
  SPPPPPS  
  SPPPPPS  
  SPPPPPS  
  SSSSSSS  
           
           
           
}}



==== Materials ====

{| class="wikitable sortable mw-collapsible"
|-
! Name !! Total !! Layer 1 !! Layer 2 !! Layer 3 !! Layer 4 !! Layer 5 !! Layer 6 !! Layer 7 !! Layer 8 
|-
| {{BlockLink|Acacia Door}} || 1 || - || - || - || 1 || - || - || - || - 
|-
| {{BlockLink|Acacia Fence}} || 20 || 10 || 10 || - || - || - || - || - || - 
|-
| {{BlockLink|Acacia Log}} || 44 || - || - || - || 15 || 13 || 16 || - || - 
|-
| {{BlockLink|Acacia Planks}} || 44 || 3 || 1 || - || - || - || - || 25 || 15 
|-
| {{BlockLink|Acacia Slab}} || 65 || - || - || 65 || - || - || - || - || - 
|-
| {{BlockLink|Acacia Stairs}} || 54 || 3 || 3 || - || - || - || - || 28 || 20 
|-
| {{BlockLink|Acacia Wood}} || 14 || - || - || - || 6 || 4 || 4 || - || - 
|-
| {{BlockLink|Brown Wall Banner}} || 8 || - || - || - || 6 || - || 2 || - || - 
|-
| {{BlockLink|Cartography Table}} || 1 || - || - || - || 1 || - || - || - || - 
|-
| {{BlockLink|Chest}} || 1 || - || - || - || 1 || - || - || - || - 
|-
| {{BlockLink|Glass Pane}} || 2 || - || - || - || - || 2 || - || - || - 
|-
| {{BlockLink|Torch}} || 3 || - || - || - || - || 2 || 1 || - || - 
|}<noinclude>
[[Category:Village blueprints]]

[[fr:Village/Structure/Savane Cartographe 1 plan]]
[[ja:村/構造/設計図/サバンナの製図所1]]
[[zh:村庄/结构/图示/热带草原制图师房屋]]
</noinclude>