<noinclude>{{structure info}}</noinclude>

[[File:Taiga Weaponsmith 1.png|thumb|Weaponsmith 1 (Taiga)]]



==== Blueprint ====

{{layered blueprint|name=
Taiga Weaponsmith 1|default=Layer 1
|G=Grass Block+top
|S=Spruce Log-rot-90
|D=Dirt
|P=Spruce Planks
|C=Cobblestone
|H=Chest-rot-180
|R=Dirt Path+top
|F=Fern
|U=Spruce Trapdoor
|I=Grindstone
|W=Wall Torch-rot-90
|O=Poppy
|E=Spruce Door+bottom
|p=Spruce Door+top
|L=Glass Pane
|T=Spruce Stairs
|N=Spruce Fence
         
|----Layer 1|
         
 GGGGGGG 
 RRDDDDG 
 RGDPPDG 
 RRPPPDG 
 RGDPPDG 
 RRDDDDG 
 GGGGGGG 
         
|----Layer 2|
         
 F       
   CCCC  
  ICTTC  
   E  C  
  ICHNC  
   CCCC  
   F     
         
|----Layer 3|
         
         
   CCCCU 
   C  L  
   p  CU 
   C UL  
   CCCCU 
         
         
|----Layer 4|
         
         
   CCCC  
   C  C  
  WC  C  
   C  C  
   CCCC  
         
         
|----Layer 5|
         
  U      
 UGPPPP  
 UGP  P  
 UGP  P  
 UGP  P  
 UGPPPP  
  U      
         
|----Layer 6|
         
  SSSSSS 
  FPPPPU 
  OL  L  
  FP WPU 
   L  L  
  OPPPPU 
  SSSSSS 
         
|----Layer 7|
         
         
  SSSSSS 
   P  P  
  WP  P  
   P  P  
  SSSSSS 
         
         
|----Layer 8|
         
         
         
  SSSSSS 
   P  P  
  SSSSSS 
         
         
         
|----Layer 9|
         
         
         
         
  SSSSSS 
         
         
         
         
}}



==== Materials ====

{| class="wikitable sortable mw-collapsible"
|-
! Name !! Total !! Layer 1 !! Layer 2 !! Layer 3 !! Layer 4 !! Layer 5 !! Layer 6 !! Layer 7 !! Layer 8 !! Layer 9 
|-
| {{BlockLink|Chest}} || 1 || - || 1 || - || - || - || - || - || - || - 
|-
| {{BlockLink|Cobblestone}} || 38 || - || 13 || 11 || 14 || - || - || - || - || - 
|-
| {{BlockLink|Dirt}} || 13 || 13 || - || - || - || - || - || - || - || - 
|-
| {{BlockLink|Fern}} || 4 || - || 2 || - || - || - || 2 || - || - || - 
|-
| {{BlockLink|Glass Pane}} || 6 || - || - || 2 || - || - || 4 || - || - || - 
|-
| {{BlockLink|Grass Block}} || 26 || 21 || - || - || - || 5 || - || - || - || - 
|-
| {{BlockLink|Dirt Path}} || 8 || 8 || - || - || - || - || - || - || - || - 
|-
| {{BlockLink|Grindstone}} || 2 || - || 2 || - || - || - || - || - || - || - 
|-
| {{BlockLink|Poppy}} || 2 || - || - || - || - || - || 2 || - || - || - 
|-
| {{BlockLink|Spruce Door}} || 1 || - || 1 || - || - || - || - || - || - || - 
|-
| {{BlockLink|Spruce Fence}} || 1 || - || 1 || - || - || - || - || - || - || - 
|-
| {{BlockLink|Spruce Log}} || 42 || - || - || - || - || - || 12 || 12 || 12 || 6 
|-
| {{BlockLink|Spruce Planks}} || 39 || 7 || - || - || - || 14 || 10 || 6 || 2 || - 
|-
| {{BlockLink|Spruce Stairs}} || 2 || - || 2 || - || - || - || - || - || - || - 
|-
| {{BlockLink|Spruce Trapdoor}} || 14 || - || - || 4 || - || 7 || 3 || - || - || - 
|-
| {{BlockLink|Torch}} || 3 || - || - || - || 1 || - || 1 || 1 || - || - 
|}<noinclude>
[[Category:Village blueprints]]

[[fr:Village/Structure/Taïga Forge d'Armes 1 plan]]
[[zh:村庄/结构/图示/针叶林铁匠铺1]]
</noinclude>