<noinclude>{{structure info}}</noinclude>

[[File:Taiga Butcher Shop 1.png|thumb|Butcher Shop 1 (Taiga)]]



==== Blueprint ====

{{layered blueprint|name=
Taiga Butcher Shop 1|default=Layer 1
|S=Spruce Log
|C=Cobblestone
|P=Spruce Log+top
|M=Smooth Stone Slab
|e=Double Smooth Stone Slab
|R=Spruce Log-rot-90
|G=Grass Block+top
|O=Smoker
|A=Campfire
|F=Fern
|Y=Poppy
|U=Spruce Trapdoor
|L=Glass Pane
|B=Cobblestone Stairs-rot-180
|E=Cobblestone Stairs
|N=Large Fern
|n=Large Fern+bottom
|l=Glass Pane-rot-90
|T=Cobblestone Wall
|W=Wall Torch-rot-270
|H=Wall Torch-rot-180
|D=Spruce Door+bottom
|p=Spruce Door+top
|r=Spruce Fence
|a=Wall Torch-rot-90
|o=Torch
           
|----Layer 1|
           
   nFnUUU  
  CCCCGGGU 
 FCMMCGGGU 
  CMMCGGGU 
  CMMCGGGU 
 YCMMCCCUn 
 YCPPPPCCE 
 FCPPPPCCE 
  CCPPPCCE 
  CCCCCCnY 
   Y  n    
           
|----Layer 2|
           
   N N     
  CCCCrrr  
  CeeC  r  
  C  D  r  
  C  C rr  
  CO CCC N 
  C    C   
  CU   D   
  C U  C   
  CCCCCCN  
      N    
           
|----Layer 3|
           
           
  CCCC  o  
 UC  C     
  L  p     
 UC  C     
  CT CCC   
 UC    C   
  L    p   
 UC    C   
  CllCCC   
  U  U     
           
|----Layer 4|
           
 S    S    
 SCCCCS    
 SCHHCS    
 SC  CS    
 SCU CRRR  
 SCTUCCC   
 SCU   C   
 SCW  aC   
 SC    C   
 SCCCCCC   
 S    RRR  
           
|----Layer 5|
           
  S  S     
  SCCS     
  SCCS     
  SCCS     
  SCCS     
  SACRRRR  
  SRRRRC   
  SRRRRCW  
  SRRRRC   
  SCCRRRR  
  S  S     
           
|----Layer 6|
           
   SS      
   SS      
   SS      
   SS      
  BSC      
  C C      
  BCSRRRR  
   SSPRC   
   SSRRRR  
   SS      
   SS      
           
|----Layer 7|
           
           
           
           
           
  EEE      
  E E      
  EEE      
     RRRR  
           
           
           
           
}}



==== Materials ====

{| class="wikitable sortable mw-collapsible"
|-
! Name !! Total !! Layer 1 !! Layer 2 !! Layer 3 !! Layer 4 !! Layer 5 !! Layer 6 !! Layer 7 
|-
| {{BlockLink|Campfire}} || 1 || - || - || - || - || 1 || - || - 
|-
| {{BlockLink|Cobblestone}} || 119 || 30 || 24 || 20 || 26 || 14 || 5 || - 
|-
| {{BlockLink|Cobblestone Stairs}} || 13 || 3 || - || - || - || - || 2 || 8 
|-
| {{BlockLink|Cobblestone Wall}} || 2 || - || - || 1 || 1 || - || - || - 
|-
| {{BlockLink|Fern}} || 3 || 3 || - || - || - || - || - || - 
|-
| {{BlockLink|Glass Pane}} || 4 || - || - || 4 || - || - || - || - 
|-
| {{BlockLink|Grass Block}} || 12 || 12 || - || - || - || - || - || - 
|-
| {{BlockLink|Large Fern}} || 10 || 5 || 5 || - || - || - || - || - 
|-
| {{BlockLink|Poppy}} || 4 || 4 || - || - || - || - || - || - 
|-
| {{BlockLink|Smoker}} || 1 || - || 1 || - || - || - || - || - 
|-
| {{BlockLink|Smooth Stone Slab}} || 12 || 8 || 4 || - || - || - || - || - 
|-
| {{BlockLink|Spruce Door}} || 2 || - || 2 || - || - || - || - || - 
|-
| {{BlockLink|Spruce Fence}} || 7 || - || 7 || - || - || - || - || - 
|-
| {{BlockLink|Spruce Log}} || 101 || 11 || - || - || 21 || 37 || 28 || 4 
|-
| {{BlockLink|Spruce Trapdoor}} || 19 || 8 || 2 || 6 || 3 || - || - || - 
|-
| {{BlockLink|Torch}} || 6 || - || - || 1 || 4 || 1 || - || - 
|}<noinclude>
[[Category:Village blueprints]]

[[fr:Village/Structure/Taïga Échoppe de Boucher 1 plan]]
[[ja:村/構造/設計図/タイガの肉屋1]]
[[zh:村庄/结构/图示/针叶林肉铺]]
</noinclude>