<noinclude>{{structure info}}</noinclude>

[[File:Snowy Tundra Medium House 2.png|thumb|Medium house 2 (Snowy tundra)]]



==== Blueprint ====

{{layered blueprint
|name=Snowy Medium House 2 snowy_medium_house_2
|default=Layer 2
|s=Snow Block
|S=Snow
|w=Stripped Spruce Wood
|p=Spruce Planks
|L=Spruce Slab
|l=Spruce Slab+top
|x=Spruce Stairs
|y=Spruce Stairs-rot90
|z=Spruce Stairs-rot270
|t=Torch-rot180
|X=Torch-rot90
|Y=Torch-rot270
|f=Furnace-rot90
|b=Blue Bed+top-head-rot270
|B=Blue Bed+top-foot-rot270
|r=Red Bed+top-head-rot270
|R=Red Bed+top-foot-rot270
|g=Glass Pane-rot90
|d=Spruce Door+bottom
|D=Spruce Door+top
                
|----Layer 1|
                
 SSSSSSSSSSSSSS 
 sSSSSSssSSSSSS 
 SswwwwwwwwwsSS 
 sswpppppppwssS 
 sswpppppppwsSS 
 sswwwwwwwwwssS 
 SsSSxSsSxSSSSS 
                
|----Layer 2|
                
                
 S    Ss        
  SwwwwwwwwwS   
 Sswb     rwsS  
 SSwB pz  RwS   
  SwwdwwwdwwS   
  S             
                
|----Layer 3|
                
                
                
   wgwgwgwgw    
   w   t t w    
   w  z    w    
   wwDwwwDww    
                
|----Layer 4|
                
                
  lplplplplpl   
   wwwwwwwww    
   wlllllllw    
   wlz   llw    
   wwwwwwwww    
  lplplplplpl   
                
|----Layer 5|
                
                
  ppppppppppp   
  lwwwwwwwww    
   w      fw    
   w      yw    
  lwwwwwwwww    
  ppppppppppp   
                
|----Layer 6|
                
                
  SL LLSLL LS   
  ppgppgppgpp   
   wX     Yw    
   wX     Yw    
  ppgppgppgpp   
  SLSLLSLL LS   
                
|----Layer 7|
                
                
                
  ppppppppppp   
  lw       w    
  lw       w    
  ppppppppppp   
                
|----Layer 8|
                
             
             
  SSLSSLSSLSS   
  ppppppppppp   
  ppppppppppp   
  SSLSSLSSLSS   
                
|----Layer 9|
                
                
                
                
  SSSSSSSSSSS   
  SSSSSSSSSSS   
                
}}

The spruce slabs in layer 6 and layer 8 are bottom slabs, while the rest in the blueprint are top slabs.

==== Materials ====

{| class="wikitable sortable mw-collapsible"
|-
! Name !! Total !! Layer 1 !! Layer 2 !! Layer 3 !! Layer 4 !! Layer 5 !! Layer 6 !! Layer 7!! Layer 8!! Layer 9 
|-
| {{BlockLink|Blue Bed}} || 1 || - || 1 || - || - || - || - || - || - || - 
|-
| {{BlockLink|Furnace}} || 1 || - || - || - || - || 1 || - || - || - || - 
|-
| {{BlockLink|Glass Pane}} || 10 || - || - || 4 || - || - || 6 || - || - || - 
|-
| {{BlockLink|Red Bed}} || 1 || - || 1 || - || - || - || - || - || - || - 
|-
| {{BlockLink|Snow}} || 180 || 104 || 28 || - || - || - || 7 || - || 19 || 22 
|-
| {{BlockLink|Snow Block}} || 22 || 19 || 3 || - || - || - || - || - || - || - 
|-
| {{ItemLink|Spruce Door}} || 2 || - || 2 || - || - || - || - || - || - || - 
|-
| {{BlockLink|Spruce Planks}} || 103 || 14 || 1 || - || 10 || 22 || 12 || 22 || 22 || - 
|-
| {{BlockLink|Spruce Slab}} || 44 || - || - || - || 22 || 2 || 12 || 2 || 6 || - 
|-
| {{BlockLink|Spruce Stairs}} || 6 || 2 || 1 || 1 || 1 || 1 || - || - || - || - 
|-
| {{BlockLink|Stripped Spruce Wood}} || 110 || 22 || 20 || 16 || 22 || 22 || 4 || 4 || - || - 
|-
| {{BlockLink|Torch}} || 5 || - || - || 1 || - || - || 4 || - || - || - 
|}<noinclude>
[[Category:Village blueprints]]

[[fr:Village/Structure/Toundra enneigée Maison Moyenne 2 plan]]
[[en:村/構造/設計図/雪原の中くらいの家2]]
[[zh:村庄/结构/图示/雪原中型房屋2]]
</noinclude>