<noinclude>{{structure info}}</noinclude>

[[File:Taiga Weaponsmith 2.png|thumb|Weaponsmith 2 (Taiga)]]



==== Blueprint ====

{{layered blueprint|name=
Taiga Weaponsmith 2|default=Layer 1
|G=Grass Block+top
|C=Cobblestone
|S=Spruce Log
|D=Dirt
|R=Dirt Path+top
|F=Fern
|O=Cobblestone Wall
|L=Large Fern
|l=Large Fern+bottom
|T=Torch
|I=Grindstone
         
|----Layer 1|
         
  GG     
 RGGGGGD 
 RRRRGGD 
 DRRCRGD 
 RGRRGGD 
 GGGGGGD 
         
|----Layer 2|
         
  l      
  OOOFOS 
     l S 
    I OS 
     FFS 
 FOOO OS 
         
|----Layer 3|
         
  L      
  T O S  
     LS  
      S  
      S  
  T O S  
         
|----Layer 4|
         
         
    OS   
     S   
     S   
     S   
    OS   
         
|----Layer 5|
         
         
    S    
    S    
    S    
    S    
    S    
         
}}



==== Materials ====

{| class="wikitable sortable mw-collapsible"
|-
! Name !! Total !! Layer 1 !! Layer 2 !! Layer 3 !! Layer 4 !! Layer 5 
|-
| {{BlockLink|Cobblestone}} || 1 || 1 || - || - || - || - 
|-
| {{BlockLink|Cobblestone Wall}} || 13 || - || 9 || 2 || 2 || - 
|-
| {{BlockLink|Dirt}} || 5 || 6 || - || - || - || - 
|-
| {{BlockLink|Fern}} || 4 || - || 4 || - || - || - 
|-
| {{BlockLink|Grass Block}} || 19 || 19 || - || - || - || - 
|-
| {{BlockLink|Dirt Path}} || 11 || 11 || - || - || - || - 
|-
| {{BlockLink|Grindstone}} || 1 || - || 1 || - || - || - 
|-
| {{BlockLink|Large Fern}} || 4 || - || 2 || 2 || - || - 
|-
| {{BlockLink|Spruce Log}} || 20 || - || 5 || 5 || 5 || 5 
|-
| {{BlockLink|Torch}} || 2 || - || - || 2 || - || - 
|}<noinclude>
[[Category:Village blueprints]]

[[fr:Village/Structure/Taïga Forge d'Armes 2 plan]]
[[zh:村庄/结构/图示/针叶林铁匠铺2]]
</noinclude>