<noinclude>{{structure info}}</noinclude>

[[File:Savanna Tannery 1.png|thumb|Tannery 1 (Savanna)]]



==== Blueprint ====

{{layered blueprint|name=
Savanna Tannery 1|default=Layer 1
|G=Grass Block+top
|D=Dirt
|Y=Yellow Terracotta
|A=Acacia Planks
|C=Acacia Log
|I=Acacia Log+top
|S=Smooth Stone
|B=Brown Wall Banner
|H=Chest-rot-270
|R=Dirt Path+top
|r=Short Grass
|T=Acacia Stairs
|U=Water Cauldron
|F=Acacia Fence
|L=Glass Pane-rot-90
|c=Acacia Slab
|O=Acacia Door+bottom
|a=Acacia Door+top
|W=Wall Torch
|l=Wall Torch-rot-180
           
|----Layer 1|
           
 RRRG RRRR 
 GGGGRGGGG 
 GGGGRGGGG 
 GGDDCDDGG 
 GDCIIICDG 
 GDCIIICDG 
 GGDDDDDGG 
 GGGGGGGGG 
           
|----Layer 2|
           
    r      
 rr F Frrr 
 r         
   YYOYYrr 
 rYU   SY  
 rYU   HYr 
 r YYYYY   
  rrrrrr   
           
|----Layer 3|
           
           
    F F    
           
   YYaYY   
  Y     Y  
  Y     Y  
   YLYLY   
           
           
|----Layer 4|
           
    B B    
    AcA    
    cWc    
   YYYYY   
  Y  l  Y  
  Y  W  Y  
   YYYYY   
           
           
|----Layer 5|
           
           
           
  TTTTTTT  
 TAAAAAAAT 
 TA     AT 
 TA     AT 
 TAAAAAAAT 
  TTTTTTT  
           
|----Layer 6|
           
           
           
           
  TTTTTTT  
  TAAAAAT  
  TAAAAAT  
  TTTTTTT  
           
           
}}



==== Materials ====

{| class="wikitable sortable mw-collapsible"
|-
! Name !! Total !! Layer 1 !! Layer 2 !! Layer 3 !! Layer 4 !! Layer 5 !! Layer 6 
|-
| {{BlockLink|Acacia Door}} || 1 || - || 1 || - || - || - || - 
|-
| {{BlockLink|Acacia Fence}} || 4 || - || 2 || 2 || - || - || - 
|-
| {{BlockLink|Acacia Log}} || 11 || 11 || - || - || - || - || - 
|-
| {{BlockLink|Acacia Planks}} || 30 || - || - || - || 2 || 18 || 10 
|-
| {{BlockLink|Acacia Slab}} || 3 || - || - || - || 3 || - || - 
|-
| {{BlockLink|Acacia Stairs}} || 40 || - || - || - || - || 22 || 18 
|-
| {{BlockLink|Brown Wall Banner}} || 2 || - || - || - || 2 || - || - 
|-
| {{BlockLink|Water Cauldron}} || 2 || - || 2 || - || - || - || - 
|-
| {{BlockLink|Chest}} || 1 || - || 1 || - || - || - || - 
|-
| {{BlockLink|Dirt}} || 13 || 13 || - || - || - || - || - 
|-
| {{BlockLink|Glass Pane}} || 2 || - || - || 2 || - || - || - 
|-
| {{BlockLink|Short Grass}} || 19 || - || 19 || - || - || - || - 
|-
| {{BlockLink|Grass Block}} || 38 || 38 || - || - || - || - || - 
|-
| {{BlockLink|Dirt Path}} || 9 || 9 || - || - || - || - || - 
|-
| {{BlockLink|Smooth Stone}} || 1 || - || 1 || - || - || - || - 
|-
| {{BlockLink|Torch}} || 3 || - || - || - || 3 || - || - 
|-
| {{BlockLink|Yellow Terracotta}} || 38 || - || 13 || 11 || 14 || - || - 
|}<noinclude>
[[Category:Village blueprints]]

[[fr:Village/Structure/Savane Tannerie 1 plan]]
[[ja:村/構造/設計図/サバンナの革加工場1]]
[[zh:村庄/结构/图示/热带草原皮匠屋]]
</noinclude>