<noinclude>{{structure info}}</noinclude>

[[File:Savanna Animal Pen 2.png|thumb|Animal Pen 2 (Savanna)]]



==== Blueprint ====

{{layered blueprint|name=
Savanna Animal Pen 2|default=Layer 3
|D=dirt
|G=grass block+top
|A=acacia fence
|C=acacia fence
|F=acacia fence
|E=acacia fence
|N=acacia fence
|a=acacia fence
|T=torch
|c=acacia fence
|R=short grass
|i=acacia fence
|f=acacia fence
|L=tall grass+bottom
|S=tall grass
|W=water+top
|e=acacia fence gate
              
|----Layer 1|
              
     DDDD     
     DDDD     
    DDDDDDDDD 
  DDDDDDDDDDD 
  DDDDDDDDDDD 
  DDDDDDDDDDD 
 DDDDDDDDDDDD 
 DDDDDDDDDDDD 
 DDDDDDDDD    
 DDDDDDDDD    
 DDDDDDDDD    
   DDDDDD  D  
   D DDDD     
              
|----Layer 2|
              
     GGGG     
     GGGG     
    GGGGGGGGG 
  GGGGGGGGGGG 
  GGGGGWGGGGG 
  GGGGWGGGGGG 
 GGGGGGGGGGGG 
 GGGGGGGGGGGG 
 DGGGGGGGG    
 GGGGGGWGG    
 GGGGGGGGG    
   GGGGGG  G  
   G GGGG     
              
|----Layer 3|
              
     Fccf     
     CRRC     
    Fi LAcccf 
  Fci RR RR C 
  CRRRR   LLC 
  C R    R RC 
 Fi  L R RLLC 
 C RRR R Fcci 
 eRRR RRRC    
 CRRL R  C    
 Acf  R Fi    
   AcfRRC     
     Acci     
              
|----Layer 4|
              
     T        
              
       S      
              
          SS  
              
     S    SS  
 E       T    
              
 E  S         
              
              
     T        
              
|----Layer 5|
              
              
              
              
              
              
              
              
 a            
 C            
 N            
              
              
              
              
|----Layer 6|
              
              
              
              
              
              
              
              
 T            
              
 T            
              
              
              
              
}}



==== Materials ====

{| class="wikitable sortable mw-collapsible"
|-
! Name !! Total !! Layer 1 !! Layer 2 !! Layer 3 !! Layer 4 !! Layer 5 !! Layer 6 
|-
| {{BlockLink|Acacia Fence}} || 50 || - || - || 45 || 2 || 3 || - 
|-
| {{BlockLink|Acacia Fence Gate}} || 1 || - || - || 1 || - || - || - 
|-
| {{BlockLink|Dirt}} || 114 || 113 || 1 || - || - || - || - 
|-
| {{BlockLink|Short Grass}} || 31 || - || - || 31 || - || - || - 
|-
| {{BlockLink|Grass Block}} || 109 || - || 109 || - || - || - || - 
|-
| {{BlockLink|Tall Grass}} || 7 || - || - || 7 || - || - || - 
|-
| {{BlockLink|Torch}} || 5 || - || - || - || 3 || - || 2 
|-
| {{BlockLink|Water}} || 3 || - || 3 || - || - || - || - 
|}<noinclude>
[[Category:Village blueprints]]

[[fr:Village/Structure/Savane Enclos 2 plan]]
[[ja:村/構造/設計図/サバンナの牧柵2]]
[[zh:村庄/结构/图示/热带草原牲畜栏2]]
</noinclude>