<noinclude>{{structure info}}</noinclude>

[[File:Taiga Small House 5.png|thumb|Small House 5 (Taiga)]]



==== Blueprint ====

{{layered blueprint|name=
Taiga Small House 5|default=Layer 1
|S=Spruce Log
|P=Spruce Log+top
|C=Cobblestone
|R=Spruce Planks
|H=Chest
|U=Purple Bed+top+foot-rot-90
|L=Purple Bed+top+head-rot-90
|E=Spruce Trapdoor
|G=Glass Pane
|A=Large Fern
|a=Large Fern+bottom
|D=Spruce Door+bottom
|O=Spruce Door+top
|N=Glass Pane-rot-90
|W=Wall Torch-rot-180
|T=Wall Torch
|B=Cobblestone Stairs
         
|----Layer 1|
         
         
  P   P  
  CCCCC  
  CRRRC  
  CRRRC  
  CRRRC  
  CCCCC  
  PaBaP  
         
         
|----Layer 2|
         
         
  P   P  
  CCCCC  
  CL BC  
  CU  C  
  CH  C  
  CCDCC  
  PA AP  
         
         
|----Layer 3|
         
         
  PE EP  
  CCNCC  
 EC   CE 
  G   G  
 EC   CE 
  CCOCC  
  P   P  
         
         
|----Layer 4|
         
 S     S 
 SP   PS 
 SCCCCCS 
 SC W CS 
 SC   CS 
 SC T CS 
 SCCCCCS 
 SP W PS 
 S     S 
         
|----Layer 5|
         
  S   S  
  S   S  
  SCCCS  
  S   S  
  S   S  
  S   S  
  SCCCS  
  S   S  
  S   S  
         
|----Layer 6|
         
   S S   
   S S   
   SCS   
   S S   
   S S   
   S S   
   SCS   
   S S   
   S S   
         
|----Layer 7|
         
    S    
    S    
    S    
    S    
    S    
    S    
    S    
    S    
    S    
         
}}



==== Materials ====

{| class="wikitable sortable mw-collapsible"
|-
! Name !! Total !! Layer 1 !! Layer 2 !! Layer 3 !! Layer 4 !! Layer 5 !! Layer 6 !! Layer 7 
|-
| {{BlockLink|Chest}} || 1 || - || 1 || - || - || - || - || - 
|-
| {{BlockLink|Cobblestone}} || 67 || 16 || 15 || 12 || 16 || 6 || 2 || - 
|-
| {{BlockLink|Cobblestone Stairs}} || 2 || 1 || 1 || - || - || - || - || - 
|-
| {{BlockLink|Glass Pane}} || 3 || - || - || 3 || - || - || - || - 
|-
| {{BlockLink|Large Fern}} || 4 || 2 || 2 || - || - || - || - || - 
|-
| {{BlockLink|Purple Bed}} || 1 || - || 1 || - || - || - || - || - 
|-
| {{BlockLink|Spruce Door}} || 1 || - || 1 || - || - || - || - || - 
|-
| {{BlockLink|Spruce Log}} || 79 || 4 || 4 || 4 || 22 || 18 || 18 || 9 
|-
| {{BlockLink|Spruce Planks}} || 9 || 9 || - || - || - || - || - || - 
|-
| {{BlockLink|Spruce Trapdoor}} || 6 || - || - || 6 || - || - || - || - 
|-
| {{BlockLink|Torch}} || 3 || - || - || - || 3 || - || - || - 
|}<noinclude>
[[Category:Village blueprints]]

[[fr:Village/Structure/Taïga Petite Maison 5 plan]]
[[zh:村庄/结构/图示/针叶林小型房屋5]]
</noinclude>