<noinclude>{{structure info}}</noinclude>

[[File:Plains Medium House 1.png|thumb|Medium House 1 (Plains)]]



==== Blueprint ====

{{layered blueprint
|name=Village Plains Houses plains_medium_house_1
|default=Layer 2
|C=Cobblestone
|O=Oak Log+top
|S=Stripped Oak Log+top
|s=Stripped Oak Log-rot90
|a=Stripped Oak Log
|P=Oak Planks
|L=Oak Stairs
|F=Oak Stairs-rot90
|>=Oak Stairs-rot180
|V=Oak Stairs-rot270
|I=Oak Fence
|h=Oak Pressure Plate
|D=Oak Door+bottom
|d=Oak Door+top
|i=Torch
|T=Torch-rot90
|t=Torch-rot180
|q=torch-rot270
|G=Glass Pane
|g=Glass Pane-rot90
|W=White Bed+top-head-rot270
|w=White Bed+top-foot-rot270
             
|----Layer 1|
             
             
    SCCCCCS  
    CPPPPPC  
    CPPPPPC  
    CPPPPPC  
    CPPPPPC  
  SCCPPPPPC  
  CPPPPPPPC  
  CPPPPPPPC  
  CPPPPPPPC  
  CPPPPPPPC  
  SCCCCCCCS  
    F        
             
|----Layer 2|
             
             
    SCCCCCS  
    CIW WIC  
    C w w C  
    C     C  
    C     C  
  SCC    IC  
  C       C  
  C       C  
  C       C  
  C   LI> C  
  SCDCCCCCS  
             
             
|----Layer 3|
             
       i     
    SCCCCCS  
    Oh t hO  
    G     G  
    G     G  
    O     O  
  SPP    ha  
  O       O  
  G       G  
  G       G  
  O    h  O  
  SsdsOgOsS  
   t t       
             
|----Layer 4|
             
   >P     PL 
   >SCCCCCSL 
   >C     CL 
   >C     CL 
   >C     CL 
 VVPC     CV 
 PSPP    qCP 
  C       C  
  C       C  
  C       C  
  C i     C  
 PSPPPPPPPSP 
 FFFFFFFFFFF 
             
|----Layer 5|
             
    >P   PL  
    >POgOPL  
    >P   PL  
    >P   PL  
    >P   PL  
    >P   PL  
 VVVPP   PVV 
 PPPPP   PPP 
  C      PC  
  C      PC  
 PPPPPPPPPPP 
 FFFFFFFFFFF 
             
             
|----Layer 6|
             
     >P PL   
     >PCPL   
     >P PL   
     >P PL   
     >P PL   
     >P PL   
     >P PL   
 VVVVPP PPVV 
 PPPPPPPPPPP 
 PPPPPPPPPPP 
 FFFFFFFFFFF 
             
             
             
|----Layer 7|
             
      >PL    
      >PL    
      >PL    
      >PL    
      >PL    
      >PL    
      >PL    
      >PL    
 VVVVVPPPVVV 
 FFFFFFFFFFF 
             
             
             
             
}}

This structure resembles the [[Village/Structure (old)/Blueprints/Large_house|old Large House]] seen in [[Village/Structure (old)/Blueprints |pre-1.14 villages]], with some minor changes. It also contains two white beds and some furniture, which the original structure lacked.



==== Materials ====

{| class="wikitable sortable mw-collapsible"
|-
! Name !! Total !! Layer 1 !! Layer 2 !! Layer 3 !! Layer 4 !! Layer 5 !! Layer 6 !! Layer 7 
|-
| {{BlockLink|Cobblestone}} || 93 || 31 || 30 || 5 || 22 || 4 || 1 || - 
|-
| {{BlockLink|Glass Pane}} || 10 || - || - || 9 || - || 1 || - || - 
|-
| {{ItemLink|Oak Door}} || 1 || - || 1 || - || - || - || - || - 
|-
| {{BlockLink|Oak Fence}} || 4 || - || 4 || - || - || - || - || - 
|-
| {{BlockLink|Oak Log}} || 12 || - || - || 10 || - || 2 || - || - 
|-
| {{BlockLink|Oak Planks}} || 158 || 53 || - || 2 || 16 || 36 || 40 || 11 
|-
| {{BlockLink|Oak Pressure Plate}} || 4 || - || - || 4 || - || - || - || - 
|-
| {{BlockLink|Oak Stairs}} || 121 || 1 || 2 || - || 24 || 28 || 31 || 35 
|-
| {{BlockLink|Stripped Oak Log}} || 24 || 5 || 5 || 9 || 5 || - || - || - 
|-
| {{BlockLink|Torch}} || 6 || - || - || 4 || 2 || - || - || - 
|-
| {{BlockLink|White Bed}} || 2 || - || 2 || - || - || - || - || - 
|}<noinclude>
[[Category:Village blueprints]]

[[fr:Village/Structure/Plaines Maison Moyenne 1 plan]]
[[ja:村/構造/設計図/平原の中くらいの家1]]
[[zh:村庄/结构/图示/平原中型房屋1]]
</noinclude>