<noinclude>{{structure info}}</noinclude>

[[File:Plains Stable 1.png|thumb|Stable 1 (Plains)]]



==== Blueprint ====

{{layered blueprint
|name=Stable 1 stable-1
|default=Layer 1
|g=Grass Block+top
|P=Dirt Path+top
|d=Dirt
|i=Oak Door+bottom
|I=Oak Door+top
|p=Glass Pane
|a=Glass Pane-rot90
|c=Cobblestone
|h=Hay Bale+top
|t=Torch
|T=Torch-rot180
|r=Torch-rot270
|R=Torch-rot90
|o=Oak Log
|O=Oak Log-rot90
|w=Water+top
|f=Oak Fence
|l=Oak Planks
|x=Cobblestone Stairs
|X=Cobblestone Stairs-rot180
|y=Oak Stairs
|Y=Oak Stairs-rot180
                 
|----Layer 0|
                  
 gggggg           
 gggggg           
 gggggdddddddddd  
 gggggdggggggdgd  
 ggggggggggggdgd  
 gggdggggddggdgd  
 gggggddgddddddd  
 gggggggPggggggg  
 gggggggPggggggg  
                  
|----Layer 1|
                  
 ffffff           
 f    f           
 f    cccccccccc  
 f    h      owc  
 f           owc  
 f  h    hh  owc  
 f    cciccccccc  
 f    f           
 ffffff           
                  
|----Layer 2|
                  
 t    t           
                  
      cccOaOaOcc  
               o  
               p  
         h     o  
      ccIcOaOaOc  
                  
 t    t           
                  
|----Layer 3|
                  
                  
                  
      cccccccccc  
      x        c  
               c  
      X        c  
      cccccccccc  
                  
                  
                  
|----Layer 4|
                  
                  
     YYYYYYYYYYYY 
     yccccccccccy 
      c    T   c  
     rcR      rc  
      c    t   c  
     YccccccccccY 
     yyyyyyyyyyyy 
                  
                  
|----Layer 5|
                  
                  
                  
     YYYYYYYYYYYY 
     yc        cy 
      c        cR 
     Yc        cY 
     yyyyyyyyyyyy 
                  
                  
                  
|----Layer 6|
                  
                  
                  
                  
     YYYYYYYYYYYY 
     llllllllllll 
     yyyyyyyyyyyy 
                  
                  
                  
                  
}}

The cobblestone stairs in layer 3 are upside down.

==== Materials ====

{| class="wikitable sortable mw-collapsible"
|-
! Name !! Total !! Layer 0 !! Layer 1 !! Layer 2 !! Layer 3 !! Layer 4 !! Layer 5 !! Layer 6 
|-
| {{BlockLink|Cobblestone}} || 86 || - || 22 || 9 || 23 || 26 || 6 || - 
|-
| {{BlockLink|Cobblestone Stairs}} || 2 || - || - || - || 2 || - || - || - 
|-
| {{BlockLink|Dirt}} || 29 || 29 || - || - || - || - || - || - 
|-
| {{BlockLink|Dirt Path}} || 2 || 2 || - || - || - || - || - || - 
|-
| {{BlockLink|Glass Pane}} || 5 || - || - || 5 || - || - || - || - 
|-
| {{BlockLink|Grass Block}} || 86 || 86 || - || - || - || - || - || - 
|-  
| {{BlockLink|Hay Bale}} || 5 || - || 4 || 1 || - || - || - || - 
|-
| {{ItemLink|Oak Door}} || 1 || - || 1 || - || - || - || - || - 
|-
| {{BlockLink|Oak Fence}} || 21 || - || 21 || - || - || - || - || - 
|-
| {{BlockLink|Oak Log}} || 11 || - || 3 || 8 || - || - || - || - 
|-
| {{BlockLink|Oak Planks}} || 12 || - || - || - || - || - || - || 12 
|-
| {{BlockLink|Oak Stairs}} || 80 || - || - || - || - || 28 || 28 || 24 
|-
| {{BlockLink|Torch}} || 10 || - || - || 4 || - || 5 || 1 || - 
|-
| {{BlockLink|Water}} || 3 || - || 3 || - || - || - || - || - 
|}<noinclude>
[[Category:Village blueprints]]

[[fr:Village/Structure/Plaines Étable 1 plan]]
[[ja:村/構造/設計図/平原の厩舎1]]
[[zh:村庄/结构/图示/平原马厩1]]
</noinclude>