<noinclude>{{structure info}}</noinclude>

[[File:Desert Animal Pen 2.png|thumb|Animal pen 2 (Desert)]]



==== Blueprint ====

{{layered blueprint|name=Village Desert Houses animal_pen_2|default=Layer 1
|C=Cut Sandstone
|S=Smooth Sandstone Stairs
|z=Waterlogged Smooth Sandstone Stairs-rot90
|x=Waterlogged Smooth Sandstone Stairs-rot180
|y=Waterlogged Smooth Sandstone Stairs-rot270
|s=Waterlogged Smooth Sandstone Stairs
|G=Grass Block+top
|W=Sandstone Wall
|L=Smooth Sandstone Slab
|g=Jungle Fence Gate
|----Layer 1|
            
     SS     
 CCCCCCCCCC 
 CGGGGGGGGC 
 CGGGGGGGGC 
 CGGGGGGGGC 
 CGGGGGGGGC 
 CGGGGGGGGC 
 CCCCCCCCCC 
            
|----Layer 2|
            
            
 WWWWggWWWW 
 W        W 
 W        W 
 W zxx    W 
 W ssy    W 
 W        W 
 WWWWWWWWWW 
            
|----Layer 3-4|
            
            
            
            
            
 W        W 
            
            
 W        W 
            
|----Layer 5|
            
            
            
            
            
 LLLLLLLLLL 
 LLLLLLLLLL 
 LLLLLLLLLL 
 LLLLLLLLLL 
            
}}

All smooth sandstone slabs are bottom slabs. The water inside the stairs forms a rectangle.

==== Materials ====

{| class="wikitable sortable mw-collapsible"
|-
! Name !! Total !! Layer 1 !! Layer 2 !! Layer 3 !! Layer 4 !! Layer 5 
|-
| {{BlockLink|Cut Sandstone}} || 30 || 30 || - || - || - || - 
|-
| {{BlockLink|Grass Block}} || 40 || 40 || - || - || - || - 
|-
| {{BlockLink|Jungle Fence Gate}} || 2 || - || 2 || - || - || - 
|-
| {{BlockLink|Sandstone Wall}} || 36 || - || 28 || 4 || 4 || - 
|-
| {{BlockLink|Smooth Sandstone Slab}} || 40 || - || - || - || - || 40 
|-
| {{BlockLink|Smooth Sandstone Stairs}} || 8 || 2 || 6 || - || - || - 
|-
| {{BlockLink|Water}} || 6 || - || 6 || - || - || - 
|}<noinclude>
[[Category:Village blueprints]]

[[fr:Village/Structure/Désert Enclos 2 plan]]
[[ja:村/構造/設計図/砂漠の牧柵2]]
[[zh:村庄/结构/图示/沙漠牲畜栏2]]
</noinclude>