<noinclude>{{structure info}}</noinclude>

[[File:Plains Armorer House 1.png|thumb|Armorer House 1 (Plains)]]



==== Blueprint ====

{{layered blueprint
|name=Village Plains Houses plains_armorer_house_1
|default=Layer 2
|O=Oak Log+top
|L=Oak Log-rot90
|l=Oak Log
|C=Cobblestone
|c=Cobblestone Stairs
|B=Bricks
|X=Smooth Stone
|F=Blast Furnace-rot90
|d=Oak Door+bottom
|D=Oak Door+top
|)=Cobblestone Stairs-rot270
|^=Cobblestone Stairs-rot180
|(=Cobblestone Stairs-rot90
|T=torch-rot180
|t=torch-rot90
|k=torch-rot270
|<=Oak Stairs-rot90
|>=Oak Stairs-rot270
|s=Oak Stairs
|S=Oak Stairs-rot180
|p=Oak Slab
|o=Cobblestone Wall
|g=glass Pane
|G=glass Pane-rot90
|----Layer 1|
          
          
  OCCCCO  
  CCCCCC  
  CCCCCCC 
  CCCCBCC 
  CCCCCCC 
  CCCCCC  
  OCCCCO  
    cc    
          
|----Layer 2|
          
          
  OCCCCO  
  CXXXXC  
  CX  CCC 
  CX   FC 
  CX  CCC 
  CX   C  
  OCddCO  
          
|----Layer 3|
          
          
  OLGGLO  
  l    C  
  g   CC^ 
  lt   B) 
  g   CCc 
  l    C  
  OCDDCO  
   T  T   
          
|----Layer 4|
          
 <>    <> 
 <OCCCCO> 
 <C    Cs 
 <C   ^Cp 
 <C   CCp 
 <C   cCp 
 <C    CS 
 <OCCCCO> 
 <>    <> 
          
|----Layer 5|
          
  <>  <>  
  <CCCC>  
  <   k>  
  <    >  
  <   (C  
  <    >  
  <   k>  
  <CCCC>  
  <>  <>  
          
|----Layer 6|
          
   <><>   
   <CC>   
   <  >   
   <  >   
   <  >C  
   <  >   
   <  >   
   <CC>   
   <><>   
          
|----Layer 7|
          
    <>    
    <>    
    <>    
    <>    
    <> C  
    <>    
    <>    
    <>    
    <>    
          
|----Layer 8|
          
          
          
          
          
       o  
          
          
          
          
}}



==== Materials ====

{| class="wikitable sortable mw-collapsible"
|-
! Name !! Total !! Layer 1 !! Layer 2 !! Layer 3 !! Layer 4 !! Layer 5 !! Layer 6 !! Layer 7 !! Layer 8 
|-
| {{BlockLink|Blast Furnace}} || 1 || - || 1 || - || - || - || - || - || - 
|-
| {{BlockLink|Bricks}} || 2 || 1 || - || 1 || - || - || - || - || - 
|-
| {{BlockLink|Cobblestone}} || 102 || 40 || 20 || 8 || 19 || 9 || 5 || 1 || - 
|-
| {{BlockLink|Cobblestone Stairs}} || 8 || 2 || - || 3 || 2 || 1 || - || - || - 
|-
| {{BlockLink|Cobblestone Wall}} || 1 || - || - || - || - || - || - || - || 1 
|-
| {{BlockLink|Glass Pane}} || 4 || - || - || 4 || - || - || - || - || - 
|-
| {{ItemLink|Oak Door}} || 2 || - || 2 || - || - || - || - || - || - 
|-
| {{BlockLink|Oak Log}} || 21 || 4 || 4 || 9 || 4 || - || - || - || - 
|-
| {{BlockLink|Oak Slab}} || 3 || - || - || - || 3 || - || - || - || - 
|-
| {{BlockLink|Oak Stairs}} || 80 || - || - || - || 19 || 21 || 22 || 18 || - 
|-
| {{BlockLink|Smooth Stone}} || 8 || - || 8 || - || - || - || - || - || - 
|-
| {{BlockLink|Torch}} || 5 || - || - || 3 || - || 2 || - || - || - 
|}

<noinclude>
[[Category:Village blueprints]]

[[fr:Village/Structure/Plaines Enclos 3 plan]]
[[ja:村/構造/設計図/平原の防具鍛冶の家1]]
[[ko:마을/구조물/청사진/평원/갑옷 대장장이 집 1]]
[[zh:村庄/结构/图示/平原盔甲匠房屋]]
</noinclude>