<noinclude>{{structure info}}</noinclude>

[[File:Savanna Meeting Point 1.png|thumb|Meeting Point 1 (Savanna)]]



==== Blueprint ====

{{layered blueprint|name=
Savanna Meeting Point 1|default=Layer 1
|G=Grass Block+top
|D=Dirt
|A=Acacia Log+top
|B=Brown Wall Banner
|E=Bell
|R=Dirt Path+top
|C=Acacia Fence
|S=Short Grass
|T=Torch
|I=Acacia Slab
|c=Acacia Stairs
|t=Tall Grass
|L=Tall Grass+bottom
              
|----Layer 1|
              
 GGGGGGGGGGGG 
 GRRRGGGGGGGG 
 GGRGGDDRGRGG 
 RRRRGRRGRGRG 
 GGRRGRRRRRRR 
 RRRRRGRRRGRR 
 RGRGRRGRGRRG 
 RRGRGGGRGRGR 
 GGRGRRGRRRRR 
 RGGGRRRRGGGG 
 RGDRRRGRRDRG 
 RGDRRGRRRDRR 
 RGRGRRRRGGGR 
 RGRRRRRGRGRG 
              
|----Layer 2|
              
      L       
     C  C     
 SS   AA   C  
     C  C S   
 SS  S        
      S       
       S S    
   S   E S S  
 CS S  S      
  CSC    CSCS 
   A      A S 
  SA  S   A   
  C C    CSC  
  S     S S C 
              
|----Layer 3|
              
      t       
     C  C     
           T  
     C  C     
              
              
              
              
 T            
  C C    C C  
              
              
  C C    C C  
            T 
              
|----Layer 4|
              
              
     C  C     
              
     C  C     
              
              
              
              
              
  C C    C C  
              
              
  C C    C C  
              
              
|----Layer 5|
              
      BB      
     IccI     
     IccI     
     IccI     
              
              
              
              
              
  III    III  
 Bccc    cccB 
 Bccc    cccB 
  III    III  
              
              
}}



==== Materials ====

{| class="wikitable sortable mw-collapsible"
|-
! Name !! Total !! Layer 1 !! Layer 2 !! Layer 3 !! Layer 4 !! Layer 5 
|-
| {{BlockLink|Acacia Fence}} || 39 || - || 15 || 12 || 12 || - 
|-
| {{BlockLink|Acacia Log}} || 6 || - || 6 || - || - || - 
|-
| {{BlockLink|Acacia Slab}} || 18 || - || - || - || - || 18 
|-
| {{BlockLink|Acacia Stairs}} || 18 || - || - || - || - || 18 
|-
| {{BlockLink|Bell}} || 1 || - || 1 || - || - || - 
|-
| {{BlockLink|Brown Wall Banner}} || 6 || - || - || - || - || 6 
|-
| {{BlockLink|Dirt}} || 6 || 6 || - || - || - || - 
|-
| {{BlockLink|Short Grass}} || 25 || - || 25 || - || - || - 
|-
| {{BlockLink|Grass Block}} || 73 || 73 || - || - || - || - 
|-
| {{BlockLink|Dirt Path}} || 89 || 89 || - || - || - || - 
|-
| {{BlockLink|Tall Grass}} || 1 || - || 1 || - || - || - 
|-
| {{BlockLink|Torch}} || 3 || - || - || 3 || - || - 
|}<noinclude>
[[Category:Village blueprints]]

[[fr:Village/Structure/Savane Lieu de Rassemblement 1 plan]]
[[ja:村/構造/設計図/サバンナの集会所1]]
[[zh:村庄/结构/图示/热带草原会合点1]]
</noinclude>