<noinclude>{{structure info}}</noinclude>

[[File:Desert Meeting Point 3.png|thumb|Meeting point 3 (Desert)]]



==== Blueprint ====

{{layered blueprint|name=Desert Meeting Point 3
|default=Layer 1
|S=Sand
|M=Smooth Sandstone
|W=White Glazed Terracotta-rot-180
|X=White Glazed Terracotta-rot-90
|Y=White Glazed Terracotta-rot-270
|Z=White Glazed Terracotta
|H=Hay Bale
|h=Hay Bale+top
|C=Cut Sandstone
|T=Terracotta
|B=Bell+ceiling
|A=Sandstone Wall
|O=Smooth Sandstone Slab
|P=Potted Cactus
|R=Torch
|E=Potted Dead Bush
|N=Sandstone Slab
|a=Water+top
|D=Smooth Sandstone Stairs
                 
|----Layer 0|
                 
        SSSSSS   
     SSSSSSSSS S 
     SSSSSSSSS S 
  SSSSSSSSSSSSS  
   SSSSSSSSSSSSS 
 SSSSSSSSSSSSSSS 
 SSSSSSSSSSSSSSS 
 MMMMMSSSSSSSSSS 
 SMSMMMMMMMSSSSS 
 SMSMMSSSSMSSSSS 
 MMMMMSMMSMSSSS  
 SSSSMSMMSMSSSS  
  SSSMSSSSMSSSS  
 SSSSMMMMMMSSS   
    SSSMSMSSS    
                 
|----Layer 1|
                 
        P        
     EADA        
      ECE        
   H   CP        
      EC    A  A 
 h    ADA    WX  
             YZ  
 A A        A  A 
 W X             
 Y Z  CMMC       
 A A  MaaM       
      MaaM       
      CMMC       
                 
    C            
                 
|----Layer 2|
                 
                 
      A A        
       P         
       E         
       P    A  A 
      A A        
                 
 A A        A  A 
                 
   P  N  N       
 A A             
                 
      N  N       
                 
    C            
                 
|----Layer 3|
                 
                 
      A A        
                 
                 
            A  A 
      A A        
                 
 A A        A  A 
   B             
                 
 A A             
                 
                 
                 
    T            
                 
|----Layer 4|
                 
                 
      A A        
                 
                 
            OOOO 
      A A   O  O 
            O  O 
 OOO        OOOO 
 O O             
 O O             
 OOO             
                 
                 
                 
    R            
                 
|----Layer 5|
                 
                 
      OOO        
      O O        
      O O        
      O O        
      OOO        
                 
                 
                 
                 
                 
                 
                 
                 
                 
                 
}}



==== Materials ====

{| class="wikitable sortable mw-collapsible"
|-
! Name !! Total !! Layer 0 !! Layer 1 !! Layer 2 !! Layer 3 !! Layer 4 !! Layer 5 
|-
| {{BlockLink|Bell}} || 1 || - || - || - || 1 || - || - 
|-
| {{BlockLink|Cut Sandstone}} || 9 || - || 8 || 1 || - || - || - 
|-
| {{BlockLink|Hay Bale}} || 2 || - || 2 || - || - || - || - 
|-
| {{BlockLink|Potted Cactus}} || 5 || - || 2 || 3 || - || - || - 
|-
| {{BlockLink|Potted Dead Bush}} || 5 || - || 4 || 1 || - || - || - 
|-
| {{BlockLink|Sand}} || 151 || 151 || - || - || - || - || - 
|-
| {{BlockLink|Sandstone Slab}} || 4 || - || - || 4 || - || - || - 
|-
| {{BlockLink|Sandstone Wall}} || 40 || - || 12 || 12 || 12 || 4 || - 
|-
| {{BlockLink|Smooth Sandstone}} || 47 || 39 || 8 || - || - || - || - 
|-
| {{BlockLink|Smooth Sandstone Slab}} || 34 || - || - || - || - || 22 || 12 
|-
| {{BlockLink|Smooth Sandstone Stairs}} || 2 || - || 2 || - || - || - || - 
|-
| {{BlockLink|Terracotta}} || 1 || - || - || - || 1 || - || - 
|-
| {{BlockLink|Torch}} || 1 || - || - || - || - || 1 || - 
|-
| {{BlockLink|Water}} || 4 || - || 4 || - || - || - || - 
|-
| {{BlockLink|White Glazed Terracotta}} || 8 || - || 8 || - || - || - || - 
|}<noinclude>
[[Category:Village blueprints]]

[[fr:Village/Structure/Désert Lieu de Rassemblement 3 plan]]
[[ja:村/構造/設計図/砂漠の集会所3]]
[[zh:村庄/结构/图示/沙漠会合点3]]
</noinclude>