<noinclude>{{structure info}}</noinclude>

[[File:Taiga Medium House 3.png|thumb|Medium House 3 (Taiga)]]



==== Blueprint ====

{{layered blueprint|name=
Taiga Medium House 3|default=Layer 1
|G=Grass Block+top
|S=Spruce Log-rot-90
|D=Dirt
|C=Cobblestone
|P=Spruce Log
|R=Spruce Planks
|B=Bookshelf
|A=Crafting Table
|H=Chest
|L=Blue Bed+top+foot-rot-90
|U=Blue Bed+top+head-rot-90
|E=Large Fern
|e=Large Fern+bottom
|T=Spruce Trapdoor
|r=Dirt Path+top
|O=Spruce Door+bottom
|F=Spruce Fence
|p=Spruce Door+top
|N=Glass Pane-rot-90
|W=Wall Torch-rot-180
|a=Wall Torch
|I=Spruce Stairs
               
|----Layer 1|
               
               
 GDDDDDDDDDDD  
  DCCCCCCCCCD  
  DCCCCCCCCCD  
  DCCCDDDCCCD  
 G DCD   DCD   
   DCD G DCD   
    r  D  r    
               
|----Layer 2|
               
               
 eCCCCCCCCCCC  
  CUF IFI FUC  
  CL       LC  
  CH  CCC  AC  
   R R   R R   
   ROR   ROR   
               
               
|----Layer 3|
               
   T TT TT T   
 ECCNCCNCCNCC  
  C T  T  T C  
  C         C  
  C   CNC   C  
   R RT TR R   
   RpR   RpR   
               
               
|----Layer 4|
               
 SSSSSSSSSSSSS 
  CCCCCCCCCCC  
  C         C  
  C    a    C  
  C   CCC   C  
 SPRaRP PRaRPS 
  PRRRP PRRRP  
  P W P P W P  
               
|----Layer 5|
               
               
 SSSSSSSSSSSSS 
  CB       BC  
  CB       BC  
 SSSSSSSSSSSSS 
   PRP   PRP   
   PRP   PRP   
   P P   P P   
               
|----Layer 6|
               
               
               
 SSSSSSSSSSSSS 
 SSSSSSSSSSSSS 
    P     P    
    P     P    
    P     P    
    P     P    
               
}}



==== Materials ====

{| class="wikitable sortable mw-collapsible"
|-
! Name !! Total !! Layer 1 !! Layer 2 !! Layer 3 !! Layer 4 !! Layer 5 !! Layer 6 
|-
| {{BlockLink|Blue Bed}} || 2 || - || 2 || - || - || - || - 
|-
| {{BlockLink|Bookshelf}} || 4 || - || - || - || - || 4 || - 
|-
| {{BlockLink|Chest}} || 1 || - || 1 || - || - || - || - 
|-
| {{BlockLink|Cobblestone}} || 88 || 28 || 20 || 16 || 20 || 4 || - 
|-
| {{BlockLink|Crafting Table}} || 1 || - || 1 || - || - || - || - 
|-
| {{BlockLink|Dirt}} || 29 || 29 || - || - || - || - || - 
|-
| {{BlockLink|Glass Pane}} || 4 || - || - || 4 || - || - || - 
|-
| {{BlockLink|Grass Block}} || 3 || 3 || - || - || - || - || - 
|-
| {{BlockLink|Dirt Path}} || 2 || 2 || - || - || - || - || - 
|-
| {{BlockLink|Large Fern}} || 2 || - || 1 || 1 || - || - || - 
|-
| {{BlockLink|Spruce Door}} || 2 || - || 2 || - || - || - || - 
|-
| {{BlockLink|Spruce Fence}} || 3 || - || 3 || - || - || - || - 
|-
| {{BlockLink|Spruce Log}} || 99 || - || - || - || 27 || 38 || 34 
|-
| {{BlockLink|Spruce Planks}} || 30 || - || 8 || 8 || 10 || 4 || - 
|-
| {{BlockLink|Spruce Stairs}} || 2 || - || 2 || - || - || - || - 
|-
| {{BlockLink|Spruce Trapdoor}} || 11 || - || - || 11 || - || - || - 
|-
| {{BlockLink|Torch}} || 5 || - || - || - || 5 || - || - 
|}<noinclude>
[[Category:Village blueprints]]

[[fr:Village/Structure/Taïga Maison Moyenne 3 plan]]
[[ja:村/構造/設計図/タイガの中くらいの家3]]
[[zh:村庄/结构/图示/针叶林中型房屋3]]
</noinclude>