<noinclude>{{structure info}}</noinclude>

[[File:Snowy Tundra Library 1.png|thumb|Library 1 (Snowy tundra)]]



==== Blueprint ====

{{layered blueprint
|name=Snowy Library 1 snowy_library_1
|default=Layer 2
|w=Stripped Spruce Wood
|L=Lectern
|l=Lantern
|b=Bookshelf
|f=Spruce Fence
|p=Spruce Planks
|g=Glass Pane
|G=Glass Pane-rot90
|x=Spruce Stairs
|S=Snow
|s=Snow Block
|t=Torch-rot180
|o=Spruce Door+bottom
|O=Spruce Door+top
         
|----Layer 1|
         
 SSSSSSS 
 SSSsssS 
 SwwwwwS 
 swpppwS 
 SwpppwS 
 SwpppwS 
 swpppws 
 swpppwS 
 swpppwS 
 SwpppwS 
 SwwwwwS 
 SsSxssS 
 SSSSSSS 
         
|----Layer 2|
         
         
    SsS  
 SwwGww  
  wp pw  
  g   g  
  w L w  
  g   g  
 sw  bw  
 Sg   g  
  wf fw  
  wwoww  
     s   
         
|----Layer 3|
         
         
     S   
  wwGww  
  wl  w  
  g   g  
  w   w  
  g   g  
  w  bw  
  g   g  
  wt tw  
  wwOww  
         
|----Layer 4|
         
         
 p     p 
 pwwwwwp 
 pw   wp 
 pw   wp 
 pw   wp 
 pw   wp 
 pw  bwp 
 pw   wp 
 pw   wp 
 pwwwwwp 
 p     p 
         
|----Layer 5|
         
         
 p     p 
 pwwGwwp 
 pw   wp 
 pw   wp 
 pw   wp 
 pw   wp 
 pw  bwp 
 pw   wp 
 pw   wp 
 pwwGwwp 
 p     p 
         
|----Layer 6|
         
         
 Sp   pS 
 SpwGwpS 
 Sp  fpS 
 Sp  fpS 
 Sp  fpS 
 Sp lfpS 
 Sp  bpS 
 Sp  fpS 
 Sp  fpS 
 SpwGwps 
  p   pS 
         
|----Layer 7|
         
         
  p   p  
  pwwwp  
  p  bp  
  p  bp  
  p  bp  
  p fpp  
  p  bp  
  p  bp  
  p  bp  
  pwwwpS 
  p   p  
         
|----Layer 8|
         
         
  Sp pS  
  SpwpS  
  Sp pS  
  Sp pS  
  Sp pS  
  SpfpS  
  Sp pS  
  Sp pS  
  Sp pS  
  SpwpS  
  Sp pS  
         
|----Layer 9|
         
         
   SpS   
   SpS   
   SpS   
   SpS   
   SpS   
   SpS   
   SpS   
   SpS   
   SpS   
   SpS   
   SpS   
         
|----Layer 10|
         
         
    S    
    S    
    S    
    S    
    S    
    S    
    S    
    S    
    S    
    S    
    S    
         
}}



==== Materials ====

{| class="wikitable sortable mw-collapsible"
|-
! Name !! Total !! Layer 1 !! Layer 2 !! Layer 3 !! Layer 4 !! Layer 5 !! Layer 6 !! Layer 7 !! Layer 8 !! Layer 9 !! Layer 10 
|-
| {{BlockLink|Bookshelf}} || 11 || - || 1 || 1 || 1 || 1 || 1 || 6 || - || - || - 
|-
| {{BlockLink|Glass Pane}} || 18 || - || 7 || 7 || - || 2 || 2 || - || - || - || - 
|-
| {{BlockLink|Lantern}} || 2 || - || - || 1 || - || - || 1 || - || - || - || - 
|-
| {{BlockLink|Lectern}} || 1 || - || 1 || - || - || - || - || - || - || - || - 
|-
| {{BlockLink|Snow}} || 209 || 95 || 6 || 1 || - || - || 29 || 1 || 30 || 28 || 19 
|-
| {{BlockLink|Snow Block}} || 15 || 11 || 3 || - || - || - || 1 || - || - || - || - 
|-
| {{ItemLink|Spruce Door}} || 1 || - || 1 || - || - || - || - || - || - || - || - 
|-
| {{BlockLink|Spruce Fence}} || 10 || - || 2 || - || - || - || 6 || 1 || 1 || - || - 
|-
| {{BlockLink|Spruce Planks}} || 145 || 21 || 2 || - || 22 || 22 || 22 || 23 || 22 || 11 || - 
|-
| {{BlockLink|Spruce Stairs}} || 1 || 1 || - || - || - || - || - || - || - || - || - 
|-
| {{BlockLink|Stripped Spruce Wood}} || 114 || 24 || 16 || 16 || 24 || 22 || 4 || 6 || 2 || - || - 
|-
| {{BlockLink|Torch}} || 2 || - || - || 2 || - || - || - || - || - || - || - 
|}<noinclude>
[[Category:Village blueprints]]

[[fr:Village/Structure/Toundra enneigée Bibliothèque 1 plan]]
[[ja:村/構造/設計図/雪原の図書室1]]
[[zh:村庄/结构/图示/雪原图书馆]]
</noinclude>