<noinclude>{{structure info}}</noinclude>

[[File:Plains fisher cottage 1.png|thumb|Fisher Cottage 1 (Plains)]]



==== Blueprint ====
* [[Java Edition]]
{{layered blueprint|name=
Plains Fisher Cottage 1 (JE)
|default=Layer 1
|O=oak planks
|l=Oak Log
|L=Oak Log+top
|k=Oak Log-rot90
|s=Oak Stairs-rot180
|b=Oak Stairs-rot90
|B=Oak Stairs-rot270
|f=Oak Fence
|S=Oak Slab
|g=Glass Pane
|r=Barrel+top
|h=Chest
|w=Water+top
|d=Oak Door+bottom
|D=Oak Door+top
|t=Oak Trapdoor
|T=Torch
|u=Torch-rot180
|C=Cobblestone
|c=Cobblestone Stairs
|a=Cobblestone Stairs-rot90
|A=Cobblestone Stairs-rot270
|G=Grass Block+top
|i=Dirt
            
|----Layer 0|
            
 GGGGGGGGGG 
 GGGGGwwGGG 
 GGGGwwwwGG 
 GGwwwfwwwG 
 GwwwwfwwwG 
 GwwiiiiiwG 
 GwwiCiiiwG 
 GGwiCiiiGG 
 GGiiCiiiGG 
 GGGiiiiiGG 
 GGGGiiiGGG 
            
|----Layer 1|
            
            
        r   
            
      S     
      s     
    LCCCL   
    CwOOC   
    CwOOC   
   rCwOOC   
    LCCCL   
     acA    
            
|----Layer 2|
            
            
            
            
            
            
    LCdCL   
    C thC   
    C t C   
    C t C   
    LCdCL   
            
            
|----Layer 3|
            
            
            
            
            
            
    LCDCL   
    C   C   
    g   g   
    C   C   
    LCDCL   
            
            
|----Layer 4|
            
            
            
            
            
      T     
    LCCCL   
    C   C   
    C   C   
    C   C   
    LCCCL   
      u     
            
|----Layer 5|
            
            
            
            
            
   bB   bB  
   bLkkkLB  
   bl   lB  
   bl   lB  
   bl   lB  
   bLkkkLB  
   bB   bB  
            
|----Layer 6|
            
            
            
            
            
    bB bB   
    bCCCB   
    b   B   
    b   B   
    b   B   
    bCCCB   
    bB bB   
            
|----Layer 7|
            
            
            
            
            
     bOB    
     bOB    
     bOB    
     bOB    
     bOB    
     bOB    
     bOB    
            
}}

* [[Bedrock Edition]]
{{layered blueprint|name=
Plains Fisher Cottage 1 (BE)
|default=Layer 1
|O=oak planks
|l=Oak Log
|L=Oak Log+top
|k=Oak Log-rot90
|s=Oak Stairs-rot180
|b=Oak Stairs-rot90
|B=Oak Stairs-rot270
|f=Oak Fence
|S=Oak Slab
|g=Glass Pane
|r=Barrel+top
|h=Crafting Table
|w=Water+top
|d=Oak Door+bottom
|D=Oak Door+top
|t=Oak Trapdoor
|T=Torch
|u=Torch-rot180
|C=Cobblestone
|c=Cobblestone Stairs
|a=Cobblestone Stairs-rot90
|A=Cobblestone Stairs-rot270
|G=Grass Block+top
|i=Dirt
            
|----Layer 0|
            
 GGGGGGGGGG 
 GGGGGwwGGG 
 GGGGwwwwGG 
 GGwwwfwwwG 
 GwwwwfwwwG 
 GwwiiiiiwG 
 GwwiCiiiwG 
 GGwiCiiiGG 
 GGiiCiiiGG 
 GGGiiiiiGG 
 GGGGiiiGGG 
            
|----Layer 1|
            
            
            
            
      S     
      s     
    LCCCL   
    CwOOC   
    CwOOC   
    CwOOC   
    LCCCL   
     acA    
            
|----Layer 2|
            
            
            
            
            
            
    LCdCL   
    C thC   
    C t C   
    C trC   
    LCdCL   
            
            
|----Layer 3|
            
            
            
            
            
            
    LCDCL   
    C   C   
    g   g   
    C   C   
    LCDCL   
            
            
|----Layer 4|
            
            
            
            
            
      T     
    LCCCL   
    C   C   
    C   C   
    C   C   
    LCCCL   
      u     
            
|----Layer 5|
            
            
            
            
            
   bB   bB  
   bLkkkLB  
   bl   lB  
   bl   lB  
   bl   lB  
   bLkkkLB  
   bB   bB  
            
|----Layer 6|
            
            
            
            
            
    bB bB   
    bCCCB   
    b   B   
    b   B   
    b   B   
    bCCCB   
    bB bB   
            
|----Layer 7|
            
            
            
            
            
     bOB    
     bOB    
     bOB    
     bOB    
     bOB    
     bOB    
     bOB    
            
}}

The oak fences in layer 0 should be waterlogged. {{IN|bedrock}}, 2 barrels in layer 1 are not generated. Instead, a barrel generates in layer 2 inside the cottage. Also a chest is replaced by a crafting table.



==== Materials ====

{| class="wikitable sortable mw-collapsible"
|-
! Name !! Total !! Layer 0 !! Layer 1 !! Layer 2 !! Layer 3 !! Layer 4 !! Layer 5 !! Layer 6 !! Layer 7 
|-
| {{BlockLink|Barrel}} || 2{{only|JE|short=1}} 1{{only|BE|short=1}}|| - || 2{{only|JE|short=1}}|| 1{{only|BE|short=1}}|| - || - || - || - || -
|-
| {{BlockLink|Chest}}{{only|JE|short=1}}|| 1 || - || - || 1 || - || - || - || - || - 
|-
| {{BlockLink|Cobblestone}} || 51 || 3 || 12 || 10 || 8 || 12 || - || 6 || - 
|-
| {{BlockLink|Cobblestone Stairs}} || 3 || - || 3 || - || - || - || - || - || - 
|-
| {{BlockLink|Crafting Table}}{{only|BE|short=1}}|| 1 || - || - || 1 || - || - || - || - || - 
|-
| {{BlockLink|Dirt}} || 26 || 26 || - || - || - || - || - || - || - 
|-
| {{BlockLink|Glass Pane}} || 2 || - || - || - || 2 || - || - || - || - 
|-
| {{BlockLink|Grass Block}} || 53 || 53 || - || - || - || - || - || - || - 
|-
| {{ItemLink|Oak Door}} || 2 || - || - || 2 || - || - || - || - || - 
|-
| {{BlockLink|Oak Fence}} || 2 || 2 || - || - || - || - || - || - || - 
|- 
| {{BlockLink|Oak Log}} || 32 || - || 4 || 4 || 4 || 4 || 16 || - || - 
|- 
| {{BlockLink|Oak Planks}} || 13 || - || 6 || - || - || - || - || - || 7 
|-
| {{BlockLink|Oak Slab}} || 1 || - || 1 || - || - || - || - || - || - 
|-
| {{BlockLink|Oak Stairs}} || 51 || - || 1 || - || - || - || 18 || 18 || 14 
|-
| {{BlockLink|Oak Trapdoor}} || 3 || - || - || 3 || - || - || - || - || - 
|-
| {{BlockLink|Torch}} || 2 || - || - || - || - || 2 || - || - || - 
|- 
| {{BlockLink|Water}} || 31 || 28 || 3 || - || - || - || - || - || - 
|}

<noinclude>
[[Category:Village blueprints]]

[[fr:Village/Structure/Plaines Cabanon de Pêcheur 1 plan]]
[[ja:村/構造/設計図/平原の釣り小屋1]]
[[zh:村庄/结构/图示/平原渔夫小屋]]
</noinclude>