<noinclude>{{structure info}}</noinclude>

[[File:Desert Small House 4.png|thumb|Small house 4 (Desert)]]



==== Blueprint ====

{{layered blueprint
|name=Desert Small House 4 desert_small_house_4
|default=Layer 1
|a=Sand
|s=Smooth Sandstone
|t=Terracotta
|T=Torch
|B=Cyan Bed+top-head-rot180
|b=Cyan Bed+top-foot-rot180
|C=Chest
|c=Cut Sandstone
|S=Smooth Sandstone Slab+top
|w=Smooth Sandstone Stairs
|x=Smooth Sandstone Stairs-rot90
|y=Smooth Sandstone Stairs-rot180
|z=Smooth Sandstone Stairs-rot270
|j=Jungle Door+up+right
|J=Jungle Door+top
       
|----Layer 0|
       
 aaaaa 
 asssa 
 astsa 
 asssa 
 aasaa 
       
|----Layer 1|
       
 csssc 
 sBbCs 
 s   s 
 s   s 
 csjsc 
       
|----Layer 2|
       
 cs sc 
 s   s 
 s   s 
 s   s 
 csJsc 
       
|----Layer 3|
       
 csSsc 
 s   s 
 s   s 
 s T s 
 csssc 
       
|----Layer 4|
       
 tytyt 
 xSSSz 
 tSSSt 
 xSSSz 
 twtwt 
       
}}



==== Materials ====

{| class="wikitable sortable mw-collapsible"
|-
! Name !! Total !! Layer 0 !! Layer 1 !! Layer 2 !! Layer 3 !! Layer 4 
|-
| {{BlockLink|Chest}} || 1 || - || 1 || - || - || - 
|-
| {{BlockLink|Cut Sandstone}} || 12 || - || 4 || 4 || 4 || - 
|-
| {{BlockLink|Cyan Bed}} || 1 || - || 1 || - || - || - 
|-
| {{ItemLink|Jungle Door}} || 1 || - || 1 || - || - || - 
|-
| {{BlockLink|Sand}} || 15 || 15 || - || - || - || - 
|-
| {{BlockLink|Smooth Sandstone}} || 41 || 9 || 11 || 10 || 11 || - 
|-
| {{BlockLink|Smooth Sandstone Slab}} || 10 || - || - || - || 1 || 9 
|-
| {{BlockLink|Smooth Sandstone Stairs}} || 8 || - || - || - || - || 8 
|-
| {{BlockLink|Terracotta}} || 9 || 1 || - || - || - || 8 
|-
| {{BlockLink|Torch}} || 1 || - || - || - || 1 || - 
|}<noinclude>
[[Category:Village blueprints]]

[[fr:Village/Structure/Désert Petite Maison 4 plan]]
[[ja:村/構造/設計図/砂漠の小さな家4]]
[[zh:村庄/结构/图示/沙漠小型房屋4]]
</noinclude>