<noinclude>{{structure info}}</noinclude>

[[File:Savanna Fletcher House 1.png|thumb|Fletcher House 1 (Savanna)]]



==== Blueprint ====

{{layered blueprint|name=
Savanna Fletcher House 1|default=Layer 1
|G=Grass Block+top
|D=Dirt
|Y=Yellow Terracotta
|A=Acacia Log+top
|C=Acacia Planks
|I=Acacia Log
|F=Fletching Table
|S=Acacia Slab
|B=Brown Wall Banner
|R=Short Grass
|T=Acacia Stairs
|L=Glass Pane
|P=Poppy
|O=Torch
|E=Acacia Fence
|N=Glass Pane-rot-90
|U=Acacia Pressure Plate
|c=Acacia Door+bottom
|a=Acacia Door+top
|H=Dirt Path+top
|W=Wall Torch-rot-270
           
|----Layer 1|
           
 GGGGGGGGG 
 GGDDDGGGG 
 GDCCCDGGG 
 GDCCCCHHH 
 GDCCCDGGG 
 GDCCCDGGG 
 GDCCCDGGG 
 GDCCCCHHH 
 GDCCCDGGG 
 GGDDDGGGG 
 GGGGGGGGG 
           
|----Layer 2|
           
 RRRRRRR R 
   YYY  E  
  YTETY RR 
 RY   c    
 RYI  YRR  
  AF  ARE  
 RYI  YR   
 RY   c    
 RYTETYR R 
 R YYY  ER 
 RRPR RRR  
           
|----Layer 3|
           
           
   YNY  E  
  Y U Y    
  L   a    
  YO  Y    
  A   A E  
  YO  Y    
  L   a    
  Y U Y    
   YNY  E  
           
           
|----Layer 4|
           
           
   YNY  E  
  Y   Y    
  L   YW   
  Y   Y    
  A   A E  
  Y   Y    
  L   YW   
  Y   Y    
   YNY  E  
           
           
|----Layer 5|
           
    B      
   YYYSSSB 
  Y   YSS  
 BY   YSS  
  Y   YSS  
  A   ASSB 
  Y   YSS  
 BY   YSS  
  Y   YSS  
   YYYSSSB 
    B      
           
|----Layer 6|
           
 TTTTTTT   
 TCCCCCT   
 TC   CT   
 TC   CT   
 TC   CT   
 TC   CT   
 TC   CT   
 TC   CT   
 TC   CT   
 TCCCCCT   
 TTTTTTT   
           
|----Layer 7|
           
           
  TTTTT    
  TCCCT    
  TCCCT    
  TCCCT    
  TCCCT    
  TCCCT    
  TCCCT    
  TCCCT    
  TTTTT    
           
           
}}



==== Materials ====

{| class="wikitable sortable mw-collapsible"
|-
! Name !! Total !! Layer 1 !! Layer 2 !! Layer 3 !! Layer 4 !! Layer 5 !! Layer 6 !! Layer 7 
|-
| {{BlockLink|Acacia Door}} || 2 || - || 2 || - || - || - || - || - 
|-
| {{BlockLink|Acacia Fence}} || 11 || - || 5 || 3 || 3 || - || - || - 
|-
| {{BlockLink|Acacia Log}} || 10 || - || 4 || 2 || 2 || 2 || - || - 
|-
| {{BlockLink|Acacia Planks}} || 68 || 23 || - || - || - || - || 24 || 21 
|-
| {{BlockLink|Acacia Pressure Plate}} || 2 || - || - || 2 || - || - || - || - 
|-
| {{BlockLink|Acacia Slab}} || 20 || - || - || - || - || 20 || - || - 
|-
| {{BlockLink|Acacia Stairs}} || 60 || - || 4 || - || - || - || 32 || 24 
|-
| {{BlockLink|Brown Wall Banner}} || 7 || - || - || - || - || 7 || - || - 
|-
| {{BlockLink|Dirt}} || 18 || 18 || - || - || - || - || - || - 
|-
| {{BlockLink|Fletching Table}} || 1 || - || 1 || - || - || - || - || - 
|-
| {{BlockLink|Glass Pane}} || 8 || - || - || 4 || 4 || - || - || - 
|-
| {{BlockLink|Short Grass}} || 29 || - || 29 || - || - || - || - || - 
|-
| {{BlockLink|Grass Block}} || 52 || 52 || - || - || - || - || - || - 
|-
| {{BlockLink|Dirt Path}} || 6 || 6 || - || - || - || - || - || - 
|-
| {{BlockLink|Poppy}} || 1 || - || 1 || - || - || - || - || - 
|-
| {{BlockLink|Torch}} || 4 || - || - || 2 || 2 || - || - || - 
|-
| {{BlockLink|Yellow Terracotta}} || 60 || - || 16 || 12 || 14 || 18 || - || - 
|}<noinclude>
[[Category:Village blueprints]]

[[fr:Village/Structure/Savane Maison de Fléchier 1 plan]]
[[ja:村/構造/設計図/サバンナの矢師の家1]]
[[zh:村庄/结构/图示/热带草原制箭师房屋]]
</noinclude>