<noinclude>{{structure info}}</noinclude>

[[File:Taiga Masons House 1.png|thumb|Masons House 1 (Taiga)]]



==== Blueprint ====

{{layered blueprint|name=
Taiga Masons House 1|default=Layer 1
|G=Grass Block+top
|S=Spruce Log
|D=Dirt
|C=Cobblestone
|P=Spruce Planks
|R=Spruce Fence
|U=Spruce Trapdoor
|O=Potted Spruce Sapling
|W=Wall Torch-rot-180
|E=Spruce Door+bottom
|T=Stonecutter
|p=Spruce Door+top
|L=Glass Pane-rot-90
|B=Cobblestone Stairs
           
|----Layer 1|
           
 G       G 
  DDDDDDDG 
  DDDDDDDG 
  DDDDDDDG 
  DDDDDDDG 
  GGDDDGGG 
 GGGGDGGGG 
 GGGGGGGGG 
           
|----Layer 2|
           
 R       R 
  CCCCCCC  
  CPPPPPC  
  CPPPPPC  
  CCPPPCC  
   UCCCU   
 RU UBU UR 
   U   U   
           
|----Layer 3|
           
 S       S 
 SCCCCCCCS 
 SR  T  RS 
 SR     RS 
 SCCO BCCS 
 S  CEC  S 
 S       S 
           
           
|----Layer 4|
           
  S U U S  
  SCCLCCS  
  S     S  
  S     S  
  SC   CS  
  S CpC S  
  S W W S  
           
           
|----Layer 5|
           
   S   S   
   SCCCS   
   S W S   
   S   S   
   S   S   
   SCCCS   
   S   S   
           
           
|----Layer 6|
           
    S S    
    SCS    
    S S    
    S S    
    S S    
    SCS    
    S S    
           
           
|----Layer 7|
           
     S     
     S     
     S     
     S     
     S     
     S     
     S     
           
           
}}



==== Materials ====

{| class="wikitable sortable mw-collapsible"
|-
! Name !! Total !! Layer 1 !! Layer 2 !! Layer 3 !! Layer 4 !! Layer 5 !! Layer 6 !! Layer 7 
|-
| {{BlockLink|Cobblestone}} || 47 || - || 18 || 13 || 8 || 6 || 2 || - 
|-
| {{BlockLink|Cobblestone Stairs}} || 2 || - || 1 || 1 || - || - || - || - 
|-
| {{BlockLink|Dirt}} || 32 || 32 || - || - || - || - || - || - 
|-
| {{BlockLink|Glass Pane}} || 1 || - || - || - || 1 || - || - || - 
|-
| {{BlockLink|Grass Block}} || 28 || 28 || - || - || - || - || - || - 
|-
| {{BlockLink|Potted Spruce Sapling}} || 1 || - || - || 1 || - || - || - || - 
|-
| {{BlockLink|Spruce Door}} || 1 || - || - || 1 || - || - || - || - 
|-
| {{BlockLink|Spruce Fence}} || 8 || - || 4 || 4 || - || - || - || - 
|-
| {{BlockLink|Spruce Log}} || 63 || - || - || 14 || 14 || 14 || 14 || 7 
|-
| {{BlockLink|Spruce Planks}} || 13 || - || 13 || - || - || - || - || - 
|-
| {{BlockLink|Spruce Trapdoor}} || 10 || - || 8 || - || 2 || - || - || - 
|-
| {{BlockLink|Stonecutter}} || 1 || - || - || 1 || - || - || - || - 
|-
| {{BlockLink|Torch}} || 3 || - || - || - || 2 || 1 || - || - 
|}<noinclude>
[[Category:Village blueprints]]

[[fr:Village/Structure/Taïga Maison de Maçon 1 plan]]
[[zh:村庄/结构/图示/针叶林石匠屋]]
</noinclude>