<noinclude>{{structure info}}</noinclude>
Each of the jails have a [[Vindicator]] spawn in front of the doors.

;Large Jail Room (2x2_a1)
The two [[cobblestone stairs]] are upside down and face each other.

{{layered blueprint|name=Large Jail|default=Layer 0|W=Birch Planks|C=Cobblestone|c=Cobblestone Wall|I=Iron Door+Bottom|i=Iron Door+Top|S=Cobblestone Stairs|s=Cobblestone Slab|R=Lever|r=Iron Bars|B=Brown Carpet|b=Cauldron|w=Polished Andesite|v=EntitySprite:vindicator
|----Layer 0|
WWWWWWWWWWWWWWW
WWWWWWWWWWWWWWW
WWWWWWWWWWWWWWW
WWWWWWWWWWWWWWW
WWWWWWWWWWWWWWW
WWWWWWWWWWWWWWW
WWWWWWWWWWWWWWW
WWWWWWWWWWWWWWW
WWWWWWWWWWWWWWW
WWWWWWWWWWWWWWW
WWWWWWWWWWWWWWW
WWWWWWWWWWWWWWW
WWWWWWWWWWWWWWW
WWWWWWWWWWWWWWW
WWWWWWWWWWWWWWW
|----Layer 1|
CCCCCCCCCCCCCCC
CCCCCCCCCCCCCCC
CCCCCCCCCCCCCCC
CCCCCCCCCCCCCCC
CCCCCCCCCCCCCCC
CssssCsssCCCCCC
     ssssCCCCCC
     ssssCCCCCC
     CCCCCCCCCC
     sCCCCCCCCC
     sCCCCCCCCC
  v  sCCCCCCCCC
     sCCCCCCCCC
     CCCCCCCCCC
     sCCCCCCCCC
|----Layer 2|
CCCCCCCCCCCCCCC
C   BBCSS  B  C
C    bC    B  C
C   BBC      bC
CCICCCCICCCCCCC
c    c   Cb   C
         C   BC
         I   BC
     cCCCCCCCCC
      C   b   C
      C     BBC
      I       C
      C       C
     cC     BBC
      CCCCCCCCC
|----Layer 3|
CCCCCCCCCCCCCCC
C     C       C
C     C       C
C     C       C
CwiCrCwiCCCCCCC
cR   cR  r    C
        Rw    C
         i    C
     cCCCCCCCCC
      r       C
      C       C
      i       C
     Rw       C
     cC       C
      CCCCCCCCC
|----Layer 4-5|
CCCCCCCCCCCCCCC
C     C       C
C     C       C
C     C       C
CCCCCCCCCCCCCCC
c    c   C    C
         C    C
         C    C
     cCCCCCCCCC
      C       C
      C       C
      C       C
      C       C
     cC       C
      CCCCCCCCC
|----Layer 6|
CCCCCCCCCCCCCCC
CCCCCCCCCCCCCCC
CCCCCCCCCCCCCCC
CCCCCCCCCCCCCCC
CCCCCCCCCCCCCCC
C    C   CCCCCC
         CCCCCC
         CCCCCC
     CCCCCCCCCC
      CCCCCCCCC
      CCCCCCCCC
      CCCCCCCCC
      CCCCCCCCC
     CCCCCCCCCC
      CCCCCCCCC
|----Layer 7|
 
 
 
 
cccccccccc
         c
         c
         c
      cccc
      c
      c
      c
      c
      c
      c
}}

;Medium Jail Room (1x2_b1)
The Medium Jail is also known as the Redstone Jail.


All of the [[cobblestone stairs]] are upside down.

{{layered blueprint|name=Medium Jail|default=Layer 0|C=Cobblestone|W=Birch Planks|c=Cobblestone Wall|S=Cobblestone Stairs|s=Cobblestone Slab|B=Brown Carpet|b=Cauldron|R=Redstone Dust|I=Iron Door+Bottom|i=Iron Door+Top|r=Lever|v=EntitySprite:vindicator
|----Layer 0|
WWWWWWW
WCCCCCW
WCCCCCW
WCCCCCW
WCCCCCW
WCCCCCW
WCCCCCW
WCCCCCW
WCCCCCW
WCCCCCW
WCCCCCW
WCCCCCW
WCCCCCW
WCCCCCW
WWWWWWW
|----Layer 1|
CCCCCCC
CbB  BC
C B  BC
C     C
C     C
C SS sC
C SS  C
C SS sC
C     C
C  RRRC
C  R CC
CCCIICC
Cs   sC
Cs v sC
CC   CC
|----Layer 2|
C c c C
 
c     c
 
c     c
 
c     c
 
c     c
 
c    Rc
C CiiCC
c    rc
 
CC   CC
|----Layer 3|
CCcCcCC
C     C
c     c
C     C
c     c
C     C
c     c
C     C
c     c
C     C
c     c
CcCCCCC
c     c
C     C
CC   CC
|----Layer 4-6|
C c c C
 
c     c
 
c     c
 
c     c
 
c     c
 
c     c
 
c     c
 
CC   CC
|----Layer 7|
CCCCCCC
C  C  C
C  C  C
C  C  C
C  C  C
C  C  C
C  C  C
C  C  C
C  C  C
C  C  C
CCCCCCC
C     C
C     C
C     C
CCCCCCC
}}

;Small Jail Room (1x2_b2)

The [[oak wood stairs]] on Layer 1 past row 10 are upside down.<br />
The [[cobblestone stairs]] on Layer 4 are upside down and face inside.

{{layered blueprint|name=Small Jail|default=Layer 0|B=Birch Planks|C=Cobblestone|o=Oak Stairs|O=Oak Planks|c=Cobblestone Wall|S=Cobblestone Stairs|I=Iron Door+Bottom|i=Iron Door+Top|s=Cobblestone Slab|A=Brown Carpet|b=Cauldron|a=Lever|v=EntitySprite:vindicator
|----Layer 0|
BBBBBBB
BBBBBBB
BBBBBBB
BBBBBBB
BBBBBBB
BBBBBBB
BBBBBBB
BBBBBBB
BBBBBBB
BBBBBBB
BBBBBBB
BBBBBBB
BBBBBBB
BBBBBBB
BBBBBBB
|----Layer 1|
CCCCCCC
CCCCCCC
CCCCCCC
CCCCCCC
CCCCCCC
CCCCCCC
CCCCCCC
  csssc
o  sss
 
oo
Oo   v
Oo
oo
|----Layer 2|
CCCCCCC
C A   C
C A   C
C     C
C     C
Cb    C
CCCCICC
  c   c
|----Layer 3|
CCCCCCC
C     C
C     C
C     C
C     C
C     C
CCCCiCC
  ca  c
|----Layer 4|
CCCCCCC
C     C
S     C
S     C
S     C
C     C
CCCCCCC
  c   c
|----Layer 5 - 6|
CCCCCCC
C     C
C     C
C     C
C     C
C     C
CCCCCCC
|----Layer 7|
CCCCCCC
CCCCCCC
CCCCCCC
CCCCCCC
CCCCCCC
CCCCCCC
CCCCCCC
}}<noinclude>
[[fr:Manoir/Structure/Prisons]]
[[pt:Mansão da floresta/Estrutura/Prisões]]
[[zh:林地府邸/结构/监狱房]]
</noinclude>