<noinclude>{{structure info}}</noinclude>
; Stair with Side Entrance (1x2_c_stairs)
These stairs spawn with the entrance to the sides of the [[cobblestone stairs]].

{{layered blueprint|name=Woodland Mansion 1x2_c_stairs|default=Layer 0|A=Birch Planks|C=Cobblestone|D=Cobblestone Stairs|I=Red Carpet|J=Cobblestone Wall|L=Birch Stairs|M=Birch Stairs|N=Birch Stairs|O=Dark Oak Stairs|P=Dark Oak Planks|Q=Light Gray Wool|R=Black Wool|S=White Wool|T=Green Wool|U=Gray Wool|V=Dark Oak Stairs
|----Layer 0|
AAAAAAAAAAAAAAA
AAAAAAAAAAAAAAA
AAAAAAAAAAAAAAA
AAAAAAAAAAAAAAA
AAAAAAAAAAAAAAA
AAAAAAAAAAAAAAA
AAAAAAAAAAAAAAA
|----Layer 1|
         C
 
CCCCC     D
CCCCC    DCD
CCCCCC    D
CCCCCC
CCCDDC   C
|----Layer 2|
         C
DDD
CCCCC
CCCCC     C
CCCCCC
CCDIIC
CCD  D   C
|----Layer 3|
         C
CCCD
IIDCC
IIDCC     C
IIDCCC
II   J
II       C
|----Layer 4|
         C
  DCD
   DCC
   DCC    C
   DCC
     J
         C
|----Layer 5|
         C
   DCD
    DCC
    DCC   C
    DCC
    CJ
         C
|----Layer 6|
         C
    DCD
     DCC
     DCC  C
     DCC
    DCD
         C
|----Layer 7|
         C
     DCD
      DCC
      DCC C
      DCC
     DCD
         C
|----Layer 8|
         C
      DCD
       DCCD
       DCCC
       DCCD
      DCD
         C
|----Layer 9|
         C
       DCDAAA
        DCAAAA
        DCAAAA
        DCAAAA
       DCDAAA
         C
|----Layer 10|
         C
        DCLLLM
         IIIIM
         IIIIM
         IIIIM
        DCNNNN
         C
|----Layer 11|
O        CLLLLM
O        C    M
O             M
O             M
O             M
O        C    M
O        CNNNNN
|----Layer 12|
P        D
Q
Q
QR
Q
Q
P        D
|----Layer 13|
P
Q
Q
QR
Q
Q
P
|----Layer 14|
P
S
T
Q
T
S
P
|----Layer 15|
P
U
U
U
U
U
P
|----Layer 16 - 18|
P
Q
Q
Q
Q
Q
P
|----Layer 19|
V
V
V
V
V
V              
V
}}

;Stairs with Straight On Entrance (1x2_d_stairs)
There is no pillar of [[cobblestone]] supporting it and the entrance is straight on.

{{layered blueprint|name=Woodland Mansion 1x2_d_stairs|default=Layer 0|A=Birch Planks|C=Cobblestone|D=Cobblestone Stairs|E=White Carpet|G=Red Carpet|K=Birch Stairs|P=Dark Oak Stairs|R=Light Gray Wool|S=Black Wool|T=White Wool|U=Green Wool|V=Gray Wool|W=Dark Oak Stairs
|----Layer 0|
AAAAAAAAAAAAAAA
AAAAAAAAAAAAAAA
AAAAAAAAAAAAAAA
AAAAAAAAAAAAAAA
AAAAAAAAAAAAAAA
AAAAAAAAAAAAAAA
AAAAAAAAAAAAAAA

|----Layer 1|
     C
            DCE
           CCDG
           CCDG
           CCDG
            DCE
     C
|----Layer 2|
     C
           DCD
          CCD
          CCD
          CCD
           DCD
     C
|----Layer 3|
     C
          DCD
         CCD
         CCD
         CCD
          DCD
     C
|----Layer 4|
     C
         DCD
        CCD
        CCD
        CCD
         DCD
     C
|----Layer 5|
     C
        DCD
       CCD
       CCD
       CCD
        DCD
     C
|----Layer 6|
     C
       DCD
      CCD
      CCD
      CCD
       DCD
     C
|----Layer 7|
     C
      DCD
     CCD
     CCD
     CCD
      DCD
     C
|----Layer 8|
     C
     DCD
    CCD
    CCD
    CCD
     DCD
     C
|----Layer 9|
     C
CCCCCCD
CCCCCD
CCCCCD
CCCCCD
CCCCCCD
    AC
|----Layer 10|
KKKKKC
AKKKKC
AKGGG
AKGGG
AKGGG
AKKKKC
KKKKAC
|----Layer 11|
KKKKKC        P
K    C        P
K             P
K             P
K             P
K    C        P
KKKKKC        P
|----Layer 12|
     D        P
              R
              R
             SR
              R
              R
     D        P
|----Layer 13|
              P
              R
              R
             SR
              R
              R
              P
|----Layer 14|
              P
              T
              U
              R
              U
              T
              P
|----Layer 15|
              P
              V
              V
              V
              V
              V
              P
|----Layer 16 - 18|
              P
              R
              R
              R
              R
              R
              P
|----Layer 19|
              W
              W
              W
              W
              W
              W
              W
}}<noinclude>
[[fr:Manoir/Structure/Escaliers 2e au 3e étage]]
[[pt:Mansão da floresta/Estrutura/Escada do 2º para o 3º andar]]
[[zh:林地府邸/结构/2-3楼楼梯间]]
</noinclude>