<noinclude>{{structure info}}</noinclude>
; Map Room (2x2_b4)
Two [[Vindicator]]s and one [[Evoker]] spawns here
{{layered blueprint|name=Woodland Mansion Map Room|default=Layer 0|A=Birch Planks|C=Oak Planks|D=Oak Stairs|F=Oak Stairs|G=Oak Stairs|H=Oak Stairs|I=Oak Stairs|J=Oak Stairs|K=Oak Stairs|L=Oak Stairs|M=Bookshelf|N=Blue Carpet|O=Yellow Carpet|P=Lime Carpet|Q=Oak Fence|R=Torch|e=EntitySprite:evoker|v=EntitySprite:vindicator
|----Layer 0|
AAAAAAAAAAAAAAA
AAAAAAAAAAAAAAA
AAAAAAAAAAAAAAA
AAAAAAAAAAAAAAA
AAAAAAAAAAAAAAA
AAAAAAAAAAAAAAA
AAAAAAAAAAAAAAA
AAAAAAAAAAAAAAA
AAAAAAAAAAAAAAA
AAAAAAAAAAAAAAA
AAAAAAAAAAAAAAA
AAAAAAAAAAAAAAA
AAAAAAAAAAAAAAA
AAAAAAAAAAAAAAA
AAAAAAAAAAAAAAA
|----Layer 1|
     CCCCC
 
     D  D
          v
     FFFFF
    GCCCCCH
  I GCCCCCHeJ
    GCCCCCH
  I GCCCCCH J
    GCCCCCH
     KKKKK
           v
      L L
|----Layer 2|
     CMMMC
 
 
 
 
     NNNNO
     NNPPP
     NPPPP
     PPPNP
     POOPP
|----Layer 3 - 4|
     CMMMC
|----Layer 5|
|----Layer 6|
 
 
 
 
 
 
       Q
      QQQ
       Q
|----Layer 7|
 
 
 
 
 
 
       R
      RQR
       R
|----Layer 8 - 10|
 
 
 
 
 
 
 
       Q     
}}<noinclude>
[[fr:Manoir/Structure/Salle de la carte]]
[[pt:Mansão da floresta/Estrutura/Sala de mapas]]
[[zh:林地府邸/结构/地图房]]
</noinclude>