<noinclude>{{structure info}}</noinclude>
;Wood Arch Hallway
There are three empty layers of space above the blueprint. The chest has loot, and one vindicator spawns here.

The structure is called "1x2_b3".
{{layered blueprint|name=Wooden Loot Arches|default=Layer 0|B=Birch Planks|D=Dark Oak Log|C=Chest|v=EntitySprite:vindicator
|----Layer 0|
BBBBBBB
BBBBBBB
BBBBBBB
BBBBBBB
BBBBBBB
BBBBBBB
BBBBBBB
BBBBBBB
BBBBBBB
BBBBBBB
BBBBBBB
BBBBBBB
BBBBBBB
BBBBBBB
BBBBBBB
|----Layer 1|
   C
 D   D
 
 
 D v D
 
 
 D   D
 
 
 D   D
 
 
 D   D
|----Layer 2-3|
 
 D   D
 
 
 D   D
 
 
 D   D
 
 
 D   D
 
 
 D   D
|----Layer 4|
 
DDDDDDD
 
 
DDDDDDD
 
 
DDDDDDD
 
 
DDDDDDD
 
 
DDDDDDD
}}

;Gray Banner Room 
There are two layers of empty space above the blueprint. One vindicator spawns here. The banner is plain gray.

The structure is called "1x2_a1".
{{layered blueprint|name=Gray Banner Room|default=Layer 0|B=Birch Planks|C=Cobblestone|S=Cobblestone Stairs|s=Cobblestone Slab|b=Gray Banner|c=Chest|v=EntitySprite:vindicator
|----Layer 0|
BBBBBBB
BBBBBBB
BBBBBBB
BBBBBBB
BBBBBBB
BBBBBBB
BBBBBBB
BBBBBBB
BBBBBBB
BBBBBBB
BBBBBBB
BBBBBBB
BBBBBBB
BBBBBBB
BBBBBBB
|----Layer 1|
CCCCCCC
C     C
C  c  C
C CCC C
C CsC C
C CsC C
C CsC C
C CsC C
C CCC C
CSSSSSC
      C
   v  C
      C
C     C
CCCCCCC
|----Layer 2|
C     C
 
 
  CCC
  C C
  C C
  C C
  C C
C S S C
 
 
 
 
 
 
C     C
|----Layer 3|
 
 
 
  CCC
  C C
  C C
  C C
  C C
  S S
|----Layer 4|
 
 
 
  CCC
  C C
  C C
  C C
  S S
|----Layer 5|
 
 
 
  CCC
  CbC
  C C
  S S
|----Layer 6|
 
 
 
  sss
  s s
  s s
}}

;Fake End Portal Room 
The loot is in the trapped chest. There are three layers of empty space above the blueprint.

The structure is called "1x2_s2".

{{layered blueprint|name=Explosive End Portal Room|default=Layer 0|B=Birch Planks|G=Green Wool|O=Orange Wool|T=Trapped Chest|N=Tnt|S=Cobblestone Stairs|C=Infested Cobblestone
|----Layer 0|
BBBBBBB
BBBBBBB
BBBBBBB
BBBBBBB
BBBBBBB
BBBBBBB
BBBBBBB
BBBBBBB
BBBBBBB
BBBBBBB
BBBBBBB
BBBBBBB
BBBBBBB
BBBBBBB
BBBBBBB
|----Layer 1|
CCCCCCC
C     C
C     C
 
 
 
  OOO
  OOO
  OOO
 
  CCC
  CCC
  SSS
C     C
C     C
     
|----Layer 2|
 
 
 
 
 
 
 
 
 
 
  CCC
  SSS
|----Layer 3|
 
 
 
 
 
  GGG
 G   G
 G   G
 G   G
  GGG
  SSS
|----Layer 4|
 
 
 
 
 
  NTN
}}

;Obsidian Room 
The loot is a diamond block.

The structure is called "1x1_as3".

{{layered blueprint|name=Obsidian Room|default=Layer 0|B=Birch Planks|b=Block of Diamond|O=Obsidian
|----Layer 0|
BBBBBBB
BBBBBBB
BBBBBBB
BBBBBBB
BBBBBBB
BBBBBBB
BBBBBBB
|----Layer 1|
 
 
 
   O
|----Layer 2|
 
   O
  OOO
 OObOO
  OOO
   O
|----Layer 3|
 
 
   O
  OOO
   O
|----Layer 4|
 
 
 
   O
}}

;Checkerboard Room 
The loot is in the chest.

The structure is called "1x1_a4".

{{layered blueprint|name=Cage Room|default=Layer 0|F=Oak Fence|w=Birch Planks|W=Dark Oak Log|G=Gray Carpet|g=Light Gray Carpet|f=Chest
|----Layer 0|
wwwwwww
wwwwwww
wwwwwww
wwwwwww
wwwwwww
wwwwwww
wwwwwww
|----Layer 1|
WFFFFFW
FGgGgGF
FgGgGgF
FGgGgGF
FgGgGgF
FGgGgGF
WFGgGFW
|----Layer 2 - 4|
WFFFFFW
F     F
F     F
F     F
F     F
F     F
WF   FW
|----Layer 5|
WWWWWWW
W     W
W     W
W     W
W     W
W     W
WWWWWWW
|----Layer 6|
 
 
 
 
 
 
   f
}}

;Lava Room 
The loot is a diamond block.

The structure is called "2x2_s1".

{{layered blueprint|name=Lava Room|default=Layer 0|B=Birch Planks|b=Block of Diamond|O=Obsidian|o=Glass|L=Lava
|----Layer 0|
BBBBBBBBBBBBBBB
BBBBBBBBBBBBBBB
BBBBBBBBBBBBBBB
BBBBBBBBBBBBBBB
BBBBBBBBBBBBBBB
BBBBBBBBBBBBBBB
BBBBBBBBBBBBBBB
BBBBBBBBBBBBBBB
BBBBBBBBBBBBBBB
BBBBBBBBBBBBBBB
BBBBBBBBBBBBBBB
BBBBBBBBBBBBBBB
BBBBBBBBBBBBBBB
BBBBBBBBBBBBBBB
BBBBBBBBBBBBBBB
|----Layer 1|
 
 
 
 
    OOOOOOO
    OOOOOOO
    OOOOOOO
    OOOOOOO
    OOOOOOO
    OOOOOOO
    OOOOOOO
|----Layer 2|
 
 
 
 
 
     ooooo
     ooooo
     ooooo
     ooooo
     ooooo
|----Layer 3|
 
 
 
 
 
     ooooo
     oLLLo
     oLoLo
     oLLLo
     ooooo
|----Layer 4|
 
 
 
 
 
     ooooo
     oLLLo
     oLbLo
     oLLLo
     ooooo
|----Layer 5|
 
 
 
 
 
     ooooo
     oLLLo
     oLLLo
     oLLLo
     ooooo
|----Layer 6|
 
 
 
 
 
     ooooo
     ooooo
     ooooo
     ooooo
     ooooo
|----Layer 7|
 
 
 
 
    OOOOOOO
    OOOOOOO
    OOOOOOO
    OOOOOOO
    OOOOOOO
    OOOOOOO
    OOOOOOO
|----Layer 8 - 10|
 
 
 
 
    O     O
 
 
 
 
 
    O     O
}}

;Cobblestone X Cage 

The structure is called "1x1_as1".

{{layered blueprint|name=Cobblestone Treasure Room|default=Layer 0|C=Chest|c=Cobblestone|B=Birch Planks
|----Layer 0|
BBBBBBB
BBBBBBB
BBBBBBB
BBBBBBB
BBBBBBB
BBBBBBB
BBBBBBB
|----Layer 1|
ccccccc
c     c
c     c
c     c
c     c
cC    c
ccccccc
|----Layer 2|
cc   cc
c     c
 
 
 
c     c
cc   cc
|----Layer 3|
c c c c

c     c
 
c     c

c c c c
|----Layer 4|
c  c  c


c     c
 

c  c  c
|----Layer 5|
c c c c

c     c
 
c     c

c c c c
|----Layer 6|
cc   cc
c     c
 
 
 
c     c
cc   cc
|----Layer 7|
ccccccc
c c c c
ccccccc
c c c c
ccccccc
c c c c
ccccccc
}}

;Confusing Spiral Staircase With Loot 

The structure is called "1x2_b4".

{{layered blueprint|name=Confusing Spiral Staircase|default=Layer 0|A=Birch Planks|B=Oak Slab|C=Oak Slab|E=Dark Oak Planks|F=Oak Planks
|----Layer 0|
AAAAAAAAAAAAAAA
AAAAAAAAAAAAAAA
AAAAAAAAAAAAAAA
AAAAAAAAAAAAAAA
AAAAAAAAAAAAAAA
AAAAAAAAAAAAAAA
AAAAAAAAAAAAAAA
|----Layer 1|
BC           EE
CEEEEEEEEEEE EE
 E     CBC   E
 E EEEEEEEEEE
 E       EEE
 EEEEEEEEEE
           FB
|----Layer 2|
  BC         EE
 EEEEEEEEEEE EE
BE   CB   BC E
CE EEEEEEEEEE
 E       EEE
 EEEEEEEEEE
         CB
|----Layer 3|
    BC       EE
 EEEEEEEEEEECEE
 E CB       BE
 E EEEEEEEEEE
BE     CB EE
CEEEEEEEEEE
       CB
|----Layer 4|
      BC   CBEE
 EEEEEEEEEEE EE
 EB          E
 ECEEEEEEEEEE
 E   CB   EE
 EEEEEEEEEE
BC   CB
|----Layer 5|
        BCB  EE
 EEEEEEEEEEE EE
 E           E
 E EEEEEEEEEE
 EBCB     EE
 EEEEEEEEEE
  BCB
|----Layer 6 - 7|
             EE
 EEEEEEEEEEE EE
 E           E
 E EEEEEEEEEE
 E        EE
 EEEEEEEEEE
}}

;Spider Room 
The [[monster spawner]] spawns [[spider]]s. To recreate, {{control|use|text=use}} a spider [[spawn egg]] on the monster spawner.

The structure is called "1x1_as2".

{{layered blueprint|name=Spider Room|default=Layer 0|B=Birch Planks|b=cobweb+with-background|S=Monster Spawner
|----Layer 0|
BBBBBBB
BBBBBBB
BBBBBBB
BBBBBBB
BBBBBBB
BBBBBBB
BBBBBBB
|----Layer 1|
 
  b bb
bb b  b
  S bb
 b  b b
  bb
   b  b
|----Layer 2|
 
    b
   b
    b
 b  b b
   bb
   b bb
|----Layer 3|
b  bbb
   b
   b
      b
 
b  b bb
|----Layer 4|
   bb b
b     b
 
 
b     b
 
  bbb b
|----Layer 5|
 bb b b
bb  bbb
b  bbbb
   b  b
b  b  b
b     b
b  bb b
|----Layer 6|
   b bb
b
b     b
  bb  b
      b
  b
  b   b
|----Layer 7|
 b
 
b
b
b
b b   b
    b
}}

;Cage Room 
The structure is called "2x2_b5".

{{layered blueprint|name=Arena Room|default=Layer 0|B=Birch Planks|D=Dark Oak Fence|G=Dark Oak Fence Gate|f=Oak Fence|O=Oak Planks|L=Ladder|S=Double Smooth Stone Slab|s=Smooth Stone Slab|o=Oak Stairs|C=Chest
|----Layer 0|
BBBBBBBBBBBBBBB
BBBBBBBBBBBBBBB
BBBBBBBBBBBBBBB
BBBBBBBBBBBBBBB
BBBBBBBBBBBBBBB
BBBBBBBBBBBBBBB
BBBBBBBBBBBBBBB
BBBBBBBBBBBBBBB
BBBBBBBBBBBBBBB
BBBBBBBBBBBBBBB
BBBBBBBBBBBBBBB
BBBBBBBBBBBBBBB
BBBBBBBBBBBBBBB
BBBBBBBBBBBBBBB
BBBBBBBBBBBBBBB
|----Layer 1|
       O
       L
 
 
    SSSSSSS
    SSSSSSS
    SSSSSSS
    SSSSSSS
    SSSSSSS
    SSSSSSS
    SSSSSSS
        sss
|----Layer 2-3|
       O
       L
 
 
    DDDDDDD
    D     D
    D     D
    D     D
    D     D
    D     D
    DDDDDGD
|----Layer 4|
       O
       L
|----Layer 5|
      oOo
       L
 
 
 
 
 
o             o
 
 
 
 
 
 
       o
|----Layer 6|
OOOOOOOOOOOOOOO
OOOOOOOLOOOOOOO
OOOOOOOOOOOOOOO 
OOO         OOO
OOO         OOO
OOO         OOO
OOO         OOO
OOO         OOO
OOO         OOO
OOO         OOO
OOO         OOO
OOO         OOO
OOOOOOOOOOOOOOO
OOOOOOOOOOOOOOO
OOOOOOOOOOOOOOO
|----Layer 7|
       O
       L
  fffffffffff
  f         f
  f         f
  f         f
  f         f
C f         f
  f         f
  f         f
  f         f
  f         f
  fffffffffff
|----Layer 8-10|
       O
       L
  f         f
 
 
 
 
 
 
 
 
 
  f         f
}}

;Roof-Chest Room 
The chests are hidden in the "attic."

The structure is called "1x2_se1".

{{layered blueprint|name=Roof-Chest Room|default=Layer 0|D=Dark Oak Log|d=Dark Oak Planks|B=Birch Planks|b=Chest|A=Dark Oak Stairs
|----Layer 0|
BBBBBBB
BBBBBBB
BBBBBBB
BBBBBBB
BBBBBBB
BBBBBBB
BBBBBBB
BBBBBBB
BBBBBBB
BBBBBBB
BBBBBBB
BBBBBBB
BBBBBBB
BBBBBBB
BBBBBBB
|----Layer 1|
 D   D
D     D
 
 
 
D     D
 
 
 
D     D
 
 
 
D     D
 D   D
|----Layer 2|
 DdddD
D     D
d     d
d     d
d     d
D     D
 
 
 
D     D
d     d
d     d
d     d
D     D
 DdddD
|----Layer 3|
 Dd dD
D     D
d     d
 
d     d
D     D
 
 
 
D     D
d     d
 
d     d
D     D
 Dd dD
|----Layer 4|
 D d D
D     D
       
d     d
       
D     D
 
 
 
D     D
       
d     d
       
D     D
 D d D
|----Layer 5|
 Dd dD
D     D
d     d
       
d     d
D     D
 
 
 
D     D
d     d
       
d     d
D     D
 Dd dD
|----Layer 6|
 DdddD
D     D
d     d
d     d
d     d
D     D
d
d
d
D     D
d     d
d     d
d     d
D     D
 DdddD
|----Layer 7|
D     D
D     D
D     D
D     D
D     D
D     D
D     D
D     D
D     D
D     D
D     D
D     D
D     D
D     D
D     D
|----Layer 8|
AdddddA
AdddddA
AdddddA
AdddddA
AdddddA
AdddddA
AdddddA
AdddddA
AdddddA
AdddddA
AdddddA
AdddddA
AdddddA
AdddddA
AdddddA
|----Layer 9|
 
   b
 
 
 
 
 
 
 
 
 
 
 
   b
}}

;Lone Chest Room 
The structure is called "1x2_s1".

{{layered blueprint|name=Lone Chest Room|default=Layer 0|B=Birch Planks|b=Dark Oak Fence|C=Chest|c=Torch
|----Layer 0|
BBBBBBB
BBBBBBB
BBBBBBB
BBBBBBB
BBBBBBB
BBBBBBB
BBBBBBB
BBBBBBB
BBBBBBB
BBBBBBB
BBBBBBB
BBBBBBB
BBBBBBB
BBBBBBB
BBBBBBB
|----Layer 1|
 
 b   b
 
 
 
 
 
 
 
 
   C
 
 
 b   b
|----Layer 2|
 
 c   c
 
 
 
 
 
 
 
 
 
 
 
 c   c
}}<noinclude>
[[fr:Manoir/Structure/Salles de butin]]
[[pt:Mansão da floresta/Estrutura/Salas com saque]]
[[zh:林地府邸/结构/战利品房间]]
</noinclude>