<noinclude>{{structure info}}</noinclude>
;Pumpkin Room
The ladders in this room depend on the walls around them. Layers 5 and 6 are empty.

The structure is called "1x1_a2"

{{layered blueprint|name=Pumpkin Room|default=Layer 0|D=Dark Oak Stairs|C=Cobblestone|R=Rail|P=Pumpkin|B=Birch Planks|L=Ladder|S=Cobblestone Stairs
|----Layer 0|
BBBBBBB
BBBBBBB
BBBBBBB
BBBBBBB
BBBBBBB
BBBBBBB
BBBBBBB
|----Layer 1|
CSSSSSC
S     S
S     S
S     S
S     S
S     S
C     C
|----Layer 2|
CLLLLLC
L     L
L     L
L     L
L     L
L     L
C     C
|----Layer 3|
CSSSSSC
S     S
S     S
S     S
S     S
S     S
C     C
|----Layer 4|
RRRPRRR
R     R
R     R
R     R
R     R
R     R
R     R
|----Layer 5-6|
|----Layer 7|
DDDDDDD
D     D
D     D
D     D
D     D
D     D
D     D
}}

;Flower Room
The [[flower pot]]s have two [[allium]]s, one [[azure bluet]], one [[blue orchid]], and one [[oxeye daisy]].<br />

The structure is called "1x1_a1"

{{layered blueprint|name=Flower Room|default=Layer 0|R=Birch Planks|C=Cobblestone|W=Cobblestone Wall|S=Cobblestone Stairs|A=Potted Allium|B=Potted Azure Bluet|O=Potted Blue Orchid|D=Potted Oxeye Daisy
|----Layer 0|
RRRRRRR
RRRRRRR
RRRRRRR
RRRRRRR
RRRRRRR
RRRRRRR
RRRRRRR
|----Layer 1|
CCCCCCC
CCCCCCC
C     C
C     C
C     C
C     C
CC   CC
|----Layer 2|
CSSSSSC
SABAODS
C     C
C     C
C     C
C     C
CC   CC
|----Layer 3|
W     W 
|----Layer 4-7|
W     W
}}

;White Tulip Sanctuary Room
The flower pot has a white tulip in it. Layers 5-6 are empty.

The structure is called "1x1_a5"

{{layered blueprint|name=White Tulip Room|default=Layer 0|R=Birch Planks|C=Cobblestone|S=Cobblestone Stairs|c=Cobblestone Slab|F=Potted White Tulip|D=Dark Oak Stairs|d=Dark Oak Planks
|----Layer 0|
RRRRRRR
RRRRRRR
RRRRRRR
RRRRRRR
RRRRRRR
RRRRRRR
RRRRRRR
|----Layer 1|
CCCCCCC
C ccc C
C ccc C
C     C
CS   SC
CC   CC
CC   CC
|----Layer 2|
CCCFCCC
C     C
C     C
C     C
C     C
CS   SC
CC   CC
|----Layer 3|
 SCSCS
|----Layer 4|
  SCS
|----Layer 5-6|
|----Layer 7|
DDDDDDD
D     D
D     D
ddddddd
D     D
D     D
DDDDDDD
}}

;Allium Room
Layers 5 and 6 are empty. The chest contains 8 alliums. All of the flower pots have alliums in them. There are 3 empty layers above the blueprint. The cauldron is completely full.

The structure is called "1x1_b5"


{{layered blueprint|name=Allium Room|default=Layer 0|R=Birch Planks|O=Oak Planks|F=Oak Fence|f=Potted Allium|V=Vines|C=Cauldron|c=Chest
|----Layer 0|
RRRRRRR
RRRRRRR
RRRRRRR
RRRRRRR
RRRRRRR
RRRRRRR
RRRRRRR
|----Layer 1|
 OOOOO
 C   O
     O
     O
 
c
|----Layer 2|
 FfffF
     f
     f
     F
|----Layer 3|
 F   F
 
 
     F
|----Layer 4|
 OOOOO
 VVVVO
    VO
    VO
|----Layer 5-6|
|----Layer 7|
FFFFFFFF
FFFFFFFF
FFFFFFFF
FFFFFFFF
FFFFFFFF
FFFFFFFF
FFFFFFFF
FFFFFFFF
}}

;Birch Pillar Room
The structure is called "1x1_as4"

{{layered blueprint|name=Birch Pillar Room|default=Layer 0|B=Birch Planks
|----Layer 0|
BBBBBBB
BBBBBBB
BBBBBBB
BBBBBBB
BBBBBBB
BBBBBBB
BBBBBBB
|----Layer 1-6|
 
 B   B
 
 
 
 B   B
|----Layer 7|
 
 BB BB
 B   B
  
 B   B
 BB BB
}}

;Birch Arches Room
Layer 8 is empty.

The structure is called "1x1_b1"

{{layered blueprint|name=Birch Arches Room|default=Layer 0|B=Birch Planks|L=Birch Slab|S=Birch Stairs|F=Birch Fence|f=Potted Azure Bluet|C=Pink Carpet
|----Layer 0|
BBBBBBB
BBBBBBB
BBBBBBB
BBBBBBB
BBBBBBB
BBBBBBB
BBBBBBB
|----Layer 1|
BS   SB
SS   SS
 
 
 
S
SS
|----Layer 2|
F     F
 
 
 
 
 
Cf
|----Layer 3|
F     F
|----Layer 4|
B     B
|----Layer 5|
F     F
|----Layer 6|
BL   LB
|----Layer 7|
 LSBSL
|----Layer 8|
|----Layer 9|
SSSSSSS
S     S
S     S
S     S
S     S
S     S
SSSSSSS
|----Layer 10|
BBBBBBB
B  S  B
B  L  B
BSLLLSB
B  L  B
B  S  B
BBBBBBB
}}

;Chicken Room
The structure is called "1x2_d5"

{{layered blueprint|name=Chicken Room|default=Layer 0|B=Birch Planks|W=White Wool|G=Gray Wool|O=Orange Wool
|----Layer 0|
BBBBBBB
BBBBBBB
BBBBBBB
BBBBBBB
BBBBBBB
BBBBBBB
BBBBBBB
BBBBBBB
BBBBBBB
BBBBBBB
BBBBBBB
BBBBBBB
BBBBBBB
BBBBBBB
BBBBBBB
|----Layer 1|
 
 
 
 
 
 
  O O
  O O
|----Layer 2|
 
 
 
 
 
 
  O O
|----Layer 3|
 
 
 
 
 
  WWW
  OWO
  WWW
|----Layer 4-5|
 
 
 
 
  WWW
 WWWWW
 WWWWW
 WWWWW
  WWW
|----Layer 6|
 
 
 
 
  WWW
 WWWWW
 WWWWW
 WWWWW
  WWW
  WWW
  OOO
|----Layer 7|
 
 
 
 
 
 
 
  WWW
  WWW
  WWW
|----Layer 8|
 
 
 
 
 
 
 
  WWW
  WWW
  GWG
|----Layer 9|
 
 
 
 
 
 
 
  WWW
  WWW
  WWW
}}


;Cat Room
There is an extra 3 blocks of empty space above the blueprint.

The structure is called "1x2_d4"

{{layered blueprint|name=Cat Room|default=Layer 0|B=Birch Planks|W=White Wool|A=Black Wool|L=Lime Wool
|----Layer 0|
BBBBBBB
BBBBBBB
BBBBBBB
BBBBBBB
BBBBBBB
BBBBBBB
BBBBBBB
BBBBBBB
BBBBBBB
BBBBBBB
BBBBBBB
BBBBBBB
BBBBBBB
BBBBBBB
BBBBBBB
|----Layer 1|
 
 
 W   W 
 A   A
 A   A
 AWWWA
 AAAAA
  AAA
  AAA
 WAAAW
 AAAAA
 AAAAA
 AAAAA
 AAAAA
|----Layer 2|
 
 
 
 
 
  AWA
 AAAAA
 AAAAA
  AAA
  AAA
  AAA
 AAAAA
 AAAAA
 AAAAA
|----Layer 3|
 
 
 
  AWA
  AAA
  AAA
  AAA
 AAAAA
  AAA
  AAA
  AAA
  AAA
 AAAAA
 AAAAA
|----Layer 4|
 
 
 
  LAL
  AAA
  AAA
   A
   A
   A
   A
  AAA
  AAA
  AAA
|----Layer 5|
 
 
 
  AAA
  AAA
  AAA
 
 
 
 
 
 
 
   A
|----Layer 6|
 
 
 
     
  W W
     
 
 
 
 
 
 
 
   A
|----Layer 7|
 
 
 
     
     
     
 
 
 
 
   W
   A
   A
    
}}

;Tree Room With Water
Place [[water]] where there is water blocks on Layer 2.

The structure is called "2x2_a4"

The [[Tree|dark oak tree]] is a custom tree, not normally able to be grown in vanilla.
{{layered blueprint|name=Tree Room|default=Layer 0|L=Dark Oak Log|l=Dark Oak Leaves|S=Polished Andesite|s=Smooth Stone Slab|D=Dirt|d=Water|B=Birch Planks
|----Layer 0|
BBBBBBBBBBBBBBB
BBBBBBBBBBBBBBB
BBBBBBBBBBBBBBB
BBBBBBBBBBBBBBB
BBBBBBBBBBBBBBB
BBBBBBBBBBBBBBB
BBBBBBBBBBBBBBB
BBBBBBBBBBBBBBB
BBBBBBBBBBBBBBB
BBBBBBBBBBBBBBB
BBBBBBBBBBBBBBB
BBBBBBBBBBBBBBB
BBBBBBBBBBBBBBB
BBBBBBBBBBBBBBB
BBBBBBBBBBBBBBB
|----Layer 1|
 
 
 SSSSS  ssssss
 SDDDS  sSSSSs
 SDDDS  sSSSSs
 SDDDS  sSSSSs
 SSSSS  sSSSSs
        sSSSSs
        sSSSSs
 ssssssssSSSSs
 sSSSSSSSSSSSs
 sSSSSSSSSSSSs
 sSSSSSSSSSSSs
 sSSSSSSSSSSSs
 sssssssssssss
|----Layer 2|
 
 
 
 
   L      SSS
          SdS
          S S
          S S
          S S
          S S
          S S
 SSSSSSSSSS S
 Sd         S
 SSSSSSSSSSSS
|----Layer 3|
 
 
 
 
   L
|----Layer 4|
 
 
   l
  lll
 llLll
  lll
   l
|----Layer 5|
 
 
  lll
 lllll
 llLll
 lllll
  lll
|----Layer 6|
 
 
  lll
 lllll
 lllll
 lllll
  lll
|----Layer 7|
 
 
 
  lll
  lll
  lll
}}

;Sapling Room
The chest has 28 dark oak saplings in it.

The structure is called "1x2_a4"

{{layered blueprint|name=Sapling Room|default=Layer 0|B=Birch Planks|O=Oak Planks|S=Dark Oak Sapling|L=Ladder|C=Chest|G=Green Carpet|D=Dirt
|----Layer 0|
BBBBBBB
BBBBBBB
BBBBBBB
BBBBBBB
BBBBBBB
BBBBBBB
BBBBBBB
BBBBBBB
BBBBBBB
BBBBBBB
BBBBBBB
BBBBBBB
BBBBBBB
BBBBBBB
BBBBBBB
|----Layer 1|
OOOOOOO
O     L
OLGGGGG
O GGGGG
O GGGGG
O GGG C
O GGGLO
OLGGG O
O GGG O
O GGG O
O GGG O
O GGG O
OLGGGLO
O     O
OOOOOOO
|----Layer 2|
DDDDDDD
D     L
D
D
D
D
D    LD
DL    D
D     D
D     D
D     D
D     D
DL   LD
D     D
DDDDDDD
|----Layer 3|
SSSSSSS
S     L
S
S
S
S
S    LS
SL    S
S     S
S     S
S     S
S     S
SL   LS
S     S
SSSSSSS
|----Layer 4|
OOOOOOO
O     L
O
O
O
O
O    LO
OL    O
O     O
O     O
O     O
O     O
OL   LO
O     O
OOOOOOO
|----Layer 5|
DDDDDDD
D     L
D
D
D
D
D    LD
DL    D
D     D
D     D
D     D
D     D
DL   LD
D     D
DDDDDDD
|----Layer 6|
SSSSSSS
S     L
S
S
S
S
S    LS
SL    S
S     S
S     S
S     S
S     S
SL   LS
S     S
SSSSSSS
|----Layer 7|
OOOOOOO
O     L
O
O
O
O
O    LO
OL    O
O     O
O     O
O     O
O     O
OL   LO
O     O
OOOOOOO
}}

;Wool Pile Room
There are three layers of empty layers above the blueprints

The structure is called "1x2_a5"

{{layered blueprint|name=Wool Piles|default=Layer 0|B=Birch Planks|W=Blue Wool|C=Cyan Wool|L=Light Blue Wool
|----Layer 0|
BBBBBBB
BBBBBBB
BBBBBBB
BBBBBBB
BBBBBBB
BBBBBBB
BBBBBBB
BBBBBBB
BBBBBBB
BBBBBBB
BBBBBBB
BBBBBBB
BBBBBBB
BBBBBBB
BBBBBBB
|----Layer 1|
LLLLWWW
LLLWWWW
LLLLWWW
LLLLWWW
LLLLWWW
LLLLWWW
CCLC  W
CCC
CCC
CC
|----Layer 2|
LLLWWWW
LLLWWWW
LLLLWWW
LLLL WW
LLLLLW
L LL  W
CC
CC
C
|----Layer 3|
L   WWW
LL  WWW
L   W
L
LLL
L
C
C
|----Layer 4|
    WWW
      W
 
L
 
 
C
}}

;Tree Chopping Room
The structure is called "1x2_a6"

{{layered blueprint|name=Tree Chopping|default=Layer 0|L=Dark Oak Log|l=Dark Oak Leaves|D=Dirt|d=Dark Oak Planks|B=Birch Planks|C=Chest
|----Layer 0|
BBBBBBB
BBBBBBB
BBBBBBB
BBBBBBB
BBBBBBB
BBBBBBB
BBBBBBB
BBBBBBB
BBBBBBB
BBBBBBB
BBBBBBB
BBBBBBB
BBBBBBB
BBBBBBB
BBBBBBB
|----Layer 1|

 
 LLLLL 
 LDDDL
 LDDDL
 LDDDL
 LLLLL
    C
    
 
d
d
d
d
d

|----Layer 2-3|

   
   
   
   L
   




d
d
d
d
d
|----Layer 4|

  
  lll
 lllll
 llLll
 lllll  
  lll
 


d
d
d
d
d

|----Layer 5|


 
 lllll
 lllll
 llLll
 lllll
 lllll







|----Layer 6|

 
 lllll   
 lllll   
 lllll
 lllll
 lllll








|----Layer 7|


  
  
  lll
  lll
  lll
   l







}}

;Illager Head Room
The structure is called "1x2_b5"

{{layered blueprint|name=Illager Head|default=Layer 0|B=Birch Planks|D=Dark Oak Planks|L=Light Gray Wool|G=Gray Wool|W=White Wool|R=Green Wool|A=Black Wool
|----Layer 0|
BBBBBBB
BBBBBBB
BBBBBBB
BBBBBBB
BBBBBBB
BBBBBBB
BBBBBBB
BBBBBBB
BBBBBBB
BBBBBBB
BBBBBBB
BBBBBBB
BBBBBBB
BBBBBBB
BBBBBBB
|----Layer 1-2|
DLLLLLD
   A
|----Layer 3|
DWRLRWD
|----Layer 4|
DGGGGGD
|----Layer 5-7|
DLLLLLD
}}

;Grave Room
An evoker and two vindicators spawn here. Layer 5 is empty.

The structure is called "1x2_d3"

{{layered blueprint|name=Grave Room|default=Layer 0|B=Birch Planks|C=Cobblestone|S=Cobblestone Stairs|O=Cobblestone Slab|W=White Carpet|L=Black Carpet|A=Black Banner|e=EntitySprite:evoker|v=EntitySprite:vindicator
|----Layer 0|
BBBBBBB
BBBBBBB
BBBBBBB
BBBBBBB
BBBBBBB
BBBBBBB
BBBBBBB
BBBBBBB
BBBBBBB
BBBBBBB
BBBBBBB
BBBBBBB
BBBBBBB
BBBBBBB
BBBBBBB
|----Layer 1|
CCCCCCC
CCCCCCC
CCCCCCC
CCCCCCC
CCCCCCC
CCCCCCC
CCCCCCC
CCCCCCC
CCCCCCC
CCCCCCC
CCCCCCC
 SSSSS
 OOOOO
   W
   W
|----Layer 2|
 
  SSS
  CCC
  CCC
  CCC
S CCC S
S SSS S
S OOO S
S OOO S
S  W  S
  vWv
|----Layer 3|
 
 
   C
   e
   W
   W
|----Layer 4|
 
 
   L
|----Layer 5|
|----Layer 6|
  SCS
|----Layer 7|
 SCCCS
|----Layer 8|
 CCCCC
  ASA
|----Layer 9|
 CCCCC
  SCS
|----Layer 10|
 CCCCC
  CCC
   S
}}

;Illager Statue Room
The structure is called "2x2_a3"

{{layered blueprint|name=Illager Statue|default=Layer 0|B=Birch Planks|L=Light Gray Wool|A=Black Wool|Y=Yellow Wool|W=White Wool|G=Green Wool|R=Gray Wool|O=Brown Wool|Q=Block of Lapis Lazuli
|----Layer 0|
BBBBBBBBBBBBBBB
BBBBBBBBBBBBBBB
BBBBBBBBBBBBBBB
BBBBBBBBBBBBBBB
BBBBBBBBBBBBBBB
BBBBBBBBBBBBBBB
BBBBBBBBBBBBBBB
BBBBBBBBBBBBBBB
BBBBBBBBBBBBBBB
BBBBBBBBBBBBBBB
BBBBBBBBBBBBBBB
BBBBBBBBBBBBBBB
BBBBBBBBBBBBBBB
BBBBBBBBBBBBBBB
BBBBBBBBBBBBBBB
|----Layer 1|
 
 
     LLLLL     
  OOOLLLLLOOO  
  OOOLLLLLOOO  
  OOOLLLLLOOO  
     LLLLL     
       A
 
  LLL     LLL
          LAL
          LLL
|----Layer 2|
 
 
     LLLLL     
     LLLLL
     LLLLL
     LLLLL
     LLLLL     
       A
 
  LLL
           A
|----Layer 3|
 
 
     LLLLL
     LLLLL
     LLLLL
     LLLLL
     WGLGW
 
 
  LLL
           A
|----Layer 4|
 
 
     LLLLL
     LLLLL
     LLLLL
     LLLLL
     RRRRR
 
 
 
           A
|----Layer 5|
 
 
     LLLLL
     LLLLL
     LLQLL
     LLLLL
     LLLLL
 
 
 
           A
|----Layer 6-7|
 
 
     LLLLL
     LLLLL
     LLLLL
     LLLLL
     LLLLL
 
 
 
          YWY
}}<noinclude>
[[fr:Manoir/Structure/Salles des trophées]]
[[pt:Mansão da floresta/Estrutura/Salas de troféus]]
[[zh:林地府邸/结构/装饰品房间]]
</noinclude>