<noinclude>{{structure info}}</noinclude>
There are three different sizes of libraries.

Any [[flowers]] on top of [[flower pots]] is what you put in the flower pot.

;Small Library (1x1_b4)
The ring of [[dark oak stairs]] all are upside down and face inside<br />
The [[flower pot]] have one [[allium]].
{{layered blueprint|name=Small Library|default=Layer 0|O=Oak Planks|o=Oak Stairs|B=Birch Planks|b=Bookshelf|D=Dark Oak Stairs|F=Flower Pot|f=Allium|d=Oak Slab
|----Layer 0|
BBBBBBB
BBBBBBB
BBBBBBB
BBBBBBB
BBBBBBB
BBBBBBB
BBBBBBB
|----Layer 1|
OOoooOO
O     O
      o
      o
      o
O     O
OOoooOO
|----Layer 2|
b     F
O
 
 
 
O     b
b    bO
|----Layer 3|
b     f
O
 
 
 
O     b
b    bO
|----Layer 4|
d
d
 
 
 
d     b
d    bO
|----Layer 5|
 
 
 
 
 
      b
     bO
|----Layer 6|
 
 
 
 
 
      d
     dd
|----Layer 7 - 9||----Layer 10|
DDDDDDD
D     D
D     D
D     D
D     D
D     D
DDDDDDD
}}

;Medium Library (1x2_c4)
The [[oak stairs]] around the outside the structure face in and the oak stairs in the center are upside down and face out<br />
The [[flower pot]]s have one [[dandelion]], one [[oxeye daisy]], one [[red tulip]], and one [[poppy]]
{{layered blueprint|name=Medium Library|default=Layer 0|B=Birch Planks|b=Bookshelf|O=Oak Planks|o=Oak Stairs|F=Flower Pot|f=Oak Fence|D=Dandelion|d=Oxeye Daisy|R=Red Tulip|r=Poppy
|----Layer 0|
BBBBBBB
BBBBBBB
BBBBBBB
BBBBBBB
BBBBBBB
BBBBBBB
BBBBBBB
BBBBBBB
BBBBBBB
BBBBBBB
BBBBBBB
BBBBBBB
BBBBBBB
BBBBBBB
BBBBBBB
|----Layer 1|
 OoooO
 
 
 
  ooo
  oOo O
  oOo o
b oOo o
b oOo o
  ooo O
 
 
 
 
bb   bb
|----Layer 2|
 f   f
 
 
 
 
   F  f
   F
b  F
b  F
      f
 
 
 
 
bb   bb
|----Layer 3|
 f   f
 
 
 
 
   D  f
   r
b  R
b  d
      f
 
 
 
 
bb   bb
|----Layer 4|
 f   f
 
 
 
 
      f
 
b
b
      f
 
 
 
 
bb   bb
|----Layer 5|
 f   f
 
 
 
 
      f
 
 
 
      f
|----Layer 6|
OOoooOO
o     o
o     o
o     o
o     o
o     O
o     o
o     o
o     o
o     O
o     o
o     o
o     o
o     o
ooooooo
}}

;Large Library (2x2_b3)
[[File:MansionLargeLibrarySeating.png|thumb]]

The [[oak slab]]s on Layer 1 is upside down.
The [[oak stairs]] on Layer 1 face the table, while the oak stairs on Layer 2 face away from the table. Refer to the image if unsure how each stair is placed.
{{layered blueprint|name=Large Library|default=Layer 0|B=Birch Planks|b=Bookshelf|O=Oak Planks|o=Oak Stairs|S=Oak Slab
|----Layer 0|
BBBBBBBBBBBBBBB
BBBBBBBBBBBBBBB
BBBBBBBBBBBBBBB
BBBBBBBBBBBBBBB
BBBBBBBBBBBBBBB
BBBBBBBBBBBBBBB
BBBBBBBBBBBBBBB
BBBBBBBBBBBBBBB
BBBBBBBBBBBBBBB
BBBBBBBBBBBBBBB
BBBBBBBBBBBBBBB
BBBBBBBBBBBBBBB
BBBBBBBBBBBBBBB
BBBBBBBBBBBBBBB
BBBBBBBBBBBBBBB
|----Layer 1|
           OOOO
 ObbbbbbO  Oooo
 ObbbbbbO
            OSS
 ObbbbbbO
 ObbbbbbO  Oooo
           OOOO
 ObbbbbbO
 ObbbbbbO  OOOO
           Oooo
 
            OSS
 
           Oooo
           OOOO
|----Layer 2|
           oooo
 ObbbbbbO  o
 ObbbbbbO
 
 ObbbbbbO
 ObbbbbbO  o
           oooo
 ObbbbbbO
 ObbbbbbO  oooo
           o
 
 
 
           o
           oooo
|----Layer 3 - 5|
 
 ObbbbbbO
 ObbbbbbO
 
 ObbbbbbO
 ObbbbbbO
 
 ObbbbbbO
 ObbbbbbO
}}<noinclude>
[[fr:Manoir/Structure/Librairies]]
[[pt:Mansão da floresta/Estrutura/Bibliotecas]]
[[zh:林地府邸/结构/图书馆]]
</noinclude>