<noinclude>{{structure info}}</noinclude>
;Forge Room (1x2_a3)
One [[Vindicator]] spawns in this room.
[[Stone Slab]]s on Layer 5 are upper slabs.
{{layered blueprint|name=Woodland Mansion Blacksmith|default=Layer 0|A=Birch Planks|B=Polished Andesite|C=Smooth Stone Slab|D=Double Smooth Stone Slab|F=Lava|H=Anvil|I=Smooth Stone Slab|v=EntitySprite:vindicator
|----Layer 0|
AAAAAAAAAAAAAAA
AAAAAAAAAAAAAAA
AAAAAAAAAAAAAAA
AAAAAAAAAAAAAAA
AAAAAAAAAAAAAAA
AAAAAAAAAAAAAAA
AAAAAAAAAAAAAAA

|----Layer 1|
BBBBBBBBBBBBBBB
BCCCCCCCCCCDBBB
BCCCCCCCCCCDBBB
BCCCCDDCDDCDBBB
BCCCCBBCBBCCCBB
BCCCCCCCCCCCCCB
BDCCCDBBBBBBBBB

|----Layer 2|
BBBBBBBBBBBBBBB
B           BFB
B           BFB
B       v   BBB
B    BB BB   HB
B             B
BD   DBBBBBBBBB

|----Layer 3|
        B  BBBB
              B
              B
              B
              B
               
 D   D  B     B

|----Layer 4|
        B  BBBB
              B
              B
              B
              B
               
 D   D  B     B

|----Layer 5|
        B     B
               
               
               
               
               
 BIIIB  B     B

|----Layer 6|
        B     B
               
               
               
               
               
 C B C  B     B

|----Layer 7|
        BBBBBBB
        B     B
        B     B
        B     B
        B     B
        B     B
        BBBBBBB

}}<noinclude>
[[fr:Manoir/Structure/Forge]]
[[pt:Mansão da floresta/Estrutura/Ferreiro]]
[[zh:林地府邸/结构/铁匠屋]]
</noinclude>