<noinclude>{{structure info}}</noinclude>
; Mushroom Farm (1x2_a7)

[[Chest]] contains nothing.
The [[oak stairs]] on Layer 1 at the last row is upside down.

{{layered blueprint|name=Mushroom Farm|default=Layer 0|L=Dark Oak Wood|O=Oak Planks|S=Oak Stairs|M=Red Mushroom|m=Brown Mushroom|B=Birch Planks|D=Dirt|C=Chest|F=Oak Fence
|----Layer 0|
BBBBBBB
BBBBBBB
BBBBBBB
BBBBBBB
BBBBBBB
BBBBBBB
BBBBBBB
BBBBBBB
BBBBBBB
BBBBBBB
BBBBBBB
BBBBBBB
BBBBBBB
BBBBBBB
BBBBBBB
|----Layer 1|
 
 OLLLO
 LDDDL
 LDDDL
 LDDDL
 LDDDL
 LDDDL
 LDDDL
 LDDDL
 OLLLO
 
 
 
 S
 SSC
|----Layer 2|
 
 F   F
  mMM
  Mmm
  mMM
  MmM
  Mmm
  MmM
  mMm
 F   F
|----Layer 3|
 
 F   F
 
 
 
 
 
 
 
 F   F
|----Layer 4|
OOOOOOO
OOOOOOO
OOOOOOO
OOOOOOO
FOOOOOF
FOOOOOF
FOOOOOF
FOOOOOF
FOOOOOF
FOOOOOF
|----Layer 5|
  SOS
  SOS
  SOS
  SOS
  SOS
  SOS
  SOS
  SOS
  SOS
  SSS
}}

; Melon and Pumpkin Farm (1x2_a8)
This is also known as the Stem Farm.
The [[Pumpkin]] and [[Watermelon]] Blocks do grow on their own, so consider them optional.

{{layered blueprint|name=Melon and Pumpkin Farm|default=Layer 0|B=Birch Planks|D=Dark Oak Planks|L=Dark Oak Wood|d=Dirt|F=Farmland|O=Oak Planks|o=Oak Slab|W=Water|P=Pumpkin|M=Melon|p=Pumpkin Stem|m=Melon Stem|f=Oak Fence|T=Torch
|----Layer 0|
BBBBBBB
BBBBBBB
BBBBBBB
BBBBBBB
BBBBBBB
BBBBBBB
BBBBBBB
BBBBBBB
BBBBBBB
BBBBBBB
BBBBBBB
BBBBBBB
BBBBBBB
BBBBBBB
BBBBBBB
|----Layer 1|
OLdFWFd
OLdFWFd
OLdFWFd
OLdFWFd
OLdFWFd
OLdFWFd
OLdFWFd
OLdFWFd
oLLLLLL
|----Layer 2|
OfPp pP
O Pp pP
O Pp pP
O Pp pP
O Pp pP
O Pp pP
o Pp pP
  Pp pP
|----Layer 3|
OT
O
O
O
o
|----Layer 4|
OLDDDDD
OLDDDDD
oLDDDDD
 LDDDDD
 LDDDDD
 LDDDDD
 LDDDDD
 LDDDDD
 LLLLLL
|----Layer 5|
oLdFWFd
 LdFWFd
 LdFWFd
 LdFWFd
 LdFWFd
 LdFWFd
 LdFWFd
 LdFWFd
 LLLLLL
|----Layer 6|
  Mm mM
  Mm mM
  Mm mM
  Mm mM
  Mm mM
  Mm mM
  Mm mM
  Mm mM
}}

; Wheat Farm (1x2_a2)
{{layered blueprint|name=Wheat Farm|default=Layer 0|D=Dark Oak Wood|d=Dark Oak Planks|s=Dark Oak Stairs|S=Oak Stairs|F=Dark Oak Fence|W=Wheat|L=Lily Pad|l=White Carpet|B=Birch Planks|b=Farmland|w=Water|f=Torch
|----Layer 0|
BBBBBBB
BBBBBBB
BBBBBBB
BBBBBBB
BBBBBBB
BBBBBBB
BBBBBBB
BBBBBBB
BBBBBBB
BBBBBBB
BBBBBBB
BBBBBBB
BBBBBBB
BBBBBBB
BBBBBBB
|----Layer 1|
DDDDDDD
DbbwbbD
DbbwbbD
DbbwbbD
DbbwbbD
DbbwbbD
DbbwbbD
DbbwbbD
DbbwbbD
DDDDDDD
s  s  s
 
 
    S S
     SS
|----Layer 2|
 
 WWLWW
 WWLWW
 WWLWW
 WWLWW
 WWLWW
 WWLWW
 WWLWW
 WWLWW
 
 
 
 
      l
|----Layer 3||----Layer 4|
 
 
   f
  fdf
   d
   d
  fdf
   f
|----Layer 5-7|
 
 
 
   F
 
 
   F
}}<noinclude>
[[fr:Manoir/Structure/Fermes]]
[[pt:Mansão da floresta/Estrutura/Fazendas]]
[[zh:林地府邸/结构/农场]]
</noinclude>