{{Structure info}}

== Blueprints ==
The individual regions of a woodland mansion can be divided into two categories: the outside (walls, roof, etc.) and inside (hallways, staircases, rooms, etc.).

=== Outside ===
==== The Entrance ====
The entrance structure is made with the 1st-floor-to-second-floor staircase.

The structure is called "entrance".

{{layered blueprint|name=Entrance Decoration|default=Ground Layer|D=Dark Oak Planks|T=Torch|C=Cobblestone|W=Cobblestone Wall|L=Dark Oak Log|O=Dark Oak Log+Top|w=Dark Oak Log+Horizontal|F=Dark Oak Fence|G=Glass Pane|S=Cobblestone Stairs|A=Cobblestone Slab|H=White Carpet|R=Red Carpet|B=Birch Planks|b=Birch Fence|d=Dark Oak Stairs
|----Ground Layer|
BBBBBBBBBBBBBBBB
BBBBBBBBBBBBBBBB
BBBBBBBBBBBBBBBB
BBBBBBBBBBBBBBBB
BBBBBBBBBBBBBBBB
BBBBBBBBBBBBBBBB
BBBBBBBBBBBBBBBB
BBBBBBBBBBBBBBBB
BBBBBBBBBBBBBBBB
BBBBBBBBBBBBBBBB
BBBBBBBBBBBBBBBB
BBBBBBBBBBBBBBBB
BBBBBBBBBBBBBBBB
BBBBBBBBBBBBBBBB
BBBBBBBBBBBBBBBB
BBBBBBBBBBBBBBBB
CCCCCCCCCCCCCCCC
CCCCCCCSSSCCCCCC
   AAAAAAAAAAA
    AAAAAAAAA
     CAAAAAC
|----Layer 1|
DDDDDDDDDDDDDDDD
D
D
D
D
D
D
D      CCC
D     SCCCS
L     CSSSC
HHHHHHHRRRHHHHHH
RRRRRRRRRRRRRRRR
RRRRRRRRRRRRRRRR
RRRRRRRRRRRRRRRR
HHHHHHHRRRHHHHHH
L     HRRRH
DDDDDDDRRRDDDDDD
WWSWWSS   SSWWSW
   
   
     T     T    
|----Layer 2|
LLLLLLLLLLLLLLLL
w
w
w
w
w
w
w     SCCCS
w     CSSSC
w     S   S
  
  
  
  
  
w
DDLGGLD   DLGGLD
|----Layer 3|
DDDDDDDDDDDDDDDD
D
D
D
D
D
D     SCCCS
D     CSSSC
D     S   S
w
  
  
  
  
  
w
DDLGGLD   DLGGLD
|----Layer 4|
DDDDDDDDDDDDDDDD
D
D
D
D
D     SCCCC
D     CSSSC
D     S   S
D
w
  
  
  
  
  
w
DDLGGLDd dDLGGLD
  F  F     F  F
|----Layer 5|
DDDDDDDDDDDDDDDD
D     CCCCC
D     CCCCC
D     CCCCC
D     CCCCC
D     CSSSC
D     S   S
D
D
w
  
  
  
  
  
w
DDLGGLDDDDDLGGLD
  F  F SSS F  F
|----Layer 6|
DDDDDDDDDDDDDDDD
D    CCSSSCC
D     SRRRS
D     SRRRS
D     SRRRS
D
D
D
D
D
w
w
w
w
w
D
DDLLLLDDDDDLLLLD
  wwww     wwww
|----Layer 7|
DDDDDDDDDDDDDDDD
DCCCCCS   SCCCCC
DCCCCS     SCCCC
DCCCCS     SCCCC
DCCCCS     SCCCC
DCCCCCS   SCCCCC
DCCCCC     CCCCC
DCCCCS     SCCCC
D
D
D
D
D
D
D
D
DDDDDDDDDDDDDDDD
SSS  SSSSSSS  SS
|----Layer 8|
CCCCCCCCCCCCCCCC
CSSSSS     SSSSS
CSRRR       RRRS
CSRRR       RRRS
CSRRR       RRRS
CSRRRC     CRRRS
CSRRRC     CRRRS
CCSSSC     CSSSC
CBBBBS     SBBBB
CBBBBS     SBBBB
CBBBBSSSSSSSBBBB
CBBBBBBBBBBBBBBB
CBBBBBBBBBBBBBBB
CBBBBBBBBBBBBBBB
CBBBBBBBBBBBBBBB
CBBBBBBBBBBBBBBB
wCCCCCCCwCCCCCCC
CCCCCCCCCCCCCCCC
|----Layer 9|
DDDDDDDDDDDDDDDD
D
D
D
D
D    b     b
D    b     b
DC   b     b   C
DHRRRb     bRRRH
DHRRRb     bRRRH
HHRRRbbbbbbbRRRH
RRRRRRRRRRRRRRRR
RRRRRRRRRRRRRRRR
RRRRRRRRRRRRRRRR
HHRRRRRRRRRRRRRH
DHRRRRRRRRRRRRRH
DDDDDDDDDDDDDDDD
WWSWWWSWWWSWWWSW
|----Layer 10|
DDDDDDDLDLDDDDDD
D
D
D
D
D
D
D
D
D
 
 
 
 
 
D
DDLGGGLDDDLGGGLD
|----Layer 11|
DDDDDDLDLDLDDDDD
D
D
D
D
D
D
D
D
D
 
 
 
 
 
D
DDLGGGLDDDLGGGLD
|----Layer 12|
DDDDDDLDLDLDDDDD
D
D
D
D
D
D
D
D
D
F
 
 
 
F
D
DDLGGGLDDDLGGGLD
|----Layer 13|
DDDDDDLDLDLDDDDD
D
D
D
D
D
D
D
D
D
T
 
 
 
T
D
DDLGGGLDDDLGGGLD
  F   F   F   F 
|----Layer 14|
DDDDDDLDLDLDDDDD
D
D
D
D
D
D
D
D
D
 
 
 
 
 
D
DDLGGGLDDDLGGGLD
  F   F   F   F 
|----Layer 15|
DDDDDDDLDLDDDDDD
D
D
D
D
D
D
D
D
D
 
 
 
 
 
D
DDLLLLLDDDLLLLLD
  wwwww   wwwww
|----Layer 16|
DDDDDDDDDDDDDDDD
D
D
D
D
D
D
D
D
D
 
 
 
 
 
D
DDDDDDDDDDDDDDDD
SSS   SSSSS   SS
|----Layer 17|
LLLLLLLLLLLLLLLL
L
L
L
L
L
L
L
L
D
 
 
 
 
 
D
|----Layer 18|
DDDDDDDDDDDDDDDD
D
D
D
D
D
D
D
D
D
 
 
 
 
 
D
|----Layer 19|
DDDDDDDDDDDDDDDD
Dddddddddddddddd
Dd             d
Dd             d
Dd             d
Dd             d
Dd             d
Dd             d
Dd             d
Dd             d
d
 
 
 
d
D
}}

==== Outside Wall ====
Outside Walls can have two variants: windowed and window-less.

===== Window-less =====
The cobblestone stairs are upside down. The top row faces inside.

The structure is called "wall_flat".

{{layered blueprint|name=Windowless Outside Wall Segment|default=Wall|D=Dark Oak Planks|C=Cobblestone|W=Cobblestone Wall|L=Dark Oak Log|S=Cobblestone Stairs|s=Cobblestone Stairs-rot270|c=Cobblestone Stairs-rot90
|----Layer 1|
CCCCCCCC
WW     W
|----Layer 2 - 3|
DDDDDDDD
        
|----Layer 4|
DDDDLDDD
        
|----Layer 5|
DDDLDLDD
        
|----Layer 6|
DDDDLDDD
        
|----Layer 7|
DDDDDDDD
        
|----Layer 8|
DDDDDDDD
SSs   cS
}}

===== Window =====
The top row faces inside.

The structure is called "wall_window".

Cobblestone stairs in Layer 2 are normal, while the ones in Layer 8 are all upside-down.

{{layered blueprint|name=Outside Wall Segment|default=Wall|D=Dark Oak Planks|C=Cobblestone|W=Cobblestone Wall|L=Dark Oak Log|l=Dark Oak Log-rot90|S=Cobblestone Stairs|s=Cobblestone Stairs-rot90|c=Cobblestone Stairs-rot270|G=Glass Pane|F=Dark Oak Fence
|----Layer 1|
CCCCCCCC
CCCCCCCC
|----Layer 2|
DDDDDDDD
WWSWWWSW
|----Layer 3 - 4|
DDLGGGLD
        
|----Layer 5 - 6|
DDLGGGLD
  F   F 
|----Layer 7|
DDLLLLLD
  lllll 
|----Layer 8|
DDDDDDDD
SSc   sS
}}

==== Roof ====
The roof is made entirely out of dark oak planks with a trim of upward-facing dark oak stairs.

=== Inside ===
None of the rooms will have walls included because they can be mixed and matched based on what's around them.
==== Walls ====
There are two different wall designs that come in segments. Since they are flat, there will only be one layer for the sake of readability. Some of these walls can have a row of logs and planks on top, creating the "_2" variants.

===== Solid Wall =====
The farthest right block is going to be covered by the pillars that come with the hallways.

The structure is called "indoors_wall".

{{layered blueprint|name=Solid Wall|default=Wall|D=Dark Oak Planks|L=Dark Oak Log
|----Layer 1|
DDDDDDDD

|----Layer 2 - 3|
DDDLDDDD

|----Layer 4|
DLLDLLDD

|----Layer 5 - 6|
DDDLDDDD

|----Layer 7|
DDDDDDDD
}}

===== 2nd & 3rd Floor Solid Wall =====
This is basically the first floor walls but 3 blocks added on the top.
{{layered blueprint|name=2nd & 3rd Floor Solid Wall|default=Wall|D=Dark Oak Planks|L=Dark Oak Log
|----Layer 1|
DDDDDDDD

|----Layer 2 - 3|
DDDLDDDD

|----Layer 4|
DLLDLLDD

|----Layer 5 - 6|
DDDLDDDD

|----Layer 7 - 8|
DDDDDDDD

|----Layer 9|
LLLLLLLL

|----Layer 10|
DDDDDDDD
}}

===== Entrance To A Room =====
The stairs are upside-down, facing the opening. The farthest right block is going to be covered by the pillars that come with the hallways.

The structure is called "indoors_door".

{{layered blueprint|name=Entrance To A Room|default=Wall|D=Dark Oak Planks|S=Dark Oak Stairs
|----Layer 1 - 3|
DD   DDD

|----Layer 4|
DDS SDDD

|----Layer 5 - 7|
DDDDDDDD
}}

==== Hallways ====
This does not include the walls on either side since that can change based on whether the hallway borders an outside wall or an inside wall, or has a staircase leading to it. These come in segments, so each blueprint will show one segment.

===== Straight Hallway =====
{{layered blueprint|name=Straight Hallway|default=Layer 0|D=Dark Oak Planks|T=Torch|F=Dark Oak Fence|B=Birch Planks|W=White Carpet|R=Red Carpet
|----Layer 0|
BBBBBBB
BBBBBBB
BBBBBBB
BBBBBBB
BBBBBBB
BBBBBBB
BBBBBBB
BBBBBBB
|----Layer 1|
DWRRRWD
 WRRRW 
 WRRRW 
 WRRRW 
 WRRRW 
 WRRRW 
 WRRRW 
 WRRRW 
|----Layer 2-3|
D     D
|----Layer 4|
DF   FD
|----Layer 5|
DT   TD
|----Layer 6-7|
D     D
}}

===== Curved Hallway =====
This blueprint shows a left turn, but it can be mirrored to turn the other way.
{{layered blueprint|name=Curved Hallway|default=Layer 0|D=Dark Oak Planks|T=Torch|F=Dark Oak Fence|B=Birch Planks|W=White Carpet|R=Red Carpet
|----Layer 0|
BBBBBBB
BBBBBBB
BBBBBBB
BBBBBBB
BBBBBBB
BBBBBBB
BBBBBBB
|----Layer 1|
D
WWWWWWW
RRRRRRW
RRRRRRW
RRRRRRW
WWWRRRW
D WRRRW
|----Layer 2-3|
D
 
 
 
 
 
D
|----Layer 4|
D
F
 
 
 
F
D
|----Layer 5|
D
T
 
 
 
T
D
|----Layer 6-7|
D
 
 
 
 
 
D
}}

===== Dead-End Hallway =====
There is no decoration in a dead-end hallway that does not include the walls after the layer with carpet.
{{layered blueprint|name=Dead-End|default=Layer 0|B=Birch Planks|W=White Carpet|R=Red Carpet
|----Layer 0|
BBBBBBB
BBBBBBB
BBBBBBB
BBBBBBB
BBBBBBB
BBBBBBB
BBBBBBB
|----Layer 1|
   
 WWWWW
 WRRRW
 WRRRW
 WRRRW
 WRRRW
 WRRRW
}}

===== T-Intersection Hallway =====
{{layered blueprint|name=T-Intersection|default=Layer 0|D=Dark Oak Planks|T=Torch|F=Dark Oak Fence|B=Birch Planks|W=White Carpet|R=Red Carpet
|----Layer 0|
BBBBBBBB
BBBBBBBB
BBBBBBBB
BBBBBBBB
BBBBBBBB
BBBBBBBB
BBBBBBBB
BBBBBBBB
|----Layer 1|
DDWRRRWD
D WRRRW
WWWRRRW
RRRRRRW
RRRRRRW
RRRRRRW
WWWRRRW
D WRRRW
|----Layer 2-3|
DD     D
D
 
 
 
 
 
D
|----Layer 4|
DDF   FD
D
F
 
 
 
F
D
|----Layer 5|
DDT   TD
D
T
 
 
 
T
D
|----Layer 6-7|
DD     D
D
 
 
 
 
 
D
}}

{{LoadPage|Woodland Mansion/Structure/2nd_to_3rd_Floor_Staircase|2nd Floor to 3rd Floor Staircase|h4}}
{{LoadPage|Woodland Mansion/Structure/Farms|Farms|h4}}
{{LoadPage|Woodland Mansion/Structure/Trophy Rooms|Trophy Rooms|h4}}
{{LoadPage|Woodland Mansion/Structure/Jails|Jails|h4}}
{{LoadPage|Woodland Mansion/Structure/Libraries|Libraries|h4}}

==== Office ====
There are four layers of empty space above the blueprint.

The structure is called "1x1_a3".

{{layered blueprint|name=Office|default=Layer 0|B=Birch Planks|C=Cobblestone|S=Cobblestone Stairs|O=Oak Planks|o=Oak Stairs|F=Potted Red Tulip|G=Light Gray Carpet
|----Layer 0|
BBBBBBB
BBBBBBB
BBBBBBB
BBBBBBB
BBBBBBB
BBBBBBB
BBBBBBB
|----Layer 1|
CS    C
CS    C
CSo
CS    O
CS
 o
|----Layer 2|
     SC
F    SC
 G   SS
F     o
 G
|----Layer 3|
       
      F
      G
}}


==== Dining Halls ====
They come in three sizes.

===== Small Dining Hall =====
The structure is called "1x1_b2".

{{layered blueprint|name=Small Dining Hall|default=Layer 0|B=Birch Planks|D=Dark Oak Planks|F=Dark Oak Fence|L=Light Gray Carpet|C=Black Carpet|O=Oak Planks|S=Oak Stairs|d=Dark Oak Stairs
|----Layer 0|
BBBBBBB
BBBBBBB
BBBBBBB
BBBBBBB
BBBBBBB
BBBBBBB
BBBBBBB
|----Layer 1|
 
  S S
  SSSS
  OOOO
 SSSSS
 
   S
|----Layer 2|
 
 
  LLLL
  LCCL
  LLLL
|----Layer 3-5|
|----Layer 6|
 
 
d     d
D     D
d     d
|----Layer 7|
 
 
 
DF   FD
|----Layer 8-10|
 
 
 
D     D
}}

===== Medium Dining Hall =====
There are three layers of empty space above the blueprint.

The structure is called "1x2_c1".

{{layered blueprint|name=Medium Dining Hall|default=Layer 0|B=Birch Planks|F=Dark Oak Fence|G=Gray Carpet|W=White Carpet|O=Oak Planks|S=Oak Stairs|T=Torch|L=Oak Slab|f=Potted Oxeye Daisy
|----Layer 0|
BBBBBBB
BBBBBBB
BBBBBBB
BBBBBBB
BBBBBBB
BBBBBBB
BBBBBBB
BBBBBBB
BBBBBBB
BBBBBBB
BBBBBBB
BBBBBBB
BBBBBBB
BBBBBBB
BBBBBBB
|----Layer 1|
OOOOS
OOOOS
SSSSS
GGGGG
 
 
 
 
 
  SLS
S SLS S
  SLS
S SLS S
  SLS
|----Layer 2|
WWWWW
WWWWW
WWWWW
WWWWW
 
 
 
 
 
 
  W W
   f
  W W
|----Layer 3-4|
|----Layer 5|
 
 
 
 
 
 
   F
  FFF
   F
|----Layer 6|
 
 
 
 
 
 
   T
  TFT
   T
|----Layer 7|
 
 
 
 
 
 
 
FFFFFFF
}}

===== Large Dining Hall =====
An evoker and two vindicators spawn here.

The structure is called "2x2_b1".

{{layered blueprint|name=Large Dining Hall|default=Layer 0|B=Birch Planks|O=Oak Planks|S=Oak Stairs|f=Potted Birch Sapling|F=Oak Fence|W=White Carpet|M=Magenta Carpet|T=Torch|L=Oak Slab|e=EntitySprite:evoker|v=EntitySprite:vindicator
|----Layer 0|
BBBBBBBBBBBBBBB
BBBBBBBBBBBBBBB
BBBBBBBBBBBBBBB
BBBBBBBBBBBBBBB
BBBBBBBBBBBBBBB
BBBBBBBBBBBBBBB
BBBBBBBBBBBBBBB
BBBBBBBBBBBBBBB
BBBBBBBBBBBBBBB
BBBBBBBBBBBBBBB
BBBBBBBBBBBBBBB
BBBBBBBBBBBBBBB
BBBBBBBBBBBBBBB
BBBBBBBBBBBBBBB
BBBBBBBBBBBBBBB
|----Layer 1|
         LLLLL
    S    OLLLO
      e
    SS
   SOOS S vS
 S SOOS
    SS    SS
       S SOOS
     v   SOOS S
     SS   SS
  S SOOS
    SOOS S
     SS
 
     S
|----Layer 2|
         MLWWM
         MWWWM
 
     W
     f W
    W      W
         W
          f W
             
            
     W f  
        W
      W
|----Layer 3-4|
|----Layer 5|
       F
 
 
 
 
 
 
F             F
 
 
 
 
 
 
       F
|----Layer 6|
       T
 
 
 
 
 
 
T             T
 
 
 
 
 
 
       T
|----Layer 7|
 
 
 
 
 
 
       F
      FFF
       F
|----Layer 8|
 
 
 
 
 
 
       T
      TFT
       T
|----Layer 9-10|
 
 
 
 
 
 
 
       F
}}

{{LoadPage|Woodland Mansion/Structure/Chest Rooms|Chest Rooms|h4}}
{{LoadPage|Woodland Mansion/Structure/Blacksmith|Blacksmith|h4}}

{{LoadPage|Woodland Mansion/Structure/Map Room|Map Room|h4}}
{{LoadPage|Woodland Mansion/Structure/Loot Rooms|Loot Rooms|h4}}

==== Conference Room ====
One evoker and two vindicators spawn here. Layers 3-6 are empty.

The structure is called "2x2_b2".

{{layered blueprint|name=Conference Room|default=Layer 0|B=Birch Planks|O=Oak Planks|S=Oak Stairs|F=Oak Fence|T=Torch|W=White Carpet|f=Potted White Tulip|e=EntitySprite:evoker|v=EntitySprite:vindicator
|----Layer 0|
BBBBBBBBBBBBBBB
BBBBBBBBBBBBBBB
BBBBBBBBBBBBBBB
BBBBBBBBBBBBBBB
BBBBBBBBBBBBBBB
BBBBBBBBBBBBBBB
BBBBBBBBBBBBBBB
BBBBBBBBBBBBBBB
BBBBBBBBBBBBBBB
BBBBBBBBBBBBBBB
BBBBBBBBBBBBBBB
BBBBBBBBBBBBBBB
BBBBBBBBBBBBBBB
BBBBBBBBBBBBBBB
BBBBBBBBBBBBBBB
|----Layer 1|
    S  S  S
 
   SSSSSSSSS
   SOOOOOOOS
   SSSSSSSOS
         SOS S
     v   SOS S
         SOSe
         SOS S
         SOS S
   SSSSSSSOS
   SOOOOOOOS
 v SSSSSSSSS
 
    S  S  S
|----Layer 2|
    
 
    W  W  W
     f  f
 
           W S
           W S
 
           W S
          fW S
 
     f  f
    W  W  W
 
    S  S  S
|----Layer 3-6|
|----Layer 7|
 
 
 
 
 
 
   F       F
  FFF     FFF
   F       F
|----Layer 8|
 
 
 
 
 
 
   T       T
  TFT     TFT
   T       T
|----Layer 9-10|
 
 
 
 
 
 
 
   F       F
}}

==== Bedrooms ====
===== Master Bedroom =====
This room has a loot chest. There are two layers of empty space above the blueprint.

The structure is called "1x2_d2".

{{layered blueprint|name=Master Bedroom|default=Layer 0|B=Birch Planks|d=Dark Oak Door+bottom|D=Dark Oak Door+top|O=Oak Planks|S=Oak Stairs|L=Ladder|W=White Wool|C=Chest|F=Oak Fence|R=Red Carpet|f=Potted Red Tulip|c=Cyan Carpet|l=Light Blue Carpet
|----Layer 0|
BBBBBBB
BBBBBBB
BBBBBBB
BBBBBBB
BBBBBBB
BBBBBBB
BBBBBBB
BBBBBBB
BBBBBBB
BBBBBBB
BBBBBBB
BBBBBBB
BBBBBBB
BBBBBBB
BBBBBBB
|----Layer 1|
  
 OOOOO
 O O O
 OdOdO
  
SSSSO
WWWWS
WWWWS
WWWWS
SSSSO
 
 
 
 
 L
 O
|----Layer 2|
  
 OOOOO
 O O O
 ODODO
  
 
 RRR
 RRR
 RRR
 
 
 
 
 
 L
 O
|----Layer 3|
 
 OOOOO
 O O O
 OSOSO
 
 
 
 
 
 
 
 
 
 
 L
 O
|----Layer 4|
 
 OOOOO
 OOOOO
 SSSSS
 
 
 
 
 
 
 
 
 
 
 L
 O
|----Layer 5|
 
 
 
 
 
 
 
 
 
 
 
 
 
 
 L
 O
|----Layer 6|
 
 
 
 
 
 
 
 
 
 
 
 
OOOOOOO
OOOOOOO
OLOOOOO
OOOOOOO
|----Layer 7|

 
 
 
 
 
 
 
 
 
 
 
FFFFFFF
      C
    WWW
O   WWW
|----Layer 8|

 
 
 
 
 
 
 
 
 
 
 
 
 
    ccl
f   ccl
}}

===== Master Bedroom With Banners =====
This banners are light gray with a white gear pattern.

The structure is called "1x2_d1".

{{layered blueprint|name=Banner Bedroom|default=Layer 0|B=Birch Planks|O=Oak Planks|F=Oak Fence|S=Oak Slab|s=Oak Stairs|P=Potted Oxeye Daisy|b=Birch Stairs|A=Light Gray Banner|R=Red Carpet|G=Light Gray Carpet|K=Bookshelf|W=White Wool|f=Potted Birch Sapling
|----Layer 0|
BBBBBBB
BBBBBBB
BBBBBBB
BBBBBBB
BBBBBBB
BBBBBBB
BBBBBBB
BBBBBBB
BBBBBBB
BBBBBBB
BBBBBBB
BBBBBBB
BBBBBBB
BBBBBBB
BBBBBBB
|----Layer 1|
 
 
SS
OS S
SS
 
 
 
 
 OSSSO
 SWWWS
 SWWWS
 SWWWS
 SWWWS
OOOOOO
|----Layer 2|
 
 
f
 G
 
 
 
 
 
 F   F
  RRR
  RRR
  RRR
 
KFP  F
OOOOOO
|----Layer 3-5|
 
 
 
 
 
 
 
 
 
 F   F
 
 
 
 
 F   F
|----Layer 6|
   b
 
 
 
 
 
 
 
 
 OSSSO
 SSSSS
 SSSSS
 SSSSS
 SSSSS
 OSSSO
|----Layer 7|
  BBB
  A A
|----Layer 8|
  BBB
   A
|----Layer 9|
  bBb
|----Layer 10|
   b
}}

===== Single Bed Room =====
The structure is called "1x1_b3".

{{layered blueprint|name=Single Bedroom|default=Layer 0|B=Birch Planks|C=Cobblestone|W=White Wool|R=Red Wool|F=Dark Oak Fence|l=Dark Oak Leaves|S=Cobblestone Slab|s=Cobblestone Stairs|O=Oak Planks|o=Oak Slab
|----Layer 0|
BBBBBBB
BBBBBBB
BBBBBBB
BBBBBBB
BBBBBBB
BBBBBBB
BBBBBBB
|----Layer 1|
SCC oWW
CCS oRR
CSS oRR
    ooo
       
 O     
|----Layer 2|
       
       
       
       
       
 F     
|----Layer 3|
CS
SS
 
 
 
 l
|----Layer 4-9|
C
|----Layer 10|
Cs
ss
}}

===== Double Bed Room =====
There are 8 layers of empty space above the blueprint.

The structure is called "1x2_c2".

{{layered blueprint|name=Double Bedroom|default=Layer 0|B=Birch Planks|W=White Wool|T=Oak Stairs|S=Oak Slab|F=Potted Allium|w=White Carpet|P=Purple Carpet|p=Pink Carpet|O=Oak Planks
|----Layer 0|
BBBBBBB
BBBBBBB
BBBBBBB
BBBBBBB
BBBBBBB
BBBBBBB
BBBBBBB
BBBBBBB
BBBBBBB
BBBBBBB
BBBBBBB
BBBBBBB
BBBBBBB
BBBBBBB
BBBBBBB
|----Layer 1|
       
 WW WW 
 WW WW
 WW WW
 
 
      T
     TT
      T
 
 
 
 
 
      S
|----Layer 2|
       
 pp pp 
 PP PP
 PP PP
 
 
 
      w
 
 
 
 
 
 
      F
}}

===== Triple Bed Room =====
Three vindicators spawn at the base of the beds. There are 8 layers of empty space above the blueprint.

The structure is called "1x2_c3".

{{layered blueprint|name=Triple Bedroom|default=Layer 0|B=Birch Planks|W=White Wool|T=Oak Stairs|S=Oak Slab|F=Potted Azure Bluet|w=White Carpet|L=Blue Carpet|l=Light Blue Carpet|O=Oak Planks|v=EntitySprite:vindicator
|----Layer 0|
BBBBBBB
BBBBBBB
BBBBBBB
BBBBBBB
BBBBBBB
BBBBBBB
BBBBBBB
BBBBBBB
BBBBBBB
BBBBBBB
BBBBBBB
BBBBBBB
BBBBBBB
BBBBBBB
BBBBBBB
|----Layer 1|
       
T  WWW 
T vWWW 
       
   WWW 
T vWWW 
T      
   WWW 
  vWWW 
       
      O
    T O
|----Layer 2|
       
   LLl 
   LLl 
       
   LLl 
   LLl 
       
   LLl 
   LLl 
       
      F
       
}}

[[Category:Structure Blueprints]]

[[fr:Manoir/Structure]]
[[ja:森の洋館/構造]]
[[pt:Mansão da floresta/Estrutura]]
[[zh:林地府邸/结构]]